{'asks': [{'price': '0.99', 'size': '4217.01'}, {'price': '0.98', 'size': '505'}, {'price': '0.97', 'size': '511.03'}, {'price': '0.96', 'size': '300'}, {'price': '0.95', 'size': '657.12'}, {'price': '0.94', 'size': '300'}, {'price': '0.92', 'size': '20000.45'}, {'price': '0.91', 'size': '10406.3'}, {'price': '0.9', 'size': '4587.5'}, {'price': '0.89', 'size': '13017.18'}, {'price': '0.88', 'size': '200'}, {'price': '0.87', 'size': '3229'}, {'price': '0.86', 'size': '17.1'}, {'price': '0.85', 'size': '109.68'}, {'price': '0.84', 'size': '250'}, {'price': '0.83', 'size': '100'}, {'price': '0.82', 'size': '16029'}, {'price': '0.81', 'size': '45721.39'}, {'price': '0.8', 'size': '26531'}, {'price': '0.79', 'size': '7110'}, {'price': '0.78', 'size': '10350'}, {'price': '0.77', 'size': '67'}, {'price': '0.76', 'size': '200'}, {'price': '0.75', 'size': '18329.25'}, {'price': '0.74', 'size': '11370.7'}, {'price': '0.73', 'size': '5020.1'}, {'price': '0.72', 'size': '380.52'}, {'price': '0.71', 'size': '15073.2'}, {'price': '0.7', 'size': '5570.1'}, {'price': '0.69', 'size': '6088.6'}, {'price': '0.68', 'size': '2131.34'}, {'price': '0.67', 'size': '3010.1'}, {'price': '0.66', 'size': '4510.1'}, {'price': '0.65', 'size': '1010.1'}, {'price': '0.64', 'size': '1230.1'}, {'price': '0.63', 'size': '210.1'}, {'price': '0.62', 'size': '300.1'}, {'price': '0.61', 'size': '511.06'}, {'price': '0.6', 'size': '467.85'}, {'price': '0.59', 'size': '5510'}, {'price': '0.58', 'size': '1958.1'}, {'price': '0.57', 'size': '110.1'}, {'price': '0.56', 'size': '1161.75'}, {'price': '0.55', 'size': '1714.23'}], 'asset_id': '114416409796971863099144323163249651172534872992222856507897414949637892047507', 'bids': [{'price': '0.01', 'size': '2850.27'}, {'price': '0.02', 'size': '500'}, {'price': '0.03', 'size': '500'}, {'price': '0.04', 'size': '300'}, {'price': '0.05', 'size': '320'}, {'price': '0.06', 'size': '300'}, {'price': '0.08', 'size': '250'}, {'price': '0.09', 'size': '300'}, {'price': '0.1', 'size': '205'}, {'price': '0.11', 'size': '5454'}, {'price': '0.12', 'size': '200'}, {'price': '0.13', 'size': '426.92'}, {'price': '0.14', 'size': '15'}, {'price': '0.15', 'size': '110'}, {'price': '0.16', 'size': '4709.51'}, {'price': '0.18', 'size': '19.13'}, {'price': '0.19', 'size': '120'}, {'price': '0.2', 'size': '691.17'}, {'price': '0.24', 'size': '5027'}, {'price': '0.25', 'size': '86.66'}, {'price': '0.27', 'size': '215.25'}, {'price': '0.29', 'size': '1102.28'}, {'price': '0.31', 'size': '1130.65'}, {'price': '0.32', 'size': '200'}, {'price': '0.33', 'size': '4620'}, {'price': '0.35', 'size': '232'}, {'price': '0.39', 'size': '10.5'}, {'price': '0.4', 'size': '3135'}, {'price': '0.41', 'size': '20'}, {'price': '0.42', 'size': '3050'}, {'price': '0.43', 'size': '50'}, {'price': '0.44', 'size': '3660'}, {'price': '0.45', 'size': '478'}, {'price': '0.46', 'size': '500'}, {'price': '0.47', 'size': '2550'}, {'price': '0.48', 'size': '2342.18'}, {'price': '0.49', 'size': '390'}, {'price': '0.5', 'size': '3815'}, {'price': '0.51', 'size': '1186.18'}, {'price': '0.52', 'size': '752.77'}], 'event_type': 'book', 'hash': '414cbbe13603c10377ba8bed5cd3d993679707b0', 'market': '0x7aa4a910b31b2c4ddb09d1e3408e52aa8e09a14402f376070a44b1b85cb36d13', 'timestamp': '1733332946525'}
{'asks': [{'price': '0.99', 'size': '4217.01'}, {'price': '0.98', 'size': '505'}, {'price': '0.97', 'size': '511.03'}, {'price': '0.96', 'size': '300'}, {'price': '0.95', 'size': '657.12'}, {'price': '0.94', 'size': '300'}, {'price': '0.92', 'size': '20000.45'}, {'price': '0.91', 'size': '10406.3'}, {'price': '0.9', 'size': '4587.5'}, {'price': '0.89', 'size': '13017.18'}, {'price': '0.88', 'size': '200'}, {'price': '0.87', 'size': '3229'}, {'price': '0.86', 'size': '17.1'}, {'price': '0.85', 'size': '109.68'}, {'price': '0.84', 'size': '250'}, {'price': '0.83', 'size': '100'}, {'price': '0.82', 'size': '16029'}, {'price': '0.81', 'size': '45721.39'}, {'price': '0.8', 'size': '26531'}, {'price': '0.79', 'size': '7110'}, {'price': '0.78', 'size': '10350'}, {'price': '0.77', 'size': '67'}, {'price': '0.76', 'size': '200'}, {'price': '0.75', 'size': '18329.25'}, {'price': '0.74', 'size': '11370.7'}, {'price': '0.73', 'size': '5020.1'}, {'price': '0.72', 'size': '380.52'}, {'price': '0.71', 'size': '15073.2'}, {'price': '0.7', 'size': '5570.1'}, {'price': '0.69', 'size': '6088.6'}, {'price': '0.68', 'size': '2131.34'}, {'price': '0.67', 'size': '3010.1'}, {'price': '0.66', 'size': '4510.1'}, {'price': '0.65', 'size': '1010.1'}, {'price': '0.64', 'size': '1230.1'}, {'price': '0.63', 'size': '210.1'}, {'price': '0.62', 'size': '300.1'}, {'price': '0.61', 'size': '511.06'}, {'price': '0.6', 'size': '467.85'}, {'price': '0.59', 'size': '5510'}, {'price': '0.58', 'size': '1958.1'}, {'price': '0.57', 'size': '110.1'}, {'price': '0.56', 'size': '1161.75'}, {'price': '0.55', 'size': '1714.23'}], 'asset_id': '114416409796971863099144323163249651172534872992222856507897414949637892047507', 'bids': [{'price': '0.01', 'size': '2850.27'}, {'price': '0.02', 'size': '500'}, {'price': '0.03', 'size': '500'}, {'price': '0.04', 'size': '300'}, {'price': '0.05', 'size': '320'}, {'price': '0.06', 'size': '300'}, {'price': '0.08', 'size': '250'}, {'price': '0.09', 'size': '300'}, {'price': '0.1', 'size': '205'}, {'price': '0.11', 'size': '5454'}, {'price': '0.12', 'size': '200'}, {'price': '0.13', 'size': '426.92'}, {'price': '0.14', 'size': '15'}, {'price': '0.15', 'size': '110'}, {'price': '0.16', 'size': '4709.51'}, {'price': '0.18', 'size': '19.13'}, {'price': '0.19', 'size': '120'}, {'price': '0.2', 'size': '691.17'}, {'price': '0.24', 'size': '5027'}, {'price': '0.25', 'size': '86.66'}, {'price': '0.27', 'size': '215.25'}, {'price': '0.29', 'size': '1102.28'}, {'price': '0.31', 'size': '1130.65'}, {'price': '0.32', 'size': '200'}, {'price': '0.33', 'size': '4620'}, {'price': '0.35', 'size': '232'}, {'price': '0.39', 'size': '10.5'}, {'price': '0.4', 'size': '3135'}, {'price': '0.41', 'size': '20'}, {'price': '0.42', 'size': '3050'}, {'price': '0.43', 'size': '50'}, {'price': '0.44', 'size': '3660'}, {'price': '0.45', 'size': '478'}, {'price': '0.46', 'size': '500'}, {'price': '0.47', 'size': '2550'}, {'price': '0.48', 'size': '2342.18'}, {'price': '0.49', 'size': '390'}, {'price': '0.5', 'size': '3815'}, {'price': '0.51', 'size': '1186.18'}, {'price': '0.52', 'size': '752.77'}], 'event_type': 'book', 'hash': '414cbbe13603c10377ba8bed5cd3d993679707b0', 'market': '0x7aa4a910b31b2c4ddb09d1e3408e52aa8e09a14402f376070a44b1b85cb36d13', 'timestamp': '1733332946525'}
{'asset_id': '114416409796971863099144323163249651172534872992222856507897414949637892047507', 'changes': [{'price': '0.56', 'side': 'SELL', 'size': '2361.75'}, {'price': '0.58', 'side': 'SELL', 'size': '3958.1'}], 'event_type': 'price_change', 'hash': 'f3b77e0b7e5f4b2747cc9e9cd8a9c6ece0c2a0cb', 'market': '0x7aa4a910b31b2c4ddb09d1e3408e52aa8e09a14402f376070a44b1b85cb36d13', 'timestamp': '1733332950713'}
{'asset_id': '114416409796971863099144323163249651172534872992222856507897414949637892047507', 'changes': [{'price': '0.56', 'side': 'SELL', 'size': '2361.75'}, {'price': '0.58', 'side': 'SELL', 'size': '3958.1'}], 'event_type': 'price_change', 'hash': 'f3b77e0b7e5f4b2747cc9e9cd8a9c6ece0c2a0cb', 'market': '0x7aa4a910b31b2c4ddb09d1e3408e52aa8e09a14402f376070a44b1b85cb36d13', 'timestamp': '1733332950713'}
{'asset_id': '114416409796971863099144323163249651172534872992222856507897414949637892047507', 'changes': [{'price': '0.5', 'side': 'BUY', 'size': '2315'}, {'price': '0.58', 'side': 'SELL', 'size': '2458.1'}], 'event_type': 'price_change', 'hash': 'afe8490976fea78be41c21a7a1b43f8f0e697369', 'market': '0x7aa4a910b31b2c4ddb09d1e3408e52aa8e09a14402f376070a44b1b85cb36d13', 'timestamp': '1733332973926'}
{'asset_id': '114416409796971863099144323163249651172534872992222856507897414949637892047507', 'changes': [{'price': '0.5', 'side': 'BUY', 'size': '2315'}, {'price': '0.58', 'side': 'SELL', 'size': '2458.1'}], 'event_type': 'price_change', 'hash': 'afe8490976fea78be41c21a7a1b43f8f0e697369', 'market': '0x7aa4a910b31b2c4ddb09d1e3408e52aa8e09a14402f376070a44b1b85cb36d13', 'timestamp': '1733332973926'}
{'asset_id': '114416409796971863099144323163249651172534872992222856507897414949637892047507', 'changes': [{'price': '0.51', 'side': 'BUY', 'size': '1086.18'}], 'event_type': 'price_change', 'hash': '25454728da8b55603b33ecf010b7fa22608780b6', 'market': '0x7aa4a910b31b2c4ddb09d1e3408e52aa8e09a14402f376070a44b1b85cb36d13', 'timestamp': '1733332974081'}
{'asset_id': '114416409796971863099144323163249651172534872992222856507897414949637892047507', 'changes': [{'price': '0.51', 'side': 'BUY', 'size': '1086.18'}], 'event_type': 'price_change', 'hash': '25454728da8b55603b33ecf010b7fa22608780b6', 'market': '0x7aa4a910b31b2c4ddb09d1e3408e52aa8e09a14402f376070a44b1b85cb36d13', 'timestamp': '1733332974081'}
{'asset_id': '114416409796971863099144323163249651172534872992222856507897414949637892047507', 'changes': [{'price': '0.5', 'side': 'BUY', 'size': '2415'}], 'event_type': 'price_change', 'hash': '4a1fc1a3bf996dbbad9eb880417041b2158b9de6', 'market': '0x7aa4a910b31b2c4ddb09d1e3408e52aa8e09a14402f376070a44b1b85cb36d13', 'timestamp': '1733332974982'}
{'asset_id': '114416409796971863099144323163249651172534872992222856507897414949637892047507', 'changes': [{'price': '0.5', 'side': 'BUY', 'size': '2415'}], 'event_type': 'price_change', 'hash': '4a1fc1a3bf996dbbad9eb880417041b2158b9de6', 'market': '0x7aa4a910b31b2c4ddb09d1e3408e52aa8e09a14402f376070a44b1b85cb36d13', 'timestamp': '1733332974982'}
{'asset_id': '114416409796971863099144323163249651172534872992222856507897414949637892047507', 'changes': [{'price': '0.48', 'side': 'BUY', 'size': '3842.18'}, {'price': '0.57', 'side': 'SELL', 'size': '1610.1'}], 'event_type': 'price_change', 'hash': '852b9decb09411577e9932712561e31f937379b3', 'market': '0x7aa4a910b31b2c4ddb09d1e3408e52aa8e09a14402f376070a44b1b85cb36d13', 'timestamp': '1733332981394'}
{'asset_id': '114416409796971863099144323163249651172534872992222856507897414949637892047507', 'changes': [{'price': '0.48', 'side': 'BUY', 'size': '3842.18'}, {'price': '0.57', 'side': 'SELL', 'size': '1610.1'}], 'event_type': 'price_change', 'hash': '852b9decb09411577e9932712561e31f937379b3', 'market': '0x7aa4a910b31b2c4ddb09d1e3408e52aa8e09a14402f376070a44b1b85cb36d13', 'timestamp': '1733332981394'}
{'asset_id': '114416409796971863099144323163249651172534872992222856507897414949637892047507', 'changes': [{'price': '0.47', 'side': 'BUY', 'size': '2797.23'}], 'event_type': 'price_change', 'hash': 'f66486bb1521e6f2eece6afa0fe436a491d54a69', 'market': '0x7aa4a910b31b2c4ddb09d1e3408e52aa8e09a14402f376070a44b1b85cb36d13', 'timestamp': '1733332983154'}
{'asset_id': '114416409796971863099144323163249651172534872992222856507897414949637892047507', 'changes': [{'price': '0.47', 'side': 'BUY', 'size': '2797.23'}], 'event_type': 'price_change', 'hash': 'f66486bb1521e6f2eece6afa0fe436a491d54a69', 'market': '0x7aa4a910b31b2c4ddb09d1e3408e52aa8e09a14402f376070a44b1b85cb36d13', 'timestamp': '1733332983154'}
{'asset_id': '114416409796971863099144323163249651172534872992222856507897414949637892047507', 'changes': [{'price': '0.5', 'side': 'BUY', 'size': '2315'}], 'event_type': 'price_change', 'hash': '769cf1a5c728c8b0cd275d1802be19eba2573aae', 'market': '0x7aa4a910b31b2c4ddb09d1e3408e52aa8e09a14402f376070a44b1b85cb36d13', 'timestamp': '1733332985367'}
{'asset_id': '114416409796971863099144323163249651172534872992222856507897414949637892047507', 'changes': [{'price': '0.5', 'side': 'BUY', 'size': '2315'}], 'event_type': 'price_change', 'hash': '769cf1a5c728c8b0cd275d1802be19eba2573aae', 'market': '0x7aa4a910b31b2c4ddb09d1e3408e52aa8e09a14402f376070a44b1b85cb36d13', 'timestamp': '1733332985367'}
{'asset_id': '114416409796971863099144323163249651172534872992222856507897414949637892047507', 'changes': [{'price': '0.5', 'side': 'BUY', 'size': '1115'}, {'price': '0.56', 'side': 'SELL', 'size': '1161.75'}], 'event_type': 'price_change', 'hash': '5e777c24dcfed18b298a7c93bea38983be4ce242', 'market': '0x7aa4a910b31b2c4ddb09d1e3408e52aa8e09a14402f376070a44b1b85cb36d13', 'timestamp': '1733332989706'}
{'asset_id': '114416409796971863099144323163249651172534872992222856507897414949637892047507', 'changes': [{'price': '0.5', 'side': 'BUY', 'size': '1115'}, {'price': '0.56', 'side': 'SELL', 'size': '1161.75'}], 'event_type': 'price_change', 'hash': '5e777c24dcfed18b298a7c93bea38983be4ce242', 'market': '0x7aa4a910b31b2c4ddb09d1e3408e52aa8e09a14402f376070a44b1b85cb36d13', 'timestamp': '1733332989706'}
{'asset_id': '114416409796971863099144323163249651172534872992222856507897414949637892047507', 'changes': [{'price': '0.55', 'side': 'SELL', 'size': '2914.23'}, {'price': '0.49', 'side': 'BUY', 'size': '1590'}], 'event_type': 'price_change', 'hash': 'e2e4ac6ee0a4147f6251f999046c007d1f99310e', 'market': '0x7aa4a910b31b2c4ddb09d1e3408e52aa8e09a14402f376070a44b1b85cb36d13', 'timestamp': '1733332990059'}
{'asset_id': '114416409796971863099144323163249651172534872992222856507897414949637892047507', 'changes': [{'price': '0.55', 'side': 'SELL', 'size': '2914.23'}, {'price': '0.49', 'side': 'BUY', 'size': '1590'}], 'event_type': 'price_change', 'hash': 'e2e4ac6ee0a4147f6251f999046c007d1f99310e', 'market': '0x7aa4a910b31b2c4ddb09d1e3408e52aa8e09a14402f376070a44b1b85cb36d13', 'timestamp': '1733332990059'}
{'asset_id': '114416409796971863099144323163249651172534872992222856507897414949637892047507', 'changes': [{'price': '0.5', 'side': 'BUY', 'size': '1215'}], 'event_type': 'price_change', 'hash': 'f85dbfa9404c619358601038dda4d2e5edf4c5f1', 'market': '0x7aa4a910b31b2c4ddb09d1e3408e52aa8e09a14402f376070a44b1b85cb36d13', 'timestamp': '1733332992465'}
{'asset_id': '114416409796971863099144323163249651172534872992222856507897414949637892047507', 'changes': [{'price': '0.5', 'side': 'BUY', 'size': '1215'}], 'event_type': 'price_change', 'hash': 'f85dbfa9404c619358601038dda4d2e5edf4c5f1', 'market': '0x7aa4a910b31b2c4ddb09d1e3408e52aa8e09a14402f376070a44b1b85cb36d13', 'timestamp': '1733332992465'}
{'asset_id': '114416409796971863099144323163249651172534872992222856507897414949637892047507', 'changes': [{'price': '0.46', 'side': 'BUY', 'size': '0'}, {'price': '0.55', 'side': 'SELL', 'size': '2414.23'}, {'price': '0.5', 'side': 'BUY', 'size': '215'}], 'event_type': 'price_change', 'hash': 'c93ebfabe14743d68dc855eb02d01752b73e072c', 'market': '0x7aa4a910b31b2c4ddb09d1e3408e52aa8e09a14402f376070a44b1b85cb36d13', 'timestamp': '1733332992717'}
{'asset_id': '114416409796971863099144323163249651172534872992222856507897414949637892047507', 'changes': [{'price': '0.46', 'side': 'BUY', 'size': '0'}, {'price': '0.55', 'side': 'SELL', 'size': '2414.23'}, {'price': '0.5', 'side': 'BUY', 'size': '215'}], 'event_type': 'price_change', 'hash': 'c93ebfabe14743d68dc855eb02d01752b73e072c', 'market': '0x7aa4a910b31b2c4ddb09d1e3408e52aa8e09a14402f376070a44b1b85cb36d13', 'timestamp': '1733332992717'}
{'asset_id': '114416409796971863099144323163249651172534872992222856507897414949637892047507', 'changes': [{'price': '0.45', 'side': 'BUY', 'size': '978'}], 'event_type': 'price_change', 'hash': '478c00bd62099a9b5f718f3dec3ed3d6c6b81df5', 'market': '0x7aa4a910b31b2c4ddb09d1e3408e52aa8e09a14402f376070a44b1b85cb36d13', 'timestamp': '1733332993859'}
{'asset_id': '114416409796971863099144323163249651172534872992222856507897414949637892047507', 'changes': [{'price': '0.45', 'side': 'BUY', 'size': '978'}], 'event_type': 'price_change', 'hash': '478c00bd62099a9b5f718f3dec3ed3d6c6b81df5', 'market': '0x7aa4a910b31b2c4ddb09d1e3408e52aa8e09a14402f376070a44b1b85cb36d13', 'timestamp': '1733332993859'}
{'asset_id': '114416409796971863099144323163249651172534872992222856507897414949637892047507', 'changes': [{'price': '0.54', 'side': 'SELL', 'size': '500'}], 'event_type': 'price_change', 'hash': 'be17229903e19f12fdc21e82d705ae9aa8bc8746', 'market': '0x7aa4a910b31b2c4ddb09d1e3408e52aa8e09a14402f376070a44b1b85cb36d13', 'timestamp': '1733332994227'}
{'asset_id': '114416409796971863099144323163249651172534872992222856507897414949637892047507', 'changes': [{'price': '0.54', 'side': 'SELL', 'size': '500'}], 'event_type': 'price_change', 'hash': 'be17229903e19f12fdc21e82d705ae9aa8bc8746', 'market': '0x7aa4a910b31b2c4ddb09d1e3408e52aa8e09a14402f376070a44b1b85cb36d13', 'timestamp': '1733332994227'}
{'asset_id': '114416409796971863099144323163249651172534872992222856507897414949637892047507', 'changes': [{'price': '0.49', 'side': 'BUY', 'size': '2590'}], 'event_type': 'price_change', 'hash': 'b3e3e19159c33222fa19d30c62da985c3d94b566', 'market': '0x7aa4a910b31b2c4ddb09d1e3408e52aa8e09a14402f376070a44b1b85cb36d13', 'timestamp': '1733332994592'}
{'asset_id': '114416409796971863099144323163249651172534872992222856507897414949637892047507', 'changes': [{'price': '0.49', 'side': 'BUY', 'size': '2590'}], 'event_type': 'price_change', 'hash': 'b3e3e19159c33222fa19d30c62da985c3d94b566', 'market': '0x7aa4a910b31b2c4ddb09d1e3408e52aa8e09a14402f376070a44b1b85cb36d13', 'timestamp': '1733332994592'}
{'asset_id': '114416409796971863099144323163249651172534872992222856507897414949637892047507', 'changes': [{'price': '0.55', 'side': 'SELL', 'size': '2389.22'}], 'event_type': 'price_change', 'hash': '94a6155850bcd9b41cba5a9c4798414eb309df33', 'market': '0x7aa4a910b31b2c4ddb09d1e3408e52aa8e09a14402f376070a44b1b85cb36d13', 'timestamp': '1733332995083'}
{'asset_id': '114416409796971863099144323163249651172534872992222856507897414949637892047507', 'changes': [{'price': '0.55', 'side': 'SELL', 'size': '2389.22'}], 'event_type': 'price_change', 'hash': '94a6155850bcd9b41cba5a9c4798414eb309df33', 'market': '0x7aa4a910b31b2c4ddb09d1e3408e52aa8e09a14402f376070a44b1b85cb36d13', 'timestamp': '1733332995083'}
{'asset_id': '114416409796971863099144323163249651172534872992222856507897414949637892047507', 'changes': [{'price': '0.54', 'side': 'SELL', 'size': '525.01'}], 'event_type': 'price_change', 'hash': 'f7b4ea5c0c0710ace407e75e9f85b51aab6d7b45', 'market': '0x7aa4a910b31b2c4ddb09d1e3408e52aa8e09a14402f376070a44b1b85cb36d13', 'timestamp': '1733332995712'}
{'asset_id': '114416409796971863099144323163249651172534872992222856507897414949637892047507', 'changes': [{'price': '0.54', 'side': 'SELL', 'size': '525.01'}], 'event_type': 'price_change', 'hash': 'f7b4ea5c0c0710ace407e75e9f85b51aab6d7b45', 'market': '0x7aa4a910b31b2c4ddb09d1e3408e52aa8e09a14402f376070a44b1b85cb36d13', 'timestamp': '1733332995712'}
{'asset_id': '114416409796971863099144323163249651172534872992222856507897414949637892047507', 'changes': [{'price': '0.58', 'side': 'SELL', 'size': '2188.1'}, {'price': '0.49', 'side': 'BUY', 'size': '2340'}], 'event_type': 'price_change', 'hash': '1ebf4fe6c411a2a500d7bcfd4e0d8741f3a7e4e6', 'market': '0x7aa4a910b31b2c4ddb09d1e3408e52aa8e09a14402f376070a44b1b85cb36d13', 'timestamp': '1733332997331'}
{'asset_id': '114416409796971863099144323163249651172534872992222856507897414949637892047507', 'changes': [{'price': '0.58', 'side': 'SELL', 'size': '2188.1'}, {'price': '0.49', 'side': 'BUY', 'size': '2340'}], 'event_type': 'price_change', 'hash': '1ebf4fe6c411a2a500d7bcfd4e0d8741f3a7e4e6', 'market': '0x7aa4a910b31b2c4ddb09d1e3408e52aa8e09a14402f376070a44b1b85cb36d13', 'timestamp': '1733332997331'}
{'asset_id': '114416409796971863099144323163249651172534872992222856507897414949637892047507', 'changes': [{'price': '0.49', 'side': 'BUY', 'size': '2560'}, {'price': '0.55', 'side': 'SELL', 'size': '2289.22'}], 'event_type': 'price_change', 'hash': '615670a4bc2c1fa88626224063ceb4bd3ec19d85', 'market': '0x7aa4a910b31b2c4ddb09d1e3408e52aa8e09a14402f376070a44b1b85cb36d13', 'timestamp': '1733332997611'}
{'asset_id': '114416409796971863099144323163249651172534872992222856507897414949637892047507', 'changes': [{'price': '0.49', 'side': 'BUY', 'size': '2560'}, {'price': '0.55', 'side': 'SELL', 'size': '2289.22'}], 'event_type': 'price_change', 'hash': '615670a4bc2c1fa88626224063ceb4bd3ec19d85', 'market': '0x7aa4a910b31b2c4ddb09d1e3408e52aa8e09a14402f376070a44b1b85cb36d13', 'timestamp': '1733332997611'}
{'asset_id': '114416409796971863099144323163249651172534872992222856507897414949637892047507', 'changes': [{'price': '0.57', 'side': 'SELL', 'size': '1850.1'}], 'event_type': 'price_change', 'hash': '615670a4bc2c1fa88626224063ceb4bd3ec19d85', 'market': '0x7aa4a910b31b2c4ddb09d1e3408e52aa8e09a14402f376070a44b1b85cb36d13', 'timestamp': '1733332997614'}
{'asset_id': '114416409796971863099144323163249651172534872992222856507897414949637892047507', 'changes': [{'price': '0.57', 'side': 'SELL', 'size': '1850.1'}], 'event_type': 'price_change', 'hash': '615670a4bc2c1fa88626224063ceb4bd3ec19d85', 'market': '0x7aa4a910b31b2c4ddb09d1e3408e52aa8e09a14402f376070a44b1b85cb36d13', 'timestamp': '1733332997614'}
{'asset_id': '114416409796971863099144323163249651172534872992222856507897414949637892047507', 'changes': [{'price': '0.54', 'side': 'SELL', 'size': '625.01'}], 'event_type': 'price_change', 'hash': 'b69b9fd1ea1d8350aa0da59d4e993ba49b1ffcb1', 'market': '0x7aa4a910b31b2c4ddb09d1e3408e52aa8e09a14402f376070a44b1b85cb36d13', 'timestamp': '1733332998133'}
{'asset_id': '114416409796971863099144323163249651172534872992222856507897414949637892047507', 'changes': [{'price': '0.54', 'side': 'SELL', 'size': '625.01'}], 'event_type': 'price_change', 'hash': 'b69b9fd1ea1d8350aa0da59d4e993ba49b1ffcb1', 'market': '0x7aa4a910b31b2c4ddb09d1e3408e52aa8e09a14402f376070a44b1b85cb36d13', 'timestamp': '1733332998133'}
{'asset_id': '114416409796971863099144323163249651172534872992222856507897414949637892047507', 'changes': [{'price': '0.45', 'side': 'BUY', 'size': '478'}, {'price': '0.54', 'side': 'SELL', 'size': '125.01'}, {'price': '0.49', 'side': 'BUY', 'size': '1560'}], 'event_type': 'price_change', 'hash': '22d869b0f86341dc31e36a27b4cfb6392d0fd951', 'market': '0x7aa4a910b31b2c4ddb09d1e3408e52aa8e09a14402f376070a44b1b85cb36d13', 'timestamp': '1733333002995'}
{'asset_id': '114416409796971863099144323163249651172534872992222856507897414949637892047507', 'changes': [{'price': '0.45', 'side': 'BUY', 'size': '478'}, {'price': '0.54', 'side': 'SELL', 'size': '125.01'}, {'price': '0.49', 'side': 'BUY', 'size': '1560'}], 'event_type': 'price_change', 'hash': '22d869b0f86341dc31e36a27b4cfb6392d0fd951', 'market': '0x7aa4a910b31b2c4ddb09d1e3408e52aa8e09a14402f376070a44b1b85cb36d13', 'timestamp': '1733333002995'}
{'asset_id': '114416409796971863099144323163249651172534872992222856507897414949637892047507', 'changes': [{'price': '0.46', 'side': 'BUY', 'size': '500'}], 'event_type': 'price_change', 'hash': 'ee9b2f7afdb684b7cdd1c2b4d26cf595cf62e906', 'market': '0x7aa4a910b31b2c4ddb09d1e3408e52aa8e09a14402f376070a44b1b85cb36d13', 'timestamp': '1733333004028'}
{'asset_id': '114416409796971863099144323163249651172534872992222856507897414949637892047507', 'changes': [{'price': '0.46', 'side': 'BUY', 'size': '500'}], 'event_type': 'price_change', 'hash': 'ee9b2f7afdb684b7cdd1c2b4d26cf595cf62e906', 'market': '0x7aa4a910b31b2c4ddb09d1e3408e52aa8e09a14402f376070a44b1b85cb36d13', 'timestamp': '1733333004028'}
{'asset_id': '114416409796971863099144323163249651172534872992222856507897414949637892047507', 'changes': [{'price': '0.55', 'side': 'SELL', 'size': '2789.22'}], 'event_type': 'price_change', 'hash': '1e83caaf3424017ec4646d1ecb1a1228e87ab3ff', 'market': '0x7aa4a910b31b2c4ddb09d1e3408e52aa8e09a14402f376070a44b1b85cb36d13', 'timestamp': '1733333004398'}
{'asset_id': '114416409796971863099144323163249651172534872992222856507897414949637892047507', 'changes': [{'price': '0.55', 'side': 'SELL', 'size': '2789.22'}], 'event_type': 'price_change', 'hash': '1e83caaf3424017ec4646d1ecb1a1228e87ab3ff', 'market': '0x7aa4a910b31b2c4ddb09d1e3408e52aa8e09a14402f376070a44b1b85cb36d13', 'timestamp': '1733333004398'}
{'asset_id': '114416409796971863099144323163249651172534872992222856507897414949637892047507', 'changes': [{'price': '0.54', 'side': 'SELL', 'size': '25.01'}], 'event_type': 'price_change', 'hash': '71dc378316d7f7ff3e5933ce5ac070cd723331d3', 'market': '0x7aa4a910b31b2c4ddb09d1e3408e52aa8e09a14402f376070a44b1b85cb36d13', 'timestamp': '1733333004496'}
{'asset_id': '114416409796971863099144323163249651172534872992222856507897414949637892047507', 'changes': [{'price': '0.54', 'side': 'SELL', 'size': '25.01'}], 'event_type': 'price_change', 'hash': '71dc378316d7f7ff3e5933ce5ac070cd723331d3', 'market': '0x7aa4a910b31b2c4ddb09d1e3408e52aa8e09a14402f376070a44b1b85cb36d13', 'timestamp': '1733333004496'}
{'asset_id': '114416409796971863099144323163249651172534872992222856507897414949637892047507', 'changes': [{'price': '0.55', 'side': 'SELL', 'size': '2889.22'}], 'event_type': 'price_change', 'hash': '2dcf9c630c5088465519942009e6d2879c07729a', 'market': '0x7aa4a910b31b2c4ddb09d1e3408e52aa8e09a14402f376070a44b1b85cb36d13', 'timestamp': '1733333004667'}
{'asset_id': '114416409796971863099144323163249651172534872992222856507897414949637892047507', 'changes': [{'price': '0.55', 'side': 'SELL', 'size': '2889.22'}], 'event_type': 'price_change', 'hash': '2dcf9c630c5088465519942009e6d2879c07729a', 'market': '0x7aa4a910b31b2c4ddb09d1e3408e52aa8e09a14402f376070a44b1b85cb36d13', 'timestamp': '1733333004667'}
{'asset_id': '114416409796971863099144323163249651172534872992222856507897414949637892047507', 'changes': [{'price': '0.5', 'side': 'BUY', 'size': '1215'}], 'event_type': 'price_change', 'hash': 'e0b501be750d452d189f5b8eeb2c269514d5dd2f', 'market': '0x7aa4a910b31b2c4ddb09d1e3408e52aa8e09a14402f376070a44b1b85cb36d13', 'timestamp': '1733333004791'}
{'asset_id': '114416409796971863099144323163249651172534872992222856507897414949637892047507', 'changes': [{'price': '0.5', 'side': 'BUY', 'size': '1215'}], 'event_type': 'price_change', 'hash': 'e0b501be750d452d189f5b8eeb2c269514d5dd2f', 'market': '0x7aa4a910b31b2c4ddb09d1e3408e52aa8e09a14402f376070a44b1b85cb36d13', 'timestamp': '1733333004791'}
{'asset_id': '114416409796971863099144323163249651172534872992222856507897414949637892047507', 'changes': [{'price': '0.48', 'side': 'BUY', 'size': '1842.18'}], 'event_type': 'price_change', 'hash': 'b6f278a4e17ee0ac3ed5a5d82c2471fd8198eaa3', 'market': '0x7aa4a910b31b2c4ddb09d1e3408e52aa8e09a14402f376070a44b1b85cb36d13', 'timestamp': '1733333006011'}
{'asset_id': '114416409796971863099144323163249651172534872992222856507897414949637892047507', 'changes': [{'price': '0.48', 'side': 'BUY', 'size': '1842.18'}], 'event_type': 'price_change', 'hash': 'b6f278a4e17ee0ac3ed5a5d82c2471fd8198eaa3', 'market': '0x7aa4a910b31b2c4ddb09d1e3408e52aa8e09a14402f376070a44b1b85cb36d13', 'timestamp': '1733333006011'}
{'asset_id': '114416409796971863099144323163249651172534872992222856507897414949637892047507', 'changes': [{'price': '0.54', 'side': 'SELL', 'size': '0'}], 'event_type': 'price_change', 'hash': 'c6d41df52e40fa5c74cd05addb49388843f87d52', 'market': '0x7aa4a910b31b2c4ddb09d1e3408e52aa8e09a14402f376070a44b1b85cb36d13', 'timestamp': '1733333006579'}
{'asset_id': '114416409796971863099144323163249651172534872992222856507897414949637892047507', 'changes': [{'price': '0.54', 'side': 'SELL', 'size': '0'}], 'event_type': 'price_change', 'hash': 'c6d41df52e40fa5c74cd05addb49388843f87d52', 'market': '0x7aa4a910b31b2c4ddb09d1e3408e52aa8e09a14402f376070a44b1b85cb36d13', 'timestamp': '1733333006579'}
{'asset_id': '114416409796971863099144323163249651172534872992222856507897414949637892047507', 'changes': [{'price': '0.55', 'side': 'SELL', 'size': '2914.23'}], 'event_type': 'price_change', 'hash': 'ee8aeef61882b737c541c5e51feba09bc8b87959', 'market': '0x7aa4a910b31b2c4ddb09d1e3408e52aa8e09a14402f376070a44b1b85cb36d13', 'timestamp': '1733333006724'}
{'asset_id': '114416409796971863099144323163249651172534872992222856507897414949637892047507', 'changes': [{'price': '0.55', 'side': 'SELL', 'size': '2914.23'}], 'event_type': 'price_change', 'hash': 'ee8aeef61882b737c541c5e51feba09bc8b87959', 'market': '0x7aa4a910b31b2c4ddb09d1e3408e52aa8e09a14402f376070a44b1b85cb36d13', 'timestamp': '1733333006724'}
{'asset_id': '114416409796971863099144323163249651172534872992222856507897414949637892047507', 'changes': [{'price': '0.57', 'side': 'SELL', 'size': '1610.1'}, {'price': '0.49', 'side': 'BUY', 'size': '1340'}], 'event_type': 'price_change', 'hash': 'a41d3c4290b083010931be8065b1e573309680ff', 'market': '0x7aa4a910b31b2c4ddb09d1e3408e52aa8e09a14402f376070a44b1b85cb36d13', 'timestamp': '1733333018949'}
{'asset_id': '114416409796971863099144323163249651172534872992222856507897414949637892047507', 'changes': [{'price': '0.57', 'side': 'SELL', 'size': '1610.1'}, {'price': '0.49', 'side': 'BUY', 'size': '1340'}], 'event_type': 'price_change', 'hash': 'a41d3c4290b083010931be8065b1e573309680ff', 'market': '0x7aa4a910b31b2c4ddb09d1e3408e52aa8e09a14402f376070a44b1b85cb36d13', 'timestamp': '1733333018949'}
{'asset_id': '114416409796971863099144323163249651172534872992222856507897414949637892047507', 'changes': [{'price': '0.58', 'side': 'SELL', 'size': '2458.1'}, {'price': '0.49', 'side': 'BUY', 'size': '1590'}], 'event_type': 'price_change', 'hash': 'ac5cc81a01d7776d2ae83801eee7b46e7dec6d2a', 'market': '0x7aa4a910b31b2c4ddb09d1e3408e52aa8e09a14402f376070a44b1b85cb36d13', 'timestamp': '1733333019313'}
{'asset_id': '114416409796971863099144323163249651172534872992222856507897414949637892047507', 'changes': [{'price': '0.58', 'side': 'SELL', 'size': '2458.1'}, {'price': '0.49', 'side': 'BUY', 'size': '1590'}], 'event_type': 'price_change', 'hash': 'ac5cc81a01d7776d2ae83801eee7b46e7dec6d2a', 'market': '0x7aa4a910b31b2c4ddb09d1e3408e52aa8e09a14402f376070a44b1b85cb36d13', 'timestamp': '1733333019313'}
{'asset_id': '114416409796971863099144323163249651172534872992222856507897414949637892047507', 'changes': [{'price': '0.47', 'side': 'BUY', 'size': '4797.23'}], 'event_type': 'price_change', 'hash': 'a4ccde502dce24791d9d1c1ded0d83452e943354', 'market': '0x7aa4a910b31b2c4ddb09d1e3408e52aa8e09a14402f376070a44b1b85cb36d13', 'timestamp': '1733333019616'}
{'asset_id': '114416409796971863099144323163249651172534872992222856507897414949637892047507', 'changes': [{'price': '0.47', 'side': 'BUY', 'size': '4797.23'}], 'event_type': 'price_change', 'hash': 'a4ccde502dce24791d9d1c1ded0d83452e943354', 'market': '0x7aa4a910b31b2c4ddb09d1e3408e52aa8e09a14402f376070a44b1b85cb36d13', 'timestamp': '1733333019616'}
{'asset_id': '114416409796971863099144323163249651172534872992222856507897414949637892047507', 'changes': [{'price': '0.5', 'side': 'BUY', 'size': '1115'}], 'event_type': 'price_change', 'hash': 'd5093d15024624639800de20c96925b4a0e5e6a0', 'market': '0x7aa4a910b31b2c4ddb09d1e3408e52aa8e09a14402f376070a44b1b85cb36d13', 'timestamp': '1733333022026'}
{'asset_id': '114416409796971863099144323163249651172534872992222856507897414949637892047507', 'changes': [{'price': '0.5', 'side': 'BUY', 'size': '1115'}], 'event_type': 'price_change', 'hash': 'd5093d15024624639800de20c96925b4a0e5e6a0', 'market': '0x7aa4a910b31b2c4ddb09d1e3408e52aa8e09a14402f376070a44b1b85cb36d13', 'timestamp': '1733333022026'}
{'asset_id': '114416409796971863099144323163249651172534872992222856507897414949637892047507', 'changes': [{'price': '0.5', 'side': 'BUY', 'size': '1215'}], 'event_type': 'price_change', 'hash': 'a8afcfb9ba57d2e52b4dd0940b71d61fc084adaf', 'market': '0x7aa4a910b31b2c4ddb09d1e3408e52aa8e09a14402f376070a44b1b85cb36d13', 'timestamp': '1733333023958'}
{'asset_id': '114416409796971863099144323163249651172534872992222856507897414949637892047507', 'changes': [{'price': '0.5', 'side': 'BUY', 'size': '1215'}], 'event_type': 'price_change', 'hash': 'a8afcfb9ba57d2e52b4dd0940b71d61fc084adaf', 'market': '0x7aa4a910b31b2c4ddb09d1e3408e52aa8e09a14402f376070a44b1b85cb36d13', 'timestamp': '1733333023958'}
{'asset_id': '114416409796971863099144323163249651172534872992222856507897414949637892047507', 'changes': [{'price': '0.5', 'side': 'BUY', 'size': '1115'}], 'event_type': 'price_change', 'hash': '3771e29a96a4677b851da3ae77c6a24819ecc8d4', 'market': '0x7aa4a910b31b2c4ddb09d1e3408e52aa8e09a14402f376070a44b1b85cb36d13', 'timestamp': '1733333028893'}
{'asset_id': '114416409796971863099144323163249651172534872992222856507897414949637892047507', 'changes': [{'price': '0.5', 'side': 'BUY', 'size': '1115'}], 'event_type': 'price_change', 'hash': '3771e29a96a4677b851da3ae77c6a24819ecc8d4', 'market': '0x7aa4a910b31b2c4ddb09d1e3408e52aa8e09a14402f376070a44b1b85cb36d13', 'timestamp': '1733333028893'}
{'asset_id': '114416409796971863099144323163249651172534872992222856507897414949637892047507', 'changes': [{'price': '0.59', 'side': 'SELL', 'size': '2510'}], 'event_type': 'price_change', 'hash': '1b4e7babc17025857a43cc7d4b107dd7a640cef1', 'market': '0x7aa4a910b31b2c4ddb09d1e3408e52aa8e09a14402f376070a44b1b85cb36d13', 'timestamp': '1733333034010'}
{'asset_id': '114416409796971863099144323163249651172534872992222856507897414949637892047507', 'changes': [{'price': '0.59', 'side': 'SELL', 'size': '2510'}], 'event_type': 'price_change', 'hash': '1b4e7babc17025857a43cc7d4b107dd7a640cef1', 'market': '0x7aa4a910b31b2c4ddb09d1e3408e52aa8e09a14402f376070a44b1b85cb36d13', 'timestamp': '1733333034010'}
{'asset_id': '114416409796971863099144323163249651172534872992222856507897414949637892047507', 'changes': [{'price': '0.6', 'side': 'SELL', 'size': '3467.85'}], 'event_type': 'price_change', 'hash': '26e1f0c9b9a786ff389209bdd176206f86141a1c', 'market': '0x7aa4a910b31b2c4ddb09d1e3408e52aa8e09a14402f376070a44b1b85cb36d13', 'timestamp': '1733333035256'}
{'asset_id': '114416409796971863099144323163249651172534872992222856507897414949637892047507', 'changes': [{'price': '0.6', 'side': 'SELL', 'size': '3467.85'}], 'event_type': 'price_change', 'hash': '26e1f0c9b9a786ff389209bdd176206f86141a1c', 'market': '0x7aa4a910b31b2c4ddb09d1e3408e52aa8e09a14402f376070a44b1b85cb36d13', 'timestamp': '1733333035256'}
{'asset_id': '114416409796971863099144323163249651172534872992222856507897414949637892047507', 'changes': [{'price': '0.5', 'side': 'BUY', 'size': '1215'}], 'event_type': 'price_change', 'hash': 'fe582f6905095d99bfc414908a42fed5c6f1fb11', 'market': '0x7aa4a910b31b2c4ddb09d1e3408e52aa8e09a14402f376070a44b1b85cb36d13', 'timestamp': '1733333042687'}
{'asset_id': '114416409796971863099144323163249651172534872992222856507897414949637892047507', 'changes': [{'price': '0.5', 'side': 'BUY', 'size': '1215'}], 'event_type': 'price_change', 'hash': 'fe582f6905095d99bfc414908a42fed5c6f1fb11', 'market': '0x7aa4a910b31b2c4ddb09d1e3408e52aa8e09a14402f376070a44b1b85cb36d13', 'timestamp': '1733333042687'}
{'asset_id': '114416409796971863099144323163249651172534872992222856507897414949637892047507', 'changes': [{'price': '0.5', 'side': 'BUY', 'size': '1115'}], 'event_type': 'price_change', 'hash': 'fd21a011b3f9ec866358ed2bc6d2db19da7d5c68', 'market': '0x7aa4a910b31b2c4ddb09d1e3408e52aa8e09a14402f376070a44b1b85cb36d13', 'timestamp': '1733333045786'}
{'asset_id': '114416409796971863099144323163249651172534872992222856507897414949637892047507', 'changes': [{'price': '0.5', 'side': 'BUY', 'size': '1115'}], 'event_type': 'price_change', 'hash': 'fd21a011b3f9ec866358ed2bc6d2db19da7d5c68', 'market': '0x7aa4a910b31b2c4ddb09d1e3408e52aa8e09a14402f376070a44b1b85cb36d13', 'timestamp': '1733333045786'}
{'asset_id': '114416409796971863099144323163249651172534872992222856507897414949637892047507', 'changes': [{'price': '0.5', 'side': 'BUY', 'size': '1215'}], 'event_type': 'price_change', 'hash': '1812be10479fd75ad25a0d316a28542fbace3d37', 'market': '0x7aa4a910b31b2c4ddb09d1e3408e52aa8e09a14402f376070a44b1b85cb36d13', 'timestamp': '1733333052357'}
{'asset_id': '114416409796971863099144323163249651172534872992222856507897414949637892047507', 'changes': [{'price': '0.5', 'side': 'BUY', 'size': '1215'}], 'event_type': 'price_change', 'hash': '1812be10479fd75ad25a0d316a28542fbace3d37', 'market': '0x7aa4a910b31b2c4ddb09d1e3408e52aa8e09a14402f376070a44b1b85cb36d13', 'timestamp': '1733333052357'}
{'asset_id': '114416409796971863099144323163249651172534872992222856507897414949637892047507', 'changes': [{'price': '0.5', 'side': 'BUY', 'size': '215'}, {'price': '0.55', 'side': 'SELL', 'size': '2414.23'}, {'price': '0.46', 'side': 'BUY', 'size': '0'}], 'event_type': 'price_change', 'hash': 'f3b06544f3c62a35d9689f026f84662ded6c8a3e', 'market': '0x7aa4a910b31b2c4ddb09d1e3408e52aa8e09a14402f376070a44b1b85cb36d13', 'timestamp': '1733333054517'}
{'asset_id': '114416409796971863099144323163249651172534872992222856507897414949637892047507', 'changes': [{'price': '0.5', 'side': 'BUY', 'size': '215'}, {'price': '0.55', 'side': 'SELL', 'size': '2414.23'}, {'price': '0.46', 'side': 'BUY', 'size': '0'}], 'event_type': 'price_change', 'hash': 'f3b06544f3c62a35d9689f026f84662ded6c8a3e', 'market': '0x7aa4a910b31b2c4ddb09d1e3408e52aa8e09a14402f376070a44b1b85cb36d13', 'timestamp': '1733333054517'}
{'asset_id': '114416409796971863099144323163249651172534872992222856507897414949637892047507', 'changes': [{'price': '0.45', 'side': 'BUY', 'size': '978'}], 'event_type': 'price_change', 'hash': '41be78c794ce8e5801b32ac66278d02b51a3ee1a', 'market': '0x7aa4a910b31b2c4ddb09d1e3408e52aa8e09a14402f376070a44b1b85cb36d13', 'timestamp': '1733333055557'}
{'asset_id': '114416409796971863099144323163249651172534872992222856507897414949637892047507', 'changes': [{'price': '0.45', 'side': 'BUY', 'size': '978'}], 'event_type': 'price_change', 'hash': '41be78c794ce8e5801b32ac66278d02b51a3ee1a', 'market': '0x7aa4a910b31b2c4ddb09d1e3408e52aa8e09a14402f376070a44b1b85cb36d13', 'timestamp': '1733333055557'}
{'asset_id': '114416409796971863099144323163249651172534872992222856507897414949637892047507', 'changes': [{'price': '0.54', 'side': 'SELL', 'size': '500'}], 'event_type': 'price_change', 'hash': '54a789f105924d33595038662d118469c4cdfb45', 'market': '0x7aa4a910b31b2c4ddb09d1e3408e52aa8e09a14402f376070a44b1b85cb36d13', 'timestamp': '1733333055932'}
{'asset_id': '114416409796971863099144323163249651172534872992222856507897414949637892047507', 'changes': [{'price': '0.54', 'side': 'SELL', 'size': '500'}], 'event_type': 'price_change', 'hash': '54a789f105924d33595038662d118469c4cdfb45', 'market': '0x7aa4a910b31b2c4ddb09d1e3408e52aa8e09a14402f376070a44b1b85cb36d13', 'timestamp': '1733333055932'}
{'asset_id': '114416409796971863099144323163249651172534872992222856507897414949637892047507', 'changes': [{'price': '0.5', 'side': 'BUY', 'size': '115'}, {'price': '0.49', 'side': 'BUY', 'size': '2590'}], 'event_type': 'price_change', 'hash': '8ee7e20176ecf10b92dad2c35a7f7eb384efc729', 'market': '0x7aa4a910b31b2c4ddb09d1e3408e52aa8e09a14402f376070a44b1b85cb36d13', 'timestamp': '1733333056473'}
{'asset_id': '114416409796971863099144323163249651172534872992222856507897414949637892047507', 'changes': [{'price': '0.5', 'side': 'BUY', 'size': '115'}, {'price': '0.49', 'side': 'BUY', 'size': '2590'}], 'event_type': 'price_change', 'hash': '8ee7e20176ecf10b92dad2c35a7f7eb384efc729', 'market': '0x7aa4a910b31b2c4ddb09d1e3408e52aa8e09a14402f376070a44b1b85cb36d13', 'timestamp': '1733333056473'}
{'asset_id': '114416409796971863099144323163249651172534872992222856507897414949637892047507', 'changes': [{'price': '0.55', 'side': 'SELL', 'size': '2389.22'}], 'event_type': 'price_change', 'hash': 'bb9f018a324deb07a78eaeb311fc38c1eab6686e', 'market': '0x7aa4a910b31b2c4ddb09d1e3408e52aa8e09a14402f376070a44b1b85cb36d13', 'timestamp': '1733333056830'}
{'asset_id': '114416409796971863099144323163249651172534872992222856507897414949637892047507', 'changes': [{'price': '0.55', 'side': 'SELL', 'size': '2389.22'}], 'event_type': 'price_change', 'hash': 'bb9f018a324deb07a78eaeb311fc38c1eab6686e', 'market': '0x7aa4a910b31b2c4ddb09d1e3408e52aa8e09a14402f376070a44b1b85cb36d13', 'timestamp': '1733333056830'}
{'asset_id': '114416409796971863099144323163249651172534872992222856507897414949637892047507', 'changes': [{'price': '0.54', 'side': 'SELL', 'size': '525.01'}], 'event_type': 'price_change', 'hash': '2b40d60d6f77fb513cb913e83b828748727e6f27', 'market': '0x7aa4a910b31b2c4ddb09d1e3408e52aa8e09a14402f376070a44b1b85cb36d13', 'timestamp': '1733333057040'}
{'asset_id': '114416409796971863099144323163249651172534872992222856507897414949637892047507', 'changes': [{'price': '0.54', 'side': 'SELL', 'size': '525.01'}], 'event_type': 'price_change', 'hash': '2b40d60d6f77fb513cb913e83b828748727e6f27', 'market': '0x7aa4a910b31b2c4ddb09d1e3408e52aa8e09a14402f376070a44b1b85cb36d13', 'timestamp': '1733333057040'}
{'asset_id': '114416409796971863099144323163249651172534872992222856507897414949637892047507', 'changes': [{'price': '0.51', 'side': 'BUY', 'size': '1186.18'}], 'event_type': 'price_change', 'hash': 'c25a94539ba64f61283689a70f134852c8361a85', 'market': '0x7aa4a910b31b2c4ddb09d1e3408e52aa8e09a14402f376070a44b1b85cb36d13', 'timestamp': '1733333057288'}
{'asset_id': '114416409796971863099144323163249651172534872992222856507897414949637892047507', 'changes': [{'price': '0.51', 'side': 'BUY', 'size': '1186.18'}], 'event_type': 'price_change', 'hash': 'c25a94539ba64f61283689a70f134852c8361a85', 'market': '0x7aa4a910b31b2c4ddb09d1e3408e52aa8e09a14402f376070a44b1b85cb36d13', 'timestamp': '1733333057288'}
{'asset_id': '114416409796971863099144323163249651172534872992222856507897414949637892047507', 'changes': [{'price': '0.51', 'side': 'BUY', 'size': '1086.18'}], 'event_type': 'price_change', 'hash': '433804122a8a8fd7602de6cf06a26eccde680f02', 'market': '0x7aa4a910b31b2c4ddb09d1e3408e52aa8e09a14402f376070a44b1b85cb36d13', 'timestamp': '1733333058020'}
{'asset_id': '114416409796971863099144323163249651172534872992222856507897414949637892047507', 'changes': [{'price': '0.51', 'side': 'BUY', 'size': '1086.18'}], 'event_type': 'price_change', 'hash': '433804122a8a8fd7602de6cf06a26eccde680f02', 'market': '0x7aa4a910b31b2c4ddb09d1e3408e52aa8e09a14402f376070a44b1b85cb36d13', 'timestamp': '1733333058020'}
{'asset_id': '114416409796971863099144323163249651172534872992222856507897414949637892047507', 'changes': [{'price': '0.5', 'side': 'BUY', 'size': '215'}], 'event_type': 'price_change', 'hash': '87a44c6afedded30c80978a595cc9ab57ffa6c0c', 'market': '0x7aa4a910b31b2c4ddb09d1e3408e52aa8e09a14402f376070a44b1b85cb36d13', 'timestamp': '1733333058903'}
{'asset_id': '114416409796971863099144323163249651172534872992222856507897414949637892047507', 'changes': [{'price': '0.5', 'side': 'BUY', 'size': '215'}], 'event_type': 'price_change', 'hash': '87a44c6afedded30c80978a595cc9ab57ffa6c0c', 'market': '0x7aa4a910b31b2c4ddb09d1e3408e52aa8e09a14402f376070a44b1b85cb36d13', 'timestamp': '1733333058903'}
{'asset_id': '114416409796971863099144323163249651172534872992222856507897414949637892047507', 'changes': [{'price': '0.55', 'side': 'SELL', 'size': '2289.22'}], 'event_type': 'price_change', 'hash': '4a8af6438154cde1b202d81434763efee609c138', 'market': '0x7aa4a910b31b2c4ddb09d1e3408e52aa8e09a14402f376070a44b1b85cb36d13', 'timestamp': '1733333059018'}
{'asset_id': '114416409796971863099144323163249651172534872992222856507897414949637892047507', 'changes': [{'price': '0.55', 'side': 'SELL', 'size': '2289.22'}], 'event_type': 'price_change', 'hash': '4a8af6438154cde1b202d81434763efee609c138', 'market': '0x7aa4a910b31b2c4ddb09d1e3408e52aa8e09a14402f376070a44b1b85cb36d13', 'timestamp': '1733333059018'}
{'asset_id': '114416409796971863099144323163249651172534872992222856507897414949637892047507', 'changes': [{'price': '0.54', 'side': 'SELL', 'size': '625.01'}], 'event_type': 'price_change', 'hash': 'b263ecab6c641f93a8abebde024b795c25b8034d', 'market': '0x7aa4a910b31b2c4ddb09d1e3408e52aa8e09a14402f376070a44b1b85cb36d13', 'timestamp': '1733333059189'}
{'asset_id': '114416409796971863099144323163249651172534872992222856507897414949637892047507', 'changes': [{'price': '0.54', 'side': 'SELL', 'size': '625.01'}], 'event_type': 'price_change', 'hash': 'b263ecab6c641f93a8abebde024b795c25b8034d', 'market': '0x7aa4a910b31b2c4ddb09d1e3408e52aa8e09a14402f376070a44b1b85cb36d13', 'timestamp': '1733333059189'}
{'asset_id': '114416409796971863099144323163249651172534872992222856507897414949637892047507', 'changes': [{'price': '0.49', 'side': 'BUY', 'size': '2340'}, {'price': '0.58', 'side': 'SELL', 'size': '2188.1'}], 'event_type': 'price_change', 'hash': '5ee81c60f4e63da7dbe2fe7ec5b4118b651e7ba9', 'market': '0x7aa4a910b31b2c4ddb09d1e3408e52aa8e09a14402f376070a44b1b85cb36d13', 'timestamp': '1733333066497'}
{'asset_id': '114416409796971863099144323163249651172534872992222856507897414949637892047507', 'changes': [{'price': '0.49', 'side': 'BUY', 'size': '2340'}, {'price': '0.58', 'side': 'SELL', 'size': '2188.1'}], 'event_type': 'price_change', 'hash': '5ee81c60f4e63da7dbe2fe7ec5b4118b651e7ba9', 'market': '0x7aa4a910b31b2c4ddb09d1e3408e52aa8e09a14402f376070a44b1b85cb36d13', 'timestamp': '1733333066497'}
{'asset_id': '114416409796971863099144323163249651172534872992222856507897414949637892047507', 'changes': [{'price': '0.57', 'side': 'SELL', 'size': '1850.1'}, {'price': '0.49', 'side': 'BUY', 'size': '2560'}], 'event_type': 'price_change', 'hash': '13d07f29c7686af0054063ee3cc665cd553c5069', 'market': '0x7aa4a910b31b2c4ddb09d1e3408e52aa8e09a14402f376070a44b1b85cb36d13', 'timestamp': '1733333066779'}
{'asset_id': '114416409796971863099144323163249651172534872992222856507897414949637892047507', 'changes': [{'price': '0.57', 'side': 'SELL', 'size': '1850.1'}, {'price': '0.49', 'side': 'BUY', 'size': '2560'}], 'event_type': 'price_change', 'hash': '13d07f29c7686af0054063ee3cc665cd553c5069', 'market': '0x7aa4a910b31b2c4ddb09d1e3408e52aa8e09a14402f376070a44b1b85cb36d13', 'timestamp': '1733333066779'}
{'asset_id': '114416409796971863099144323163249651172534872992222856507897414949637892047507', 'changes': [{'price': '0.54', 'side': 'SELL', 'size': '125.01'}, {'price': '0.49', 'side': 'BUY', 'size': '1560'}], 'event_type': 'price_change', 'hash': 'f950d74f70750d115d1604328b5f4457e6077e94', 'market': '0x7aa4a910b31b2c4ddb09d1e3408e52aa8e09a14402f376070a44b1b85cb36d13', 'timestamp': '1733333075175'}
{'asset_id': '114416409796971863099144323163249651172534872992222856507897414949637892047507', 'changes': [{'price': '0.54', 'side': 'SELL', 'size': '125.01'}, {'price': '0.49', 'side': 'BUY', 'size': '1560'}], 'event_type': 'price_change', 'hash': 'f950d74f70750d115d1604328b5f4457e6077e94', 'market': '0x7aa4a910b31b2c4ddb09d1e3408e52aa8e09a14402f376070a44b1b85cb36d13', 'timestamp': '1733333075175'}
{'asset_id': '114416409796971863099144323163249651172534872992222856507897414949637892047507', 'changes': [{'price': '0.45', 'side': 'BUY', 'size': '478'}], 'event_type': 'price_change', 'hash': '9b2c974313d135516d0fcbc476319c05d13233c7', 'market': '0x7aa4a910b31b2c4ddb09d1e3408e52aa8e09a14402f376070a44b1b85cb36d13', 'timestamp': '1733333075184'}
{'asset_id': '114416409796971863099144323163249651172534872992222856507897414949637892047507', 'changes': [{'price': '0.45', 'side': 'BUY', 'size': '478'}], 'event_type': 'price_change', 'hash': '9b2c974313d135516d0fcbc476319c05d13233c7', 'market': '0x7aa4a910b31b2c4ddb09d1e3408e52aa8e09a14402f376070a44b1b85cb36d13', 'timestamp': '1733333075184'}
{'asset_id': '114416409796971863099144323163249651172534872992222856507897414949637892047507', 'changes': [{'price': '0.46', 'side': 'BUY', 'size': '500'}], 'event_type': 'price_change', 'hash': '1ebe313230aab2dc8a9a43e15455e9f2c193b501', 'market': '0x7aa4a910b31b2c4ddb09d1e3408e52aa8e09a14402f376070a44b1b85cb36d13', 'timestamp': '1733333076227'}
{'asset_id': '114416409796971863099144323163249651172534872992222856507897414949637892047507', 'changes': [{'price': '0.46', 'side': 'BUY', 'size': '500'}], 'event_type': 'price_change', 'hash': '1ebe313230aab2dc8a9a43e15455e9f2c193b501', 'market': '0x7aa4a910b31b2c4ddb09d1e3408e52aa8e09a14402f376070a44b1b85cb36d13', 'timestamp': '1733333076227'}
{'asset_id': '114416409796971863099144323163249651172534872992222856507897414949637892047507', 'changes': [{'price': '0.54', 'side': 'SELL', 'size': '100'}], 'event_type': 'price_change', 'hash': '1cfd8acd6b5517b2d83167b39150dc976912c87e', 'market': '0x7aa4a910b31b2c4ddb09d1e3408e52aa8e09a14402f376070a44b1b85cb36d13', 'timestamp': '1733333076399'}
{'asset_id': '114416409796971863099144323163249651172534872992222856507897414949637892047507', 'changes': [{'price': '0.54', 'side': 'SELL', 'size': '100'}], 'event_type': 'price_change', 'hash': '1cfd8acd6b5517b2d83167b39150dc976912c87e', 'market': '0x7aa4a910b31b2c4ddb09d1e3408e52aa8e09a14402f376070a44b1b85cb36d13', 'timestamp': '1733333076399'}
{'asset_id': '114416409796971863099144323163249651172534872992222856507897414949637892047507', 'changes': [{'price': '0.55', 'side': 'SELL', 'size': '2314.23'}], 'event_type': 'price_change', 'hash': '270918ed8b4e01efb426d51ac2f208eb91929884', 'market': '0x7aa4a910b31b2c4ddb09d1e3408e52aa8e09a14402f376070a44b1b85cb36d13', 'timestamp': '1733333076572'}
{'asset_id': '114416409796971863099144323163249651172534872992222856507897414949637892047507', 'changes': [{'price': '0.55', 'side': 'SELL', 'size': '2314.23'}], 'event_type': 'price_change', 'hash': '270918ed8b4e01efb426d51ac2f208eb91929884', 'market': '0x7aa4a910b31b2c4ddb09d1e3408e52aa8e09a14402f376070a44b1b85cb36d13', 'timestamp': '1733333076572'}
{'asset_id': '114416409796971863099144323163249651172534872992222856507897414949637892047507', 'changes': [{'price': '0.55', 'side': 'SELL', 'size': '2814.23'}], 'event_type': 'price_change', 'hash': 'bd5681f82c6abaebdaaa1dba2b62e7a668260316', 'market': '0x7aa4a910b31b2c4ddb09d1e3408e52aa8e09a14402f376070a44b1b85cb36d13', 'timestamp': '1733333076593'}
{'asset_id': '114416409796971863099144323163249651172534872992222856507897414949637892047507', 'changes': [{'price': '0.55', 'side': 'SELL', 'size': '2814.23'}], 'event_type': 'price_change', 'hash': 'bd5681f82c6abaebdaaa1dba2b62e7a668260316', 'market': '0x7aa4a910b31b2c4ddb09d1e3408e52aa8e09a14402f376070a44b1b85cb36d13', 'timestamp': '1733333076593'}
{'asset_id': '114416409796971863099144323163249651172534872992222856507897414949637892047507', 'changes': [{'price': '0.5', 'side': 'BUY', 'size': '1215'}], 'event_type': 'price_change', 'hash': '2a15ffa0e109d4dc8f9c147f0529bcc801c89977', 'market': '0x7aa4a910b31b2c4ddb09d1e3408e52aa8e09a14402f376070a44b1b85cb36d13', 'timestamp': '1733333076968'}
{'asset_id': '114416409796971863099144323163249651172534872992222856507897414949637892047507', 'changes': [{'price': '0.5', 'side': 'BUY', 'size': '1215'}], 'event_type': 'price_change', 'hash': '2a15ffa0e109d4dc8f9c147f0529bcc801c89977', 'market': '0x7aa4a910b31b2c4ddb09d1e3408e52aa8e09a14402f376070a44b1b85cb36d13', 'timestamp': '1733333076968'}
{'asset_id': '114416409796971863099144323163249651172534872992222856507897414949637892047507', 'changes': [{'price': '0.54', 'side': 'SELL', 'size': '0'}], 'event_type': 'price_change', 'hash': '9afd79f082eb3931d17736c1ba8eafe3d5fcc378', 'market': '0x7aa4a910b31b2c4ddb09d1e3408e52aa8e09a14402f376070a44b1b85cb36d13', 'timestamp': '1733333078425'}
{'asset_id': '114416409796971863099144323163249651172534872992222856507897414949637892047507', 'changes': [{'price': '0.54', 'side': 'SELL', 'size': '0'}], 'event_type': 'price_change', 'hash': '9afd79f082eb3931d17736c1ba8eafe3d5fcc378', 'market': '0x7aa4a910b31b2c4ddb09d1e3408e52aa8e09a14402f376070a44b1b85cb36d13', 'timestamp': '1733333078425'}
{'asset_id': '114416409796971863099144323163249651172534872992222856507897414949637892047507', 'changes': [{'price': '0.55', 'side': 'SELL', 'size': '2914.23'}], 'event_type': 'price_change', 'hash': '89bfa3a5a84eec1a02c1aaba417163372f28fb4c', 'market': '0x7aa4a910b31b2c4ddb09d1e3408e52aa8e09a14402f376070a44b1b85cb36d13', 'timestamp': '1733333078608'}
{'asset_id': '114416409796971863099144323163249651172534872992222856507897414949637892047507', 'changes': [{'price': '0.55', 'side': 'SELL', 'size': '2914.23'}], 'event_type': 'price_change', 'hash': '89bfa3a5a84eec1a02c1aaba417163372f28fb4c', 'market': '0x7aa4a910b31b2c4ddb09d1e3408e52aa8e09a14402f376070a44b1b85cb36d13', 'timestamp': '1733333078608'}
{'asset_id': '114416409796971863099144323163249651172534872992222856507897414949637892047507', 'changes': [{'price': '0.5', 'side': 'BUY', 'size': '1115'}], 'event_type': 'price_change', 'hash': '8522196e17b47f88c97c6610206f8b063061cd6a', 'market': '0x7aa4a910b31b2c4ddb09d1e3408e52aa8e09a14402f376070a44b1b85cb36d13', 'timestamp': '1733333081219'}
{'asset_id': '114416409796971863099144323163249651172534872992222856507897414949637892047507', 'changes': [{'price': '0.5', 'side': 'BUY', 'size': '1115'}], 'event_type': 'price_change', 'hash': '8522196e17b47f88c97c6610206f8b063061cd6a', 'market': '0x7aa4a910b31b2c4ddb09d1e3408e52aa8e09a14402f376070a44b1b85cb36d13', 'timestamp': '1733333081219'}
{'asset_id': '114416409796971863099144323163249651172534872992222856507897414949637892047507', 'changes': [{'price': '0.51', 'side': 'BUY', 'size': '1186.18'}], 'event_type': 'price_change', 'hash': '415788118b2c78f3507782261e686c1c82261845', 'market': '0x7aa4a910b31b2c4ddb09d1e3408e52aa8e09a14402f376070a44b1b85cb36d13', 'timestamp': '1733333081983'}
{'asset_id': '114416409796971863099144323163249651172534872992222856507897414949637892047507', 'changes': [{'price': '0.51', 'side': 'BUY', 'size': '1186.18'}], 'event_type': 'price_change', 'hash': '415788118b2c78f3507782261e686c1c82261845', 'market': '0x7aa4a910b31b2c4ddb09d1e3408e52aa8e09a14402f376070a44b1b85cb36d13', 'timestamp': '1733333081983'}
{'asset_id': '114416409796971863099144323163249651172534872992222856507897414949637892047507', 'changes': [{'price': '0.49', 'side': 'BUY', 'size': '360'}], 'event_type': 'price_change', 'hash': 'e99c4ccf963bc2b8f64e858bc0df43d694c1b421', 'market': '0x7aa4a910b31b2c4ddb09d1e3408e52aa8e09a14402f376070a44b1b85cb36d13', 'timestamp': '1733333092509'}
{'asset_id': '114416409796971863099144323163249651172534872992222856507897414949637892047507', 'changes': [{'price': '0.49', 'side': 'BUY', 'size': '360'}], 'event_type': 'price_change', 'hash': 'e99c4ccf963bc2b8f64e858bc0df43d694c1b421', 'market': '0x7aa4a910b31b2c4ddb09d1e3408e52aa8e09a14402f376070a44b1b85cb36d13', 'timestamp': '1733333092509'}
{'asset_id': '114416409796971863099144323163249651172534872992222856507897414949637892047507', 'changes': [{'price': '0.51', 'side': 'BUY', 'size': '1086.18'}], 'event_type': 'price_change', 'hash': '7077d157309ae98226df66051cb3680ce395fdca', 'market': '0x7aa4a910b31b2c4ddb09d1e3408e52aa8e09a14402f376070a44b1b85cb36d13', 'timestamp': '1733333093931'}
{'asset_id': '114416409796971863099144323163249651172534872992222856507897414949637892047507', 'changes': [{'price': '0.51', 'side': 'BUY', 'size': '1086.18'}], 'event_type': 'price_change', 'hash': '7077d157309ae98226df66051cb3680ce395fdca', 'market': '0x7aa4a910b31b2c4ddb09d1e3408e52aa8e09a14402f376070a44b1b85cb36d13', 'timestamp': '1733333093931'}
{'asset_id': '114416409796971863099144323163249651172534872992222856507897414949637892047507', 'changes': [{'price': '0.5', 'side': 'BUY', 'size': '1215'}], 'event_type': 'price_change', 'hash': 'd456935facaade0ee2c652b98dde93a0d274cd47', 'market': '0x7aa4a910b31b2c4ddb09d1e3408e52aa8e09a14402f376070a44b1b85cb36d13', 'timestamp': '1733333094835'}
{'asset_id': '114416409796971863099144323163249651172534872992222856507897414949637892047507', 'changes': [{'price': '0.5', 'side': 'BUY', 'size': '1215'}], 'event_type': 'price_change', 'hash': 'd456935facaade0ee2c652b98dde93a0d274cd47', 'market': '0x7aa4a910b31b2c4ddb09d1e3408e52aa8e09a14402f376070a44b1b85cb36d13', 'timestamp': '1733333094835'}
{'asset_id': '114416409796971863099144323163249651172534872992222856507897414949637892047507', 'changes': [{'price': '0.5', 'side': 'BUY', 'size': '2415'}], 'event_type': 'price_change', 'hash': '871944574ed8f11c33a49b8babbd075940ef930b', 'market': '0x7aa4a910b31b2c4ddb09d1e3408e52aa8e09a14402f376070a44b1b85cb36d13', 'timestamp': '1733333099028'}
{'asset_id': '114416409796971863099144323163249651172534872992222856507897414949637892047507', 'changes': [{'price': '0.5', 'side': 'BUY', 'size': '2415'}], 'event_type': 'price_change', 'hash': '871944574ed8f11c33a49b8babbd075940ef930b', 'market': '0x7aa4a910b31b2c4ddb09d1e3408e52aa8e09a14402f376070a44b1b85cb36d13', 'timestamp': '1733333099028'}
{'asset_id': '114416409796971863099144323163249651172534872992222856507897414949637892047507', 'changes': [{'price': '0.5', 'side': 'BUY', 'size': '2315'}], 'event_type': 'price_change', 'hash': 'ec01ba0ac92085cd10561358c345174cdf6933cf', 'market': '0x7aa4a910b31b2c4ddb09d1e3408e52aa8e09a14402f376070a44b1b85cb36d13', 'timestamp': '1733333104393'}
{'asset_id': '114416409796971863099144323163249651172534872992222856507897414949637892047507', 'changes': [{'price': '0.5', 'side': 'BUY', 'size': '2315'}], 'event_type': 'price_change', 'hash': 'ec01ba0ac92085cd10561358c345174cdf6933cf', 'market': '0x7aa4a910b31b2c4ddb09d1e3408e52aa8e09a14402f376070a44b1b85cb36d13', 'timestamp': '1733333104393'}
{'asset_id': '114416409796971863099144323163249651172534872992222856507897414949637892047507', 'changes': [{'price': '0.5', 'side': 'BUY', 'size': '1115'}], 'event_type': 'price_change', 'hash': '7b6702c5eef8fab6587799efe7daba4f68855c82', 'market': '0x7aa4a910b31b2c4ddb09d1e3408e52aa8e09a14402f376070a44b1b85cb36d13', 'timestamp': '1733333107764'}
{'asset_id': '114416409796971863099144323163249651172534872992222856507897414949637892047507', 'changes': [{'price': '0.5', 'side': 'BUY', 'size': '1115'}], 'event_type': 'price_change', 'hash': '7b6702c5eef8fab6587799efe7daba4f68855c82', 'market': '0x7aa4a910b31b2c4ddb09d1e3408e52aa8e09a14402f376070a44b1b85cb36d13', 'timestamp': '1733333107764'}
{'asset_id': '114416409796971863099144323163249651172534872992222856507897414949637892047507', 'changes': [{'price': '0.46', 'side': 'BUY', 'size': '0'}, {'price': '0.55', 'side': 'SELL', 'size': '2414.23'}, {'price': '0.5', 'side': 'BUY', 'size': '115'}], 'event_type': 'price_change', 'hash': 'b87abbef1cce412bb83d1bddde339a2985e1f5a4', 'market': '0x7aa4a910b31b2c4ddb09d1e3408e52aa8e09a14402f376070a44b1b85cb36d13', 'timestamp': '1733333107995'}
{'asset_id': '114416409796971863099144323163249651172534872992222856507897414949637892047507', 'changes': [{'price': '0.46', 'side': 'BUY', 'size': '0'}, {'price': '0.55', 'side': 'SELL', 'size': '2414.23'}, {'price': '0.5', 'side': 'BUY', 'size': '115'}], 'event_type': 'price_change', 'hash': 'b87abbef1cce412bb83d1bddde339a2985e1f5a4', 'market': '0x7aa4a910b31b2c4ddb09d1e3408e52aa8e09a14402f376070a44b1b85cb36d13', 'timestamp': '1733333107995'}
{'asset_id': '114416409796971863099144323163249651172534872992222856507897414949637892047507', 'changes': [{'price': '0.49', 'side': 'BUY', 'size': '1560'}], 'event_type': 'price_change', 'hash': '556d3ec76c11f7bdd5244933095ca63412a66f71', 'market': '0x7aa4a910b31b2c4ddb09d1e3408e52aa8e09a14402f376070a44b1b85cb36d13', 'timestamp': '1733333108108'}
{'asset_id': '114416409796971863099144323163249651172534872992222856507897414949637892047507', 'changes': [{'price': '0.49', 'side': 'BUY', 'size': '1560'}], 'event_type': 'price_change', 'hash': '556d3ec76c11f7bdd5244933095ca63412a66f71', 'market': '0x7aa4a910b31b2c4ddb09d1e3408e52aa8e09a14402f376070a44b1b85cb36d13', 'timestamp': '1733333108108'}
{'asset_id': '114416409796971863099144323163249651172534872992222856507897414949637892047507', 'changes': [{'price': '0.45', 'side': 'BUY', 'size': '978'}], 'event_type': 'price_change', 'hash': '7294dd88f0f083de7e12dbed4d929c325ebac0fa', 'market': '0x7aa4a910b31b2c4ddb09d1e3408e52aa8e09a14402f376070a44b1b85cb36d13', 'timestamp': '1733333109039'}
{'asset_id': '114416409796971863099144323163249651172534872992222856507897414949637892047507', 'changes': [{'price': '0.45', 'side': 'BUY', 'size': '978'}], 'event_type': 'price_change', 'hash': '7294dd88f0f083de7e12dbed4d929c325ebac0fa', 'market': '0x7aa4a910b31b2c4ddb09d1e3408e52aa8e09a14402f376070a44b1b85cb36d13', 'timestamp': '1733333109039'}
{'asset_id': '114416409796971863099144323163249651172534872992222856507897414949637892047507', 'changes': [{'price': '0.54', 'side': 'SELL', 'size': '500'}], 'event_type': 'price_change', 'hash': '62551979579783fc3303b266686c716e65d16789', 'market': '0x7aa4a910b31b2c4ddb09d1e3408e52aa8e09a14402f376070a44b1b85cb36d13', 'timestamp': '1733333109431'}
{'asset_id': '114416409796971863099144323163249651172534872992222856507897414949637892047507', 'changes': [{'price': '0.54', 'side': 'SELL', 'size': '500'}], 'event_type': 'price_change', 'hash': '62551979579783fc3303b266686c716e65d16789', 'market': '0x7aa4a910b31b2c4ddb09d1e3408e52aa8e09a14402f376070a44b1b85cb36d13', 'timestamp': '1733333109431'}
{'asset_id': '114416409796971863099144323163249651172534872992222856507897414949637892047507', 'changes': [{'price': '0.5', 'side': 'BUY', 'size': '1115'}], 'event_type': 'price_change', 'hash': '0f2d09404f2d4d994bdecf3014d87712856c94b9', 'market': '0x7aa4a910b31b2c4ddb09d1e3408e52aa8e09a14402f376070a44b1b85cb36d13', 'timestamp': '1733333109801'}
{'asset_id': '114416409796971863099144323163249651172534872992222856507897414949637892047507', 'changes': [{'price': '0.5', 'side': 'BUY', 'size': '1115'}], 'event_type': 'price_change', 'hash': '0f2d09404f2d4d994bdecf3014d87712856c94b9', 'market': '0x7aa4a910b31b2c4ddb09d1e3408e52aa8e09a14402f376070a44b1b85cb36d13', 'timestamp': '1733333109801'}
{'asset_id': '114416409796971863099144323163249651172534872992222856507897414949637892047507', 'changes': [{'price': '0.55', 'side': 'SELL', 'size': '2314.23'}], 'event_type': 'price_change', 'hash': '0b2131f64f5c05ecaaf8e619de5220c91cbbec8d', 'market': '0x7aa4a910b31b2c4ddb09d1e3408e52aa8e09a14402f376070a44b1b85cb36d13', 'timestamp': '1733333110867'}
{'asset_id': '114416409796971863099144323163249651172534872992222856507897414949637892047507', 'changes': [{'price': '0.55', 'side': 'SELL', 'size': '2314.23'}], 'event_type': 'price_change', 'hash': '0b2131f64f5c05ecaaf8e619de5220c91cbbec8d', 'market': '0x7aa4a910b31b2c4ddb09d1e3408e52aa8e09a14402f376070a44b1b85cb36d13', 'timestamp': '1733333110867'}
{'asset_id': '114416409796971863099144323163249651172534872992222856507897414949637892047507', 'changes': [{'price': '0.54', 'side': 'SELL', 'size': '600'}], 'event_type': 'price_change', 'hash': 'ae8391662b79ada8b7c6ff203ae0b7ab2ebe019d', 'market': '0x7aa4a910b31b2c4ddb09d1e3408e52aa8e09a14402f376070a44b1b85cb36d13', 'timestamp': '1733333111018'}
{'asset_id': '114416409796971863099144323163249651172534872992222856507897414949637892047507', 'changes': [{'price': '0.54', 'side': 'SELL', 'size': '600'}], 'event_type': 'price_change', 'hash': 'ae8391662b79ada8b7c6ff203ae0b7ab2ebe019d', 'market': '0x7aa4a910b31b2c4ddb09d1e3408e52aa8e09a14402f376070a44b1b85cb36d13', 'timestamp': '1733333111018'}
{'asset_id': '114416409796971863099144323163249651172534872992222856507897414949637892047507', 'changes': [{'price': '0.5', 'side': 'BUY', 'size': '1215'}], 'event_type': 'price_change', 'hash': '58b414642c0a6ff660f07a7f3b4fe5c23fbd51ac', 'market': '0x7aa4a910b31b2c4ddb09d1e3408e52aa8e09a14402f376070a44b1b85cb36d13', 'timestamp': '1733333112566'}
{'asset_id': '114416409796971863099144323163249651172534872992222856507897414949637892047507', 'changes': [{'price': '0.5', 'side': 'BUY', 'size': '1215'}], 'event_type': 'price_change', 'hash': '58b414642c0a6ff660f07a7f3b4fe5c23fbd51ac', 'market': '0x7aa4a910b31b2c4ddb09d1e3408e52aa8e09a14402f376070a44b1b85cb36d13', 'timestamp': '1733333112566'}
{'asset_id': '114416409796971863099144323163249651172534872992222856507897414949637892047507', 'changes': [{'price': '0.55', 'side': 'SELL', 'size': '2289.22'}], 'event_type': 'price_change', 'hash': '59bb5343e1ec2d5985ac6a9142a3abbc376776af', 'market': '0x7aa4a910b31b2c4ddb09d1e3408e52aa8e09a14402f376070a44b1b85cb36d13', 'timestamp': '1733333113121'}
{'asset_id': '114416409796971863099144323163249651172534872992222856507897414949637892047507', 'changes': [{'price': '0.55', 'side': 'SELL', 'size': '2289.22'}], 'event_type': 'price_change', 'hash': '59bb5343e1ec2d5985ac6a9142a3abbc376776af', 'market': '0x7aa4a910b31b2c4ddb09d1e3408e52aa8e09a14402f376070a44b1b85cb36d13', 'timestamp': '1733333113121'}
{'asset_id': '114416409796971863099144323163249651172534872992222856507897414949637892047507', 'changes': [{'price': '0.54', 'side': 'SELL', 'size': '625.01'}], 'event_type': 'price_change', 'hash': 'cc7d5fe37a3ed83071f1e9532b094f7dfe1dd49f', 'market': '0x7aa4a910b31b2c4ddb09d1e3408e52aa8e09a14402f376070a44b1b85cb36d13', 'timestamp': '1733333113283'}
{'asset_id': '114416409796971863099144323163249651172534872992222856507897414949637892047507', 'changes': [{'price': '0.54', 'side': 'SELL', 'size': '625.01'}], 'event_type': 'price_change', 'hash': 'cc7d5fe37a3ed83071f1e9532b094f7dfe1dd49f', 'market': '0x7aa4a910b31b2c4ddb09d1e3408e52aa8e09a14402f376070a44b1b85cb36d13', 'timestamp': '1733333113283'}
{'asset_id': '114416409796971863099144323163249651172534872992222856507897414949637892047507', 'changes': [{'price': '0.5', 'side': 'BUY', 'size': '1115'}], 'event_type': 'price_change', 'hash': 'ff6817d80f408d973d99d8e5d2fb5077ab5b5aa7', 'market': '0x7aa4a910b31b2c4ddb09d1e3408e52aa8e09a14402f376070a44b1b85cb36d13', 'timestamp': '1733333117852'}
{'asset_id': '114416409796971863099144323163249651172534872992222856507897414949637892047507', 'changes': [{'price': '0.5', 'side': 'BUY', 'size': '1115'}], 'event_type': 'price_change', 'hash': 'ff6817d80f408d973d99d8e5d2fb5077ab5b5aa7', 'market': '0x7aa4a910b31b2c4ddb09d1e3408e52aa8e09a14402f376070a44b1b85cb36d13', 'timestamp': '1733333117852'}
{'asset_id': '114416409796971863099144323163249651172534872992222856507897414949637892047507', 'changes': [{'price': '0.5', 'side': 'BUY', 'size': '1215'}], 'event_type': 'price_change', 'hash': 'f84ffd9f2295d5578c7f4e6b8a1110aa5bc08f10', 'market': '0x7aa4a910b31b2c4ddb09d1e3408e52aa8e09a14402f376070a44b1b85cb36d13', 'timestamp': '1733333125021'}
{'asset_id': '114416409796971863099144323163249651172534872992222856507897414949637892047507', 'changes': [{'price': '0.5', 'side': 'BUY', 'size': '1215'}], 'event_type': 'price_change', 'hash': 'f84ffd9f2295d5578c7f4e6b8a1110aa5bc08f10', 'market': '0x7aa4a910b31b2c4ddb09d1e3408e52aa8e09a14402f376070a44b1b85cb36d13', 'timestamp': '1733333125021'}
{'asset_id': '114416409796971863099144323163249651172534872992222856507897414949637892047507', 'changes': [{'price': '0.5', 'side': 'BUY', 'size': '1115'}], 'event_type': 'price_change', 'hash': 'af5fc02f149c1d3677fe800536b83dba4b126b3e', 'market': '0x7aa4a910b31b2c4ddb09d1e3408e52aa8e09a14402f376070a44b1b85cb36d13', 'timestamp': '1733333127268'}
{'asset_id': '114416409796971863099144323163249651172534872992222856507897414949637892047507', 'changes': [{'price': '0.5', 'side': 'BUY', 'size': '1115'}], 'event_type': 'price_change', 'hash': 'af5fc02f149c1d3677fe800536b83dba4b126b3e', 'market': '0x7aa4a910b31b2c4ddb09d1e3408e52aa8e09a14402f376070a44b1b85cb36d13', 'timestamp': '1733333127268'}
{'asset_id': '114416409796971863099144323163249651172534872992222856507897414949637892047507', 'changes': [{'price': '0.5', 'side': 'BUY', 'size': '1215'}], 'event_type': 'price_change', 'hash': '7244fc5913ada76d566d01e869a3f149d0484c59', 'market': '0x7aa4a910b31b2c4ddb09d1e3408e52aa8e09a14402f376070a44b1b85cb36d13', 'timestamp': '1733333130299'}
{'asset_id': '114416409796971863099144323163249651172534872992222856507897414949637892047507', 'changes': [{'price': '0.5', 'side': 'BUY', 'size': '1115'}], 'event_type': 'price_change', 'hash': 'bd3132a0dbdccb194bd674349aac808a928dcc42', 'market': '0x7aa4a910b31b2c4ddb09d1e3408e52aa8e09a14402f376070a44b1b85cb36d13', 'timestamp': '1733333133805'}
{'asset_id': '114416409796971863099144323163249651172534872992222856507897414949637892047507', 'changes': [{'price': '0.5', 'side': 'BUY', 'size': '1115'}], 'event_type': 'price_change', 'hash': 'bd3132a0dbdccb194bd674349aac808a928dcc42', 'market': '0x7aa4a910b31b2c4ddb09d1e3408e52aa8e09a14402f376070a44b1b85cb36d13', 'timestamp': '1733333133805'}
{'asset_id': '114416409796971863099144323163249651172534872992222856507897414949637892047507', 'changes': [{'price': '0.5', 'side': 'BUY', 'size': '1215'}], 'event_type': 'price_change', 'hash': 'a710c166b1bdb4bb19239dc982dc9105a3eb9689', 'market': '0x7aa4a910b31b2c4ddb09d1e3408e52aa8e09a14402f376070a44b1b85cb36d13', 'timestamp': '1733333136049'}
{'asset_id': '114416409796971863099144323163249651172534872992222856507897414949637892047507', 'changes': [{'price': '0.5', 'side': 'BUY', 'size': '1215'}], 'event_type': 'price_change', 'hash': 'a710c166b1bdb4bb19239dc982dc9105a3eb9689', 'market': '0x7aa4a910b31b2c4ddb09d1e3408e52aa8e09a14402f376070a44b1b85cb36d13', 'timestamp': '1733333136049'}
{'asset_id': '114416409796971863099144323163249651172534872992222856507897414949637892047507', 'changes': [{'price': '0.59', 'side': 'SELL', 'size': '10'}], 'event_type': 'price_change', 'hash': 'd4bdce597d68b048fcfdd67edd6eb8024d45b26d', 'market': '0x7aa4a910b31b2c4ddb09d1e3408e52aa8e09a14402f376070a44b1b85cb36d13', 'timestamp': '1733333140015'}
{'asset_id': '114416409796971863099144323163249651172534872992222856507897414949637892047507', 'changes': [{'price': '0.59', 'side': 'SELL', 'size': '10'}], 'event_type': 'price_change', 'hash': 'd4bdce597d68b048fcfdd67edd6eb8024d45b26d', 'market': '0x7aa4a910b31b2c4ddb09d1e3408e52aa8e09a14402f376070a44b1b85cb36d13', 'timestamp': '1733333140015'}
{'asset_id': '114416409796971863099144323163249651172534872992222856507897414949637892047507', 'changes': [{'price': '0.52', 'side': 'BUY', 'size': '762.77'}], 'event_type': 'price_change', 'hash': 'ca714eb8b36563ae3822969b3dab64bac143d323', 'market': '0x7aa4a910b31b2c4ddb09d1e3408e52aa8e09a14402f376070a44b1b85cb36d13', 'timestamp': '1733333141425'}
{'asset_id': '114416409796971863099144323163249651172534872992222856507897414949637892047507', 'changes': [{'price': '0.52', 'side': 'BUY', 'size': '762.77'}], 'event_type': 'price_change', 'hash': 'ca714eb8b36563ae3822969b3dab64bac143d323', 'market': '0x7aa4a910b31b2c4ddb09d1e3408e52aa8e09a14402f376070a44b1b85cb36d13', 'timestamp': '1733333141425'}
{'asset_id': '114416409796971863099144323163249651172534872992222856507897414949637892047507', 'changes': [{'price': '0.54', 'side': 'SELL', 'size': '675.01'}], 'event_type': 'price_change', 'hash': '34544ceb5d3ab495bb9146160df97bced9e637b8', 'market': '0x7aa4a910b31b2c4ddb09d1e3408e52aa8e09a14402f376070a44b1b85cb36d13', 'timestamp': '1733333145925'}
{'asset_id': '114416409796971863099144323163249651172534872992222856507897414949637892047507', 'changes': [{'price': '0.54', 'side': 'SELL', 'size': '675.01'}], 'event_type': 'price_change', 'hash': '34544ceb5d3ab495bb9146160df97bced9e637b8', 'market': '0x7aa4a910b31b2c4ddb09d1e3408e52aa8e09a14402f376070a44b1b85cb36d13', 'timestamp': '1733333145925'}
{'asset_id': '114416409796971863099144323163249651172534872992222856507897414949637892047507', 'changes': [{'price': '0.59', 'side': 'SELL', 'size': '2510'}], 'event_type': 'price_change', 'hash': '09da6fa48865f6a0323a1b090854973592f3c42e', 'market': '0x7aa4a910b31b2c4ddb09d1e3408e52aa8e09a14402f376070a44b1b85cb36d13', 'timestamp': '1733333148561'}
{'asset_id': '114416409796971863099144323163249651172534872992222856507897414949637892047507', 'changes': [{'price': '0.59', 'side': 'SELL', 'size': '2510'}], 'event_type': 'price_change', 'hash': '09da6fa48865f6a0323a1b090854973592f3c42e', 'market': '0x7aa4a910b31b2c4ddb09d1e3408e52aa8e09a14402f376070a44b1b85cb36d13', 'timestamp': '1733333148561'}
{'asset_id': '114416409796971863099144323163249651172534872992222856507897414949637892047507', 'changes': [{'price': '0.53', 'side': 'BUY', 'size': '10'}], 'event_type': 'price_change', 'hash': 'ceaa7a03720dfaa7f30c7be384c6132685d436ef', 'market': '0x7aa4a910b31b2c4ddb09d1e3408e52aa8e09a14402f376070a44b1b85cb36d13', 'timestamp': '1733333156224'}
{'asset_id': '114416409796971863099144323163249651172534872992222856507897414949637892047507', 'changes': [{'price': '0.53', 'side': 'BUY', 'size': '10'}], 'event_type': 'price_change', 'hash': 'ceaa7a03720dfaa7f30c7be384c6132685d436ef', 'market': '0x7aa4a910b31b2c4ddb09d1e3408e52aa8e09a14402f376070a44b1b85cb36d13', 'timestamp': '1733333156224'}
{'asks': [{'price': '0.99', 'size': '4217.01'}, {'price': '0.98', 'size': '505'}, {'price': '0.97', 'size': '511.03'}, {'price': '0.96', 'size': '300'}, {'price': '0.95', 'size': '657.12'}, {'price': '0.94', 'size': '300'}, {'price': '0.92', 'size': '20000.45'}, {'price': '0.91', 'size': '10406.3'}, {'price': '0.9', 'size': '4587.5'}, {'price': '0.89', 'size': '13017.18'}, {'price': '0.88', 'size': '200'}, {'price': '0.87', 'size': '3229'}, {'price': '0.86', 'size': '17.1'}, {'price': '0.85', 'size': '109.68'}, {'price': '0.84', 'size': '250'}, {'price': '0.83', 'size': '100'}, {'price': '0.82', 'size': '16029'}, {'price': '0.81', 'size': '45721.39'}, {'price': '0.8', 'size': '26531'}, {'price': '0.79', 'size': '7110'}, {'price': '0.78', 'size': '10350'}, {'price': '0.77', 'size': '67'}, {'price': '0.76', 'size': '200'}, {'price': '0.75', 'size': '18329.25'}, {'price': '0.74', 'size': '11370.7'}, {'price': '0.73', 'size': '5020.1'}, {'price': '0.72', 'size': '380.52'}, {'price': '0.71', 'size': '15073.2'}, {'price': '0.7', 'size': '5570.1'}, {'price': '0.69', 'size': '6088.6'}, {'price': '0.68', 'size': '2131.34'}, {'price': '0.67', 'size': '3010.1'}, {'price': '0.66', 'size': '4510.1'}, {'price': '0.65', 'size': '1010.1'}, {'price': '0.64', 'size': '1230.1'}, {'price': '0.63', 'size': '210.1'}, {'price': '0.62', 'size': '300.1'}, {'price': '0.61', 'size': '511.06'}, {'price': '0.6', 'size': '3467.85'}, {'price': '0.59', 'size': '2510'}, {'price': '0.58', 'size': '2188.1'}, {'price': '0.57', 'size': '1850.1'}, {'price': '0.56', 'size': '1161.75'}, {'price': '0.55', 'size': '2289.22'}, {'price': '0.54', 'size': '675.01'}, {'price': '0.53', 'size': '5'}], 'asset_id': '114416409796971863099144323163249651172534872992222856507897414949637892047507', 'bids': [{'price': '0.01', 'size': '2850.27'}, {'price': '0.02', 'size': '500'}, {'price': '0.03', 'size': '500'}, {'price': '0.04', 'size': '300'}, {'price': '0.05', 'size': '320'}, {'price': '0.06', 'size': '300'}, {'price': '0.08', 'size': '250'}, {'price': '0.09', 'size': '300'}, {'price': '0.1', 'size': '205'}, {'price': '0.11', 'size': '5454'}, {'price': '0.12', 'size': '200'}, {'price': '0.13', 'size': '426.92'}, {'price': '0.14', 'size': '15'}, {'price': '0.15', 'size': '110'}, {'price': '0.16', 'size': '4709.51'}, {'price': '0.18', 'size': '19.13'}, {'price': '0.19', 'size': '120'}, {'price': '0.2', 'size': '691.17'}, {'price': '0.24', 'size': '5027'}, {'price': '0.25', 'size': '86.66'}, {'price': '0.27', 'size': '215.25'}, {'price': '0.29', 'size': '1102.28'}, {'price': '0.31', 'size': '1130.65'}, {'price': '0.32', 'size': '200'}, {'price': '0.33', 'size': '4620'}, {'price': '0.35', 'size': '232'}, {'price': '0.39', 'size': '10.5'}, {'price': '0.4', 'size': '3135'}, {'price': '0.41', 'size': '20'}, {'price': '0.42', 'size': '3050'}, {'price': '0.43', 'size': '50'}, {'price': '0.44', 'size': '3660'}, {'price': '0.45', 'size': '978'}, {'price': '0.47', 'size': '4797.23'}, {'price': '0.48', 'size': '1842.18'}, {'price': '0.49', 'size': '1560'}, {'price': '0.5', 'size': '1215'}, {'price': '0.51', 'size': '1086.18'}, {'price': '0.52', 'size': '762.77'}], 'event_type': 'book', 'hash': '9118ac3aa60b52e8a19c717308cc31af21055f48', 'market': '0x7aa4a910b31b2c4ddb09d1e3408e52aa8e09a14402f376070a44b1b85cb36d13', 'timestamp': '1733333156650'}
{'asset_id': '114416409796971863099144323163249651172534872992222856507897414949637892047507', 'changes': [{'price': '0.53', 'side': 'SELL', 'size': '5'}], 'event_type': 'price_change', 'hash': '9118ac3aa60b52e8a19c717308cc31af21055f48', 'market': '0x7aa4a910b31b2c4ddb09d1e3408e52aa8e09a14402f376070a44b1b85cb36d13', 'timestamp': '1733333156659'}
{'asks': [{'price': '0.99', 'size': '4217.01'}, {'price': '0.98', 'size': '505'}, {'price': '0.97', 'size': '511.03'}, {'price': '0.96', 'size': '300'}, {'price': '0.95', 'size': '657.12'}, {'price': '0.94', 'size': '300'}, {'price': '0.92', 'size': '20000.45'}, {'price': '0.91', 'size': '10406.3'}, {'price': '0.9', 'size': '4587.5'}, {'price': '0.89', 'size': '13017.18'}, {'price': '0.88', 'size': '200'}, {'price': '0.87', 'size': '3229'}, {'price': '0.86', 'size': '17.1'}, {'price': '0.85', 'size': '109.68'}, {'price': '0.84', 'size': '250'}, {'price': '0.83', 'size': '100'}, {'price': '0.82', 'size': '16029'}, {'price': '0.81', 'size': '45721.39'}, {'price': '0.8', 'size': '26531'}, {'price': '0.79', 'size': '7110'}, {'price': '0.78', 'size': '10350'}, {'price': '0.77', 'size': '67'}, {'price': '0.76', 'size': '200'}, {'price': '0.75', 'size': '18329.25'}, {'price': '0.74', 'size': '11370.7'}, {'price': '0.73', 'size': '5020.1'}, {'price': '0.72', 'size': '380.52'}, {'price': '0.71', 'size': '15073.2'}, {'price': '0.7', 'size': '5570.1'}, {'price': '0.69', 'size': '6088.6'}, {'price': '0.68', 'size': '2131.34'}, {'price': '0.67', 'size': '3010.1'}, {'price': '0.66', 'size': '4510.1'}, {'price': '0.65', 'size': '1010.1'}, {'price': '0.64', 'size': '1230.1'}, {'price': '0.63', 'size': '210.1'}, {'price': '0.62', 'size': '300.1'}, {'price': '0.61', 'size': '511.06'}, {'price': '0.6', 'size': '3467.85'}, {'price': '0.59', 'size': '2510'}, {'price': '0.58', 'size': '2188.1'}, {'price': '0.57', 'size': '1850.1'}, {'price': '0.56', 'size': '1161.75'}, {'price': '0.55', 'size': '2289.22'}, {'price': '0.54', 'size': '675.01'}, {'price': '0.53', 'size': '5'}], 'asset_id': '114416409796971863099144323163249651172534872992222856507897414949637892047507', 'bids': [{'price': '0.01', 'size': '2850.27'}, {'price': '0.02', 'size': '500'}, {'price': '0.03', 'size': '500'}, {'price': '0.04', 'size': '300'}, {'price': '0.05', 'size': '320'}, {'price': '0.06', 'size': '300'}, {'price': '0.08', 'size': '250'}, {'price': '0.09', 'size': '300'}, {'price': '0.1', 'size': '205'}, {'price': '0.11', 'size': '5454'}, {'price': '0.12', 'size': '200'}, {'price': '0.13', 'size': '426.92'}, {'price': '0.14', 'size': '15'}, {'price': '0.15', 'size': '110'}, {'price': '0.16', 'size': '4709.51'}, {'price': '0.18', 'size': '19.13'}, {'price': '0.19', 'size': '120'}, {'price': '0.2', 'size': '691.17'}, {'price': '0.24', 'size': '5027'}, {'price': '0.25', 'size': '86.66'}, {'price': '0.27', 'size': '215.25'}, {'price': '0.29', 'size': '1102.28'}, {'price': '0.31', 'size': '1130.65'}, {'price': '0.32', 'size': '200'}, {'price': '0.33', 'size': '4620'}, {'price': '0.35', 'size': '232'}, {'price': '0.39', 'size': '10.5'}, {'price': '0.4', 'size': '3135'}, {'price': '0.41', 'size': '20'}, {'price': '0.42', 'size': '3050'}, {'price': '0.43', 'size': '50'}, {'price': '0.44', 'size': '3660'}, {'price': '0.45', 'size': '978'}, {'price': '0.47', 'size': '4797.23'}, {'price': '0.48', 'size': '1842.18'}, {'price': '0.49', 'size': '1560'}, {'price': '0.5', 'size': '1215'}, {'price': '0.51', 'size': '1086.18'}, {'price': '0.52', 'size': '762.77'}], 'event_type': 'book', 'hash': '9118ac3aa60b52e8a19c717308cc31af21055f48', 'market': '0x7aa4a910b31b2c4ddb09d1e3408e52aa8e09a14402f376070a44b1b85cb36d13', 'timestamp': '1733333156650'}
{'asset_id': '114416409796971863099144323163249651172534872992222856507897414949637892047507', 'changes': [{'price': '0.53', 'side': 'SELL', 'size': '5'}], 'event_type': 'price_change', 'hash': '9118ac3aa60b52e8a19c717308cc31af21055f48', 'market': '0x7aa4a910b31b2c4ddb09d1e3408e52aa8e09a14402f376070a44b1b85cb36d13', 'timestamp': '1733333156659'}
{'asset_id': '114416409796971863099144323163249651172534872992222856507897414949637892047507', 'changes': [{'price': '0.53', 'side': 'SELL', 'size': '0'}], 'event_type': 'price_change', 'hash': '45498038b132cc68ced52b78116fa697c680ebb1', 'market': '0x7aa4a910b31b2c4ddb09d1e3408e52aa8e09a14402f376070a44b1b85cb36d13', 'timestamp': '1733333157379'}
{'asset_id': '114416409796971863099144323163249651172534872992222856507897414949637892047507', 'changes': [{'price': '0.53', 'side': 'SELL', 'size': '0'}], 'event_type': 'price_change', 'hash': '45498038b132cc68ced52b78116fa697c680ebb1', 'market': '0x7aa4a910b31b2c4ddb09d1e3408e52aa8e09a14402f376070a44b1b85cb36d13', 'timestamp': '1733333157379'}
{'asset_id': '114416409796971863099144323163249651172534872992222856507897414949637892047507', 'changes': [{'price': '0.45', 'side': 'BUY', 'size': '478'}, {'price': '0.54', 'side': 'SELL', 'size': '175.01'}, {'price': '0.5', 'side': 'BUY', 'size': '215'}], 'event_type': 'price_change', 'hash': '454fbd304bda63a4900d054e0bac4df7e9f1ac5d', 'market': '0x7aa4a910b31b2c4ddb09d1e3408e52aa8e09a14402f376070a44b1b85cb36d13', 'timestamp': '1733333158920'}
{'asset_id': '114416409796971863099144323163249651172534872992222856507897414949637892047507', 'changes': [{'price': '0.45', 'side': 'BUY', 'size': '478'}, {'price': '0.54', 'side': 'SELL', 'size': '175.01'}, {'price': '0.5', 'side': 'BUY', 'size': '215'}], 'event_type': 'price_change', 'hash': '454fbd304bda63a4900d054e0bac4df7e9f1ac5d', 'market': '0x7aa4a910b31b2c4ddb09d1e3408e52aa8e09a14402f376070a44b1b85cb36d13', 'timestamp': '1733333158920'}
{'asset_id': '114416409796971863099144323163249651172534872992222856507897414949637892047507', 'changes': [{'price': '0.46', 'side': 'BUY', 'size': '500'}], 'event_type': 'price_change', 'hash': '22dee8eabc4c8d213f2c0848543fb4e64b104e47', 'market': '0x7aa4a910b31b2c4ddb09d1e3408e52aa8e09a14402f376070a44b1b85cb36d13', 'timestamp': '1733333159957'}
{'asset_id': '114416409796971863099144323163249651172534872992222856507897414949637892047507', 'changes': [{'price': '0.46', 'side': 'BUY', 'size': '500'}], 'event_type': 'price_change', 'hash': '22dee8eabc4c8d213f2c0848543fb4e64b104e47', 'market': '0x7aa4a910b31b2c4ddb09d1e3408e52aa8e09a14402f376070a44b1b85cb36d13', 'timestamp': '1733333159957'}
{'asset_id': '114416409796971863099144323163249651172534872992222856507897414949637892047507', 'changes': [{'price': '0.55', 'side': 'SELL', 'size': '2789.22'}], 'event_type': 'price_change', 'hash': '0fe23a81245c2cf1e47174e82eda21c967ebbd5b', 'market': '0x7aa4a910b31b2c4ddb09d1e3408e52aa8e09a14402f376070a44b1b85cb36d13', 'timestamp': '1733333160359'}
{'asset_id': '114416409796971863099144323163249651172534872992222856507897414949637892047507', 'changes': [{'price': '0.55', 'side': 'SELL', 'size': '2789.22'}], 'event_type': 'price_change', 'hash': '0fe23a81245c2cf1e47174e82eda21c967ebbd5b', 'market': '0x7aa4a910b31b2c4ddb09d1e3408e52aa8e09a14402f376070a44b1b85cb36d13', 'timestamp': '1733333160359'}
{'asset_id': '114416409796971863099144323163249651172534872992222856507897414949637892047507', 'changes': [{'price': '0.54', 'side': 'SELL', 'size': '150'}], 'event_type': 'price_change', 'hash': 'b8408a769828f02255b6dab6c386652b362b529a', 'market': '0x7aa4a910b31b2c4ddb09d1e3408e52aa8e09a14402f376070a44b1b85cb36d13', 'timestamp': '1733333160539'}
{'asset_id': '114416409796971863099144323163249651172534872992222856507897414949637892047507', 'changes': [{'price': '0.54', 'side': 'SELL', 'size': '150'}], 'event_type': 'price_change', 'hash': 'b8408a769828f02255b6dab6c386652b362b529a', 'market': '0x7aa4a910b31b2c4ddb09d1e3408e52aa8e09a14402f376070a44b1b85cb36d13', 'timestamp': '1733333160539'}
{'asset_id': '114416409796971863099144323163249651172534872992222856507897414949637892047507', 'changes': [{'price': '0.5', 'side': 'BUY', 'size': '1215'}, {'price': '0.55', 'side': 'SELL', 'size': '2814.23'}], 'event_type': 'price_change', 'hash': 'd0c3aa9e42a99126dc2ed3ad854b6d10f721f7f1', 'market': '0x7aa4a910b31b2c4ddb09d1e3408e52aa8e09a14402f376070a44b1b85cb36d13', 'timestamp': '1733333160752'}
{'asset_id': '114416409796971863099144323163249651172534872992222856507897414949637892047507', 'changes': [{'price': '0.5', 'side': 'BUY', 'size': '1215'}, {'price': '0.55', 'side': 'SELL', 'size': '2814.23'}], 'event_type': 'price_change', 'hash': 'd0c3aa9e42a99126dc2ed3ad854b6d10f721f7f1', 'market': '0x7aa4a910b31b2c4ddb09d1e3408e52aa8e09a14402f376070a44b1b85cb36d13', 'timestamp': '1733333160752'}
{'asset_id': '114416409796971863099144323163249651172534872992222856507897414949637892047507', 'changes': [{'price': '0.52', 'side': 'BUY', 'size': '772.76'}], 'event_type': 'price_change', 'hash': 'e1156daa2bab54780fd066b20955abdceb37e5c4', 'market': '0x7aa4a910b31b2c4ddb09d1e3408e52aa8e09a14402f376070a44b1b85cb36d13', 'timestamp': '1733333162561'}
{'asset_id': '114416409796971863099144323163249651172534872992222856507897414949637892047507', 'changes': [{'price': '0.52', 'side': 'BUY', 'size': '772.76'}], 'event_type': 'price_change', 'hash': 'e1156daa2bab54780fd066b20955abdceb37e5c4', 'market': '0x7aa4a910b31b2c4ddb09d1e3408e52aa8e09a14402f376070a44b1b85cb36d13', 'timestamp': '1733333162561'}
{'asset_id': '114416409796971863099144323163249651172534872992222856507897414949637892047507', 'changes': [{'price': '0.54', 'side': 'SELL', 'size': '50'}], 'event_type': 'price_change', 'hash': '4cdb82ef51ea13a2193d641655b59ff8ff911221', 'market': '0x7aa4a910b31b2c4ddb09d1e3408e52aa8e09a14402f376070a44b1b85cb36d13', 'timestamp': '1733333162740'}
{'asset_id': '114416409796971863099144323163249651172534872992222856507897414949637892047507', 'changes': [{'price': '0.54', 'side': 'SELL', 'size': '50'}], 'event_type': 'price_change', 'hash': '4cdb82ef51ea13a2193d641655b59ff8ff911221', 'market': '0x7aa4a910b31b2c4ddb09d1e3408e52aa8e09a14402f376070a44b1b85cb36d13', 'timestamp': '1733333162740'}
{'asset_id': '114416409796971863099144323163249651172534872992222856507897414949637892047507', 'changes': [{'price': '0.55', 'side': 'SELL', 'size': '2914.23'}], 'event_type': 'price_change', 'hash': '187145ef2b8c14dab18b40d510f9408dcf548df4', 'market': '0x7aa4a910b31b2c4ddb09d1e3408e52aa8e09a14402f376070a44b1b85cb36d13', 'timestamp': '1733333162981'}
{'asset_id': '114416409796971863099144323163249651172534872992222856507897414949637892047507', 'changes': [{'price': '0.55', 'side': 'SELL', 'size': '2914.23'}], 'event_type': 'price_change', 'hash': '187145ef2b8c14dab18b40d510f9408dcf548df4', 'market': '0x7aa4a910b31b2c4ddb09d1e3408e52aa8e09a14402f376070a44b1b85cb36d13', 'timestamp': '1733333162981'}
{'asset_id': '114416409796971863099144323163249651172534872992222856507897414949637892047507', 'changes': [{'price': '0.55', 'side': 'SELL', 'size': '1714.23'}], 'event_type': 'price_change', 'hash': '4f7bc1f457535f00c86b72273264af317c829545', 'market': '0x7aa4a910b31b2c4ddb09d1e3408e52aa8e09a14402f376070a44b1b85cb36d13', 'timestamp': '1733333169011'}
{'asset_id': '114416409796971863099144323163249651172534872992222856507897414949637892047507', 'changes': [{'price': '0.55', 'side': 'SELL', 'size': '1714.23'}], 'event_type': 'price_change', 'hash': '4f7bc1f457535f00c86b72273264af317c829545', 'market': '0x7aa4a910b31b2c4ddb09d1e3408e52aa8e09a14402f376070a44b1b85cb36d13', 'timestamp': '1733333169011'}
{'asset_id': '114416409796971863099144323163249651172534872992222856507897414949637892047507', 'changes': [{'price': '0.56', 'side': 'SELL', 'size': '2361.75'}], 'event_type': 'price_change', 'hash': 'c607b47aa4261c1213d876cd20c6e68e8ffb2dd0', 'market': '0x7aa4a910b31b2c4ddb09d1e3408e52aa8e09a14402f376070a44b1b85cb36d13', 'timestamp': '1733333179180'}
{'asset_id': '114416409796971863099144323163249651172534872992222856507897414949637892047507', 'changes': [{'price': '0.56', 'side': 'SELL', 'size': '2361.75'}], 'event_type': 'price_change', 'hash': 'c607b47aa4261c1213d876cd20c6e68e8ffb2dd0', 'market': '0x7aa4a910b31b2c4ddb09d1e3408e52aa8e09a14402f376070a44b1b85cb36d13', 'timestamp': '1733333179180'}
{'asset_id': '114416409796971863099144323163249651172534872992222856507897414949637892047507', 'changes': [{'price': '0.54', 'side': 'SELL', 'size': '60.1'}], 'event_type': 'price_change', 'hash': '2053f3cc7cbc28ff87a866f28c504fce80b0b0bc', 'market': '0x7aa4a910b31b2c4ddb09d1e3408e52aa8e09a14402f376070a44b1b85cb36d13', 'timestamp': '1733333179496'}
{'asset_id': '114416409796971863099144323163249651172534872992222856507897414949637892047507', 'changes': [{'price': '0.54', 'side': 'SELL', 'size': '60.1'}], 'event_type': 'price_change', 'hash': '2053f3cc7cbc28ff87a866f28c504fce80b0b0bc', 'market': '0x7aa4a910b31b2c4ddb09d1e3408e52aa8e09a14402f376070a44b1b85cb36d13', 'timestamp': '1733333179496'}
{'asset_id': '114416409796971863099144323163249651172534872992222856507897414949637892047507', 'changes': [{'price': '0.5', 'side': 'BUY', 'size': '1115'}], 'event_type': 'price_change', 'hash': '40fd56b511f0661d9b93fa1591e401b80a24e7d1', 'market': '0x7aa4a910b31b2c4ddb09d1e3408e52aa8e09a14402f376070a44b1b85cb36d13', 'timestamp': '1733333181206'}
{'asset_id': '114416409796971863099144323163249651172534872992222856507897414949637892047507', 'changes': [{'price': '0.5', 'side': 'BUY', 'size': '1115'}], 'event_type': 'price_change', 'hash': '40fd56b511f0661d9b93fa1591e401b80a24e7d1', 'market': '0x7aa4a910b31b2c4ddb09d1e3408e52aa8e09a14402f376070a44b1b85cb36d13', 'timestamp': '1733333181206'}
{'asset_id': '114416409796971863099144323163249651172534872992222856507897414949637892047507', 'changes': [{'price': '0.5', 'side': 'BUY', 'size': '1215'}], 'event_type': 'price_change', 'hash': '742883bf648b0fc797b8892fe75b91b3f2231f37', 'market': '0x7aa4a910b31b2c4ddb09d1e3408e52aa8e09a14402f376070a44b1b85cb36d13', 'timestamp': '1733333183004'}
{'asset_id': '114416409796971863099144323163249651172534872992222856507897414949637892047507', 'changes': [{'price': '0.5', 'side': 'BUY', 'size': '1215'}], 'event_type': 'price_change', 'hash': '742883bf648b0fc797b8892fe75b91b3f2231f37', 'market': '0x7aa4a910b31b2c4ddb09d1e3408e52aa8e09a14402f376070a44b1b85cb36d13', 'timestamp': '1733333183004'}
{'asset_id': '114416409796971863099144323163249651172534872992222856507897414949637892047507', 'changes': [{'price': '0.5', 'side': 'BUY', 'size': '1115'}], 'event_type': 'price_change', 'hash': '52c0658b48bf06cf6d7f38475559346c34d18134', 'market': '0x7aa4a910b31b2c4ddb09d1e3408e52aa8e09a14402f376070a44b1b85cb36d13', 'timestamp': '1733333184676'}
{'asset_id': '114416409796971863099144323163249651172534872992222856507897414949637892047507', 'changes': [{'price': '0.5', 'side': 'BUY', 'size': '1115'}], 'event_type': 'price_change', 'hash': '52c0658b48bf06cf6d7f38475559346c34d18134', 'market': '0x7aa4a910b31b2c4ddb09d1e3408e52aa8e09a14402f376070a44b1b85cb36d13', 'timestamp': '1733333184676'}
{'asset_id': '114416409796971863099144323163249651172534872992222856507897414949637892047507', 'changes': [{'price': '0.51', 'side': 'BUY', 'size': '1186.18'}], 'event_type': 'price_change', 'hash': '87f1393b511c014c35db7b8e8adebe6690c9325e', 'market': '0x7aa4a910b31b2c4ddb09d1e3408e52aa8e09a14402f376070a44b1b85cb36d13', 'timestamp': '1733333185652'}
{'asset_id': '114416409796971863099144323163249651172534872992222856507897414949637892047507', 'changes': [{'price': '0.51', 'side': 'BUY', 'size': '1186.18'}], 'event_type': 'price_change', 'hash': '87f1393b511c014c35db7b8e8adebe6690c9325e', 'market': '0x7aa4a910b31b2c4ddb09d1e3408e52aa8e09a14402f376070a44b1b85cb36d13', 'timestamp': '1733333185652'}
{'asset_id': '114416409796971863099144323163249651172534872992222856507897414949637892047507', 'changes': [{'price': '0.49', 'side': 'BUY', 'size': '360'}], 'event_type': 'price_change', 'hash': 'a0448d686aa225e8ad52b04ec536986cb2bf2f14', 'market': '0x7aa4a910b31b2c4ddb09d1e3408e52aa8e09a14402f376070a44b1b85cb36d13', 'timestamp': '1733333187272'}
{'asset_id': '114416409796971863099144323163249651172534872992222856507897414949637892047507', 'changes': [{'price': '0.49', 'side': 'BUY', 'size': '360'}], 'event_type': 'price_change', 'hash': 'a0448d686aa225e8ad52b04ec536986cb2bf2f14', 'market': '0x7aa4a910b31b2c4ddb09d1e3408e52aa8e09a14402f376070a44b1b85cb36d13', 'timestamp': '1733333187272'}
{'asset_id': '114416409796971863099144323163249651172534872992222856507897414949637892047507', 'changes': [{'price': '0.5', 'side': 'BUY', 'size': '2315'}], 'event_type': 'price_change', 'hash': '20e34747427d1385ed7723f4627ff1e4049e26aa', 'market': '0x7aa4a910b31b2c4ddb09d1e3408e52aa8e09a14402f376070a44b1b85cb36d13', 'timestamp': '1733333187602'}
{'asset_id': '114416409796971863099144323163249651172534872992222856507897414949637892047507', 'changes': [{'price': '0.51', 'side': 'BUY', 'size': '1086.18'}], 'event_type': 'price_change', 'hash': '5f8f09b1e0a8217d32408d3dad5712c8fa0ed49e', 'market': '0x7aa4a910b31b2c4ddb09d1e3408e52aa8e09a14402f376070a44b1b85cb36d13', 'timestamp': '1733333191714'}
{'asset_id': '114416409796971863099144323163249651172534872992222856507897414949637892047507', 'changes': [{'price': '0.51', 'side': 'BUY', 'size': '1086.18'}], 'event_type': 'price_change', 'hash': '5f8f09b1e0a8217d32408d3dad5712c8fa0ed49e', 'market': '0x7aa4a910b31b2c4ddb09d1e3408e52aa8e09a14402f376070a44b1b85cb36d13', 'timestamp': '1733333191714'}
{'asset_id': '114416409796971863099144323163249651172534872992222856507897414949637892047507', 'changes': [{'price': '0.5', 'side': 'BUY', 'size': '2415'}], 'event_type': 'price_change', 'hash': '8cd43a9f9ad5bce6d1b2a62a4e40638025183340', 'market': '0x7aa4a910b31b2c4ddb09d1e3408e52aa8e09a14402f376070a44b1b85cb36d13', 'timestamp': '1733333192489'}
{'asset_id': '114416409796971863099144323163249651172534872992222856507897414949637892047507', 'changes': [{'price': '0.5', 'side': 'BUY', 'size': '2415'}], 'event_type': 'price_change', 'hash': '8cd43a9f9ad5bce6d1b2a62a4e40638025183340', 'market': '0x7aa4a910b31b2c4ddb09d1e3408e52aa8e09a14402f376070a44b1b85cb36d13', 'timestamp': '1733333192489'}
{'asset_id': '114416409796971863099144323163249651172534872992222856507897414949637892047507', 'changes': [{'price': '0.5', 'side': 'BUY', 'size': '2315'}], 'event_type': 'price_change', 'hash': '4b52835a0d4f9a8f6779ea318ff2fa028972ff0f', 'market': '0x7aa4a910b31b2c4ddb09d1e3408e52aa8e09a14402f376070a44b1b85cb36d13', 'timestamp': '1733333193319'}
{'asset_id': '114416409796971863099144323163249651172534872992222856507897414949637892047507', 'changes': [{'price': '0.5', 'side': 'BUY', 'size': '2315'}], 'event_type': 'price_change', 'hash': '4b52835a0d4f9a8f6779ea318ff2fa028972ff0f', 'market': '0x7aa4a910b31b2c4ddb09d1e3408e52aa8e09a14402f376070a44b1b85cb36d13', 'timestamp': '1733333193319'}
{'asset_id': '114416409796971863099144323163249651172534872992222856507897414949637892047507', 'changes': [{'price': '0.51', 'side': 'BUY', 'size': '1186.18'}], 'event_type': 'price_change', 'hash': '36b6501e2398b0a23456415a44fecb056511e03f', 'market': '0x7aa4a910b31b2c4ddb09d1e3408e52aa8e09a14402f376070a44b1b85cb36d13', 'timestamp': '1733333194138'}
{'asset_id': '114416409796971863099144323163249651172534872992222856507897414949637892047507', 'changes': [{'price': '0.51', 'side': 'BUY', 'size': '1186.18'}], 'event_type': 'price_change', 'hash': '36b6501e2398b0a23456415a44fecb056511e03f', 'market': '0x7aa4a910b31b2c4ddb09d1e3408e52aa8e09a14402f376070a44b1b85cb36d13', 'timestamp': '1733333194138'}
{'asset_id': '114416409796971863099144323163249651172534872992222856507897414949637892047507', 'changes': [{'price': '0.48', 'side': 'BUY', 'size': '342.18'}], 'event_type': 'price_change', 'hash': '839a699a9b718c8e36d68716a284e37995001c45', 'market': '0x7aa4a910b31b2c4ddb09d1e3408e52aa8e09a14402f376070a44b1b85cb36d13', 'timestamp': '1733333194990'}
{'asset_id': '114416409796971863099144323163249651172534872992222856507897414949637892047507', 'changes': [{'price': '0.48', 'side': 'BUY', 'size': '342.18'}], 'event_type': 'price_change', 'hash': '839a699a9b718c8e36d68716a284e37995001c45', 'market': '0x7aa4a910b31b2c4ddb09d1e3408e52aa8e09a14402f376070a44b1b85cb36d13', 'timestamp': '1733333194990'}
{'asset_id': '114416409796971863099144323163249651172534872992222856507897414949637892047507', 'changes': [{'price': '0.49', 'side': 'BUY', 'size': '1860'}], 'event_type': 'price_change', 'hash': 'dc3ded00016edb44efd8350bcf89e1efae895382', 'market': '0x7aa4a910b31b2c4ddb09d1e3408e52aa8e09a14402f376070a44b1b85cb36d13', 'timestamp': '1733333196464'}
{'asset_id': '114416409796971863099144323163249651172534872992222856507897414949637892047507', 'changes': [{'price': '0.49', 'side': 'BUY', 'size': '1860'}], 'event_type': 'price_change', 'hash': 'dc3ded00016edb44efd8350bcf89e1efae895382', 'market': '0x7aa4a910b31b2c4ddb09d1e3408e52aa8e09a14402f376070a44b1b85cb36d13', 'timestamp': '1733333196464'}
{'asset_id': '114416409796971863099144323163249651172534872992222856507897414949637892047507', 'changes': [{'price': '0.51', 'side': 'BUY', 'size': '1086.18'}], 'event_type': 'price_change', 'hash': '75a12dce1a21d140329d3ed3b1950b0b8d51b11f', 'market': '0x7aa4a910b31b2c4ddb09d1e3408e52aa8e09a14402f376070a44b1b85cb36d13', 'timestamp': '1733333201054'}
{'asset_id': '114416409796971863099144323163249651172534872992222856507897414949637892047507', 'changes': [{'price': '0.51', 'side': 'BUY', 'size': '1086.18'}], 'event_type': 'price_change', 'hash': '75a12dce1a21d140329d3ed3b1950b0b8d51b11f', 'market': '0x7aa4a910b31b2c4ddb09d1e3408e52aa8e09a14402f376070a44b1b85cb36d13', 'timestamp': '1733333201054'}
{'asset_id': '114416409796971863099144323163249651172534872992222856507897414949637892047507', 'changes': [{'price': '0.5', 'side': 'BUY', 'size': '2415'}], 'event_type': 'price_change', 'hash': '2f9e05cbd08fdc12d5ebc5201b6f1762c238ad53', 'market': '0x7aa4a910b31b2c4ddb09d1e3408e52aa8e09a14402f376070a44b1b85cb36d13', 'timestamp': '1733333201930'}
{'asset_id': '114416409796971863099144323163249651172534872992222856507897414949637892047507', 'changes': [{'price': '0.5', 'side': 'BUY', 'size': '2415'}], 'event_type': 'price_change', 'hash': '2f9e05cbd08fdc12d5ebc5201b6f1762c238ad53', 'market': '0x7aa4a910b31b2c4ddb09d1e3408e52aa8e09a14402f376070a44b1b85cb36d13', 'timestamp': '1733333201930'}
{'asset_id': '114416409796971863099144323163249651172534872992222856507897414949637892047507', 'changes': [{'price': '0.5', 'side': 'BUY', 'size': '2315'}], 'event_type': 'price_change', 'hash': '3468a5e3482bad628ba194002b2722d1c6ddca5e', 'market': '0x7aa4a910b31b2c4ddb09d1e3408e52aa8e09a14402f376070a44b1b85cb36d13', 'timestamp': '1733333210870'}
{'asset_id': '114416409796971863099144323163249651172534872992222856507897414949637892047507', 'changes': [{'price': '0.5', 'side': 'BUY', 'size': '2315'}], 'event_type': 'price_change', 'hash': '3468a5e3482bad628ba194002b2722d1c6ddca5e', 'market': '0x7aa4a910b31b2c4ddb09d1e3408e52aa8e09a14402f376070a44b1b85cb36d13', 'timestamp': '1733333210870'}
{'asset_id': '114416409796971863099144323163249651172534872992222856507897414949637892047507', 'changes': [{'price': '0.5', 'side': 'BUY', 'size': '1115'}, {'price': '0.56', 'side': 'SELL', 'size': '1161.75'}], 'event_type': 'price_change', 'hash': '270fb2db06735e5464bcdc2b41b51c17b5cfcd0d', 'market': '0x7aa4a910b31b2c4ddb09d1e3408e52aa8e09a14402f376070a44b1b85cb36d13', 'timestamp': '1733333212800'}
{'asset_id': '114416409796971863099144323163249651172534872992222856507897414949637892047507', 'changes': [{'price': '0.5', 'side': 'BUY', 'size': '1115'}, {'price': '0.56', 'side': 'SELL', 'size': '1161.75'}], 'event_type': 'price_change', 'hash': '270fb2db06735e5464bcdc2b41b51c17b5cfcd0d', 'market': '0x7aa4a910b31b2c4ddb09d1e3408e52aa8e09a14402f376070a44b1b85cb36d13', 'timestamp': '1733333212800'}
{'asset_id': '114416409796971863099144323163249651172534872992222856507897414949637892047507', 'changes': [{'price': '0.46', 'side': 'BUY', 'size': '0'}, {'price': '0.55', 'side': 'SELL', 'size': '1214.23'}, {'price': '0.5', 'side': 'BUY', 'size': '115'}], 'event_type': 'price_change', 'hash': 'a7e4332d57724847e8ef2b20f1bd7495176f6adf', 'market': '0x7aa4a910b31b2c4ddb09d1e3408e52aa8e09a14402f376070a44b1b85cb36d13', 'timestamp': '1733333216515'}
{'asset_id': '114416409796971863099144323163249651172534872992222856507897414949637892047507', 'changes': [{'price': '0.46', 'side': 'BUY', 'size': '0'}, {'price': '0.55', 'side': 'SELL', 'size': '1214.23'}, {'price': '0.5', 'side': 'BUY', 'size': '115'}], 'event_type': 'price_change', 'hash': 'a7e4332d57724847e8ef2b20f1bd7495176f6adf', 'market': '0x7aa4a910b31b2c4ddb09d1e3408e52aa8e09a14402f376070a44b1b85cb36d13', 'timestamp': '1733333216515'}
{'asset_id': '114416409796971863099144323163249651172534872992222856507897414949637892047507', 'changes': [{'price': '0.45', 'side': 'BUY', 'size': '978'}], 'event_type': 'price_change', 'hash': '1d2598fcc855999c2d1844353349f151f48150a2', 'market': '0x7aa4a910b31b2c4ddb09d1e3408e52aa8e09a14402f376070a44b1b85cb36d13', 'timestamp': '1733333217568'}
{'asset_id': '114416409796971863099144323163249651172534872992222856507897414949637892047507', 'changes': [{'price': '0.45', 'side': 'BUY', 'size': '978'}], 'event_type': 'price_change', 'hash': '1d2598fcc855999c2d1844353349f151f48150a2', 'market': '0x7aa4a910b31b2c4ddb09d1e3408e52aa8e09a14402f376070a44b1b85cb36d13', 'timestamp': '1733333217568'}
{'asset_id': '114416409796971863099144323163249651172534872992222856507897414949637892047507', 'changes': [{'price': '0.54', 'side': 'SELL', 'size': '560.1'}], 'event_type': 'price_change', 'hash': 'ded658adac78d404add152d5c69bf503523a7d0c', 'market': '0x7aa4a910b31b2c4ddb09d1e3408e52aa8e09a14402f376070a44b1b85cb36d13', 'timestamp': '1733333217987'}
{'asset_id': '114416409796971863099144323163249651172534872992222856507897414949637892047507', 'changes': [{'price': '0.54', 'side': 'SELL', 'size': '560.1'}], 'event_type': 'price_change', 'hash': 'ded658adac78d404add152d5c69bf503523a7d0c', 'market': '0x7aa4a910b31b2c4ddb09d1e3408e52aa8e09a14402f376070a44b1b85cb36d13', 'timestamp': '1733333217987'}
{'asset_id': '114416409796971863099144323163249651172534872992222856507897414949637892047507', 'changes': [{'price': '0.5', 'side': 'BUY', 'size': '1115'}], 'event_type': 'price_change', 'hash': 'cd65c426d90150bc2d18893160e01b93b4afc3ba', 'market': '0x7aa4a910b31b2c4ddb09d1e3408e52aa8e09a14402f376070a44b1b85cb36d13', 'timestamp': '1733333218423'}
{'asset_id': '114416409796971863099144323163249651172534872992222856507897414949637892047507', 'changes': [{'price': '0.5', 'side': 'BUY', 'size': '1115'}], 'event_type': 'price_change', 'hash': 'cd65c426d90150bc2d18893160e01b93b4afc3ba', 'market': '0x7aa4a910b31b2c4ddb09d1e3408e52aa8e09a14402f376070a44b1b85cb36d13', 'timestamp': '1733333218423'}
{'asset_id': '114416409796971863099144323163249651172534872992222856507897414949637892047507', 'changes': [{'price': '0.49', 'side': 'BUY', 'size': '3060'}, {'price': '0.55', 'side': 'SELL', 'size': '2414.23'}], 'event_type': 'price_change', 'hash': '0ea2bcb79a759db17aef75012b4ba4d94aeddbc7', 'market': '0x7aa4a910b31b2c4ddb09d1e3408e52aa8e09a14402f376070a44b1b85cb36d13', 'timestamp': '1733333219581'}
{'asset_id': '114416409796971863099144323163249651172534872992222856507897414949637892047507', 'changes': [{'price': '0.49', 'side': 'BUY', 'size': '3060'}, {'price': '0.55', 'side': 'SELL', 'size': '2414.23'}], 'event_type': 'price_change', 'hash': '0ea2bcb79a759db17aef75012b4ba4d94aeddbc7', 'market': '0x7aa4a910b31b2c4ddb09d1e3408e52aa8e09a14402f376070a44b1b85cb36d13', 'timestamp': '1733333219581'}
{'asset_id': '114416409796971863099144323163249651172534872992222856507897414949637892047507', 'changes': [{'price': '0.55', 'side': 'SELL', 'size': '2389.22'}], 'event_type': 'price_change', 'hash': '3775837f7cc671108c8f00a23a3aeea5a672674d', 'market': '0x7aa4a910b31b2c4ddb09d1e3408e52aa8e09a14402f376070a44b1b85cb36d13', 'timestamp': '1733333219878'}
{'asset_id': '114416409796971863099144323163249651172534872992222856507897414949637892047507', 'changes': [{'price': '0.55', 'side': 'SELL', 'size': '2389.22'}], 'event_type': 'price_change', 'hash': '3775837f7cc671108c8f00a23a3aeea5a672674d', 'market': '0x7aa4a910b31b2c4ddb09d1e3408e52aa8e09a14402f376070a44b1b85cb36d13', 'timestamp': '1733333219878'}
{'asset_id': '114416409796971863099144323163249651172534872992222856507897414949637892047507', 'changes': [{'price': '0.54', 'side': 'SELL', 'size': '585.11'}], 'event_type': 'price_change', 'hash': '54238b7820ec27f3b84a09fba3e99537641fb862', 'market': '0x7aa4a910b31b2c4ddb09d1e3408e52aa8e09a14402f376070a44b1b85cb36d13', 'timestamp': '1733333220140'}
{'asset_id': '114416409796971863099144323163249651172534872992222856507897414949637892047507', 'changes': [{'price': '0.54', 'side': 'SELL', 'size': '585.11'}], 'event_type': 'price_change', 'hash': '54238b7820ec27f3b84a09fba3e99537641fb862', 'market': '0x7aa4a910b31b2c4ddb09d1e3408e52aa8e09a14402f376070a44b1b85cb36d13', 'timestamp': '1733333220140'}
{'asset_id': '114416409796971863099144323163249651172534872992222856507897414949637892047507', 'changes': [{'price': '0.55', 'side': 'SELL', 'size': '2289.22'}], 'event_type': 'price_change', 'hash': '5feb643ba0bedbc9df307214f18fd8dd99434d75', 'market': '0x7aa4a910b31b2c4ddb09d1e3408e52aa8e09a14402f376070a44b1b85cb36d13', 'timestamp': '1733333222190'}
{'asset_id': '114416409796971863099144323163249651172534872992222856507897414949637892047507', 'changes': [{'price': '0.55', 'side': 'SELL', 'size': '2289.22'}], 'event_type': 'price_change', 'hash': '5feb643ba0bedbc9df307214f18fd8dd99434d75', 'market': '0x7aa4a910b31b2c4ddb09d1e3408e52aa8e09a14402f376070a44b1b85cb36d13', 'timestamp': '1733333222190'}
{'asset_id': '114416409796971863099144323163249651172534872992222856507897414949637892047507', 'changes': [{'price': '0.54', 'side': 'SELL', 'size': '685.11'}], 'event_type': 'price_change', 'hash': 'ae88f34812a7253e3924f21bb914cb5e43f6de5a', 'market': '0x7aa4a910b31b2c4ddb09d1e3408e52aa8e09a14402f376070a44b1b85cb36d13', 'timestamp': '1733333222373'}
{'asset_id': '114416409796971863099144323163249651172534872992222856507897414949637892047507', 'changes': [{'price': '0.54', 'side': 'SELL', 'size': '685.11'}], 'event_type': 'price_change', 'hash': 'ae88f34812a7253e3924f21bb914cb5e43f6de5a', 'market': '0x7aa4a910b31b2c4ddb09d1e3408e52aa8e09a14402f376070a44b1b85cb36d13', 'timestamp': '1733333222373'}
{'asset_id': '114416409796971863099144323163249651172534872992222856507897414949637892047507', 'changes': [{'price': '0.5', 'side': 'BUY', 'size': '1215'}], 'event_type': 'price_change', 'hash': '73656e446e5dac35f8a0606799caf8e84feab913', 'market': '0x7aa4a910b31b2c4ddb09d1e3408e52aa8e09a14402f376070a44b1b85cb36d13', 'timestamp': '1733333227654'}
{'asset_id': '114416409796971863099144323163249651172534872992222856507897414949637892047507', 'changes': [{'price': '0.5', 'side': 'BUY', 'size': '1215'}], 'event_type': 'price_change', 'hash': '73656e446e5dac35f8a0606799caf8e84feab913', 'market': '0x7aa4a910b31b2c4ddb09d1e3408e52aa8e09a14402f376070a44b1b85cb36d13', 'timestamp': '1733333227654'}
{'asset_id': '114416409796971863099144323163249651172534872992222856507897414949637892047507', 'changes': [{'price': '0.57', 'side': 'SELL', 'size': '350.1'}], 'event_type': 'price_change', 'hash': 'acb63987b15b8f30ded370bead0904c86e376580', 'market': '0x7aa4a910b31b2c4ddb09d1e3408e52aa8e09a14402f376070a44b1b85cb36d13', 'timestamp': '1733333231020'}
{'asset_id': '114416409796971863099144323163249651172534872992222856507897414949637892047507', 'changes': [{'price': '0.57', 'side': 'SELL', 'size': '350.1'}], 'event_type': 'price_change', 'hash': 'acb63987b15b8f30ded370bead0904c86e376580', 'market': '0x7aa4a910b31b2c4ddb09d1e3408e52aa8e09a14402f376070a44b1b85cb36d13', 'timestamp': '1733333231020'}
{'asset_id': '114416409796971863099144323163249651172534872992222856507897414949637892047507', 'changes': [{'price': '0.52', 'side': 'BUY', 'size': '762.77'}], 'event_type': 'price_change', 'hash': '0c7a70bfe270016bde32d2ba44ce95fa06151c1c', 'market': '0x7aa4a910b31b2c4ddb09d1e3408e52aa8e09a14402f376070a44b1b85cb36d13', 'timestamp': '1733333232706'}
{'asset_id': '114416409796971863099144323163249651172534872992222856507897414949637892047507', 'changes': [{'price': '0.52', 'side': 'BUY', 'size': '762.77'}], 'event_type': 'price_change', 'hash': '0c7a70bfe270016bde32d2ba44ce95fa06151c1c', 'market': '0x7aa4a910b31b2c4ddb09d1e3408e52aa8e09a14402f376070a44b1b85cb36d13', 'timestamp': '1733333232706'}
{'asset_id': '114416409796971863099144323163249651172534872992222856507897414949637892047507', 'changes': [{'price': '0.56', 'side': 'SELL', 'size': '2661.75'}], 'event_type': 'price_change', 'hash': '02c32e6c4c45d28d50b00878e3aca4f4bbc51229', 'market': '0x7aa4a910b31b2c4ddb09d1e3408e52aa8e09a14402f376070a44b1b85cb36d13', 'timestamp': '1733333233930'}
{'asset_id': '114416409796971863099144323163249651172534872992222856507897414949637892047507', 'changes': [{'price': '0.56', 'side': 'SELL', 'size': '2661.75'}], 'event_type': 'price_change', 'hash': '02c32e6c4c45d28d50b00878e3aca4f4bbc51229', 'market': '0x7aa4a910b31b2c4ddb09d1e3408e52aa8e09a14402f376070a44b1b85cb36d13', 'timestamp': '1733333233930'}
{'asset_id': '114416409796971863099144323163249651172534872992222856507897414949637892047507', 'changes': [{'price': '0.52', 'side': 'BUY', 'size': '772.76'}], 'event_type': 'price_change', 'hash': 'bd0a1bf61424d5053e9b8712d900a7c44531b7bc', 'market': '0x7aa4a910b31b2c4ddb09d1e3408e52aa8e09a14402f376070a44b1b85cb36d13', 'timestamp': '1733333236616'}
{'asset_id': '114416409796971863099144323163249651172534872992222856507897414949637892047507', 'changes': [{'price': '0.52', 'side': 'BUY', 'size': '772.76'}], 'event_type': 'price_change', 'hash': 'bd0a1bf61424d5053e9b8712d900a7c44531b7bc', 'market': '0x7aa4a910b31b2c4ddb09d1e3408e52aa8e09a14402f376070a44b1b85cb36d13', 'timestamp': '1733333236616'}
{'asset_id': '114416409796971863099144323163249651172534872992222856507897414949637892047507', 'changes': [{'price': '0.33', 'side': 'BUY', 'size': '620'}], 'event_type': 'price_change', 'hash': '935805d207cc67218e9a79f32d366f675f58a3ab', 'market': '0x7aa4a910b31b2c4ddb09d1e3408e52aa8e09a14402f376070a44b1b85cb36d13', 'timestamp': '1733333246010'}
{'asset_id': '114416409796971863099144323163249651172534872992222856507897414949637892047507', 'changes': [{'price': '0.33', 'side': 'BUY', 'size': '620'}], 'event_type': 'price_change', 'hash': '935805d207cc67218e9a79f32d366f675f58a3ab', 'market': '0x7aa4a910b31b2c4ddb09d1e3408e52aa8e09a14402f376070a44b1b85cb36d13', 'timestamp': '1733333246010'}
{'asset_id': '114416409796971863099144323163249651172534872992222856507897414949637892047507', 'changes': [{'price': '0.34', 'side': 'BUY', 'size': '4000'}], 'event_type': 'price_change', 'hash': '4a92e04fd2dce04e7d9d1de8101a1e9d0eaa08cb', 'market': '0x7aa4a910b31b2c4ddb09d1e3408e52aa8e09a14402f376070a44b1b85cb36d13', 'timestamp': '1733333249147'}
{'asset_id': '114416409796971863099144323163249651172534872992222856507897414949637892047507', 'changes': [{'price': '0.34', 'side': 'BUY', 'size': '4000'}], 'event_type': 'price_change', 'hash': '4a92e04fd2dce04e7d9d1de8101a1e9d0eaa08cb', 'market': '0x7aa4a910b31b2c4ddb09d1e3408e52aa8e09a14402f376070a44b1b85cb36d13', 'timestamp': '1733333249147'}
{'asset_id': '114416409796971863099144323163249651172534872992222856507897414949637892047507', 'changes': [{'price': '0.5', 'side': 'BUY', 'size': '1115'}], 'event_type': 'price_change', 'hash': 'e033ee5e9a45dd5459b91265b45aed30f5949d84', 'market': '0x7aa4a910b31b2c4ddb09d1e3408e52aa8e09a14402f376070a44b1b85cb36d13', 'timestamp': '1733333261615'}
{'asset_id': '114416409796971863099144323163249651172534872992222856507897414949637892047507', 'changes': [{'price': '0.5', 'side': 'BUY', 'size': '1115'}], 'event_type': 'price_change', 'hash': 'e033ee5e9a45dd5459b91265b45aed30f5949d84', 'market': '0x7aa4a910b31b2c4ddb09d1e3408e52aa8e09a14402f376070a44b1b85cb36d13', 'timestamp': '1733333261615'}
{'asset_id': '114416409796971863099144323163249651172534872992222856507897414949637892047507', 'changes': [{'price': '0.51', 'side': 'BUY', 'size': '1186.18'}], 'event_type': 'price_change', 'hash': 'ea8573c4fb496b7d8ed3bb2daf5abc76d317287b', 'market': '0x7aa4a910b31b2c4ddb09d1e3408e52aa8e09a14402f376070a44b1b85cb36d13', 'timestamp': '1733333262635'}
{'asset_id': '114416409796971863099144323163249651172534872992222856507897414949637892047507', 'changes': [{'price': '0.51', 'side': 'BUY', 'size': '1186.18'}], 'event_type': 'price_change', 'hash': 'ea8573c4fb496b7d8ed3bb2daf5abc76d317287b', 'market': '0x7aa4a910b31b2c4ddb09d1e3408e52aa8e09a14402f376070a44b1b85cb36d13', 'timestamp': '1733333262635'}
{'asset_id': '114416409796971863099144323163249651172534872992222856507897414949637892047507', 'changes': [{'price': '0.51', 'side': 'BUY', 'size': '1086.18'}], 'event_type': 'price_change', 'hash': 'b097c771b16683aae5e106318a7292c83985eb25', 'market': '0x7aa4a910b31b2c4ddb09d1e3408e52aa8e09a14402f376070a44b1b85cb36d13', 'timestamp': '1733333263256'}
{'asset_id': '114416409796971863099144323163249651172534872992222856507897414949637892047507', 'changes': [{'price': '0.51', 'side': 'BUY', 'size': '1086.18'}], 'event_type': 'price_change', 'hash': 'b097c771b16683aae5e106318a7292c83985eb25', 'market': '0x7aa4a910b31b2c4ddb09d1e3408e52aa8e09a14402f376070a44b1b85cb36d13', 'timestamp': '1733333263256'}
{'asset_id': '114416409796971863099144323163249651172534872992222856507897414949637892047507', 'changes': [{'price': '0.5', 'side': 'BUY', 'size': '1215'}], 'event_type': 'price_change', 'hash': '53086361565a107c228312922c0d14032b6b7838', 'market': '0x7aa4a910b31b2c4ddb09d1e3408e52aa8e09a14402f376070a44b1b85cb36d13', 'timestamp': '1733333264082'}
{'asset_id': '114416409796971863099144323163249651172534872992222856507897414949637892047507', 'changes': [{'price': '0.5', 'side': 'BUY', 'size': '1215'}], 'event_type': 'price_change', 'hash': '53086361565a107c228312922c0d14032b6b7838', 'market': '0x7aa4a910b31b2c4ddb09d1e3408e52aa8e09a14402f376070a44b1b85cb36d13', 'timestamp': '1733333264082'}
{'asset_id': '114416409796971863099144323163249651172534872992222856507897414949637892047507', 'changes': [{'price': '0.5', 'side': 'BUY', 'size': '1115'}], 'event_type': 'price_change', 'hash': '614ef60725d930e2cdd129d47eeee8a31337e751', 'market': '0x7aa4a910b31b2c4ddb09d1e3408e52aa8e09a14402f376070a44b1b85cb36d13', 'timestamp': '1733333265738'}
{'asset_id': '114416409796971863099144323163249651172534872992222856507897414949637892047507', 'changes': [{'price': '0.5', 'side': 'BUY', 'size': '1115'}], 'event_type': 'price_change', 'hash': '614ef60725d930e2cdd129d47eeee8a31337e751', 'market': '0x7aa4a910b31b2c4ddb09d1e3408e52aa8e09a14402f376070a44b1b85cb36d13', 'timestamp': '1733333265738'}
{'asset_id': '114416409796971863099144323163249651172534872992222856507897414949637892047507', 'changes': [{'price': '0.45', 'side': 'BUY', 'size': '478'}, {'price': '0.54', 'side': 'SELL', 'size': '185.11'}, {'price': '0.5', 'side': 'BUY', 'size': '115'}], 'event_type': 'price_change', 'hash': '3abb609a8734d42f858ca191ab9227e49d37db33', 'market': '0x7aa4a910b31b2c4ddb09d1e3408e52aa8e09a14402f376070a44b1b85cb36d13', 'timestamp': '1733333265962'}
{'asset_id': '114416409796971863099144323163249651172534872992222856507897414949637892047507', 'changes': [{'price': '0.45', 'side': 'BUY', 'size': '478'}, {'price': '0.54', 'side': 'SELL', 'size': '185.11'}, {'price': '0.5', 'side': 'BUY', 'size': '115'}], 'event_type': 'price_change', 'hash': '3abb609a8734d42f858ca191ab9227e49d37db33', 'market': '0x7aa4a910b31b2c4ddb09d1e3408e52aa8e09a14402f376070a44b1b85cb36d13', 'timestamp': '1733333265962'}
{'asset_id': '114416409796971863099144323163249651172534872992222856507897414949637892047507', 'changes': [{'price': '0.51', 'side': 'BUY', 'size': '1186.18'}], 'event_type': 'price_change', 'hash': '98c6cfa3d6e10477d4bf7e15be9f6fe788be6a97', 'market': '0x7aa4a910b31b2c4ddb09d1e3408e52aa8e09a14402f376070a44b1b85cb36d13', 'timestamp': '1733333266625'}
{'asset_id': '114416409796971863099144323163249651172534872992222856507897414949637892047507', 'changes': [{'price': '0.51', 'side': 'BUY', 'size': '1186.18'}], 'event_type': 'price_change', 'hash': '98c6cfa3d6e10477d4bf7e15be9f6fe788be6a97', 'market': '0x7aa4a910b31b2c4ddb09d1e3408e52aa8e09a14402f376070a44b1b85cb36d13', 'timestamp': '1733333266625'}
{'asset_id': '114416409796971863099144323163249651172534872992222856507897414949637892047507', 'changes': [{'price': '0.46', 'side': 'BUY', 'size': '500'}], 'event_type': 'price_change', 'hash': '4455c0b6168e063a04b08131d97bbe4759849638', 'market': '0x7aa4a910b31b2c4ddb09d1e3408e52aa8e09a14402f376070a44b1b85cb36d13', 'timestamp': '1733333267042'}
{'asset_id': '114416409796971863099144323163249651172534872992222856507897414949637892047507', 'changes': [{'price': '0.46', 'side': 'BUY', 'size': '500'}], 'event_type': 'price_change', 'hash': '4455c0b6168e063a04b08131d97bbe4759849638', 'market': '0x7aa4a910b31b2c4ddb09d1e3408e52aa8e09a14402f376070a44b1b85cb36d13', 'timestamp': '1733333267042'}
{'asset_id': '114416409796971863099144323163249651172534872992222856507897414949637892047507', 'changes': [{'price': '0.55', 'side': 'SELL', 'size': '2789.22'}], 'event_type': 'price_change', 'hash': 'bb23d3c6f87a0a737218d6db1dcefc082a89daaa', 'market': '0x7aa4a910b31b2c4ddb09d1e3408e52aa8e09a14402f376070a44b1b85cb36d13', 'timestamp': '1733333267416'}
{'asset_id': '114416409796971863099144323163249651172534872992222856507897414949637892047507', 'changes': [{'price': '0.55', 'side': 'SELL', 'size': '2789.22'}], 'event_type': 'price_change', 'hash': 'bb23d3c6f87a0a737218d6db1dcefc082a89daaa', 'market': '0x7aa4a910b31b2c4ddb09d1e3408e52aa8e09a14402f376070a44b1b85cb36d13', 'timestamp': '1733333267416'}
{'asset_id': '114416409796971863099144323163249651172534872992222856507897414949637892047507', 'changes': [{'price': '0.5', 'side': 'BUY', 'size': '1115'}], 'event_type': 'price_change', 'hash': 'f2afd270c25dc0226142bbfdae255185ce01edb0', 'market': '0x7aa4a910b31b2c4ddb09d1e3408e52aa8e09a14402f376070a44b1b85cb36d13', 'timestamp': '1733333267790'}
{'asset_id': '114416409796971863099144323163249651172534872992222856507897414949637892047507', 'changes': [{'price': '0.5', 'side': 'BUY', 'size': '1115'}], 'event_type': 'price_change', 'hash': 'f2afd270c25dc0226142bbfdae255185ce01edb0', 'market': '0x7aa4a910b31b2c4ddb09d1e3408e52aa8e09a14402f376070a44b1b85cb36d13', 'timestamp': '1733333267790'}
{'asset_id': '114416409796971863099144323163249651172534872992222856507897414949637892047507', 'changes': [{'price': '0.54', 'side': 'SELL', 'size': '85.11'}], 'event_type': 'price_change', 'hash': '046e081936a6f16e5dfdbd5bf3f5732e66f463f4', 'market': '0x7aa4a910b31b2c4ddb09d1e3408e52aa8e09a14402f376070a44b1b85cb36d13', 'timestamp': '1733333267943'}
{'asset_id': '114416409796971863099144323163249651172534872992222856507897414949637892047507', 'changes': [{'price': '0.54', 'side': 'SELL', 'size': '85.11'}], 'event_type': 'price_change', 'hash': '046e081936a6f16e5dfdbd5bf3f5732e66f463f4', 'market': '0x7aa4a910b31b2c4ddb09d1e3408e52aa8e09a14402f376070a44b1b85cb36d13', 'timestamp': '1733333267943'}
{'asset_id': '114416409796971863099144323163249651172534872992222856507897414949637892047507', 'changes': [{'price': '0.55', 'side': 'SELL', 'size': '2889.22'}], 'event_type': 'price_change', 'hash': 'd8a469787853d6e451b0da5117fd314b4f5ae36a', 'market': '0x7aa4a910b31b2c4ddb09d1e3408e52aa8e09a14402f376070a44b1b85cb36d13', 'timestamp': '1733333268168'}
{'asset_id': '114416409796971863099144323163249651172534872992222856507897414949637892047507', 'changes': [{'price': '0.55', 'side': 'SELL', 'size': '2889.22'}], 'event_type': 'price_change', 'hash': 'd8a469787853d6e451b0da5117fd314b4f5ae36a', 'market': '0x7aa4a910b31b2c4ddb09d1e3408e52aa8e09a14402f376070a44b1b85cb36d13', 'timestamp': '1733333268168'}
{'asset_id': '114416409796971863099144323163249651172534872992222856507897414949637892047507', 'changes': [{'price': '0.54', 'side': 'SELL', 'size': '60.1'}], 'event_type': 'price_change', 'hash': '4ad64cacf1f307b992e667ff5d07e2583754535f', 'market': '0x7aa4a910b31b2c4ddb09d1e3408e52aa8e09a14402f376070a44b1b85cb36d13', 'timestamp': '1733333269981'}
{'asset_id': '114416409796971863099144323163249651172534872992222856507897414949637892047507', 'changes': [{'price': '0.54', 'side': 'SELL', 'size': '60.1'}], 'event_type': 'price_change', 'hash': '4ad64cacf1f307b992e667ff5d07e2583754535f', 'market': '0x7aa4a910b31b2c4ddb09d1e3408e52aa8e09a14402f376070a44b1b85cb36d13', 'timestamp': '1733333269981'}
{'asset_id': '114416409796971863099144323163249651172534872992222856507897414949637892047507', 'changes': [{'price': '0.55', 'side': 'SELL', 'size': '2914.23'}], 'event_type': 'price_change', 'hash': 'f4488b25757982ed5266c1861408d4a083ff380c', 'market': '0x7aa4a910b31b2c4ddb09d1e3408e52aa8e09a14402f376070a44b1b85cb36d13', 'timestamp': '1733333270152'}
{'asset_id': '114416409796971863099144323163249651172534872992222856507897414949637892047507', 'changes': [{'price': '0.55', 'side': 'SELL', 'size': '2914.23'}], 'event_type': 'price_change', 'hash': 'f4488b25757982ed5266c1861408d4a083ff380c', 'market': '0x7aa4a910b31b2c4ddb09d1e3408e52aa8e09a14402f376070a44b1b85cb36d13', 'timestamp': '1733333270152'}
{'asset_id': '114416409796971863099144323163249651172534872992222856507897414949637892047507', 'changes': [{'price': '0.49', 'side': 'BUY', 'size': '1860'}], 'event_type': 'price_change', 'hash': '9c28d9163777b6ab0a5c8e8885a5402116b264a2', 'market': '0x7aa4a910b31b2c4ddb09d1e3408e52aa8e09a14402f376070a44b1b85cb36d13', 'timestamp': '1733333276045'}
{'asset_id': '114416409796971863099144323163249651172534872992222856507897414949637892047507', 'changes': [{'price': '0.49', 'side': 'BUY', 'size': '1860'}], 'event_type': 'price_change', 'hash': '9c28d9163777b6ab0a5c8e8885a5402116b264a2', 'market': '0x7aa4a910b31b2c4ddb09d1e3408e52aa8e09a14402f376070a44b1b85cb36d13', 'timestamp': '1733333276045'}
{'asset_id': '114416409796971863099144323163249651172534872992222856507897414949637892047507', 'changes': [{'price': '0.5', 'side': 'BUY', 'size': '2315'}], 'event_type': 'price_change', 'hash': '5a13dd2531d7075055dd7a83fdc8ba460a23537e', 'market': '0x7aa4a910b31b2c4ddb09d1e3408e52aa8e09a14402f376070a44b1b85cb36d13', 'timestamp': '1733333283022'}
{'asset_id': '114416409796971863099144323163249651172534872992222856507897414949637892047507', 'changes': [{'price': '0.5', 'side': 'BUY', 'size': '2315'}], 'event_type': 'price_change', 'hash': '5a13dd2531d7075055dd7a83fdc8ba460a23537e', 'market': '0x7aa4a910b31b2c4ddb09d1e3408e52aa8e09a14402f376070a44b1b85cb36d13', 'timestamp': '1733333283022'}
{'asset_id': '114416409796971863099144323163249651172534872992222856507897414949637892047507', 'changes': [{'price': '0.51', 'side': 'BUY', 'size': '1086.18'}], 'event_type': 'price_change', 'hash': 'ab971900fc3848b25774a9bec2f73f334510ce58', 'market': '0x7aa4a910b31b2c4ddb09d1e3408e52aa8e09a14402f376070a44b1b85cb36d13', 'timestamp': '1733333283410'}
{'asset_id': '114416409796971863099144323163249651172534872992222856507897414949637892047507', 'changes': [{'price': '0.51', 'side': 'BUY', 'size': '1086.18'}], 'event_type': 'price_change', 'hash': 'ab971900fc3848b25774a9bec2f73f334510ce58', 'market': '0x7aa4a910b31b2c4ddb09d1e3408e52aa8e09a14402f376070a44b1b85cb36d13', 'timestamp': '1733333283410'}
{'asset_id': '114416409796971863099144323163249651172534872992222856507897414949637892047507', 'changes': [{'price': '0.5', 'side': 'BUY', 'size': '2415'}], 'event_type': 'price_change', 'hash': '8bb5bfdde5a0cbd033f303d29e21ccbf5b845a63', 'market': '0x7aa4a910b31b2c4ddb09d1e3408e52aa8e09a14402f376070a44b1b85cb36d13', 'timestamp': '1733333283954'}
{'asset_id': '114416409796971863099144323163249651172534872992222856507897414949637892047507', 'changes': [{'price': '0.5', 'side': 'BUY', 'size': '2415'}], 'event_type': 'price_change', 'hash': '8bb5bfdde5a0cbd033f303d29e21ccbf5b845a63', 'market': '0x7aa4a910b31b2c4ddb09d1e3408e52aa8e09a14402f376070a44b1b85cb36d13', 'timestamp': '1733333283954'}
{'asset_id': '114416409796971863099144323163249651172534872992222856507897414949637892047507', 'changes': [{'price': '0.5', 'side': 'BUY', 'size': '2315'}], 'event_type': 'price_change', 'hash': '1d9cb15700a233b516189eb0939760e99517cffb', 'market': '0x7aa4a910b31b2c4ddb09d1e3408e52aa8e09a14402f376070a44b1b85cb36d13', 'timestamp': '1733333284923'}
{'asset_id': '114416409796971863099144323163249651172534872992222856507897414949637892047507', 'changes': [{'price': '0.5', 'side': 'BUY', 'size': '2315'}], 'event_type': 'price_change', 'hash': '1d9cb15700a233b516189eb0939760e99517cffb', 'market': '0x7aa4a910b31b2c4ddb09d1e3408e52aa8e09a14402f376070a44b1b85cb36d13', 'timestamp': '1733333284923'}
{'asset_id': '114416409796971863099144323163249651172534872992222856507897414949637892047507', 'changes': [{'price': '0.51', 'side': 'BUY', 'size': '1186.18'}], 'event_type': 'price_change', 'hash': '900bf06b8f6afb11a4ee6189a5d2dc39f89d1f28', 'market': '0x7aa4a910b31b2c4ddb09d1e3408e52aa8e09a14402f376070a44b1b85cb36d13', 'timestamp': '1733333285535'}
{'asset_id': '114416409796971863099144323163249651172534872992222856507897414949637892047507', 'changes': [{'price': '0.51', 'side': 'BUY', 'size': '1186.18'}], 'event_type': 'price_change', 'hash': '900bf06b8f6afb11a4ee6189a5d2dc39f89d1f28', 'market': '0x7aa4a910b31b2c4ddb09d1e3408e52aa8e09a14402f376070a44b1b85cb36d13', 'timestamp': '1733333285535'}
{'asset_id': '114416409796971863099144323163249651172534872992222856507897414949637892047507', 'changes': [{'price': '0.51', 'side': 'BUY', 'size': '1086.18'}], 'event_type': 'price_change', 'hash': '560edd9308e540438bf551e9561d0cd2965a7cd1', 'market': '0x7aa4a910b31b2c4ddb09d1e3408e52aa8e09a14402f376070a44b1b85cb36d13', 'timestamp': '1733333286381'}
{'asset_id': '114416409796971863099144323163249651172534872992222856507897414949637892047507', 'changes': [{'price': '0.51', 'side': 'BUY', 'size': '1086.18'}], 'event_type': 'price_change', 'hash': '560edd9308e540438bf551e9561d0cd2965a7cd1', 'market': '0x7aa4a910b31b2c4ddb09d1e3408e52aa8e09a14402f376070a44b1b85cb36d13', 'timestamp': '1733333286381'}
{'asset_id': '114416409796971863099144323163249651172534872992222856507897414949637892047507', 'changes': [{'price': '0.5', 'side': 'BUY', 'size': '2415'}], 'event_type': 'price_change', 'hash': '9888e6920ea898496ca1c7305ccf49401f358d57', 'market': '0x7aa4a910b31b2c4ddb09d1e3408e52aa8e09a14402f376070a44b1b85cb36d13', 'timestamp': '1733333287172'}
{'asset_id': '114416409796971863099144323163249651172534872992222856507897414949637892047507', 'changes': [{'price': '0.5', 'side': 'BUY', 'size': '2415'}], 'event_type': 'price_change', 'hash': '9888e6920ea898496ca1c7305ccf49401f358d57', 'market': '0x7aa4a910b31b2c4ddb09d1e3408e52aa8e09a14402f376070a44b1b85cb36d13', 'timestamp': '1733333287172'}
{'asset_id': '114416409796971863099144323163249651172534872992222856507897414949637892047507', 'changes': [{'price': '0.5', 'side': 'BUY', 'size': '2315'}], 'event_type': 'price_change', 'hash': 'b9c77b3adc01d60d3fc1dddb4c2a9b39f202af57', 'market': '0x7aa4a910b31b2c4ddb09d1e3408e52aa8e09a14402f376070a44b1b85cb36d13', 'timestamp': '1733333287921'}
{'asset_id': '114416409796971863099144323163249651172534872992222856507897414949637892047507', 'changes': [{'price': '0.5', 'side': 'BUY', 'size': '2315'}], 'event_type': 'price_change', 'hash': 'b9c77b3adc01d60d3fc1dddb4c2a9b39f202af57', 'market': '0x7aa4a910b31b2c4ddb09d1e3408e52aa8e09a14402f376070a44b1b85cb36d13', 'timestamp': '1733333287921'}
{'asset_id': '114416409796971863099144323163249651172534872992222856507897414949637892047507', 'changes': [{'price': '0.51', 'side': 'BUY', 'size': '1186.18'}], 'event_type': 'price_change', 'hash': '839c5a6f672cb581c80d15baaf2899a7f5c4ed8f', 'market': '0x7aa4a910b31b2c4ddb09d1e3408e52aa8e09a14402f376070a44b1b85cb36d13', 'timestamp': '1733333288850'}
{'asset_id': '114416409796971863099144323163249651172534872992222856507897414949637892047507', 'changes': [{'price': '0.51', 'side': 'BUY', 'size': '1186.18'}], 'event_type': 'price_change', 'hash': '839c5a6f672cb581c80d15baaf2899a7f5c4ed8f', 'market': '0x7aa4a910b31b2c4ddb09d1e3408e52aa8e09a14402f376070a44b1b85cb36d13', 'timestamp': '1733333288850'}
{'asset_id': '114416409796971863099144323163249651172534872992222856507897414949637892047507', 'changes': [{'price': '0.51', 'side': 'BUY', 'size': '1086.18'}], 'event_type': 'price_change', 'hash': '2143a49966c6a993f1cc800f6fb28805616b365c', 'market': '0x7aa4a910b31b2c4ddb09d1e3408e52aa8e09a14402f376070a44b1b85cb36d13', 'timestamp': '1733333295448'}
{'asset_id': '114416409796971863099144323163249651172534872992222856507897414949637892047507', 'changes': [{'price': '0.51', 'side': 'BUY', 'size': '1086.18'}], 'event_type': 'price_change', 'hash': '2143a49966c6a993f1cc800f6fb28805616b365c', 'market': '0x7aa4a910b31b2c4ddb09d1e3408e52aa8e09a14402f376070a44b1b85cb36d13', 'timestamp': '1733333295448'}
{'asset_id': '114416409796971863099144323163249651172534872992222856507897414949637892047507', 'changes': [{'price': '0.5', 'side': 'BUY', 'size': '2415'}], 'event_type': 'price_change', 'hash': 'dcbbcc58cc3fced2105fc0b12d87af07db81ce02', 'market': '0x7aa4a910b31b2c4ddb09d1e3408e52aa8e09a14402f376070a44b1b85cb36d13', 'timestamp': '1733333296399'}
{'asset_id': '114416409796971863099144323163249651172534872992222856507897414949637892047507', 'changes': [{'price': '0.5', 'side': 'BUY', 'size': '2415'}], 'event_type': 'price_change', 'hash': 'dcbbcc58cc3fced2105fc0b12d87af07db81ce02', 'market': '0x7aa4a910b31b2c4ddb09d1e3408e52aa8e09a14402f376070a44b1b85cb36d13', 'timestamp': '1733333296399'}
{'asset_id': '114416409796971863099144323163249651172534872992222856507897414949637892047507', 'changes': [{'price': '0.5', 'side': 'BUY', 'size': '2315'}], 'event_type': 'price_change', 'hash': '43941ce3702090a282870de57cd4787ea17e4a31', 'market': '0x7aa4a910b31b2c4ddb09d1e3408e52aa8e09a14402f376070a44b1b85cb36d13', 'timestamp': '1733333330046'}
{'asset_id': '114416409796971863099144323163249651172534872992222856507897414949637892047507', 'changes': [{'price': '0.5', 'side': 'BUY', 'size': '2315'}], 'event_type': 'price_change', 'hash': '43941ce3702090a282870de57cd4787ea17e4a31', 'market': '0x7aa4a910b31b2c4ddb09d1e3408e52aa8e09a14402f376070a44b1b85cb36d13', 'timestamp': '1733333330046'}
{'asset_id': '114416409796971863099144323163249651172534872992222856507897414949637892047507', 'changes': [{'price': '0.51', 'side': 'BUY', 'size': '1186.18'}], 'event_type': 'price_change', 'hash': 'f30febe6382b599d632be85a189d3f1f580ccfb7', 'market': '0x7aa4a910b31b2c4ddb09d1e3408e52aa8e09a14402f376070a44b1b85cb36d13', 'timestamp': '1733333330908'}
{'asset_id': '114416409796971863099144323163249651172534872992222856507897414949637892047507', 'changes': [{'price': '0.51', 'side': 'BUY', 'size': '1186.18'}], 'event_type': 'price_change', 'hash': 'f30febe6382b599d632be85a189d3f1f580ccfb7', 'market': '0x7aa4a910b31b2c4ddb09d1e3408e52aa8e09a14402f376070a44b1b85cb36d13', 'timestamp': '1733333330908'}
{'asset_id': '114416409796971863099144323163249651172534872992222856507897414949637892047507', 'changes': [{'price': '0.53', 'side': 'BUY', 'size': '14'}], 'event_type': 'price_change', 'hash': '9d12c718977d9a59726698135d00869138741492', 'market': '0x7aa4a910b31b2c4ddb09d1e3408e52aa8e09a14402f376070a44b1b85cb36d13', 'timestamp': '1733333354089'}
{'asset_id': '114416409796971863099144323163249651172534872992222856507897414949637892047507', 'changes': [{'price': '0.53', 'side': 'BUY', 'size': '14'}], 'event_type': 'price_change', 'hash': '9d12c718977d9a59726698135d00869138741492', 'market': '0x7aa4a910b31b2c4ddb09d1e3408e52aa8e09a14402f376070a44b1b85cb36d13', 'timestamp': '1733333354089'}
{'asset_id': '114416409796971863099144323163249651172534872992222856507897414949637892047507', 'changes': [{'price': '0.52', 'side': 'BUY', 'size': '762.77'}], 'event_type': 'price_change', 'hash': 'f0da40a9b749cfcc1af5e83f0b4a8cef92a2ae81', 'market': '0x7aa4a910b31b2c4ddb09d1e3408e52aa8e09a14402f376070a44b1b85cb36d13', 'timestamp': '1733333354815'}
{'asset_id': '114416409796971863099144323163249651172534872992222856507897414949637892047507', 'changes': [{'price': '0.52', 'side': 'BUY', 'size': '762.77'}], 'event_type': 'price_change', 'hash': 'f0da40a9b749cfcc1af5e83f0b4a8cef92a2ae81', 'market': '0x7aa4a910b31b2c4ddb09d1e3408e52aa8e09a14402f376070a44b1b85cb36d13', 'timestamp': '1733333354815'}
{'asset_id': '114416409796971863099144323163249651172534872992222856507897414949637892047507', 'changes': [{'price': '0.58', 'side': 'SELL', 'size': '188.1'}], 'event_type': 'price_change', 'hash': '470b4cd7ea6ed2047b17e30adcf67157875a06ea', 'market': '0x7aa4a910b31b2c4ddb09d1e3408e52aa8e09a14402f376070a44b1b85cb36d13', 'timestamp': '1733333359011'}
{'asset_id': '114416409796971863099144323163249651172534872992222856507897414949637892047507', 'changes': [{'price': '0.58', 'side': 'SELL', 'size': '188.1'}], 'event_type': 'price_change', 'hash': '470b4cd7ea6ed2047b17e30adcf67157875a06ea', 'market': '0x7aa4a910b31b2c4ddb09d1e3408e52aa8e09a14402f376070a44b1b85cb36d13', 'timestamp': '1733333359011'}
{'asset_id': '114416409796971863099144323163249651172534872992222856507897414949637892047507', 'changes': [{'price': '0.53', 'side': 'BUY', 'size': '23.99'}, {'price': '0.46', 'side': 'BUY', 'size': '0'}, {'price': '0.5', 'side': 'BUY', 'size': '1315'}, {'price': '0.55', 'side': 'SELL', 'size': '2414.23'}], 'event_type': 'price_change', 'hash': 'e9c97bf0f583bd60c517a038804bafd476096dd7', 'market': '0x7aa4a910b31b2c4ddb09d1e3408e52aa8e09a14402f376070a44b1b85cb36d13', 'timestamp': '1733333362721'}
{'asset_id': '114416409796971863099144323163249651172534872992222856507897414949637892047507', 'changes': [{'price': '0.53', 'side': 'BUY', 'size': '23.99'}, {'price': '0.46', 'side': 'BUY', 'size': '0'}, {'price': '0.5', 'side': 'BUY', 'size': '1315'}, {'price': '0.55', 'side': 'SELL', 'size': '2414.23'}], 'event_type': 'price_change', 'hash': 'e9c97bf0f583bd60c517a038804bafd476096dd7', 'market': '0x7aa4a910b31b2c4ddb09d1e3408e52aa8e09a14402f376070a44b1b85cb36d13', 'timestamp': '1733333362721'}
{'asset_id': '114416409796971863099144323163249651172534872992222856507897414949637892047507', 'changes': [{'price': '0.46', 'side': 'BUY', 'size': '500'}], 'event_type': 'price_change', 'hash': '83de03e957a59e0d6a9f2220ae050d7720996efb', 'market': '0x7aa4a910b31b2c4ddb09d1e3408e52aa8e09a14402f376070a44b1b85cb36d13', 'timestamp': '1733333363774'}
{'asset_id': '114416409796971863099144323163249651172534872992222856507897414949637892047507', 'changes': [{'price': '0.46', 'side': 'BUY', 'size': '500'}], 'event_type': 'price_change', 'hash': '83de03e957a59e0d6a9f2220ae050d7720996efb', 'market': '0x7aa4a910b31b2c4ddb09d1e3408e52aa8e09a14402f376070a44b1b85cb36d13', 'timestamp': '1733333363774'}
{'asset_id': '114416409796971863099144323163249651172534872992222856507897414949637892047507', 'changes': [{'price': '0.55', 'side': 'SELL', 'size': '2914.23'}], 'event_type': 'price_change', 'hash': '90e9ff81fa1a61fbc73f0412647fcd6fcb4d58ae', 'market': '0x7aa4a910b31b2c4ddb09d1e3408e52aa8e09a14402f376070a44b1b85cb36d13', 'timestamp': '1733333364145'}
{'asset_id': '114416409796971863099144323163249651172534872992222856507897414949637892047507', 'changes': [{'price': '0.55', 'side': 'SELL', 'size': '2914.23'}], 'event_type': 'price_change', 'hash': '90e9ff81fa1a61fbc73f0412647fcd6fcb4d58ae', 'market': '0x7aa4a910b31b2c4ddb09d1e3408e52aa8e09a14402f376070a44b1b85cb36d13', 'timestamp': '1733333364145'}
{'asset_id': '114416409796971863099144323163249651172534872992222856507897414949637892047507', 'changes': [{'price': '0.51', 'side': 'BUY', 'size': '2186.18'}], 'event_type': 'price_change', 'hash': '60ce79c299e224f892724126b67cbc24c3739e65', 'market': '0x7aa4a910b31b2c4ddb09d1e3408e52aa8e09a14402f376070a44b1b85cb36d13', 'timestamp': '1733333364527'}
{'asset_id': '114416409796971863099144323163249651172534872992222856507897414949637892047507', 'changes': [{'price': '0.51', 'side': 'BUY', 'size': '2186.18'}], 'event_type': 'price_change', 'hash': '60ce79c299e224f892724126b67cbc24c3739e65', 'market': '0x7aa4a910b31b2c4ddb09d1e3408e52aa8e09a14402f376070a44b1b85cb36d13', 'timestamp': '1733333364527'}
{'asset_id': '114416409796971863099144323163249651172534872992222856507897414949637892047507', 'changes': [{'price': '0.58', 'side': 'SELL', 'size': '2188.1'}], 'event_type': 'price_change', 'hash': '60a3d9ce6b9b0d6bec7a47b830479eb70036ab4f', 'market': '0x7aa4a910b31b2c4ddb09d1e3408e52aa8e09a14402f376070a44b1b85cb36d13', 'timestamp': '1733333377182'}
{'asset_id': '114416409796971863099144323163249651172534872992222856507897414949637892047507', 'changes': [{'price': '0.58', 'side': 'SELL', 'size': '2188.1'}], 'event_type': 'price_change', 'hash': '60a3d9ce6b9b0d6bec7a47b830479eb70036ab4f', 'market': '0x7aa4a910b31b2c4ddb09d1e3408e52aa8e09a14402f376070a44b1b85cb36d13', 'timestamp': '1733333377182'}
{'asset_id': '114416409796971863099144323163249651172534872992222856507897414949637892047507', 'changes': [{'price': '0.55', 'side': 'SELL', 'size': '1714.23'}, {'price': '0.47', 'side': 'BUY', 'size': '2797.23'}], 'event_type': 'price_change', 'hash': '6031cd7639ffd1292d1f7f52eae38f0e41b2f370', 'market': '0x7aa4a910b31b2c4ddb09d1e3408e52aa8e09a14402f376070a44b1b85cb36d13', 'timestamp': '1733333383376'}
{'asset_id': '114416409796971863099144323163249651172534872992222856507897414949637892047507', 'changes': [{'price': '0.55', 'side': 'SELL', 'size': '1714.23'}, {'price': '0.47', 'side': 'BUY', 'size': '2797.23'}], 'event_type': 'price_change', 'hash': '6031cd7639ffd1292d1f7f52eae38f0e41b2f370', 'market': '0x7aa4a910b31b2c4ddb09d1e3408e52aa8e09a14402f376070a44b1b85cb36d13', 'timestamp': '1733333383376'}
{'asset_id': '114416409796971863099144323163249651172534872992222856507897414949637892047507', 'changes': [{'price': '0.57', 'side': 'SELL', 'size': '1550.1'}], 'event_type': 'price_change', 'hash': 'df388aa537e7cb5fcaa75821063cf43ebaac0446', 'market': '0x7aa4a910b31b2c4ddb09d1e3408e52aa8e09a14402f376070a44b1b85cb36d13', 'timestamp': '1733333385933'}
{'asset_id': '114416409796971863099144323163249651172534872992222856507897414949637892047507', 'changes': [{'price': '0.57', 'side': 'SELL', 'size': '1550.1'}], 'event_type': 'price_change', 'hash': 'df388aa537e7cb5fcaa75821063cf43ebaac0446', 'market': '0x7aa4a910b31b2c4ddb09d1e3408e52aa8e09a14402f376070a44b1b85cb36d13', 'timestamp': '1733333385933'}
{'asset_id': '114416409796971863099144323163249651172534872992222856507897414949637892047507', 'changes': [{'price': '0.48', 'side': 'BUY', 'size': '2342.18'}], 'event_type': 'price_change', 'hash': '71ecb78c3f0a555da686d784dc47af27ba24449d', 'market': '0x7aa4a910b31b2c4ddb09d1e3408e52aa8e09a14402f376070a44b1b85cb36d13', 'timestamp': '1733333385954'}
{'asset_id': '114416409796971863099144323163249651172534872992222856507897414949637892047507', 'changes': [{'price': '0.48', 'side': 'BUY', 'size': '2342.18'}], 'event_type': 'price_change', 'hash': '71ecb78c3f0a555da686d784dc47af27ba24449d', 'market': '0x7aa4a910b31b2c4ddb09d1e3408e52aa8e09a14402f376070a44b1b85cb36d13', 'timestamp': '1733333385954'}
{'asset_id': '114416409796971863099144323163249651172534872992222856507897414949637892047507', 'changes': [{'price': '0.51', 'side': 'BUY', 'size': '2086.18'}], 'event_type': 'price_change', 'hash': 'a3a514568a1056a61bc83513df57bac3c64958e2', 'market': '0x7aa4a910b31b2c4ddb09d1e3408e52aa8e09a14402f376070a44b1b85cb36d13', 'timestamp': '1733333389300'}
{'asset_id': '114416409796971863099144323163249651172534872992222856507897414949637892047507', 'changes': [{'price': '0.51', 'side': 'BUY', 'size': '2086.18'}], 'event_type': 'price_change', 'hash': 'a3a514568a1056a61bc83513df57bac3c64958e2', 'market': '0x7aa4a910b31b2c4ddb09d1e3408e52aa8e09a14402f376070a44b1b85cb36d13', 'timestamp': '1733333389300'}
{'asset_id': '114416409796971863099144323163249651172534872992222856507897414949637892047507', 'changes': [{'price': '0.52', 'side': 'BUY', 'size': '862.77'}], 'event_type': 'price_change', 'hash': '2637d9cd2baeb4c9a0a9c941984ed9b45bb29c7a', 'market': '0x7aa4a910b31b2c4ddb09d1e3408e52aa8e09a14402f376070a44b1b85cb36d13', 'timestamp': '1733333389901'}
{'asset_id': '114416409796971863099144323163249651172534872992222856507897414949637892047507', 'changes': [{'price': '0.52', 'side': 'BUY', 'size': '862.77'}], 'event_type': 'price_change', 'hash': '2637d9cd2baeb4c9a0a9c941984ed9b45bb29c7a', 'market': '0x7aa4a910b31b2c4ddb09d1e3408e52aa8e09a14402f376070a44b1b85cb36d13', 'timestamp': '1733333389901'}
{'asset_id': '114416409796971863099144323163249651172534872992222856507897414949637892047507', 'changes': [{'price': '0.52', 'side': 'BUY', 'size': '762.77'}], 'event_type': 'price_change', 'hash': 'd7bff76917e992b9646aaa9bafbff65452c9288d', 'market': '0x7aa4a910b31b2c4ddb09d1e3408e52aa8e09a14402f376070a44b1b85cb36d13', 'timestamp': '1733333393171'}
{'asset_id': '114416409796971863099144323163249651172534872992222856507897414949637892047507', 'changes': [{'price': '0.52', 'side': 'BUY', 'size': '762.77'}], 'event_type': 'price_change', 'hash': 'd7bff76917e992b9646aaa9bafbff65452c9288d', 'market': '0x7aa4a910b31b2c4ddb09d1e3408e52aa8e09a14402f376070a44b1b85cb36d13', 'timestamp': '1733333393171'}
{'asset_id': '114416409796971863099144323163249651172534872992222856507897414949637892047507', 'changes': [{'price': '0.51', 'side': 'BUY', 'size': '2186.18'}], 'event_type': 'price_change', 'hash': 'bbcc6b4cfd52891e45a291e794cb52d9ed7a936d', 'market': '0x7aa4a910b31b2c4ddb09d1e3408e52aa8e09a14402f376070a44b1b85cb36d13', 'timestamp': '1733333394272'}
{'asset_id': '114416409796971863099144323163249651172534872992222856507897414949637892047507', 'changes': [{'price': '0.51', 'side': 'BUY', 'size': '2186.18'}], 'event_type': 'price_change', 'hash': 'bbcc6b4cfd52891e45a291e794cb52d9ed7a936d', 'market': '0x7aa4a910b31b2c4ddb09d1e3408e52aa8e09a14402f376070a44b1b85cb36d13', 'timestamp': '1733333394272'}
{'asset_id': '114416409796971863099144323163249651172534872992222856507897414949637892047507', 'changes': [{'price': '0.57', 'side': 'SELL', 'size': '1310.1'}, {'price': '0.49', 'side': 'BUY', 'size': '1640'}], 'event_type': 'price_change', 'hash': '02b68a37a3042cccdf7545ad0fc4fc82312685d2', 'market': '0x7aa4a910b31b2c4ddb09d1e3408e52aa8e09a14402f376070a44b1b85cb36d13', 'timestamp': '1733333395344'}
{'asset_id': '114416409796971863099144323163249651172534872992222856507897414949637892047507', 'changes': [{'price': '0.57', 'side': 'SELL', 'size': '1310.1'}, {'price': '0.49', 'side': 'BUY', 'size': '1640'}], 'event_type': 'price_change', 'hash': '02b68a37a3042cccdf7545ad0fc4fc82312685d2', 'market': '0x7aa4a910b31b2c4ddb09d1e3408e52aa8e09a14402f376070a44b1b85cb36d13', 'timestamp': '1733333395344'}
{'asset_id': '114416409796971863099144323163249651172534872992222856507897414949637892047507', 'changes': [{'price': '0.58', 'side': 'SELL', 'size': '2458.1'}, {'price': '0.49', 'side': 'BUY', 'size': '1890'}], 'event_type': 'price_change', 'hash': '8af0cbdebdbb3e1db389bfc41ac689b87444e092', 'market': '0x7aa4a910b31b2c4ddb09d1e3408e52aa8e09a14402f376070a44b1b85cb36d13', 'timestamp': '1733333395669'}
{'asset_id': '114416409796971863099144323163249651172534872992222856507897414949637892047507', 'changes': [{'price': '0.58', 'side': 'SELL', 'size': '2458.1'}, {'price': '0.49', 'side': 'BUY', 'size': '1890'}], 'event_type': 'price_change', 'hash': '8af0cbdebdbb3e1db389bfc41ac689b87444e092', 'market': '0x7aa4a910b31b2c4ddb09d1e3408e52aa8e09a14402f376070a44b1b85cb36d13', 'timestamp': '1733333395669'}
{'asset_id': '114416409796971863099144323163249651172534872992222856507897414949637892047507', 'changes': [{'price': '0.87', 'side': 'SELL', 'size': '923'}], 'event_type': 'price_change', 'hash': '39cdb36e1973ce4d00c6c4e183ceda4a3a10cc47', 'market': '0x7aa4a910b31b2c4ddb09d1e3408e52aa8e09a14402f376070a44b1b85cb36d13', 'timestamp': '1733333406533'}
{'asset_id': '114416409796971863099144323163249651172534872992222856507897414949637892047507', 'changes': [{'price': '0.87', 'side': 'SELL', 'size': '923'}], 'event_type': 'price_change', 'hash': '39cdb36e1973ce4d00c6c4e183ceda4a3a10cc47', 'market': '0x7aa4a910b31b2c4ddb09d1e3408e52aa8e09a14402f376070a44b1b85cb36d13', 'timestamp': '1733333406533'}
{'asset_id': '114416409796971863099144323163249651172534872992222856507897414949637892047507', 'changes': [{'price': '0.16', 'side': 'BUY', 'size': '3209.51'}], 'event_type': 'price_change', 'hash': 'ffb5cf60add24f7a7094ba84ef8b72bea539dedd', 'market': '0x7aa4a910b31b2c4ddb09d1e3408e52aa8e09a14402f376070a44b1b85cb36d13', 'timestamp': '1733333407116'}
{'asset_id': '114416409796971863099144323163249651172534872992222856507897414949637892047507', 'changes': [{'price': '0.16', 'side': 'BUY', 'size': '3209.51'}], 'event_type': 'price_change', 'hash': 'ffb5cf60add24f7a7094ba84ef8b72bea539dedd', 'market': '0x7aa4a910b31b2c4ddb09d1e3408e52aa8e09a14402f376070a44b1b85cb36d13', 'timestamp': '1733333407116'}
{'asset_id': '114416409796971863099144323163249651172534872992222856507897414949637892047507', 'changes': [{'price': '0.11', 'side': 'BUY', 'size': '0'}], 'event_type': 'price_change', 'hash': 'ce6049ba716d7d314d110872764e620c3c24a890', 'market': '0x7aa4a910b31b2c4ddb09d1e3408e52aa8e09a14402f376070a44b1b85cb36d13', 'timestamp': '1733333409010'}
{'asset_id': '114416409796971863099144323163249651172534872992222856507897414949637892047507', 'changes': [{'price': '0.11', 'side': 'BUY', 'size': '0'}], 'event_type': 'price_change', 'hash': 'ce6049ba716d7d314d110872764e620c3c24a890', 'market': '0x7aa4a910b31b2c4ddb09d1e3408e52aa8e09a14402f376070a44b1b85cb36d13', 'timestamp': '1733333409010'}
{'asset_id': '114416409796971863099144323163249651172534872992222856507897414949637892047507', 'changes': [{'price': '0.16', 'side': 'BUY', 'size': '1335.51'}], 'event_type': 'price_change', 'hash': '425f3ad993b3966beb7db55c454b4ab60c0ea6ad', 'market': '0x7aa4a910b31b2c4ddb09d1e3408e52aa8e09a14402f376070a44b1b85cb36d13', 'timestamp': '1733333409370'}
{'asset_id': '114416409796971863099144323163249651172534872992222856507897414949637892047507', 'changes': [{'price': '0.16', 'side': 'BUY', 'size': '1335.51'}], 'event_type': 'price_change', 'hash': '425f3ad993b3966beb7db55c454b4ab60c0ea6ad', 'market': '0x7aa4a910b31b2c4ddb09d1e3408e52aa8e09a14402f376070a44b1b85cb36d13', 'timestamp': '1733333409370'}
{'asset_id': '114416409796971863099144323163249651172534872992222856507897414949637892047507', 'changes': [{'price': '0.87', 'side': 'SELL', 'size': '0'}], 'event_type': 'price_change', 'hash': 'edf3f08760b1a6ac5c560304f30756bb3a0e5942', 'market': '0x7aa4a910b31b2c4ddb09d1e3408e52aa8e09a14402f376070a44b1b85cb36d13', 'timestamp': '1733333411597'}
{'asset_id': '114416409796971863099144323163249651172534872992222856507897414949637892047507', 'changes': [{'price': '0.87', 'side': 'SELL', 'size': '0'}], 'event_type': 'price_change', 'hash': 'edf3f08760b1a6ac5c560304f30756bb3a0e5942', 'market': '0x7aa4a910b31b2c4ddb09d1e3408e52aa8e09a14402f376070a44b1b85cb36d13', 'timestamp': '1733333411597'}
{'asset_id': '114416409796971863099144323163249651172534872992222856507897414949637892047507', 'changes': [{'price': '0.57', 'side': 'SELL', 'size': '110.1'}], 'event_type': 'price_change', 'hash': '89fed21d88ab9240dc74304b00a673e105d52094', 'market': '0x7aa4a910b31b2c4ddb09d1e3408e52aa8e09a14402f376070a44b1b85cb36d13', 'timestamp': '1733333428961'}
{'asset_id': '114416409796971863099144323163249651172534872992222856507897414949637892047507', 'changes': [{'price': '0.57', 'side': 'SELL', 'size': '110.1'}], 'event_type': 'price_change', 'hash': '89fed21d88ab9240dc74304b00a673e105d52094', 'market': '0x7aa4a910b31b2c4ddb09d1e3408e52aa8e09a14402f376070a44b1b85cb36d13', 'timestamp': '1733333428961'}
{'asset_id': '114416409796971863099144323163249651172534872992222856507897414949637892047507', 'changes': [{'price': '0.5', 'side': 'BUY', 'size': '115'}], 'event_type': 'price_change', 'hash': 'f1ee5f2347973883a5dccef05c2003c340f7b4eb', 'market': '0x7aa4a910b31b2c4ddb09d1e3408e52aa8e09a14402f376070a44b1b85cb36d13', 'timestamp': '1733333431011'}
{'asset_id': '114416409796971863099144323163249651172534872992222856507897414949637892047507', 'changes': [{'price': '0.5', 'side': 'BUY', 'size': '115'}], 'event_type': 'price_change', 'hash': 'f1ee5f2347973883a5dccef05c2003c340f7b4eb', 'market': '0x7aa4a910b31b2c4ddb09d1e3408e52aa8e09a14402f376070a44b1b85cb36d13', 'timestamp': '1733333431011'}
{'asset_id': '114416409796971863099144323163249651172534872992222856507897414949637892047507', 'changes': [{'price': '0.56', 'side': 'SELL', 'size': '3861.75'}], 'event_type': 'price_change', 'hash': '930d36856cff06e16be21655b40d78c363ca87f8', 'market': '0x7aa4a910b31b2c4ddb09d1e3408e52aa8e09a14402f376070a44b1b85cb36d13', 'timestamp': '1733333436265'}
{'asset_id': '114416409796971863099144323163249651172534872992222856507897414949637892047507', 'changes': [{'price': '0.56', 'side': 'SELL', 'size': '3861.75'}], 'event_type': 'price_change', 'hash': '930d36856cff06e16be21655b40d78c363ca87f8', 'market': '0x7aa4a910b31b2c4ddb09d1e3408e52aa8e09a14402f376070a44b1b85cb36d13', 'timestamp': '1733333436265'}
{'asset_id': '114416409796971863099144323163249651172534872992222856507897414949637892047507', 'changes': [{'price': '0.5', 'side': 'BUY', 'size': '1315'}], 'event_type': 'price_change', 'hash': '23ba658afb79cc60974effbdf868e635b9b1f638', 'market': '0x7aa4a910b31b2c4ddb09d1e3408e52aa8e09a14402f376070a44b1b85cb36d13', 'timestamp': '1733333444215'}
{'asset_id': '114416409796971863099144323163249651172534872992222856507897414949637892047507', 'changes': [{'price': '0.5', 'side': 'BUY', 'size': '1315'}], 'event_type': 'price_change', 'hash': '23ba658afb79cc60974effbdf868e635b9b1f638', 'market': '0x7aa4a910b31b2c4ddb09d1e3408e52aa8e09a14402f376070a44b1b85cb36d13', 'timestamp': '1733333444215'}
{'asset_id': '114416409796971863099144323163249651172534872992222856507897414949637892047507', 'changes': [{'price': '0.53', 'side': 'BUY', 'size': '14'}], 'event_type': 'price_change', 'hash': 'a14d4ba252c7ced59701440be56798033a775699', 'market': '0x7aa4a910b31b2c4ddb09d1e3408e52aa8e09a14402f376070a44b1b85cb36d13', 'timestamp': '1733333456617'}
{'asset_id': '114416409796971863099144323163249651172534872992222856507897414949637892047507', 'changes': [{'price': '0.53', 'side': 'BUY', 'size': '14'}], 'event_type': 'price_change', 'hash': 'a14d4ba252c7ced59701440be56798033a775699', 'market': '0x7aa4a910b31b2c4ddb09d1e3408e52aa8e09a14402f376070a44b1b85cb36d13', 'timestamp': '1733333456617'}
{'asset_id': '114416409796971863099144323163249651172534872992222856507897414949637892047507', 'changes': [{'price': '0.53', 'side': 'BUY', 'size': '23.99'}], 'event_type': 'price_change', 'hash': '4849f4983e3e1085dee4c357ac0368592190487e', 'market': '0x7aa4a910b31b2c4ddb09d1e3408e52aa8e09a14402f376070a44b1b85cb36d13', 'timestamp': '1733333462506'}
{'asset_id': '114416409796971863099144323163249651172534872992222856507897414949637892047507', 'changes': [{'price': '0.53', 'side': 'BUY', 'size': '23.99'}], 'event_type': 'price_change', 'hash': '4849f4983e3e1085dee4c357ac0368592190487e', 'market': '0x7aa4a910b31b2c4ddb09d1e3408e52aa8e09a14402f376070a44b1b85cb36d13', 'timestamp': '1733333462506'}
{'asset_id': '114416409796971863099144323163249651172534872992222856507897414949637892047507', 'changes': [{'price': '0.51', 'side': 'BUY', 'size': '2086.18'}], 'event_type': 'price_change', 'hash': 'fb2bb64c8dfaa1402e055b4b37928804e51790ca', 'market': '0x7aa4a910b31b2c4ddb09d1e3408e52aa8e09a14402f376070a44b1b85cb36d13', 'timestamp': '1733333463557'}
{'asset_id': '114416409796971863099144323163249651172534872992222856507897414949637892047507', 'changes': [{'price': '0.51', 'side': 'BUY', 'size': '2086.18'}], 'event_type': 'price_change', 'hash': 'fb2bb64c8dfaa1402e055b4b37928804e51790ca', 'market': '0x7aa4a910b31b2c4ddb09d1e3408e52aa8e09a14402f376070a44b1b85cb36d13', 'timestamp': '1733333463557'}
{'asset_id': '114416409796971863099144323163249651172534872992222856507897414949637892047507', 'changes': [{'price': '0.49', 'side': 'BUY', 'size': '390'}], 'event_type': 'price_change', 'hash': 'a39b6ddfb10a8f406dc60bfad3901fb384e58836', 'market': '0x7aa4a910b31b2c4ddb09d1e3408e52aa8e09a14402f376070a44b1b85cb36d13', 'timestamp': '1733333466012'}
{'asset_id': '114416409796971863099144323163249651172534872992222856507897414949637892047507', 'changes': [{'price': '0.49', 'side': 'BUY', 'size': '390'}], 'event_type': 'price_change', 'hash': 'a39b6ddfb10a8f406dc60bfad3901fb384e58836', 'market': '0x7aa4a910b31b2c4ddb09d1e3408e52aa8e09a14402f376070a44b1b85cb36d13', 'timestamp': '1733333466012'}
{'asset_id': '114416409796971863099144323163249651172534872992222856507897414949637892047507', 'changes': [{'price': '0.47', 'side': 'BUY', 'size': '297.23'}], 'event_type': 'price_change', 'hash': 'dddf71615be2562425811014dcb66d87762c03db', 'market': '0x7aa4a910b31b2c4ddb09d1e3408e52aa8e09a14402f376070a44b1b85cb36d13', 'timestamp': '1733333467010'}
{'asset_id': '114416409796971863099144323163249651172534872992222856507897414949637892047507', 'changes': [{'price': '0.47', 'side': 'BUY', 'size': '297.23'}], 'event_type': 'price_change', 'hash': 'dddf71615be2562425811014dcb66d87762c03db', 'market': '0x7aa4a910b31b2c4ddb09d1e3408e52aa8e09a14402f376070a44b1b85cb36d13', 'timestamp': '1733333467010'}
{'asset_id': '114416409796971863099144323163249651172534872992222856507897414949637892047507', 'changes': [{'price': '0.46', 'side': 'BUY', 'size': '0'}, {'price': '0.51', 'side': 'BUY', 'size': '1086.18'}, {'price': '0.55', 'side': 'SELL', 'size': '1214.23'}], 'event_type': 'price_change', 'hash': '3204b7c6834ff798391a2613d612a656472afdea', 'market': '0x7aa4a910b31b2c4ddb09d1e3408e52aa8e09a14402f376070a44b1b85cb36d13', 'timestamp': '1733333467871'}
{'asset_id': '114416409796971863099144323163249651172534872992222856507897414949637892047507', 'changes': [{'price': '0.46', 'side': 'BUY', 'size': '0'}, {'price': '0.51', 'side': 'BUY', 'size': '1086.18'}, {'price': '0.55', 'side': 'SELL', 'size': '1214.23'}], 'event_type': 'price_change', 'hash': '3204b7c6834ff798391a2613d612a656472afdea', 'market': '0x7aa4a910b31b2c4ddb09d1e3408e52aa8e09a14402f376070a44b1b85cb36d13', 'timestamp': '1733333467871'}
{'asset_id': '114416409796971863099144323163249651172534872992222856507897414949637892047507', 'changes': [{'price': '0.46', 'side': 'BUY', 'size': '500'}], 'event_type': 'price_change', 'hash': '4f4df35eee2349a860b48d76141d185ef545aab8', 'market': '0x7aa4a910b31b2c4ddb09d1e3408e52aa8e09a14402f376070a44b1b85cb36d13', 'timestamp': '1733333468916'}
{'asset_id': '114416409796971863099144323163249651172534872992222856507897414949637892047507', 'changes': [{'price': '0.46', 'side': 'BUY', 'size': '500'}], 'event_type': 'price_change', 'hash': '4f4df35eee2349a860b48d76141d185ef545aab8', 'market': '0x7aa4a910b31b2c4ddb09d1e3408e52aa8e09a14402f376070a44b1b85cb36d13', 'timestamp': '1733333468916'}
{'asset_id': '114416409796971863099144323163249651172534872992222856507897414949637892047507', 'changes': [{'price': '0.55', 'side': 'SELL', 'size': '1714.23'}], 'event_type': 'price_change', 'hash': 'a83667f413ccdbb980ea7ddfd79bd4888891dcc2', 'market': '0x7aa4a910b31b2c4ddb09d1e3408e52aa8e09a14402f376070a44b1b85cb36d13', 'timestamp': '1733333469286'}
{'asset_id': '114416409796971863099144323163249651172534872992222856507897414949637892047507', 'changes': [{'price': '0.55', 'side': 'SELL', 'size': '1714.23'}], 'event_type': 'price_change', 'hash': 'a83667f413ccdbb980ea7ddfd79bd4888891dcc2', 'market': '0x7aa4a910b31b2c4ddb09d1e3408e52aa8e09a14402f376070a44b1b85cb36d13', 'timestamp': '1733333469286'}
{'asset_id': '114416409796971863099144323163249651172534872992222856507897414949637892047507', 'changes': [{'price': '0.5', 'side': 'BUY', 'size': '2315'}], 'event_type': 'price_change', 'hash': '3c27bc5e86e34b0907d7ca28327cb9913192a35d', 'market': '0x7aa4a910b31b2c4ddb09d1e3408e52aa8e09a14402f376070a44b1b85cb36d13', 'timestamp': '1733333469671'}
{'asset_id': '114416409796971863099144323163249651172534872992222856507897414949637892047507', 'changes': [{'price': '0.5', 'side': 'BUY', 'size': '2315'}], 'event_type': 'price_change', 'hash': '3c27bc5e86e34b0907d7ca28327cb9913192a35d', 'market': '0x7aa4a910b31b2c4ddb09d1e3408e52aa8e09a14402f376070a44b1b85cb36d13', 'timestamp': '1733333469671'}
{'asset_id': '114416409796971863099144323163249651172534872992222856507897414949637892047507', 'changes': [{'price': '0.53', 'side': 'BUY', 'size': '14'}], 'event_type': 'price_change', 'hash': '7af0d76b05e0b598a174ffcf4bef0a188583d93c', 'market': '0x7aa4a910b31b2c4ddb09d1e3408e52aa8e09a14402f376070a44b1b85cb36d13', 'timestamp': '1733333474719'}
{'asset_id': '114416409796971863099144323163249651172534872992222856507897414949637892047507', 'changes': [{'price': '0.53', 'side': 'BUY', 'size': '14'}], 'event_type': 'price_change', 'hash': '7af0d76b05e0b598a174ffcf4bef0a188583d93c', 'market': '0x7aa4a910b31b2c4ddb09d1e3408e52aa8e09a14402f376070a44b1b85cb36d13', 'timestamp': '1733333474719'}
{'asks': [{'price': '0.99', 'size': '4217.01'}, {'price': '0.98', 'size': '505'}, {'price': '0.97', 'size': '511.03'}, {'price': '0.96', 'size': '300'}, {'price': '0.95', 'size': '657.12'}, {'price': '0.94', 'size': '300'}, {'price': '0.92', 'size': '20000.45'}, {'price': '0.91', 'size': '10406.3'}, {'price': '0.9', 'size': '4587.5'}, {'price': '0.89', 'size': '13017.18'}, {'price': '0.88', 'size': '200'}, {'price': '0.86', 'size': '17.1'}, {'price': '0.85', 'size': '109.68'}, {'price': '0.84', 'size': '250'}, {'price': '0.83', 'size': '100'}, {'price': '0.82', 'size': '16029'}, {'price': '0.81', 'size': '45721.39'}, {'price': '0.8', 'size': '26531'}, {'price': '0.79', 'size': '7110'}, {'price': '0.78', 'size': '10350'}, {'price': '0.77', 'size': '67'}, {'price': '0.76', 'size': '200'}, {'price': '0.75', 'size': '18329.25'}, {'price': '0.74', 'size': '11370.7'}, {'price': '0.73', 'size': '5020.1'}, {'price': '0.72', 'size': '380.52'}, {'price': '0.71', 'size': '15073.2'}, {'price': '0.7', 'size': '5570.1'}, {'price': '0.69', 'size': '6088.6'}, {'price': '0.68', 'size': '2131.34'}, {'price': '0.67', 'size': '3010.1'}, {'price': '0.66', 'size': '4510.1'}, {'price': '0.65', 'size': '1010.1'}, {'price': '0.64', 'size': '1230.1'}, {'price': '0.63', 'size': '210.1'}, {'price': '0.62', 'size': '300.1'}, {'price': '0.61', 'size': '511.06'}, {'price': '0.6', 'size': '3467.85'}, {'price': '0.59', 'size': '2510'}, {'price': '0.58', 'size': '2458.1'}, {'price': '0.57', 'size': '110.1'}, {'price': '0.56', 'size': '3861.75'}, {'price': '0.55', 'size': '1714.23'}, {'price': '0.54', 'size': '60.1'}], 'asset_id': '114416409796971863099144323163249651172534872992222856507897414949637892047507', 'bids': [{'price': '0.01', 'size': '2850.27'}, {'price': '0.02', 'size': '500'}, {'price': '0.03', 'size': '500'}, {'price': '0.04', 'size': '300'}, {'price': '0.05', 'size': '320'}, {'price': '0.06', 'size': '300'}, {'price': '0.08', 'size': '250'}, {'price': '0.09', 'size': '300'}, {'price': '0.1', 'size': '205'}, {'price': '0.12', 'size': '200'}, {'price': '0.13', 'size': '426.92'}, {'price': '0.14', 'size': '15'}, {'price': '0.15', 'size': '110'}, {'price': '0.16', 'size': '1335.51'}, {'price': '0.18', 'size': '19.13'}, {'price': '0.19', 'size': '120'}, {'price': '0.2', 'size': '691.17'}, {'price': '0.24', 'size': '5027'}, {'price': '0.25', 'size': '86.66'}, {'price': '0.27', 'size': '215.25'}, {'price': '0.29', 'size': '1102.28'}, {'price': '0.31', 'size': '1130.65'}, {'price': '0.32', 'size': '200'}, {'price': '0.33', 'size': '620'}, {'price': '0.34', 'size': '4000'}, {'price': '0.35', 'size': '232'}, {'price': '0.39', 'size': '10.5'}, {'price': '0.4', 'size': '3135'}, {'price': '0.41', 'size': '20'}, {'price': '0.42', 'size': '3050'}, {'price': '0.43', 'size': '50'}, {'price': '0.44', 'size': '3660'}, {'price': '0.45', 'size': '478'}, {'price': '0.46', 'size': '500'}, {'price': '0.47', 'size': '297.23'}, {'price': '0.48', 'size': '2342.18'}, {'price': '0.49', 'size': '390'}, {'price': '0.5', 'size': '2415'}, {'price': '0.51', 'size': '1086.18'}, {'price': '0.52', 'size': '762.77'}, {'price': '0.53', 'size': '9'}], 'event_type': 'book', 'hash': '6d60949fe87c5b0833dfb5975b25b1cc2e26a18d', 'market': '0x7aa4a910b31b2c4ddb09d1e3408e52aa8e09a14402f376070a44b1b85cb36d13', 'timestamp': '1733333475201'}
{'asset_id': '114416409796971863099144323163249651172534872992222856507897414949637892047507', 'changes': [{'price': '0.5', 'side': 'BUY', 'size': '2415'}, {'price': '0.45', 'side': 'BUY', 'size': '2978'}, {'price': '0.48', 'side': 'BUY', 'size': '3842.18'}], 'event_type': 'price_change', 'hash': '887fa6382096e3fea7650d8d41ac1b1a2797927e', 'market': '0x7aa4a910b31b2c4ddb09d1e3408e52aa8e09a14402f376070a44b1b85cb36d13', 'timestamp': '1733333475249'}
{'asks': [{'price': '0.99', 'size': '4217.01'}, {'price': '0.98', 'size': '505'}, {'price': '0.97', 'size': '511.03'}, {'price': '0.96', 'size': '300'}, {'price': '0.95', 'size': '657.12'}, {'price': '0.94', 'size': '300'}, {'price': '0.92', 'size': '20000.45'}, {'price': '0.91', 'size': '10406.3'}, {'price': '0.9', 'size': '4587.5'}, {'price': '0.89', 'size': '13017.18'}, {'price': '0.88', 'size': '200'}, {'price': '0.86', 'size': '17.1'}, {'price': '0.85', 'size': '109.68'}, {'price': '0.84', 'size': '250'}, {'price': '0.83', 'size': '100'}, {'price': '0.82', 'size': '16029'}, {'price': '0.81', 'size': '45721.39'}, {'price': '0.8', 'size': '26531'}, {'price': '0.79', 'size': '7110'}, {'price': '0.78', 'size': '10350'}, {'price': '0.77', 'size': '67'}, {'price': '0.76', 'size': '200'}, {'price': '0.75', 'size': '18329.25'}, {'price': '0.74', 'size': '11370.7'}, {'price': '0.73', 'size': '5020.1'}, {'price': '0.72', 'size': '380.52'}, {'price': '0.71', 'size': '15073.2'}, {'price': '0.7', 'size': '5570.1'}, {'price': '0.69', 'size': '6088.6'}, {'price': '0.68', 'size': '2131.34'}, {'price': '0.67', 'size': '3010.1'}, {'price': '0.66', 'size': '4510.1'}, {'price': '0.65', 'size': '1010.1'}, {'price': '0.64', 'size': '1230.1'}, {'price': '0.63', 'size': '210.1'}, {'price': '0.62', 'size': '300.1'}, {'price': '0.61', 'size': '511.06'}, {'price': '0.6', 'size': '3467.85'}, {'price': '0.59', 'size': '2510'}, {'price': '0.58', 'size': '2458.1'}, {'price': '0.57', 'size': '110.1'}, {'price': '0.56', 'size': '3861.75'}, {'price': '0.55', 'size': '1714.23'}, {'price': '0.54', 'size': '60.1'}], 'asset_id': '114416409796971863099144323163249651172534872992222856507897414949637892047507', 'bids': [{'price': '0.01', 'size': '2850.27'}, {'price': '0.02', 'size': '500'}, {'price': '0.03', 'size': '500'}, {'price': '0.04', 'size': '300'}, {'price': '0.05', 'size': '320'}, {'price': '0.06', 'size': '300'}, {'price': '0.08', 'size': '250'}, {'price': '0.09', 'size': '300'}, {'price': '0.1', 'size': '205'}, {'price': '0.12', 'size': '200'}, {'price': '0.13', 'size': '426.92'}, {'price': '0.14', 'size': '15'}, {'price': '0.15', 'size': '110'}, {'price': '0.16', 'size': '1335.51'}, {'price': '0.18', 'size': '19.13'}, {'price': '0.19', 'size': '120'}, {'price': '0.2', 'size': '691.17'}, {'price': '0.24', 'size': '5027'}, {'price': '0.25', 'size': '86.66'}, {'price': '0.27', 'size': '215.25'}, {'price': '0.29', 'size': '1102.28'}, {'price': '0.31', 'size': '1130.65'}, {'price': '0.32', 'size': '200'}, {'price': '0.33', 'size': '620'}, {'price': '0.34', 'size': '4000'}, {'price': '0.35', 'size': '232'}, {'price': '0.39', 'size': '10.5'}, {'price': '0.4', 'size': '3135'}, {'price': '0.41', 'size': '20'}, {'price': '0.42', 'size': '3050'}, {'price': '0.43', 'size': '50'}, {'price': '0.44', 'size': '3660'}, {'price': '0.45', 'size': '478'}, {'price': '0.46', 'size': '500'}, {'price': '0.47', 'size': '297.23'}, {'price': '0.48', 'size': '2342.18'}, {'price': '0.49', 'size': '390'}, {'price': '0.5', 'size': '2415'}, {'price': '0.51', 'size': '1086.18'}, {'price': '0.52', 'size': '762.77'}, {'price': '0.53', 'size': '9'}], 'event_type': 'book', 'hash': '6d60949fe87c5b0833dfb5975b25b1cc2e26a18d', 'market': '0x7aa4a910b31b2c4ddb09d1e3408e52aa8e09a14402f376070a44b1b85cb36d13', 'timestamp': '1733333475201'}
{'asset_id': '114416409796971863099144323163249651172534872992222856507897414949637892047507', 'changes': [{'price': '0.5', 'side': 'BUY', 'size': '2415'}, {'price': '0.45', 'side': 'BUY', 'size': '2978'}, {'price': '0.48', 'side': 'BUY', 'size': '3842.18'}], 'event_type': 'price_change', 'hash': '887fa6382096e3fea7650d8d41ac1b1a2797927e', 'market': '0x7aa4a910b31b2c4ddb09d1e3408e52aa8e09a14402f376070a44b1b85cb36d13', 'timestamp': '1733333475249'}
{'asset_id': '114416409796971863099144323163249651172534872992222856507897414949637892047507', 'changes': [{'price': '0.58', 'side': 'SELL', 'size': '2188.1'}, {'price': '0.49', 'side': 'BUY', 'size': '140'}], 'event_type': 'price_change', 'hash': '14a2ab343d31ab62936cb13255d9a4e86e5c851f', 'market': '0x7aa4a910b31b2c4ddb09d1e3408e52aa8e09a14402f376070a44b1b85cb36d13', 'timestamp': '1733333480670'}
{'asset_id': '114416409796971863099144323163249651172534872992222856507897414949637892047507', 'changes': [{'price': '0.58', 'side': 'SELL', 'size': '2188.1'}, {'price': '0.49', 'side': 'BUY', 'size': '140'}], 'event_type': 'price_change', 'hash': '14a2ab343d31ab62936cb13255d9a4e86e5c851f', 'market': '0x7aa4a910b31b2c4ddb09d1e3408e52aa8e09a14402f376070a44b1b85cb36d13', 'timestamp': '1733333480670'}
{'asset_id': '114416409796971863099144323163249651172534872992222856507897414949637892047507', 'changes': [{'price': '0.49', 'side': 'BUY', 'size': '360'}, {'price': '0.57', 'side': 'SELL', 'size': '350.1'}], 'event_type': 'price_change', 'hash': '4d5694bcf9a67839444ae4a07d6d97e4f11d7457', 'market': '0x7aa4a910b31b2c4ddb09d1e3408e52aa8e09a14402f376070a44b1b85cb36d13', 'timestamp': '1733333480985'}
{'asset_id': '114416409796971863099144323163249651172534872992222856507897414949637892047507', 'changes': [{'price': '0.49', 'side': 'BUY', 'size': '360'}, {'price': '0.57', 'side': 'SELL', 'size': '350.1'}], 'event_type': 'price_change', 'hash': '4d5694bcf9a67839444ae4a07d6d97e4f11d7457', 'market': '0x7aa4a910b31b2c4ddb09d1e3408e52aa8e09a14402f376070a44b1b85cb36d13', 'timestamp': '1733333480985'}
{'asset_id': '114416409796971863099144323163249651172534872992222856507897414949637892047507', 'changes': [{'price': '0.56', 'side': 'SELL', 'size': '2361.75'}], 'event_type': 'price_change', 'hash': '230d6879852eb6d6c35ddf1b007fd10ff3d89920', 'market': '0x7aa4a910b31b2c4ddb09d1e3408e52aa8e09a14402f376070a44b1b85cb36d13', 'timestamp': '1733333483010'}
{'asset_id': '114416409796971863099144323163249651172534872992222856507897414949637892047507', 'changes': [{'price': '0.56', 'side': 'SELL', 'size': '2361.75'}], 'event_type': 'price_change', 'hash': '230d6879852eb6d6c35ddf1b007fd10ff3d89920', 'market': '0x7aa4a910b31b2c4ddb09d1e3408e52aa8e09a14402f376070a44b1b85cb36d13', 'timestamp': '1733333483010'}
{'asset_id': '114416409796971863099144323163249651172534872992222856507897414949637892047507', 'changes': [{'price': '0.56', 'side': 'SELL', 'size': '1161.75'}], 'event_type': 'price_change', 'hash': '39650dbea1abf6ce56769faa081d0af36c80f149', 'market': '0x7aa4a910b31b2c4ddb09d1e3408e52aa8e09a14402f376070a44b1b85cb36d13', 'timestamp': '1733333483449'}
{'asset_id': '114416409796971863099144323163249651172534872992222856507897414949637892047507', 'changes': [{'price': '0.56', 'side': 'SELL', 'size': '1161.75'}], 'event_type': 'price_change', 'hash': '39650dbea1abf6ce56769faa081d0af36c80f149', 'market': '0x7aa4a910b31b2c4ddb09d1e3408e52aa8e09a14402f376070a44b1b85cb36d13', 'timestamp': '1733333483449'}
{'asset_id': '114416409796971863099144323163249651172534872992222856507897414949637892047507', 'changes': [{'price': '0.55', 'side': 'SELL', 'size': '2914.23'}], 'event_type': 'price_change', 'hash': 'c86e0a61904bd78e88973a92ba3785911541044e', 'market': '0x7aa4a910b31b2c4ddb09d1e3408e52aa8e09a14402f376070a44b1b85cb36d13', 'timestamp': '1733333483826'}
{'asset_id': '114416409796971863099144323163249651172534872992222856507897414949637892047507', 'changes': [{'price': '0.55', 'side': 'SELL', 'size': '2914.23'}], 'event_type': 'price_change', 'hash': 'c86e0a61904bd78e88973a92ba3785911541044e', 'market': '0x7aa4a910b31b2c4ddb09d1e3408e52aa8e09a14402f376070a44b1b85cb36d13', 'timestamp': '1733333483826'}
{'asset_id': '114416409796971863099144323163249651172534872992222856507897414949637892047507', 'changes': [{'price': '0.5', 'side': 'BUY', 'size': '2315'}], 'event_type': 'price_change', 'hash': '6bf12765812728753a0e7fdc34d1a243e948b654', 'market': '0x7aa4a910b31b2c4ddb09d1e3408e52aa8e09a14402f376070a44b1b85cb36d13', 'timestamp': '1733333486417'}
{'asset_id': '114416409796971863099144323163249651172534872992222856507897414949637892047507', 'changes': [{'price': '0.5', 'side': 'BUY', 'size': '2315'}], 'event_type': 'price_change', 'hash': '6bf12765812728753a0e7fdc34d1a243e948b654', 'market': '0x7aa4a910b31b2c4ddb09d1e3408e52aa8e09a14402f376070a44b1b85cb36d13', 'timestamp': '1733333486417'}
{'asset_id': '114416409796971863099144323163249651172534872992222856507897414949637892047507', 'changes': [{'price': '0.5', 'side': 'BUY', 'size': '2415'}], 'event_type': 'price_change', 'hash': '0502b68dbaa2be86dae4c286239ec4f53607e075', 'market': '0x7aa4a910b31b2c4ddb09d1e3408e52aa8e09a14402f376070a44b1b85cb36d13', 'timestamp': '1733333488413'}
{'asset_id': '114416409796971863099144323163249651172534872992222856507897414949637892047507', 'changes': [{'price': '0.5', 'side': 'BUY', 'size': '2415'}], 'event_type': 'price_change', 'hash': '0502b68dbaa2be86dae4c286239ec4f53607e075', 'market': '0x7aa4a910b31b2c4ddb09d1e3408e52aa8e09a14402f376070a44b1b85cb36d13', 'timestamp': '1733333488413'}
{'asset_id': '114416409796971863099144323163249651172534872992222856507897414949637892047507', 'changes': [{'price': '0.56', 'side': 'SELL', 'size': '2661.75'}], 'event_type': 'price_change', 'hash': '63fa37d4615119a1a4787bf8e618b9e419ee3824', 'market': '0x7aa4a910b31b2c4ddb09d1e3408e52aa8e09a14402f376070a44b1b85cb36d13', 'timestamp': '1733333491464'}
{'asset_id': '114416409796971863099144323163249651172534872992222856507897414949637892047507', 'changes': [{'price': '0.56', 'side': 'SELL', 'size': '2661.75'}], 'event_type': 'price_change', 'hash': '63fa37d4615119a1a4787bf8e618b9e419ee3824', 'market': '0x7aa4a910b31b2c4ddb09d1e3408e52aa8e09a14402f376070a44b1b85cb36d13', 'timestamp': '1733333491464'}
{'asset_id': '114416409796971863099144323163249651172534872992222856507897414949637892047507', 'changes': [{'price': '0.5', 'side': 'BUY', 'size': '2315'}], 'event_type': 'price_change', 'hash': '19aeaf4bded6829b48b98c51cfcf87bee52bcee7', 'market': '0x7aa4a910b31b2c4ddb09d1e3408e52aa8e09a14402f376070a44b1b85cb36d13', 'timestamp': '1733333491930'}
{'asset_id': '114416409796971863099144323163249651172534872992222856507897414949637892047507', 'changes': [{'price': '0.5', 'side': 'BUY', 'size': '2315'}], 'event_type': 'price_change', 'hash': '19aeaf4bded6829b48b98c51cfcf87bee52bcee7', 'market': '0x7aa4a910b31b2c4ddb09d1e3408e52aa8e09a14402f376070a44b1b85cb36d13', 'timestamp': '1733333491930'}
{'asks': [{'price': '0.99', 'size': '4217.01'}, {'price': '0.98', 'size': '505'}, {'price': '0.97', 'size': '511.03'}, {'price': '0.96', 'size': '300'}, {'price': '0.95', 'size': '657.12'}, {'price': '0.94', 'size': '300'}, {'price': '0.92', 'size': '20000.45'}, {'price': '0.91', 'size': '10406.3'}, {'price': '0.9', 'size': '4587.5'}, {'price': '0.89', 'size': '13017.18'}, {'price': '0.88', 'size': '200'}, {'price': '0.86', 'size': '17.1'}, {'price': '0.85', 'size': '109.68'}, {'price': '0.84', 'size': '250'}, {'price': '0.83', 'size': '100'}, {'price': '0.82', 'size': '16029'}, {'price': '0.81', 'size': '45721.39'}, {'price': '0.8', 'size': '26531'}, {'price': '0.79', 'size': '7110'}, {'price': '0.78', 'size': '10350'}, {'price': '0.77', 'size': '67'}, {'price': '0.76', 'size': '200'}, {'price': '0.75', 'size': '18329.25'}, {'price': '0.74', 'size': '11370.7'}, {'price': '0.73', 'size': '5020.1'}, {'price': '0.72', 'size': '380.52'}, {'price': '0.71', 'size': '15073.2'}, {'price': '0.7', 'size': '5570.1'}, {'price': '0.69', 'size': '6088.6'}, {'price': '0.68', 'size': '2131.34'}, {'price': '0.67', 'size': '3010.1'}, {'price': '0.66', 'size': '4510.1'}, {'price': '0.65', 'size': '1010.1'}, {'price': '0.64', 'size': '1230.1'}, {'price': '0.63', 'size': '210.1'}, {'price': '0.62', 'size': '300.1'}, {'price': '0.61', 'size': '511.06'}, {'price': '0.6', 'size': '3467.85'}, {'price': '0.59', 'size': '2510'}, {'price': '0.58', 'size': '2188.1'}, {'price': '0.57', 'size': '350.1'}, {'price': '0.56', 'size': '2661.75'}, {'price': '0.55', 'size': '2914.23'}, {'price': '0.54', 'size': '23.06'}], 'asset_id': '114416409796971863099144323163249651172534872992222856507897414949637892047507', 'bids': [{'price': '0.01', 'size': '2850.27'}, {'price': '0.02', 'size': '500'}, {'price': '0.03', 'size': '500'}, {'price': '0.04', 'size': '300'}, {'price': '0.05', 'size': '320'}, {'price': '0.06', 'size': '300'}, {'price': '0.08', 'size': '250'}, {'price': '0.09', 'size': '300'}, {'price': '0.1', 'size': '205'}, {'price': '0.12', 'size': '200'}, {'price': '0.13', 'size': '426.92'}, {'price': '0.14', 'size': '15'}, {'price': '0.15', 'size': '110'}, {'price': '0.16', 'size': '1335.51'}, {'price': '0.18', 'size': '19.13'}, {'price': '0.19', 'size': '120'}, {'price': '0.2', 'size': '691.17'}, {'price': '0.24', 'size': '5027'}, {'price': '0.25', 'size': '86.66'}, {'price': '0.27', 'size': '215.25'}, {'price': '0.29', 'size': '1102.28'}, {'price': '0.31', 'size': '1130.65'}, {'price': '0.32', 'size': '200'}, {'price': '0.33', 'size': '620'}, {'price': '0.34', 'size': '4000'}, {'price': '0.35', 'size': '232'}, {'price': '0.39', 'size': '10.5'}, {'price': '0.4', 'size': '3135'}, {'price': '0.41', 'size': '20'}, {'price': '0.42', 'size': '3050'}, {'price': '0.43', 'size': '50'}, {'price': '0.44', 'size': '3660'}, {'price': '0.45', 'size': '2978'}, {'price': '0.46', 'size': '500'}, {'price': '0.47', 'size': '297.23'}, {'price': '0.48', 'size': '3842.18'}, {'price': '0.49', 'size': '360'}, {'price': '0.5', 'size': '2315'}, {'price': '0.51', 'size': '1086.18'}, {'price': '0.52', 'size': '762.77'}, {'price': '0.53', 'size': '9'}], 'event_type': 'book', 'hash': 'acdd2070adaa968e6878b10ce4a30edd24f3765f', 'market': '0x7aa4a910b31b2c4ddb09d1e3408e52aa8e09a14402f376070a44b1b85cb36d13', 'timestamp': '1733333492587'}
{'asset_id': '114416409796971863099144323163249651172534872992222856507897414949637892047507', 'event_type': 'last_trade_price', 'fee_rate_bps': '0', 'market': '0x7aa4a910b31b2c4ddb09d1e3408e52aa8e09a14402f376070a44b1b85cb36d13', 'price': '0.54', 'side': 'BUY', 'size': '37.037036', 'timestamp': '1733333492612'}
