{'market': '0x84c0ffe3f56cb357ff5ff8bc5d2182ae90be4dd6718e8403a6af472b452dbfa8', 'asset_id': '72936048731589292555781174533757608024096898681344338816447372274344589246891', 'timestamp': '1733411269309', 'hash': 'a1da0f6e5e810910f1de0d5a845044926ff37cda', 'bids': [{'price': '0.001', 'size': '10000'}, {'price': '0.002', 'size': '15000'}, {'price': '0.003', 'size': '3000'}, {'price': '0.004', 'size': '2049'}, {'price': '0.005', 'size': '1000'}, {'price': '0.007', 'size': '5000'}, {'price': '0.019', 'size': '500'}, {'price': '0.02', 'size': '2060'}, {'price': '0.021', 'size': '50'}, {'price': '0.07', 'size': '2000'}, {'price': '0.093', 'size': '2591.01'}, {'price': '0.094', 'size': '6382'}, {'price': '0.111', 'size': '333'}, {'price': '0.114', 'size': '3682'}, {'price': '0.17', 'size': '125'}, {'price': '0.2', 'size': '3629.03'}, {'price': '0.201', 'size': '1000'}, {'price': '0.214', 'size': '3333'}, {'price': '0.22', 'size': '90'}, {'price': '0.24', 'size': '80'}, {'price': '0.26', 'size': '70'}, {'price': '0.27', 'size': '50'}, {'price': '0.281', 'size': '500'}, {'price': '0.29', 'size': '40'}, {'price': '0.3', 'size': '155.37'}, {'price': '0.307', 'size': '272'}, {'price': '0.31', 'size': '35'}, {'price': '0.33', 'size': '31'}, {'price': '0.335', 'size': '111'}, {'price': '0.35', 'size': '2258.06'}, {'price': '0.352', 'size': '50'}, {'price': '0.359', 'size': '30'}, {'price': '0.37', 'size': '270'}, {'price': '0.38', 'size': '30'}, {'price': '0.382', 'size': '333'}, {'price': '0.39', 'size': '473.12'}, {'price': '0.4', 'size': '330'}, {'price': '0.401', 'size': '1111'}, {'price': '0.403', 'size': '100'}, {'price': '0.409', 'size': '30'}, {'price': '0.411', 'size': '52.8'}, {'price': '0.42', 'size': '10000'}, {'price': '0.421', 'size': '1500'}, {'price': '0.422', 'size': '201.99'}, {'price': '0.429', 'size': '25'}, {'price': '0.44', 'size': '100'}, {'price': '0.446', 'size': '60'}, {'price': '0.449', 'size': '21'}, {'price': '0.45', 'size': '200'}, {'price': '0.455', 'size': '100'}, {'price': '0.456', 'size': '429'}, {'price': '0.463', 'size': '445'}, {'price': '0.472', 'size': '211'}, {'price': '0.479', 'size': '2241'}, {'price': '0.48', 'size': '500'}, {'price': '0.482', 'size': '21.44'}, {'price': '0.491', 'size': '100'}, {'price': '0.499', 'size': '17'}, {'price': '0.5', 'size': '2869.52'}, {'price': '0.501', 'size': '100'}, {'price': '0.504', 'size': '80'}, {'price': '0.505', 'size': '1000'}, {'price': '0.509', 'size': '50'}, {'price': '0.51', 'size': '150'}, {'price': '0.519', 'size': '15'}, {'price': '0.52', 'size': '364.62'}, {'price': '0.521', 'size': '5000'}, {'price': '0.524', 'size': '130'}, {'price': '0.527', 'size': '2222'}, {'price': '0.528', 'size': '487.05'}, {'price': '0.53', 'size': '1509'}, {'price': '0.54', 'size': '2243.6'}, {'price': '0.541', 'size': '1100'}, {'price': '0.542', 'size': '250'}], 'asks': [{'price': '0.999', 'size': '20000.17'}, {'price': '0.998', 'size': '2371.78'}, {'price': '0.99', 'size': '80.39'}, {'price': '0.984', 'size': '10059.05'}, {'price': '0.983', 'size': '1000'}, {'price': '0.98', 'size': '193.52'}, {'price': '0.979', 'size': '516'}, {'price': '0.978', 'size': '1000'}, {'price': '0.9', 'size': '440'}, {'price': '0.889', 'size': '10000'}, {'price': '0.888', 'size': '4000'}, {'price': '0.886', 'size': '5000'}, {'price': '0.885', 'size': '3651'}, {'price': '0.847', 'size': '5555'}, {'price': '0.846', 'size': '8000'}, {'price': '0.83', 'size': '8000'}, {'price': '0.82', 'size': '5.31'}, {'price': '0.807', 'size': '5'}, {'price': '0.806', 'size': '3000'}, {'price': '0.78', 'size': '5000'}, {'price': '0.777', 'size': '500'}, {'price': '0.765', 'size': '131.67'}, {'price': '0.75', 'size': '420'}, {'price': '0.746', 'size': '5000'}, {'price': '0.744', 'size': '2504.19'}, {'price': '0.741', 'size': '50'}, {'price': '0.74', 'size': '2000'}, {'price': '0.739', 'size': '3333'}, {'price': '0.719', 'size': '50'}, {'price': '0.714', 'size': '15000'}, {'price': '0.712', 'size': '50'}, {'price': '0.711', 'size': '2500'}, {'price': '0.71', 'size': '170'}, {'price': '0.702', 'size': '80'}, {'price': '0.7', 'size': '2306.13'}, {'price': '0.695', 'size': '150'}, {'price': '0.691', 'size': '1378'}, {'price': '0.671', 'size': '8'}, {'price': '0.66', 'size': '197.98'}, {'price': '0.658', 'size': '48.86'}, {'price': '0.657', 'size': '1000'}, {'price': '0.65', 'size': '20'}, {'price': '0.645', 'size': '1391.79'}, {'price': '0.64', 'size': '4444'}, {'price': '0.639', 'size': '1000'}, {'price': '0.631', 'size': '55'}, {'price': '0.63', 'size': '8555'}, {'price': '0.629', 'size': '2272'}, {'price': '0.624', 'size': '500'}, {'price': '0.621', 'size': '8.75'}, {'price': '0.615', 'size': '2999'}, {'price': '0.613', 'size': '24.66'}, {'price': '0.611', 'size': '11818.05'}, {'price': '0.61', 'size': '1051.29'}, {'price': '0.607', 'size': '1666'}, {'price': '0.604', 'size': '1384.01'}, {'price': '0.603', 'size': '500'}, {'price': '0.6', 'size': '2220'}, {'price': '0.599', 'size': '555'}, {'price': '0.597', 'size': '2333.81'}, {'price': '0.596', 'size': '500'}, {'price': '0.585', 'size': '222'}, {'price': '0.584', 'size': '500'}, {'price': '0.581', 'size': '888'}, {'price': '0.58', 'size': '1100.02'}, {'price': '0.579', 'size': '161.52'}, {'price': '0.578', 'size': '47.39'}, {'price': '0.573', 'size': '472'}, {'price': '0.572', 'size': '400'}, {'price': '0.57', 'size': '21'}, {'price': '0.563', 'size': '59.86'}, {'price': '0.562', 'size': '91'}, {'price': '0.561', 'size': '24'}, {'price': '0.56', 'size': '28.58'}], 'event_type': 'book'}
{'asset_id': '72936048731589292555781174533757608024096898681344338816447372274344589246891', 'changes': [{'price': '0.53', 'side': 'BUY', 'size': '1608.18'}], 'event_type': 'price_change', 'hash': '4cb74da0bd18bf2b60de9f412ecfc3a0d20b3f6d', 'market': '0x84c0ffe3f56cb357ff5ff8bc5d2182ae90be4dd6718e8403a6af472b452dbfa8', 'timestamp': '1733411286840'}
{'asset_id': '72936048731589292555781174533757608024096898681344338816447372274344589246891', 'changes': [{'price': '0.579', 'side': 'SELL', 'size': '189.19'}], 'event_type': 'price_change', 'hash': '5700ce88faf098f236dbda094bd15026c5662a96', 'market': '0x84c0ffe3f56cb357ff5ff8bc5d2182ae90be4dd6718e8403a6af472b452dbfa8', 'timestamp': '1733411287043'}
{'asset_id': '72936048731589292555781174533757608024096898681344338816447372274344589246891', 'changes': [{'price': '0.528', 'side': 'BUY', 'size': '1180.03'}], 'event_type': 'price_change', 'hash': '4416903cad3d7252e0214210bb3017ff6c7dfc79', 'market': '0x84c0ffe3f56cb357ff5ff8bc5d2182ae90be4dd6718e8403a6af472b452dbfa8', 'timestamp': '1733411293532'}
{'asset_id': '72936048731589292555781174533757608024096898681344338816447372274344589246891', 'changes': [{'price': '0.576', 'side': 'SELL', 'size': '692.98'}], 'event_type': 'price_change', 'hash': '3d11aa4e9fc4ce0ebd5be1c21f281ca514961ab4', 'market': '0x84c0ffe3f56cb357ff5ff8bc5d2182ae90be4dd6718e8403a6af472b452dbfa8', 'timestamp': '1733411293814'}
{'asset_id': '72936048731589292555781174533757608024096898681344338816447372274344589246891', 'changes': [{'price': '0.576', 'side': 'SELL', 'size': '0'}, {'price': '0.528', 'side': 'BUY', 'size': '487.05'}], 'event_type': 'price_change', 'hash': '0d6dea697fe4fb2f1ad19c2e40171a69d9e81c9f', 'market': '0x84c0ffe3f56cb357ff5ff8bc5d2182ae90be4dd6718e8403a6af472b452dbfa8', 'timestamp': '1733411294333'}
{'asset_id': '72936048731589292555781174533757608024096898681344338816447372274344589246891', 'changes': [{'price': '0.421', 'side': 'BUY', 'size': '0'}], 'event_type': 'price_change', 'hash': 'dfaf42b6f9ecd5d0118946292f9b9cd2531e7215', 'market': '0x84c0ffe3f56cb357ff5ff8bc5d2182ae90be4dd6718e8403a6af472b452dbfa8', 'timestamp': '1733411315081'}
{'asset_id': '72936048731589292555781174533757608024096898681344338816447372274344589246891', 'changes': [{'price': '0.543', 'side': 'BUY', 'size': '686.19'}], 'event_type': 'price_change', 'hash': '90eb3a68a44bf03255e63ccc1e548145d9a02d27', 'market': '0x84c0ffe3f56cb357ff5ff8bc5d2182ae90be4dd6718e8403a6af472b452dbfa8', 'timestamp': '1733411340690'}
{'asset_id': '72936048731589292555781174533757608024096898681344338816447372274344589246891', 'changes': [{'price': '0.528', 'side': 'BUY', 'size': '1180.03'}], 'event_type': 'price_change', 'hash': 'fe4a01fb96147d90d30e1ad6f76aede44533a252', 'market': '0x84c0ffe3f56cb357ff5ff8bc5d2182ae90be4dd6718e8403a6af472b452dbfa8', 'timestamp': '1733411345676'}
{'asset_id': '72936048731589292555781174533757608024096898681344338816447372274344589246891', 'changes': [{'price': '0.576', 'side': 'SELL', 'size': '692.98'}], 'event_type': 'price_change', 'hash': 'f8e937f3c3e1bc219a54fd1adc1ccf2b27d34152', 'market': '0x84c0ffe3f56cb357ff5ff8bc5d2182ae90be4dd6718e8403a6af472b452dbfa8', 'timestamp': '1733411345971'}
{'asset_id': '72936048731589292555781174533757608024096898681344338816447372274344589246891', 'changes': [{'price': '0.57', 'side': 'SELL', 'size': '0'}], 'event_type': 'price_change', 'hash': '532f2d5b9ff76aa350132622014e4147ff7d70f6', 'market': '0x84c0ffe3f56cb357ff5ff8bc5d2182ae90be4dd6718e8403a6af472b452dbfa8', 'timestamp': '1733411348957'}
{'asset_id': '72936048731589292555781174533757608024096898681344338816447372274344589246891', 'changes': [{'price': '0.569', 'side': 'SELL', 'size': '21'}], 'event_type': 'price_change', 'hash': 'eaaad425a9647ad9d60c6b33cefb2987d29fcd89', 'market': '0x84c0ffe3f56cb357ff5ff8bc5d2182ae90be4dd6718e8403a6af472b452dbfa8', 'timestamp': '1733411349420'}
{'market': '0x84c0ffe3f56cb357ff5ff8bc5d2182ae90be4dd6718e8403a6af472b452dbfa8', 'asset_id': '72936048731589292555781174533757608024096898681344338816447372274344589246891', 'timestamp': '1733411501338', 'hash': '2fcf043f62dc7115e56390445a7a1583832c556d', 'bids': [{'price': '0.001', 'size': '10000'}, {'price': '0.002', 'size': '15000'}, {'price': '0.003', 'size': '3000'}, {'price': '0.004', 'size': '2049'}, {'price': '0.005', 'size': '1000'}, {'price': '0.007', 'size': '5000'}, {'price': '0.019', 'size': '500'}, {'price': '0.02', 'size': '2060'}, {'price': '0.021', 'size': '50'}, {'price': '0.07', 'size': '2000'}, {'price': '0.093', 'size': '2591.01'}, {'price': '0.094', 'size': '6382'}, {'price': '0.111', 'size': '333'}, {'price': '0.114', 'size': '3682'}, {'price': '0.17', 'size': '125'}, {'price': '0.2', 'size': '3629.03'}, {'price': '0.201', 'size': '1000'}, {'price': '0.214', 'size': '3333'}, {'price': '0.22', 'size': '90'}, {'price': '0.24', 'size': '80'}, {'price': '0.26', 'size': '70'}, {'price': '0.27', 'size': '50'}, {'price': '0.281', 'size': '500'}, {'price': '0.29', 'size': '40'}, {'price': '0.3', 'size': '155.37'}, {'price': '0.307', 'size': '272'}, {'price': '0.31', 'size': '35'}, {'price': '0.33', 'size': '31'}, {'price': '0.335', 'size': '111'}, {'price': '0.35', 'size': '2258.06'}, {'price': '0.352', 'size': '50'}, {'price': '0.359', 'size': '30'}, {'price': '0.37', 'size': '270'}, {'price': '0.38', 'size': '30'}, {'price': '0.382', 'size': '333'}, {'price': '0.39', 'size': '473.12'}, {'price': '0.4', 'size': '330'}, {'price': '0.401', 'size': '1111'}, {'price': '0.403', 'size': '100'}, {'price': '0.409', 'size': '30'}, {'price': '0.411', 'size': '52.8'}, {'price': '0.42', 'size': '10000'}, {'price': '0.422', 'size': '201.99'}, {'price': '0.429', 'size': '25'}, {'price': '0.44', 'size': '100'}, {'price': '0.446', 'size': '60'}, {'price': '0.449', 'size': '21'}, {'price': '0.45', 'size': '200'}, {'price': '0.455', 'size': '100'}, {'price': '0.456', 'size': '429'}, {'price': '0.463', 'size': '445'}, {'price': '0.472', 'size': '211'}, {'price': '0.479', 'size': '2241'}, {'price': '0.48', 'size': '500'}, {'price': '0.482', 'size': '21.44'}, {'price': '0.491', 'size': '100'}, {'price': '0.499', 'size': '17'}, {'price': '0.5', 'size': '2869.52'}, {'price': '0.501', 'size': '100'}, {'price': '0.504', 'size': '80'}, {'price': '0.505', 'size': '1000'}, {'price': '0.509', 'size': '50'}, {'price': '0.51', 'size': '150'}, {'price': '0.519', 'size': '15'}, {'price': '0.52', 'size': '364.62'}, {'price': '0.521', 'size': '5000'}, {'price': '0.524', 'size': '130'}, {'price': '0.527', 'size': '2222'}, {'price': '0.528', 'size': '1180.03'}, {'price': '0.53', 'size': '1478.18'}, {'price': '0.54', 'size': '2370.6'}, {'price': '0.541', 'size': '1000'}, {'price': '0.542', 'size': '250'}, {'price': '0.543', 'size': '686.19'}, {'price': '0.544', 'size': '1000'}, {'price': '0.545', 'size': '154.4'}], 'asks': [{'price': '0.999', 'size': '20000.17'}, {'price': '0.998', 'size': '2371.78'}, {'price': '0.99', 'size': '80.39'}, {'price': '0.984', 'size': '10059.05'}, {'price': '0.983', 'size': '1000'}, {'price': '0.98', 'size': '193.52'}, {'price': '0.979', 'size': '516'}, {'price': '0.978', 'size': '1000'}, {'price': '0.9', 'size': '440'}, {'price': '0.889', 'size': '10000'}, {'price': '0.888', 'size': '4000'}, {'price': '0.886', 'size': '5000'}, {'price': '0.885', 'size': '3651'}, {'price': '0.847', 'size': '5555'}, {'price': '0.846', 'size': '8000'}, {'price': '0.83', 'size': '8000'}, {'price': '0.82', 'size': '5.31'}, {'price': '0.807', 'size': '5'}, {'price': '0.806', 'size': '3000'}, {'price': '0.78', 'size': '5000'}, {'price': '0.777', 'size': '500'}, {'price': '0.765', 'size': '131.67'}, {'price': '0.75', 'size': '420'}, {'price': '0.746', 'size': '5000'}, {'price': '0.744', 'size': '2504.19'}, {'price': '0.741', 'size': '50'}, {'price': '0.74', 'size': '2000'}, {'price': '0.739', 'size': '3333'}, {'price': '0.719', 'size': '50'}, {'price': '0.714', 'size': '15000'}, {'price': '0.712', 'size': '50'}, {'price': '0.711', 'size': '2500'}, {'price': '0.71', 'size': '170'}, {'price': '0.702', 'size': '80'}, {'price': '0.7', 'size': '2306.13'}, {'price': '0.695', 'size': '150'}, {'price': '0.691', 'size': '1378'}, {'price': '0.671', 'size': '8'}, {'price': '0.66', 'size': '197.98'}, {'price': '0.658', 'size': '48.86'}, {'price': '0.657', 'size': '1000'}, {'price': '0.65', 'size': '20'}, {'price': '0.645', 'size': '1391.79'}, {'price': '0.64', 'size': '4444'}, {'price': '0.639', 'size': '1000'}, {'price': '0.631', 'size': '55'}, {'price': '0.63', 'size': '8555'}, {'price': '0.629', 'size': '2272'}, {'price': '0.624', 'size': '500'}, {'price': '0.621', 'size': '8.75'}, {'price': '0.615', 'size': '2999'}, {'price': '0.613', 'size': '24.66'}, {'price': '0.611', 'size': '11818.05'}, {'price': '0.61', 'size': '1051.29'}, {'price': '0.607', 'size': '1666'}, {'price': '0.604', 'size': '1384.01'}, {'price': '0.603', 'size': '500'}, {'price': '0.6', 'size': '2220'}, {'price': '0.599', 'size': '555'}, {'price': '0.597', 'size': '2333.81'}, {'price': '0.596', 'size': '500'}, {'price': '0.585', 'size': '222'}, {'price': '0.584', 'size': '500'}, {'price': '0.581', 'size': '888'}, {'price': '0.58', 'size': '1100.02'}, {'price': '0.579', 'size': '189.19'}, {'price': '0.578', 'size': '47.39'}, {'price': '0.576', 'size': '692.98'}, {'price': '0.573', 'size': '472'}, {'price': '0.571', 'size': '341'}, {'price': '0.569', 'size': '77'}, {'price': '0.568', 'size': '400'}, {'price': '0.567', 'size': '400'}, {'price': '0.564', 'size': '92'}, {'price': '0.563', 'size': '59.86'}, {'price': '0.559', 'size': '44'}, {'price': '0.558', 'size': '28.6'}], 'event_type': 'book'}
{'market': '0x84c0ffe3f56cb357ff5ff8bc5d2182ae90be4dd6718e8403a6af472b452dbfa8', 'asset_id': '72936048731589292555781174533757608024096898681344338816447372274344589246891', 'timestamp': '1733411501338', 'hash': '2fcf043f62dc7115e56390445a7a1583832c556d', 'bids': [{'price': '0.001', 'size': '10000'}, {'price': '0.002', 'size': '15000'}, {'price': '0.003', 'size': '3000'}, {'price': '0.004', 'size': '2049'}, {'price': '0.005', 'size': '1000'}, {'price': '0.007', 'size': '5000'}, {'price': '0.019', 'size': '500'}, {'price': '0.02', 'size': '2060'}, {'price': '0.021', 'size': '50'}, {'price': '0.07', 'size': '2000'}, {'price': '0.093', 'size': '2591.01'}, {'price': '0.094', 'size': '6382'}, {'price': '0.111', 'size': '333'}, {'price': '0.114', 'size': '3682'}, {'price': '0.17', 'size': '125'}, {'price': '0.2', 'size': '3629.03'}, {'price': '0.201', 'size': '1000'}, {'price': '0.214', 'size': '3333'}, {'price': '0.22', 'size': '90'}, {'price': '0.24', 'size': '80'}, {'price': '0.26', 'size': '70'}, {'price': '0.27', 'size': '50'}, {'price': '0.281', 'size': '500'}, {'price': '0.29', 'size': '40'}, {'price': '0.3', 'size': '155.37'}, {'price': '0.307', 'size': '272'}, {'price': '0.31', 'size': '35'}, {'price': '0.33', 'size': '31'}, {'price': '0.335', 'size': '111'}, {'price': '0.35', 'size': '2258.06'}, {'price': '0.352', 'size': '50'}, {'price': '0.359', 'size': '30'}, {'price': '0.37', 'size': '270'}, {'price': '0.38', 'size': '30'}, {'price': '0.382', 'size': '333'}, {'price': '0.39', 'size': '473.12'}, {'price': '0.4', 'size': '330'}, {'price': '0.401', 'size': '1111'}, {'price': '0.403', 'size': '100'}, {'price': '0.409', 'size': '30'}, {'price': '0.411', 'size': '52.8'}, {'price': '0.42', 'size': '10000'}, {'price': '0.422', 'size': '201.99'}, {'price': '0.429', 'size': '25'}, {'price': '0.44', 'size': '100'}, {'price': '0.446', 'size': '60'}, {'price': '0.449', 'size': '21'}, {'price': '0.45', 'size': '200'}, {'price': '0.455', 'size': '100'}, {'price': '0.456', 'size': '429'}, {'price': '0.463', 'size': '445'}, {'price': '0.472', 'size': '211'}, {'price': '0.479', 'size': '2241'}, {'price': '0.48', 'size': '500'}, {'price': '0.482', 'size': '21.44'}, {'price': '0.491', 'size': '100'}, {'price': '0.499', 'size': '17'}, {'price': '0.5', 'size': '2869.52'}, {'price': '0.501', 'size': '100'}, {'price': '0.504', 'size': '80'}, {'price': '0.505', 'size': '1000'}, {'price': '0.509', 'size': '50'}, {'price': '0.51', 'size': '150'}, {'price': '0.519', 'size': '15'}, {'price': '0.52', 'size': '364.62'}, {'price': '0.521', 'size': '5000'}, {'price': '0.524', 'size': '130'}, {'price': '0.527', 'size': '2222'}, {'price': '0.528', 'size': '1180.03'}, {'price': '0.53', 'size': '1478.18'}, {'price': '0.54', 'size': '2370.6'}, {'price': '0.541', 'size': '1000'}, {'price': '0.542', 'size': '250'}, {'price': '0.543', 'size': '686.19'}, {'price': '0.544', 'size': '1000'}, {'price': '0.545', 'size': '154.4'}], 'asks': [{'price': '0.999', 'size': '20000.17'}, {'price': '0.998', 'size': '2371.78'}, {'price': '0.99', 'size': '80.39'}, {'price': '0.984', 'size': '10059.05'}, {'price': '0.983', 'size': '1000'}, {'price': '0.98', 'size': '193.52'}, {'price': '0.979', 'size': '516'}, {'price': '0.978', 'size': '1000'}, {'price': '0.9', 'size': '440'}, {'price': '0.889', 'size': '10000'}, {'price': '0.888', 'size': '4000'}, {'price': '0.886', 'size': '5000'}, {'price': '0.885', 'size': '3651'}, {'price': '0.847', 'size': '5555'}, {'price': '0.846', 'size': '8000'}, {'price': '0.83', 'size': '8000'}, {'price': '0.82', 'size': '5.31'}, {'price': '0.807', 'size': '5'}, {'price': '0.806', 'size': '3000'}, {'price': '0.78', 'size': '5000'}, {'price': '0.777', 'size': '500'}, {'price': '0.765', 'size': '131.67'}, {'price': '0.75', 'size': '420'}, {'price': '0.746', 'size': '5000'}, {'price': '0.744', 'size': '2504.19'}, {'price': '0.741', 'size': '50'}, {'price': '0.74', 'size': '2000'}, {'price': '0.739', 'size': '3333'}, {'price': '0.719', 'size': '50'}, {'price': '0.714', 'size': '15000'}, {'price': '0.712', 'size': '50'}, {'price': '0.711', 'size': '2500'}, {'price': '0.71', 'size': '170'}, {'price': '0.702', 'size': '80'}, {'price': '0.7', 'size': '2306.13'}, {'price': '0.695', 'size': '150'}, {'price': '0.691', 'size': '1378'}, {'price': '0.671', 'size': '8'}, {'price': '0.66', 'size': '197.98'}, {'price': '0.658', 'size': '48.86'}, {'price': '0.657', 'size': '1000'}, {'price': '0.65', 'size': '20'}, {'price': '0.645', 'size': '1391.79'}, {'price': '0.64', 'size': '4444'}, {'price': '0.639', 'size': '1000'}, {'price': '0.631', 'size': '55'}, {'price': '0.63', 'size': '8555'}, {'price': '0.629', 'size': '2272'}, {'price': '0.624', 'size': '500'}, {'price': '0.621', 'size': '8.75'}, {'price': '0.615', 'size': '2999'}, {'price': '0.613', 'size': '24.66'}, {'price': '0.611', 'size': '11818.05'}, {'price': '0.61', 'size': '1051.29'}, {'price': '0.607', 'size': '1666'}, {'price': '0.604', 'size': '1384.01'}, {'price': '0.603', 'size': '500'}, {'price': '0.6', 'size': '2220'}, {'price': '0.599', 'size': '555'}, {'price': '0.597', 'size': '2333.81'}, {'price': '0.596', 'size': '500'}, {'price': '0.585', 'size': '222'}, {'price': '0.584', 'size': '500'}, {'price': '0.581', 'size': '888'}, {'price': '0.58', 'size': '1100.02'}, {'price': '0.579', 'size': '189.19'}, {'price': '0.578', 'size': '47.39'}, {'price': '0.576', 'size': '692.98'}, {'price': '0.573', 'size': '472'}, {'price': '0.571', 'size': '341'}, {'price': '0.569', 'size': '77'}, {'price': '0.568', 'size': '400'}, {'price': '0.567', 'size': '400'}, {'price': '0.564', 'size': '92'}, {'price': '0.563', 'size': '59.86'}, {'price': '0.559', 'size': '44'}, {'price': '0.558', 'size': '28.6'}], 'event_type': 'book'}
{'asks': [{'price': '0.999', 'size': '20000.17'}, {'price': '0.998', 'size': '2371.78'}, {'price': '0.99', 'size': '80.39'}, {'price': '0.984', 'size': '10059.05'}, {'price': '0.983', 'size': '1000'}, {'price': '0.98', 'size': '193.52'}, {'price': '0.979', 'size': '516'}, {'price': '0.978', 'size': '1000'}, {'price': '0.9', 'size': '440'}, {'price': '0.889', 'size': '10000'}, {'price': '0.888', 'size': '4000'}, {'price': '0.886', 'size': '5000'}, {'price': '0.885', 'size': '3651'}, {'price': '0.847', 'size': '5555'}, {'price': '0.846', 'size': '8000'}, {'price': '0.83', 'size': '8000'}, {'price': '0.82', 'size': '5.31'}, {'price': '0.807', 'size': '5'}, {'price': '0.806', 'size': '3000'}, {'price': '0.78', 'size': '5000'}, {'price': '0.777', 'size': '500'}, {'price': '0.765', 'size': '131.67'}, {'price': '0.75', 'size': '420'}, {'price': '0.746', 'size': '5000'}, {'price': '0.744', 'size': '2504.19'}, {'price': '0.741', 'size': '50'}, {'price': '0.74', 'size': '2000'}, {'price': '0.739', 'size': '3333'}, {'price': '0.719', 'size': '50'}, {'price': '0.714', 'size': '15000'}, {'price': '0.712', 'size': '50'}, {'price': '0.711', 'size': '2500'}, {'price': '0.71', 'size': '170'}, {'price': '0.702', 'size': '80'}, {'price': '0.7', 'size': '2306.13'}, {'price': '0.695', 'size': '150'}, {'price': '0.691', 'size': '1378'}, {'price': '0.671', 'size': '8'}, {'price': '0.66', 'size': '197.98'}, {'price': '0.658', 'size': '48.86'}, {'price': '0.657', 'size': '1000'}, {'price': '0.65', 'size': '20'}, {'price': '0.645', 'size': '1391.79'}, {'price': '0.64', 'size': '4444'}, {'price': '0.639', 'size': '1000'}, {'price': '0.631', 'size': '55'}, {'price': '0.63', 'size': '8555'}, {'price': '0.629', 'size': '2272'}, {'price': '0.624', 'size': '500'}, {'price': '0.621', 'size': '8.75'}, {'price': '0.615', 'size': '2999'}, {'price': '0.613', 'size': '24.66'}, {'price': '0.611', 'size': '11818.05'}, {'price': '0.61', 'size': '1051.29'}, {'price': '0.607', 'size': '1666'}, {'price': '0.604', 'size': '1384.01'}, {'price': '0.603', 'size': '500'}, {'price': '0.6', 'size': '2220'}, {'price': '0.599', 'size': '555'}, {'price': '0.597', 'size': '2333.81'}, {'price': '0.596', 'size': '500'}, {'price': '0.585', 'size': '222'}, {'price': '0.584', 'size': '500'}, {'price': '0.581', 'size': '888'}, {'price': '0.58', 'size': '497.43'}], 'asset_id': '72936048731589292555781174533757608024096898681344338816447372274344589246891', 'bids': [{'price': '0.001', 'size': '10000'}, {'price': '0.002', 'size': '15000'}, {'price': '0.003', 'size': '3000'}, {'price': '0.004', 'size': '2049'}, {'price': '0.005', 'size': '1000'}, {'price': '0.007', 'size': '5000'}, {'price': '0.019', 'size': '500'}, {'price': '0.02', 'size': '2060'}, {'price': '0.021', 'size': '50'}, {'price': '0.07', 'size': '2000'}, {'price': '0.093', 'size': '2591.01'}, {'price': '0.094', 'size': '6382'}, {'price': '0.111', 'size': '333'}, {'price': '0.114', 'size': '3682'}, {'price': '0.17', 'size': '125'}, {'price': '0.2', 'size': '3629.03'}, {'price': '0.201', 'size': '1000'}, {'price': '0.214', 'size': '3333'}, {'price': '0.22', 'size': '90'}, {'price': '0.24', 'size': '80'}, {'price': '0.26', 'size': '70'}, {'price': '0.27', 'size': '50'}, {'price': '0.281', 'size': '500'}, {'price': '0.29', 'size': '40'}, {'price': '0.3', 'size': '155.37'}, {'price': '0.307', 'size': '272'}, {'price': '0.31', 'size': '35'}, {'price': '0.33', 'size': '31'}, {'price': '0.335', 'size': '111'}, {'price': '0.35', 'size': '2258.06'}, {'price': '0.352', 'size': '50'}, {'price': '0.359', 'size': '30'}, {'price': '0.37', 'size': '270'}, {'price': '0.38', 'size': '30'}, {'price': '0.382', 'size': '333'}, {'price': '0.39', 'size': '473.12'}, {'price': '0.4', 'size': '330'}, {'price': '0.401', 'size': '1111'}, {'price': '0.403', 'size': '100'}, {'price': '0.409', 'size': '30'}, {'price': '0.411', 'size': '52.8'}, {'price': '0.42', 'size': '10000'}, {'price': '0.422', 'size': '201.99'}, {'price': '0.429', 'size': '25'}, {'price': '0.44', 'size': '100'}, {'price': '0.446', 'size': '60'}, {'price': '0.449', 'size': '21'}, {'price': '0.45', 'size': '200'}, {'price': '0.455', 'size': '100'}, {'price': '0.456', 'size': '429'}, {'price': '0.463', 'size': '445'}, {'price': '0.472', 'size': '211'}, {'price': '0.479', 'size': '2241'}, {'price': '0.48', 'size': '500'}, {'price': '0.482', 'size': '21.44'}, {'price': '0.491', 'size': '100'}, {'price': '0.499', 'size': '17'}, {'price': '0.5', 'size': '2869.52'}, {'price': '0.501', 'size': '100'}, {'price': '0.504', 'size': '80'}, {'price': '0.505', 'size': '1000'}, {'price': '0.509', 'size': '50'}, {'price': '0.51', 'size': '150'}, {'price': '0.519', 'size': '15'}, {'price': '0.52', 'size': '364.62'}, {'price': '0.521', 'size': '5000'}, {'price': '0.524', 'size': '130'}, {'price': '0.527', 'size': '2222'}, {'price': '0.528', 'size': '1180.03'}, {'price': '0.53', 'size': '1478.18'}, {'price': '0.54', 'size': '2370.6'}, {'price': '0.541', 'size': '1000'}, {'price': '0.542', 'size': '250'}, {'price': '0.543', 'size': '686.19'}, {'price': '0.544', 'size': '1000'}, {'price': '0.545', 'size': '154.4'}], 'event_type': 'book', 'hash': '4a06d8067a38eec5ac61570bf71961f020c926ed', 'market': '0x84c0ffe3f56cb357ff5ff8bc5d2182ae90be4dd6718e8403a6af472b452dbfa8', 'timestamp': '1733411506950'}
{'asset_id': '72936048731589292555781174533757608024096898681344338816447372274344589246891', 'event_type': 'last_trade_price', 'fee_rate_bps': '0', 'market': '0x84c0ffe3f56cb357ff5ff8bc5d2182ae90be4dd6718e8403a6af472b452dbfa8', 'price': '0.573', 'side': 'BUY', 'size': '3446.601223', 'timestamp': '1733411506990'}
{'asset_id': '72936048731589292555781174533757608024096898681344338816447372274344589246891', 'changes': [{'price': '0.571', 'side': 'SELL', 'size': '20'}], 'event_type': 'price_change', 'hash': '1cbb677d674e1bc3805be9d99253b5b4af3e4448', 'market': '0x84c0ffe3f56cb357ff5ff8bc5d2182ae90be4dd6718e8403a6af472b452dbfa8', 'timestamp': '1733411507048'}
{'asset_id': '72936048731589292555781174533757608024096898681344338816447372274344589246891', 'changes': [{'price': '0.571', 'side': 'SELL', 'size': '20'}], 'event_type': 'price_change', 'hash': '1cbb677d674e1bc3805be9d99253b5b4af3e4448', 'market': '0x84c0ffe3f56cb357ff5ff8bc5d2182ae90be4dd6718e8403a6af472b452dbfa8', 'timestamp': '1733411507048'}
{'asset_id': '72936048731589292555781174533757608024096898681344338816447372274344589246891', 'changes': [{'price': '0.567', 'side': 'SELL', 'size': '400'}], 'event_type': 'price_change', 'hash': 'cf2e4cba4449be0fd9e2f2d8074fbaf30ebed12f', 'market': '0x84c0ffe3f56cb357ff5ff8bc5d2182ae90be4dd6718e8403a6af472b452dbfa8', 'timestamp': '1733411507170'}
{'asset_id': '72936048731589292555781174533757608024096898681344338816447372274344589246891', 'changes': [{'price': '0.567', 'side': 'SELL', 'size': '400'}], 'event_type': 'price_change', 'hash': 'cf2e4cba4449be0fd9e2f2d8074fbaf30ebed12f', 'market': '0x84c0ffe3f56cb357ff5ff8bc5d2182ae90be4dd6718e8403a6af472b452dbfa8', 'timestamp': '1733411507170'}
{'asset_id': '72936048731589292555781174533757608024096898681344338816447372274344589246891', 'changes': [{'price': '0.566', 'side': 'SELL', 'size': '92'}, {'price': '0.571', 'side': 'SELL', 'size': '0'}, {'price': '0.572', 'side': 'SELL', 'size': '400'}], 'event_type': 'price_change', 'hash': '1a43bc954f3d50897840fcf4c7c19eaca031c0ca', 'market': '0x84c0ffe3f56cb357ff5ff8bc5d2182ae90be4dd6718e8403a6af472b452dbfa8', 'timestamp': '1733411507497'}
{'asset_id': '72936048731589292555781174533757608024096898681344338816447372274344589246891', 'changes': [{'price': '0.566', 'side': 'SELL', 'size': '92'}, {'price': '0.571', 'side': 'SELL', 'size': '0'}, {'price': '0.572', 'side': 'SELL', 'size': '400'}], 'event_type': 'price_change', 'hash': '1a43bc954f3d50897840fcf4c7c19eaca031c0ca', 'market': '0x84c0ffe3f56cb357ff5ff8bc5d2182ae90be4dd6718e8403a6af472b452dbfa8', 'timestamp': '1733411507497'}
{'asset_id': '72936048731589292555781174533757608024096898681344338816447372274344589246891', 'changes': [{'price': '0.528', 'side': 'BUY', 'size': '487.05'}, {'price': '0.565', 'side': 'SELL', 'size': '20'}], 'event_type': 'price_change', 'hash': 'ed11b66997299459bbc77a0ecf5730dce7a5172d', 'market': '0x84c0ffe3f56cb357ff5ff8bc5d2182ae90be4dd6718e8403a6af472b452dbfa8', 'timestamp': '1733411507554'}
{'asset_id': '72936048731589292555781174533757608024096898681344338816447372274344589246891', 'changes': [{'price': '0.528', 'side': 'BUY', 'size': '487.05'}, {'price': '0.565', 'side': 'SELL', 'size': '20'}], 'event_type': 'price_change', 'hash': 'ed11b66997299459bbc77a0ecf5730dce7a5172d', 'market': '0x84c0ffe3f56cb357ff5ff8bc5d2182ae90be4dd6718e8403a6af472b452dbfa8', 'timestamp': '1733411507554'}
{'asset_id': '72936048731589292555781174533757608024096898681344338816447372274344589246891', 'changes': [{'price': '0.573', 'side': 'SELL', 'size': '400'}], 'event_type': 'price_change', 'hash': 'c93e51ab104fc3ab64d168364cb21ffdf6149631', 'market': '0x84c0ffe3f56cb357ff5ff8bc5d2182ae90be4dd6718e8403a6af472b452dbfa8', 'timestamp': '1733411507675'}
{'asset_id': '72936048731589292555781174533757608024096898681344338816447372274344589246891', 'changes': [{'price': '0.573', 'side': 'SELL', 'size': '400'}], 'event_type': 'price_change', 'hash': 'c93e51ab104fc3ab64d168364cb21ffdf6149631', 'market': '0x84c0ffe3f56cb357ff5ff8bc5d2182ae90be4dd6718e8403a6af472b452dbfa8', 'timestamp': '1733411507675'}
{'asset_id': '72936048731589292555781174533757608024096898681344338816447372274344589246891', 'changes': [{'price': '0.567', 'side': 'SELL', 'size': '0'}], 'event_type': 'price_change', 'hash': '956afca6085b3dab1ef9bea124d1211d5ea3d50e', 'market': '0x84c0ffe3f56cb357ff5ff8bc5d2182ae90be4dd6718e8403a6af472b452dbfa8', 'timestamp': '1733411507731'}
{'asset_id': '72936048731589292555781174533757608024096898681344338816447372274344589246891', 'changes': [{'price': '0.567', 'side': 'SELL', 'size': '0'}], 'event_type': 'price_change', 'hash': '956afca6085b3dab1ef9bea124d1211d5ea3d50e', 'market': '0x84c0ffe3f56cb357ff5ff8bc5d2182ae90be4dd6718e8403a6af472b452dbfa8', 'timestamp': '1733411507731'}
{'asset_id': '72936048731589292555781174533757608024096898681344338816447372274344589246891', 'changes': [{'price': '0.565', 'side': 'SELL', 'size': '0'}], 'event_type': 'price_change', 'hash': '8564ffab952260a3b079812f6c7f21edb7f90a82', 'market': '0x84c0ffe3f56cb357ff5ff8bc5d2182ae90be4dd6718e8403a6af472b452dbfa8', 'timestamp': '1733411507839'}
{'asset_id': '72936048731589292555781174533757608024096898681344338816447372274344589246891', 'changes': [{'price': '0.565', 'side': 'SELL', 'size': '0'}], 'event_type': 'price_change', 'hash': '8564ffab952260a3b079812f6c7f21edb7f90a82', 'market': '0x84c0ffe3f56cb357ff5ff8bc5d2182ae90be4dd6718e8403a6af472b452dbfa8', 'timestamp': '1733411507839'}
{'asset_id': '72936048731589292555781174533757608024096898681344338816447372274344589246891', 'changes': [{'price': '0.572', 'side': 'SELL', 'size': '0'}], 'event_type': 'price_change', 'hash': '56714fc944758082b0ee7d1aca754aa5719be1fb', 'market': '0x84c0ffe3f56cb357ff5ff8bc5d2182ae90be4dd6718e8403a6af472b452dbfa8', 'timestamp': '1733411507940'}
{'asset_id': '72936048731589292555781174533757608024096898681344338816447372274344589246891', 'changes': [{'price': '0.572', 'side': 'SELL', 'size': '0'}], 'event_type': 'price_change', 'hash': '56714fc944758082b0ee7d1aca754aa5719be1fb', 'market': '0x84c0ffe3f56cb357ff5ff8bc5d2182ae90be4dd6718e8403a6af472b452dbfa8', 'timestamp': '1733411507940'}
{'asset_id': '72936048731589292555781174533757608024096898681344338816447372274344589246891', 'changes': [{'price': '0.546', 'side': 'BUY', 'size': '28.6'}], 'event_type': 'price_change', 'hash': 'b5cd1719e61b09dd7e61df0df6e59de5e6c86def', 'market': '0x84c0ffe3f56cb357ff5ff8bc5d2182ae90be4dd6718e8403a6af472b452dbfa8', 'timestamp': '1733411508596'}
{'asset_id': '72936048731589292555781174533757608024096898681344338816447372274344589246891', 'changes': [{'price': '0.546', 'side': 'BUY', 'size': '28.6'}], 'event_type': 'price_change', 'hash': 'b5cd1719e61b09dd7e61df0df6e59de5e6c86def', 'market': '0x84c0ffe3f56cb357ff5ff8bc5d2182ae90be4dd6718e8403a6af472b452dbfa8', 'timestamp': '1733411508596'}
{'asset_id': '72936048731589292555781174533757608024096898681344338816447372274344589246891', 'changes': [{'price': '0.58', 'side': 'SELL', 'size': '397.43'}], 'event_type': 'price_change', 'hash': 'b55b37176751631963a64ffa88f371f81f04b103', 'market': '0x84c0ffe3f56cb357ff5ff8bc5d2182ae90be4dd6718e8403a6af472b452dbfa8', 'timestamp': '1733411508760'}
{'asset_id': '72936048731589292555781174533757608024096898681344338816447372274344589246891', 'changes': [{'price': '0.58', 'side': 'SELL', 'size': '397.43'}], 'event_type': 'price_change', 'hash': 'b55b37176751631963a64ffa88f371f81f04b103', 'market': '0x84c0ffe3f56cb357ff5ff8bc5d2182ae90be4dd6718e8403a6af472b452dbfa8', 'timestamp': '1733411508760'}
{'asset_id': '72936048731589292555781174533757608024096898681344338816447372274344589246891', 'changes': [{'price': '0.545', 'side': 'BUY', 'size': '0'}], 'event_type': 'price_change', 'hash': '66a78b657cde7efc948fbe6c15dc20a3c48782f8', 'market': '0x84c0ffe3f56cb357ff5ff8bc5d2182ae90be4dd6718e8403a6af472b452dbfa8', 'timestamp': '1733411508952'}
{'asset_id': '72936048731589292555781174533757608024096898681344338816447372274344589246891', 'changes': [{'price': '0.545', 'side': 'BUY', 'size': '0'}], 'event_type': 'price_change', 'hash': '66a78b657cde7efc948fbe6c15dc20a3c48782f8', 'market': '0x84c0ffe3f56cb357ff5ff8bc5d2182ae90be4dd6718e8403a6af472b452dbfa8', 'timestamp': '1733411508952'}
{'asset_id': '72936048731589292555781174533757608024096898681344338816447372274344589246891', 'changes': [{'price': '0.581', 'side': 'SELL', 'size': '988'}], 'event_type': 'price_change', 'hash': 'd52484e506b2d718980cb61c579251fd9d9ae6cb', 'market': '0x84c0ffe3f56cb357ff5ff8bc5d2182ae90be4dd6718e8403a6af472b452dbfa8', 'timestamp': '1733411510472'}
{'asset_id': '72936048731589292555781174533757608024096898681344338816447372274344589246891', 'changes': [{'price': '0.581', 'side': 'SELL', 'size': '988'}], 'event_type': 'price_change', 'hash': 'd52484e506b2d718980cb61c579251fd9d9ae6cb', 'market': '0x84c0ffe3f56cb357ff5ff8bc5d2182ae90be4dd6718e8403a6af472b452dbfa8', 'timestamp': '1733411510472'}
