{'market': '0x7aa4a910b31b2c4ddb09d1e3408e52aa8e09a14402f376070a44b1b85cb36d13', 'asset_id': '114416409796971863099144323163249651172534872992222856507897414949637892047507', 'timestamp': '1733332137587', 'hash': 'bfe36383f80af358589a66dc8f51eb48b2f9cd9a', 'bids': [{'price': '0.01', 'size': '2850.27'}, {'price': '0.02', 'size': '500'}, {'price': '0.03', 'size': '500'}, {'price': '0.04', 'size': '300'}, {'price': '0.05', 'size': '320'}, {'price': '0.06', 'size': '300'}, {'price': '0.08', 'size': '250'}, {'price': '0.09', 'size': '300'}, {'price': '0.1', 'size': '205'}, {'price': '0.11', 'size': '5454'}, {'price': '0.12', 'size': '200'}, {'price': '0.13', 'size': '426.92'}, {'price': '0.14', 'size': '15'}, {'price': '0.15', 'size': '110'}, {'price': '0.16', 'size': '4709.51'}, {'price': '0.18', 'size': '19.13'}, {'price': '0.19', 'size': '120'}, {'price': '0.2', 'size': '691.17'}, {'price': '0.24', 'size': '5027'}, {'price': '0.25', 'size': '86.66'}, {'price': '0.27', 'size': '215.25'}, {'price': '0.29', 'size': '1102.28'}, {'price': '0.31', 'size': '1130.65'}, {'price': '0.32', 'size': '200'}, {'price': '0.33', 'size': '620'}, {'price': '0.34', 'size': '4000'}, {'price': '0.35', 'size': '232'}, {'price': '0.39', 'size': '10.5'}, {'price': '0.4', 'size': '3135'}, {'price': '0.41', 'size': '20'}, {'price': '0.42', 'size': '3050'}, {'price': '0.43', 'size': '50'}, {'price': '0.44', 'size': '3660'}, {'price': '0.45', 'size': '928'}, {'price': '0.46', 'size': '2500'}, {'price': '0.47', 'size': '2050'}, {'price': '0.48', 'size': '1842.18'}, {'price': '0.49', 'size': '360'}, {'price': '0.5', 'size': '115'}, {'price': '0.51', 'size': '1836.18'}, {'price': '0.52', 'size': '120'}, {'price': '0.53', 'size': '16.97'}], 'asks': [{'price': '0.99', 'size': '4217.01'}, {'price': '0.98', 'size': '505'}, {'price': '0.97', 'size': '511.03'}, {'price': '0.96', 'size': '300'}, {'price': '0.95', 'size': '657.12'}, {'price': '0.94', 'size': '300'}, {'price': '0.92', 'size': '20000.45'}, {'price': '0.91', 'size': '10406.3'}, {'price': '0.9', 'size': '4587.5'}, {'price': '0.89', 'size': '13017.18'}, {'price': '0.88', 'size': '200'}, {'price': '0.87', 'size': '3229'}, {'price': '0.86', 'size': '17.1'}, {'price': '0.85', 'size': '109.68'}, {'price': '0.84', 'size': '250'}, {'price': '0.83', 'size': '100'}, {'price': '0.82', 'size': '16029'}, {'price': '0.81', 'size': '45721.39'}, {'price': '0.8', 'size': '26531'}, {'price': '0.79', 'size': '7110'}, {'price': '0.78', 'size': '10350'}, {'price': '0.77', 'size': '67'}, {'price': '0.76', 'size': '5200'}, {'price': '0.75', 'size': '13329.25'}, {'price': '0.74', 'size': '11370.7'}, {'price': '0.73', 'size': '5020.1'}, {'price': '0.72', 'size': '380.52'}, {'price': '0.71', 'size': '15073.2'}, {'price': '0.7', 'size': '5730.1'}, {'price': '0.69', 'size': '6088.6'}, {'price': '0.68', 'size': '2131.34'}, {'price': '0.67', 'size': '3010.1'}, {'price': '0.66', 'size': '510.1'}, {'price': '0.65', 'size': '5010.1'}, {'price': '0.64', 'size': '1590.1'}, {'price': '0.63', 'size': '210.1'}, {'price': '0.62', 'size': '300.1'}, {'price': '0.61', 'size': '111.06'}, {'price': '0.6', 'size': '67.85'}, {'price': '0.59', 'size': '3061.65'}, {'price': '0.58', 'size': '2688.1'}, {'price': '0.57', 'size': '2350.1'}, {'price': '0.56', 'size': '1110.1'}, {'price': '0.55', 'size': '3634.38'}, {'price': '0.54', 'size': '1092.02'}], 'event_type': 'book'}
{'asset_id': '114416409796971863099144323163249651172534872992222856507897414949637892047507', 'changes': [{'price': '0.49', 'side': 'BUY', 'size': '1560'}], 'event_type': 'price_change', 'hash': '303c19df64d746956117744690bc9cde488bdb86', 'market': '0x7aa4a910b31b2c4ddb09d1e3408e52aa8e09a14402f376070a44b1b85cb36d13', 'timestamp': '1733332139984'}
{'asset_id': '114416409796971863099144323163249651172534872992222856507897414949637892047507', 'changes': [{'price': '0.76', 'side': 'SELL', 'size': '200'}], 'event_type': 'price_change', 'hash': 'f4ea5ef2459ff9950d4a844d76c4250bb7ff2fad', 'market': '0x7aa4a910b31b2c4ddb09d1e3408e52aa8e09a14402f376070a44b1b85cb36d13', 'timestamp': '1733332141010'}
{'market': '0x7aa4a910b31b2c4ddb09d1e3408e52aa8e09a14402f376070a44b1b85cb36d13', 'asset_id': '114416409796971863099144323163249651172534872992222856507897414949637892047507', 'timestamp': '1733332141000', 'hash': 'f4ea5ef2459ff9950d4a844d76c4250bb7ff2fad', 'bids': [{'price': '0.01', 'size': '2850.27'}, {'price': '0.02', 'size': '500'}, {'price': '0.03', 'size': '500'}, {'price': '0.04', 'size': '300'}, {'price': '0.05', 'size': '320'}, {'price': '0.06', 'size': '300'}, {'price': '0.08', 'size': '250'}, {'price': '0.09', 'size': '300'}, {'price': '0.1', 'size': '205'}, {'price': '0.11', 'size': '5454'}, {'price': '0.12', 'size': '200'}, {'price': '0.13', 'size': '426.92'}, {'price': '0.14', 'size': '15'}, {'price': '0.15', 'size': '110'}, {'price': '0.16', 'size': '4709.51'}, {'price': '0.18', 'size': '19.13'}, {'price': '0.19', 'size': '120'}, {'price': '0.2', 'size': '691.17'}, {'price': '0.24', 'size': '5027'}, {'price': '0.25', 'size': '86.66'}, {'price': '0.27', 'size': '215.25'}, {'price': '0.29', 'size': '1102.28'}, {'price': '0.31', 'size': '1130.65'}, {'price': '0.32', 'size': '200'}, {'price': '0.33', 'size': '620'}, {'price': '0.34', 'size': '4000'}, {'price': '0.35', 'size': '232'}, {'price': '0.39', 'size': '10.5'}, {'price': '0.4', 'size': '3135'}, {'price': '0.41', 'size': '20'}, {'price': '0.42', 'size': '3050'}, {'price': '0.43', 'size': '50'}, {'price': '0.44', 'size': '3660'}, {'price': '0.45', 'size': '928'}, {'price': '0.46', 'size': '2500'}, {'price': '0.47', 'size': '2050'}, {'price': '0.48', 'size': '1842.18'}, {'price': '0.49', 'size': '1560'}, {'price': '0.5', 'size': '115'}, {'price': '0.51', 'size': '1836.18'}, {'price': '0.52', 'size': '120'}, {'price': '0.53', 'size': '16.97'}], 'asks': [{'price': '0.99', 'size': '4217.01'}, {'price': '0.98', 'size': '505'}, {'price': '0.97', 'size': '511.03'}, {'price': '0.96', 'size': '300'}, {'price': '0.95', 'size': '657.12'}, {'price': '0.94', 'size': '300'}, {'price': '0.92', 'size': '20000.45'}, {'price': '0.91', 'size': '10406.3'}, {'price': '0.9', 'size': '4587.5'}, {'price': '0.89', 'size': '13017.18'}, {'price': '0.88', 'size': '200'}, {'price': '0.87', 'size': '3229'}, {'price': '0.86', 'size': '17.1'}, {'price': '0.85', 'size': '109.68'}, {'price': '0.84', 'size': '250'}, {'price': '0.83', 'size': '100'}, {'price': '0.82', 'size': '16029'}, {'price': '0.81', 'size': '45721.39'}, {'price': '0.8', 'size': '26531'}, {'price': '0.79', 'size': '7110'}, {'price': '0.78', 'size': '10350'}, {'price': '0.77', 'size': '67'}, {'price': '0.76', 'size': '200'}, {'price': '0.75', 'size': '13329.25'}, {'price': '0.74', 'size': '11370.7'}, {'price': '0.73', 'size': '5020.1'}, {'price': '0.72', 'size': '380.52'}, {'price': '0.71', 'size': '15073.2'}, {'price': '0.7', 'size': '5730.1'}, {'price': '0.69', 'size': '6088.6'}, {'price': '0.68', 'size': '2131.34'}, {'price': '0.67', 'size': '3010.1'}, {'price': '0.66', 'size': '510.1'}, {'price': '0.65', 'size': '5010.1'}, {'price': '0.64', 'size': '1590.1'}, {'price': '0.63', 'size': '210.1'}, {'price': '0.62', 'size': '300.1'}, {'price': '0.61', 'size': '111.06'}, {'price': '0.6', 'size': '67.85'}, {'price': '0.59', 'size': '3061.65'}, {'price': '0.58', 'size': '2688.1'}, {'price': '0.57', 'size': '2350.1'}, {'price': '0.56', 'size': '1110.1'}, {'price': '0.55', 'size': '3634.38'}, {'price': '0.54', 'size': '1092.02'}], 'event_type': 'book'}
{'asset_id': '114416409796971863099144323163249651172534872992222856507897414949637892047507', 'changes': [{'price': '0.75', 'side': 'SELL', 'size': '18329.25'}], 'event_type': 'price_change', 'hash': 'a199ebee781ed1363b2ab96d7b518ae7b5cb878c', 'market': '0x7aa4a910b31b2c4ddb09d1e3408e52aa8e09a14402f376070a44b1b85cb36d13', 'timestamp': '1733332148285'}
{'asset_id': '114416409796971863099144323163249651172534872992222856507897414949637892047507', 'changes': [{'price': '0.75', 'side': 'SELL', 'size': '18329.25'}], 'event_type': 'price_change', 'hash': 'a199ebee781ed1363b2ab96d7b518ae7b5cb878c', 'market': '0x7aa4a910b31b2c4ddb09d1e3408e52aa8e09a14402f376070a44b1b85cb36d13', 'timestamp': '1733332148285'}
{'asset_id': '114416409796971863099144323163249651172534872992222856507897414949637892047507', 'changes': [{'price': '0.64', 'side': 'SELL', 'size': '1470.1'}], 'event_type': 'price_change', 'hash': '6d2e350ceb81858a2bbe6cea71505ce3f0aff018', 'market': '0x7aa4a910b31b2c4ddb09d1e3408e52aa8e09a14402f376070a44b1b85cb36d13', 'timestamp': '1733332155498'}
{'asset_id': '114416409796971863099144323163249651172534872992222856507897414949637892047507', 'changes': [{'price': '0.64', 'side': 'SELL', 'size': '1470.1'}], 'event_type': 'price_change', 'hash': '6d2e350ceb81858a2bbe6cea71505ce3f0aff018', 'market': '0x7aa4a910b31b2c4ddb09d1e3408e52aa8e09a14402f376070a44b1b85cb36d13', 'timestamp': '1733332155498'}
{'asset_id': '114416409796971863099144323163249651172534872992222856507897414949637892047507', 'changes': [{'price': '0.45', 'side': 'BUY', 'size': '428'}, {'price': '0.55', 'side': 'SELL', 'size': '3134.38'}, {'price': '0.51', 'side': 'BUY', 'size': '836.18'}], 'event_type': 'price_change', 'hash': '12f6fef6150c4e872f3243fd600f4f2c4f088795', 'market': '0x7aa4a910b31b2c4ddb09d1e3408e52aa8e09a14402f376070a44b1b85cb36d13', 'timestamp': '1733332158180'}
{'asset_id': '114416409796971863099144323163249651172534872992222856507897414949637892047507', 'changes': [{'price': '0.45', 'side': 'BUY', 'size': '428'}, {'price': '0.55', 'side': 'SELL', 'size': '3134.38'}, {'price': '0.51', 'side': 'BUY', 'size': '836.18'}], 'event_type': 'price_change', 'hash': '12f6fef6150c4e872f3243fd600f4f2c4f088795', 'market': '0x7aa4a910b31b2c4ddb09d1e3408e52aa8e09a14402f376070a44b1b85cb36d13', 'timestamp': '1733332158180'}
{'asset_id': '114416409796971863099144323163249651172534872992222856507897414949637892047507', 'changes': [{'price': '0.45', 'side': 'BUY', 'size': '928'}], 'event_type': 'price_change', 'hash': 'd9cd4c3bd3fbdc1b322a123cfe1cad78eed1393d', 'market': '0x7aa4a910b31b2c4ddb09d1e3408e52aa8e09a14402f376070a44b1b85cb36d13', 'timestamp': '1733332159190'}
{'asset_id': '114416409796971863099144323163249651172534872992222856507897414949637892047507', 'changes': [{'price': '0.45', 'side': 'BUY', 'size': '928'}], 'event_type': 'price_change', 'hash': 'd9cd4c3bd3fbdc1b322a123cfe1cad78eed1393d', 'market': '0x7aa4a910b31b2c4ddb09d1e3408e52aa8e09a14402f376070a44b1b85cb36d13', 'timestamp': '1733332159190'}
{'asset_id': '114416409796971863099144323163249651172534872992222856507897414949637892047507', 'changes': [{'price': '0.55', 'side': 'SELL', 'size': '3634.38'}], 'event_type': 'price_change', 'hash': '328cd50c9227f0f1ba07a4c6869f13354ed19079', 'market': '0x7aa4a910b31b2c4ddb09d1e3408e52aa8e09a14402f376070a44b1b85cb36d13', 'timestamp': '1733332159563'}
{'asset_id': '114416409796971863099144323163249651172534872992222856507897414949637892047507', 'changes': [{'price': '0.55', 'side': 'SELL', 'size': '3634.38'}], 'event_type': 'price_change', 'hash': '328cd50c9227f0f1ba07a4c6869f13354ed19079', 'market': '0x7aa4a910b31b2c4ddb09d1e3408e52aa8e09a14402f376070a44b1b85cb36d13', 'timestamp': '1733332159563'}
{'asset_id': '114416409796971863099144323163249651172534872992222856507897414949637892047507', 'changes': [{'price': '0.5', 'side': 'BUY', 'size': '1115'}], 'event_type': 'price_change', 'hash': 'ab36f904bd0487485857951da4d44f935a850785', 'market': '0x7aa4a910b31b2c4ddb09d1e3408e52aa8e09a14402f376070a44b1b85cb36d13', 'timestamp': '1733332159926'}
{'asset_id': '114416409796971863099144323163249651172534872992222856507897414949637892047507', 'changes': [{'price': '0.5', 'side': 'BUY', 'size': '1115'}], 'event_type': 'price_change', 'hash': 'ab36f904bd0487485857951da4d44f935a850785', 'market': '0x7aa4a910b31b2c4ddb09d1e3408e52aa8e09a14402f376070a44b1b85cb36d13', 'timestamp': '1733332159926'}
{'asset_id': '114416409796971863099144323163249651172534872992222856507897414949637892047507', 'changes': [{'price': '0.49', 'side': 'BUY', 'size': '360'}], 'event_type': 'price_change', 'hash': '9e30768ff3e072d4001b07bf7db641c8932a529d', 'market': '0x7aa4a910b31b2c4ddb09d1e3408e52aa8e09a14402f376070a44b1b85cb36d13', 'timestamp': '1733332173388'}
{'asset_id': '114416409796971863099144323163249651172534872992222856507897414949637892047507', 'changes': [{'price': '0.49', 'side': 'BUY', 'size': '360'}], 'event_type': 'price_change', 'hash': '9e30768ff3e072d4001b07bf7db641c8932a529d', 'market': '0x7aa4a910b31b2c4ddb09d1e3408e52aa8e09a14402f376070a44b1b85cb36d13', 'timestamp': '1733332173388'}
{'asset_id': '114416409796971863099144323163249651172534872992222856507897414949637892047507', 'changes': [{'price': '0.48', 'side': 'BUY', 'size': '3042.18'}], 'event_type': 'price_change', 'hash': 'a81a480353d3317ede48882f546cc78638a90801', 'market': '0x7aa4a910b31b2c4ddb09d1e3408e52aa8e09a14402f376070a44b1b85cb36d13', 'timestamp': '1733332180881'}
{'asset_id': '114416409796971863099144323163249651172534872992222856507897414949637892047507', 'changes': [{'price': '0.48', 'side': 'BUY', 'size': '3042.18'}], 'event_type': 'price_change', 'hash': 'a81a480353d3317ede48882f546cc78638a90801', 'market': '0x7aa4a910b31b2c4ddb09d1e3408e52aa8e09a14402f376070a44b1b85cb36d13', 'timestamp': '1733332180881'}
{'market': '0x7aa4a910b31b2c4ddb09d1e3408e52aa8e09a14402f376070a44b1b85cb36d13', 'asset_id': '114416409796971863099144323163249651172534872992222856507897414949637892047507', 'timestamp': '1733332384217', 'hash': '063b10090b01c8156bc0ed8c03777bbd0db5aadf', 'bids': [{'price': '0.01', 'size': '2850.27'}, {'price': '0.02', 'size': '500'}, {'price': '0.03', 'size': '500'}, {'price': '0.04', 'size': '300'}, {'price': '0.05', 'size': '320'}, {'price': '0.06', 'size': '300'}, {'price': '0.08', 'size': '250'}, {'price': '0.09', 'size': '300'}, {'price': '0.1', 'size': '205'}, {'price': '0.11', 'size': '5454'}, {'price': '0.12', 'size': '200'}, {'price': '0.13', 'size': '426.92'}, {'price': '0.14', 'size': '15'}, {'price': '0.15', 'size': '110'}, {'price': '0.16', 'size': '4709.51'}, {'price': '0.18', 'size': '19.13'}, {'price': '0.19', 'size': '120'}, {'price': '0.2', 'size': '691.17'}, {'price': '0.24', 'size': '5027'}, {'price': '0.25', 'size': '86.66'}, {'price': '0.27', 'size': '215.25'}, {'price': '0.29', 'size': '1102.28'}, {'price': '0.31', 'size': '1130.65'}, {'price': '0.32', 'size': '200'}, {'price': '0.33', 'size': '4620'}, {'price': '0.35', 'size': '232'}, {'price': '0.39', 'size': '3010.5'}, {'price': '0.4', 'size': '3135'}, {'price': '0.41', 'size': '20'}, {'price': '0.42', 'size': '50'}, {'price': '0.43', 'size': '3050'}, {'price': '0.44', 'size': '3710'}, {'price': '0.45', 'size': '428'}, {'price': '0.47', 'size': '3550'}, {'price': '0.48', 'size': '1542.18'}, {'price': '0.49', 'size': '390'}, {'price': '0.5', 'size': '115'}, {'price': '0.51', 'size': '1086.18'}, {'price': '0.52', 'size': '310.96'}, {'price': '0.53', 'size': '850'}], 'asks': [{'price': '0.99', 'size': '4217.01'}, {'price': '0.98', 'size': '505'}, {'price': '0.97', 'size': '511.03'}, {'price': '0.96', 'size': '300'}, {'price': '0.95', 'size': '657.12'}, {'price': '0.94', 'size': '300'}, {'price': '0.92', 'size': '20000.45'}, {'price': '0.91', 'size': '10406.3'}, {'price': '0.9', 'size': '4587.5'}, {'price': '0.89', 'size': '13017.18'}, {'price': '0.88', 'size': '200'}, {'price': '0.87', 'size': '3229'}, {'price': '0.86', 'size': '17.1'}, {'price': '0.85', 'size': '109.68'}, {'price': '0.84', 'size': '250'}, {'price': '0.83', 'size': '100'}, {'price': '0.82', 'size': '16029'}, {'price': '0.81', 'size': '45721.39'}, {'price': '0.8', 'size': '26531'}, {'price': '0.79', 'size': '7110'}, {'price': '0.78', 'size': '10350'}, {'price': '0.77', 'size': '67'}, {'price': '0.76', 'size': '200'}, {'price': '0.75', 'size': '18329.25'}, {'price': '0.74', 'size': '11370.7'}, {'price': '0.73', 'size': '5020.1'}, {'price': '0.72', 'size': '380.52'}, {'price': '0.71', 'size': '15073.2'}, {'price': '0.7', 'size': '5730.1'}, {'price': '0.69', 'size': '6088.6'}, {'price': '0.68', 'size': '2131.34'}, {'price': '0.67', 'size': '3010.1'}, {'price': '0.66', 'size': '510.1'}, {'price': '0.65', 'size': '5010.1'}, {'price': '0.64', 'size': '1630.1'}, {'price': '0.63', 'size': '210.1'}, {'price': '0.62', 'size': '300.1'}, {'price': '0.61', 'size': '111.06'}, {'price': '0.6', 'size': '67.85'}, {'price': '0.59', 'size': '3061.65'}, {'price': '0.58', 'size': '458.1'}, {'price': '0.57', 'size': '110.1'}, {'price': '0.56', 'size': '3610.1'}, {'price': '0.55', 'size': '4759.39'}, {'price': '0.54', 'size': '500'}], 'event_type': 'book'}
{'asset_id': '114416409796971863099144323163249651172534872992222856507897414949637892047507', 'changes': [{'price': '0.49', 'side': 'BUY', 'size': '1390'}], 'event_type': 'price_change', 'hash': '2ee2b61a29b6df286b1b5792311ea16153cd0351', 'market': '0x7aa4a910b31b2c4ddb09d1e3408e52aa8e09a14402f376070a44b1b85cb36d13', 'timestamp': '1733332384361'}
{'asset_id': '114416409796971863099144323163249651172534872992222856507897414949637892047507', 'changes': [{'price': '0.55', 'side': 'SELL', 'size': '4659.39'}], 'event_type': 'price_change', 'hash': 'b252152ea383f2c8f63c70acda221bd127d39b0b', 'market': '0x7aa4a910b31b2c4ddb09d1e3408e52aa8e09a14402f376070a44b1b85cb36d13', 'timestamp': '1733332384557'}
{'asset_id': '114416409796971863099144323163249651172534872992222856507897414949637892047507', 'changes': [{'price': '0.56', 'side': 'SELL', 'size': '3710.1'}], 'event_type': 'price_change', 'hash': '3a6d1c60ecf4bd6aa85a335bceeef679324722e7', 'market': '0x7aa4a910b31b2c4ddb09d1e3408e52aa8e09a14402f376070a44b1b85cb36d13', 'timestamp': '1733332385645'}
{'asset_id': '114416409796971863099144323163249651172534872992222856507897414949637892047507', 'changes': [{'price': '0.56', 'side': 'SELL', 'size': '3610.1'}], 'event_type': 'price_change', 'hash': '2d3e3162ad7d670605a958423a58055c2025e51e', 'market': '0x7aa4a910b31b2c4ddb09d1e3408e52aa8e09a14402f376070a44b1b85cb36d13', 'timestamp': '1733332386354'}
{'market': '0x7aa4a910b31b2c4ddb09d1e3408e52aa8e09a14402f376070a44b1b85cb36d13', 'asset_id': '114416409796971863099144323163249651172534872992222856507897414949637892047507', 'timestamp': '1733332386343', 'hash': '2d3e3162ad7d670605a958423a58055c2025e51e', 'bids': [{'price': '0.01', 'size': '2850.27'}, {'price': '0.02', 'size': '500'}, {'price': '0.03', 'size': '500'}, {'price': '0.04', 'size': '300'}, {'price': '0.05', 'size': '320'}, {'price': '0.06', 'size': '300'}, {'price': '0.08', 'size': '250'}, {'price': '0.09', 'size': '300'}, {'price': '0.1', 'size': '205'}, {'price': '0.11', 'size': '5454'}, {'price': '0.12', 'size': '200'}, {'price': '0.13', 'size': '426.92'}, {'price': '0.14', 'size': '15'}, {'price': '0.15', 'size': '110'}, {'price': '0.16', 'size': '4709.51'}, {'price': '0.18', 'size': '19.13'}, {'price': '0.19', 'size': '120'}, {'price': '0.2', 'size': '691.17'}, {'price': '0.24', 'size': '5027'}, {'price': '0.25', 'size': '86.66'}, {'price': '0.27', 'size': '215.25'}, {'price': '0.29', 'size': '1102.28'}, {'price': '0.31', 'size': '1130.65'}, {'price': '0.32', 'size': '200'}, {'price': '0.33', 'size': '4620'}, {'price': '0.35', 'size': '232'}, {'price': '0.39', 'size': '3010.5'}, {'price': '0.4', 'size': '3135'}, {'price': '0.41', 'size': '20'}, {'price': '0.42', 'size': '50'}, {'price': '0.43', 'size': '3050'}, {'price': '0.44', 'size': '3710'}, {'price': '0.45', 'size': '428'}, {'price': '0.47', 'size': '3550'}, {'price': '0.48', 'size': '1542.18'}, {'price': '0.49', 'size': '1390'}, {'price': '0.5', 'size': '115'}, {'price': '0.51', 'size': '1086.18'}, {'price': '0.52', 'size': '310.96'}, {'price': '0.53', 'size': '850'}], 'asks': [{'price': '0.99', 'size': '4217.01'}, {'price': '0.98', 'size': '505'}, {'price': '0.97', 'size': '511.03'}, {'price': '0.96', 'size': '300'}, {'price': '0.95', 'size': '657.12'}, {'price': '0.94', 'size': '300'}, {'price': '0.92', 'size': '20000.45'}, {'price': '0.91', 'size': '10406.3'}, {'price': '0.9', 'size': '4587.5'}, {'price': '0.89', 'size': '13017.18'}, {'price': '0.88', 'size': '200'}, {'price': '0.87', 'size': '3229'}, {'price': '0.86', 'size': '17.1'}, {'price': '0.85', 'size': '109.68'}, {'price': '0.84', 'size': '250'}, {'price': '0.83', 'size': '100'}, {'price': '0.82', 'size': '16029'}, {'price': '0.81', 'size': '45721.39'}, {'price': '0.8', 'size': '26531'}, {'price': '0.79', 'size': '7110'}, {'price': '0.78', 'size': '10350'}, {'price': '0.77', 'size': '67'}, {'price': '0.76', 'size': '200'}, {'price': '0.75', 'size': '18329.25'}, {'price': '0.74', 'size': '11370.7'}, {'price': '0.73', 'size': '5020.1'}, {'price': '0.72', 'size': '380.52'}, {'price': '0.71', 'size': '15073.2'}, {'price': '0.7', 'size': '5730.1'}, {'price': '0.69', 'size': '6088.6'}, {'price': '0.68', 'size': '2131.34'}, {'price': '0.67', 'size': '3010.1'}, {'price': '0.66', 'size': '510.1'}, {'price': '0.65', 'size': '5010.1'}, {'price': '0.64', 'size': '1630.1'}, {'price': '0.63', 'size': '210.1'}, {'price': '0.62', 'size': '300.1'}, {'price': '0.61', 'size': '111.06'}, {'price': '0.6', 'size': '67.85'}, {'price': '0.59', 'size': '3061.65'}, {'price': '0.58', 'size': '458.1'}, {'price': '0.57', 'size': '110.1'}, {'price': '0.56', 'size': '3610.1'}, {'price': '0.55', 'size': '4659.39'}, {'price': '0.54', 'size': '500'}], 'event_type': 'book'}
{'asset_id': '114416409796971863099144323163249651172534872992222856507897414949637892047507', 'changes': [{'price': '0.55', 'side': 'SELL', 'size': '4759.39'}], 'event_type': 'price_change', 'hash': '57aa96570a4a3db258cccb59cd71b21b0067a5c0', 'market': '0x7aa4a910b31b2c4ddb09d1e3408e52aa8e09a14402f376070a44b1b85cb36d13', 'timestamp': '1733332387204'}
{'asset_id': '114416409796971863099144323163249651172534872992222856507897414949637892047507', 'changes': [{'price': '0.55', 'side': 'SELL', 'size': '4759.39'}], 'event_type': 'price_change', 'hash': '57aa96570a4a3db258cccb59cd71b21b0067a5c0', 'market': '0x7aa4a910b31b2c4ddb09d1e3408e52aa8e09a14402f376070a44b1b85cb36d13', 'timestamp': '1733332387204'}
{'asset_id': '114416409796971863099144323163249651172534872992222856507897414949637892047507', 'changes': [{'price': '0.55', 'side': 'SELL', 'size': '4734.38'}], 'event_type': 'price_change', 'hash': '5b0db7d07d9d9668097ea2c837d9fe9c3802ab76', 'market': '0x7aa4a910b31b2c4ddb09d1e3408e52aa8e09a14402f376070a44b1b85cb36d13', 'timestamp': '1733332387618'}
{'asset_id': '114416409796971863099144323163249651172534872992222856507897414949637892047507', 'changes': [{'price': '0.55', 'side': 'SELL', 'size': '4734.38'}], 'event_type': 'price_change', 'hash': '5b0db7d07d9d9668097ea2c837d9fe9c3802ab76', 'market': '0x7aa4a910b31b2c4ddb09d1e3408e52aa8e09a14402f376070a44b1b85cb36d13', 'timestamp': '1733332387618'}
{'asset_id': '114416409796971863099144323163249651172534872992222856507897414949637892047507', 'changes': [{'price': '0.54', 'side': 'SELL', 'size': '525.01'}], 'event_type': 'price_change', 'hash': '6df47583d70dabb5e71e7e3513994a4d4db140ed', 'market': '0x7aa4a910b31b2c4ddb09d1e3408e52aa8e09a14402f376070a44b1b85cb36d13', 'timestamp': '1733332387788'}
{'asset_id': '114416409796971863099144323163249651172534872992222856507897414949637892047507', 'changes': [{'price': '0.54', 'side': 'SELL', 'size': '525.01'}], 'event_type': 'price_change', 'hash': '6df47583d70dabb5e71e7e3513994a4d4db140ed', 'market': '0x7aa4a910b31b2c4ddb09d1e3408e52aa8e09a14402f376070a44b1b85cb36d13', 'timestamp': '1733332387788'}
{'asks': [{'price': '0.99', 'size': '4217.01'}, {'price': '0.98', 'size': '505'}, {'price': '0.97', 'size': '511.03'}, {'price': '0.96', 'size': '300'}, {'price': '0.95', 'size': '657.12'}, {'price': '0.94', 'size': '300'}, {'price': '0.92', 'size': '20000.45'}, {'price': '0.91', 'size': '10406.3'}, {'price': '0.9', 'size': '4587.5'}, {'price': '0.89', 'size': '13017.18'}, {'price': '0.88', 'size': '200'}, {'price': '0.87', 'size': '3229'}, {'price': '0.86', 'size': '17.1'}, {'price': '0.85', 'size': '109.68'}, {'price': '0.84', 'size': '250'}, {'price': '0.83', 'size': '100'}, {'price': '0.82', 'size': '16029'}, {'price': '0.81', 'size': '45721.39'}, {'price': '0.8', 'size': '26531'}, {'price': '0.79', 'size': '7110'}, {'price': '0.78', 'size': '10350'}, {'price': '0.77', 'size': '67'}, {'price': '0.76', 'size': '200'}, {'price': '0.75', 'size': '18329.25'}, {'price': '0.74', 'size': '11370.7'}, {'price': '0.73', 'size': '5020.1'}, {'price': '0.72', 'size': '380.52'}, {'price': '0.71', 'size': '15073.2'}, {'price': '0.7', 'size': '5730.1'}, {'price': '0.69', 'size': '6088.6'}, {'price': '0.68', 'size': '2131.34'}, {'price': '0.67', 'size': '3010.1'}, {'price': '0.66', 'size': '510.1'}, {'price': '0.65', 'size': '5010.1'}, {'price': '0.64', 'size': '1630.1'}, {'price': '0.63', 'size': '210.1'}, {'price': '0.62', 'size': '300.1'}, {'price': '0.61', 'size': '111.06'}, {'price': '0.6', 'size': '67.85'}, {'price': '0.59', 'size': '3061.65'}, {'price': '0.58', 'size': '458.1'}, {'price': '0.57', 'size': '110.1'}, {'price': '0.56', 'size': '3610.1'}, {'price': '0.55', 'size': '4734.38'}, {'price': '0.54', 'size': '525.01'}], 'asset_id': '114416409796971863099144323163249651172534872992222856507897414949637892047507', 'bids': [{'price': '0.01', 'size': '2850.27'}, {'price': '0.02', 'size': '500'}, {'price': '0.03', 'size': '500'}, {'price': '0.04', 'size': '300'}, {'price': '0.05', 'size': '320'}, {'price': '0.06', 'size': '300'}, {'price': '0.08', 'size': '250'}, {'price': '0.09', 'size': '300'}, {'price': '0.1', 'size': '205'}, {'price': '0.11', 'size': '5454'}, {'price': '0.12', 'size': '200'}, {'price': '0.13', 'size': '426.92'}, {'price': '0.14', 'size': '15'}, {'price': '0.15', 'size': '110'}, {'price': '0.16', 'size': '4709.51'}, {'price': '0.18', 'size': '19.13'}, {'price': '0.19', 'size': '120'}, {'price': '0.2', 'size': '691.17'}, {'price': '0.24', 'size': '5027'}, {'price': '0.25', 'size': '86.66'}, {'price': '0.27', 'size': '215.25'}, {'price': '0.29', 'size': '1102.28'}, {'price': '0.31', 'size': '1130.65'}, {'price': '0.32', 'size': '200'}, {'price': '0.33', 'size': '4620'}, {'price': '0.35', 'size': '232'}, {'price': '0.39', 'size': '3010.5'}, {'price': '0.4', 'size': '3135'}, {'price': '0.41', 'size': '20'}, {'price': '0.42', 'size': '50'}, {'price': '0.43', 'size': '3050'}, {'price': '0.44', 'size': '3710'}, {'price': '0.45', 'size': '428'}, {'price': '0.47', 'size': '3550'}, {'price': '0.48', 'size': '1542.18'}, {'price': '0.49', 'size': '1390'}, {'price': '0.5', 'size': '115'}, {'price': '0.51', 'size': '1086.18'}, {'price': '0.52', 'size': '310.96'}], 'event_type': 'book', 'hash': '7ac6ba0f3c0d5c9dded28ae95f31467ef4892b82', 'market': '0x7aa4a910b31b2c4ddb09d1e3408e52aa8e09a14402f376070a44b1b85cb36d13', 'timestamp': '1733332390681'}
{'asks': [{'price': '0.99', 'size': '4217.01'}, {'price': '0.98', 'size': '505'}, {'price': '0.97', 'size': '511.03'}, {'price': '0.96', 'size': '300'}, {'price': '0.95', 'size': '657.12'}, {'price': '0.94', 'size': '300'}, {'price': '0.92', 'size': '20000.45'}, {'price': '0.91', 'size': '10406.3'}, {'price': '0.9', 'size': '4587.5'}, {'price': '0.89', 'size': '13017.18'}, {'price': '0.88', 'size': '200'}, {'price': '0.87', 'size': '3229'}, {'price': '0.86', 'size': '17.1'}, {'price': '0.85', 'size': '109.68'}, {'price': '0.84', 'size': '250'}, {'price': '0.83', 'size': '100'}, {'price': '0.82', 'size': '16029'}, {'price': '0.81', 'size': '45721.39'}, {'price': '0.8', 'size': '26531'}, {'price': '0.79', 'size': '7110'}, {'price': '0.78', 'size': '10350'}, {'price': '0.77', 'size': '67'}, {'price': '0.76', 'size': '200'}, {'price': '0.75', 'size': '18329.25'}, {'price': '0.74', 'size': '11370.7'}, {'price': '0.73', 'size': '5020.1'}, {'price': '0.72', 'size': '380.52'}, {'price': '0.71', 'size': '15073.2'}, {'price': '0.7', 'size': '5730.1'}, {'price': '0.69', 'size': '6088.6'}, {'price': '0.68', 'size': '2131.34'}, {'price': '0.67', 'size': '3010.1'}, {'price': '0.66', 'size': '510.1'}, {'price': '0.65', 'size': '5010.1'}, {'price': '0.64', 'size': '1630.1'}, {'price': '0.63', 'size': '210.1'}, {'price': '0.62', 'size': '300.1'}, {'price': '0.61', 'size': '111.06'}, {'price': '0.6', 'size': '67.85'}, {'price': '0.59', 'size': '3061.65'}, {'price': '0.58', 'size': '458.1'}, {'price': '0.57', 'size': '110.1'}, {'price': '0.56', 'size': '3610.1'}, {'price': '0.55', 'size': '4734.38'}, {'price': '0.54', 'size': '525.01'}], 'asset_id': '114416409796971863099144323163249651172534872992222856507897414949637892047507', 'bids': [{'price': '0.01', 'size': '2850.27'}, {'price': '0.02', 'size': '500'}, {'price': '0.03', 'size': '500'}, {'price': '0.04', 'size': '300'}, {'price': '0.05', 'size': '320'}, {'price': '0.06', 'size': '300'}, {'price': '0.08', 'size': '250'}, {'price': '0.09', 'size': '300'}, {'price': '0.1', 'size': '205'}, {'price': '0.11', 'size': '5454'}, {'price': '0.12', 'size': '200'}, {'price': '0.13', 'size': '426.92'}, {'price': '0.14', 'size': '15'}, {'price': '0.15', 'size': '110'}, {'price': '0.16', 'size': '4709.51'}, {'price': '0.18', 'size': '19.13'}, {'price': '0.19', 'size': '120'}, {'price': '0.2', 'size': '691.17'}, {'price': '0.24', 'size': '5027'}, {'price': '0.25', 'size': '86.66'}, {'price': '0.27', 'size': '215.25'}, {'price': '0.29', 'size': '1102.28'}, {'price': '0.31', 'size': '1130.65'}, {'price': '0.32', 'size': '200'}, {'price': '0.33', 'size': '4620'}, {'price': '0.35', 'size': '232'}, {'price': '0.39', 'size': '3010.5'}, {'price': '0.4', 'size': '3135'}, {'price': '0.41', 'size': '20'}, {'price': '0.42', 'size': '50'}, {'price': '0.43', 'size': '3050'}, {'price': '0.44', 'size': '3710'}, {'price': '0.45', 'size': '428'}, {'price': '0.47', 'size': '3550'}, {'price': '0.48', 'size': '1542.18'}, {'price': '0.49', 'size': '1390'}, {'price': '0.5', 'size': '115'}, {'price': '0.51', 'size': '1086.18'}, {'price': '0.52', 'size': '310.96'}], 'event_type': 'book', 'hash': '7ac6ba0f3c0d5c9dded28ae95f31467ef4892b82', 'market': '0x7aa4a910b31b2c4ddb09d1e3408e52aa8e09a14402f376070a44b1b85cb36d13', 'timestamp': '1733332390681'}
{'asset_id': '114416409796971863099144323163249651172534872992222856507897414949637892047507', 'changes': [{'price': '0.47', 'side': 'BUY', 'size': '1550'}], 'event_type': 'price_change', 'hash': '2d7c7efbc6ac91eaa8765f417bad4a750983f55d', 'market': '0x7aa4a910b31b2c4ddb09d1e3408e52aa8e09a14402f376070a44b1b85cb36d13', 'timestamp': '1733332392011'}
{'asset_id': '114416409796971863099144323163249651172534872992222856507897414949637892047507', 'changes': [{'price': '0.47', 'side': 'BUY', 'size': '1550'}], 'event_type': 'price_change', 'hash': '2d7c7efbc6ac91eaa8765f417bad4a750983f55d', 'market': '0x7aa4a910b31b2c4ddb09d1e3408e52aa8e09a14402f376070a44b1b85cb36d13', 'timestamp': '1733332392011'}
{'asset_id': '114416409796971863099144323163249651172534872992222856507897414949637892047507', 'changes': [{'price': '0.45', 'side': 'BUY', 'size': '2428'}], 'event_type': 'price_change', 'hash': 'e4cbdb6825e013783ee909379e665c7d66be38dc', 'market': '0x7aa4a910b31b2c4ddb09d1e3408e52aa8e09a14402f376070a44b1b85cb36d13', 'timestamp': '1733332396546'}
{'asset_id': '114416409796971863099144323163249651172534872992222856507897414949637892047507', 'changes': [{'price': '0.45', 'side': 'BUY', 'size': '2428'}], 'event_type': 'price_change', 'hash': 'e4cbdb6825e013783ee909379e665c7d66be38dc', 'market': '0x7aa4a910b31b2c4ddb09d1e3408e52aa8e09a14402f376070a44b1b85cb36d13', 'timestamp': '1733332396546'}
{'asset_id': '114416409796971863099144323163249651172534872992222856507897414949637892047507', 'changes': [{'price': '0.43', 'side': 'BUY', 'size': '2550'}, {'price': '0.49', 'side': 'BUY', 'size': '390'}, {'price': '0.54', 'side': 'SELL', 'size': '25.01'}], 'event_type': 'price_change', 'hash': '5dadd0498f3231461a1b660ce572eac5344ecbb9', 'market': '0x7aa4a910b31b2c4ddb09d1e3408e52aa8e09a14402f376070a44b1b85cb36d13', 'timestamp': '1733332398805'}
{'asset_id': '114416409796971863099144323163249651172534872992222856507897414949637892047507', 'changes': [{'price': '0.43', 'side': 'BUY', 'size': '2550'}, {'price': '0.49', 'side': 'BUY', 'size': '390'}, {'price': '0.54', 'side': 'SELL', 'size': '25.01'}], 'event_type': 'price_change', 'hash': '5dadd0498f3231461a1b660ce572eac5344ecbb9', 'market': '0x7aa4a910b31b2c4ddb09d1e3408e52aa8e09a14402f376070a44b1b85cb36d13', 'timestamp': '1733332398805'}
{'asset_id': '114416409796971863099144323163249651172534872992222856507897414949637892047507', 'changes': [{'price': '0.55', 'side': 'SELL', 'size': '4834.38'}], 'event_type': 'price_change', 'hash': 'b746708d2239579cbcdfaa86dd57cb6313f017e7', 'market': '0x7aa4a910b31b2c4ddb09d1e3408e52aa8e09a14402f376070a44b1b85cb36d13', 'timestamp': '1733332399629'}
{'asset_id': '114416409796971863099144323163249651172534872992222856507897414949637892047507', 'changes': [{'price': '0.55', 'side': 'SELL', 'size': '4834.38'}], 'event_type': 'price_change', 'hash': 'b746708d2239579cbcdfaa86dd57cb6313f017e7', 'market': '0x7aa4a910b31b2c4ddb09d1e3408e52aa8e09a14402f376070a44b1b85cb36d13', 'timestamp': '1733332399629'}
{'asset_id': '114416409796971863099144323163249651172534872992222856507897414949637892047507', 'changes': [{'price': '0.44', 'side': 'BUY', 'size': '4210'}], 'event_type': 'price_change', 'hash': '8a9dee6152f7672b3d94e0f2891ded6ceaa6a32a', 'market': '0x7aa4a910b31b2c4ddb09d1e3408e52aa8e09a14402f376070a44b1b85cb36d13', 'timestamp': '1733332399816'}
{'asset_id': '114416409796971863099144323163249651172534872992222856507897414949637892047507', 'changes': [{'price': '0.44', 'side': 'BUY', 'size': '4210'}], 'event_type': 'price_change', 'hash': '8a9dee6152f7672b3d94e0f2891ded6ceaa6a32a', 'market': '0x7aa4a910b31b2c4ddb09d1e3408e52aa8e09a14402f376070a44b1b85cb36d13', 'timestamp': '1733332399816'}
{'asset_id': '114416409796971863099144323163249651172534872992222856507897414949637892047507', 'changes': [{'price': '0.54', 'side': 'SELL', 'size': '525.01'}], 'event_type': 'price_change', 'hash': '3f554dc944ae9a879004ba67c0d00d55754030ee', 'market': '0x7aa4a910b31b2c4ddb09d1e3408e52aa8e09a14402f376070a44b1b85cb36d13', 'timestamp': '1733332400184'}
{'asset_id': '114416409796971863099144323163249651172534872992222856507897414949637892047507', 'changes': [{'price': '0.54', 'side': 'SELL', 'size': '525.01'}], 'event_type': 'price_change', 'hash': '3f554dc944ae9a879004ba67c0d00d55754030ee', 'market': '0x7aa4a910b31b2c4ddb09d1e3408e52aa8e09a14402f376070a44b1b85cb36d13', 'timestamp': '1733332400184'}
{'asset_id': '114416409796971863099144323163249651172534872992222856507897414949637892047507', 'changes': [{'price': '0.49', 'side': 'BUY', 'size': '1390'}], 'event_type': 'price_change', 'hash': 'd62da7fe3bcfe71484773c819bc965bf7cf8b3fe', 'market': '0x7aa4a910b31b2c4ddb09d1e3408e52aa8e09a14402f376070a44b1b85cb36d13', 'timestamp': '1733332400559'}
{'asset_id': '114416409796971863099144323163249651172534872992222856507897414949637892047507', 'changes': [{'price': '0.49', 'side': 'BUY', 'size': '1390'}], 'event_type': 'price_change', 'hash': 'd62da7fe3bcfe71484773c819bc965bf7cf8b3fe', 'market': '0x7aa4a910b31b2c4ddb09d1e3408e52aa8e09a14402f376070a44b1b85cb36d13', 'timestamp': '1733332400559'}
{'asset_id': '114416409796971863099144323163249651172534872992222856507897414949637892047507', 'changes': [{'price': '0.55', 'side': 'SELL', 'size': '4734.38'}], 'event_type': 'price_change', 'hash': 'c1a10c2f92be6b518c1e2aa030079ccd98cf834f', 'market': '0x7aa4a910b31b2c4ddb09d1e3408e52aa8e09a14402f376070a44b1b85cb36d13', 'timestamp': '1733332402950'}
{'asset_id': '114416409796971863099144323163249651172534872992222856507897414949637892047507', 'changes': [{'price': '0.55', 'side': 'SELL', 'size': '4734.38'}], 'event_type': 'price_change', 'hash': 'c1a10c2f92be6b518c1e2aa030079ccd98cf834f', 'market': '0x7aa4a910b31b2c4ddb09d1e3408e52aa8e09a14402f376070a44b1b85cb36d13', 'timestamp': '1733332402950'}
{'asset_id': '114416409796971863099144323163249651172534872992222856507897414949637892047507', 'changes': [{'price': '0.54', 'side': 'SELL', 'size': '625.01'}], 'event_type': 'price_change', 'hash': '9629222023b439346a7d9a89f0cbab815e6459ad', 'market': '0x7aa4a910b31b2c4ddb09d1e3408e52aa8e09a14402f376070a44b1b85cb36d13', 'timestamp': '1733332403182'}
{'asset_id': '114416409796971863099144323163249651172534872992222856507897414949637892047507', 'changes': [{'price': '0.54', 'side': 'SELL', 'size': '625.01'}], 'event_type': 'price_change', 'hash': '9629222023b439346a7d9a89f0cbab815e6459ad', 'market': '0x7aa4a910b31b2c4ddb09d1e3408e52aa8e09a14402f376070a44b1b85cb36d13', 'timestamp': '1733332403182'}
{'asset_id': '114416409796971863099144323163249651172534872992222856507897414949637892047507', 'changes': [{'price': '0.45', 'side': 'BUY', 'size': '428'}], 'event_type': 'price_change', 'hash': '847f5f1292f8ec74bb18d8ad4a18a2957a929026', 'market': '0x7aa4a910b31b2c4ddb09d1e3408e52aa8e09a14402f376070a44b1b85cb36d13', 'timestamp': '1733332403342'}
{'asset_id': '114416409796971863099144323163249651172534872992222856507897414949637892047507', 'changes': [{'price': '0.45', 'side': 'BUY', 'size': '428'}], 'event_type': 'price_change', 'hash': '847f5f1292f8ec74bb18d8ad4a18a2957a929026', 'market': '0x7aa4a910b31b2c4ddb09d1e3408e52aa8e09a14402f376070a44b1b85cb36d13', 'timestamp': '1733332403342'}
{'asset_id': '114416409796971863099144323163249651172534872992222856507897414949637892047507', 'changes': [{'price': '0.46', 'side': 'BUY', 'size': '2000'}], 'event_type': 'price_change', 'hash': 'dd288fa5919369a5898c3168953fa724da5ec80a', 'market': '0x7aa4a910b31b2c4ddb09d1e3408e52aa8e09a14402f376070a44b1b85cb36d13', 'timestamp': '1733332404239'}
{'asset_id': '114416409796971863099144323163249651172534872992222856507897414949637892047507', 'changes': [{'price': '0.46', 'side': 'BUY', 'size': '2000'}], 'event_type': 'price_change', 'hash': 'dd288fa5919369a5898c3168953fa724da5ec80a', 'market': '0x7aa4a910b31b2c4ddb09d1e3408e52aa8e09a14402f376070a44b1b85cb36d13', 'timestamp': '1733332404239'}
{'asset_id': '114416409796971863099144323163249651172534872992222856507897414949637892047507', 'changes': [{'price': '0.44', 'side': 'BUY', 'size': '3710'}, {'price': '0.54', 'side': 'SELL', 'size': '125.01'}, {'price': '0.49', 'side': 'BUY', 'size': '390'}], 'event_type': 'price_change', 'hash': 'fd7b34b5417b28b6ad30fc448d0af9fe0708b07f', 'market': '0x7aa4a910b31b2c4ddb09d1e3408e52aa8e09a14402f376070a44b1b85cb36d13', 'timestamp': '1733332406829'}
{'asset_id': '114416409796971863099144323163249651172534872992222856507897414949637892047507', 'changes': [{'price': '0.44', 'side': 'BUY', 'size': '3710'}, {'price': '0.54', 'side': 'SELL', 'size': '125.01'}, {'price': '0.49', 'side': 'BUY', 'size': '390'}], 'event_type': 'price_change', 'hash': 'fd7b34b5417b28b6ad30fc448d0af9fe0708b07f', 'market': '0x7aa4a910b31b2c4ddb09d1e3408e52aa8e09a14402f376070a44b1b85cb36d13', 'timestamp': '1733332406829'}
{'asset_id': '114416409796971863099144323163249651172534872992222856507897414949637892047507', 'changes': [{'price': '0.45', 'side': 'BUY', 'size': '928'}], 'event_type': 'price_change', 'hash': '6d9c6ffb5ac520283d003d43e7fbc903bbd4d0f2', 'market': '0x7aa4a910b31b2c4ddb09d1e3408e52aa8e09a14402f376070a44b1b85cb36d13', 'timestamp': '1733332407867'}
{'asset_id': '114416409796971863099144323163249651172534872992222856507897414949637892047507', 'changes': [{'price': '0.45', 'side': 'BUY', 'size': '928'}], 'event_type': 'price_change', 'hash': '6d9c6ffb5ac520283d003d43e7fbc903bbd4d0f2', 'market': '0x7aa4a910b31b2c4ddb09d1e3408e52aa8e09a14402f376070a44b1b85cb36d13', 'timestamp': '1733332407867'}
{'asset_id': '114416409796971863099144323163249651172534872992222856507897414949637892047507', 'changes': [{'price': '0.54', 'side': 'SELL', 'size': '100'}, {'price': '0.55', 'side': 'SELL', 'size': '5234.38'}], 'event_type': 'price_change', 'hash': '32d65d0869d419b74f6e709a17caf0f0cec41bf0', 'market': '0x7aa4a910b31b2c4ddb09d1e3408e52aa8e09a14402f376070a44b1b85cb36d13', 'timestamp': '1733332408236'}
{'asset_id': '114416409796971863099144323163249651172534872992222856507897414949637892047507', 'changes': [{'price': '0.54', 'side': 'SELL', 'size': '100'}, {'price': '0.55', 'side': 'SELL', 'size': '5234.38'}], 'event_type': 'price_change', 'hash': '32d65d0869d419b74f6e709a17caf0f0cec41bf0', 'market': '0x7aa4a910b31b2c4ddb09d1e3408e52aa8e09a14402f376070a44b1b85cb36d13', 'timestamp': '1733332408236'}
{'asset_id': '114416409796971863099144323163249651172534872992222856507897414949637892047507', 'changes': [{'price': '0.58', 'side': 'SELL', 'size': '188.1'}, {'price': '0.49', 'side': 'BUY', 'size': '140'}, {'price': '0.55', 'side': 'SELL', 'size': '5259.39'}], 'event_type': 'price_change', 'hash': '7f60ee1103e05676361532fb438dab8e833cf96e', 'market': '0x7aa4a910b31b2c4ddb09d1e3408e52aa8e09a14402f376070a44b1b85cb36d13', 'timestamp': '1733332408408'}
{'asset_id': '114416409796971863099144323163249651172534872992222856507897414949637892047507', 'changes': [{'price': '0.58', 'side': 'SELL', 'size': '188.1'}, {'price': '0.49', 'side': 'BUY', 'size': '140'}, {'price': '0.55', 'side': 'SELL', 'size': '5259.39'}], 'event_type': 'price_change', 'hash': '7f60ee1103e05676361532fb438dab8e833cf96e', 'market': '0x7aa4a910b31b2c4ddb09d1e3408e52aa8e09a14402f376070a44b1b85cb36d13', 'timestamp': '1733332408408'}
{'asset_id': '114416409796971863099144323163249651172534872992222856507897414949637892047507', 'changes': [{'price': '0.49', 'side': 'BUY', 'size': '360'}, {'price': '0.5', 'side': 'BUY', 'size': '1115'}], 'event_type': 'price_change', 'hash': '9d57233664419420bb66b705d4824aba44c8c638', 'market': '0x7aa4a910b31b2c4ddb09d1e3408e52aa8e09a14402f376070a44b1b85cb36d13', 'timestamp': '1733332408599'}
{'asset_id': '114416409796971863099144323163249651172534872992222856507897414949637892047507', 'changes': [{'price': '0.49', 'side': 'BUY', 'size': '360'}, {'price': '0.5', 'side': 'BUY', 'size': '1115'}], 'event_type': 'price_change', 'hash': '9d57233664419420bb66b705d4824aba44c8c638', 'market': '0x7aa4a910b31b2c4ddb09d1e3408e52aa8e09a14402f376070a44b1b85cb36d13', 'timestamp': '1733332408599'}
{'asset_id': '114416409796971863099144323163249651172534872992222856507897414949637892047507', 'changes': [{'price': '0.57', 'side': 'SELL', 'size': '350.1'}], 'event_type': 'price_change', 'hash': 'b3e9f3461255ee2b6786b509e781c20dd71f18e6', 'market': '0x7aa4a910b31b2c4ddb09d1e3408e52aa8e09a14402f376070a44b1b85cb36d13', 'timestamp': '1733332408617'}
{'asset_id': '114416409796971863099144323163249651172534872992222856507897414949637892047507', 'changes': [{'price': '0.57', 'side': 'SELL', 'size': '350.1'}], 'event_type': 'price_change', 'hash': 'b3e9f3461255ee2b6786b509e781c20dd71f18e6', 'market': '0x7aa4a910b31b2c4ddb09d1e3408e52aa8e09a14402f376070a44b1b85cb36d13', 'timestamp': '1733332408617'}
{'asset_id': '114416409796971863099144323163249651172534872992222856507897414949637892047507', 'changes': [{'price': '0.54', 'side': 'SELL', 'size': '0'}], 'event_type': 'price_change', 'hash': 'aaaae5989f22e03af95205608dc4d3b65eb8565e', 'market': '0x7aa4a910b31b2c4ddb09d1e3408e52aa8e09a14402f376070a44b1b85cb36d13', 'timestamp': '1733332410329'}
{'asset_id': '114416409796971863099144323163249651172534872992222856507897414949637892047507', 'changes': [{'price': '0.54', 'side': 'SELL', 'size': '0'}], 'event_type': 'price_change', 'hash': 'aaaae5989f22e03af95205608dc4d3b65eb8565e', 'market': '0x7aa4a910b31b2c4ddb09d1e3408e52aa8e09a14402f376070a44b1b85cb36d13', 'timestamp': '1733332410329'}
{'asset_id': '114416409796971863099144323163249651172534872992222856507897414949637892047507', 'changes': [{'price': '0.55', 'side': 'SELL', 'size': '5359.39'}], 'event_type': 'price_change', 'hash': 'be22fee6b76254b962410fd32a5bdb72b0713c4f', 'market': '0x7aa4a910b31b2c4ddb09d1e3408e52aa8e09a14402f376070a44b1b85cb36d13', 'timestamp': '1733332410531'}
{'asset_id': '114416409796971863099144323163249651172534872992222856507897414949637892047507', 'changes': [{'price': '0.55', 'side': 'SELL', 'size': '5359.39'}], 'event_type': 'price_change', 'hash': 'be22fee6b76254b962410fd32a5bdb72b0713c4f', 'market': '0x7aa4a910b31b2c4ddb09d1e3408e52aa8e09a14402f376070a44b1b85cb36d13', 'timestamp': '1733332410531'}
{'asset_id': '114416409796971863099144323163249651172534872992222856507897414949637892047507', 'changes': [{'price': '0.55', 'side': 'SELL', 'size': '5259.39'}], 'event_type': 'price_change', 'hash': '4193b36f07603a87b4c736abd7965179e2d04a64', 'market': '0x7aa4a910b31b2c4ddb09d1e3408e52aa8e09a14402f376070a44b1b85cb36d13', 'timestamp': '1733332411305'}
{'asset_id': '114416409796971863099144323163249651172534872992222856507897414949637892047507', 'changes': [{'price': '0.55', 'side': 'SELL', 'size': '5259.39'}], 'event_type': 'price_change', 'hash': '4193b36f07603a87b4c736abd7965179e2d04a64', 'market': '0x7aa4a910b31b2c4ddb09d1e3408e52aa8e09a14402f376070a44b1b85cb36d13', 'timestamp': '1733332411305'}
{'asset_id': '114416409796971863099144323163249651172534872992222856507897414949637892047507', 'changes': [{'price': '0.56', 'side': 'SELL', 'size': '3710.1'}], 'event_type': 'price_change', 'hash': 'e5d7a2f18facb71e9e295e51bdda6f19231c921d', 'market': '0x7aa4a910b31b2c4ddb09d1e3408e52aa8e09a14402f376070a44b1b85cb36d13', 'timestamp': '1733332411949'}
{'asset_id': '114416409796971863099144323163249651172534872992222856507897414949637892047507', 'changes': [{'price': '0.56', 'side': 'SELL', 'size': '3710.1'}], 'event_type': 'price_change', 'hash': 'e5d7a2f18facb71e9e295e51bdda6f19231c921d', 'market': '0x7aa4a910b31b2c4ddb09d1e3408e52aa8e09a14402f376070a44b1b85cb36d13', 'timestamp': '1733332411949'}
{'asset_id': '114416409796971863099144323163249651172534872992222856507897414949637892047507', 'changes': [{'price': '0.43', 'side': 'BUY', 'size': '50'}, {'price': '0.48', 'side': 'BUY', 'size': '342.18'}, {'price': '0.47', 'side': 'BUY', 'size': '50'}], 'event_type': 'price_change', 'hash': 'dabb75ecab2726313d1498a35e3260f9e6dd8520', 'market': '0x7aa4a910b31b2c4ddb09d1e3408e52aa8e09a14402f376070a44b1b85cb36d13', 'timestamp': '1733332412367'}
{'asset_id': '114416409796971863099144323163249651172534872992222856507897414949637892047507', 'changes': [{'price': '0.43', 'side': 'BUY', 'size': '50'}, {'price': '0.48', 'side': 'BUY', 'size': '342.18'}, {'price': '0.47', 'side': 'BUY', 'size': '50'}], 'event_type': 'price_change', 'hash': 'dabb75ecab2726313d1498a35e3260f9e6dd8520', 'market': '0x7aa4a910b31b2c4ddb09d1e3408e52aa8e09a14402f376070a44b1b85cb36d13', 'timestamp': '1733332412367'}
{'asset_id': '114416409796971863099144323163249651172534872992222856507897414949637892047507', 'changes': [{'price': '0.48', 'side': 'BUY', 'size': '1842.18'}, {'price': '0.45', 'side': 'BUY', 'size': '3428'}], 'event_type': 'price_change', 'hash': '16949fd668eddc909e286b278320816eaa387c71', 'market': '0x7aa4a910b31b2c4ddb09d1e3408e52aa8e09a14402f376070a44b1b85cb36d13', 'timestamp': '1733332412770'}
{'asset_id': '114416409796971863099144323163249651172534872992222856507897414949637892047507', 'changes': [{'price': '0.48', 'side': 'BUY', 'size': '1842.18'}, {'price': '0.45', 'side': 'BUY', 'size': '3428'}], 'event_type': 'price_change', 'hash': '16949fd668eddc909e286b278320816eaa387c71', 'market': '0x7aa4a910b31b2c4ddb09d1e3408e52aa8e09a14402f376070a44b1b85cb36d13', 'timestamp': '1733332412770'}
{'asset_id': '114416409796971863099144323163249651172534872992222856507897414949637892047507', 'changes': [{'price': '0.5', 'side': 'BUY', 'size': '1515'}], 'event_type': 'price_change', 'hash': '7f376cbf4a814ba68fc17842544a9d1d7fc75210', 'market': '0x7aa4a910b31b2c4ddb09d1e3408e52aa8e09a14402f376070a44b1b85cb36d13', 'timestamp': '1733332417206'}
{'asset_id': '114416409796971863099144323163249651172534872992222856507897414949637892047507', 'changes': [{'price': '0.5', 'side': 'BUY', 'size': '1515'}], 'event_type': 'price_change', 'hash': '7f376cbf4a814ba68fc17842544a9d1d7fc75210', 'market': '0x7aa4a910b31b2c4ddb09d1e3408e52aa8e09a14402f376070a44b1b85cb36d13', 'timestamp': '1733332417206'}
{'asks': [{'price': '0.99', 'size': '4217.01'}, {'price': '0.98', 'size': '505'}, {'price': '0.97', 'size': '511.03'}, {'price': '0.96', 'size': '300'}, {'price': '0.95', 'size': '657.12'}, {'price': '0.94', 'size': '300'}, {'price': '0.92', 'size': '20000.45'}, {'price': '0.91', 'size': '10406.3'}, {'price': '0.9', 'size': '4587.5'}, {'price': '0.89', 'size': '13017.18'}, {'price': '0.88', 'size': '200'}, {'price': '0.87', 'size': '3229'}, {'price': '0.86', 'size': '17.1'}, {'price': '0.85', 'size': '109.68'}, {'price': '0.84', 'size': '250'}, {'price': '0.83', 'size': '100'}, {'price': '0.82', 'size': '16029'}, {'price': '0.81', 'size': '45721.39'}, {'price': '0.8', 'size': '26531'}, {'price': '0.79', 'size': '7110'}, {'price': '0.78', 'size': '10350'}, {'price': '0.77', 'size': '67'}, {'price': '0.76', 'size': '200'}, {'price': '0.75', 'size': '18329.25'}, {'price': '0.74', 'size': '11370.7'}, {'price': '0.73', 'size': '5020.1'}, {'price': '0.72', 'size': '380.52'}, {'price': '0.71', 'size': '15073.2'}, {'price': '0.7', 'size': '5730.1'}, {'price': '0.69', 'size': '6088.6'}, {'price': '0.68', 'size': '2131.34'}, {'price': '0.67', 'size': '3010.1'}, {'price': '0.66', 'size': '510.1'}, {'price': '0.65', 'size': '5010.1'}, {'price': '0.64', 'size': '1630.1'}, {'price': '0.63', 'size': '210.1'}, {'price': '0.62', 'size': '300.1'}, {'price': '0.61', 'size': '111.06'}, {'price': '0.6', 'size': '67.85'}, {'price': '0.59', 'size': '3061.65'}, {'price': '0.58', 'size': '188.1'}, {'price': '0.57', 'size': '350.1'}, {'price': '0.56', 'size': '3710.1'}, {'price': '0.55', 'size': '5199.4'}], 'asset_id': '114416409796971863099144323163249651172534872992222856507897414949637892047507', 'bids': [{'price': '0.01', 'size': '2850.27'}, {'price': '0.02', 'size': '500'}, {'price': '0.03', 'size': '500'}, {'price': '0.04', 'size': '300'}, {'price': '0.05', 'size': '320'}, {'price': '0.06', 'size': '300'}, {'price': '0.08', 'size': '250'}, {'price': '0.09', 'size': '300'}, {'price': '0.1', 'size': '205'}, {'price': '0.11', 'size': '5454'}, {'price': '0.12', 'size': '200'}, {'price': '0.13', 'size': '426.92'}, {'price': '0.14', 'size': '15'}, {'price': '0.15', 'size': '110'}, {'price': '0.16', 'size': '4709.51'}, {'price': '0.18', 'size': '19.13'}, {'price': '0.19', 'size': '120'}, {'price': '0.2', 'size': '691.17'}, {'price': '0.24', 'size': '5027'}, {'price': '0.25', 'size': '86.66'}, {'price': '0.27', 'size': '215.25'}, {'price': '0.29', 'size': '1102.28'}, {'price': '0.31', 'size': '1130.65'}, {'price': '0.32', 'size': '200'}, {'price': '0.33', 'size': '4620'}, {'price': '0.35', 'size': '232'}, {'price': '0.39', 'size': '3010.5'}, {'price': '0.4', 'size': '3135'}, {'price': '0.41', 'size': '20'}, {'price': '0.42', 'size': '50'}, {'price': '0.43', 'size': '50'}, {'price': '0.44', 'size': '3710'}, {'price': '0.45', 'size': '3428'}, {'price': '0.46', 'size': '2000'}, {'price': '0.47', 'size': '50'}, {'price': '0.48', 'size': '1842.18'}, {'price': '0.49', 'size': '360'}, {'price': '0.5', 'size': '1515'}, {'price': '0.51', 'size': '1086.18'}, {'price': '0.52', 'size': '310.96'}], 'event_type': 'book', 'hash': '98484f621c88eb1adbee32342bac1e9d7d902efc', 'market': '0x7aa4a910b31b2c4ddb09d1e3408e52aa8e09a14402f376070a44b1b85cb36d13', 'timestamp': '1733332422546'}
{'asks': [{'price': '0.99', 'size': '4217.01'}, {'price': '0.98', 'size': '505'}, {'price': '0.97', 'size': '511.03'}, {'price': '0.96', 'size': '300'}, {'price': '0.95', 'size': '657.12'}, {'price': '0.94', 'size': '300'}, {'price': '0.92', 'size': '20000.45'}, {'price': '0.91', 'size': '10406.3'}, {'price': '0.9', 'size': '4587.5'}, {'price': '0.89', 'size': '13017.18'}, {'price': '0.88', 'size': '200'}, {'price': '0.87', 'size': '3229'}, {'price': '0.86', 'size': '17.1'}, {'price': '0.85', 'size': '109.68'}, {'price': '0.84', 'size': '250'}, {'price': '0.83', 'size': '100'}, {'price': '0.82', 'size': '16029'}, {'price': '0.81', 'size': '45721.39'}, {'price': '0.8', 'size': '26531'}, {'price': '0.79', 'size': '7110'}, {'price': '0.78', 'size': '10350'}, {'price': '0.77', 'size': '67'}, {'price': '0.76', 'size': '200'}, {'price': '0.75', 'size': '18329.25'}, {'price': '0.74', 'size': '11370.7'}, {'price': '0.73', 'size': '5020.1'}, {'price': '0.72', 'size': '380.52'}, {'price': '0.71', 'size': '15073.2'}, {'price': '0.7', 'size': '5730.1'}, {'price': '0.69', 'size': '6088.6'}, {'price': '0.68', 'size': '2131.34'}, {'price': '0.67', 'size': '3010.1'}, {'price': '0.66', 'size': '510.1'}, {'price': '0.65', 'size': '5010.1'}, {'price': '0.64', 'size': '1630.1'}, {'price': '0.63', 'size': '210.1'}, {'price': '0.62', 'size': '300.1'}, {'price': '0.61', 'size': '111.06'}, {'price': '0.6', 'size': '67.85'}, {'price': '0.59', 'size': '3061.65'}, {'price': '0.58', 'size': '188.1'}, {'price': '0.57', 'size': '350.1'}, {'price': '0.56', 'size': '3710.1'}, {'price': '0.55', 'size': '5199.4'}], 'asset_id': '114416409796971863099144323163249651172534872992222856507897414949637892047507', 'bids': [{'price': '0.01', 'size': '2850.27'}, {'price': '0.02', 'size': '500'}, {'price': '0.03', 'size': '500'}, {'price': '0.04', 'size': '300'}, {'price': '0.05', 'size': '320'}, {'price': '0.06', 'size': '300'}, {'price': '0.08', 'size': '250'}, {'price': '0.09', 'size': '300'}, {'price': '0.1', 'size': '205'}, {'price': '0.11', 'size': '5454'}, {'price': '0.12', 'size': '200'}, {'price': '0.13', 'size': '426.92'}, {'price': '0.14', 'size': '15'}, {'price': '0.15', 'size': '110'}, {'price': '0.16', 'size': '4709.51'}, {'price': '0.18', 'size': '19.13'}, {'price': '0.19', 'size': '120'}, {'price': '0.2', 'size': '691.17'}, {'price': '0.24', 'size': '5027'}, {'price': '0.25', 'size': '86.66'}, {'price': '0.27', 'size': '215.25'}, {'price': '0.29', 'size': '1102.28'}, {'price': '0.31', 'size': '1130.65'}, {'price': '0.32', 'size': '200'}, {'price': '0.33', 'size': '4620'}, {'price': '0.35', 'size': '232'}, {'price': '0.39', 'size': '3010.5'}, {'price': '0.4', 'size': '3135'}, {'price': '0.41', 'size': '20'}, {'price': '0.42', 'size': '50'}, {'price': '0.43', 'size': '50'}, {'price': '0.44', 'size': '3710'}, {'price': '0.45', 'size': '3428'}, {'price': '0.46', 'size': '2000'}, {'price': '0.47', 'size': '50'}, {'price': '0.48', 'size': '1842.18'}, {'price': '0.49', 'size': '360'}, {'price': '0.5', 'size': '1515'}, {'price': '0.51', 'size': '1086.18'}, {'price': '0.52', 'size': '310.96'}], 'event_type': 'book', 'hash': '98484f621c88eb1adbee32342bac1e9d7d902efc', 'market': '0x7aa4a910b31b2c4ddb09d1e3408e52aa8e09a14402f376070a44b1b85cb36d13', 'timestamp': '1733332422546'}
{'asset_id': '114416409796971863099144323163249651172534872992222856507897414949637892047507', 'changes': [{'price': '0.52', 'side': 'BUY', 'size': '325.96'}], 'event_type': 'price_change', 'hash': '812850e6456038dacb7cacbcd5915071c58ed8c7', 'market': '0x7aa4a910b31b2c4ddb09d1e3408e52aa8e09a14402f376070a44b1b85cb36d13', 'timestamp': '1733332423035'}
{'asset_id': '114416409796971863099144323163249651172534872992222856507897414949637892047507', 'changes': [{'price': '0.52', 'side': 'BUY', 'size': '325.96'}], 'event_type': 'price_change', 'hash': '812850e6456038dacb7cacbcd5915071c58ed8c7', 'market': '0x7aa4a910b31b2c4ddb09d1e3408e52aa8e09a14402f376070a44b1b85cb36d13', 'timestamp': '1733332423035'}
{'asset_id': '114416409796971863099144323163249651172534872992222856507897414949637892047507', 'changes': [{'price': '0.44', 'side': 'BUY', 'size': '3660'}], 'event_type': 'price_change', 'hash': '2b3587c6e2e477ce046978d07dee8be310081a0a', 'market': '0x7aa4a910b31b2c4ddb09d1e3408e52aa8e09a14402f376070a44b1b85cb36d13', 'timestamp': '1733332423781'}
{'asset_id': '114416409796971863099144323163249651172534872992222856507897414949637892047507', 'changes': [{'price': '0.44', 'side': 'BUY', 'size': '3660'}], 'event_type': 'price_change', 'hash': '2b3587c6e2e477ce046978d07dee8be310081a0a', 'market': '0x7aa4a910b31b2c4ddb09d1e3408e52aa8e09a14402f376070a44b1b85cb36d13', 'timestamp': '1733332423781'}
{'asset_id': '114416409796971863099144323163249651172534872992222856507897414949637892047507', 'changes': [{'price': '0.52', 'side': 'BUY', 'size': '310.96'}], 'event_type': 'price_change', 'hash': '31d871fa4fbcfca2771bf21bb50ba00e45cc5424', 'market': '0x7aa4a910b31b2c4ddb09d1e3408e52aa8e09a14402f376070a44b1b85cb36d13', 'timestamp': '1733332424671'}
{'asset_id': '114416409796971863099144323163249651172534872992222856507897414949637892047507', 'changes': [{'price': '0.52', 'side': 'BUY', 'size': '310.96'}], 'event_type': 'price_change', 'hash': '31d871fa4fbcfca2771bf21bb50ba00e45cc5424', 'market': '0x7aa4a910b31b2c4ddb09d1e3408e52aa8e09a14402f376070a44b1b85cb36d13', 'timestamp': '1733332424671'}
{'asset_id': '114416409796971863099144323163249651172534872992222856507897414949637892047507', 'changes': [{'price': '0.52', 'side': 'BUY', 'size': '325.96'}], 'event_type': 'price_change', 'hash': 'ec0730023c62e5e28a0f18472b9edf7d12b52417', 'market': '0x7aa4a910b31b2c4ddb09d1e3408e52aa8e09a14402f376070a44b1b85cb36d13', 'timestamp': '1733332428732'}
{'asset_id': '114416409796971863099144323163249651172534872992222856507897414949637892047507', 'changes': [{'price': '0.52', 'side': 'BUY', 'size': '325.96'}], 'event_type': 'price_change', 'hash': 'ec0730023c62e5e28a0f18472b9edf7d12b52417', 'market': '0x7aa4a910b31b2c4ddb09d1e3408e52aa8e09a14402f376070a44b1b85cb36d13', 'timestamp': '1733332428732'}
{'asset_id': '114416409796971863099144323163249651172534872992222856507897414949637892047507', 'changes': [{'price': '0.57', 'side': 'SELL', 'size': '110.1'}, {'price': '0.49', 'side': 'BUY', 'size': '140'}], 'event_type': 'price_change', 'hash': '7a34ec26dce39099b482d65118aeb929bfe6bf5c', 'market': '0x7aa4a910b31b2c4ddb09d1e3408e52aa8e09a14402f376070a44b1b85cb36d13', 'timestamp': '1733332431771'}
{'asset_id': '114416409796971863099144323163249651172534872992222856507897414949637892047507', 'changes': [{'price': '0.57', 'side': 'SELL', 'size': '110.1'}, {'price': '0.49', 'side': 'BUY', 'size': '140'}], 'event_type': 'price_change', 'hash': '7a34ec26dce39099b482d65118aeb929bfe6bf5c', 'market': '0x7aa4a910b31b2c4ddb09d1e3408e52aa8e09a14402f376070a44b1b85cb36d13', 'timestamp': '1733332431771'}
{'asset_id': '114416409796971863099144323163249651172534872992222856507897414949637892047507', 'changes': [{'price': '0.58', 'side': 'SELL', 'size': '458.1'}, {'price': '0.49', 'side': 'BUY', 'size': '390'}], 'event_type': 'price_change', 'hash': 'd9529f079e9eb594b72bed256607945add5d182d', 'market': '0x7aa4a910b31b2c4ddb09d1e3408e52aa8e09a14402f376070a44b1b85cb36d13', 'timestamp': '1733332432097'}
{'asset_id': '114416409796971863099144323163249651172534872992222856507897414949637892047507', 'changes': [{'price': '0.58', 'side': 'SELL', 'size': '458.1'}, {'price': '0.49', 'side': 'BUY', 'size': '390'}], 'event_type': 'price_change', 'hash': 'd9529f079e9eb594b72bed256607945add5d182d', 'market': '0x7aa4a910b31b2c4ddb09d1e3408e52aa8e09a14402f376070a44b1b85cb36d13', 'timestamp': '1733332432097'}
{'asset_id': '114416409796971863099144323163249651172534872992222856507897414949637892047507', 'changes': [{'price': '0.52', 'side': 'BUY', 'size': '310.96'}], 'event_type': 'price_change', 'hash': '1eb84a1590cf858d03aa48ac7a5f4afcca0a764d', 'market': '0x7aa4a910b31b2c4ddb09d1e3408e52aa8e09a14402f376070a44b1b85cb36d13', 'timestamp': '1733332432840'}
{'asset_id': '114416409796971863099144323163249651172534872992222856507897414949637892047507', 'changes': [{'price': '0.52', 'side': 'BUY', 'size': '310.96'}], 'event_type': 'price_change', 'hash': '1eb84a1590cf858d03aa48ac7a5f4afcca0a764d', 'market': '0x7aa4a910b31b2c4ddb09d1e3408e52aa8e09a14402f376070a44b1b85cb36d13', 'timestamp': '1733332432840'}
{'asset_id': '114416409796971863099144323163249651172534872992222856507897414949637892047507', 'changes': [{'price': '0.45', 'side': 'BUY', 'size': '2928'}, {'price': '0.55', 'side': 'SELL', 'size': '4699.4'}, {'price': '0.5', 'side': 'BUY', 'size': '515'}], 'event_type': 'price_change', 'hash': 'c9529944171e70d1b816191e72f8203a1073489e', 'market': '0x7aa4a910b31b2c4ddb09d1e3408e52aa8e09a14402f376070a44b1b85cb36d13', 'timestamp': '1733332437370'}
{'asset_id': '114416409796971863099144323163249651172534872992222856507897414949637892047507', 'changes': [{'price': '0.45', 'side': 'BUY', 'size': '2928'}, {'price': '0.55', 'side': 'SELL', 'size': '4699.4'}, {'price': '0.5', 'side': 'BUY', 'size': '515'}], 'event_type': 'price_change', 'hash': 'c9529944171e70d1b816191e72f8203a1073489e', 'market': '0x7aa4a910b31b2c4ddb09d1e3408e52aa8e09a14402f376070a44b1b85cb36d13', 'timestamp': '1733332437370'}
{'asset_id': '114416409796971863099144323163249651172534872992222856507897414949637892047507', 'changes': [{'price': '0.53', 'side': 'SELL', 'size': '800'}], 'event_type': 'price_change', 'hash': 'de6c0b114f6a1064cd8d8d9aa0ab95e2ae42c188', 'market': '0x7aa4a910b31b2c4ddb09d1e3408e52aa8e09a14402f376070a44b1b85cb36d13', 'timestamp': '1733332438073'}
{'asset_id': '114416409796971863099144323163249651172534872992222856507897414949637892047507', 'changes': [{'price': '0.53', 'side': 'SELL', 'size': '800'}], 'event_type': 'price_change', 'hash': 'de6c0b114f6a1064cd8d8d9aa0ab95e2ae42c188', 'market': '0x7aa4a910b31b2c4ddb09d1e3408e52aa8e09a14402f376070a44b1b85cb36d13', 'timestamp': '1733332438073'}
{'asset_id': '114416409796971863099144323163249651172534872992222856507897414949637892047507', 'changes': [{'price': '0.45', 'side': 'BUY', 'size': '3428'}], 'event_type': 'price_change', 'hash': 'edfd803356ff8863fd3b8bd70ffb4bebba940090', 'market': '0x7aa4a910b31b2c4ddb09d1e3408e52aa8e09a14402f376070a44b1b85cb36d13', 'timestamp': '1733332438396'}
{'asset_id': '114416409796971863099144323163249651172534872992222856507897414949637892047507', 'changes': [{'price': '0.45', 'side': 'BUY', 'size': '3428'}], 'event_type': 'price_change', 'hash': 'edfd803356ff8863fd3b8bd70ffb4bebba940090', 'market': '0x7aa4a910b31b2c4ddb09d1e3408e52aa8e09a14402f376070a44b1b85cb36d13', 'timestamp': '1733332438396'}
{'asset_id': '114416409796971863099144323163249651172534872992222856507897414949637892047507', 'changes': [{'price': '0.45', 'side': 'BUY', 'size': '3478'}], 'event_type': 'price_change', 'hash': '9589beb21b4a5c967b68b15c619aac380ab16011', 'market': '0x7aa4a910b31b2c4ddb09d1e3408e52aa8e09a14402f376070a44b1b85cb36d13', 'timestamp': '1733332438547'}
{'asset_id': '114416409796971863099144323163249651172534872992222856507897414949637892047507', 'changes': [{'price': '0.45', 'side': 'BUY', 'size': '3478'}], 'event_type': 'price_change', 'hash': '9589beb21b4a5c967b68b15c619aac380ab16011', 'market': '0x7aa4a910b31b2c4ddb09d1e3408e52aa8e09a14402f376070a44b1b85cb36d13', 'timestamp': '1733332438547'}
{'asset_id': '114416409796971863099144323163249651172534872992222856507897414949637892047507', 'changes': [{'price': '0.55', 'side': 'SELL', 'size': '5199.4'}], 'event_type': 'price_change', 'hash': 'f65131ec1d27df2a17e1d6e06a780751809df6c9', 'market': '0x7aa4a910b31b2c4ddb09d1e3408e52aa8e09a14402f376070a44b1b85cb36d13', 'timestamp': '1733332438754'}
{'asset_id': '114416409796971863099144323163249651172534872992222856507897414949637892047507', 'changes': [{'price': '0.55', 'side': 'SELL', 'size': '5199.4'}], 'event_type': 'price_change', 'hash': 'f65131ec1d27df2a17e1d6e06a780751809df6c9', 'market': '0x7aa4a910b31b2c4ddb09d1e3408e52aa8e09a14402f376070a44b1b85cb36d13', 'timestamp': '1733332438754'}
{'asset_id': '114416409796971863099144323163249651172534872992222856507897414949637892047507', 'changes': [{'price': '0.56', 'side': 'SELL', 'size': '3610.1'}], 'event_type': 'price_change', 'hash': '4f76b0151a561c667a987b068a7094e3baafad3b', 'market': '0x7aa4a910b31b2c4ddb09d1e3408e52aa8e09a14402f376070a44b1b85cb36d13', 'timestamp': '1733332438876'}
{'asset_id': '114416409796971863099144323163249651172534872992222856507897414949637892047507', 'changes': [{'price': '0.56', 'side': 'SELL', 'size': '3610.1'}], 'event_type': 'price_change', 'hash': '4f76b0151a561c667a987b068a7094e3baafad3b', 'market': '0x7aa4a910b31b2c4ddb09d1e3408e52aa8e09a14402f376070a44b1b85cb36d13', 'timestamp': '1733332438876'}
{'asset_id': '114416409796971863099144323163249651172534872992222856507897414949637892047507', 'changes': [{'price': '0.51', 'side': 'BUY', 'size': '2086.18'}], 'event_type': 'price_change', 'hash': '207da14645a4582dc292cd6b1d91ab89bf8a51cc', 'market': '0x7aa4a910b31b2c4ddb09d1e3408e52aa8e09a14402f376070a44b1b85cb36d13', 'timestamp': '1733332439111'}
{'asset_id': '114416409796971863099144323163249651172534872992222856507897414949637892047507', 'changes': [{'price': '0.51', 'side': 'BUY', 'size': '2086.18'}], 'event_type': 'price_change', 'hash': '207da14645a4582dc292cd6b1d91ab89bf8a51cc', 'market': '0x7aa4a910b31b2c4ddb09d1e3408e52aa8e09a14402f376070a44b1b85cb36d13', 'timestamp': '1733332439111'}
{'asset_id': '114416409796971863099144323163249651172534872992222856507897414949637892047507', 'changes': [{'price': '0.54', 'side': 'SELL', 'size': '100'}, {'price': '0.55', 'side': 'SELL', 'size': '5099.4'}], 'event_type': 'price_change', 'hash': '6eb8bc5bcb9ce241ba6f7e971a8974ce4cd9b550', 'market': '0x7aa4a910b31b2c4ddb09d1e3408e52aa8e09a14402f376070a44b1b85cb36d13', 'timestamp': '1733332440051'}
{'asset_id': '114416409796971863099144323163249651172534872992222856507897414949637892047507', 'changes': [{'price': '0.54', 'side': 'SELL', 'size': '100'}, {'price': '0.55', 'side': 'SELL', 'size': '5099.4'}], 'event_type': 'price_change', 'hash': '6eb8bc5bcb9ce241ba6f7e971a8974ce4cd9b550', 'market': '0x7aa4a910b31b2c4ddb09d1e3408e52aa8e09a14402f376070a44b1b85cb36d13', 'timestamp': '1733332440051'}
{'asset_id': '114416409796971863099144323163249651172534872992222856507897414949637892047507', 'changes': [{'price': '0.53', 'side': 'SELL', 'size': '900'}], 'event_type': 'price_change', 'hash': '73fdfd3849f732dc8ee16523276b032e011b923b', 'market': '0x7aa4a910b31b2c4ddb09d1e3408e52aa8e09a14402f376070a44b1b85cb36d13', 'timestamp': '1733332440293'}
{'asset_id': '114416409796971863099144323163249651172534872992222856507897414949637892047507', 'changes': [{'price': '0.53', 'side': 'SELL', 'size': '900'}], 'event_type': 'price_change', 'hash': '73fdfd3849f732dc8ee16523276b032e011b923b', 'market': '0x7aa4a910b31b2c4ddb09d1e3408e52aa8e09a14402f376070a44b1b85cb36d13', 'timestamp': '1733332440293'}
{'asset_id': '114416409796971863099144323163249651172534872992222856507897414949637892047507', 'changes': [{'price': '0.55', 'side': 'SELL', 'size': '5074.39'}], 'event_type': 'price_change', 'hash': '14412fccea4e5f78b6977b4b71346de46d5403c1', 'market': '0x7aa4a910b31b2c4ddb09d1e3408e52aa8e09a14402f376070a44b1b85cb36d13', 'timestamp': '1733332442354'}
{'asset_id': '114416409796971863099144323163249651172534872992222856507897414949637892047507', 'changes': [{'price': '0.55', 'side': 'SELL', 'size': '5074.39'}], 'event_type': 'price_change', 'hash': '14412fccea4e5f78b6977b4b71346de46d5403c1', 'market': '0x7aa4a910b31b2c4ddb09d1e3408e52aa8e09a14402f376070a44b1b85cb36d13', 'timestamp': '1733332442354'}
{'asset_id': '114416409796971863099144323163249651172534872992222856507897414949637892047507', 'changes': [{'price': '0.52', 'side': 'BUY', 'size': '325.96'}], 'event_type': 'price_change', 'hash': '1911924bab6e75373af4452337181286b2f743a6', 'market': '0x7aa4a910b31b2c4ddb09d1e3408e52aa8e09a14402f376070a44b1b85cb36d13', 'timestamp': '1733332442423'}
{'asset_id': '114416409796971863099144323163249651172534872992222856507897414949637892047507', 'changes': [{'price': '0.52', 'side': 'BUY', 'size': '325.96'}], 'event_type': 'price_change', 'hash': '1911924bab6e75373af4452337181286b2f743a6', 'market': '0x7aa4a910b31b2c4ddb09d1e3408e52aa8e09a14402f376070a44b1b85cb36d13', 'timestamp': '1733332442423'}
{'asset_id': '114416409796971863099144323163249651172534872992222856507897414949637892047507', 'changes': [{'price': '0.53', 'side': 'SELL', 'size': '925.01'}], 'event_type': 'price_change', 'hash': 'e164ba5527f9cd631843f7916221ffaf972f3ff0', 'market': '0x7aa4a910b31b2c4ddb09d1e3408e52aa8e09a14402f376070a44b1b85cb36d13', 'timestamp': '1733332442539'}
{'asset_id': '114416409796971863099144323163249651172534872992222856507897414949637892047507', 'changes': [{'price': '0.53', 'side': 'SELL', 'size': '925.01'}], 'event_type': 'price_change', 'hash': 'e164ba5527f9cd631843f7916221ffaf972f3ff0', 'market': '0x7aa4a910b31b2c4ddb09d1e3408e52aa8e09a14402f376070a44b1b85cb36d13', 'timestamp': '1733332442539'}
{'asset_id': '114416409796971863099144323163249651172534872992222856507897414949637892047507', 'changes': [{'price': '0.49', 'side': 'BUY', 'size': '1590'}, {'price': '0.55', 'side': 'SELL', 'size': '6274.39'}], 'event_type': 'price_change', 'hash': 'dcc1baded67b8a3249d8cb444f80e961577a2a96', 'market': '0x7aa4a910b31b2c4ddb09d1e3408e52aa8e09a14402f376070a44b1b85cb36d13', 'timestamp': '1733332443439'}
{'asset_id': '114416409796971863099144323163249651172534872992222856507897414949637892047507', 'changes': [{'price': '0.49', 'side': 'BUY', 'size': '1590'}, {'price': '0.55', 'side': 'SELL', 'size': '6274.39'}], 'event_type': 'price_change', 'hash': 'dcc1baded67b8a3249d8cb444f80e961577a2a96', 'market': '0x7aa4a910b31b2c4ddb09d1e3408e52aa8e09a14402f376070a44b1b85cb36d13', 'timestamp': '1733332443439'}
{'asset_id': '114416409796971863099144323163249651172534872992222856507897414949637892047507', 'changes': [{'price': '0.52', 'side': 'BUY', 'size': '310.96'}], 'event_type': 'price_change', 'hash': 'e42b73d4f5865c2e36418fd7be08e23d5bfccece', 'market': '0x7aa4a910b31b2c4ddb09d1e3408e52aa8e09a14402f376070a44b1b85cb36d13', 'timestamp': '1733332444908'}
{'asset_id': '114416409796971863099144323163249651172534872992222856507897414949637892047507', 'changes': [{'price': '0.52', 'side': 'BUY', 'size': '310.96'}], 'event_type': 'price_change', 'hash': 'e42b73d4f5865c2e36418fd7be08e23d5bfccece', 'market': '0x7aa4a910b31b2c4ddb09d1e3408e52aa8e09a14402f376070a44b1b85cb36d13', 'timestamp': '1733332444908'}
{'asset_id': '114416409796971863099144323163249651172534872992222856507897414949637892047507', 'changes': [{'price': '0.52', 'side': 'BUY', 'size': '325.96'}], 'event_type': 'price_change', 'hash': 'feddb630ecb12b2664d6a24b7148b35dcb9122b2', 'market': '0x7aa4a910b31b2c4ddb09d1e3408e52aa8e09a14402f376070a44b1b85cb36d13', 'timestamp': '1733332446641'}
{'asset_id': '114416409796971863099144323163249651172534872992222856507897414949637892047507', 'changes': [{'price': '0.52', 'side': 'BUY', 'size': '325.96'}], 'event_type': 'price_change', 'hash': 'feddb630ecb12b2664d6a24b7148b35dcb9122b2', 'market': '0x7aa4a910b31b2c4ddb09d1e3408e52aa8e09a14402f376070a44b1b85cb36d13', 'timestamp': '1733332446641'}
{'asset_id': '114416409796971863099144323163249651172534872992222856507897414949637892047507', 'changes': [{'price': '0.55', 'side': 'SELL', 'size': '6214.39'}], 'event_type': 'price_change', 'hash': 'ec596413d63f807a19c46978cf2ee6b75006ceb1', 'market': '0x7aa4a910b31b2c4ddb09d1e3408e52aa8e09a14402f376070a44b1b85cb36d13', 'timestamp': '1733332448710'}
{'asset_id': '114416409796971863099144323163249651172534872992222856507897414949637892047507', 'changes': [{'price': '0.55', 'side': 'SELL', 'size': '6214.39'}], 'event_type': 'price_change', 'hash': 'ec596413d63f807a19c46978cf2ee6b75006ceb1', 'market': '0x7aa4a910b31b2c4ddb09d1e3408e52aa8e09a14402f376070a44b1b85cb36d13', 'timestamp': '1733332448710'}
{'asset_id': '114416409796971863099144323163249651172534872992222856507897414949637892047507', 'changes': [{'price': '0.54', 'side': 'SELL', 'size': '160'}], 'event_type': 'price_change', 'hash': '6814e02c26333edd81bd4e288cea6896dc4ad3c6', 'market': '0x7aa4a910b31b2c4ddb09d1e3408e52aa8e09a14402f376070a44b1b85cb36d13', 'timestamp': '1733332448896'}
{'asset_id': '114416409796971863099144323163249651172534872992222856507897414949637892047507', 'changes': [{'price': '0.54', 'side': 'SELL', 'size': '160'}], 'event_type': 'price_change', 'hash': '6814e02c26333edd81bd4e288cea6896dc4ad3c6', 'market': '0x7aa4a910b31b2c4ddb09d1e3408e52aa8e09a14402f376070a44b1b85cb36d13', 'timestamp': '1733332448896'}
{'asset_id': '114416409796971863099144323163249651172534872992222856507897414949637892047507', 'changes': [{'price': '0.58', 'side': 'SELL', 'size': '188.1'}, {'price': '0.49', 'side': 'BUY', 'size': '1340'}], 'event_type': 'price_change', 'hash': '230d9ac653f0a1e7570cdd4c1fe7f43f3c28a2c4', 'market': '0x7aa4a910b31b2c4ddb09d1e3408e52aa8e09a14402f376070a44b1b85cb36d13', 'timestamp': '1733332451358'}
{'asset_id': '114416409796971863099144323163249651172534872992222856507897414949637892047507', 'changes': [{'price': '0.58', 'side': 'SELL', 'size': '188.1'}, {'price': '0.49', 'side': 'BUY', 'size': '1340'}], 'event_type': 'price_change', 'hash': '230d9ac653f0a1e7570cdd4c1fe7f43f3c28a2c4', 'market': '0x7aa4a910b31b2c4ddb09d1e3408e52aa8e09a14402f376070a44b1b85cb36d13', 'timestamp': '1733332451358'}
{'asset_id': '114416409796971863099144323163249651172534872992222856507897414949637892047507', 'changes': [{'price': '0.48', 'side': 'BUY', 'size': '2092.18'}, {'price': '0.57', 'side': 'SELL', 'size': '380.1'}], 'event_type': 'price_change', 'hash': '1e97b46de97c1c510411f935d972dc33300435d4', 'market': '0x7aa4a910b31b2c4ddb09d1e3408e52aa8e09a14402f376070a44b1b85cb36d13', 'timestamp': '1733332451684'}
{'asset_id': '114416409796971863099144323163249651172534872992222856507897414949637892047507', 'changes': [{'price': '0.48', 'side': 'BUY', 'size': '2092.18'}, {'price': '0.57', 'side': 'SELL', 'size': '380.1'}], 'event_type': 'price_change', 'hash': '1e97b46de97c1c510411f935d972dc33300435d4', 'market': '0x7aa4a910b31b2c4ddb09d1e3408e52aa8e09a14402f376070a44b1b85cb36d13', 'timestamp': '1733332451684'}
{'asset_id': '114416409796971863099144323163249651172534872992222856507897414949637892047507', 'changes': [{'price': '0.45', 'side': 'BUY', 'size': '2978'}, {'price': '0.55', 'side': 'SELL', 'size': '5714.39'}, {'price': '0.51', 'side': 'BUY', 'size': '1086.18'}], 'event_type': 'price_change', 'hash': 'f9e6dc3392f1ab59e3423dd0a4883dfcb5ea9f77', 'market': '0x7aa4a910b31b2c4ddb09d1e3408e52aa8e09a14402f376070a44b1b85cb36d13', 'timestamp': '1733332469936'}
{'asset_id': '114416409796971863099144323163249651172534872992222856507897414949637892047507', 'changes': [{'price': '0.45', 'side': 'BUY', 'size': '2978'}, {'price': '0.55', 'side': 'SELL', 'size': '5714.39'}, {'price': '0.51', 'side': 'BUY', 'size': '1086.18'}], 'event_type': 'price_change', 'hash': 'f9e6dc3392f1ab59e3423dd0a4883dfcb5ea9f77', 'market': '0x7aa4a910b31b2c4ddb09d1e3408e52aa8e09a14402f376070a44b1b85cb36d13', 'timestamp': '1733332469936'}
{'asset_id': '114416409796971863099144323163249651172534872992222856507897414949637892047507', 'changes': [{'price': '0.45', 'side': 'BUY', 'size': '3478'}], 'event_type': 'price_change', 'hash': 'f4745db61d657d869049ccb89ac1c85c6d580664', 'market': '0x7aa4a910b31b2c4ddb09d1e3408e52aa8e09a14402f376070a44b1b85cb36d13', 'timestamp': '1733332470956'}
{'asset_id': '114416409796971863099144323163249651172534872992222856507897414949637892047507', 'changes': [{'price': '0.45', 'side': 'BUY', 'size': '3478'}], 'event_type': 'price_change', 'hash': 'f4745db61d657d869049ccb89ac1c85c6d580664', 'market': '0x7aa4a910b31b2c4ddb09d1e3408e52aa8e09a14402f376070a44b1b85cb36d13', 'timestamp': '1733332470956'}
{'asset_id': '114416409796971863099144323163249651172534872992222856507897414949637892047507', 'changes': [{'price': '0.55', 'side': 'SELL', 'size': '6214.39'}], 'event_type': 'price_change', 'hash': '79587cd3dd2d952979dfde2c26121a968445ca2e', 'market': '0x7aa4a910b31b2c4ddb09d1e3408e52aa8e09a14402f376070a44b1b85cb36d13', 'timestamp': '1733332471323'}
{'asset_id': '114416409796971863099144323163249651172534872992222856507897414949637892047507', 'changes': [{'price': '0.55', 'side': 'SELL', 'size': '6214.39'}], 'event_type': 'price_change', 'hash': '79587cd3dd2d952979dfde2c26121a968445ca2e', 'market': '0x7aa4a910b31b2c4ddb09d1e3408e52aa8e09a14402f376070a44b1b85cb36d13', 'timestamp': '1733332471323'}
{'asset_id': '114416409796971863099144323163249651172534872992222856507897414949637892047507', 'changes': [{'price': '0.5', 'side': 'BUY', 'size': '1515'}], 'event_type': 'price_change', 'hash': '89a3c18a6b42b817b3002ddf320b07136f64aab6', 'market': '0x7aa4a910b31b2c4ddb09d1e3408e52aa8e09a14402f376070a44b1b85cb36d13', 'timestamp': '1733332471696'}
{'asset_id': '114416409796971863099144323163249651172534872992222856507897414949637892047507', 'changes': [{'price': '0.5', 'side': 'BUY', 'size': '1515'}], 'event_type': 'price_change', 'hash': '89a3c18a6b42b817b3002ddf320b07136f64aab6', 'market': '0x7aa4a910b31b2c4ddb09d1e3408e52aa8e09a14402f376070a44b1b85cb36d13', 'timestamp': '1733332471696'}
{'asset_id': '114416409796971863099144323163249651172534872992222856507897414949637892047507', 'changes': [{'price': '0.52', 'side': 'BUY', 'size': '310.96'}], 'event_type': 'price_change', 'hash': 'bcb7fca030f783b650083be906a46dc4c12a3208', 'market': '0x7aa4a910b31b2c4ddb09d1e3408e52aa8e09a14402f376070a44b1b85cb36d13', 'timestamp': '1733332476852'}
{'asset_id': '114416409796971863099144323163249651172534872992222856507897414949637892047507', 'changes': [{'price': '0.52', 'side': 'BUY', 'size': '310.96'}], 'event_type': 'price_change', 'hash': 'bcb7fca030f783b650083be906a46dc4c12a3208', 'market': '0x7aa4a910b31b2c4ddb09d1e3408e52aa8e09a14402f376070a44b1b85cb36d13', 'timestamp': '1733332476852'}
{'asset_id': '114416409796971863099144323163249651172534872992222856507897414949637892047507', 'changes': [{'price': '0.52', 'side': 'BUY', 'size': '325.96'}], 'event_type': 'price_change', 'hash': 'cc2a7e513b20c92966f2d9928dbc8b36c85febe0', 'market': '0x7aa4a910b31b2c4ddb09d1e3408e52aa8e09a14402f376070a44b1b85cb36d13', 'timestamp': '1733332504666'}
{'asset_id': '114416409796971863099144323163249651172534872992222856507897414949637892047507', 'changes': [{'price': '0.52', 'side': 'BUY', 'size': '325.96'}], 'event_type': 'price_change', 'hash': 'cc2a7e513b20c92966f2d9928dbc8b36c85febe0', 'market': '0x7aa4a910b31b2c4ddb09d1e3408e52aa8e09a14402f376070a44b1b85cb36d13', 'timestamp': '1733332504666'}
{'asset_id': '114416409796971863099144323163249651172534872992222856507897414949637892047507', 'changes': [{'price': '0.7', 'side': 'SELL', 'size': '5570.1'}], 'event_type': 'price_change', 'hash': '7fb0cef9b06d1c1a5d49879f7d27e91bc92820cd', 'market': '0x7aa4a910b31b2c4ddb09d1e3408e52aa8e09a14402f376070a44b1b85cb36d13', 'timestamp': '1733332510349'}
{'asset_id': '114416409796971863099144323163249651172534872992222856507897414949637892047507', 'changes': [{'price': '0.7', 'side': 'SELL', 'size': '5570.1'}], 'event_type': 'price_change', 'hash': '7fb0cef9b06d1c1a5d49879f7d27e91bc92820cd', 'market': '0x7aa4a910b31b2c4ddb09d1e3408e52aa8e09a14402f376070a44b1b85cb36d13', 'timestamp': '1733332510349'}
{'asset_id': '114416409796971863099144323163249651172534872992222856507897414949637892047507', 'changes': [{'price': '0.52', 'side': 'BUY', 'size': '310.96'}], 'event_type': 'price_change', 'hash': '4b85762f3a7f1c51c9c1222d826cc5e4ff15f92f', 'market': '0x7aa4a910b31b2c4ddb09d1e3408e52aa8e09a14402f376070a44b1b85cb36d13', 'timestamp': '1733332510924'}
{'asset_id': '114416409796971863099144323163249651172534872992222856507897414949637892047507', 'changes': [{'price': '0.52', 'side': 'BUY', 'size': '310.96'}], 'event_type': 'price_change', 'hash': '4b85762f3a7f1c51c9c1222d826cc5e4ff15f92f', 'market': '0x7aa4a910b31b2c4ddb09d1e3408e52aa8e09a14402f376070a44b1b85cb36d13', 'timestamp': '1733332510924'}
{'asset_id': '114416409796971863099144323163249651172534872992222856507897414949637892047507', 'changes': [{'price': '0.52', 'side': 'BUY', 'size': '325.96'}], 'event_type': 'price_change', 'hash': 'ab542708e9d2221a9b2d194a84f74334339079df', 'market': '0x7aa4a910b31b2c4ddb09d1e3408e52aa8e09a14402f376070a44b1b85cb36d13', 'timestamp': '1733332514338'}
{'asset_id': '114416409796971863099144323163249651172534872992222856507897414949637892047507', 'changes': [{'price': '0.52', 'side': 'BUY', 'size': '325.96'}], 'event_type': 'price_change', 'hash': 'ab542708e9d2221a9b2d194a84f74334339079df', 'market': '0x7aa4a910b31b2c4ddb09d1e3408e52aa8e09a14402f376070a44b1b85cb36d13', 'timestamp': '1733332514338'}
{'asset_id': '114416409796971863099144323163249651172534872992222856507897414949637892047507', 'changes': [{'price': '0.52', 'side': 'BUY', 'size': '310.96'}], 'event_type': 'price_change', 'hash': 'b43795a1b58f700a04697b6087059f1a0bde61da', 'market': '0x7aa4a910b31b2c4ddb09d1e3408e52aa8e09a14402f376070a44b1b85cb36d13', 'timestamp': '1733332518949'}
{'asset_id': '114416409796971863099144323163249651172534872992222856507897414949637892047507', 'changes': [{'price': '0.52', 'side': 'BUY', 'size': '310.96'}], 'event_type': 'price_change', 'hash': 'b43795a1b58f700a04697b6087059f1a0bde61da', 'market': '0x7aa4a910b31b2c4ddb09d1e3408e52aa8e09a14402f376070a44b1b85cb36d13', 'timestamp': '1733332518949'}
{'asset_id': '114416409796971863099144323163249651172534872992222856507897414949637892047507', 'changes': [{'price': '0.45', 'side': 'BUY', 'size': '2978'}, {'price': '0.55', 'side': 'SELL', 'size': '5714.39'}, {'price': '0.5', 'side': 'BUY', 'size': '515'}], 'event_type': 'price_change', 'hash': '1b434726dbfd462c9c722ce6ece5bff6ea2ffb84', 'market': '0x7aa4a910b31b2c4ddb09d1e3408e52aa8e09a14402f376070a44b1b85cb36d13', 'timestamp': '1733332521300'}
{'asset_id': '114416409796971863099144323163249651172534872992222856507897414949637892047507', 'changes': [{'price': '0.45', 'side': 'BUY', 'size': '2978'}, {'price': '0.55', 'side': 'SELL', 'size': '5714.39'}, {'price': '0.5', 'side': 'BUY', 'size': '515'}], 'event_type': 'price_change', 'hash': '1b434726dbfd462c9c722ce6ece5bff6ea2ffb84', 'market': '0x7aa4a910b31b2c4ddb09d1e3408e52aa8e09a14402f376070a44b1b85cb36d13', 'timestamp': '1733332521300'}
{'asset_id': '114416409796971863099144323163249651172534872992222856507897414949637892047507', 'changes': [{'price': '0.45', 'side': 'BUY', 'size': '3478'}], 'event_type': 'price_change', 'hash': 'ad9242fc73cfc98af698e162b5f33d00281fc3d5', 'market': '0x7aa4a910b31b2c4ddb09d1e3408e52aa8e09a14402f376070a44b1b85cb36d13', 'timestamp': '1733332522363'}
{'asset_id': '114416409796971863099144323163249651172534872992222856507897414949637892047507', 'changes': [{'price': '0.45', 'side': 'BUY', 'size': '3478'}], 'event_type': 'price_change', 'hash': 'ad9242fc73cfc98af698e162b5f33d00281fc3d5', 'market': '0x7aa4a910b31b2c4ddb09d1e3408e52aa8e09a14402f376070a44b1b85cb36d13', 'timestamp': '1733332522363'}
{'asset_id': '114416409796971863099144323163249651172534872992222856507897414949637892047507', 'changes': [{'price': '0.52', 'side': 'BUY', 'size': '325.96'}], 'event_type': 'price_change', 'hash': 'd779802a89b6ca082121b697a8bb03cb104548a0', 'market': '0x7aa4a910b31b2c4ddb09d1e3408e52aa8e09a14402f376070a44b1b85cb36d13', 'timestamp': '1733332522435'}
{'asset_id': '114416409796971863099144323163249651172534872992222856507897414949637892047507', 'changes': [{'price': '0.52', 'side': 'BUY', 'size': '325.96'}], 'event_type': 'price_change', 'hash': 'd779802a89b6ca082121b697a8bb03cb104548a0', 'market': '0x7aa4a910b31b2c4ddb09d1e3408e52aa8e09a14402f376070a44b1b85cb36d13', 'timestamp': '1733332522435'}
{'asset_id': '114416409796971863099144323163249651172534872992222856507897414949637892047507', 'changes': [{'price': '0.55', 'side': 'SELL', 'size': '6214.39'}], 'event_type': 'price_change', 'hash': '577550c52397a9e360c44e6e712419e8c503c932', 'market': '0x7aa4a910b31b2c4ddb09d1e3408e52aa8e09a14402f376070a44b1b85cb36d13', 'timestamp': '1733332522732'}
{'asset_id': '114416409796971863099144323163249651172534872992222856507897414949637892047507', 'changes': [{'price': '0.55', 'side': 'SELL', 'size': '6214.39'}], 'event_type': 'price_change', 'hash': '577550c52397a9e360c44e6e712419e8c503c932', 'market': '0x7aa4a910b31b2c4ddb09d1e3408e52aa8e09a14402f376070a44b1b85cb36d13', 'timestamp': '1733332522732'}
{'asset_id': '114416409796971863099144323163249651172534872992222856507897414949637892047507', 'changes': [{'price': '0.51', 'side': 'BUY', 'size': '2086.18'}], 'event_type': 'price_change', 'hash': '98df321161ff2961dfd3d3e569f52258f171d68d', 'market': '0x7aa4a910b31b2c4ddb09d1e3408e52aa8e09a14402f376070a44b1b85cb36d13', 'timestamp': '1733332523110'}
{'asset_id': '114416409796971863099144323163249651172534872992222856507897414949637892047507', 'changes': [{'price': '0.51', 'side': 'BUY', 'size': '2086.18'}], 'event_type': 'price_change', 'hash': '98df321161ff2961dfd3d3e569f52258f171d68d', 'market': '0x7aa4a910b31b2c4ddb09d1e3408e52aa8e09a14402f376070a44b1b85cb36d13', 'timestamp': '1733332523110'}
{'asset_id': '114416409796971863099144323163249651172534872992222856507897414949637892047507', 'changes': [{'price': '0.55', 'side': 'SELL', 'size': '4714.39'}], 'event_type': 'price_change', 'hash': '8f821219d17c035b20e3ec159acf3a3d384f12ed', 'market': '0x7aa4a910b31b2c4ddb09d1e3408e52aa8e09a14402f376070a44b1b85cb36d13', 'timestamp': '1733332524011'}
{'asset_id': '114416409796971863099144323163249651172534872992222856507897414949637892047507', 'changes': [{'price': '0.55', 'side': 'SELL', 'size': '4714.39'}], 'event_type': 'price_change', 'hash': '8f821219d17c035b20e3ec159acf3a3d384f12ed', 'market': '0x7aa4a910b31b2c4ddb09d1e3408e52aa8e09a14402f376070a44b1b85cb36d13', 'timestamp': '1733332524011'}
{'asset_id': '114416409796971863099144323163249651172534872992222856507897414949637892047507', 'changes': [{'price': '0.52', 'side': 'BUY', 'size': '310.96'}], 'event_type': 'price_change', 'hash': '5e11866c5f57dc9f336de25687519b3637825f1d', 'market': '0x7aa4a910b31b2c4ddb09d1e3408e52aa8e09a14402f376070a44b1b85cb36d13', 'timestamp': '1733332524721'}
{'asset_id': '114416409796971863099144323163249651172534872992222856507897414949637892047507', 'changes': [{'price': '0.52', 'side': 'BUY', 'size': '310.96'}], 'event_type': 'price_change', 'hash': '5e11866c5f57dc9f336de25687519b3637825f1d', 'market': '0x7aa4a910b31b2c4ddb09d1e3408e52aa8e09a14402f376070a44b1b85cb36d13', 'timestamp': '1733332524721'}
{'asset_id': '114416409796971863099144323163249651172534872992222856507897414949637892047507', 'changes': [{'price': '0.56', 'side': 'SELL', 'size': '1110.1'}, {'price': '0.55', 'side': 'SELL', 'size': '2714.39'}, {'price': '0.46', 'side': 'BUY', 'size': '0'}], 'event_type': 'price_change', 'hash': 'a660f3d92a0a578b0e781597fc3ec1a5a3d8d329', 'market': '0x7aa4a910b31b2c4ddb09d1e3408e52aa8e09a14402f376070a44b1b85cb36d13', 'timestamp': '1733332526313'}
{'asset_id': '114416409796971863099144323163249651172534872992222856507897414949637892047507', 'changes': [{'price': '0.56', 'side': 'SELL', 'size': '1110.1'}, {'price': '0.55', 'side': 'SELL', 'size': '2714.39'}, {'price': '0.46', 'side': 'BUY', 'size': '0'}], 'event_type': 'price_change', 'hash': 'a660f3d92a0a578b0e781597fc3ec1a5a3d8d329', 'market': '0x7aa4a910b31b2c4ddb09d1e3408e52aa8e09a14402f376070a44b1b85cb36d13', 'timestamp': '1733332526313'}
{'asset_id': '114416409796971863099144323163249651172534872992222856507897414949637892047507', 'changes': [{'price': '0.52', 'side': 'BUY', 'size': '325.96'}], 'event_type': 'price_change', 'hash': 'ae6b3b6068bfd3a1d85a75d50862eb28919aec70', 'market': '0x7aa4a910b31b2c4ddb09d1e3408e52aa8e09a14402f376070a44b1b85cb36d13', 'timestamp': '1733332526527'}
{'asset_id': '114416409796971863099144323163249651172534872992222856507897414949637892047507', 'changes': [{'price': '0.52', 'side': 'BUY', 'size': '325.96'}], 'event_type': 'price_change', 'hash': 'ae6b3b6068bfd3a1d85a75d50862eb28919aec70', 'market': '0x7aa4a910b31b2c4ddb09d1e3408e52aa8e09a14402f376070a44b1b85cb36d13', 'timestamp': '1733332526527'}
{'asks': [{'price': '0.99', 'size': '4217.01'}, {'price': '0.98', 'size': '505'}, {'price': '0.97', 'size': '511.03'}, {'price': '0.96', 'size': '300'}, {'price': '0.95', 'size': '657.12'}, {'price': '0.94', 'size': '300'}, {'price': '0.92', 'size': '20000.45'}, {'price': '0.91', 'size': '10406.3'}, {'price': '0.9', 'size': '4587.5'}, {'price': '0.89', 'size': '13017.18'}, {'price': '0.88', 'size': '200'}, {'price': '0.87', 'size': '3229'}, {'price': '0.86', 'size': '17.1'}, {'price': '0.85', 'size': '109.68'}, {'price': '0.84', 'size': '250'}, {'price': '0.83', 'size': '100'}, {'price': '0.82', 'size': '16029'}, {'price': '0.81', 'size': '45721.39'}, {'price': '0.8', 'size': '26531'}, {'price': '0.79', 'size': '7110'}, {'price': '0.78', 'size': '10350'}, {'price': '0.77', 'size': '67'}, {'price': '0.76', 'size': '200'}, {'price': '0.75', 'size': '18329.25'}, {'price': '0.74', 'size': '11370.7'}, {'price': '0.73', 'size': '5020.1'}, {'price': '0.72', 'size': '380.52'}, {'price': '0.71', 'size': '15073.2'}, {'price': '0.7', 'size': '5570.1'}, {'price': '0.69', 'size': '6088.6'}, {'price': '0.68', 'size': '2131.34'}, {'price': '0.67', 'size': '3010.1'}, {'price': '0.66', 'size': '510.1'}, {'price': '0.65', 'size': '5010.1'}, {'price': '0.64', 'size': '1630.1'}, {'price': '0.63', 'size': '210.1'}, {'price': '0.62', 'size': '300.1'}, {'price': '0.61', 'size': '111.06'}, {'price': '0.6', 'size': '67.85'}, {'price': '0.59', 'size': '3061.65'}, {'price': '0.58', 'size': '188.1'}, {'price': '0.57', 'size': '380.1'}, {'price': '0.56', 'size': '1110.1'}, {'price': '0.55', 'size': '2714.39'}, {'price': '0.54', 'size': '160'}, {'price': '0.53', 'size': '925.01'}], 'asset_id': '114416409796971863099144323163249651172534872992222856507897414949637892047507', 'bids': [{'price': '0.01', 'size': '2850.27'}, {'price': '0.02', 'size': '500'}, {'price': '0.03', 'size': '500'}, {'price': '0.04', 'size': '300'}, {'price': '0.05', 'size': '320'}, {'price': '0.06', 'size': '300'}, {'price': '0.08', 'size': '250'}, {'price': '0.09', 'size': '300'}, {'price': '0.1', 'size': '205'}, {'price': '0.11', 'size': '5454'}, {'price': '0.12', 'size': '200'}, {'price': '0.13', 'size': '426.92'}, {'price': '0.14', 'size': '15'}, {'price': '0.15', 'size': '110'}, {'price': '0.16', 'size': '4709.51'}, {'price': '0.18', 'size': '19.13'}, {'price': '0.19', 'size': '120'}, {'price': '0.2', 'size': '691.17'}, {'price': '0.24', 'size': '5027'}, {'price': '0.25', 'size': '86.66'}, {'price': '0.27', 'size': '215.25'}, {'price': '0.29', 'size': '1102.28'}, {'price': '0.31', 'size': '1130.65'}, {'price': '0.32', 'size': '200'}, {'price': '0.33', 'size': '4620'}, {'price': '0.35', 'size': '232'}, {'price': '0.39', 'size': '3010.5'}, {'price': '0.4', 'size': '3135'}, {'price': '0.41', 'size': '20'}, {'price': '0.42', 'size': '50'}, {'price': '0.43', 'size': '50'}, {'price': '0.44', 'size': '3660'}, {'price': '0.45', 'size': '3478'}, {'price': '0.47', 'size': '50'}, {'price': '0.48', 'size': '2092.18'}, {'price': '0.49', 'size': '1340'}, {'price': '0.5', 'size': '515'}, {'price': '0.51', 'size': '2086.18'}, {'price': '0.52', 'size': '15'}], 'event_type': 'book', 'hash': '222bbb76077c5588763f7fa0268b884ca1c89951', 'market': '0x7aa4a910b31b2c4ddb09d1e3408e52aa8e09a14402f376070a44b1b85cb36d13', 'timestamp': '1733332531152'}
{'asks': [{'price': '0.99', 'size': '4217.01'}, {'price': '0.98', 'size': '505'}, {'price': '0.97', 'size': '511.03'}, {'price': '0.96', 'size': '300'}, {'price': '0.95', 'size': '657.12'}, {'price': '0.94', 'size': '300'}, {'price': '0.92', 'size': '20000.45'}, {'price': '0.91', 'size': '10406.3'}, {'price': '0.9', 'size': '4587.5'}, {'price': '0.89', 'size': '13017.18'}, {'price': '0.88', 'size': '200'}, {'price': '0.87', 'size': '3229'}, {'price': '0.86', 'size': '17.1'}, {'price': '0.85', 'size': '109.68'}, {'price': '0.84', 'size': '250'}, {'price': '0.83', 'size': '100'}, {'price': '0.82', 'size': '16029'}, {'price': '0.81', 'size': '45721.39'}, {'price': '0.8', 'size': '26531'}, {'price': '0.79', 'size': '7110'}, {'price': '0.78', 'size': '10350'}, {'price': '0.77', 'size': '67'}, {'price': '0.76', 'size': '200'}, {'price': '0.75', 'size': '18329.25'}, {'price': '0.74', 'size': '11370.7'}, {'price': '0.73', 'size': '5020.1'}, {'price': '0.72', 'size': '380.52'}, {'price': '0.71', 'size': '15073.2'}, {'price': '0.7', 'size': '5570.1'}, {'price': '0.69', 'size': '6088.6'}, {'price': '0.68', 'size': '2131.34'}, {'price': '0.67', 'size': '3010.1'}, {'price': '0.66', 'size': '510.1'}, {'price': '0.65', 'size': '5010.1'}, {'price': '0.64', 'size': '1630.1'}, {'price': '0.63', 'size': '210.1'}, {'price': '0.62', 'size': '300.1'}, {'price': '0.61', 'size': '111.06'}, {'price': '0.6', 'size': '67.85'}, {'price': '0.59', 'size': '3061.65'}, {'price': '0.58', 'size': '188.1'}, {'price': '0.57', 'size': '380.1'}, {'price': '0.56', 'size': '1110.1'}, {'price': '0.55', 'size': '2714.39'}, {'price': '0.54', 'size': '160'}, {'price': '0.53', 'size': '925.01'}], 'asset_id': '114416409796971863099144323163249651172534872992222856507897414949637892047507', 'bids': [{'price': '0.01', 'size': '2850.27'}, {'price': '0.02', 'size': '500'}, {'price': '0.03', 'size': '500'}, {'price': '0.04', 'size': '300'}, {'price': '0.05', 'size': '320'}, {'price': '0.06', 'size': '300'}, {'price': '0.08', 'size': '250'}, {'price': '0.09', 'size': '300'}, {'price': '0.1', 'size': '205'}, {'price': '0.11', 'size': '5454'}, {'price': '0.12', 'size': '200'}, {'price': '0.13', 'size': '426.92'}, {'price': '0.14', 'size': '15'}, {'price': '0.15', 'size': '110'}, {'price': '0.16', 'size': '4709.51'}, {'price': '0.18', 'size': '19.13'}, {'price': '0.19', 'size': '120'}, {'price': '0.2', 'size': '691.17'}, {'price': '0.24', 'size': '5027'}, {'price': '0.25', 'size': '86.66'}, {'price': '0.27', 'size': '215.25'}, {'price': '0.29', 'size': '1102.28'}, {'price': '0.31', 'size': '1130.65'}, {'price': '0.32', 'size': '200'}, {'price': '0.33', 'size': '4620'}, {'price': '0.35', 'size': '232'}, {'price': '0.39', 'size': '3010.5'}, {'price': '0.4', 'size': '3135'}, {'price': '0.41', 'size': '20'}, {'price': '0.42', 'size': '50'}, {'price': '0.43', 'size': '50'}, {'price': '0.44', 'size': '3660'}, {'price': '0.45', 'size': '3478'}, {'price': '0.47', 'size': '50'}, {'price': '0.48', 'size': '2092.18'}, {'price': '0.49', 'size': '1340'}, {'price': '0.5', 'size': '515'}, {'price': '0.51', 'size': '2086.18'}, {'price': '0.52', 'size': '15'}], 'event_type': 'book', 'hash': '222bbb76077c5588763f7fa0268b884ca1c89951', 'market': '0x7aa4a910b31b2c4ddb09d1e3408e52aa8e09a14402f376070a44b1b85cb36d13', 'timestamp': '1733332531152'}
{'asset_id': '114416409796971863099144323163249651172534872992222856507897414949637892047507', 'changes': [{'price': '0.59', 'side': 'SELL', 'size': '5561.65'}, {'price': '0.47', 'side': 'BUY', 'size': '2050'}, {'price': '0.58', 'side': 'SELL', 'size': '2188.1'}, {'price': '0.57', 'side': 'SELL', 'size': '1880.1'}], 'event_type': 'price_change', 'hash': '02ab05a60172d7da84843af40b88e4989d1e31d3', 'market': '0x7aa4a910b31b2c4ddb09d1e3408e52aa8e09a14402f376070a44b1b85cb36d13', 'timestamp': '1733332534247'}
{'asset_id': '114416409796971863099144323163249651172534872992222856507897414949637892047507', 'changes': [{'price': '0.59', 'side': 'SELL', 'size': '5561.65'}, {'price': '0.47', 'side': 'BUY', 'size': '2050'}, {'price': '0.58', 'side': 'SELL', 'size': '2188.1'}, {'price': '0.57', 'side': 'SELL', 'size': '1880.1'}], 'event_type': 'price_change', 'hash': '02ab05a60172d7da84843af40b88e4989d1e31d3', 'market': '0x7aa4a910b31b2c4ddb09d1e3408e52aa8e09a14402f376070a44b1b85cb36d13', 'timestamp': '1733332534247'}
{'asset_id': '114416409796971863099144323163249651172534872992222856507897414949637892047507', 'changes': [{'price': '0.57', 'side': 'SELL', 'size': '1610.1'}, {'price': '0.48', 'side': 'BUY', 'size': '1842.18'}], 'event_type': 'price_change', 'hash': 'c53c46e694355010f3c688c3eddb4f2fc0bc7e58', 'market': '0x7aa4a910b31b2c4ddb09d1e3408e52aa8e09a14402f376070a44b1b85cb36d13', 'timestamp': '1733332551941'}
{'asset_id': '114416409796971863099144323163249651172534872992222856507897414949637892047507', 'changes': [{'price': '0.57', 'side': 'SELL', 'size': '1610.1'}, {'price': '0.48', 'side': 'BUY', 'size': '1842.18'}], 'event_type': 'price_change', 'hash': 'c53c46e694355010f3c688c3eddb4f2fc0bc7e58', 'market': '0x7aa4a910b31b2c4ddb09d1e3408e52aa8e09a14402f376070a44b1b85cb36d13', 'timestamp': '1733332551941'}
{'asset_id': '114416409796971863099144323163249651172534872992222856507897414949637892047507', 'changes': [{'price': '0.56', 'side': 'SELL', 'size': '1350.1'}], 'event_type': 'price_change', 'hash': 'a81ba279e6c31f38f31473a4cf13161d32860284', 'market': '0x7aa4a910b31b2c4ddb09d1e3408e52aa8e09a14402f376070a44b1b85cb36d13', 'timestamp': '1733332552206'}
{'asset_id': '114416409796971863099144323163249651172534872992222856507897414949637892047507', 'changes': [{'price': '0.56', 'side': 'SELL', 'size': '1350.1'}], 'event_type': 'price_change', 'hash': 'a81ba279e6c31f38f31473a4cf13161d32860284', 'market': '0x7aa4a910b31b2c4ddb09d1e3408e52aa8e09a14402f376070a44b1b85cb36d13', 'timestamp': '1733332552206'}
{'asset_id': '114416409796971863099144323163249651172534872992222856507897414949637892047507', 'changes': [{'price': '0.48', 'side': 'BUY', 'size': '2072.18'}], 'event_type': 'price_change', 'hash': '4faf40dbfc54120e767794b06ea0830acefdb5fb', 'market': '0x7aa4a910b31b2c4ddb09d1e3408e52aa8e09a14402f376070a44b1b85cb36d13', 'timestamp': '1733332552472'}
{'asset_id': '114416409796971863099144323163249651172534872992222856507897414949637892047507', 'changes': [{'price': '0.48', 'side': 'BUY', 'size': '2072.18'}], 'event_type': 'price_change', 'hash': '4faf40dbfc54120e767794b06ea0830acefdb5fb', 'market': '0x7aa4a910b31b2c4ddb09d1e3408e52aa8e09a14402f376070a44b1b85cb36d13', 'timestamp': '1733332552472'}
{'asset_id': '114416409796971863099144323163249651172534872992222856507897414949637892047507', 'changes': [{'price': '0.59', 'side': 'SELL', 'size': '5510'}], 'event_type': 'price_change', 'hash': 'd0804b085c81f793ea307e3f07d9420dddd01112', 'market': '0x7aa4a910b31b2c4ddb09d1e3408e52aa8e09a14402f376070a44b1b85cb36d13', 'timestamp': '1733332558041'}
{'asset_id': '114416409796971863099144323163249651172534872992222856507897414949637892047507', 'changes': [{'price': '0.59', 'side': 'SELL', 'size': '5510'}], 'event_type': 'price_change', 'hash': 'd0804b085c81f793ea307e3f07d9420dddd01112', 'market': '0x7aa4a910b31b2c4ddb09d1e3408e52aa8e09a14402f376070a44b1b85cb36d13', 'timestamp': '1733332558041'}
{'asset_id': '114416409796971863099144323163249651172534872992222856507897414949637892047507', 'changes': [{'price': '0.57', 'side': 'SELL', 'size': '1661.75'}], 'event_type': 'price_change', 'hash': 'a5ac52a3ffadd46adc3215f72e77f2f1ccffb9b1', 'market': '0x7aa4a910b31b2c4ddb09d1e3408e52aa8e09a14402f376070a44b1b85cb36d13', 'timestamp': '1733332558707'}
{'asset_id': '114416409796971863099144323163249651172534872992222856507897414949637892047507', 'changes': [{'price': '0.57', 'side': 'SELL', 'size': '1661.75'}], 'event_type': 'price_change', 'hash': 'a5ac52a3ffadd46adc3215f72e77f2f1ccffb9b1', 'market': '0x7aa4a910b31b2c4ddb09d1e3408e52aa8e09a14402f376070a44b1b85cb36d13', 'timestamp': '1733332558707'}
{'asset_id': '114416409796971863099144323163249651172534872992222856507897414949637892047507', 'changes': [{'price': '0.54', 'side': 'SELL', 'size': '60'}], 'event_type': 'price_change', 'hash': '3e573382f48ce7a94b334435029443e1c9a5928d', 'market': '0x7aa4a910b31b2c4ddb09d1e3408e52aa8e09a14402f376070a44b1b85cb36d13', 'timestamp': '1733332571902'}
{'asset_id': '114416409796971863099144323163249651172534872992222856507897414949637892047507', 'changes': [{'price': '0.54', 'side': 'SELL', 'size': '60'}], 'event_type': 'price_change', 'hash': '3e573382f48ce7a94b334435029443e1c9a5928d', 'market': '0x7aa4a910b31b2c4ddb09d1e3408e52aa8e09a14402f376070a44b1b85cb36d13', 'timestamp': '1733332571902'}
{'asset_id': '114416409796971863099144323163249651172534872992222856507897414949637892047507', 'changes': [{'price': '0.55', 'side': 'SELL', 'size': '2814.39'}], 'event_type': 'price_change', 'hash': '7f68f8dd4b33f413d009c4c489d162c00bb3f904', 'market': '0x7aa4a910b31b2c4ddb09d1e3408e52aa8e09a14402f376070a44b1b85cb36d13', 'timestamp': '1733332572804'}
{'asset_id': '114416409796971863099144323163249651172534872992222856507897414949637892047507', 'changes': [{'price': '0.55', 'side': 'SELL', 'size': '2714.39'}], 'event_type': 'price_change', 'hash': '999496c3a364afd5da56537e3256bb37d8c24555', 'market': '0x7aa4a910b31b2c4ddb09d1e3408e52aa8e09a14402f376070a44b1b85cb36d13', 'timestamp': '1733332573542'}
{'asset_id': '114416409796971863099144323163249651172534872992222856507897414949637892047507', 'changes': [{'price': '0.55', 'side': 'SELL', 'size': '2714.39'}], 'event_type': 'price_change', 'hash': '999496c3a364afd5da56537e3256bb37d8c24555', 'market': '0x7aa4a910b31b2c4ddb09d1e3408e52aa8e09a14402f376070a44b1b85cb36d13', 'timestamp': '1733332573542'}
{'asset_id': '114416409796971863099144323163249651172534872992222856507897414949637892047507', 'changes': [{'price': '0.54', 'side': 'SELL', 'size': '160'}], 'event_type': 'price_change', 'hash': 'e07f9741e026b5b62bcea3d89332e477fe9da999', 'market': '0x7aa4a910b31b2c4ddb09d1e3408e52aa8e09a14402f376070a44b1b85cb36d13', 'timestamp': '1733332574455'}
{'asset_id': '114416409796971863099144323163249651172534872992222856507897414949637892047507', 'changes': [{'price': '0.54', 'side': 'SELL', 'size': '160'}], 'event_type': 'price_change', 'hash': 'e07f9741e026b5b62bcea3d89332e477fe9da999', 'market': '0x7aa4a910b31b2c4ddb09d1e3408e52aa8e09a14402f376070a44b1b85cb36d13', 'timestamp': '1733332574455'}
{'asset_id': '114416409796971863099144323163249651172534872992222856507897414949637892047507', 'changes': [{'price': '0.45', 'side': 'BUY', 'size': '2978'}, {'price': '0.51', 'side': 'BUY', 'size': '1086.18'}, {'price': '0.55', 'side': 'SELL', 'size': '2214.39'}], 'event_type': 'price_change', 'hash': '15aa70bc4954f0a927551c2405da6d51a4eb9638', 'market': '0x7aa4a910b31b2c4ddb09d1e3408e52aa8e09a14402f376070a44b1b85cb36d13', 'timestamp': '1733332574555'}
{'asset_id': '114416409796971863099144323163249651172534872992222856507897414949637892047507', 'changes': [{'price': '0.45', 'side': 'BUY', 'size': '2978'}, {'price': '0.51', 'side': 'BUY', 'size': '1086.18'}, {'price': '0.55', 'side': 'SELL', 'size': '2214.39'}], 'event_type': 'price_change', 'hash': '15aa70bc4954f0a927551c2405da6d51a4eb9638', 'market': '0x7aa4a910b31b2c4ddb09d1e3408e52aa8e09a14402f376070a44b1b85cb36d13', 'timestamp': '1733332574555'}
{'asset_id': '114416409796971863099144323163249651172534872992222856507897414949637892047507', 'changes': [{'price': '0.54', 'side': 'SELL', 'size': '60'}], 'event_type': 'price_change', 'hash': 'aa63ca1ebe13d453aadf54bcdac6205348f1d1fa', 'market': '0x7aa4a910b31b2c4ddb09d1e3408e52aa8e09a14402f376070a44b1b85cb36d13', 'timestamp': '1733332575220'}
{'asset_id': '114416409796971863099144323163249651172534872992222856507897414949637892047507', 'changes': [{'price': '0.54', 'side': 'SELL', 'size': '60'}], 'event_type': 'price_change', 'hash': 'aa63ca1ebe13d453aadf54bcdac6205348f1d1fa', 'market': '0x7aa4a910b31b2c4ddb09d1e3408e52aa8e09a14402f376070a44b1b85cb36d13', 'timestamp': '1733332575220'}
{'asset_id': '114416409796971863099144323163249651172534872992222856507897414949637892047507', 'changes': [{'price': '0.46', 'side': 'BUY', 'size': '500'}], 'event_type': 'price_change', 'hash': 'd61b59e3c6a4e32d695d6a68f40e38732590137c', 'market': '0x7aa4a910b31b2c4ddb09d1e3408e52aa8e09a14402f376070a44b1b85cb36d13', 'timestamp': '1733332575585'}
{'asset_id': '114416409796971863099144323163249651172534872992222856507897414949637892047507', 'changes': [{'price': '0.46', 'side': 'BUY', 'size': '500'}], 'event_type': 'price_change', 'hash': 'd61b59e3c6a4e32d695d6a68f40e38732590137c', 'market': '0x7aa4a910b31b2c4ddb09d1e3408e52aa8e09a14402f376070a44b1b85cb36d13', 'timestamp': '1733332575585'}
{'asset_id': '114416409796971863099144323163249651172534872992222856507897414949637892047507', 'changes': [{'price': '0.56', 'side': 'SELL', 'size': '1850.1'}], 'event_type': 'price_change', 'hash': 'e7e3f2a3c09c8bb08428b5ea95c9259c71841c9c', 'market': '0x7aa4a910b31b2c4ddb09d1e3408e52aa8e09a14402f376070a44b1b85cb36d13', 'timestamp': '1733332575963'}
{'asset_id': '114416409796971863099144323163249651172534872992222856507897414949637892047507', 'changes': [{'price': '0.56', 'side': 'SELL', 'size': '1850.1'}], 'event_type': 'price_change', 'hash': 'e7e3f2a3c09c8bb08428b5ea95c9259c71841c9c', 'market': '0x7aa4a910b31b2c4ddb09d1e3408e52aa8e09a14402f376070a44b1b85cb36d13', 'timestamp': '1733332575963'}
{'asset_id': '114416409796971863099144323163249651172534872992222856507897414949637892047507', 'changes': [{'price': '0.55', 'side': 'SELL', 'size': '2314.39'}, {'price': '0.51', 'side': 'BUY', 'size': '2086.18'}], 'event_type': 'price_change', 'hash': 'ab58d13490c7413b11b887e94a14e9e307e73272', 'market': '0x7aa4a910b31b2c4ddb09d1e3408e52aa8e09a14402f376070a44b1b85cb36d13', 'timestamp': '1733332576332'}
{'asset_id': '114416409796971863099144323163249651172534872992222856507897414949637892047507', 'changes': [{'price': '0.55', 'side': 'SELL', 'size': '2314.39'}, {'price': '0.51', 'side': 'BUY', 'size': '2086.18'}], 'event_type': 'price_change', 'hash': 'ab58d13490c7413b11b887e94a14e9e307e73272', 'market': '0x7aa4a910b31b2c4ddb09d1e3408e52aa8e09a14402f376070a44b1b85cb36d13', 'timestamp': '1733332576332'}
{'asset_id': '114416409796971863099144323163249651172534872992222856507897414949637892047507', 'changes': [{'price': '0.52', 'side': 'BUY', 'size': '215'}], 'event_type': 'price_change', 'hash': 'de81fe22d2de6f8e2bcdc1548726cd649cc3c652', 'market': '0x7aa4a910b31b2c4ddb09d1e3408e52aa8e09a14402f376070a44b1b85cb36d13', 'timestamp': '1733332577248'}
{'asset_id': '114416409796971863099144323163249651172534872992222856507897414949637892047507', 'changes': [{'price': '0.52', 'side': 'BUY', 'size': '215'}], 'event_type': 'price_change', 'hash': 'de81fe22d2de6f8e2bcdc1548726cd649cc3c652', 'market': '0x7aa4a910b31b2c4ddb09d1e3408e52aa8e09a14402f376070a44b1b85cb36d13', 'timestamp': '1733332577248'}
{'asset_id': '114416409796971863099144323163249651172534872992222856507897414949637892047507', 'changes': [{'price': '0.48', 'side': 'BUY', 'size': '572.18'}, {'price': '0.49', 'side': 'BUY', 'size': '140'}, {'price': '0.39', 'side': 'BUY', 'size': '10.5'}], 'event_type': 'price_change', 'hash': '168e1315f34410981b70b2ac3cfc659c7f4258ed', 'market': '0x7aa4a910b31b2c4ddb09d1e3408e52aa8e09a14402f376070a44b1b85cb36d13', 'timestamp': '1733332577464'}
{'asset_id': '114416409796971863099144323163249651172534872992222856507897414949637892047507', 'changes': [{'price': '0.48', 'side': 'BUY', 'size': '572.18'}, {'price': '0.49', 'side': 'BUY', 'size': '140'}, {'price': '0.39', 'side': 'BUY', 'size': '10.5'}], 'event_type': 'price_change', 'hash': '168e1315f34410981b70b2ac3cfc659c7f4258ed', 'market': '0x7aa4a910b31b2c4ddb09d1e3408e52aa8e09a14402f376070a44b1b85cb36d13', 'timestamp': '1733332577464'}
{'asset_id': '114416409796971863099144323163249651172534872992222856507897414949637892047507', 'changes': [{'price': '0.55', 'side': 'SELL', 'size': '2214.39'}], 'event_type': 'price_change', 'hash': '0974fa319de80c0b92c00eb746f03c27318b2834', 'market': '0x7aa4a910b31b2c4ddb09d1e3408e52aa8e09a14402f376070a44b1b85cb36d13', 'timestamp': '1733332579353'}
{'asset_id': '114416409796971863099144323163249651172534872992222856507897414949637892047507', 'changes': [{'price': '0.55', 'side': 'SELL', 'size': '2214.39'}], 'event_type': 'price_change', 'hash': '0974fa319de80c0b92c00eb746f03c27318b2834', 'market': '0x7aa4a910b31b2c4ddb09d1e3408e52aa8e09a14402f376070a44b1b85cb36d13', 'timestamp': '1733332579353'}
{'asset_id': '114416409796971863099144323163249651172534872992222856507897414949637892047507', 'changes': [{'price': '0.54', 'side': 'SELL', 'size': '160'}], 'event_type': 'price_change', 'hash': '80070858eb93c5f31c3912f12b5dc98805157aff', 'market': '0x7aa4a910b31b2c4ddb09d1e3408e52aa8e09a14402f376070a44b1b85cb36d13', 'timestamp': '1733332580226'}
{'asset_id': '114416409796971863099144323163249651172534872992222856507897414949637892047507', 'changes': [{'price': '0.54', 'side': 'SELL', 'size': '160'}], 'event_type': 'price_change', 'hash': '80070858eb93c5f31c3912f12b5dc98805157aff', 'market': '0x7aa4a910b31b2c4ddb09d1e3408e52aa8e09a14402f376070a44b1b85cb36d13', 'timestamp': '1733332580226'}
{'asset_id': '114416409796971863099144323163249651172534872992222856507897414949637892047507', 'changes': [{'price': '0.56', 'side': 'SELL', 'size': '1610.1'}, {'price': '0.48', 'side': 'BUY', 'size': '342.18'}], 'event_type': 'price_change', 'hash': '87a687c754146d7be2466b385a0e89f0a0024b19', 'market': '0x7aa4a910b31b2c4ddb09d1e3408e52aa8e09a14402f376070a44b1b85cb36d13', 'timestamp': '1733332584127'}
{'asset_id': '114416409796971863099144323163249651172534872992222856507897414949637892047507', 'changes': [{'price': '0.56', 'side': 'SELL', 'size': '1610.1'}, {'price': '0.48', 'side': 'BUY', 'size': '342.18'}], 'event_type': 'price_change', 'hash': '87a687c754146d7be2466b385a0e89f0a0024b19', 'market': '0x7aa4a910b31b2c4ddb09d1e3408e52aa8e09a14402f376070a44b1b85cb36d13', 'timestamp': '1733332584127'}
{'asset_id': '114416409796971863099144323163249651172534872992222856507897414949637892047507', 'changes': [{'price': '0.48', 'side': 'BUY', 'size': '592.18'}, {'price': '0.57', 'side': 'SELL', 'size': '1931.75'}], 'event_type': 'price_change', 'hash': '2c7af2604cfe39e1a75b1e40f42356a74f3afc2c', 'market': '0x7aa4a910b31b2c4ddb09d1e3408e52aa8e09a14402f376070a44b1b85cb36d13', 'timestamp': '1733332584445'}
{'asset_id': '114416409796971863099144323163249651172534872992222856507897414949637892047507', 'changes': [{'price': '0.5', 'side': 'BUY', 'size': '1715'}], 'event_type': 'price_change', 'hash': '14a043aa82f5cc37024556a7efef490021fbcb77', 'market': '0x7aa4a910b31b2c4ddb09d1e3408e52aa8e09a14402f376070a44b1b85cb36d13', 'timestamp': '1733332584955'}
{'asset_id': '114416409796971863099144323163249651172534872992222856507897414949637892047507', 'changes': [{'price': '0.5', 'side': 'BUY', 'size': '1715'}], 'event_type': 'price_change', 'hash': '14a043aa82f5cc37024556a7efef490021fbcb77', 'market': '0x7aa4a910b31b2c4ddb09d1e3408e52aa8e09a14402f376070a44b1b85cb36d13', 'timestamp': '1733332584955'}
{'asset_id': '114416409796971863099144323163249651172534872992222856507897414949637892047507', 'changes': [{'price': '0.42', 'side': 'BUY', 'size': '3050'}, {'price': '0.49', 'side': 'BUY', 'size': '1640'}], 'event_type': 'price_change', 'hash': '8fac4b42ac94d32972eb787c94545d36daee528d', 'market': '0x7aa4a910b31b2c4ddb09d1e3408e52aa8e09a14402f376070a44b1b85cb36d13', 'timestamp': '1733332584973'}
{'asset_id': '114416409796971863099144323163249651172534872992222856507897414949637892047507', 'changes': [{'price': '0.42', 'side': 'BUY', 'size': '3050'}, {'price': '0.49', 'side': 'BUY', 'size': '1640'}], 'event_type': 'price_change', 'hash': '8fac4b42ac94d32972eb787c94545d36daee528d', 'market': '0x7aa4a910b31b2c4ddb09d1e3408e52aa8e09a14402f376070a44b1b85cb36d13', 'timestamp': '1733332584973'}
{'asset_id': '114416409796971863099144323163249651172534872992222856507897414949637892047507', 'changes': [{'price': '0.51', 'side': 'BUY', 'size': '1086.18'}, {'price': '0.56', 'side': 'SELL', 'size': '1110.1'}], 'event_type': 'price_change', 'hash': '08691524655797daf3c25d523cc6b35b62fa59a7', 'market': '0x7aa4a910b31b2c4ddb09d1e3408e52aa8e09a14402f376070a44b1b85cb36d13', 'timestamp': '1733332586663'}
{'asset_id': '114416409796971863099144323163249651172534872992222856507897414949637892047507', 'changes': [{'price': '0.51', 'side': 'BUY', 'size': '1086.18'}, {'price': '0.56', 'side': 'SELL', 'size': '1110.1'}], 'event_type': 'price_change', 'hash': '08691524655797daf3c25d523cc6b35b62fa59a7', 'market': '0x7aa4a910b31b2c4ddb09d1e3408e52aa8e09a14402f376070a44b1b85cb36d13', 'timestamp': '1733332586663'}
{'asset_id': '114416409796971863099144323163249651172534872992222856507897414949637892047507', 'changes': [{'price': '0.46', 'side': 'BUY', 'size': '0'}], 'event_type': 'price_change', 'hash': '1be3d5686712293bb11fb58dd488c86cb188cc96', 'market': '0x7aa4a910b31b2c4ddb09d1e3408e52aa8e09a14402f376070a44b1b85cb36d13', 'timestamp': '1733332586672'}
{'asset_id': '114416409796971863099144323163249651172534872992222856507897414949637892047507', 'changes': [{'price': '0.46', 'side': 'BUY', 'size': '0'}], 'event_type': 'price_change', 'hash': '1be3d5686712293bb11fb58dd488c86cb188cc96', 'market': '0x7aa4a910b31b2c4ddb09d1e3408e52aa8e09a14402f376070a44b1b85cb36d13', 'timestamp': '1733332586672'}
{'asset_id': '114416409796971863099144323163249651172534872992222856507897414949637892047507', 'changes': [{'price': '0.45', 'side': 'BUY', 'size': '3478'}], 'event_type': 'price_change', 'hash': 'd87fa1a0f41f0a0125a958cbe05c23615b90590e', 'market': '0x7aa4a910b31b2c4ddb09d1e3408e52aa8e09a14402f376070a44b1b85cb36d13', 'timestamp': '1733332587730'}
{'asset_id': '114416409796971863099144323163249651172534872992222856507897414949637892047507', 'changes': [{'price': '0.45', 'side': 'BUY', 'size': '3478'}], 'event_type': 'price_change', 'hash': 'd87fa1a0f41f0a0125a958cbe05c23615b90590e', 'market': '0x7aa4a910b31b2c4ddb09d1e3408e52aa8e09a14402f376070a44b1b85cb36d13', 'timestamp': '1733332587730'}
{'asset_id': '114416409796971863099144323163249651172534872992222856507897414949637892047507', 'changes': [{'price': '0.56', 'side': 'SELL', 'size': '1610.1'}], 'event_type': 'price_change', 'hash': '069304d6b9bf564dacb5f0bbc2bf1d1fe55eb36c', 'market': '0x7aa4a910b31b2c4ddb09d1e3408e52aa8e09a14402f376070a44b1b85cb36d13', 'timestamp': '1733332588094'}
{'asset_id': '114416409796971863099144323163249651172534872992222856507897414949637892047507', 'changes': [{'price': '0.56', 'side': 'SELL', 'size': '1610.1'}], 'event_type': 'price_change', 'hash': '069304d6b9bf564dacb5f0bbc2bf1d1fe55eb36c', 'market': '0x7aa4a910b31b2c4ddb09d1e3408e52aa8e09a14402f376070a44b1b85cb36d13', 'timestamp': '1733332588094'}
{'asset_id': '114416409796971863099144323163249651172534872992222856507897414949637892047507', 'changes': [{'price': '0.51', 'side': 'BUY', 'size': '2086.18'}], 'event_type': 'price_change', 'hash': '8043a8439f18c527df5ff859726b023d0a783407', 'market': '0x7aa4a910b31b2c4ddb09d1e3408e52aa8e09a14402f376070a44b1b85cb36d13', 'timestamp': '1733332588463'}
{'asset_id': '114416409796971863099144323163249651172534872992222856507897414949637892047507', 'changes': [{'price': '0.51', 'side': 'BUY', 'size': '2086.18'}], 'event_type': 'price_change', 'hash': '8043a8439f18c527df5ff859726b023d0a783407', 'market': '0x7aa4a910b31b2c4ddb09d1e3408e52aa8e09a14402f376070a44b1b85cb36d13', 'timestamp': '1733332588463'}
{'asks': [{'price': '0.99', 'size': '4217.01'}, {'price': '0.98', 'size': '505'}, {'price': '0.97', 'size': '511.03'}, {'price': '0.96', 'size': '300'}, {'price': '0.95', 'size': '657.12'}, {'price': '0.94', 'size': '300'}, {'price': '0.92', 'size': '20000.45'}, {'price': '0.91', 'size': '10406.3'}, {'price': '0.9', 'size': '4587.5'}, {'price': '0.89', 'size': '13017.18'}, {'price': '0.88', 'size': '200'}, {'price': '0.87', 'size': '3229'}, {'price': '0.86', 'size': '17.1'}, {'price': '0.85', 'size': '109.68'}, {'price': '0.84', 'size': '250'}, {'price': '0.83', 'size': '100'}, {'price': '0.82', 'size': '16029'}, {'price': '0.81', 'size': '45721.39'}, {'price': '0.8', 'size': '26531'}, {'price': '0.79', 'size': '7110'}, {'price': '0.78', 'size': '10350'}, {'price': '0.77', 'size': '67'}, {'price': '0.76', 'size': '200'}, {'price': '0.75', 'size': '18329.25'}, {'price': '0.74', 'size': '11370.7'}, {'price': '0.73', 'size': '5020.1'}, {'price': '0.72', 'size': '380.52'}, {'price': '0.71', 'size': '15073.2'}, {'price': '0.7', 'size': '5570.1'}, {'price': '0.69', 'size': '6088.6'}, {'price': '0.68', 'size': '2131.34'}, {'price': '0.67', 'size': '3010.1'}, {'price': '0.66', 'size': '510.1'}, {'price': '0.65', 'size': '5010.1'}, {'price': '0.64', 'size': '1630.1'}, {'price': '0.63', 'size': '210.1'}, {'price': '0.62', 'size': '300.1'}, {'price': '0.61', 'size': '111.06'}, {'price': '0.6', 'size': '67.85'}, {'price': '0.59', 'size': '5510'}, {'price': '0.58', 'size': '2188.1'}, {'price': '0.57', 'size': '1931.75'}, {'price': '0.56', 'size': '1610.1'}, {'price': '0.55', 'size': '2214.39'}, {'price': '0.54', 'size': '160'}, {'price': '0.53', 'size': '925.01'}], 'asset_id': '114416409796971863099144323163249651172534872992222856507897414949637892047507', 'bids': [{'price': '0.01', 'size': '2850.27'}, {'price': '0.02', 'size': '500'}, {'price': '0.03', 'size': '500'}, {'price': '0.04', 'size': '300'}, {'price': '0.05', 'size': '320'}, {'price': '0.06', 'size': '300'}, {'price': '0.08', 'size': '250'}, {'price': '0.09', 'size': '300'}, {'price': '0.1', 'size': '205'}, {'price': '0.11', 'size': '5454'}, {'price': '0.12', 'size': '200'}, {'price': '0.13', 'size': '426.92'}, {'price': '0.14', 'size': '15'}, {'price': '0.15', 'size': '110'}, {'price': '0.16', 'size': '4709.51'}, {'price': '0.18', 'size': '19.13'}, {'price': '0.19', 'size': '120'}, {'price': '0.2', 'size': '691.17'}, {'price': '0.24', 'size': '5027'}, {'price': '0.25', 'size': '86.66'}, {'price': '0.27', 'size': '215.25'}, {'price': '0.29', 'size': '1102.28'}, {'price': '0.31', 'size': '1130.65'}, {'price': '0.32', 'size': '200'}, {'price': '0.33', 'size': '4620'}, {'price': '0.35', 'size': '232'}, {'price': '0.39', 'size': '10.5'}, {'price': '0.4', 'size': '3135'}, {'price': '0.41', 'size': '20'}, {'price': '0.42', 'size': '3050'}, {'price': '0.43', 'size': '50'}, {'price': '0.44', 'size': '3660'}, {'price': '0.45', 'size': '3478'}, {'price': '0.47', 'size': '2050'}, {'price': '0.48', 'size': '592.18'}, {'price': '0.49', 'size': '1640'}, {'price': '0.5', 'size': '1715'}, {'price': '0.51', 'size': '2086.18'}], 'event_type': 'book', 'hash': '30e61cde26ac9ffb5e4ea2760d7b8d51c0af6a2a', 'market': '0x7aa4a910b31b2c4ddb09d1e3408e52aa8e09a14402f376070a44b1b85cb36d13', 'timestamp': '1733332590586'}
{'asks': [{'price': '0.99', 'size': '4217.01'}, {'price': '0.98', 'size': '505'}, {'price': '0.97', 'size': '511.03'}, {'price': '0.96', 'size': '300'}, {'price': '0.95', 'size': '657.12'}, {'price': '0.94', 'size': '300'}, {'price': '0.92', 'size': '20000.45'}, {'price': '0.91', 'size': '10406.3'}, {'price': '0.9', 'size': '4587.5'}, {'price': '0.89', 'size': '13017.18'}, {'price': '0.88', 'size': '200'}, {'price': '0.87', 'size': '3229'}, {'price': '0.86', 'size': '17.1'}, {'price': '0.85', 'size': '109.68'}, {'price': '0.84', 'size': '250'}, {'price': '0.83', 'size': '100'}, {'price': '0.82', 'size': '16029'}, {'price': '0.81', 'size': '45721.39'}, {'price': '0.8', 'size': '26531'}, {'price': '0.79', 'size': '7110'}, {'price': '0.78', 'size': '10350'}, {'price': '0.77', 'size': '67'}, {'price': '0.76', 'size': '200'}, {'price': '0.75', 'size': '18329.25'}, {'price': '0.74', 'size': '11370.7'}, {'price': '0.73', 'size': '5020.1'}, {'price': '0.72', 'size': '380.52'}, {'price': '0.71', 'size': '15073.2'}, {'price': '0.7', 'size': '5570.1'}, {'price': '0.69', 'size': '6088.6'}, {'price': '0.68', 'size': '2131.34'}, {'price': '0.67', 'size': '3010.1'}, {'price': '0.66', 'size': '510.1'}, {'price': '0.65', 'size': '5010.1'}, {'price': '0.64', 'size': '1630.1'}, {'price': '0.63', 'size': '210.1'}, {'price': '0.62', 'size': '300.1'}, {'price': '0.61', 'size': '111.06'}, {'price': '0.6', 'size': '67.85'}, {'price': '0.59', 'size': '5510'}, {'price': '0.58', 'size': '2188.1'}, {'price': '0.57', 'size': '1931.75'}, {'price': '0.56', 'size': '1610.1'}, {'price': '0.55', 'size': '2214.39'}, {'price': '0.54', 'size': '160'}, {'price': '0.53', 'size': '925.01'}], 'asset_id': '114416409796971863099144323163249651172534872992222856507897414949637892047507', 'bids': [{'price': '0.01', 'size': '2850.27'}, {'price': '0.02', 'size': '500'}, {'price': '0.03', 'size': '500'}, {'price': '0.04', 'size': '300'}, {'price': '0.05', 'size': '320'}, {'price': '0.06', 'size': '300'}, {'price': '0.08', 'size': '250'}, {'price': '0.09', 'size': '300'}, {'price': '0.1', 'size': '205'}, {'price': '0.11', 'size': '5454'}, {'price': '0.12', 'size': '200'}, {'price': '0.13', 'size': '426.92'}, {'price': '0.14', 'size': '15'}, {'price': '0.15', 'size': '110'}, {'price': '0.16', 'size': '4709.51'}, {'price': '0.18', 'size': '19.13'}, {'price': '0.19', 'size': '120'}, {'price': '0.2', 'size': '691.17'}, {'price': '0.24', 'size': '5027'}, {'price': '0.25', 'size': '86.66'}, {'price': '0.27', 'size': '215.25'}, {'price': '0.29', 'size': '1102.28'}, {'price': '0.31', 'size': '1130.65'}, {'price': '0.32', 'size': '200'}, {'price': '0.33', 'size': '4620'}, {'price': '0.35', 'size': '232'}, {'price': '0.39', 'size': '10.5'}, {'price': '0.4', 'size': '3135'}, {'price': '0.41', 'size': '20'}, {'price': '0.42', 'size': '3050'}, {'price': '0.43', 'size': '50'}, {'price': '0.44', 'size': '3660'}, {'price': '0.45', 'size': '3478'}, {'price': '0.47', 'size': '2050'}, {'price': '0.48', 'size': '592.18'}, {'price': '0.49', 'size': '1640'}, {'price': '0.5', 'size': '1715'}, {'price': '0.51', 'size': '2086.18'}], 'event_type': 'book', 'hash': '30e61cde26ac9ffb5e4ea2760d7b8d51c0af6a2a', 'market': '0x7aa4a910b31b2c4ddb09d1e3408e52aa8e09a14402f376070a44b1b85cb36d13', 'timestamp': '1733332590586'}
{'asset_id': '114416409796971863099144323163249651172534872992222856507897414949637892047507', 'changes': [{'price': '0.58', 'side': 'SELL', 'size': '2138.1'}], 'event_type': 'price_change', 'hash': 'e267298a5d47888cf6fd684e8fcb133818c5c72e', 'market': '0x7aa4a910b31b2c4ddb09d1e3408e52aa8e09a14402f376070a44b1b85cb36d13', 'timestamp': '1733332599043'}
{'asset_id': '114416409796971863099144323163249651172534872992222856507897414949637892047507', 'changes': [{'price': '0.58', 'side': 'SELL', 'size': '2138.1'}], 'event_type': 'price_change', 'hash': 'e267298a5d47888cf6fd684e8fcb133818c5c72e', 'market': '0x7aa4a910b31b2c4ddb09d1e3408e52aa8e09a14402f376070a44b1b85cb36d13', 'timestamp': '1733332599043'}
{'asset_id': '114416409796971863099144323163249651172534872992222856507897414949637892047507', 'changes': [{'price': '0.51', 'side': 'BUY', 'size': '2036.18'}], 'event_type': 'price_change', 'hash': 'ff6b4963b65c20903b18941839511109fc235c54', 'market': '0x7aa4a910b31b2c4ddb09d1e3408e52aa8e09a14402f376070a44b1b85cb36d13', 'timestamp': '1733332599541'}
{'asset_id': '114416409796971863099144323163249651172534872992222856507897414949637892047507', 'changes': [{'price': '0.51', 'side': 'BUY', 'size': '2036.18'}], 'event_type': 'price_change', 'hash': 'ff6b4963b65c20903b18941839511109fc235c54', 'market': '0x7aa4a910b31b2c4ddb09d1e3408e52aa8e09a14402f376070a44b1b85cb36d13', 'timestamp': '1733332599541'}
{'asset_id': '114416409796971863099144323163249651172534872992222856507897414949637892047507', 'changes': [{'price': '0.54', 'side': 'SELL', 'size': '210'}], 'event_type': 'price_change', 'hash': 'fd36f87ec9aa25f636551f204b9770533bc41eab', 'market': '0x7aa4a910b31b2c4ddb09d1e3408e52aa8e09a14402f376070a44b1b85cb36d13', 'timestamp': '1733332599777'}
{'asset_id': '114416409796971863099144323163249651172534872992222856507897414949637892047507', 'changes': [{'price': '0.54', 'side': 'SELL', 'size': '210'}], 'event_type': 'price_change', 'hash': 'fd36f87ec9aa25f636551f204b9770533bc41eab', 'market': '0x7aa4a910b31b2c4ddb09d1e3408e52aa8e09a14402f376070a44b1b85cb36d13', 'timestamp': '1733332599777'}
{'asset_id': '114416409796971863099144323163249651172534872992222856507897414949637892047507', 'changes': [{'price': '0.47', 'side': 'BUY', 'size': '2100'}], 'event_type': 'price_change', 'hash': 'f017f6d5f02d796bc53a4df7e2f3e33b50f6df8c', 'market': '0x7aa4a910b31b2c4ddb09d1e3408e52aa8e09a14402f376070a44b1b85cb36d13', 'timestamp': '1733332600013'}
{'asset_id': '114416409796971863099144323163249651172534872992222856507897414949637892047507', 'changes': [{'price': '0.47', 'side': 'BUY', 'size': '2100'}], 'event_type': 'price_change', 'hash': 'f017f6d5f02d796bc53a4df7e2f3e33b50f6df8c', 'market': '0x7aa4a910b31b2c4ddb09d1e3408e52aa8e09a14402f376070a44b1b85cb36d13', 'timestamp': '1733332600013'}
{'asset_id': '114416409796971863099144323163249651172534872992222856507897414949637892047507', 'changes': [{'price': '0.58', 'side': 'SELL', 'size': '2088.1'}], 'event_type': 'price_change', 'hash': '2f8e13fcd2a2ff2aab0974d532c798b616915d34', 'market': '0x7aa4a910b31b2c4ddb09d1e3408e52aa8e09a14402f376070a44b1b85cb36d13', 'timestamp': '1733332600098'}
{'asset_id': '114416409796971863099144323163249651172534872992222856507897414949637892047507', 'changes': [{'price': '0.58', 'side': 'SELL', 'size': '2088.1'}], 'event_type': 'price_change', 'hash': '2f8e13fcd2a2ff2aab0974d532c798b616915d34', 'market': '0x7aa4a910b31b2c4ddb09d1e3408e52aa8e09a14402f376070a44b1b85cb36d13', 'timestamp': '1733332600098'}
{'asset_id': '114416409796971863099144323163249651172534872992222856507897414949637892047507', 'changes': [{'price': '0.51', 'side': 'BUY', 'size': '1986.18'}], 'event_type': 'price_change', 'hash': '8c1ce571b76315f5dfab375d45f5e5cad5027e3e', 'market': '0x7aa4a910b31b2c4ddb09d1e3408e52aa8e09a14402f376070a44b1b85cb36d13', 'timestamp': '1733332600574'}
{'asset_id': '114416409796971863099144323163249651172534872992222856507897414949637892047507', 'changes': [{'price': '0.51', 'side': 'BUY', 'size': '1986.18'}], 'event_type': 'price_change', 'hash': '8c1ce571b76315f5dfab375d45f5e5cad5027e3e', 'market': '0x7aa4a910b31b2c4ddb09d1e3408e52aa8e09a14402f376070a44b1b85cb36d13', 'timestamp': '1733332600574'}
{'asset_id': '114416409796971863099144323163249651172534872992222856507897414949637892047507', 'changes': [{'price': '0.54', 'side': 'SELL', 'size': '110'}], 'event_type': 'price_change', 'hash': 'd63c3b2e51d96ce1ffc7ecf69535aa312bc8f928', 'market': '0x7aa4a910b31b2c4ddb09d1e3408e52aa8e09a14402f376070a44b1b85cb36d13', 'timestamp': '1733332600645'}
{'asset_id': '114416409796971863099144323163249651172534872992222856507897414949637892047507', 'changes': [{'price': '0.54', 'side': 'SELL', 'size': '110'}], 'event_type': 'price_change', 'hash': 'd63c3b2e51d96ce1ffc7ecf69535aa312bc8f928', 'market': '0x7aa4a910b31b2c4ddb09d1e3408e52aa8e09a14402f376070a44b1b85cb36d13', 'timestamp': '1733332600645'}
{'asset_id': '114416409796971863099144323163249651172534872992222856507897414949637892047507', 'changes': [{'price': '0.54', 'side': 'SELL', 'size': '160'}], 'event_type': 'price_change', 'hash': '8d89c13b3dd6ccec12e2d3d38abf356999cf6eca', 'market': '0x7aa4a910b31b2c4ddb09d1e3408e52aa8e09a14402f376070a44b1b85cb36d13', 'timestamp': '1733332600820'}
{'asset_id': '114416409796971863099144323163249651172534872992222856507897414949637892047507', 'changes': [{'price': '0.54', 'side': 'SELL', 'size': '160'}], 'event_type': 'price_change', 'hash': '8d89c13b3dd6ccec12e2d3d38abf356999cf6eca', 'market': '0x7aa4a910b31b2c4ddb09d1e3408e52aa8e09a14402f376070a44b1b85cb36d13', 'timestamp': '1733332600820'}
{'asset_id': '114416409796971863099144323163249651172534872992222856507897414949637892047507', 'changes': [{'price': '0.6', 'side': 'SELL', 'size': '467.85'}], 'event_type': 'price_change', 'hash': '098d26aaf344ba345a59b9e77d3fb250a45a3b6c', 'market': '0x7aa4a910b31b2c4ddb09d1e3408e52aa8e09a14402f376070a44b1b85cb36d13', 'timestamp': '1733332600974'}
{'asset_id': '114416409796971863099144323163249651172534872992222856507897414949637892047507', 'changes': [{'price': '0.6', 'side': 'SELL', 'size': '467.85'}], 'event_type': 'price_change', 'hash': '098d26aaf344ba345a59b9e77d3fb250a45a3b6c', 'market': '0x7aa4a910b31b2c4ddb09d1e3408e52aa8e09a14402f376070a44b1b85cb36d13', 'timestamp': '1733332600974'}
{'asset_id': '114416409796971863099144323163249651172534872992222856507897414949637892047507', 'changes': [{'price': '0.47', 'side': 'BUY', 'size': '2150'}], 'event_type': 'price_change', 'hash': 'f458a295369908df9f447b6865bef3ec65041d40', 'market': '0x7aa4a910b31b2c4ddb09d1e3408e52aa8e09a14402f376070a44b1b85cb36d13', 'timestamp': '1733332601083'}
{'asset_id': '114416409796971863099144323163249651172534872992222856507897414949637892047507', 'changes': [{'price': '0.47', 'side': 'BUY', 'size': '2150'}], 'event_type': 'price_change', 'hash': 'f458a295369908df9f447b6865bef3ec65041d40', 'market': '0x7aa4a910b31b2c4ddb09d1e3408e52aa8e09a14402f376070a44b1b85cb36d13', 'timestamp': '1733332601083'}
{'asset_id': '114416409796971863099144323163249651172534872992222856507897414949637892047507', 'changes': [{'price': '0.55', 'side': 'SELL', 'size': '2314.39'}], 'event_type': 'price_change', 'hash': 'c69ad0dee58098d48e607c8e3f8b6f3f153b295e', 'market': '0x7aa4a910b31b2c4ddb09d1e3408e52aa8e09a14402f376070a44b1b85cb36d13', 'timestamp': '1733332601304'}
{'asset_id': '114416409796971863099144323163249651172534872992222856507897414949637892047507', 'changes': [{'price': '0.55', 'side': 'SELL', 'size': '2314.39'}], 'event_type': 'price_change', 'hash': 'c69ad0dee58098d48e607c8e3f8b6f3f153b295e', 'market': '0x7aa4a910b31b2c4ddb09d1e3408e52aa8e09a14402f376070a44b1b85cb36d13', 'timestamp': '1733332601304'}
{'asset_id': '114416409796971863099144323163249651172534872992222856507897414949637892047507', 'changes': [{'price': '0.65', 'side': 'SELL', 'size': '1010.1'}], 'event_type': 'price_change', 'hash': '52050be91fba6e1d3d2ab0025e4c5fa8a701e01c', 'market': '0x7aa4a910b31b2c4ddb09d1e3408e52aa8e09a14402f376070a44b1b85cb36d13', 'timestamp': '1733332603010'}
{'asset_id': '114416409796971863099144323163249651172534872992222856507897414949637892047507', 'changes': [{'price': '0.65', 'side': 'SELL', 'size': '1010.1'}], 'event_type': 'price_change', 'hash': '52050be91fba6e1d3d2ab0025e4c5fa8a701e01c', 'market': '0x7aa4a910b31b2c4ddb09d1e3408e52aa8e09a14402f376070a44b1b85cb36d13', 'timestamp': '1733332603010'}
{'asset_id': '114416409796971863099144323163249651172534872992222856507897414949637892047507', 'changes': [{'price': '0.64', 'side': 'SELL', 'size': '1230.1'}, {'price': '0.45', 'side': 'BUY', 'size': '2978'}], 'event_type': 'price_change', 'hash': '15adac72752c318d9af14d26b94d0fdaa641de55', 'market': '0x7aa4a910b31b2c4ddb09d1e3408e52aa8e09a14402f376070a44b1b85cb36d13', 'timestamp': '1733332605150'}
{'asset_id': '114416409796971863099144323163249651172534872992222856507897414949637892047507', 'changes': [{'price': '0.64', 'side': 'SELL', 'size': '1230.1'}, {'price': '0.45', 'side': 'BUY', 'size': '2978'}], 'event_type': 'price_change', 'hash': '15adac72752c318d9af14d26b94d0fdaa641de55', 'market': '0x7aa4a910b31b2c4ddb09d1e3408e52aa8e09a14402f376070a44b1b85cb36d13', 'timestamp': '1733332605150'}
{'asset_id': '114416409796971863099144323163249651172534872992222856507897414949637892047507', 'changes': [{'price': '0.51', 'side': 'BUY', 'size': '986.18'}, {'price': '0.56', 'side': 'SELL', 'size': '1110.1'}], 'event_type': 'price_change', 'hash': 'fe1a6072a42db17c53a348962cb0b963b1983d13', 'market': '0x7aa4a910b31b2c4ddb09d1e3408e52aa8e09a14402f376070a44b1b85cb36d13', 'timestamp': '1733332605159'}
{'asset_id': '114416409796971863099144323163249651172534872992222856507897414949637892047507', 'changes': [{'price': '0.51', 'side': 'BUY', 'size': '986.18'}, {'price': '0.56', 'side': 'SELL', 'size': '1110.1'}], 'event_type': 'price_change', 'hash': 'fe1a6072a42db17c53a348962cb0b963b1983d13', 'market': '0x7aa4a910b31b2c4ddb09d1e3408e52aa8e09a14402f376070a44b1b85cb36d13', 'timestamp': '1733332605159'}
{'asset_id': '114416409796971863099144323163249651172534872992222856507897414949637892047507', 'changes': [{'price': '0.46', 'side': 'BUY', 'size': '500'}], 'event_type': 'price_change', 'hash': '332887180085753547d620dc16df97988c8b2c78', 'market': '0x7aa4a910b31b2c4ddb09d1e3408e52aa8e09a14402f376070a44b1b85cb36d13', 'timestamp': '1733332606226'}
{'asset_id': '114416409796971863099144323163249651172534872992222856507897414949637892047507', 'changes': [{'price': '0.46', 'side': 'BUY', 'size': '500'}], 'event_type': 'price_change', 'hash': '332887180085753547d620dc16df97988c8b2c78', 'market': '0x7aa4a910b31b2c4ddb09d1e3408e52aa8e09a14402f376070a44b1b85cb36d13', 'timestamp': '1733332606226'}
{'asset_id': '114416409796971863099144323163249651172534872992222856507897414949637892047507', 'changes': [{'price': '0.56', 'side': 'SELL', 'size': '1610.1'}], 'event_type': 'price_change', 'hash': '83396b7880e74171adc8067d85c140520a70f455', 'market': '0x7aa4a910b31b2c4ddb09d1e3408e52aa8e09a14402f376070a44b1b85cb36d13', 'timestamp': '1733332606601'}
{'asset_id': '114416409796971863099144323163249651172534872992222856507897414949637892047507', 'changes': [{'price': '0.56', 'side': 'SELL', 'size': '1610.1'}], 'event_type': 'price_change', 'hash': '83396b7880e74171adc8067d85c140520a70f455', 'market': '0x7aa4a910b31b2c4ddb09d1e3408e52aa8e09a14402f376070a44b1b85cb36d13', 'timestamp': '1733332606601'}
{'asset_id': '114416409796971863099144323163249651172534872992222856507897414949637892047507', 'changes': [{'price': '0.52', 'side': 'BUY', 'size': '1000'}], 'event_type': 'price_change', 'hash': '04d96bba5b3226a87ee2babdd912b6976b7b39be', 'market': '0x7aa4a910b31b2c4ddb09d1e3408e52aa8e09a14402f376070a44b1b85cb36d13', 'timestamp': '1733332606954'}
{'asset_id': '114416409796971863099144323163249651172534872992222856507897414949637892047507', 'changes': [{'price': '0.52', 'side': 'BUY', 'size': '1000'}], 'event_type': 'price_change', 'hash': '04d96bba5b3226a87ee2babdd912b6976b7b39be', 'market': '0x7aa4a910b31b2c4ddb09d1e3408e52aa8e09a14402f376070a44b1b85cb36d13', 'timestamp': '1733332606954'}
{'asset_id': '114416409796971863099144323163249651172534872992222856507897414949637892047507', 'changes': [{'price': '0.57', 'side': 'SELL', 'size': '1661.75'}, {'price': '0.48', 'side': 'BUY', 'size': '342.18'}], 'event_type': 'price_change', 'hash': 'db01402cfec3e1deb6290cc91261faf75016661a', 'market': '0x7aa4a910b31b2c4ddb09d1e3408e52aa8e09a14402f376070a44b1b85cb36d13', 'timestamp': '1733332607732'}
{'asset_id': '114416409796971863099144323163249651172534872992222856507897414949637892047507', 'changes': [{'price': '0.57', 'side': 'SELL', 'size': '1661.75'}, {'price': '0.48', 'side': 'BUY', 'size': '342.18'}], 'event_type': 'price_change', 'hash': 'db01402cfec3e1deb6290cc91261faf75016661a', 'market': '0x7aa4a910b31b2c4ddb09d1e3408e52aa8e09a14402f376070a44b1b85cb36d13', 'timestamp': '1733332607732'}
{'asset_id': '114416409796971863099144323163249651172534872992222856507897414949637892047507', 'changes': [{'price': '0.56', 'side': 'SELL', 'size': '1850.1'}, {'price': '0.48', 'side': 'BUY', 'size': '572.18'}], 'event_type': 'price_change', 'hash': 'f07c39ca363503e202a4d2423ffa426f78fcb128', 'market': '0x7aa4a910b31b2c4ddb09d1e3408e52aa8e09a14402f376070a44b1b85cb36d13', 'timestamp': '1733332608053'}
{'asset_id': '114416409796971863099144323163249651172534872992222856507897414949637892047507', 'changes': [{'price': '0.56', 'side': 'SELL', 'size': '1850.1'}, {'price': '0.48', 'side': 'BUY', 'size': '572.18'}], 'event_type': 'price_change', 'hash': 'f07c39ca363503e202a4d2423ffa426f78fcb128', 'market': '0x7aa4a910b31b2c4ddb09d1e3408e52aa8e09a14402f376070a44b1b85cb36d13', 'timestamp': '1733332608053'}
{'asset_id': '114416409796971863099144323163249651172534872992222856507897414949637892047507', 'changes': [{'price': '0.54', 'side': 'SELL', 'size': '110'}], 'event_type': 'price_change', 'hash': 'c3f2887462dd8ce418253ccc7e25d87c4ed82b8c', 'market': '0x7aa4a910b31b2c4ddb09d1e3408e52aa8e09a14402f376070a44b1b85cb36d13', 'timestamp': '1733332609047'}
{'asset_id': '114416409796971863099144323163249651172534872992222856507897414949637892047507', 'changes': [{'price': '0.54', 'side': 'SELL', 'size': '110'}], 'event_type': 'price_change', 'hash': 'c3f2887462dd8ce418253ccc7e25d87c4ed82b8c', 'market': '0x7aa4a910b31b2c4ddb09d1e3408e52aa8e09a14402f376070a44b1b85cb36d13', 'timestamp': '1733332609047'}
{'asset_id': '114416409796971863099144323163249651172534872992222856507897414949637892047507', 'changes': [{'price': '0.61', 'side': 'SELL', 'size': '511.06'}], 'event_type': 'price_change', 'hash': 'bd2bf5795678f90196428a10da2ea02169aea6b5', 'market': '0x7aa4a910b31b2c4ddb09d1e3408e52aa8e09a14402f376070a44b1b85cb36d13', 'timestamp': '1733332609126'}
{'asset_id': '114416409796971863099144323163249651172534872992222856507897414949637892047507', 'changes': [{'price': '0.61', 'side': 'SELL', 'size': '511.06'}], 'event_type': 'price_change', 'hash': 'bd2bf5795678f90196428a10da2ea02169aea6b5', 'market': '0x7aa4a910b31b2c4ddb09d1e3408e52aa8e09a14402f376070a44b1b85cb36d13', 'timestamp': '1733332609126'}
{'asset_id': '114416409796971863099144323163249651172534872992222856507897414949637892047507', 'changes': [{'price': '0.47', 'side': 'BUY', 'size': '2100'}], 'event_type': 'price_change', 'hash': '450d665c6d76aae3947347c2fd5d09b739b13741', 'market': '0x7aa4a910b31b2c4ddb09d1e3408e52aa8e09a14402f376070a44b1b85cb36d13', 'timestamp': '1733332609527'}
{'asset_id': '114416409796971863099144323163249651172534872992222856507897414949637892047507', 'changes': [{'price': '0.47', 'side': 'BUY', 'size': '2100'}], 'event_type': 'price_change', 'hash': '450d665c6d76aae3947347c2fd5d09b739b13741', 'market': '0x7aa4a910b31b2c4ddb09d1e3408e52aa8e09a14402f376070a44b1b85cb36d13', 'timestamp': '1733332609527'}
{'asset_id': '114416409796971863099144323163249651172534872992222856507897414949637892047507', 'changes': [{'price': '0.58', 'side': 'SELL', 'size': '2138.1'}], 'event_type': 'price_change', 'hash': 'a8972cee0e4849f73caef3488df0644f19cb3285', 'market': '0x7aa4a910b31b2c4ddb09d1e3408e52aa8e09a14402f376070a44b1b85cb36d13', 'timestamp': '1733332609756'}
{'asset_id': '114416409796971863099144323163249651172534872992222856507897414949637892047507', 'changes': [{'price': '0.58', 'side': 'SELL', 'size': '2138.1'}], 'event_type': 'price_change', 'hash': 'a8972cee0e4849f73caef3488df0644f19cb3285', 'market': '0x7aa4a910b31b2c4ddb09d1e3408e52aa8e09a14402f376070a44b1b85cb36d13', 'timestamp': '1733332609756'}
{'asset_id': '114416409796971863099144323163249651172534872992222856507897414949637892047507', 'changes': [{'price': '0.51', 'side': 'BUY', 'size': '1036.18'}], 'event_type': 'price_change', 'hash': 'c6bc6a1a2c25bba8013072fa6eaac8c4844e8aec', 'market': '0x7aa4a910b31b2c4ddb09d1e3408e52aa8e09a14402f376070a44b1b85cb36d13', 'timestamp': '1733332610042'}
{'asset_id': '114416409796971863099144323163249651172534872992222856507897414949637892047507', 'changes': [{'price': '0.51', 'side': 'BUY', 'size': '1036.18'}], 'event_type': 'price_change', 'hash': 'c6bc6a1a2c25bba8013072fa6eaac8c4844e8aec', 'market': '0x7aa4a910b31b2c4ddb09d1e3408e52aa8e09a14402f376070a44b1b85cb36d13', 'timestamp': '1733332610042'}
{'asset_id': '114416409796971863099144323163249651172534872992222856507897414949637892047507', 'changes': [{'price': '0.54', 'side': 'SELL', 'size': '60'}], 'event_type': 'price_change', 'hash': '1cee2eb7052ab2a9c9641f0e8663425c9f0dcfe9', 'market': '0x7aa4a910b31b2c4ddb09d1e3408e52aa8e09a14402f376070a44b1b85cb36d13', 'timestamp': '1733332610107'}
{'asset_id': '114416409796971863099144323163249651172534872992222856507897414949637892047507', 'changes': [{'price': '0.54', 'side': 'SELL', 'size': '60'}], 'event_type': 'price_change', 'hash': '1cee2eb7052ab2a9c9641f0e8663425c9f0dcfe9', 'market': '0x7aa4a910b31b2c4ddb09d1e3408e52aa8e09a14402f376070a44b1b85cb36d13', 'timestamp': '1733332610107'}
{'asset_id': '114416409796971863099144323163249651172534872992222856507897414949637892047507', 'changes': [{'price': '0.52', 'side': 'BUY', 'size': '1010'}], 'event_type': 'price_change', 'hash': '3166850e287d46ce056e2dd8b17bdbfd8d89b4a4', 'market': '0x7aa4a910b31b2c4ddb09d1e3408e52aa8e09a14402f376070a44b1b85cb36d13', 'timestamp': '1733332610401'}
{'asset_id': '114416409796971863099144323163249651172534872992222856507897414949637892047507', 'changes': [{'price': '0.52', 'side': 'BUY', 'size': '1010'}], 'event_type': 'price_change', 'hash': '3166850e287d46ce056e2dd8b17bdbfd8d89b4a4', 'market': '0x7aa4a910b31b2c4ddb09d1e3408e52aa8e09a14402f376070a44b1b85cb36d13', 'timestamp': '1733332610401'}
{'asset_id': '114416409796971863099144323163249651172534872992222856507897414949637892047507', 'changes': [{'price': '0.47', 'side': 'BUY', 'size': '2050'}], 'event_type': 'price_change', 'hash': '057b5a9fd89dd535036f3036d226b571179ae9a0', 'market': '0x7aa4a910b31b2c4ddb09d1e3408e52aa8e09a14402f376070a44b1b85cb36d13', 'timestamp': '1733332610575'}
{'asset_id': '114416409796971863099144323163249651172534872992222856507897414949637892047507', 'changes': [{'price': '0.47', 'side': 'BUY', 'size': '2050'}], 'event_type': 'price_change', 'hash': '057b5a9fd89dd535036f3036d226b571179ae9a0', 'market': '0x7aa4a910b31b2c4ddb09d1e3408e52aa8e09a14402f376070a44b1b85cb36d13', 'timestamp': '1733332610575'}
{'asset_id': '114416409796971863099144323163249651172534872992222856507897414949637892047507', 'changes': [{'price': '0.58', 'side': 'SELL', 'size': '2188.1'}], 'event_type': 'price_change', 'hash': 'c45019979671faed7f2727a2dd0b85adf28c2294', 'market': '0x7aa4a910b31b2c4ddb09d1e3408e52aa8e09a14402f376070a44b1b85cb36d13', 'timestamp': '1733332610833'}
{'asset_id': '114416409796971863099144323163249651172534872992222856507897414949637892047507', 'changes': [{'price': '0.58', 'side': 'SELL', 'size': '2188.1'}], 'event_type': 'price_change', 'hash': 'c45019979671faed7f2727a2dd0b85adf28c2294', 'market': '0x7aa4a910b31b2c4ddb09d1e3408e52aa8e09a14402f376070a44b1b85cb36d13', 'timestamp': '1733332610833'}
{'asset_id': '114416409796971863099144323163249651172534872992222856507897414949637892047507', 'changes': [{'price': '0.47', 'side': 'BUY', 'size': '50'}], 'event_type': 'price_change', 'hash': '22de3f81a0568f293ae41ecd40aca82d52b9e5f7', 'market': '0x7aa4a910b31b2c4ddb09d1e3408e52aa8e09a14402f376070a44b1b85cb36d13', 'timestamp': '1733332610880'}
{'asset_id': '114416409796971863099144323163249651172534872992222856507897414949637892047507', 'changes': [{'price': '0.47', 'side': 'BUY', 'size': '50'}], 'event_type': 'price_change', 'hash': '22de3f81a0568f293ae41ecd40aca82d52b9e5f7', 'market': '0x7aa4a910b31b2c4ddb09d1e3408e52aa8e09a14402f376070a44b1b85cb36d13', 'timestamp': '1733332610880'}
{'asset_id': '114416409796971863099144323163249651172534872992222856507897414949637892047507', 'changes': [{'price': '0.51', 'side': 'BUY', 'size': '1086.18'}], 'event_type': 'price_change', 'hash': '380063cfd0761e1b4a3a466450d795e600a674b1', 'market': '0x7aa4a910b31b2c4ddb09d1e3408e52aa8e09a14402f376070a44b1b85cb36d13', 'timestamp': '1733332611096'}
{'asset_id': '114416409796971863099144323163249651172534872992222856507897414949637892047507', 'changes': [{'price': '0.51', 'side': 'BUY', 'size': '1086.18'}], 'event_type': 'price_change', 'hash': '380063cfd0761e1b4a3a466450d795e600a674b1', 'market': '0x7aa4a910b31b2c4ddb09d1e3408e52aa8e09a14402f376070a44b1b85cb36d13', 'timestamp': '1733332611096'}
{'asset_id': '114416409796971863099144323163249651172534872992222856507897414949637892047507', 'changes': [{'price': '0.55', 'side': 'SELL', 'size': '2214.39'}], 'event_type': 'price_change', 'hash': '45188c752e725658af96272ab9b4a92e4b6745b2', 'market': '0x7aa4a910b31b2c4ddb09d1e3408e52aa8e09a14402f376070a44b1b85cb36d13', 'timestamp': '1733332617254'}
{'asset_id': '114416409796971863099144323163249651172534872992222856507897414949637892047507', 'changes': [{'price': '0.55', 'side': 'SELL', 'size': '2214.39'}], 'event_type': 'price_change', 'hash': '45188c752e725658af96272ab9b4a92e4b6745b2', 'market': '0x7aa4a910b31b2c4ddb09d1e3408e52aa8e09a14402f376070a44b1b85cb36d13', 'timestamp': '1733332617254'}
{'asset_id': '114416409796971863099144323163249651172534872992222856507897414949637892047507', 'changes': [{'price': '0.54', 'side': 'SELL', 'size': '160'}], 'event_type': 'price_change', 'hash': '703acaca0ee999e6553035b9fe402cbe240cd2f5', 'market': '0x7aa4a910b31b2c4ddb09d1e3408e52aa8e09a14402f376070a44b1b85cb36d13', 'timestamp': '1733332618250'}
{'asset_id': '114416409796971863099144323163249651172534872992222856507897414949637892047507', 'changes': [{'price': '0.54', 'side': 'SELL', 'size': '160'}], 'event_type': 'price_change', 'hash': '703acaca0ee999e6553035b9fe402cbe240cd2f5', 'market': '0x7aa4a910b31b2c4ddb09d1e3408e52aa8e09a14402f376070a44b1b85cb36d13', 'timestamp': '1733332618250'}
{'asset_id': '114416409796971863099144323163249651172534872992222856507897414949637892047507', 'changes': [{'price': '0.56', 'side': 'SELL', 'size': '1610.1'}, {'price': '0.48', 'side': 'BUY', 'size': '342.18'}], 'event_type': 'price_change', 'hash': '5aedcabd4e08f3e79726a42a47c464d3b14d58e6', 'market': '0x7aa4a910b31b2c4ddb09d1e3408e52aa8e09a14402f376070a44b1b85cb36d13', 'timestamp': '1733332618606'}
{'asset_id': '114416409796971863099144323163249651172534872992222856507897414949637892047507', 'changes': [{'price': '0.56', 'side': 'SELL', 'size': '1610.1'}, {'price': '0.48', 'side': 'BUY', 'size': '342.18'}], 'event_type': 'price_change', 'hash': '5aedcabd4e08f3e79726a42a47c464d3b14d58e6', 'market': '0x7aa4a910b31b2c4ddb09d1e3408e52aa8e09a14402f376070a44b1b85cb36d13', 'timestamp': '1733332618606'}
{'asset_id': '114416409796971863099144323163249651172534872992222856507897414949637892047507', 'changes': [{'price': '0.48', 'side': 'BUY', 'size': '2342.18'}], 'event_type': 'price_change', 'hash': '49a5fe274817a85a098761874db82528d3204ec8', 'market': '0x7aa4a910b31b2c4ddb09d1e3408e52aa8e09a14402f376070a44b1b85cb36d13', 'timestamp': '1733332618629'}
{'asset_id': '114416409796971863099144323163249651172534872992222856507897414949637892047507', 'changes': [{'price': '0.48', 'side': 'BUY', 'size': '2342.18'}], 'event_type': 'price_change', 'hash': '49a5fe274817a85a098761874db82528d3204ec8', 'market': '0x7aa4a910b31b2c4ddb09d1e3408e52aa8e09a14402f376070a44b1b85cb36d13', 'timestamp': '1733332618629'}
{'asset_id': '114416409796971863099144323163249651172534872992222856507897414949637892047507', 'changes': [{'price': '0.66', 'side': 'SELL', 'size': '4510.1'}], 'event_type': 'price_change', 'hash': '0cf6426048e8dfbba17bbd2afc7796d2315a77c8', 'market': '0x7aa4a910b31b2c4ddb09d1e3408e52aa8e09a14402f376070a44b1b85cb36d13', 'timestamp': '1733332618730'}
{'asset_id': '114416409796971863099144323163249651172534872992222856507897414949637892047507', 'changes': [{'price': '0.66', 'side': 'SELL', 'size': '4510.1'}], 'event_type': 'price_change', 'hash': '0cf6426048e8dfbba17bbd2afc7796d2315a77c8', 'market': '0x7aa4a910b31b2c4ddb09d1e3408e52aa8e09a14402f376070a44b1b85cb36d13', 'timestamp': '1733332618730'}
{'asset_id': '114416409796971863099144323163249651172534872992222856507897414949637892047507', 'changes': [{'price': '0.57', 'side': 'SELL', 'size': '1931.75'}, {'price': '0.48', 'side': 'BUY', 'size': '2592.18'}], 'event_type': 'price_change', 'hash': '802a5b4cc805030ed92dff87e2c6070cc6cd815f', 'market': '0x7aa4a910b31b2c4ddb09d1e3408e52aa8e09a14402f376070a44b1b85cb36d13', 'timestamp': '1733332618904'}
{'asset_id': '114416409796971863099144323163249651172534872992222856507897414949637892047507', 'changes': [{'price': '0.57', 'side': 'SELL', 'size': '1931.75'}, {'price': '0.48', 'side': 'BUY', 'size': '2592.18'}], 'event_type': 'price_change', 'hash': '802a5b4cc805030ed92dff87e2c6070cc6cd815f', 'market': '0x7aa4a910b31b2c4ddb09d1e3408e52aa8e09a14402f376070a44b1b85cb36d13', 'timestamp': '1733332618904'}
{'asset_id': '114416409796971863099144323163249651172534872992222856507897414949637892047507', 'changes': [{'price': '0.55', 'side': 'SELL', 'size': '1014.39'}], 'event_type': 'price_change', 'hash': '3f754d9c2535dc2fbeaa739e4689e1f51a8cd39a', 'market': '0x7aa4a910b31b2c4ddb09d1e3408e52aa8e09a14402f376070a44b1b85cb36d13', 'timestamp': '1733332621013'}
{'asset_id': '114416409796971863099144323163249651172534872992222856507897414949637892047507', 'changes': [{'price': '0.55', 'side': 'SELL', 'size': '1014.39'}], 'event_type': 'price_change', 'hash': '3f754d9c2535dc2fbeaa739e4689e1f51a8cd39a', 'market': '0x7aa4a910b31b2c4ddb09d1e3408e52aa8e09a14402f376070a44b1b85cb36d13', 'timestamp': '1733332621013'}
{'asset_id': '114416409796971863099144323163249651172534872992222856507897414949637892047507', 'changes': [{'price': '0.24', 'side': 'BUY', 'size': '27'}], 'event_type': 'price_change', 'hash': '655792b9c591a61caf84713e3ad7a50e1fed0b59', 'market': '0x7aa4a910b31b2c4ddb09d1e3408e52aa8e09a14402f376070a44b1b85cb36d13', 'timestamp': '1733332623013'}
{'asset_id': '114416409796971863099144323163249651172534872992222856507897414949637892047507', 'changes': [{'price': '0.24', 'side': 'BUY', 'size': '27'}], 'event_type': 'price_change', 'hash': '655792b9c591a61caf84713e3ad7a50e1fed0b59', 'market': '0x7aa4a910b31b2c4ddb09d1e3408e52aa8e09a14402f376070a44b1b85cb36d13', 'timestamp': '1733332623013'}
{'asset_id': '114416409796971863099144323163249651172534872992222856507897414949637892047507', 'changes': [{'price': '0.46', 'side': 'BUY', 'size': '0'}, {'price': '0.52', 'side': 'BUY', 'size': '10'}, {'price': '0.56', 'side': 'SELL', 'size': '1110.1'}], 'event_type': 'price_change', 'hash': 'e9396669d3eab82d286a0d1b44c63b7ff27e5ac4', 'market': '0x7aa4a910b31b2c4ddb09d1e3408e52aa8e09a14402f376070a44b1b85cb36d13', 'timestamp': '1733332624162'}
{'asset_id': '114416409796971863099144323163249651172534872992222856507897414949637892047507', 'changes': [{'price': '0.46', 'side': 'BUY', 'size': '0'}, {'price': '0.52', 'side': 'BUY', 'size': '10'}, {'price': '0.56', 'side': 'SELL', 'size': '1110.1'}], 'event_type': 'price_change', 'hash': 'e9396669d3eab82d286a0d1b44c63b7ff27e5ac4', 'market': '0x7aa4a910b31b2c4ddb09d1e3408e52aa8e09a14402f376070a44b1b85cb36d13', 'timestamp': '1733332624162'}
{'asset_id': '114416409796971863099144323163249651172534872992222856507897414949637892047507', 'changes': [{'price': '0.46', 'side': 'BUY', 'size': '500'}], 'event_type': 'price_change', 'hash': '63722b78c24a48a834723c40730dae694d0d7d26', 'market': '0x7aa4a910b31b2c4ddb09d1e3408e52aa8e09a14402f376070a44b1b85cb36d13', 'timestamp': '1733332625216'}
{'asset_id': '114416409796971863099144323163249651172534872992222856507897414949637892047507', 'changes': [{'price': '0.46', 'side': 'BUY', 'size': '500'}], 'event_type': 'price_change', 'hash': '63722b78c24a48a834723c40730dae694d0d7d26', 'market': '0x7aa4a910b31b2c4ddb09d1e3408e52aa8e09a14402f376070a44b1b85cb36d13', 'timestamp': '1733332625216'}
{'asset_id': '114416409796971863099144323163249651172534872992222856507897414949637892047507', 'changes': [{'price': '0.56', 'side': 'SELL', 'size': '1610.1'}], 'event_type': 'price_change', 'hash': '2873d84863966c4aaa96018552484576a2a7fc24', 'market': '0x7aa4a910b31b2c4ddb09d1e3408e52aa8e09a14402f376070a44b1b85cb36d13', 'timestamp': '1733332625588'}
{'asset_id': '114416409796971863099144323163249651172534872992222856507897414949637892047507', 'changes': [{'price': '0.56', 'side': 'SELL', 'size': '1610.1'}], 'event_type': 'price_change', 'hash': '2873d84863966c4aaa96018552484576a2a7fc24', 'market': '0x7aa4a910b31b2c4ddb09d1e3408e52aa8e09a14402f376070a44b1b85cb36d13', 'timestamp': '1733332625588'}
{'asset_id': '114416409796971863099144323163249651172534872992222856507897414949637892047507', 'changes': [{'price': '0.51', 'side': 'BUY', 'size': '2086.18'}], 'event_type': 'price_change', 'hash': '04a011a13b88181170524d2188c83149249d4323', 'market': '0x7aa4a910b31b2c4ddb09d1e3408e52aa8e09a14402f376070a44b1b85cb36d13', 'timestamp': '1733332625952'}
{'asset_id': '114416409796971863099144323163249651172534872992222856507897414949637892047507', 'changes': [{'price': '0.51', 'side': 'BUY', 'size': '2086.18'}], 'event_type': 'price_change', 'hash': '04a011a13b88181170524d2188c83149249d4323', 'market': '0x7aa4a910b31b2c4ddb09d1e3408e52aa8e09a14402f376070a44b1b85cb36d13', 'timestamp': '1733332625952'}
{'asset_id': '114416409796971863099144323163249651172534872992222856507897414949637892047507', 'changes': [{'price': '0.24', 'side': 'BUY', 'size': '5027'}, {'price': '0.56', 'side': 'SELL', 'size': '2810.1'}], 'event_type': 'price_change', 'hash': '938f462ce4e95c50c3f44968f058c8ae8c0b9e46', 'market': '0x7aa4a910b31b2c4ddb09d1e3408e52aa8e09a14402f376070a44b1b85cb36d13', 'timestamp': '1733332626319'}
{'asset_id': '114416409796971863099144323163249651172534872992222856507897414949637892047507', 'changes': [{'price': '0.24', 'side': 'BUY', 'size': '5027'}, {'price': '0.56', 'side': 'SELL', 'size': '2810.1'}], 'event_type': 'price_change', 'hash': '938f462ce4e95c50c3f44968f058c8ae8c0b9e46', 'market': '0x7aa4a910b31b2c4ddb09d1e3408e52aa8e09a14402f376070a44b1b85cb36d13', 'timestamp': '1733332626319'}
{'asset_id': '114416409796971863099144323163249651172534872992222856507897414949637892047507', 'changes': [{'price': '0.57', 'side': 'SELL', 'size': '1661.75'}, {'price': '0.48', 'side': 'BUY', 'size': '2342.18'}], 'event_type': 'price_change', 'hash': 'cdf052a33d3ecef84b669ad5afeafff1f2fd9403', 'market': '0x7aa4a910b31b2c4ddb09d1e3408e52aa8e09a14402f376070a44b1b85cb36d13', 'timestamp': '1733332632261'}
{'asset_id': '114416409796971863099144323163249651172534872992222856507897414949637892047507', 'changes': [{'price': '0.57', 'side': 'SELL', 'size': '1661.75'}, {'price': '0.48', 'side': 'BUY', 'size': '2342.18'}], 'event_type': 'price_change', 'hash': 'cdf052a33d3ecef84b669ad5afeafff1f2fd9403', 'market': '0x7aa4a910b31b2c4ddb09d1e3408e52aa8e09a14402f376070a44b1b85cb36d13', 'timestamp': '1733332632261'}
{'asset_id': '114416409796971863099144323163249651172534872992222856507897414949637892047507', 'changes': [{'price': '0.48', 'side': 'BUY', 'size': '2572.18'}], 'event_type': 'price_change', 'hash': 'fd8138dc1c86d0174b6a9688809d06ee3cd60591', 'market': '0x7aa4a910b31b2c4ddb09d1e3408e52aa8e09a14402f376070a44b1b85cb36d13', 'timestamp': '1733332632526'}
{'asset_id': '114416409796971863099144323163249651172534872992222856507897414949637892047507', 'changes': [{'price': '0.48', 'side': 'BUY', 'size': '2572.18'}], 'event_type': 'price_change', 'hash': 'fd8138dc1c86d0174b6a9688809d06ee3cd60591', 'market': '0x7aa4a910b31b2c4ddb09d1e3408e52aa8e09a14402f376070a44b1b85cb36d13', 'timestamp': '1733332632526'}
{'asset_id': '114416409796971863099144323163249651172534872992222856507897414949637892047507', 'changes': [{'price': '0.56', 'side': 'SELL', 'size': '3050.1'}], 'event_type': 'price_change', 'hash': 'fda1dbbd10ed989aa32175a5898999d19eade6a2', 'market': '0x7aa4a910b31b2c4ddb09d1e3408e52aa8e09a14402f376070a44b1b85cb36d13', 'timestamp': '1733332632627'}
{'asset_id': '114416409796971863099144323163249651172534872992222856507897414949637892047507', 'changes': [{'price': '0.56', 'side': 'SELL', 'size': '3050.1'}], 'event_type': 'price_change', 'hash': 'fda1dbbd10ed989aa32175a5898999d19eade6a2', 'market': '0x7aa4a910b31b2c4ddb09d1e3408e52aa8e09a14402f376070a44b1b85cb36d13', 'timestamp': '1733332632627'}
{'asset_id': '114416409796971863099144323163249651172534872992222856507897414949637892047507', 'changes': [{'price': '0.5', 'side': 'BUY', 'size': '515'}, {'price': '0.56', 'side': 'SELL', 'size': '1850.1'}], 'event_type': 'price_change', 'hash': 'aa2fdf0b21ddb23275a66c499959f4a25079b83e', 'market': '0x7aa4a910b31b2c4ddb09d1e3408e52aa8e09a14402f376070a44b1b85cb36d13', 'timestamp': '1733332634898'}
{'asset_id': '114416409796971863099144323163249651172534872992222856507897414949637892047507', 'changes': [{'price': '0.5', 'side': 'BUY', 'size': '515'}, {'price': '0.56', 'side': 'SELL', 'size': '1850.1'}], 'event_type': 'price_change', 'hash': 'aa2fdf0b21ddb23275a66c499959f4a25079b83e', 'market': '0x7aa4a910b31b2c4ddb09d1e3408e52aa8e09a14402f376070a44b1b85cb36d13', 'timestamp': '1733332634898'}
{'asset_id': '114416409796971863099144323163249651172534872992222856507897414949637892047507', 'changes': [{'price': '0.55', 'side': 'SELL', 'size': '2214.39'}, {'price': '0.49', 'side': 'BUY', 'size': '2840'}], 'event_type': 'price_change', 'hash': '9ea07443d0d741ffd801b146fc5a46ed26288f0d', 'market': '0x7aa4a910b31b2c4ddb09d1e3408e52aa8e09a14402f376070a44b1b85cb36d13', 'timestamp': '1733332635235'}
{'asset_id': '114416409796971863099144323163249651172534872992222856507897414949637892047507', 'changes': [{'price': '0.55', 'side': 'SELL', 'size': '2214.39'}, {'price': '0.49', 'side': 'BUY', 'size': '2840'}], 'event_type': 'price_change', 'hash': '9ea07443d0d741ffd801b146fc5a46ed26288f0d', 'market': '0x7aa4a910b31b2c4ddb09d1e3408e52aa8e09a14402f376070a44b1b85cb36d13', 'timestamp': '1733332635235'}
{'asset_id': '114416409796971863099144323163249651172534872992222856507897414949637892047507', 'changes': [{'price': '0.46', 'side': 'BUY', 'size': '0'}, {'price': '0.56', 'side': 'SELL', 'size': '1350.1'}, {'price': '0.51', 'side': 'BUY', 'size': '1086.18'}], 'event_type': 'price_change', 'hash': 'cdcf3b6c642ca050dea0b7c4210b26febc1e00a5', 'market': '0x7aa4a910b31b2c4ddb09d1e3408e52aa8e09a14402f376070a44b1b85cb36d13', 'timestamp': '1733332636317'}
{'asset_id': '114416409796971863099144323163249651172534872992222856507897414949637892047507', 'changes': [{'price': '0.46', 'side': 'BUY', 'size': '0'}, {'price': '0.56', 'side': 'SELL', 'size': '1350.1'}, {'price': '0.51', 'side': 'BUY', 'size': '1086.18'}], 'event_type': 'price_change', 'hash': 'cdcf3b6c642ca050dea0b7c4210b26febc1e00a5', 'market': '0x7aa4a910b31b2c4ddb09d1e3408e52aa8e09a14402f376070a44b1b85cb36d13', 'timestamp': '1733332636317'}
{'asset_id': '114416409796971863099144323163249651172534872992222856507897414949637892047507', 'changes': [{'price': '0.45', 'side': 'BUY', 'size': '3478'}], 'event_type': 'price_change', 'hash': '3a9179cc309714d2d99056f7033ede5e8687a592', 'market': '0x7aa4a910b31b2c4ddb09d1e3408e52aa8e09a14402f376070a44b1b85cb36d13', 'timestamp': '1733332637382'}
{'asset_id': '114416409796971863099144323163249651172534872992222856507897414949637892047507', 'changes': [{'price': '0.45', 'side': 'BUY', 'size': '3478'}], 'event_type': 'price_change', 'hash': '3a9179cc309714d2d99056f7033ede5e8687a592', 'market': '0x7aa4a910b31b2c4ddb09d1e3408e52aa8e09a14402f376070a44b1b85cb36d13', 'timestamp': '1733332637382'}
{'asset_id': '114416409796971863099144323163249651172534872992222856507897414949637892047507', 'changes': [{'price': '0.55', 'side': 'SELL', 'size': '2714.39'}], 'event_type': 'price_change', 'hash': '94f3f1910a5f434e3ca320ba5968fab6a3714dfe', 'market': '0x7aa4a910b31b2c4ddb09d1e3408e52aa8e09a14402f376070a44b1b85cb36d13', 'timestamp': '1733332637749'}
{'asset_id': '114416409796971863099144323163249651172534872992222856507897414949637892047507', 'changes': [{'price': '0.55', 'side': 'SELL', 'size': '2714.39'}], 'event_type': 'price_change', 'hash': '94f3f1910a5f434e3ca320ba5968fab6a3714dfe', 'market': '0x7aa4a910b31b2c4ddb09d1e3408e52aa8e09a14402f376070a44b1b85cb36d13', 'timestamp': '1733332637749'}
{'asset_id': '114416409796971863099144323163249651172534872992222856507897414949637892047507', 'changes': [{'price': '0.5', 'side': 'BUY', 'size': '1515'}], 'event_type': 'price_change', 'hash': '39d3e47908606018546f4b98a031f795f6e244d0', 'market': '0x7aa4a910b31b2c4ddb09d1e3408e52aa8e09a14402f376070a44b1b85cb36d13', 'timestamp': '1733332638121'}
{'asset_id': '114416409796971863099144323163249651172534872992222856507897414949637892047507', 'changes': [{'price': '0.5', 'side': 'BUY', 'size': '1515'}], 'event_type': 'price_change', 'hash': '39d3e47908606018546f4b98a031f795f6e244d0', 'market': '0x7aa4a910b31b2c4ddb09d1e3408e52aa8e09a14402f376070a44b1b85cb36d13', 'timestamp': '1733332638121'}
{'asset_id': '114416409796971863099144323163249651172534872992222856507897414949637892047507', 'changes': [{'price': '0.57', 'side': 'SELL', 'size': '161.75'}, {'price': '0.49', 'side': 'BUY', 'size': '1340'}], 'event_type': 'price_change', 'hash': '7aa7a380c5c68b44cbaf2bc1813ad2a4cee58693', 'market': '0x7aa4a910b31b2c4ddb09d1e3408e52aa8e09a14402f376070a44b1b85cb36d13', 'timestamp': '1733332642533'}
{'asset_id': '114416409796971863099144323163249651172534872992222856507897414949637892047507', 'changes': [{'price': '0.57', 'side': 'SELL', 'size': '161.75'}, {'price': '0.49', 'side': 'BUY', 'size': '1340'}], 'event_type': 'price_change', 'hash': '7aa7a380c5c68b44cbaf2bc1813ad2a4cee58693', 'market': '0x7aa4a910b31b2c4ddb09d1e3408e52aa8e09a14402f376070a44b1b85cb36d13', 'timestamp': '1733332642533'}
{'asset_id': '114416409796971863099144323163249651172534872992222856507897414949637892047507', 'changes': [{'price': '0.56', 'side': 'SELL', 'size': '2850.1'}, {'price': '0.47', 'side': 'BUY', 'size': '1550'}], 'event_type': 'price_change', 'hash': '1afe095380e68a8c5fed6109e897a7c8487180b7', 'market': '0x7aa4a910b31b2c4ddb09d1e3408e52aa8e09a14402f376070a44b1b85cb36d13', 'timestamp': '1733332644016'}
{'asset_id': '114416409796971863099144323163249651172534872992222856507897414949637892047507', 'changes': [{'price': '0.56', 'side': 'SELL', 'size': '2850.1'}, {'price': '0.47', 'side': 'BUY', 'size': '1550'}], 'event_type': 'price_change', 'hash': '1afe095380e68a8c5fed6109e897a7c8487180b7', 'market': '0x7aa4a910b31b2c4ddb09d1e3408e52aa8e09a14402f376070a44b1b85cb36d13', 'timestamp': '1733332644016'}
{'asset_id': '114416409796971863099144323163249651172534872992222856507897414949637892047507', 'changes': [{'price': '0.45', 'side': 'BUY', 'size': '2978'}, {'price': '0.55', 'side': 'SELL', 'size': '2214.39'}, {'price': '0.5', 'side': 'BUY', 'size': '515'}], 'event_type': 'price_change', 'hash': '0cd54deb45218d07b617201ad9a4840b3721a90a', 'market': '0x7aa4a910b31b2c4ddb09d1e3408e52aa8e09a14402f376070a44b1b85cb36d13', 'timestamp': '1733332650510'}
{'asset_id': '114416409796971863099144323163249651172534872992222856507897414949637892047507', 'changes': [{'price': '0.45', 'side': 'BUY', 'size': '2978'}, {'price': '0.55', 'side': 'SELL', 'size': '2214.39'}, {'price': '0.5', 'side': 'BUY', 'size': '515'}], 'event_type': 'price_change', 'hash': '0cd54deb45218d07b617201ad9a4840b3721a90a', 'market': '0x7aa4a910b31b2c4ddb09d1e3408e52aa8e09a14402f376070a44b1b85cb36d13', 'timestamp': '1733332650510'}
{'asset_id': '114416409796971863099144323163249651172534872992222856507897414949637892047507', 'changes': [{'price': '0.44', 'side': 'BUY', 'size': '4160'}], 'event_type': 'price_change', 'hash': 'e3e026aca8913abad1a1d37773925286b4703270', 'market': '0x7aa4a910b31b2c4ddb09d1e3408e52aa8e09a14402f376070a44b1b85cb36d13', 'timestamp': '1733332651532'}
{'asset_id': '114416409796971863099144323163249651172534872992222856507897414949637892047507', 'changes': [{'price': '0.44', 'side': 'BUY', 'size': '4160'}], 'event_type': 'price_change', 'hash': 'e3e026aca8913abad1a1d37773925286b4703270', 'market': '0x7aa4a910b31b2c4ddb09d1e3408e52aa8e09a14402f376070a44b1b85cb36d13', 'timestamp': '1733332651532'}
{'asset_id': '114416409796971863099144323163249651172534872992222856507897414949637892047507', 'changes': [{'price': '0.54', 'side': 'SELL', 'size': '660'}], 'event_type': 'price_change', 'hash': '2058dd264556d73b4f9ed5a580b118ccc20d19b5', 'market': '0x7aa4a910b31b2c4ddb09d1e3408e52aa8e09a14402f376070a44b1b85cb36d13', 'timestamp': '1733332651922'}
{'asset_id': '114416409796971863099144323163249651172534872992222856507897414949637892047507', 'changes': [{'price': '0.54', 'side': 'SELL', 'size': '660'}], 'event_type': 'price_change', 'hash': '2058dd264556d73b4f9ed5a580b118ccc20d19b5', 'market': '0x7aa4a910b31b2c4ddb09d1e3408e52aa8e09a14402f376070a44b1b85cb36d13', 'timestamp': '1733332651922'}
{'asset_id': '114416409796971863099144323163249651172534872992222856507897414949637892047507', 'changes': [{'price': '0.5', 'side': 'BUY', 'size': '1515'}], 'event_type': 'price_change', 'hash': '7ffa939f67eddbffc514c554ddee2538d1ccb396', 'market': '0x7aa4a910b31b2c4ddb09d1e3408e52aa8e09a14402f376070a44b1b85cb36d13', 'timestamp': '1733332652288'}
{'asset_id': '114416409796971863099144323163249651172534872992222856507897414949637892047507', 'changes': [{'price': '0.5', 'side': 'BUY', 'size': '1515'}], 'event_type': 'price_change', 'hash': '7ffa939f67eddbffc514c554ddee2538d1ccb396', 'market': '0x7aa4a910b31b2c4ddb09d1e3408e52aa8e09a14402f376070a44b1b85cb36d13', 'timestamp': '1733332652288'}
