{'asks': [{'price': '0.99', 'size': '4217.01'}, {'price': '0.98', 'size': '505'}, {'price': '0.97', 'size': '511.03'}, {'price': '0.96', 'size': '300'}, {'price': '0.95', 'size': '657.12'}, {'price': '0.94', 'size': '300'}, {'price': '0.92', 'size': '20000.45'}, {'price': '0.91', 'size': '10406.3'}, {'price': '0.9', 'size': '4587.5'}, {'price': '0.89', 'size': '13017.18'}, {'price': '0.88', 'size': '200'}, {'price': '0.87', 'size': '3229'}, {'price': '0.86', 'size': '17.1'}, {'price': '0.85', 'size': '109.68'}, {'price': '0.84', 'size': '250'}, {'price': '0.83', 'size': '100'}, {'price': '0.82', 'size': '16029'}, {'price': '0.81', 'size': '45721.39'}, {'price': '0.8', 'size': '26531'}, {'price': '0.79', 'size': '7110'}, {'price': '0.78', 'size': '10350'}, {'price': '0.77', 'size': '67'}, {'price': '0.76', 'size': '200'}, {'price': '0.75', 'size': '18329.25'}, {'price': '0.74', 'size': '11370.7'}, {'price': '0.73', 'size': '5020.1'}, {'price': '0.72', 'size': '380.52'}, {'price': '0.71', 'size': '15073.2'}, {'price': '0.7', 'size': '5570.1'}, {'price': '0.69', 'size': '6088.6'}, {'price': '0.68', 'size': '2131.34'}, {'price': '0.67', 'size': '3010.1'}, {'price': '0.66', 'size': '4510.1'}, {'price': '0.65', 'size': '1010.1'}, {'price': '0.64', 'size': '1230.1'}, {'price': '0.63', 'size': '210.1'}, {'price': '0.62', 'size': '300.1'}, {'price': '0.61', 'size': '511.06'}, {'price': '0.6', 'size': '467.85'}, {'price': '0.59', 'size': '5510'}, {'price': '0.58', 'size': '2188.1'}, {'price': '0.57', 'size': '161.75'}, {'price': '0.56', 'size': '2850.1'}, {'price': '0.55', 'size': '2214.39'}, {'price': '0.54', 'size': '660'}, {'price': '0.53', 'size': '925.01'}], 'asset_id': '114416409796971863099144323163249651172534872992222856507897414949637892047507', 'bids': [{'price': '0.01', 'size': '2850.27'}, {'price': '0.02', 'size': '500'}, {'price': '0.03', 'size': '500'}, {'price': '0.04', 'size': '300'}, {'price': '0.05', 'size': '320'}, {'price': '0.06', 'size': '300'}, {'price': '0.08', 'size': '250'}, {'price': '0.09', 'size': '300'}, {'price': '0.1', 'size': '205'}, {'price': '0.11', 'size': '5454'}, {'price': '0.12', 'size': '200'}, {'price': '0.13', 'size': '426.92'}, {'price': '0.14', 'size': '15'}, {'price': '0.15', 'size': '110'}, {'price': '0.16', 'size': '4709.51'}, {'price': '0.18', 'size': '19.13'}, {'price': '0.19', 'size': '120'}, {'price': '0.2', 'size': '691.17'}, {'price': '0.24', 'size': '5027'}, {'price': '0.25', 'size': '86.66'}, {'price': '0.27', 'size': '215.25'}, {'price': '0.29', 'size': '1102.28'}, {'price': '0.31', 'size': '1130.65'}, {'price': '0.32', 'size': '200'}, {'price': '0.33', 'size': '4620'}, {'price': '0.35', 'size': '232'}, {'price': '0.39', 'size': '10.5'}, {'price': '0.4', 'size': '3135'}, {'price': '0.41', 'size': '20'}, {'price': '0.42', 'size': '3050'}, {'price': '0.43', 'size': '50'}, {'price': '0.44', 'size': '3660'}, {'price': '0.45', 'size': '2978'}, {'price': '0.47', 'size': '1550'}, {'price': '0.48', 'size': '2572.18'}, {'price': '0.49', 'size': '1340'}, {'price': '0.5', 'size': '1515'}, {'price': '0.51', 'size': '1086.18'}], 'event_type': 'book', 'hash': '5aed9694bb79e3e47a0b5f3da5d669f512d3c6b0', 'market': '0x7aa4a910b31b2c4ddb09d1e3408e52aa8e09a14402f376070a44b1b85cb36d13', 'timestamp': '1733332658628'}
{'asks': [{'price': '0.99', 'size': '4217.01'}, {'price': '0.98', 'size': '505'}, {'price': '0.97', 'size': '511.03'}, {'price': '0.96', 'size': '300'}, {'price': '0.95', 'size': '657.12'}, {'price': '0.94', 'size': '300'}, {'price': '0.92', 'size': '20000.45'}, {'price': '0.91', 'size': '10406.3'}, {'price': '0.9', 'size': '4587.5'}, {'price': '0.89', 'size': '13017.18'}, {'price': '0.88', 'size': '200'}, {'price': '0.87', 'size': '3229'}, {'price': '0.86', 'size': '17.1'}, {'price': '0.85', 'size': '109.68'}, {'price': '0.84', 'size': '250'}, {'price': '0.83', 'size': '100'}, {'price': '0.82', 'size': '16029'}, {'price': '0.81', 'size': '45721.39'}, {'price': '0.8', 'size': '26531'}, {'price': '0.79', 'size': '7110'}, {'price': '0.78', 'size': '10350'}, {'price': '0.77', 'size': '67'}, {'price': '0.76', 'size': '200'}, {'price': '0.75', 'size': '18329.25'}, {'price': '0.74', 'size': '11370.7'}, {'price': '0.73', 'size': '5020.1'}, {'price': '0.72', 'size': '380.52'}, {'price': '0.71', 'size': '15073.2'}, {'price': '0.7', 'size': '5570.1'}, {'price': '0.69', 'size': '6088.6'}, {'price': '0.68', 'size': '2131.34'}, {'price': '0.67', 'size': '3010.1'}, {'price': '0.66', 'size': '4510.1'}, {'price': '0.65', 'size': '1010.1'}, {'price': '0.64', 'size': '1230.1'}, {'price': '0.63', 'size': '210.1'}, {'price': '0.62', 'size': '300.1'}, {'price': '0.61', 'size': '511.06'}, {'price': '0.6', 'size': '467.85'}, {'price': '0.59', 'size': '5510'}, {'price': '0.58', 'size': '2188.1'}, {'price': '0.57', 'size': '161.75'}, {'price': '0.56', 'size': '2850.1'}, {'price': '0.55', 'size': '2214.39'}, {'price': '0.54', 'size': '660'}, {'price': '0.53', 'size': '925.01'}], 'asset_id': '114416409796971863099144323163249651172534872992222856507897414949637892047507', 'bids': [{'price': '0.01', 'size': '2850.27'}, {'price': '0.02', 'size': '500'}, {'price': '0.03', 'size': '500'}, {'price': '0.04', 'size': '300'}, {'price': '0.05', 'size': '320'}, {'price': '0.06', 'size': '300'}, {'price': '0.08', 'size': '250'}, {'price': '0.09', 'size': '300'}, {'price': '0.1', 'size': '205'}, {'price': '0.11', 'size': '5454'}, {'price': '0.12', 'size': '200'}, {'price': '0.13', 'size': '426.92'}, {'price': '0.14', 'size': '15'}, {'price': '0.15', 'size': '110'}, {'price': '0.16', 'size': '4709.51'}, {'price': '0.18', 'size': '19.13'}, {'price': '0.19', 'size': '120'}, {'price': '0.2', 'size': '691.17'}, {'price': '0.24', 'size': '5027'}, {'price': '0.25', 'size': '86.66'}, {'price': '0.27', 'size': '215.25'}, {'price': '0.29', 'size': '1102.28'}, {'price': '0.31', 'size': '1130.65'}, {'price': '0.32', 'size': '200'}, {'price': '0.33', 'size': '4620'}, {'price': '0.35', 'size': '232'}, {'price': '0.39', 'size': '10.5'}, {'price': '0.4', 'size': '3135'}, {'price': '0.41', 'size': '20'}, {'price': '0.42', 'size': '3050'}, {'price': '0.43', 'size': '50'}, {'price': '0.44', 'size': '3660'}, {'price': '0.45', 'size': '2978'}, {'price': '0.47', 'size': '1550'}, {'price': '0.48', 'size': '2572.18'}, {'price': '0.49', 'size': '1340'}, {'price': '0.5', 'size': '1515'}, {'price': '0.51', 'size': '1086.18'}], 'event_type': 'book', 'hash': '5aed9694bb79e3e47a0b5f3da5d669f512d3c6b0', 'market': '0x7aa4a910b31b2c4ddb09d1e3408e52aa8e09a14402f376070a44b1b85cb36d13', 'timestamp': '1733332658628'}
{'asset_id': '114416409796971863099144323163249651172534872992222856507897414949637892047507', 'changes': [{'price': '0.44', 'side': 'BUY', 'size': '3660'}, {'price': '0.54', 'side': 'SELL', 'size': '160'}, {'price': '0.5', 'side': 'BUY', 'size': '515'}], 'event_type': 'price_change', 'hash': '5572e3970da26299a910daed9c951ca0b96705b1', 'market': '0x7aa4a910b31b2c4ddb09d1e3408e52aa8e09a14402f376070a44b1b85cb36d13', 'timestamp': '1733332658649'}
{'asset_id': '114416409796971863099144323163249651172534872992222856507897414949637892047507', 'changes': [{'price': '0.44', 'side': 'BUY', 'size': '3660'}, {'price': '0.54', 'side': 'SELL', 'size': '160'}, {'price': '0.5', 'side': 'BUY', 'size': '515'}], 'event_type': 'price_change', 'hash': '5572e3970da26299a910daed9c951ca0b96705b1', 'market': '0x7aa4a910b31b2c4ddb09d1e3408e52aa8e09a14402f376070a44b1b85cb36d13', 'timestamp': '1733332658649'}
{'asset_id': '114416409796971863099144323163249651172534872992222856507897414949637892047507', 'changes': [{'price': '0.45', 'side': 'BUY', 'size': '3478'}], 'event_type': 'price_change', 'hash': 'b09bb8411c421206543183de0761e3c651085df6', 'market': '0x7aa4a910b31b2c4ddb09d1e3408e52aa8e09a14402f376070a44b1b85cb36d13', 'timestamp': '1733332659669'}
{'asset_id': '114416409796971863099144323163249651172534872992222856507897414949637892047507', 'changes': [{'price': '0.45', 'side': 'BUY', 'size': '3478'}], 'event_type': 'price_change', 'hash': 'b09bb8411c421206543183de0761e3c651085df6', 'market': '0x7aa4a910b31b2c4ddb09d1e3408e52aa8e09a14402f376070a44b1b85cb36d13', 'timestamp': '1733332659669'}
{'asset_id': '114416409796971863099144323163249651172534872992222856507897414949637892047507', 'changes': [{'price': '0.55', 'side': 'SELL', 'size': '2714.39'}, {'price': '0.58', 'side': 'SELL', 'size': '2138.1'}], 'event_type': 'price_change', 'hash': 'ed77ca6bf2ea1c1ed339602ed2891b24288aca33', 'market': '0x7aa4a910b31b2c4ddb09d1e3408e52aa8e09a14402f376070a44b1b85cb36d13', 'timestamp': '1733332660074'}
{'asset_id': '114416409796971863099144323163249651172534872992222856507897414949637892047507', 'changes': [{'price': '0.55', 'side': 'SELL', 'size': '2714.39'}, {'price': '0.58', 'side': 'SELL', 'size': '2138.1'}], 'event_type': 'price_change', 'hash': 'ed77ca6bf2ea1c1ed339602ed2891b24288aca33', 'market': '0x7aa4a910b31b2c4ddb09d1e3408e52aa8e09a14402f376070a44b1b85cb36d13', 'timestamp': '1733332660074'}
{'asset_id': '114416409796971863099144323163249651172534872992222856507897414949637892047507', 'changes': [{'price': '0.5', 'side': 'BUY', 'size': '1515'}], 'event_type': 'price_change', 'hash': 'bf2c732dbd0f1ec2976060f8600ef3e469af46ce', 'market': '0x7aa4a910b31b2c4ddb09d1e3408e52aa8e09a14402f376070a44b1b85cb36d13', 'timestamp': '1733332660430'}
{'asset_id': '114416409796971863099144323163249651172534872992222856507897414949637892047507', 'changes': [{'price': '0.5', 'side': 'BUY', 'size': '1515'}], 'event_type': 'price_change', 'hash': 'bf2c732dbd0f1ec2976060f8600ef3e469af46ce', 'market': '0x7aa4a910b31b2c4ddb09d1e3408e52aa8e09a14402f376070a44b1b85cb36d13', 'timestamp': '1733332660430'}
{'asset_id': '114416409796971863099144323163249651172534872992222856507897414949637892047507', 'changes': [{'price': '0.51', 'side': 'BUY', 'size': '1036.18'}], 'event_type': 'price_change', 'hash': 'ef0d649fd5de6155487334e33f1638a4162bf056', 'market': '0x7aa4a910b31b2c4ddb09d1e3408e52aa8e09a14402f376070a44b1b85cb36d13', 'timestamp': '1733332660560'}
{'asset_id': '114416409796971863099144323163249651172534872992222856507897414949637892047507', 'changes': [{'price': '0.51', 'side': 'BUY', 'size': '1036.18'}], 'event_type': 'price_change', 'hash': 'ef0d649fd5de6155487334e33f1638a4162bf056', 'market': '0x7aa4a910b31b2c4ddb09d1e3408e52aa8e09a14402f376070a44b1b85cb36d13', 'timestamp': '1733332660560'}
{'asset_id': '114416409796971863099144323163249651172534872992222856507897414949637892047507', 'changes': [{'price': '0.54', 'side': 'SELL', 'size': '210'}], 'event_type': 'price_change', 'hash': '1eccf6ce546dd90fa48722b90e25dfb5319f09ac', 'market': '0x7aa4a910b31b2c4ddb09d1e3408e52aa8e09a14402f376070a44b1b85cb36d13', 'timestamp': '1733332660875'}
{'asset_id': '114416409796971863099144323163249651172534872992222856507897414949637892047507', 'changes': [{'price': '0.54', 'side': 'SELL', 'size': '210'}], 'event_type': 'price_change', 'hash': '1eccf6ce546dd90fa48722b90e25dfb5319f09ac', 'market': '0x7aa4a910b31b2c4ddb09d1e3408e52aa8e09a14402f376070a44b1b85cb36d13', 'timestamp': '1733332660875'}
{'asset_id': '114416409796971863099144323163249651172534872992222856507897414949637892047507', 'changes': [{'price': '0.47', 'side': 'BUY', 'size': '1600'}], 'event_type': 'price_change', 'hash': '7ffcad504ca22c5540dc119cdb0d2c6690ccb558', 'market': '0x7aa4a910b31b2c4ddb09d1e3408e52aa8e09a14402f376070a44b1b85cb36d13', 'timestamp': '1733332661211'}
{'asset_id': '114416409796971863099144323163249651172534872992222856507897414949637892047507', 'changes': [{'price': '0.47', 'side': 'BUY', 'size': '1600'}], 'event_type': 'price_change', 'hash': '7ffcad504ca22c5540dc119cdb0d2c6690ccb558', 'market': '0x7aa4a910b31b2c4ddb09d1e3408e52aa8e09a14402f376070a44b1b85cb36d13', 'timestamp': '1733332661211'}
{'asset_id': '114416409796971863099144323163249651172534872992222856507897414949637892047507', 'changes': [{'price': '0.51', 'side': 'BUY', 'size': '1046.18'}], 'event_type': 'price_change', 'hash': '69be61a33404bf588155ef498e6f605349f6f74b', 'market': '0x7aa4a910b31b2c4ddb09d1e3408e52aa8e09a14402f376070a44b1b85cb36d13', 'timestamp': '1733332664688'}
{'asset_id': '114416409796971863099144323163249651172534872992222856507897414949637892047507', 'changes': [{'price': '0.51', 'side': 'BUY', 'size': '1046.18'}], 'event_type': 'price_change', 'hash': '69be61a33404bf588155ef498e6f605349f6f74b', 'market': '0x7aa4a910b31b2c4ddb09d1e3408e52aa8e09a14402f376070a44b1b85cb36d13', 'timestamp': '1733332664688'}
{'asset_id': '114416409796971863099144323163249651172534872992222856507897414949637892047507', 'changes': [{'price': '0.58', 'side': 'SELL', 'size': '2088.1'}], 'event_type': 'price_change', 'hash': 'f86e3726b3019729e1dfcb72d62c9c2629627dda', 'market': '0x7aa4a910b31b2c4ddb09d1e3408e52aa8e09a14402f376070a44b1b85cb36d13', 'timestamp': '1733332669065'}
{'asset_id': '114416409796971863099144323163249651172534872992222856507897414949637892047507', 'changes': [{'price': '0.58', 'side': 'SELL', 'size': '2088.1'}], 'event_type': 'price_change', 'hash': 'f86e3726b3019729e1dfcb72d62c9c2629627dda', 'market': '0x7aa4a910b31b2c4ddb09d1e3408e52aa8e09a14402f376070a44b1b85cb36d13', 'timestamp': '1733332669065'}
{'asset_id': '114416409796971863099144323163249651172534872992222856507897414949637892047507', 'changes': [{'price': '0.51', 'side': 'BUY', 'size': '996.18'}], 'event_type': 'price_change', 'hash': 'e152518c61f69a1eb9168a0ab6aa3bd40fdb2147', 'market': '0x7aa4a910b31b2c4ddb09d1e3408e52aa8e09a14402f376070a44b1b85cb36d13', 'timestamp': '1733332669530'}
{'asset_id': '114416409796971863099144323163249651172534872992222856507897414949637892047507', 'changes': [{'price': '0.51', 'side': 'BUY', 'size': '996.18'}], 'event_type': 'price_change', 'hash': 'e152518c61f69a1eb9168a0ab6aa3bd40fdb2147', 'market': '0x7aa4a910b31b2c4ddb09d1e3408e52aa8e09a14402f376070a44b1b85cb36d13', 'timestamp': '1733332669530'}
{'asset_id': '114416409796971863099144323163249651172534872992222856507897414949637892047507', 'changes': [{'price': '0.54', 'side': 'SELL', 'size': '260'}], 'event_type': 'price_change', 'hash': '66b06b714283d55a3d67e88382cba1ca57ee451d', 'market': '0x7aa4a910b31b2c4ddb09d1e3408e52aa8e09a14402f376070a44b1b85cb36d13', 'timestamp': '1733332669790'}
{'asset_id': '114416409796971863099144323163249651172534872992222856507897414949637892047507', 'changes': [{'price': '0.54', 'side': 'SELL', 'size': '260'}], 'event_type': 'price_change', 'hash': '66b06b714283d55a3d67e88382cba1ca57ee451d', 'market': '0x7aa4a910b31b2c4ddb09d1e3408e52aa8e09a14402f376070a44b1b85cb36d13', 'timestamp': '1733332669790'}
{'asset_id': '114416409796971863099144323163249651172534872992222856507897414949637892047507', 'changes': [{'price': '0.47', 'side': 'BUY', 'size': '1650'}], 'event_type': 'price_change', 'hash': '3baf1b618eff7cf7df270433ba914f4bc54f841f', 'market': '0x7aa4a910b31b2c4ddb09d1e3408e52aa8e09a14402f376070a44b1b85cb36d13', 'timestamp': '1733332670052'}
{'asset_id': '114416409796971863099144323163249651172534872992222856507897414949637892047507', 'changes': [{'price': '0.47', 'side': 'BUY', 'size': '1650'}], 'event_type': 'price_change', 'hash': '3baf1b618eff7cf7df270433ba914f4bc54f841f', 'market': '0x7aa4a910b31b2c4ddb09d1e3408e52aa8e09a14402f376070a44b1b85cb36d13', 'timestamp': '1733332670052'}
{'asset_id': '114416409796971863099144323163249651172534872992222856507897414949637892047507', 'changes': [{'price': '0.47', 'side': 'BUY', 'size': '150'}], 'event_type': 'price_change', 'hash': '72264feb94a5a5356f7bc6974eccc61582949a63', 'market': '0x7aa4a910b31b2c4ddb09d1e3408e52aa8e09a14402f376070a44b1b85cb36d13', 'timestamp': '1733332688282'}
{'asset_id': '114416409796971863099144323163249651172534872992222856507897414949637892047507', 'changes': [{'price': '0.47', 'side': 'BUY', 'size': '150'}], 'event_type': 'price_change', 'hash': '72264feb94a5a5356f7bc6974eccc61582949a63', 'market': '0x7aa4a910b31b2c4ddb09d1e3408e52aa8e09a14402f376070a44b1b85cb36d13', 'timestamp': '1733332688282'}
{'asset_id': '114416409796971863099144323163249651172534872992222856507897414949637892047507', 'changes': [{'price': '0.5', 'side': 'BUY', 'size': '515'}, {'price': '0.55', 'side': 'SELL', 'size': '2214.39'}, {'price': '0.45', 'side': 'BUY', 'size': '2978'}], 'event_type': 'price_change', 'hash': '7bb59d7917655951821054f5f22bcfb555597592', 'market': '0x7aa4a910b31b2c4ddb09d1e3408e52aa8e09a14402f376070a44b1b85cb36d13', 'timestamp': '1733332689225'}
{'asset_id': '114416409796971863099144323163249651172534872992222856507897414949637892047507', 'changes': [{'price': '0.5', 'side': 'BUY', 'size': '515'}, {'price': '0.55', 'side': 'SELL', 'size': '2214.39'}, {'price': '0.45', 'side': 'BUY', 'size': '2978'}], 'event_type': 'price_change', 'hash': '7bb59d7917655951821054f5f22bcfb555597592', 'market': '0x7aa4a910b31b2c4ddb09d1e3408e52aa8e09a14402f376070a44b1b85cb36d13', 'timestamp': '1733332689225'}
{'asset_id': '114416409796971863099144323163249651172534872992222856507897414949637892047507', 'changes': [{'price': '0.45', 'side': 'BUY', 'size': '3478'}], 'event_type': 'price_change', 'hash': '1824604b270a5a1670bd55302751f0646be89e64', 'market': '0x7aa4a910b31b2c4ddb09d1e3408e52aa8e09a14402f376070a44b1b85cb36d13', 'timestamp': '1733332690357'}
{'asset_id': '114416409796971863099144323163249651172534872992222856507897414949637892047507', 'changes': [{'price': '0.45', 'side': 'BUY', 'size': '3478'}], 'event_type': 'price_change', 'hash': '1824604b270a5a1670bd55302751f0646be89e64', 'market': '0x7aa4a910b31b2c4ddb09d1e3408e52aa8e09a14402f376070a44b1b85cb36d13', 'timestamp': '1733332690357'}
{'asset_id': '114416409796971863099144323163249651172534872992222856507897414949637892047507', 'changes': [{'price': '0.55', 'side': 'SELL', 'size': '2714.39'}], 'event_type': 'price_change', 'hash': '450f483ee5be4f56fbd958f2f5cce899bb9d840a', 'market': '0x7aa4a910b31b2c4ddb09d1e3408e52aa8e09a14402f376070a44b1b85cb36d13', 'timestamp': '1733332690726'}
{'asset_id': '114416409796971863099144323163249651172534872992222856507897414949637892047507', 'changes': [{'price': '0.55', 'side': 'SELL', 'size': '2714.39'}], 'event_type': 'price_change', 'hash': '450f483ee5be4f56fbd958f2f5cce899bb9d840a', 'market': '0x7aa4a910b31b2c4ddb09d1e3408e52aa8e09a14402f376070a44b1b85cb36d13', 'timestamp': '1733332690726'}
{'asset_id': '114416409796971863099144323163249651172534872992222856507897414949637892047507', 'changes': [{'price': '0.51', 'side': 'BUY', 'size': '1996.18'}], 'event_type': 'price_change', 'hash': '360c60d80cde02f1d7474dcd853a14d6227b8693', 'market': '0x7aa4a910b31b2c4ddb09d1e3408e52aa8e09a14402f376070a44b1b85cb36d13', 'timestamp': '1733332691077'}
{'asset_id': '114416409796971863099144323163249651172534872992222856507897414949637892047507', 'changes': [{'price': '0.48', 'side': 'BUY', 'size': '4072.18'}], 'event_type': 'price_change', 'hash': '4fee9004449885ba1694c72037eb7ad42eca16f7', 'market': '0x7aa4a910b31b2c4ddb09d1e3408e52aa8e09a14402f376070a44b1b85cb36d13', 'timestamp': '1733332695187'}
{'asset_id': '114416409796971863099144323163249651172534872992222856507897414949637892047507', 'changes': [{'price': '0.48', 'side': 'BUY', 'size': '4072.18'}], 'event_type': 'price_change', 'hash': '4fee9004449885ba1694c72037eb7ad42eca16f7', 'market': '0x7aa4a910b31b2c4ddb09d1e3408e52aa8e09a14402f376070a44b1b85cb36d13', 'timestamp': '1733332695187'}
{'asset_id': '114416409796971863099144323163249651172534872992222856507897414949637892047507', 'changes': [{'price': '0.54', 'side': 'SELL', 'size': '160'}], 'event_type': 'price_change', 'hash': '8c6335d8f6d926b80bb911d943697b93d4ae3d97', 'market': '0x7aa4a910b31b2c4ddb09d1e3408e52aa8e09a14402f376070a44b1b85cb36d13', 'timestamp': '1733332717267'}
{'asset_id': '114416409796971863099144323163249651172534872992222856507897414949637892047507', 'changes': [{'price': '0.54', 'side': 'SELL', 'size': '160'}], 'event_type': 'price_change', 'hash': '8c6335d8f6d926b80bb911d943697b93d4ae3d97', 'market': '0x7aa4a910b31b2c4ddb09d1e3408e52aa8e09a14402f376070a44b1b85cb36d13', 'timestamp': '1733332717267'}
{'asset_id': '114416409796971863099144323163249651172534872992222856507897414949637892047507', 'changes': [{'price': '0.55', 'side': 'SELL', 'size': '2814.39'}], 'event_type': 'price_change', 'hash': '2ec3c3359b42b6dbfe7f085aaeca9e4fb6c3b8bb', 'market': '0x7aa4a910b31b2c4ddb09d1e3408e52aa8e09a14402f376070a44b1b85cb36d13', 'timestamp': '1733332717900'}
{'asset_id': '114416409796971863099144323163249651172534872992222856507897414949637892047507', 'changes': [{'price': '0.55', 'side': 'SELL', 'size': '2814.39'}], 'event_type': 'price_change', 'hash': '2ec3c3359b42b6dbfe7f085aaeca9e4fb6c3b8bb', 'market': '0x7aa4a910b31b2c4ddb09d1e3408e52aa8e09a14402f376070a44b1b85cb36d13', 'timestamp': '1733332717900'}
{'asset_id': '114416409796971863099144323163249651172534872992222856507897414949637892047507', 'changes': [{'price': '0.54', 'side': 'SELL', 'size': '170.1'}], 'event_type': 'price_change', 'hash': 'bf36c5dbfa22eee1594abca346889ac0eb5f16fe', 'market': '0x7aa4a910b31b2c4ddb09d1e3408e52aa8e09a14402f376070a44b1b85cb36d13', 'timestamp': '1733332721031'}
{'asset_id': '114416409796971863099144323163249651172534872992222856507897414949637892047507', 'changes': [{'price': '0.54', 'side': 'SELL', 'size': '170.1'}], 'event_type': 'price_change', 'hash': 'bf36c5dbfa22eee1594abca346889ac0eb5f16fe', 'market': '0x7aa4a910b31b2c4ddb09d1e3408e52aa8e09a14402f376070a44b1b85cb36d13', 'timestamp': '1733332721031'}
{'asset_id': '114416409796971863099144323163249651172534872992222856507897414949637892047507', 'changes': [{'price': '0.49', 'side': 'BUY', 'size': '140'}, {'price': '0.48', 'side': 'BUY', 'size': '2572.18'}], 'event_type': 'price_change', 'hash': 'f6c430db8aef2a61f7d77e068c0dee57f4569e39', 'market': '0x7aa4a910b31b2c4ddb09d1e3408e52aa8e09a14402f376070a44b1b85cb36d13', 'timestamp': '1733332721871'}
{'asset_id': '114416409796971863099144323163249651172534872992222856507897414949637892047507', 'changes': [{'price': '0.49', 'side': 'BUY', 'size': '140'}, {'price': '0.48', 'side': 'BUY', 'size': '2572.18'}], 'event_type': 'price_change', 'hash': 'f6c430db8aef2a61f7d77e068c0dee57f4569e39', 'market': '0x7aa4a910b31b2c4ddb09d1e3408e52aa8e09a14402f376070a44b1b85cb36d13', 'timestamp': '1733332721871'}
{'asset_id': '114416409796971863099144323163249651172534872992222856507897414949637892047507', 'changes': [{'price': '0.45', 'side': 'BUY', 'size': '2978'}, {'price': '0.55', 'side': 'SELL', 'size': '2314.39'}, {'price': '0.51', 'side': 'BUY', 'size': '996.18'}], 'event_type': 'price_change', 'hash': '0a1fa300590c7d42c9043bc17051354c8544a637', 'market': '0x7aa4a910b31b2c4ddb09d1e3408e52aa8e09a14402f376070a44b1b85cb36d13', 'timestamp': '1733332722154'}
{'asset_id': '114416409796971863099144323163249651172534872992222856507897414949637892047507', 'changes': [{'price': '0.45', 'side': 'BUY', 'size': '2978'}, {'price': '0.55', 'side': 'SELL', 'size': '2314.39'}, {'price': '0.51', 'side': 'BUY', 'size': '996.18'}], 'event_type': 'price_change', 'hash': '0a1fa300590c7d42c9043bc17051354c8544a637', 'market': '0x7aa4a910b31b2c4ddb09d1e3408e52aa8e09a14402f376070a44b1b85cb36d13', 'timestamp': '1733332722154'}
{'asset_id': '114416409796971863099144323163249651172534872992222856507897414949637892047507', 'changes': [{'price': '0.46', 'side': 'BUY', 'size': '500'}], 'event_type': 'price_change', 'hash': '8b02c093d415f1e8c0bc6ad0d9b362ca16743511', 'market': '0x7aa4a910b31b2c4ddb09d1e3408e52aa8e09a14402f376070a44b1b85cb36d13', 'timestamp': '1733332723192'}
{'asset_id': '114416409796971863099144323163249651172534872992222856507897414949637892047507', 'changes': [{'price': '0.46', 'side': 'BUY', 'size': '500'}], 'event_type': 'price_change', 'hash': '8b02c093d415f1e8c0bc6ad0d9b362ca16743511', 'market': '0x7aa4a910b31b2c4ddb09d1e3408e52aa8e09a14402f376070a44b1b85cb36d13', 'timestamp': '1733332723192'}
{'asset_id': '114416409796971863099144323163249651172534872992222856507897414949637892047507', 'changes': [{'price': '0.56', 'side': 'SELL', 'size': '3350.1'}], 'event_type': 'price_change', 'hash': '11a03a6819b3ecda50e5ae9874191f56e490cc3f', 'market': '0x7aa4a910b31b2c4ddb09d1e3408e52aa8e09a14402f376070a44b1b85cb36d13', 'timestamp': '1733332723556'}
{'asset_id': '114416409796971863099144323163249651172534872992222856507897414949637892047507', 'changes': [{'price': '0.56', 'side': 'SELL', 'size': '3350.1'}], 'event_type': 'price_change', 'hash': '11a03a6819b3ecda50e5ae9874191f56e490cc3f', 'market': '0x7aa4a910b31b2c4ddb09d1e3408e52aa8e09a14402f376070a44b1b85cb36d13', 'timestamp': '1733332723556'}
{'asset_id': '114416409796971863099144323163249651172534872992222856507897414949637892047507', 'changes': [{'price': '0.52', 'side': 'BUY', 'size': '1000'}], 'event_type': 'price_change', 'hash': '2d07f3ef1c265e4c5b97832b8c7f6be020316794', 'market': '0x7aa4a910b31b2c4ddb09d1e3408e52aa8e09a14402f376070a44b1b85cb36d13', 'timestamp': '1733332723929'}
{'asset_id': '114416409796971863099144323163249651172534872992222856507897414949637892047507', 'changes': [{'price': '0.52', 'side': 'BUY', 'size': '1000'}], 'event_type': 'price_change', 'hash': '2d07f3ef1c265e4c5b97832b8c7f6be020316794', 'market': '0x7aa4a910b31b2c4ddb09d1e3408e52aa8e09a14402f376070a44b1b85cb36d13', 'timestamp': '1733332723929'}
{'asset_id': '114416409796971863099144323163249651172534872992222856507897414949637892047507', 'changes': [{'price': '0.51', 'side': 'BUY', 'size': '986.18'}], 'event_type': 'price_change', 'hash': '8233533204ba45a60011cf93943dbe70f9d9c3de', 'market': '0x7aa4a910b31b2c4ddb09d1e3408e52aa8e09a14402f376070a44b1b85cb36d13', 'timestamp': '1733332724543'}
{'asset_id': '114416409796971863099144323163249651172534872992222856507897414949637892047507', 'changes': [{'price': '0.51', 'side': 'BUY', 'size': '986.18'}], 'event_type': 'price_change', 'hash': '8233533204ba45a60011cf93943dbe70f9d9c3de', 'market': '0x7aa4a910b31b2c4ddb09d1e3408e52aa8e09a14402f376070a44b1b85cb36d13', 'timestamp': '1733332724543'}
{'asset_id': '114416409796971863099144323163249651172534872992222856507897414949637892047507', 'changes': [{'price': '0.52', 'side': 'BUY', 'size': '1010'}], 'event_type': 'price_change', 'hash': 'dad631bb7d995a16bdbb6b54297bf31b39db0750', 'market': '0x7aa4a910b31b2c4ddb09d1e3408e52aa8e09a14402f376070a44b1b85cb36d13', 'timestamp': '1733332724629'}
{'asset_id': '114416409796971863099144323163249651172534872992222856507897414949637892047507', 'changes': [{'price': '0.52', 'side': 'BUY', 'size': '1010'}], 'event_type': 'price_change', 'hash': 'dad631bb7d995a16bdbb6b54297bf31b39db0750', 'market': '0x7aa4a910b31b2c4ddb09d1e3408e52aa8e09a14402f376070a44b1b85cb36d13', 'timestamp': '1733332724629'}
{'asset_id': '114416409796971863099144323163249651172534872992222856507897414949637892047507', 'changes': [{'price': '0.54', 'side': 'SELL', 'size': '120.1'}], 'event_type': 'price_change', 'hash': 'cf993ebdec123eb4b5598d5bc5fca031d7ab203e', 'market': '0x7aa4a910b31b2c4ddb09d1e3408e52aa8e09a14402f376070a44b1b85cb36d13', 'timestamp': '1733332729137'}
{'asset_id': '114416409796971863099144323163249651172534872992222856507897414949637892047507', 'changes': [{'price': '0.54', 'side': 'SELL', 'size': '120.1'}], 'event_type': 'price_change', 'hash': 'cf993ebdec123eb4b5598d5bc5fca031d7ab203e', 'market': '0x7aa4a910b31b2c4ddb09d1e3408e52aa8e09a14402f376070a44b1b85cb36d13', 'timestamp': '1733332729137'}
{'asset_id': '114416409796971863099144323163249651172534872992222856507897414949637892047507', 'changes': [{'price': '0.47', 'side': 'BUY', 'size': '100'}], 'event_type': 'price_change', 'hash': 'f4c33a460c8d73b71c39af995c5e8928057261c9', 'market': '0x7aa4a910b31b2c4ddb09d1e3408e52aa8e09a14402f376070a44b1b85cb36d13', 'timestamp': '1733332729645'}
{'asset_id': '114416409796971863099144323163249651172534872992222856507897414949637892047507', 'changes': [{'price': '0.47', 'side': 'BUY', 'size': '100'}], 'event_type': 'price_change', 'hash': 'f4c33a460c8d73b71c39af995c5e8928057261c9', 'market': '0x7aa4a910b31b2c4ddb09d1e3408e52aa8e09a14402f376070a44b1b85cb36d13', 'timestamp': '1733332729645'}
{'asset_id': '114416409796971863099144323163249651172534872992222856507897414949637892047507', 'changes': [{'price': '0.58', 'side': 'SELL', 'size': '2138.1'}], 'event_type': 'price_change', 'hash': 'aa33b72224289bb0be4a53e083c802c83d8787ec', 'market': '0x7aa4a910b31b2c4ddb09d1e3408e52aa8e09a14402f376070a44b1b85cb36d13', 'timestamp': '1733332729913'}
{'asset_id': '114416409796971863099144323163249651172534872992222856507897414949637892047507', 'changes': [{'price': '0.58', 'side': 'SELL', 'size': '2138.1'}], 'event_type': 'price_change', 'hash': 'aa33b72224289bb0be4a53e083c802c83d8787ec', 'market': '0x7aa4a910b31b2c4ddb09d1e3408e52aa8e09a14402f376070a44b1b85cb36d13', 'timestamp': '1733332729913'}
{'asset_id': '114416409796971863099144323163249651172534872992222856507897414949637892047507', 'changes': [{'price': '0.54', 'side': 'SELL', 'size': '70.1'}, {'price': '0.51', 'side': 'BUY', 'size': '1036.18'}], 'event_type': 'price_change', 'hash': '7320d1996ea436de7646cb25c61ef2b81006c455', 'market': '0x7aa4a910b31b2c4ddb09d1e3408e52aa8e09a14402f376070a44b1b85cb36d13', 'timestamp': '1733332730149'}
{'asset_id': '114416409796971863099144323163249651172534872992222856507897414949637892047507', 'changes': [{'price': '0.54', 'side': 'SELL', 'size': '70.1'}, {'price': '0.51', 'side': 'BUY', 'size': '1036.18'}], 'event_type': 'price_change', 'hash': '7320d1996ea436de7646cb25c61ef2b81006c455', 'market': '0x7aa4a910b31b2c4ddb09d1e3408e52aa8e09a14402f376070a44b1b85cb36d13', 'timestamp': '1733332730149'}
{'asset_id': '114416409796971863099144323163249651172534872992222856507897414949637892047507', 'changes': [{'price': '0.47', 'side': 'BUY', 'size': '50'}], 'event_type': 'price_change', 'hash': 'bd11a908fc1cbc679bfe4a238598668e001197b7', 'market': '0x7aa4a910b31b2c4ddb09d1e3408e52aa8e09a14402f376070a44b1b85cb36d13', 'timestamp': '1733332730578'}
{'asset_id': '114416409796971863099144323163249651172534872992222856507897414949637892047507', 'changes': [{'price': '0.47', 'side': 'BUY', 'size': '50'}], 'event_type': 'price_change', 'hash': 'bd11a908fc1cbc679bfe4a238598668e001197b7', 'market': '0x7aa4a910b31b2c4ddb09d1e3408e52aa8e09a14402f376070a44b1b85cb36d13', 'timestamp': '1733332730578'}
{'asset_id': '114416409796971863099144323163249651172534872992222856507897414949637892047507', 'changes': [{'price': '0.49', 'side': 'BUY', 'size': '1640'}, {'price': '0.58', 'side': 'SELL', 'size': '2188.1'}], 'event_type': 'price_change', 'hash': '23a5d2f3a4c9aa677fc2a860bfda85924b38e972', 'market': '0x7aa4a910b31b2c4ddb09d1e3408e52aa8e09a14402f376070a44b1b85cb36d13', 'timestamp': '1733332730827'}
{'asset_id': '114416409796971863099144323163249651172534872992222856507897414949637892047507', 'changes': [{'price': '0.49', 'side': 'BUY', 'size': '1640'}, {'price': '0.58', 'side': 'SELL', 'size': '2188.1'}], 'event_type': 'price_change', 'hash': '23a5d2f3a4c9aa677fc2a860bfda85924b38e972', 'market': '0x7aa4a910b31b2c4ddb09d1e3408e52aa8e09a14402f376070a44b1b85cb36d13', 'timestamp': '1733332730827'}
{'asset_id': '114416409796971863099144323163249651172534872992222856507897414949637892047507', 'changes': [{'price': '0.5', 'side': 'BUY', 'size': '1715'}], 'event_type': 'price_change', 'hash': '920629a0a391da7188b9f031500a8aa0081a78ae', 'market': '0x7aa4a910b31b2c4ddb09d1e3408e52aa8e09a14402f376070a44b1b85cb36d13', 'timestamp': '1733332730993'}
{'asset_id': '114416409796971863099144323163249651172534872992222856507897414949637892047507', 'changes': [{'price': '0.5', 'side': 'BUY', 'size': '1715'}], 'event_type': 'price_change', 'hash': '920629a0a391da7188b9f031500a8aa0081a78ae', 'market': '0x7aa4a910b31b2c4ddb09d1e3408e52aa8e09a14402f376070a44b1b85cb36d13', 'timestamp': '1733332730993'}
{'asset_id': '114416409796971863099144323163249651172534872992222856507897414949637892047507', 'changes': [{'price': '0.51', 'side': 'BUY', 'size': '1086.18'}, {'price': '0.56', 'side': 'SELL', 'size': '3110.1'}, {'price': '0.48', 'side': 'BUY', 'size': '2342.18'}], 'event_type': 'price_change', 'hash': '501213a3b7a4c56645d5b621b0d217d036adf924', 'market': '0x7aa4a910b31b2c4ddb09d1e3408e52aa8e09a14402f376070a44b1b85cb36d13', 'timestamp': '1733332731139'}
{'asset_id': '114416409796971863099144323163249651172534872992222856507897414949637892047507', 'changes': [{'price': '0.51', 'side': 'BUY', 'size': '1086.18'}, {'price': '0.56', 'side': 'SELL', 'size': '3110.1'}, {'price': '0.48', 'side': 'BUY', 'size': '2342.18'}], 'event_type': 'price_change', 'hash': '501213a3b7a4c56645d5b621b0d217d036adf924', 'market': '0x7aa4a910b31b2c4ddb09d1e3408e52aa8e09a14402f376070a44b1b85cb36d13', 'timestamp': '1733332731139'}
{'asset_id': '114416409796971863099144323163249651172534872992222856507897414949637892047507', 'changes': [{'price': '0.48', 'side': 'BUY', 'size': '2592.18'}, {'price': '0.57', 'side': 'SELL', 'size': '431.75'}], 'event_type': 'price_change', 'hash': '0ffe1ea4f9c3cd7c28e7767d89692e8dceecd0b7', 'market': '0x7aa4a910b31b2c4ddb09d1e3408e52aa8e09a14402f376070a44b1b85cb36d13', 'timestamp': '1733332731438'}
{'asset_id': '114416409796971863099144323163249651172534872992222856507897414949637892047507', 'changes': [{'price': '0.53', 'side': 'SELL', 'size': '125.01'}], 'event_type': 'price_change', 'hash': 'e0269dc2dabe23c642a57b929bc634dc471bc10b', 'market': '0x7aa4a910b31b2c4ddb09d1e3408e52aa8e09a14402f376070a44b1b85cb36d13', 'timestamp': '1733332735646'}
{'asset_id': '114416409796971863099144323163249651172534872992222856507897414949637892047507', 'changes': [{'price': '0.53', 'side': 'SELL', 'size': '125.01'}], 'event_type': 'price_change', 'hash': 'e0269dc2dabe23c642a57b929bc634dc471bc10b', 'market': '0x7aa4a910b31b2c4ddb09d1e3408e52aa8e09a14402f376070a44b1b85cb36d13', 'timestamp': '1733332735646'}
{'asset_id': '114416409796971863099144323163249651172534872992222856507897414949637892047507', 'changes': [{'price': '0.53', 'side': 'SELL', 'size': '100'}], 'event_type': 'price_change', 'hash': '2711ceadedca1334b724b705d64d15ca57591ca2', 'market': '0x7aa4a910b31b2c4ddb09d1e3408e52aa8e09a14402f376070a44b1b85cb36d13', 'timestamp': '1733332737001'}
{'asset_id': '114416409796971863099144323163249651172534872992222856507897414949637892047507', 'changes': [{'price': '0.53', 'side': 'SELL', 'size': '100'}], 'event_type': 'price_change', 'hash': '2711ceadedca1334b724b705d64d15ca57591ca2', 'market': '0x7aa4a910b31b2c4ddb09d1e3408e52aa8e09a14402f376070a44b1b85cb36d13', 'timestamp': '1733332737001'}
{'asset_id': '114416409796971863099144323163249651172534872992222856507897414949637892047507', 'changes': [{'price': '0.55', 'side': 'SELL', 'size': '2339.4'}], 'event_type': 'price_change', 'hash': '51acea3ba3774eda36482800d60b4bbb26a04980', 'market': '0x7aa4a910b31b2c4ddb09d1e3408e52aa8e09a14402f376070a44b1b85cb36d13', 'timestamp': '1733332737167'}
{'asset_id': '114416409796971863099144323163249651172534872992222856507897414949637892047507', 'changes': [{'price': '0.55', 'side': 'SELL', 'size': '2339.4'}], 'event_type': 'price_change', 'hash': '51acea3ba3774eda36482800d60b4bbb26a04980', 'market': '0x7aa4a910b31b2c4ddb09d1e3408e52aa8e09a14402f376070a44b1b85cb36d13', 'timestamp': '1733332737167'}
{'asset_id': '114416409796971863099144323163249651172534872992222856507897414949637892047507', 'changes': [{'price': '0.53', 'side': 'SELL', 'size': '0'}], 'event_type': 'price_change', 'hash': '2c288108c97463a0a9d356b16d76e3122bde56ba', 'market': '0x7aa4a910b31b2c4ddb09d1e3408e52aa8e09a14402f376070a44b1b85cb36d13', 'timestamp': '1733332739097'}
{'asset_id': '114416409796971863099144323163249651172534872992222856507897414949637892047507', 'changes': [{'price': '0.53', 'side': 'SELL', 'size': '0'}], 'event_type': 'price_change', 'hash': '2c288108c97463a0a9d356b16d76e3122bde56ba', 'market': '0x7aa4a910b31b2c4ddb09d1e3408e52aa8e09a14402f376070a44b1b85cb36d13', 'timestamp': '1733332739097'}
{'asset_id': '114416409796971863099144323163249651172534872992222856507897414949637892047507', 'changes': [{'price': '0.55', 'side': 'SELL', 'size': '2439.4'}], 'event_type': 'price_change', 'hash': '1bae15f595be6cd3536212b1951c5e80e9513a58', 'market': '0x7aa4a910b31b2c4ddb09d1e3408e52aa8e09a14402f376070a44b1b85cb36d13', 'timestamp': '1733332739289'}
{'asset_id': '114416409796971863099144323163249651172534872992222856507897414949637892047507', 'changes': [{'price': '0.55', 'side': 'SELL', 'size': '2439.4'}], 'event_type': 'price_change', 'hash': '1bae15f595be6cd3536212b1951c5e80e9513a58', 'market': '0x7aa4a910b31b2c4ddb09d1e3408e52aa8e09a14402f376070a44b1b85cb36d13', 'timestamp': '1733332739289'}
{'asset_id': '114416409796971863099144323163249651172534872992222856507897414949637892047507', 'changes': [{'price': '0.55', 'side': 'SELL', 'size': '1239.4'}], 'event_type': 'price_change', 'hash': '000593bb1c610262ce2157a1f13d04b066dad180', 'market': '0x7aa4a910b31b2c4ddb09d1e3408e52aa8e09a14402f376070a44b1b85cb36d13', 'timestamp': '1733332742132'}
{'asset_id': '114416409796971863099144323163249651172534872992222856507897414949637892047507', 'changes': [{'price': '0.55', 'side': 'SELL', 'size': '1239.4'}], 'event_type': 'price_change', 'hash': '000593bb1c610262ce2157a1f13d04b066dad180', 'market': '0x7aa4a910b31b2c4ddb09d1e3408e52aa8e09a14402f376070a44b1b85cb36d13', 'timestamp': '1733332742132'}
{'asset_id': '114416409796971863099144323163249651172534872992222856507897414949637892047507', 'changes': [{'price': '0.48', 'side': 'BUY', 'size': '2342.18'}, {'price': '0.57', 'side': 'SELL', 'size': '161.75'}], 'event_type': 'price_change', 'hash': '1998dd954dbc4fc02f81e372156662dae527abfe', 'market': '0x7aa4a910b31b2c4ddb09d1e3408e52aa8e09a14402f376070a44b1b85cb36d13', 'timestamp': '1733332742437'}
{'asset_id': '114416409796971863099144323163249651172534872992222856507897414949637892047507', 'changes': [{'price': '0.48', 'side': 'BUY', 'size': '2342.18'}, {'price': '0.57', 'side': 'SELL', 'size': '161.75'}], 'event_type': 'price_change', 'hash': '1998dd954dbc4fc02f81e372156662dae527abfe', 'market': '0x7aa4a910b31b2c4ddb09d1e3408e52aa8e09a14402f376070a44b1b85cb36d13', 'timestamp': '1733332742437'}
{'asset_id': '114416409796971863099144323163249651172534872992222856507897414949637892047507', 'changes': [{'price': '0.57', 'side': 'SELL', 'size': '401.75'}], 'event_type': 'price_change', 'hash': 'd837dd18505ccdf308d796f2bc671f918f1ca602', 'market': '0x7aa4a910b31b2c4ddb09d1e3408e52aa8e09a14402f376070a44b1b85cb36d13', 'timestamp': '1733332742718'}
{'asset_id': '114416409796971863099144323163249651172534872992222856507897414949637892047507', 'changes': [{'price': '0.57', 'side': 'SELL', 'size': '401.75'}], 'event_type': 'price_change', 'hash': 'd837dd18505ccdf308d796f2bc671f918f1ca602', 'market': '0x7aa4a910b31b2c4ddb09d1e3408e52aa8e09a14402f376070a44b1b85cb36d13', 'timestamp': '1733332742718'}
{'asset_id': '114416409796971863099144323163249651172534872992222856507897414949637892047507', 'changes': [{'price': '0.54', 'side': 'SELL', 'size': '10.1'}], 'event_type': 'price_change', 'hash': '82ac9e8030e6371941f134d3c2ceaa4f1506a093', 'market': '0x7aa4a910b31b2c4ddb09d1e3408e52aa8e09a14402f376070a44b1b85cb36d13', 'timestamp': '1733332742898'}
{'asset_id': '114416409796971863099144323163249651172534872992222856507897414949637892047507', 'changes': [{'price': '0.54', 'side': 'SELL', 'size': '10.1'}], 'event_type': 'price_change', 'hash': '82ac9e8030e6371941f134d3c2ceaa4f1506a093', 'market': '0x7aa4a910b31b2c4ddb09d1e3408e52aa8e09a14402f376070a44b1b85cb36d13', 'timestamp': '1733332742898'}
{'asset_id': '114416409796971863099144323163249651172534872992222856507897414949637892047507', 'changes': [{'price': '0.49', 'side': 'BUY', 'size': '1860'}], 'event_type': 'price_change', 'hash': '2871d9004902b448d39db85ca0133a13c069eb29', 'market': '0x7aa4a910b31b2c4ddb09d1e3408e52aa8e09a14402f376070a44b1b85cb36d13', 'timestamp': '1733332742935'}
{'asset_id': '114416409796971863099144323163249651172534872992222856507897414949637892047507', 'changes': [{'price': '0.49', 'side': 'BUY', 'size': '1860'}], 'event_type': 'price_change', 'hash': '2871d9004902b448d39db85ca0133a13c069eb29', 'market': '0x7aa4a910b31b2c4ddb09d1e3408e52aa8e09a14402f376070a44b1b85cb36d13', 'timestamp': '1733332742935'}
{'asset_id': '114416409796971863099144323163249651172534872992222856507897414949637892047507', 'changes': [{'price': '0.55', 'side': 'SELL', 'size': '1299.4'}], 'event_type': 'price_change', 'hash': 'a5c8af30308c373c621e88cb121fc343e1a1b21f', 'market': '0x7aa4a910b31b2c4ddb09d1e3408e52aa8e09a14402f376070a44b1b85cb36d13', 'timestamp': '1733332743042'}
{'asset_id': '114416409796971863099144323163249651172534872992222856507897414949637892047507', 'changes': [{'price': '0.55', 'side': 'SELL', 'size': '1299.4'}], 'event_type': 'price_change', 'hash': 'a5c8af30308c373c621e88cb121fc343e1a1b21f', 'market': '0x7aa4a910b31b2c4ddb09d1e3408e52aa8e09a14402f376070a44b1b85cb36d13', 'timestamp': '1733332743042'}
{'asset_id': '114416409796971863099144323163249651172534872992222856507897414949637892047507', 'changes': [{'price': '0.55', 'side': 'SELL', 'size': '1199.4'}], 'event_type': 'price_change', 'hash': '56573d24cd989506e008c583b7d670ff01d8bd29', 'market': '0x7aa4a910b31b2c4ddb09d1e3408e52aa8e09a14402f376070a44b1b85cb36d13', 'timestamp': '1733332743809'}
{'asset_id': '114416409796971863099144323163249651172534872992222856507897414949637892047507', 'changes': [{'price': '0.55', 'side': 'SELL', 'size': '1199.4'}], 'event_type': 'price_change', 'hash': '56573d24cd989506e008c583b7d670ff01d8bd29', 'market': '0x7aa4a910b31b2c4ddb09d1e3408e52aa8e09a14402f376070a44b1b85cb36d13', 'timestamp': '1733332743809'}
{'asset_id': '114416409796971863099144323163249651172534872992222856507897414949637892047507', 'changes': [{'price': '0.53', 'side': 'SELL', 'size': '10.1'}], 'event_type': 'price_change', 'hash': '4b111a8ecca0b698f34f5f0ff1232fac98a3588e', 'market': '0x7aa4a910b31b2c4ddb09d1e3408e52aa8e09a14402f376070a44b1b85cb36d13', 'timestamp': '1733332743900'}
{'asset_id': '114416409796971863099144323163249651172534872992222856507897414949637892047507', 'changes': [{'price': '0.53', 'side': 'SELL', 'size': '10.1'}], 'event_type': 'price_change', 'hash': '4b111a8ecca0b698f34f5f0ff1232fac98a3588e', 'market': '0x7aa4a910b31b2c4ddb09d1e3408e52aa8e09a14402f376070a44b1b85cb36d13', 'timestamp': '1733332743900'}
{'asset_id': '114416409796971863099144323163249651172534872992222856507897414949637892047507', 'changes': [{'price': '0.56', 'side': 'SELL', 'size': '3210.1'}], 'event_type': 'price_change', 'hash': '2fdf33417e21247768f3027b36cdeaa9091eecd4', 'market': '0x7aa4a910b31b2c4ddb09d1e3408e52aa8e09a14402f376070a44b1b85cb36d13', 'timestamp': '1733332744488'}
{'asset_id': '114416409796971863099144323163249651172534872992222856507897414949637892047507', 'changes': [{'price': '0.56', 'side': 'SELL', 'size': '3210.1'}], 'event_type': 'price_change', 'hash': '2fdf33417e21247768f3027b36cdeaa9091eecd4', 'market': '0x7aa4a910b31b2c4ddb09d1e3408e52aa8e09a14402f376070a44b1b85cb36d13', 'timestamp': '1733332744488'}
{'asset_id': '114416409796971863099144323163249651172534872992222856507897414949637892047507', 'changes': [{'price': '0.56', 'side': 'SELL', 'size': '3110.1'}], 'event_type': 'price_change', 'hash': '5ccafc11c2ccb89479101421079033ddc9c8bdcf', 'market': '0x7aa4a910b31b2c4ddb09d1e3408e52aa8e09a14402f376070a44b1b85cb36d13', 'timestamp': '1733332745356'}
{'asset_id': '114416409796971863099144323163249651172534872992222856507897414949637892047507', 'changes': [{'price': '0.56', 'side': 'SELL', 'size': '3110.1'}], 'event_type': 'price_change', 'hash': '5ccafc11c2ccb89479101421079033ddc9c8bdcf', 'market': '0x7aa4a910b31b2c4ddb09d1e3408e52aa8e09a14402f376070a44b1b85cb36d13', 'timestamp': '1733332745356'}
{'asset_id': '114416409796971863099144323163249651172534872992222856507897414949637892047507', 'changes': [{'price': '0.55', 'side': 'SELL', 'size': '1299.4'}], 'event_type': 'price_change', 'hash': '0e1b6279b5d3107afab5897bdf104dcf7cf56ef0', 'market': '0x7aa4a910b31b2c4ddb09d1e3408e52aa8e09a14402f376070a44b1b85cb36d13', 'timestamp': '1733332746017'}
{'asset_id': '114416409796971863099144323163249651172534872992222856507897414949637892047507', 'changes': [{'price': '0.55', 'side': 'SELL', 'size': '1299.4'}], 'event_type': 'price_change', 'hash': '0e1b6279b5d3107afab5897bdf104dcf7cf56ef0', 'market': '0x7aa4a910b31b2c4ddb09d1e3408e52aa8e09a14402f376070a44b1b85cb36d13', 'timestamp': '1733332746017'}
{'asset_id': '114416409796971863099144323163249651172534872992222856507897414949637892047507', 'changes': [{'price': '0.57', 'side': 'SELL', 'size': '1601.75'}], 'event_type': 'price_change', 'hash': '3801d2cac0d3359ea090e4058b889641c8f5262f', 'market': '0x7aa4a910b31b2c4ddb09d1e3408e52aa8e09a14402f376070a44b1b85cb36d13', 'timestamp': '1733332748293'}
{'asset_id': '114416409796971863099144323163249651172534872992222856507897414949637892047507', 'changes': [{'price': '0.57', 'side': 'SELL', 'size': '1601.75'}], 'event_type': 'price_change', 'hash': '3801d2cac0d3359ea090e4058b889641c8f5262f', 'market': '0x7aa4a910b31b2c4ddb09d1e3408e52aa8e09a14402f376070a44b1b85cb36d13', 'timestamp': '1733332748293'}
{'asset_id': '114416409796971863099144323163249651172534872992222856507897414949637892047507', 'changes': [{'price': '0.55', 'side': 'SELL', 'size': '1239.4'}], 'event_type': 'price_change', 'hash': '055f6b8676f39df6cc76417e59ec754d57499912', 'market': '0x7aa4a910b31b2c4ddb09d1e3408e52aa8e09a14402f376070a44b1b85cb36d13', 'timestamp': '1733332749077'}
{'asset_id': '114416409796971863099144323163249651172534872992222856507897414949637892047507', 'changes': [{'price': '0.55', 'side': 'SELL', 'size': '1239.4'}], 'event_type': 'price_change', 'hash': '055f6b8676f39df6cc76417e59ec754d57499912', 'market': '0x7aa4a910b31b2c4ddb09d1e3408e52aa8e09a14402f376070a44b1b85cb36d13', 'timestamp': '1733332749077'}
{'asset_id': '114416409796971863099144323163249651172534872992222856507897414949637892047507', 'changes': [{'price': '0.54', 'side': 'SELL', 'size': '70.1'}], 'event_type': 'price_change', 'hash': '9667284030e41ad521dd8ec9d6cd91b22e22952c', 'market': '0x7aa4a910b31b2c4ddb09d1e3408e52aa8e09a14402f376070a44b1b85cb36d13', 'timestamp': '1733332749197'}
{'asset_id': '114416409796971863099144323163249651172534872992222856507897414949637892047507', 'changes': [{'price': '0.54', 'side': 'SELL', 'size': '70.1'}], 'event_type': 'price_change', 'hash': '9667284030e41ad521dd8ec9d6cd91b22e22952c', 'market': '0x7aa4a910b31b2c4ddb09d1e3408e52aa8e09a14402f376070a44b1b85cb36d13', 'timestamp': '1733332749197'}
{'asset_id': '114416409796971863099144323163249651172534872992222856507897414949637892047507', 'changes': [{'price': '0.57', 'side': 'SELL', 'size': '401.75'}], 'event_type': 'price_change', 'hash': '56b4cbfe874695e855238239b05e647071ca7a9c', 'market': '0x7aa4a910b31b2c4ddb09d1e3408e52aa8e09a14402f376070a44b1b85cb36d13', 'timestamp': '1733332755999'}
{'asset_id': '114416409796971863099144323163249651172534872992222856507897414949637892047507', 'changes': [{'price': '0.57', 'side': 'SELL', 'size': '401.75'}], 'event_type': 'price_change', 'hash': '56b4cbfe874695e855238239b05e647071ca7a9c', 'market': '0x7aa4a910b31b2c4ddb09d1e3408e52aa8e09a14402f376070a44b1b85cb36d13', 'timestamp': '1733332755999'}
{'asset_id': '114416409796971863099144323163249651172534872992222856507897414949637892047507', 'changes': [{'price': '0.56', 'side': 'SELL', 'size': '4310.1'}], 'event_type': 'price_change', 'hash': '522d581ff4a0ba1806f78cced10469b5022e6bb3', 'market': '0x7aa4a910b31b2c4ddb09d1e3408e52aa8e09a14402f376070a44b1b85cb36d13', 'timestamp': '1733332757525'}
{'asset_id': '114416409796971863099144323163249651172534872992222856507897414949637892047507', 'changes': [{'price': '0.56', 'side': 'SELL', 'size': '4310.1'}], 'event_type': 'price_change', 'hash': '522d581ff4a0ba1806f78cced10469b5022e6bb3', 'market': '0x7aa4a910b31b2c4ddb09d1e3408e52aa8e09a14402f376070a44b1b85cb36d13', 'timestamp': '1733332757525'}
{'asks': [{'price': '0.99', 'size': '4217.01'}, {'price': '0.98', 'size': '505'}, {'price': '0.97', 'size': '511.03'}, {'price': '0.96', 'size': '300'}, {'price': '0.95', 'size': '657.12'}, {'price': '0.94', 'size': '300'}, {'price': '0.92', 'size': '20000.45'}, {'price': '0.91', 'size': '10406.3'}, {'price': '0.9', 'size': '4587.5'}, {'price': '0.89', 'size': '13017.18'}, {'price': '0.88', 'size': '200'}, {'price': '0.87', 'size': '3229'}, {'price': '0.86', 'size': '17.1'}, {'price': '0.85', 'size': '109.68'}, {'price': '0.84', 'size': '250'}, {'price': '0.83', 'size': '100'}, {'price': '0.82', 'size': '16029'}, {'price': '0.81', 'size': '45721.39'}, {'price': '0.8', 'size': '26531'}, {'price': '0.79', 'size': '7110'}, {'price': '0.78', 'size': '10350'}, {'price': '0.77', 'size': '67'}, {'price': '0.76', 'size': '200'}, {'price': '0.75', 'size': '18329.25'}, {'price': '0.74', 'size': '11370.7'}, {'price': '0.73', 'size': '5020.1'}, {'price': '0.72', 'size': '380.52'}, {'price': '0.71', 'size': '15073.2'}, {'price': '0.7', 'size': '5570.1'}, {'price': '0.69', 'size': '6088.6'}, {'price': '0.68', 'size': '2131.34'}, {'price': '0.67', 'size': '3010.1'}, {'price': '0.66', 'size': '4510.1'}, {'price': '0.65', 'size': '1010.1'}, {'price': '0.64', 'size': '1230.1'}, {'price': '0.63', 'size': '210.1'}, {'price': '0.62', 'size': '300.1'}, {'price': '0.61', 'size': '511.06'}, {'price': '0.6', 'size': '467.85'}, {'price': '0.59', 'size': '5510'}, {'price': '0.58', 'size': '2188.1'}, {'price': '0.57', 'size': '401.75'}, {'price': '0.56', 'size': '4310.1'}, {'price': '0.55', 'size': '1239.4'}, {'price': '0.54', 'size': '70.1'}, {'price': '0.53', 'size': '10.1'}], 'asset_id': '114416409796971863099144323163249651172534872992222856507897414949637892047507', 'bids': [{'price': '0.01', 'size': '2850.27'}, {'price': '0.02', 'size': '500'}, {'price': '0.03', 'size': '500'}, {'price': '0.04', 'size': '300'}, {'price': '0.05', 'size': '320'}, {'price': '0.06', 'size': '300'}, {'price': '0.08', 'size': '250'}, {'price': '0.09', 'size': '300'}, {'price': '0.1', 'size': '205'}, {'price': '0.11', 'size': '5454'}, {'price': '0.12', 'size': '200'}, {'price': '0.13', 'size': '426.92'}, {'price': '0.14', 'size': '15'}, {'price': '0.15', 'size': '110'}, {'price': '0.16', 'size': '4709.51'}, {'price': '0.18', 'size': '19.13'}, {'price': '0.19', 'size': '120'}, {'price': '0.2', 'size': '691.17'}, {'price': '0.24', 'size': '5027'}, {'price': '0.25', 'size': '86.66'}, {'price': '0.27', 'size': '215.25'}, {'price': '0.29', 'size': '1102.28'}, {'price': '0.31', 'size': '1130.65'}, {'price': '0.32', 'size': '200'}, {'price': '0.33', 'size': '4620'}, {'price': '0.35', 'size': '232'}, {'price': '0.39', 'size': '10.5'}, {'price': '0.4', 'size': '3135'}, {'price': '0.41', 'size': '20'}, {'price': '0.42', 'size': '3050'}, {'price': '0.43', 'size': '50'}, {'price': '0.44', 'size': '3660'}, {'price': '0.45', 'size': '2978'}, {'price': '0.46', 'size': '500'}, {'price': '0.47', 'size': '50'}, {'price': '0.48', 'size': '2342.18'}, {'price': '0.49', 'size': '1860'}, {'price': '0.5', 'size': '1715'}, {'price': '0.51', 'size': '1086.18'}, {'price': '0.52', 'size': '310'}], 'event_type': 'book', 'hash': '57df31a63e092de48d017e8937e04ee62909fe71', 'market': '0x7aa4a910b31b2c4ddb09d1e3408e52aa8e09a14402f376070a44b1b85cb36d13', 'timestamp': '1733332759414'}
{'asks': [{'price': '0.99', 'size': '4217.01'}, {'price': '0.98', 'size': '505'}, {'price': '0.97', 'size': '511.03'}, {'price': '0.96', 'size': '300'}, {'price': '0.95', 'size': '657.12'}, {'price': '0.94', 'size': '300'}, {'price': '0.92', 'size': '20000.45'}, {'price': '0.91', 'size': '10406.3'}, {'price': '0.9', 'size': '4587.5'}, {'price': '0.89', 'size': '13017.18'}, {'price': '0.88', 'size': '200'}, {'price': '0.87', 'size': '3229'}, {'price': '0.86', 'size': '17.1'}, {'price': '0.85', 'size': '109.68'}, {'price': '0.84', 'size': '250'}, {'price': '0.83', 'size': '100'}, {'price': '0.82', 'size': '16029'}, {'price': '0.81', 'size': '45721.39'}, {'price': '0.8', 'size': '26531'}, {'price': '0.79', 'size': '7110'}, {'price': '0.78', 'size': '10350'}, {'price': '0.77', 'size': '67'}, {'price': '0.76', 'size': '200'}, {'price': '0.75', 'size': '18329.25'}, {'price': '0.74', 'size': '11370.7'}, {'price': '0.73', 'size': '5020.1'}, {'price': '0.72', 'size': '380.52'}, {'price': '0.71', 'size': '15073.2'}, {'price': '0.7', 'size': '5570.1'}, {'price': '0.69', 'size': '6088.6'}, {'price': '0.68', 'size': '2131.34'}, {'price': '0.67', 'size': '3010.1'}, {'price': '0.66', 'size': '4510.1'}, {'price': '0.65', 'size': '1010.1'}, {'price': '0.64', 'size': '1230.1'}, {'price': '0.63', 'size': '210.1'}, {'price': '0.62', 'size': '300.1'}, {'price': '0.61', 'size': '511.06'}, {'price': '0.6', 'size': '467.85'}, {'price': '0.59', 'size': '5510'}, {'price': '0.58', 'size': '2188.1'}, {'price': '0.57', 'size': '401.75'}, {'price': '0.56', 'size': '4310.1'}, {'price': '0.55', 'size': '1239.4'}, {'price': '0.54', 'size': '70.1'}, {'price': '0.53', 'size': '10.1'}], 'asset_id': '114416409796971863099144323163249651172534872992222856507897414949637892047507', 'bids': [{'price': '0.01', 'size': '2850.27'}, {'price': '0.02', 'size': '500'}, {'price': '0.03', 'size': '500'}, {'price': '0.04', 'size': '300'}, {'price': '0.05', 'size': '320'}, {'price': '0.06', 'size': '300'}, {'price': '0.08', 'size': '250'}, {'price': '0.09', 'size': '300'}, {'price': '0.1', 'size': '205'}, {'price': '0.11', 'size': '5454'}, {'price': '0.12', 'size': '200'}, {'price': '0.13', 'size': '426.92'}, {'price': '0.14', 'size': '15'}, {'price': '0.15', 'size': '110'}, {'price': '0.16', 'size': '4709.51'}, {'price': '0.18', 'size': '19.13'}, {'price': '0.19', 'size': '120'}, {'price': '0.2', 'size': '691.17'}, {'price': '0.24', 'size': '5027'}, {'price': '0.25', 'size': '86.66'}, {'price': '0.27', 'size': '215.25'}, {'price': '0.29', 'size': '1102.28'}, {'price': '0.31', 'size': '1130.65'}, {'price': '0.32', 'size': '200'}, {'price': '0.33', 'size': '4620'}, {'price': '0.35', 'size': '232'}, {'price': '0.39', 'size': '10.5'}, {'price': '0.4', 'size': '3135'}, {'price': '0.41', 'size': '20'}, {'price': '0.42', 'size': '3050'}, {'price': '0.43', 'size': '50'}, {'price': '0.44', 'size': '3660'}, {'price': '0.45', 'size': '2978'}, {'price': '0.46', 'size': '500'}, {'price': '0.47', 'size': '50'}, {'price': '0.48', 'size': '2342.18'}, {'price': '0.49', 'size': '1860'}, {'price': '0.5', 'size': '1715'}, {'price': '0.51', 'size': '1086.18'}, {'price': '0.52', 'size': '310'}], 'event_type': 'book', 'hash': '57df31a63e092de48d017e8937e04ee62909fe71', 'market': '0x7aa4a910b31b2c4ddb09d1e3408e52aa8e09a14402f376070a44b1b85cb36d13', 'timestamp': '1733332759414'}
{'asks': [{'price': '0.99', 'size': '4217.01'}, {'price': '0.98', 'size': '505'}, {'price': '0.97', 'size': '511.03'}, {'price': '0.96', 'size': '300'}, {'price': '0.95', 'size': '657.12'}, {'price': '0.94', 'size': '300'}, {'price': '0.92', 'size': '20000.45'}, {'price': '0.91', 'size': '10406.3'}, {'price': '0.9', 'size': '4587.5'}, {'price': '0.89', 'size': '13017.18'}, {'price': '0.88', 'size': '200'}, {'price': '0.87', 'size': '3229'}, {'price': '0.86', 'size': '17.1'}, {'price': '0.85', 'size': '109.68'}, {'price': '0.84', 'size': '250'}, {'price': '0.83', 'size': '100'}, {'price': '0.82', 'size': '16029'}, {'price': '0.81', 'size': '45721.39'}, {'price': '0.8', 'size': '26531'}, {'price': '0.79', 'size': '7110'}, {'price': '0.78', 'size': '10350'}, {'price': '0.77', 'size': '67'}, {'price': '0.76', 'size': '200'}, {'price': '0.75', 'size': '18329.25'}, {'price': '0.74', 'size': '11370.7'}, {'price': '0.73', 'size': '5020.1'}, {'price': '0.72', 'size': '380.52'}, {'price': '0.71', 'size': '15073.2'}, {'price': '0.7', 'size': '5570.1'}, {'price': '0.69', 'size': '6088.6'}, {'price': '0.68', 'size': '2131.34'}, {'price': '0.67', 'size': '3010.1'}, {'price': '0.66', 'size': '4510.1'}, {'price': '0.65', 'size': '1010.1'}, {'price': '0.64', 'size': '1230.1'}, {'price': '0.63', 'size': '210.1'}, {'price': '0.62', 'size': '300.1'}, {'price': '0.61', 'size': '511.06'}, {'price': '0.6', 'size': '467.85'}, {'price': '0.59', 'size': '5510'}, {'price': '0.58', 'size': '2188.1'}, {'price': '0.57', 'size': '401.75'}, {'price': '0.56', 'size': '4310.1'}, {'price': '0.55', 'size': '1239.4'}, {'price': '0.54', 'size': '70.1'}, {'price': '0.53', 'size': '10.1'}, {'price': '0.52', 'size': '134'}], 'asset_id': '114416409796971863099144323163249651172534872992222856507897414949637892047507', 'bids': [{'price': '0.01', 'size': '2850.27'}, {'price': '0.02', 'size': '500'}, {'price': '0.03', 'size': '500'}, {'price': '0.04', 'size': '300'}, {'price': '0.05', 'size': '320'}, {'price': '0.06', 'size': '300'}, {'price': '0.08', 'size': '250'}, {'price': '0.09', 'size': '300'}, {'price': '0.1', 'size': '205'}, {'price': '0.11', 'size': '5454'}, {'price': '0.12', 'size': '200'}, {'price': '0.13', 'size': '426.92'}, {'price': '0.14', 'size': '15'}, {'price': '0.15', 'size': '110'}, {'price': '0.16', 'size': '4709.51'}, {'price': '0.18', 'size': '19.13'}, {'price': '0.19', 'size': '120'}, {'price': '0.2', 'size': '691.17'}, {'price': '0.24', 'size': '5027'}, {'price': '0.25', 'size': '86.66'}, {'price': '0.27', 'size': '215.25'}, {'price': '0.29', 'size': '1102.28'}, {'price': '0.31', 'size': '1130.65'}, {'price': '0.32', 'size': '200'}, {'price': '0.33', 'size': '4620'}, {'price': '0.35', 'size': '232'}, {'price': '0.39', 'size': '10.5'}, {'price': '0.4', 'size': '3135'}, {'price': '0.41', 'size': '20'}, {'price': '0.42', 'size': '3050'}, {'price': '0.43', 'size': '50'}, {'price': '0.44', 'size': '3660'}, {'price': '0.45', 'size': '2978'}, {'price': '0.46', 'size': '500'}, {'price': '0.47', 'size': '50'}, {'price': '0.48', 'size': '2342.18'}, {'price': '0.49', 'size': '1860'}, {'price': '0.5', 'size': '1715'}, {'price': '0.51', 'size': '1086.18'}], 'event_type': 'book', 'hash': 'de67e949f8261eb9fa118d11f4c37d37ff47bf36', 'market': '0x7aa4a910b31b2c4ddb09d1e3408e52aa8e09a14402f376070a44b1b85cb36d13', 'timestamp': '1733332760765'}
{'asset_id': '114416409796971863099144323163249651172534872992222856507897414949637892047507', 'changes': [{'price': '0.52', 'side': 'SELL', 'size': '134'}], 'event_type': 'price_change', 'hash': 'de67e949f8261eb9fa118d11f4c37d37ff47bf36', 'market': '0x7aa4a910b31b2c4ddb09d1e3408e52aa8e09a14402f376070a44b1b85cb36d13', 'timestamp': '1733332760773'}
{'asks': [{'price': '0.99', 'size': '4217.01'}, {'price': '0.98', 'size': '505'}, {'price': '0.97', 'size': '511.03'}, {'price': '0.96', 'size': '300'}, {'price': '0.95', 'size': '657.12'}, {'price': '0.94', 'size': '300'}, {'price': '0.92', 'size': '20000.45'}, {'price': '0.91', 'size': '10406.3'}, {'price': '0.9', 'size': '4587.5'}, {'price': '0.89', 'size': '13017.18'}, {'price': '0.88', 'size': '200'}, {'price': '0.87', 'size': '3229'}, {'price': '0.86', 'size': '17.1'}, {'price': '0.85', 'size': '109.68'}, {'price': '0.84', 'size': '250'}, {'price': '0.83', 'size': '100'}, {'price': '0.82', 'size': '16029'}, {'price': '0.81', 'size': '45721.39'}, {'price': '0.8', 'size': '26531'}, {'price': '0.79', 'size': '7110'}, {'price': '0.78', 'size': '10350'}, {'price': '0.77', 'size': '67'}, {'price': '0.76', 'size': '200'}, {'price': '0.75', 'size': '18329.25'}, {'price': '0.74', 'size': '11370.7'}, {'price': '0.73', 'size': '5020.1'}, {'price': '0.72', 'size': '380.52'}, {'price': '0.71', 'size': '15073.2'}, {'price': '0.7', 'size': '5570.1'}, {'price': '0.69', 'size': '6088.6'}, {'price': '0.68', 'size': '2131.34'}, {'price': '0.67', 'size': '3010.1'}, {'price': '0.66', 'size': '4510.1'}, {'price': '0.65', 'size': '1010.1'}, {'price': '0.64', 'size': '1230.1'}, {'price': '0.63', 'size': '210.1'}, {'price': '0.62', 'size': '300.1'}, {'price': '0.61', 'size': '511.06'}, {'price': '0.6', 'size': '467.85'}, {'price': '0.59', 'size': '5510'}, {'price': '0.58', 'size': '2188.1'}, {'price': '0.57', 'size': '401.75'}, {'price': '0.56', 'size': '4310.1'}, {'price': '0.55', 'size': '1239.4'}, {'price': '0.54', 'size': '70.1'}, {'price': '0.53', 'size': '10.1'}, {'price': '0.52', 'size': '134'}], 'asset_id': '114416409796971863099144323163249651172534872992222856507897414949637892047507', 'bids': [{'price': '0.01', 'size': '2850.27'}, {'price': '0.02', 'size': '500'}, {'price': '0.03', 'size': '500'}, {'price': '0.04', 'size': '300'}, {'price': '0.05', 'size': '320'}, {'price': '0.06', 'size': '300'}, {'price': '0.08', 'size': '250'}, {'price': '0.09', 'size': '300'}, {'price': '0.1', 'size': '205'}, {'price': '0.11', 'size': '5454'}, {'price': '0.12', 'size': '200'}, {'price': '0.13', 'size': '426.92'}, {'price': '0.14', 'size': '15'}, {'price': '0.15', 'size': '110'}, {'price': '0.16', 'size': '4709.51'}, {'price': '0.18', 'size': '19.13'}, {'price': '0.19', 'size': '120'}, {'price': '0.2', 'size': '691.17'}, {'price': '0.24', 'size': '5027'}, {'price': '0.25', 'size': '86.66'}, {'price': '0.27', 'size': '215.25'}, {'price': '0.29', 'size': '1102.28'}, {'price': '0.31', 'size': '1130.65'}, {'price': '0.32', 'size': '200'}, {'price': '0.33', 'size': '4620'}, {'price': '0.35', 'size': '232'}, {'price': '0.39', 'size': '10.5'}, {'price': '0.4', 'size': '3135'}, {'price': '0.41', 'size': '20'}, {'price': '0.42', 'size': '3050'}, {'price': '0.43', 'size': '50'}, {'price': '0.44', 'size': '3660'}, {'price': '0.45', 'size': '2978'}, {'price': '0.46', 'size': '500'}, {'price': '0.47', 'size': '50'}, {'price': '0.48', 'size': '2342.18'}, {'price': '0.49', 'size': '1860'}, {'price': '0.5', 'size': '1715'}, {'price': '0.51', 'size': '1086.18'}], 'event_type': 'book', 'hash': 'de67e949f8261eb9fa118d11f4c37d37ff47bf36', 'market': '0x7aa4a910b31b2c4ddb09d1e3408e52aa8e09a14402f376070a44b1b85cb36d13', 'timestamp': '1733332760765'}
{'asset_id': '114416409796971863099144323163249651172534872992222856507897414949637892047507', 'changes': [{'price': '0.52', 'side': 'SELL', 'size': '134'}], 'event_type': 'price_change', 'hash': 'de67e949f8261eb9fa118d11f4c37d37ff47bf36', 'market': '0x7aa4a910b31b2c4ddb09d1e3408e52aa8e09a14402f376070a44b1b85cb36d13', 'timestamp': '1733332760773'}
{'asks': [{'price': '0.99', 'size': '4217.01'}, {'price': '0.98', 'size': '505'}, {'price': '0.97', 'size': '511.03'}, {'price': '0.96', 'size': '300'}, {'price': '0.95', 'size': '657.12'}, {'price': '0.94', 'size': '300'}, {'price': '0.92', 'size': '20000.45'}, {'price': '0.91', 'size': '10406.3'}, {'price': '0.9', 'size': '4587.5'}, {'price': '0.89', 'size': '13017.18'}, {'price': '0.88', 'size': '200'}, {'price': '0.87', 'size': '3229'}, {'price': '0.86', 'size': '17.1'}, {'price': '0.85', 'size': '109.68'}, {'price': '0.84', 'size': '250'}, {'price': '0.83', 'size': '100'}, {'price': '0.82', 'size': '16029'}, {'price': '0.81', 'size': '45721.39'}, {'price': '0.8', 'size': '26531'}, {'price': '0.79', 'size': '7110'}, {'price': '0.78', 'size': '10350'}, {'price': '0.77', 'size': '67'}, {'price': '0.76', 'size': '200'}, {'price': '0.75', 'size': '18329.25'}, {'price': '0.74', 'size': '11370.7'}, {'price': '0.73', 'size': '5020.1'}, {'price': '0.72', 'size': '380.52'}, {'price': '0.71', 'size': '15073.2'}, {'price': '0.7', 'size': '5570.1'}, {'price': '0.69', 'size': '6088.6'}, {'price': '0.68', 'size': '2131.34'}, {'price': '0.67', 'size': '3010.1'}, {'price': '0.66', 'size': '4510.1'}, {'price': '0.65', 'size': '1010.1'}, {'price': '0.64', 'size': '1230.1'}, {'price': '0.63', 'size': '210.1'}, {'price': '0.62', 'size': '300.1'}, {'price': '0.61', 'size': '511.06'}, {'price': '0.6', 'size': '467.85'}, {'price': '0.59', 'size': '5510'}, {'price': '0.58', 'size': '2188.1'}, {'price': '0.57', 'size': '401.75'}, {'price': '0.56', 'size': '4310.1'}, {'price': '0.55', 'size': '1139.4'}, {'price': '0.54', 'size': '70.1'}, {'price': '0.53', 'size': '10.1'}, {'price': '0.52', 'size': '109'}], 'asset_id': '114416409796971863099144323163249651172534872992222856507897414949637892047507', 'bids': [{'price': '0.01', 'size': '2850.27'}, {'price': '0.02', 'size': '500'}, {'price': '0.03', 'size': '500'}, {'price': '0.04', 'size': '300'}, {'price': '0.05', 'size': '320'}, {'price': '0.06', 'size': '300'}, {'price': '0.08', 'size': '250'}, {'price': '0.09', 'size': '300'}, {'price': '0.1', 'size': '205'}, {'price': '0.11', 'size': '5454'}, {'price': '0.12', 'size': '200'}, {'price': '0.13', 'size': '426.92'}, {'price': '0.14', 'size': '15'}, {'price': '0.15', 'size': '110'}, {'price': '0.16', 'size': '4709.51'}, {'price': '0.18', 'size': '19.13'}, {'price': '0.19', 'size': '120'}, {'price': '0.2', 'size': '691.17'}, {'price': '0.24', 'size': '5027'}, {'price': '0.25', 'size': '86.66'}, {'price': '0.27', 'size': '215.25'}, {'price': '0.29', 'size': '1102.28'}, {'price': '0.31', 'size': '1130.65'}, {'price': '0.32', 'size': '200'}, {'price': '0.33', 'size': '4620'}, {'price': '0.35', 'size': '232'}, {'price': '0.39', 'size': '10.5'}, {'price': '0.4', 'size': '3135'}, {'price': '0.41', 'size': '20'}, {'price': '0.42', 'size': '3050'}, {'price': '0.43', 'size': '50'}, {'price': '0.44', 'size': '3660'}, {'price': '0.45', 'size': '2978'}, {'price': '0.46', 'size': '500'}, {'price': '0.47', 'size': '50'}, {'price': '0.48', 'size': '2342.18'}, {'price': '0.49', 'size': '1860'}, {'price': '0.5', 'size': '1715'}, {'price': '0.51', 'size': '1086.18'}], 'event_type': 'book', 'hash': '0164bbb1e650a6f881d8d34758eaf44199e11f0b', 'market': '0x7aa4a910b31b2c4ddb09d1e3408e52aa8e09a14402f376070a44b1b85cb36d13', 'timestamp': '1733332761683'}
{'asks': [{'price': '0.99', 'size': '4217.01'}, {'price': '0.98', 'size': '505'}, {'price': '0.97', 'size': '511.03'}, {'price': '0.96', 'size': '300'}, {'price': '0.95', 'size': '657.12'}, {'price': '0.94', 'size': '300'}, {'price': '0.92', 'size': '20000.45'}, {'price': '0.91', 'size': '10406.3'}, {'price': '0.9', 'size': '4587.5'}, {'price': '0.89', 'size': '13017.18'}, {'price': '0.88', 'size': '200'}, {'price': '0.87', 'size': '3229'}, {'price': '0.86', 'size': '17.1'}, {'price': '0.85', 'size': '109.68'}, {'price': '0.84', 'size': '250'}, {'price': '0.83', 'size': '100'}, {'price': '0.82', 'size': '16029'}, {'price': '0.81', 'size': '45721.39'}, {'price': '0.8', 'size': '26531'}, {'price': '0.79', 'size': '7110'}, {'price': '0.78', 'size': '10350'}, {'price': '0.77', 'size': '67'}, {'price': '0.76', 'size': '200'}, {'price': '0.75', 'size': '18329.25'}, {'price': '0.74', 'size': '11370.7'}, {'price': '0.73', 'size': '5020.1'}, {'price': '0.72', 'size': '380.52'}, {'price': '0.71', 'size': '15073.2'}, {'price': '0.7', 'size': '5570.1'}, {'price': '0.69', 'size': '6088.6'}, {'price': '0.68', 'size': '2131.34'}, {'price': '0.67', 'size': '3010.1'}, {'price': '0.66', 'size': '4510.1'}, {'price': '0.65', 'size': '1010.1'}, {'price': '0.64', 'size': '1230.1'}, {'price': '0.63', 'size': '210.1'}, {'price': '0.62', 'size': '300.1'}, {'price': '0.61', 'size': '511.06'}, {'price': '0.6', 'size': '467.85'}, {'price': '0.59', 'size': '5510'}, {'price': '0.58', 'size': '2188.1'}, {'price': '0.57', 'size': '401.75'}, {'price': '0.56', 'size': '4310.1'}, {'price': '0.55', 'size': '1139.4'}, {'price': '0.54', 'size': '70.1'}, {'price': '0.53', 'size': '10.1'}, {'price': '0.52', 'size': '109'}], 'asset_id': '114416409796971863099144323163249651172534872992222856507897414949637892047507', 'bids': [{'price': '0.01', 'size': '2850.27'}, {'price': '0.02', 'size': '500'}, {'price': '0.03', 'size': '500'}, {'price': '0.04', 'size': '300'}, {'price': '0.05', 'size': '320'}, {'price': '0.06', 'size': '300'}, {'price': '0.08', 'size': '250'}, {'price': '0.09', 'size': '300'}, {'price': '0.1', 'size': '205'}, {'price': '0.11', 'size': '5454'}, {'price': '0.12', 'size': '200'}, {'price': '0.13', 'size': '426.92'}, {'price': '0.14', 'size': '15'}, {'price': '0.15', 'size': '110'}, {'price': '0.16', 'size': '4709.51'}, {'price': '0.18', 'size': '19.13'}, {'price': '0.19', 'size': '120'}, {'price': '0.2', 'size': '691.17'}, {'price': '0.24', 'size': '5027'}, {'price': '0.25', 'size': '86.66'}, {'price': '0.27', 'size': '215.25'}, {'price': '0.29', 'size': '1102.28'}, {'price': '0.31', 'size': '1130.65'}, {'price': '0.32', 'size': '200'}, {'price': '0.33', 'size': '4620'}, {'price': '0.35', 'size': '232'}, {'price': '0.39', 'size': '10.5'}, {'price': '0.4', 'size': '3135'}, {'price': '0.41', 'size': '20'}, {'price': '0.42', 'size': '3050'}, {'price': '0.43', 'size': '50'}, {'price': '0.44', 'size': '3660'}, {'price': '0.45', 'size': '2978'}, {'price': '0.46', 'size': '500'}, {'price': '0.47', 'size': '50'}, {'price': '0.48', 'size': '2342.18'}, {'price': '0.49', 'size': '1860'}, {'price': '0.5', 'size': '1715'}, {'price': '0.51', 'size': '1086.18'}], 'event_type': 'book', 'hash': '0164bbb1e650a6f881d8d34758eaf44199e11f0b', 'market': '0x7aa4a910b31b2c4ddb09d1e3408e52aa8e09a14402f376070a44b1b85cb36d13', 'timestamp': '1733332761683'}
{'asset_id': '114416409796971863099144323163249651172534872992222856507897414949637892047507', 'event_type': 'last_trade_price', 'fee_rate_bps': '0', 'market': '0x7aa4a910b31b2c4ddb09d1e3408e52aa8e09a14402f376070a44b1b85cb36d13', 'price': '0.52', 'side': 'BUY', 'size': '25', 'timestamp': '1733332761690'}
{'asset_id': '114416409796971863099144323163249651172534872992222856507897414949637892047507', 'event_type': 'last_trade_price', 'fee_rate_bps': '0', 'market': '0x7aa4a910b31b2c4ddb09d1e3408e52aa8e09a14402f376070a44b1b85cb36d13', 'price': '0.52', 'side': 'BUY', 'size': '25', 'timestamp': '1733332761690'}
{'asset_id': '114416409796971863099144323163249651172534872992222856507897414949637892047507', 'changes': [{'price': '0.55', 'side': 'SELL', 'size': '1139.4'}], 'event_type': 'price_change', 'hash': '0164bbb1e650a6f881d8d34758eaf44199e11f0b', 'market': '0x7aa4a910b31b2c4ddb09d1e3408e52aa8e09a14402f376070a44b1b85cb36d13', 'timestamp': '1733332761693'}
{'asset_id': '114416409796971863099144323163249651172534872992222856507897414949637892047507', 'changes': [{'price': '0.55', 'side': 'SELL', 'size': '1139.4'}], 'event_type': 'price_change', 'hash': '0164bbb1e650a6f881d8d34758eaf44199e11f0b', 'market': '0x7aa4a910b31b2c4ddb09d1e3408e52aa8e09a14402f376070a44b1b85cb36d13', 'timestamp': '1733332761693'}
{'asset_id': '114416409796971863099144323163249651172534872992222856507897414949637892047507', 'changes': [{'price': '0.54', 'side': 'SELL', 'size': '10.1'}], 'event_type': 'price_change', 'hash': 'b906b281b86425382ba0a8ca040939d398aedfb8', 'market': '0x7aa4a910b31b2c4ddb09d1e3408e52aa8e09a14402f376070a44b1b85cb36d13', 'timestamp': '1733332768124'}
{'asset_id': '114416409796971863099144323163249651172534872992222856507897414949637892047507', 'changes': [{'price': '0.54', 'side': 'SELL', 'size': '10.1'}], 'event_type': 'price_change', 'hash': 'b906b281b86425382ba0a8ca040939d398aedfb8', 'market': '0x7aa4a910b31b2c4ddb09d1e3408e52aa8e09a14402f376070a44b1b85cb36d13', 'timestamp': '1733332768124'}
{'asset_id': '114416409796971863099144323163249651172534872992222856507897414949637892047507', 'changes': [{'price': '0.53', 'side': 'SELL', 'size': '70.1'}], 'event_type': 'price_change', 'hash': 'd91a4eb50c60307f3aabc0e49a3ee53afd870b00', 'market': '0x7aa4a910b31b2c4ddb09d1e3408e52aa8e09a14402f376070a44b1b85cb36d13', 'timestamp': '1733332768255'}
{'asset_id': '114416409796971863099144323163249651172534872992222856507897414949637892047507', 'changes': [{'price': '0.53', 'side': 'SELL', 'size': '70.1'}], 'event_type': 'price_change', 'hash': 'd91a4eb50c60307f3aabc0e49a3ee53afd870b00', 'market': '0x7aa4a910b31b2c4ddb09d1e3408e52aa8e09a14402f376070a44b1b85cb36d13', 'timestamp': '1733332768255'}
{'asset_id': '114416409796971863099144323163249651172534872992222856507897414949637892047507', 'changes': [{'price': '0.58', 'side': 'SELL', 'size': '2138.1'}], 'event_type': 'price_change', 'hash': 'ff1d666d4c5b6ff32749671d1554798fd54d8dd2', 'market': '0x7aa4a910b31b2c4ddb09d1e3408e52aa8e09a14402f376070a44b1b85cb36d13', 'timestamp': '1733332769074'}
{'asset_id': '114416409796971863099144323163249651172534872992222856507897414949637892047507', 'changes': [{'price': '0.58', 'side': 'SELL', 'size': '2138.1'}], 'event_type': 'price_change', 'hash': 'ff1d666d4c5b6ff32749671d1554798fd54d8dd2', 'market': '0x7aa4a910b31b2c4ddb09d1e3408e52aa8e09a14402f376070a44b1b85cb36d13', 'timestamp': '1733332769074'}
{'asset_id': '114416409796971863099144323163249651172534872992222856507897414949637892047507', 'changes': [{'price': '0.51', 'side': 'BUY', 'size': '1036.18'}], 'event_type': 'price_change', 'hash': '51ae08542c5c4234d82a8b2a6ecfd77ad4f709a7', 'market': '0x7aa4a910b31b2c4ddb09d1e3408e52aa8e09a14402f376070a44b1b85cb36d13', 'timestamp': '1733332769590'}
{'asset_id': '114416409796971863099144323163249651172534872992222856507897414949637892047507', 'changes': [{'price': '0.51', 'side': 'BUY', 'size': '1036.18'}], 'event_type': 'price_change', 'hash': '51ae08542c5c4234d82a8b2a6ecfd77ad4f709a7', 'market': '0x7aa4a910b31b2c4ddb09d1e3408e52aa8e09a14402f376070a44b1b85cb36d13', 'timestamp': '1733332769590'}
{'asset_id': '114416409796971863099144323163249651172534872992222856507897414949637892047507', 'changes': [{'price': '0.54', 'side': 'SELL', 'size': '60.1'}], 'event_type': 'price_change', 'hash': '57df2e421c7f2133d7b1b6572423f087e073d091', 'market': '0x7aa4a910b31b2c4ddb09d1e3408e52aa8e09a14402f376070a44b1b85cb36d13', 'timestamp': '1733332769897'}
{'asset_id': '114416409796971863099144323163249651172534872992222856507897414949637892047507', 'changes': [{'price': '0.54', 'side': 'SELL', 'size': '60.1'}], 'event_type': 'price_change', 'hash': '57df2e421c7f2133d7b1b6572423f087e073d091', 'market': '0x7aa4a910b31b2c4ddb09d1e3408e52aa8e09a14402f376070a44b1b85cb36d13', 'timestamp': '1733332769897'}
{'asset_id': '114416409796971863099144323163249651172534872992222856507897414949637892047507', 'changes': [{'price': '0.47', 'side': 'BUY', 'size': '100'}, {'price': '0.58', 'side': 'SELL', 'size': '2088.1'}], 'event_type': 'price_change', 'hash': '6540c762d819ea33ab327189f77384c6ffa2cd56', 'market': '0x7aa4a910b31b2c4ddb09d1e3408e52aa8e09a14402f376070a44b1b85cb36d13', 'timestamp': '1733332770171'}
{'asset_id': '114416409796971863099144323163249651172534872992222856507897414949637892047507', 'changes': [{'price': '0.47', 'side': 'BUY', 'size': '100'}, {'price': '0.58', 'side': 'SELL', 'size': '2088.1'}], 'event_type': 'price_change', 'hash': '6540c762d819ea33ab327189f77384c6ffa2cd56', 'market': '0x7aa4a910b31b2c4ddb09d1e3408e52aa8e09a14402f376070a44b1b85cb36d13', 'timestamp': '1733332770171'}
{'asset_id': '114416409796971863099144323163249651172534872992222856507897414949637892047507', 'changes': [{'price': '0.49', 'side': 'BUY', 'size': '1640'}, {'price': '0.57', 'side': 'SELL', 'size': '161.75'}], 'event_type': 'price_change', 'hash': '3e032bfe4f4df09d0ac6757944f87d75d06fd78e', 'market': '0x7aa4a910b31b2c4ddb09d1e3408e52aa8e09a14402f376070a44b1b85cb36d13', 'timestamp': '1733332770319'}
{'asset_id': '114416409796971863099144323163249651172534872992222856507897414949637892047507', 'changes': [{'price': '0.49', 'side': 'BUY', 'size': '1640'}, {'price': '0.57', 'side': 'SELL', 'size': '161.75'}], 'event_type': 'price_change', 'hash': '3e032bfe4f4df09d0ac6757944f87d75d06fd78e', 'market': '0x7aa4a910b31b2c4ddb09d1e3408e52aa8e09a14402f376070a44b1b85cb36d13', 'timestamp': '1733332770319'}
{'asset_id': '114416409796971863099144323163249651172534872992222856507897414949637892047507', 'changes': [{'price': '0.56', 'side': 'SELL', 'size': '4580.1'}], 'event_type': 'price_change', 'hash': 'e6d1f81549dbe4a4b0a6feccd5406726462f3e55', 'market': '0x7aa4a910b31b2c4ddb09d1e3408e52aa8e09a14402f376070a44b1b85cb36d13', 'timestamp': '1733332770603'}
{'asset_id': '114416409796971863099144323163249651172534872992222856507897414949637892047507', 'changes': [{'price': '0.56', 'side': 'SELL', 'size': '4580.1'}], 'event_type': 'price_change', 'hash': 'e6d1f81549dbe4a4b0a6feccd5406726462f3e55', 'market': '0x7aa4a910b31b2c4ddb09d1e3408e52aa8e09a14402f376070a44b1b85cb36d13', 'timestamp': '1733332770603'}
{'asset_id': '114416409796971863099144323163249651172534872992222856507897414949637892047507', 'changes': [{'price': '0.47', 'side': 'BUY', 'size': '360'}, {'price': '0.51', 'side': 'BUY', 'size': '986.18'}], 'event_type': 'price_change', 'hash': '614b2cbd76e369a2b3b14d0bf4858a4a5e3aa604', 'market': '0x7aa4a910b31b2c4ddb09d1e3408e52aa8e09a14402f376070a44b1b85cb36d13', 'timestamp': '1733332770683'}
{'asset_id': '114416409796971863099144323163249651172534872992222856507897414949637892047507', 'changes': [{'price': '0.47', 'side': 'BUY', 'size': '360'}, {'price': '0.51', 'side': 'BUY', 'size': '986.18'}], 'event_type': 'price_change', 'hash': '614b2cbd76e369a2b3b14d0bf4858a4a5e3aa604', 'market': '0x7aa4a910b31b2c4ddb09d1e3408e52aa8e09a14402f376070a44b1b85cb36d13', 'timestamp': '1733332770683'}
{'asset_id': '114416409796971863099144323163249651172534872992222856507897414949637892047507', 'changes': [{'price': '0.54', 'side': 'SELL', 'size': '110.1'}], 'event_type': 'price_change', 'hash': '088a980d76ffd97d3f430c948311b2d718e00d43', 'market': '0x7aa4a910b31b2c4ddb09d1e3408e52aa8e09a14402f376070a44b1b85cb36d13', 'timestamp': '1733332770984'}
{'asset_id': '114416409796971863099144323163249651172534872992222856507897414949637892047507', 'changes': [{'price': '0.54', 'side': 'SELL', 'size': '110.1'}], 'event_type': 'price_change', 'hash': '088a980d76ffd97d3f430c948311b2d718e00d43', 'market': '0x7aa4a910b31b2c4ddb09d1e3408e52aa8e09a14402f376070a44b1b85cb36d13', 'timestamp': '1733332770984'}
{'asset_id': '114416409796971863099144323163249651172534872992222856507897414949637892047507', 'changes': [{'price': '0.47', 'side': 'BUY', 'size': '410'}], 'event_type': 'price_change', 'hash': '721347ec082d37844111b2cb768ed8d1a7ebca91', 'market': '0x7aa4a910b31b2c4ddb09d1e3408e52aa8e09a14402f376070a44b1b85cb36d13', 'timestamp': '1733332771344'}
{'asset_id': '114416409796971863099144323163249651172534872992222856507897414949637892047507', 'changes': [{'price': '0.47', 'side': 'BUY', 'size': '410'}], 'event_type': 'price_change', 'hash': '721347ec082d37844111b2cb768ed8d1a7ebca91', 'market': '0x7aa4a910b31b2c4ddb09d1e3408e52aa8e09a14402f376070a44b1b85cb36d13', 'timestamp': '1733332771344'}
{'asset_id': '114416409796971863099144323163249651172534872992222856507897414949637892047507', 'changes': [{'price': '0.54', 'side': 'SELL', 'size': '210.1'}], 'event_type': 'price_change', 'hash': 'd1953940a152d48387aea8a2a22d69130c54e4a2', 'market': '0x7aa4a910b31b2c4ddb09d1e3408e52aa8e09a14402f376070a44b1b85cb36d13', 'timestamp': '1733332774236'}
{'asset_id': '114416409796971863099144323163249651172534872992222856507897414949637892047507', 'changes': [{'price': '0.54', 'side': 'SELL', 'size': '210.1'}], 'event_type': 'price_change', 'hash': 'd1953940a152d48387aea8a2a22d69130c54e4a2', 'market': '0x7aa4a910b31b2c4ddb09d1e3408e52aa8e09a14402f376070a44b1b85cb36d13', 'timestamp': '1733332774236'}
{'asset_id': '114416409796971863099144323163249651172534872992222856507897414949637892047507', 'changes': [{'price': '0.54', 'side': 'SELL', 'size': '110.1'}], 'event_type': 'price_change', 'hash': '3afc9cfec85bb07ba31ba1f4e420cc4ff3420584', 'market': '0x7aa4a910b31b2c4ddb09d1e3408e52aa8e09a14402f376070a44b1b85cb36d13', 'timestamp': '1733332780045'}
{'asset_id': '114416409796971863099144323163249651172534872992222856507897414949637892047507', 'changes': [{'price': '0.54', 'side': 'SELL', 'size': '110.1'}], 'event_type': 'price_change', 'hash': '3afc9cfec85bb07ba31ba1f4e420cc4ff3420584', 'market': '0x7aa4a910b31b2c4ddb09d1e3408e52aa8e09a14402f376070a44b1b85cb36d13', 'timestamp': '1733332780045'}
{'asks': [{'price': '0.99', 'size': '4217.01'}, {'price': '0.98', 'size': '505'}, {'price': '0.97', 'size': '511.03'}, {'price': '0.96', 'size': '300'}, {'price': '0.95', 'size': '657.12'}, {'price': '0.94', 'size': '300'}, {'price': '0.92', 'size': '20000.45'}, {'price': '0.91', 'size': '10406.3'}, {'price': '0.9', 'size': '4587.5'}, {'price': '0.89', 'size': '13017.18'}, {'price': '0.88', 'size': '200'}, {'price': '0.87', 'size': '3229'}, {'price': '0.86', 'size': '17.1'}, {'price': '0.85', 'size': '109.68'}, {'price': '0.84', 'size': '250'}, {'price': '0.83', 'size': '100'}, {'price': '0.82', 'size': '16029'}, {'price': '0.81', 'size': '45721.39'}, {'price': '0.8', 'size': '26531'}, {'price': '0.79', 'size': '7110'}, {'price': '0.78', 'size': '10350'}, {'price': '0.77', 'size': '67'}, {'price': '0.76', 'size': '200'}, {'price': '0.75', 'size': '18329.25'}, {'price': '0.74', 'size': '11370.7'}, {'price': '0.73', 'size': '5020.1'}, {'price': '0.72', 'size': '380.52'}, {'price': '0.71', 'size': '15073.2'}, {'price': '0.7', 'size': '5570.1'}, {'price': '0.69', 'size': '6088.6'}, {'price': '0.68', 'size': '2131.34'}, {'price': '0.67', 'size': '3010.1'}, {'price': '0.66', 'size': '4510.1'}, {'price': '0.65', 'size': '1010.1'}, {'price': '0.64', 'size': '1230.1'}, {'price': '0.63', 'size': '210.1'}, {'price': '0.62', 'size': '300.1'}, {'price': '0.61', 'size': '511.06'}, {'price': '0.6', 'size': '467.85'}, {'price': '0.59', 'size': '5510'}, {'price': '0.58', 'size': '2088.1'}, {'price': '0.57', 'size': '161.75'}, {'price': '0.56', 'size': '4580.1'}, {'price': '0.55', 'size': '1139.4'}, {'price': '0.54', 'size': '110.1'}, {'price': '0.53', 'size': '70.1'}], 'asset_id': '114416409796971863099144323163249651172534872992222856507897414949637892047507', 'bids': [{'price': '0.01', 'size': '2850.27'}, {'price': '0.02', 'size': '500'}, {'price': '0.03', 'size': '500'}, {'price': '0.04', 'size': '300'}, {'price': '0.05', 'size': '320'}, {'price': '0.06', 'size': '300'}, {'price': '0.08', 'size': '250'}, {'price': '0.09', 'size': '300'}, {'price': '0.1', 'size': '205'}, {'price': '0.11', 'size': '5454'}, {'price': '0.12', 'size': '200'}, {'price': '0.13', 'size': '426.92'}, {'price': '0.14', 'size': '15'}, {'price': '0.15', 'size': '110'}, {'price': '0.16', 'size': '4709.51'}, {'price': '0.18', 'size': '19.13'}, {'price': '0.19', 'size': '120'}, {'price': '0.2', 'size': '691.17'}, {'price': '0.24', 'size': '5027'}, {'price': '0.25', 'size': '86.66'}, {'price': '0.27', 'size': '215.25'}, {'price': '0.29', 'size': '1102.28'}, {'price': '0.31', 'size': '1130.65'}, {'price': '0.32', 'size': '200'}, {'price': '0.33', 'size': '4620'}, {'price': '0.35', 'size': '232'}, {'price': '0.39', 'size': '10.5'}, {'price': '0.4', 'size': '3135'}, {'price': '0.41', 'size': '20'}, {'price': '0.42', 'size': '3050'}, {'price': '0.43', 'size': '50'}, {'price': '0.44', 'size': '3660'}, {'price': '0.45', 'size': '2978'}, {'price': '0.46', 'size': '500'}, {'price': '0.47', 'size': '410'}, {'price': '0.48', 'size': '2342.18'}, {'price': '0.49', 'size': '1640'}, {'price': '0.5', 'size': '1715'}, {'price': '0.51', 'size': '986.18'}], 'event_type': 'book', 'hash': '4806d2d0b7eaa5a6680f781c81830d8c138917a8', 'market': '0x7aa4a910b31b2c4ddb09d1e3408e52aa8e09a14402f376070a44b1b85cb36d13', 'timestamp': '1733332780480'}
{'asks': [{'price': '0.99', 'size': '4217.01'}, {'price': '0.98', 'size': '505'}, {'price': '0.97', 'size': '511.03'}, {'price': '0.96', 'size': '300'}, {'price': '0.95', 'size': '657.12'}, {'price': '0.94', 'size': '300'}, {'price': '0.92', 'size': '20000.45'}, {'price': '0.91', 'size': '10406.3'}, {'price': '0.9', 'size': '4587.5'}, {'price': '0.89', 'size': '13017.18'}, {'price': '0.88', 'size': '200'}, {'price': '0.87', 'size': '3229'}, {'price': '0.86', 'size': '17.1'}, {'price': '0.85', 'size': '109.68'}, {'price': '0.84', 'size': '250'}, {'price': '0.83', 'size': '100'}, {'price': '0.82', 'size': '16029'}, {'price': '0.81', 'size': '45721.39'}, {'price': '0.8', 'size': '26531'}, {'price': '0.79', 'size': '7110'}, {'price': '0.78', 'size': '10350'}, {'price': '0.77', 'size': '67'}, {'price': '0.76', 'size': '200'}, {'price': '0.75', 'size': '18329.25'}, {'price': '0.74', 'size': '11370.7'}, {'price': '0.73', 'size': '5020.1'}, {'price': '0.72', 'size': '380.52'}, {'price': '0.71', 'size': '15073.2'}, {'price': '0.7', 'size': '5570.1'}, {'price': '0.69', 'size': '6088.6'}, {'price': '0.68', 'size': '2131.34'}, {'price': '0.67', 'size': '3010.1'}, {'price': '0.66', 'size': '4510.1'}, {'price': '0.65', 'size': '1010.1'}, {'price': '0.64', 'size': '1230.1'}, {'price': '0.63', 'size': '210.1'}, {'price': '0.62', 'size': '300.1'}, {'price': '0.61', 'size': '511.06'}, {'price': '0.6', 'size': '467.85'}, {'price': '0.59', 'size': '5510'}, {'price': '0.58', 'size': '2088.1'}, {'price': '0.57', 'size': '161.75'}, {'price': '0.56', 'size': '4580.1'}, {'price': '0.55', 'size': '1139.4'}, {'price': '0.54', 'size': '110.1'}, {'price': '0.53', 'size': '70.1'}], 'asset_id': '114416409796971863099144323163249651172534872992222856507897414949637892047507', 'bids': [{'price': '0.01', 'size': '2850.27'}, {'price': '0.02', 'size': '500'}, {'price': '0.03', 'size': '500'}, {'price': '0.04', 'size': '300'}, {'price': '0.05', 'size': '320'}, {'price': '0.06', 'size': '300'}, {'price': '0.08', 'size': '250'}, {'price': '0.09', 'size': '300'}, {'price': '0.1', 'size': '205'}, {'price': '0.11', 'size': '5454'}, {'price': '0.12', 'size': '200'}, {'price': '0.13', 'size': '426.92'}, {'price': '0.14', 'size': '15'}, {'price': '0.15', 'size': '110'}, {'price': '0.16', 'size': '4709.51'}, {'price': '0.18', 'size': '19.13'}, {'price': '0.19', 'size': '120'}, {'price': '0.2', 'size': '691.17'}, {'price': '0.24', 'size': '5027'}, {'price': '0.25', 'size': '86.66'}, {'price': '0.27', 'size': '215.25'}, {'price': '0.29', 'size': '1102.28'}, {'price': '0.31', 'size': '1130.65'}, {'price': '0.32', 'size': '200'}, {'price': '0.33', 'size': '4620'}, {'price': '0.35', 'size': '232'}, {'price': '0.39', 'size': '10.5'}, {'price': '0.4', 'size': '3135'}, {'price': '0.41', 'size': '20'}, {'price': '0.42', 'size': '3050'}, {'price': '0.43', 'size': '50'}, {'price': '0.44', 'size': '3660'}, {'price': '0.45', 'size': '2978'}, {'price': '0.46', 'size': '500'}, {'price': '0.47', 'size': '410'}, {'price': '0.48', 'size': '2342.18'}, {'price': '0.49', 'size': '1640'}, {'price': '0.5', 'size': '1715'}, {'price': '0.51', 'size': '986.18'}], 'event_type': 'book', 'hash': '4806d2d0b7eaa5a6680f781c81830d8c138917a8', 'market': '0x7aa4a910b31b2c4ddb09d1e3408e52aa8e09a14402f376070a44b1b85cb36d13', 'timestamp': '1733332780480'}
{'asset_id': '114416409796971863099144323163249651172534872992222856507897414949637892047507', 'event_type': 'last_trade_price', 'fee_rate_bps': '0', 'market': '0x7aa4a910b31b2c4ddb09d1e3408e52aa8e09a14402f376070a44b1b85cb36d13', 'price': '0.52', 'side': 'BUY', 'size': '109', 'timestamp': '1733332780500'}
{'asset_id': '114416409796971863099144323163249651172534872992222856507897414949637892047507', 'event_type': 'last_trade_price', 'fee_rate_bps': '0', 'market': '0x7aa4a910b31b2c4ddb09d1e3408e52aa8e09a14402f376070a44b1b85cb36d13', 'price': '0.52', 'side': 'BUY', 'size': '109', 'timestamp': '1733332780500'}
{'asset_id': '114416409796971863099144323163249651172534872992222856507897414949637892047507', 'changes': [{'price': '0.53', 'side': 'SELL', 'size': '95.09'}], 'event_type': 'price_change', 'hash': 'eb0160f6b52b4da21336d214abc59d28273bfcf9', 'market': '0x7aa4a910b31b2c4ddb09d1e3408e52aa8e09a14402f376070a44b1b85cb36d13', 'timestamp': '1733332780797'}
{'asset_id': '114416409796971863099144323163249651172534872992222856507897414949637892047507', 'changes': [{'price': '0.53', 'side': 'SELL', 'size': '95.09'}], 'event_type': 'price_change', 'hash': 'eb0160f6b52b4da21336d214abc59d28273bfcf9', 'market': '0x7aa4a910b31b2c4ddb09d1e3408e52aa8e09a14402f376070a44b1b85cb36d13', 'timestamp': '1733332780797'}
{'asset_id': '114416409796971863099144323163249651172534872992222856507897414949637892047507', 'changes': [{'price': '0.55', 'side': 'SELL', 'size': '1239.4'}], 'event_type': 'price_change', 'hash': '7558c3dfb7ea323f42b09b8beceb585e93fc12ba', 'market': '0x7aa4a910b31b2c4ddb09d1e3408e52aa8e09a14402f376070a44b1b85cb36d13', 'timestamp': '1733332781939'}
{'asset_id': '114416409796971863099144323163249651172534872992222856507897414949637892047507', 'changes': [{'price': '0.55', 'side': 'SELL', 'size': '1239.4'}], 'event_type': 'price_change', 'hash': '7558c3dfb7ea323f42b09b8beceb585e93fc12ba', 'market': '0x7aa4a910b31b2c4ddb09d1e3408e52aa8e09a14402f376070a44b1b85cb36d13', 'timestamp': '1733332781939'}
{'asset_id': '114416409796971863099144323163249651172534872992222856507897414949637892047507', 'changes': [{'price': '0.56', 'side': 'SELL', 'size': '4310.1'}, {'price': '0.47', 'side': 'BUY', 'size': '150'}], 'event_type': 'price_change', 'hash': '31515cbf377240b79545179083884d916fc3f238', 'market': '0x7aa4a910b31b2c4ddb09d1e3408e52aa8e09a14402f376070a44b1b85cb36d13', 'timestamp': '1733332782830'}
{'asset_id': '114416409796971863099144323163249651172534872992222856507897414949637892047507', 'changes': [{'price': '0.56', 'side': 'SELL', 'size': '4310.1'}, {'price': '0.47', 'side': 'BUY', 'size': '150'}], 'event_type': 'price_change', 'hash': '31515cbf377240b79545179083884d916fc3f238', 'market': '0x7aa4a910b31b2c4ddb09d1e3408e52aa8e09a14402f376070a44b1b85cb36d13', 'timestamp': '1733332782830'}
{'asset_id': '114416409796971863099144323163249651172534872992222856507897414949637892047507', 'changes': [{'price': '0.56', 'side': 'SELL', 'size': '4550.1'}, {'price': '0.55', 'side': 'SELL', 'size': '1139.4'}], 'event_type': 'price_change', 'hash': 'df0c682d53af4bd5199d4287b2de61cb350ee719', 'market': '0x7aa4a910b31b2c4ddb09d1e3408e52aa8e09a14402f376070a44b1b85cb36d13', 'timestamp': '1733332783182'}
{'asset_id': '114416409796971863099144323163249651172534872992222856507897414949637892047507', 'changes': [{'price': '0.56', 'side': 'SELL', 'size': '4550.1'}, {'price': '0.55', 'side': 'SELL', 'size': '1139.4'}], 'event_type': 'price_change', 'hash': 'df0c682d53af4bd5199d4287b2de61cb350ee719', 'market': '0x7aa4a910b31b2c4ddb09d1e3408e52aa8e09a14402f376070a44b1b85cb36d13', 'timestamp': '1733332783182'}
{'asset_id': '114416409796971863099144323163249651172534872992222856507897414949637892047507', 'changes': [{'price': '0.48', 'side': 'BUY', 'size': '2572.18'}], 'event_type': 'price_change', 'hash': '05b5baf440c1a2abfb1b731edc5b8376ffa01d2e', 'market': '0x7aa4a910b31b2c4ddb09d1e3408e52aa8e09a14402f376070a44b1b85cb36d13', 'timestamp': '1733332783465'}
{'asset_id': '114416409796971863099144323163249651172534872992222856507897414949637892047507', 'changes': [{'price': '0.48', 'side': 'BUY', 'size': '2572.18'}], 'event_type': 'price_change', 'hash': '05b5baf440c1a2abfb1b731edc5b8376ffa01d2e', 'market': '0x7aa4a910b31b2c4ddb09d1e3408e52aa8e09a14402f376070a44b1b85cb36d13', 'timestamp': '1733332783465'}
{'asset_id': '114416409796971863099144323163249651172534872992222856507897414949637892047507', 'changes': [{'price': '0.54', 'side': 'SELL', 'size': '210.1'}], 'event_type': 'price_change', 'hash': 'f35240550a9b6ac41991617ad73c1875fa992ee6', 'market': '0x7aa4a910b31b2c4ddb09d1e3408e52aa8e09a14402f376070a44b1b85cb36d13', 'timestamp': '1733332784005'}
{'asset_id': '114416409796971863099144323163249651172534872992222856507897414949637892047507', 'changes': [{'price': '0.54', 'side': 'SELL', 'size': '210.1'}], 'event_type': 'price_change', 'hash': 'f35240550a9b6ac41991617ad73c1875fa992ee6', 'market': '0x7aa4a910b31b2c4ddb09d1e3408e52aa8e09a14402f376070a44b1b85cb36d13', 'timestamp': '1733332784005'}
{'asset_id': '114416409796971863099144323163249651172534872992222856507897414949637892047507', 'changes': [{'price': '0.53', 'side': 'SELL', 'size': '35.09'}], 'event_type': 'price_change', 'hash': 'be6ec803bc03da32a04ed41b7a11620313260ea6', 'market': '0x7aa4a910b31b2c4ddb09d1e3408e52aa8e09a14402f376070a44b1b85cb36d13', 'timestamp': '1733332790016'}
{'asset_id': '114416409796971863099144323163249651172534872992222856507897414949637892047507', 'changes': [{'price': '0.53', 'side': 'SELL', 'size': '35.09'}], 'event_type': 'price_change', 'hash': 'be6ec803bc03da32a04ed41b7a11620313260ea6', 'market': '0x7aa4a910b31b2c4ddb09d1e3408e52aa8e09a14402f376070a44b1b85cb36d13', 'timestamp': '1733332790016'}
{'asset_id': '114416409796971863099144323163249651172534872992222856507897414949637892047507', 'changes': [{'price': '0.54', 'side': 'SELL', 'size': '270.1'}], 'event_type': 'price_change', 'hash': '66103e698c9e80a4b730c1d53eadd670161bafa9', 'market': '0x7aa4a910b31b2c4ddb09d1e3408e52aa8e09a14402f376070a44b1b85cb36d13', 'timestamp': '1733332790151'}
{'asset_id': '114416409796971863099144323163249651172534872992222856507897414949637892047507', 'changes': [{'price': '0.54', 'side': 'SELL', 'size': '270.1'}], 'event_type': 'price_change', 'hash': '66103e698c9e80a4b730c1d53eadd670161bafa9', 'market': '0x7aa4a910b31b2c4ddb09d1e3408e52aa8e09a14402f376070a44b1b85cb36d13', 'timestamp': '1733332790151'}
{'asset_id': '114416409796971863099144323163249651172534872992222856507897414949637892047507', 'changes': [{'price': '0.46', 'side': 'BUY', 'size': '0'}, {'price': '0.56', 'side': 'SELL', 'size': '4050.1'}], 'event_type': 'price_change', 'hash': '9ed93308c53d5d4b31632247f8861ff593e62895', 'market': '0x7aa4a910b31b2c4ddb09d1e3408e52aa8e09a14402f376070a44b1b85cb36d13', 'timestamp': '1733332790521'}
{'asset_id': '114416409796971863099144323163249651172534872992222856507897414949637892047507', 'changes': [{'price': '0.46', 'side': 'BUY', 'size': '0'}, {'price': '0.56', 'side': 'SELL', 'size': '4050.1'}], 'event_type': 'price_change', 'hash': '9ed93308c53d5d4b31632247f8861ff593e62895', 'market': '0x7aa4a910b31b2c4ddb09d1e3408e52aa8e09a14402f376070a44b1b85cb36d13', 'timestamp': '1733332790521'}
{'asset_id': '114416409796971863099144323163249651172534872992222856507897414949637892047507', 'changes': [{'price': '0.46', 'side': 'BUY', 'size': '500'}], 'event_type': 'price_change', 'hash': '11f509886cc608835ab6f5fabee6c2ef83d8a68d', 'market': '0x7aa4a910b31b2c4ddb09d1e3408e52aa8e09a14402f376070a44b1b85cb36d13', 'timestamp': '1733332791575'}
{'asset_id': '114416409796971863099144323163249651172534872992222856507897414949637892047507', 'changes': [{'price': '0.46', 'side': 'BUY', 'size': '500'}], 'event_type': 'price_change', 'hash': '11f509886cc608835ab6f5fabee6c2ef83d8a68d', 'market': '0x7aa4a910b31b2c4ddb09d1e3408e52aa8e09a14402f376070a44b1b85cb36d13', 'timestamp': '1733332791575'}
{'asset_id': '114416409796971863099144323163249651172534872992222856507897414949637892047507', 'changes': [{'price': '0.55', 'side': 'SELL', 'size': '1639.4'}], 'event_type': 'price_change', 'hash': '790b22d0b70eae6d7a8588458d11293c305d80f4', 'market': '0x7aa4a910b31b2c4ddb09d1e3408e52aa8e09a14402f376070a44b1b85cb36d13', 'timestamp': '1733332791955'}
{'asset_id': '114416409796971863099144323163249651172534872992222856507897414949637892047507', 'changes': [{'price': '0.55', 'side': 'SELL', 'size': '1639.4'}], 'event_type': 'price_change', 'hash': '790b22d0b70eae6d7a8588458d11293c305d80f4', 'market': '0x7aa4a910b31b2c4ddb09d1e3408e52aa8e09a14402f376070a44b1b85cb36d13', 'timestamp': '1733332791955'}
{'asset_id': '114416409796971863099144323163249651172534872992222856507897414949637892047507', 'changes': [{'price': '0.51', 'side': 'BUY', 'size': '1986.18'}], 'event_type': 'price_change', 'hash': 'e0cf3f542a2609a21da07a176af1e5b6b7aea5c9', 'market': '0x7aa4a910b31b2c4ddb09d1e3408e52aa8e09a14402f376070a44b1b85cb36d13', 'timestamp': '1733332792315'}
{'asset_id': '114416409796971863099144323163249651172534872992222856507897414949637892047507', 'changes': [{'price': '0.51', 'side': 'BUY', 'size': '1986.18'}], 'event_type': 'price_change', 'hash': 'e0cf3f542a2609a21da07a176af1e5b6b7aea5c9', 'market': '0x7aa4a910b31b2c4ddb09d1e3408e52aa8e09a14402f376070a44b1b85cb36d13', 'timestamp': '1733332792315'}
{'asset_id': '114416409796971863099144323163249651172534872992222856507897414949637892047507', 'changes': [{'price': '0.54', 'side': 'SELL', 'size': '170.1'}], 'event_type': 'price_change', 'hash': '1b7c1ba6532c39b0d0352ab845b2e2991fbe5b82', 'market': '0x7aa4a910b31b2c4ddb09d1e3408e52aa8e09a14402f376070a44b1b85cb36d13', 'timestamp': '1733332794032'}
{'asset_id': '114416409796971863099144323163249651172534872992222856507897414949637892047507', 'changes': [{'price': '0.54', 'side': 'SELL', 'size': '170.1'}], 'event_type': 'price_change', 'hash': '1b7c1ba6532c39b0d0352ab845b2e2991fbe5b82', 'market': '0x7aa4a910b31b2c4ddb09d1e3408e52aa8e09a14402f376070a44b1b85cb36d13', 'timestamp': '1733332794032'}
{'asset_id': '114416409796971863099144323163249651172534872992222856507897414949637892047507', 'changes': [{'price': '0.55', 'side': 'SELL', 'size': '1739.4'}], 'event_type': 'price_change', 'hash': 'de8414fd13a5e73bb974e76706ff5cf4c2ccbdf4', 'market': '0x7aa4a910b31b2c4ddb09d1e3408e52aa8e09a14402f376070a44b1b85cb36d13', 'timestamp': '1733332794974'}
{'asset_id': '114416409796971863099144323163249651172534872992222856507897414949637892047507', 'changes': [{'price': '0.55', 'side': 'SELL', 'size': '1739.4'}], 'event_type': 'price_change', 'hash': 'de8414fd13a5e73bb974e76706ff5cf4c2ccbdf4', 'market': '0x7aa4a910b31b2c4ddb09d1e3408e52aa8e09a14402f376070a44b1b85cb36d13', 'timestamp': '1733332794974'}
{'asset_id': '114416409796971863099144323163249651172534872992222856507897414949637892047507', 'changes': [{'price': '0.55', 'side': 'SELL', 'size': '1639.4'}], 'event_type': 'price_change', 'hash': 'aa4478b22bf0f32392d9ebe23a7775ec8babe55d', 'market': '0x7aa4a910b31b2c4ddb09d1e3408e52aa8e09a14402f376070a44b1b85cb36d13', 'timestamp': '1733332796462'}
{'asset_id': '114416409796971863099144323163249651172534872992222856507897414949637892047507', 'changes': [{'price': '0.55', 'side': 'SELL', 'size': '1639.4'}], 'event_type': 'price_change', 'hash': 'aa4478b22bf0f32392d9ebe23a7775ec8babe55d', 'market': '0x7aa4a910b31b2c4ddb09d1e3408e52aa8e09a14402f376070a44b1b85cb36d13', 'timestamp': '1733332796462'}
{'asset_id': '114416409796971863099144323163249651172534872992222856507897414949637892047507', 'changes': [{'price': '0.54', 'side': 'SELL', 'size': '270.1'}], 'event_type': 'price_change', 'hash': 'd442ee143a052c71c911299e9baddcd6957cb03e', 'market': '0x7aa4a910b31b2c4ddb09d1e3408e52aa8e09a14402f376070a44b1b85cb36d13', 'timestamp': '1733332797343'}
{'asset_id': '114416409796971863099144323163249651172534872992222856507897414949637892047507', 'changes': [{'price': '0.54', 'side': 'SELL', 'size': '270.1'}], 'event_type': 'price_change', 'hash': 'd442ee143a052c71c911299e9baddcd6957cb03e', 'market': '0x7aa4a910b31b2c4ddb09d1e3408e52aa8e09a14402f376070a44b1b85cb36d13', 'timestamp': '1733332797343'}
{'asset_id': '114416409796971863099144323163249651172534872992222856507897414949637892047507', 'changes': [{'price': '0.54', 'side': 'SELL', 'size': '170.1'}], 'event_type': 'price_change', 'hash': '1cccf3c3dd4d30aa84132389e4c49e2a7b526769', 'market': '0x7aa4a910b31b2c4ddb09d1e3408e52aa8e09a14402f376070a44b1b85cb36d13', 'timestamp': '1733332814101'}
{'asset_id': '114416409796971863099144323163249651172534872992222856507897414949637892047507', 'changes': [{'price': '0.54', 'side': 'SELL', 'size': '170.1'}], 'event_type': 'price_change', 'hash': '1cccf3c3dd4d30aa84132389e4c49e2a7b526769', 'market': '0x7aa4a910b31b2c4ddb09d1e3408e52aa8e09a14402f376070a44b1b85cb36d13', 'timestamp': '1733332814101'}
{'asset_id': '114416409796971863099144323163249651172534872992222856507897414949637892047507', 'changes': [{'price': '0.55', 'side': 'SELL', 'size': '1739.4'}], 'event_type': 'price_change', 'hash': 'ea69198b6f20142cc0be354eb8465c207d042684', 'market': '0x7aa4a910b31b2c4ddb09d1e3408e52aa8e09a14402f376070a44b1b85cb36d13', 'timestamp': '1733332815086'}
{'asset_id': '114416409796971863099144323163249651172534872992222856507897414949637892047507', 'changes': [{'price': '0.55', 'side': 'SELL', 'size': '1739.4'}], 'event_type': 'price_change', 'hash': 'ea69198b6f20142cc0be354eb8465c207d042684', 'market': '0x7aa4a910b31b2c4ddb09d1e3408e52aa8e09a14402f376070a44b1b85cb36d13', 'timestamp': '1733332815086'}
{'asset_id': '114416409796971863099144323163249651172534872992222856507897414949637892047507', 'changes': [{'price': '0.55', 'side': 'SELL', 'size': '1639.4'}], 'event_type': 'price_change', 'hash': '809b1b28277a5c00a822089f517c9adabc1eb523', 'market': '0x7aa4a910b31b2c4ddb09d1e3408e52aa8e09a14402f376070a44b1b85cb36d13', 'timestamp': '1733332815763'}
{'asset_id': '114416409796971863099144323163249651172534872992222856507897414949637892047507', 'changes': [{'price': '0.55', 'side': 'SELL', 'size': '1639.4'}], 'event_type': 'price_change', 'hash': '809b1b28277a5c00a822089f517c9adabc1eb523', 'market': '0x7aa4a910b31b2c4ddb09d1e3408e52aa8e09a14402f376070a44b1b85cb36d13', 'timestamp': '1733332815763'}
{'asset_id': '114416409796971863099144323163249651172534872992222856507897414949637892047507', 'changes': [{'price': '0.54', 'side': 'SELL', 'size': '270.1'}], 'event_type': 'price_change', 'hash': '1691548683b2424db885d67dc8529b1840f32c4d', 'market': '0x7aa4a910b31b2c4ddb09d1e3408e52aa8e09a14402f376070a44b1b85cb36d13', 'timestamp': '1733332816804'}
{'asset_id': '114416409796971863099144323163249651172534872992222856507897414949637892047507', 'changes': [{'price': '0.54', 'side': 'SELL', 'size': '270.1'}], 'event_type': 'price_change', 'hash': '1691548683b2424db885d67dc8529b1840f32c4d', 'market': '0x7aa4a910b31b2c4ddb09d1e3408e52aa8e09a14402f376070a44b1b85cb36d13', 'timestamp': '1733332816804'}
{'asset_id': '114416409796971863099144323163249651172534872992222856507897414949637892047507', 'changes': [{'price': '0.5', 'side': 'BUY', 'size': '1315'}, {'price': '0.54', 'side': 'SELL', 'size': '170.1'}], 'event_type': 'price_change', 'hash': '286cfbe9ff645774f731b7d0673d23db5d11ce10', 'market': '0x7aa4a910b31b2c4ddb09d1e3408e52aa8e09a14402f376070a44b1b85cb36d13', 'timestamp': '1733332820344'}
{'asset_id': '114416409796971863099144323163249651172534872992222856507897414949637892047507', 'changes': [{'price': '0.5', 'side': 'BUY', 'size': '1315'}, {'price': '0.54', 'side': 'SELL', 'size': '170.1'}], 'event_type': 'price_change', 'hash': '286cfbe9ff645774f731b7d0673d23db5d11ce10', 'market': '0x7aa4a910b31b2c4ddb09d1e3408e52aa8e09a14402f376070a44b1b85cb36d13', 'timestamp': '1733332820344'}
{'asset_id': '114416409796971863099144323163249651172534872992222856507897414949637892047507', 'changes': [{'price': '0.55', 'side': 'SELL', 'size': '1739.4'}], 'event_type': 'price_change', 'hash': '0b19a339bd628873ab182956e637e9cfd4e912fc', 'market': '0x7aa4a910b31b2c4ddb09d1e3408e52aa8e09a14402f376070a44b1b85cb36d13', 'timestamp': '1733332821424'}
{'asset_id': '114416409796971863099144323163249651172534872992222856507897414949637892047507', 'changes': [{'price': '0.55', 'side': 'SELL', 'size': '1739.4'}], 'event_type': 'price_change', 'hash': '0b19a339bd628873ab182956e637e9cfd4e912fc', 'market': '0x7aa4a910b31b2c4ddb09d1e3408e52aa8e09a14402f376070a44b1b85cb36d13', 'timestamp': '1733332821424'}
{'asset_id': '114416409796971863099144323163249651172534872992222856507897414949637892047507', 'changes': [{'price': '0.52', 'side': 'BUY', 'size': '1000'}], 'event_type': 'price_change', 'hash': 'c7192eab7b8ced6803f8babd95d9c60f011cfddc', 'market': '0x7aa4a910b31b2c4ddb09d1e3408e52aa8e09a14402f376070a44b1b85cb36d13', 'timestamp': '1733332828111'}
{'asset_id': '114416409796971863099144323163249651172534872992222856507897414949637892047507', 'changes': [{'price': '0.52', 'side': 'BUY', 'size': '1000'}], 'event_type': 'price_change', 'hash': 'c7192eab7b8ced6803f8babd95d9c60f011cfddc', 'market': '0x7aa4a910b31b2c4ddb09d1e3408e52aa8e09a14402f376070a44b1b85cb36d13', 'timestamp': '1733332828111'}
{'asset_id': '114416409796971863099144323163249651172534872992222856507897414949637892047507', 'changes': [{'price': '0.54', 'side': 'SELL', 'size': '120.1'}], 'event_type': 'price_change', 'hash': '1237639290b5861c9ef2f98c6e2d13808b56540b', 'market': '0x7aa4a910b31b2c4ddb09d1e3408e52aa8e09a14402f376070a44b1b85cb36d13', 'timestamp': '1733332829110'}
{'asset_id': '114416409796971863099144323163249651172534872992222856507897414949637892047507', 'changes': [{'price': '0.54', 'side': 'SELL', 'size': '120.1'}], 'event_type': 'price_change', 'hash': '1237639290b5861c9ef2f98c6e2d13808b56540b', 'market': '0x7aa4a910b31b2c4ddb09d1e3408e52aa8e09a14402f376070a44b1b85cb36d13', 'timestamp': '1733332829110'}
{'asset_id': '114416409796971863099144323163249651172534872992222856507897414949637892047507', 'changes': [{'price': '0.47', 'side': 'BUY', 'size': '100'}], 'event_type': 'price_change', 'hash': '89374fefbe0872e8369ab14618882375a3361173', 'market': '0x7aa4a910b31b2c4ddb09d1e3408e52aa8e09a14402f376070a44b1b85cb36d13', 'timestamp': '1733332829577'}
{'asset_id': '114416409796971863099144323163249651172534872992222856507897414949637892047507', 'changes': [{'price': '0.47', 'side': 'BUY', 'size': '100'}], 'event_type': 'price_change', 'hash': '89374fefbe0872e8369ab14618882375a3361173', 'market': '0x7aa4a910b31b2c4ddb09d1e3408e52aa8e09a14402f376070a44b1b85cb36d13', 'timestamp': '1733332829577'}
{'asset_id': '114416409796971863099144323163249651172534872992222856507897414949637892047507', 'changes': [{'price': '0.58', 'side': 'SELL', 'size': '2138.1'}], 'event_type': 'price_change', 'hash': 'b621688d514f71ea1f71467e7e7a696efffea1fb', 'market': '0x7aa4a910b31b2c4ddb09d1e3408e52aa8e09a14402f376070a44b1b85cb36d13', 'timestamp': '1733332829853'}
{'asset_id': '114416409796971863099144323163249651172534872992222856507897414949637892047507', 'changes': [{'price': '0.58', 'side': 'SELL', 'size': '2138.1'}], 'event_type': 'price_change', 'hash': 'b621688d514f71ea1f71467e7e7a696efffea1fb', 'market': '0x7aa4a910b31b2c4ddb09d1e3408e52aa8e09a14402f376070a44b1b85cb36d13', 'timestamp': '1733332829853'}
{'asset_id': '114416409796971863099144323163249651172534872992222856507897414949637892047507', 'changes': [{'price': '0.51', 'side': 'BUY', 'size': '2036.18'}, {'price': '0.54', 'side': 'SELL', 'size': '70.1'}], 'event_type': 'price_change', 'hash': 'b66668cd733f95a549a67d8aa124940aed4ee399', 'market': '0x7aa4a910b31b2c4ddb09d1e3408e52aa8e09a14402f376070a44b1b85cb36d13', 'timestamp': '1733332830115'}
{'asset_id': '114416409796971863099144323163249651172534872992222856507897414949637892047507', 'changes': [{'price': '0.51', 'side': 'BUY', 'size': '2036.18'}, {'price': '0.54', 'side': 'SELL', 'size': '70.1'}], 'event_type': 'price_change', 'hash': 'b66668cd733f95a549a67d8aa124940aed4ee399', 'market': '0x7aa4a910b31b2c4ddb09d1e3408e52aa8e09a14402f376070a44b1b85cb36d13', 'timestamp': '1733332830115'}
{'asset_id': '114416409796971863099144323163249651172534872992222856507897414949637892047507', 'changes': [{'price': '0.46', 'side': 'BUY', 'size': '0'}, {'price': '0.51', 'side': 'BUY', 'size': '1036.18'}, {'price': '0.55', 'side': 'SELL', 'size': '1239.4'}], 'event_type': 'price_change', 'hash': '88d3c8bd9b0242d2694a762ad5b73db042c7a604', 'market': '0x7aa4a910b31b2c4ddb09d1e3408e52aa8e09a14402f376070a44b1b85cb36d13', 'timestamp': '1733332830177'}
{'asset_id': '114416409796971863099144323163249651172534872992222856507897414949637892047507', 'changes': [{'price': '0.46', 'side': 'BUY', 'size': '0'}, {'price': '0.51', 'side': 'BUY', 'size': '1036.18'}, {'price': '0.55', 'side': 'SELL', 'size': '1239.4'}], 'event_type': 'price_change', 'hash': '88d3c8bd9b0242d2694a762ad5b73db042c7a604', 'market': '0x7aa4a910b31b2c4ddb09d1e3408e52aa8e09a14402f376070a44b1b85cb36d13', 'timestamp': '1733332830177'}
{'asset_id': '114416409796971863099144323163249651172534872992222856507897414949637892047507', 'changes': [{'price': '0.47', 'side': 'BUY', 'size': '50'}], 'event_type': 'price_change', 'hash': 'f73197e13cbf40f7b616f4a34a20c05d6e62ce40', 'market': '0x7aa4a910b31b2c4ddb09d1e3408e52aa8e09a14402f376070a44b1b85cb36d13', 'timestamp': '1733332830581'}
{'asset_id': '114416409796971863099144323163249651172534872992222856507897414949637892047507', 'changes': [{'price': '0.47', 'side': 'BUY', 'size': '50'}], 'event_type': 'price_change', 'hash': 'f73197e13cbf40f7b616f4a34a20c05d6e62ce40', 'market': '0x7aa4a910b31b2c4ddb09d1e3408e52aa8e09a14402f376070a44b1b85cb36d13', 'timestamp': '1733332830581'}
{'asset_id': '114416409796971863099144323163249651172534872992222856507897414949637892047507', 'changes': [{'price': '0.58', 'side': 'SELL', 'size': '2188.1'}], 'event_type': 'price_change', 'hash': '9bc1c8b457adabc110b972580406a699f3816467', 'market': '0x7aa4a910b31b2c4ddb09d1e3408e52aa8e09a14402f376070a44b1b85cb36d13', 'timestamp': '1733332830958'}
{'asset_id': '114416409796971863099144323163249651172534872992222856507897414949637892047507', 'changes': [{'price': '0.58', 'side': 'SELL', 'size': '2188.1'}], 'event_type': 'price_change', 'hash': '9bc1c8b457adabc110b972580406a699f3816467', 'market': '0x7aa4a910b31b2c4ddb09d1e3408e52aa8e09a14402f376070a44b1b85cb36d13', 'timestamp': '1733332830958'}
{'asset_id': '114416409796971863099144323163249651172534872992222856507897414949637892047507', 'changes': [{'price': '0.51', 'side': 'BUY', 'size': '1086.18'}, {'price': '0.46', 'side': 'BUY', 'size': '500'}], 'event_type': 'price_change', 'hash': '72f5ecaced8bcec72605abb26c0dc38f1cbca372', 'market': '0x7aa4a910b31b2c4ddb09d1e3408e52aa8e09a14402f376070a44b1b85cb36d13', 'timestamp': '1733332831214'}
{'asset_id': '114416409796971863099144323163249651172534872992222856507897414949637892047507', 'changes': [{'price': '0.51', 'side': 'BUY', 'size': '1086.18'}, {'price': '0.46', 'side': 'BUY', 'size': '500'}], 'event_type': 'price_change', 'hash': '72f5ecaced8bcec72605abb26c0dc38f1cbca372', 'market': '0x7aa4a910b31b2c4ddb09d1e3408e52aa8e09a14402f376070a44b1b85cb36d13', 'timestamp': '1733332831214'}
{'asset_id': '114416409796971863099144323163249651172534872992222856507897414949637892047507', 'changes': [{'price': '0.56', 'side': 'SELL', 'size': '4550.1'}], 'event_type': 'price_change', 'hash': 'd0fc05be75acbd99af897dbaccec56d3a9478d5d', 'market': '0x7aa4a910b31b2c4ddb09d1e3408e52aa8e09a14402f376070a44b1b85cb36d13', 'timestamp': '1733332831584'}
{'asset_id': '114416409796971863099144323163249651172534872992222856507897414949637892047507', 'changes': [{'price': '0.56', 'side': 'SELL', 'size': '4550.1'}], 'event_type': 'price_change', 'hash': 'd0fc05be75acbd99af897dbaccec56d3a9478d5d', 'market': '0x7aa4a910b31b2c4ddb09d1e3408e52aa8e09a14402f376070a44b1b85cb36d13', 'timestamp': '1733332831584'}
{'asset_id': '114416409796971863099144323163249651172534872992222856507897414949637892047507', 'changes': [{'price': '0.51', 'side': 'BUY', 'size': '2086.18'}], 'event_type': 'price_change', 'hash': 'eece4373a2a6827452a4feb9e04b70e03433b571', 'market': '0x7aa4a910b31b2c4ddb09d1e3408e52aa8e09a14402f376070a44b1b85cb36d13', 'timestamp': '1733332831949'}
{'asset_id': '114416409796971863099144323163249651172534872992222856507897414949637892047507', 'changes': [{'price': '0.48', 'side': 'BUY', 'size': '2342.18'}, {'price': '0.56', 'side': 'SELL', 'size': '4310.1'}], 'event_type': 'price_change', 'hash': 'd09a183047aa1e94078a96d4ea6390ab0d2fc978', 'market': '0x7aa4a910b31b2c4ddb09d1e3408e52aa8e09a14402f376070a44b1b85cb36d13', 'timestamp': '1733332834059'}
{'asset_id': '114416409796971863099144323163249651172534872992222856507897414949637892047507', 'changes': [{'price': '0.48', 'side': 'BUY', 'size': '2342.18'}, {'price': '0.56', 'side': 'SELL', 'size': '4310.1'}], 'event_type': 'price_change', 'hash': 'd09a183047aa1e94078a96d4ea6390ab0d2fc978', 'market': '0x7aa4a910b31b2c4ddb09d1e3408e52aa8e09a14402f376070a44b1b85cb36d13', 'timestamp': '1733332834059'}
{'asset_id': '114416409796971863099144323163249651172534872992222856507897414949637892047507', 'changes': [{'price': '0.48', 'side': 'BUY', 'size': '2592.18'}], 'event_type': 'price_change', 'hash': 'bef0476270908c3e46e189e07ae72d237b883a88', 'market': '0x7aa4a910b31b2c4ddb09d1e3408e52aa8e09a14402f376070a44b1b85cb36d13', 'timestamp': '1733332834336'}
{'asset_id': '114416409796971863099144323163249651172534872992222856507897414949637892047507', 'changes': [{'price': '0.48', 'side': 'BUY', 'size': '2592.18'}], 'event_type': 'price_change', 'hash': 'bef0476270908c3e46e189e07ae72d237b883a88', 'market': '0x7aa4a910b31b2c4ddb09d1e3408e52aa8e09a14402f376070a44b1b85cb36d13', 'timestamp': '1733332834336'}
{'asset_id': '114416409796971863099144323163249651172534872992222856507897414949637892047507', 'changes': [{'price': '0.57', 'side': 'SELL', 'size': '431.75'}], 'event_type': 'price_change', 'hash': '7f98a82d539b1168ddf1a7e515807cd94a70fd8f', 'market': '0x7aa4a910b31b2c4ddb09d1e3408e52aa8e09a14402f376070a44b1b85cb36d13', 'timestamp': '1733332834592'}
{'asset_id': '114416409796971863099144323163249651172534872992222856507897414949637892047507', 'changes': [{'price': '0.57', 'side': 'SELL', 'size': '431.75'}], 'event_type': 'price_change', 'hash': '7f98a82d539b1168ddf1a7e515807cd94a70fd8f', 'market': '0x7aa4a910b31b2c4ddb09d1e3408e52aa8e09a14402f376070a44b1b85cb36d13', 'timestamp': '1733332834592'}
{'asset_id': '114416409796971863099144323163249651172534872992222856507897414949637892047507', 'changes': [{'price': '0.5', 'side': 'BUY', 'size': '115'}], 'event_type': 'price_change', 'hash': '7e9f3b3a363f4aed6723cfc1d5b91de0f1b57729', 'market': '0x7aa4a910b31b2c4ddb09d1e3408e52aa8e09a14402f376070a44b1b85cb36d13', 'timestamp': '1733332839477'}
{'asset_id': '114416409796971863099144323163249651172534872992222856507897414949637892047507', 'changes': [{'price': '0.5', 'side': 'BUY', 'size': '115'}], 'event_type': 'price_change', 'hash': '7e9f3b3a363f4aed6723cfc1d5b91de0f1b57729', 'market': '0x7aa4a910b31b2c4ddb09d1e3408e52aa8e09a14402f376070a44b1b85cb36d13', 'timestamp': '1733332839477'}
{'asset_id': '114416409796971863099144323163249651172534872992222856507897414949637892047507', 'changes': [{'price': '0.51', 'side': 'BUY', 'size': '3286.18'}], 'event_type': 'price_change', 'hash': 'a8fb8130df13a93765a5f688846497d8bde75f66', 'market': '0x7aa4a910b31b2c4ddb09d1e3408e52aa8e09a14402f376070a44b1b85cb36d13', 'timestamp': '1733332847415'}
{'asset_id': '114416409796971863099144323163249651172534872992222856507897414949637892047507', 'changes': [{'price': '0.51', 'side': 'BUY', 'size': '3286.18'}], 'event_type': 'price_change', 'hash': 'a8fb8130df13a93765a5f688846497d8bde75f66', 'market': '0x7aa4a910b31b2c4ddb09d1e3408e52aa8e09a14402f376070a44b1b85cb36d13', 'timestamp': '1733332847415'}
{'asset_id': '114416409796971863099144323163249651172534872992222856507897414949637892047507', 'changes': [{'price': '0.55', 'side': 'SELL', 'size': '1348.4'}], 'event_type': 'price_change', 'hash': '7e4065791ec23fc36997073bb9026995ce5d9bfb', 'market': '0x7aa4a910b31b2c4ddb09d1e3408e52aa8e09a14402f376070a44b1b85cb36d13', 'timestamp': '1733332862129'}
{'asset_id': '114416409796971863099144323163249651172534872992222856507897414949637892047507', 'changes': [{'price': '0.55', 'side': 'SELL', 'size': '1348.4'}], 'event_type': 'price_change', 'hash': '7e4065791ec23fc36997073bb9026995ce5d9bfb', 'market': '0x7aa4a910b31b2c4ddb09d1e3408e52aa8e09a14402f376070a44b1b85cb36d13', 'timestamp': '1733332862129'}
{'asset_id': '114416409796971863099144323163249651172534872992222856507897414949637892047507', 'changes': [{'price': '0.55', 'side': 'SELL', 'size': '1248.4'}], 'event_type': 'price_change', 'hash': 'e22725888501c8c78dbf0ca8a4fa96bc5c31299a', 'market': '0x7aa4a910b31b2c4ddb09d1e3408e52aa8e09a14402f376070a44b1b85cb36d13', 'timestamp': '1733332872962'}
{'asset_id': '114416409796971863099144323163249651172534872992222856507897414949637892047507', 'changes': [{'price': '0.55', 'side': 'SELL', 'size': '1248.4'}], 'event_type': 'price_change', 'hash': 'e22725888501c8c78dbf0ca8a4fa96bc5c31299a', 'market': '0x7aa4a910b31b2c4ddb09d1e3408e52aa8e09a14402f376070a44b1b85cb36d13', 'timestamp': '1733332872962'}
{'asset_id': '114416409796971863099144323163249651172534872992222856507897414949637892047507', 'changes': [{'price': '0.49', 'side': 'BUY', 'size': '140'}, {'price': '0.45', 'side': 'BUY', 'size': '478'}], 'event_type': 'price_change', 'hash': 'f37f9c33483772de748de734b15ab1eb5535c709', 'market': '0x7aa4a910b31b2c4ddb09d1e3408e52aa8e09a14402f376070a44b1b85cb36d13', 'timestamp': '1733332873036'}
{'asset_id': '114416409796971863099144323163249651172534872992222856507897414949637892047507', 'changes': [{'price': '0.49', 'side': 'BUY', 'size': '140'}, {'price': '0.45', 'side': 'BUY', 'size': '478'}], 'event_type': 'price_change', 'hash': 'f37f9c33483772de748de734b15ab1eb5535c709', 'market': '0x7aa4a910b31b2c4ddb09d1e3408e52aa8e09a14402f376070a44b1b85cb36d13', 'timestamp': '1733332873036'}
{'asset_id': '114416409796971863099144323163249651172534872992222856507897414949637892047507', 'changes': [{'price': '0.55', 'side': 'SELL', 'size': '1348.4'}], 'event_type': 'price_change', 'hash': '0d6aea24939645cb8a28bacafa7fa88531327dab', 'market': '0x7aa4a910b31b2c4ddb09d1e3408e52aa8e09a14402f376070a44b1b85cb36d13', 'timestamp': '1733332875864'}
{'asset_id': '114416409796971863099144323163249651172534872992222856507897414949637892047507', 'changes': [{'price': '0.55', 'side': 'SELL', 'size': '1348.4'}], 'event_type': 'price_change', 'hash': '0d6aea24939645cb8a28bacafa7fa88531327dab', 'market': '0x7aa4a910b31b2c4ddb09d1e3408e52aa8e09a14402f376070a44b1b85cb36d13', 'timestamp': '1733332875864'}
{'asset_id': '114416409796971863099144323163249651172534872992222856507897414949637892047507', 'changes': [{'price': '0.46', 'side': 'BUY', 'size': '0'}, {'price': '0.51', 'side': 'BUY', 'size': '2286.18'}, {'price': '0.56', 'side': 'SELL', 'size': '3810.1'}], 'event_type': 'price_change', 'hash': '70e69c61201c9d02332d892ba3c00b8e3a9393b1', 'market': '0x7aa4a910b31b2c4ddb09d1e3408e52aa8e09a14402f376070a44b1b85cb36d13', 'timestamp': '1733332877434'}
{'asset_id': '114416409796971863099144323163249651172534872992222856507897414949637892047507', 'changes': [{'price': '0.46', 'side': 'BUY', 'size': '0'}, {'price': '0.51', 'side': 'BUY', 'size': '2286.18'}, {'price': '0.56', 'side': 'SELL', 'size': '3810.1'}], 'event_type': 'price_change', 'hash': '70e69c61201c9d02332d892ba3c00b8e3a9393b1', 'market': '0x7aa4a910b31b2c4ddb09d1e3408e52aa8e09a14402f376070a44b1b85cb36d13', 'timestamp': '1733332877434'}
{'asset_id': '114416409796971863099144323163249651172534872992222856507897414949637892047507', 'changes': [{'price': '0.47', 'side': 'BUY', 'size': '550'}], 'event_type': 'price_change', 'hash': '080bdbeed20eef0294edf8b4a3121c265a159c13', 'market': '0x7aa4a910b31b2c4ddb09d1e3408e52aa8e09a14402f376070a44b1b85cb36d13', 'timestamp': '1733332878470'}
{'asset_id': '114416409796971863099144323163249651172534872992222856507897414949637892047507', 'changes': [{'price': '0.47', 'side': 'BUY', 'size': '550'}], 'event_type': 'price_change', 'hash': '080bdbeed20eef0294edf8b4a3121c265a159c13', 'market': '0x7aa4a910b31b2c4ddb09d1e3408e52aa8e09a14402f376070a44b1b85cb36d13', 'timestamp': '1733332878470'}
{'asset_id': '114416409796971863099144323163249651172534872992222856507897414949637892047507', 'changes': [{'price': '0.56', 'side': 'SELL', 'size': '4310.1'}], 'event_type': 'price_change', 'hash': 'cc2df63752eeca61a6a52edc848328f7ebac4ad3', 'market': '0x7aa4a910b31b2c4ddb09d1e3408e52aa8e09a14402f376070a44b1b85cb36d13', 'timestamp': '1733332878826'}
{'asset_id': '114416409796971863099144323163249651172534872992222856507897414949637892047507', 'changes': [{'price': '0.56', 'side': 'SELL', 'size': '4310.1'}], 'event_type': 'price_change', 'hash': 'cc2df63752eeca61a6a52edc848328f7ebac4ad3', 'market': '0x7aa4a910b31b2c4ddb09d1e3408e52aa8e09a14402f376070a44b1b85cb36d13', 'timestamp': '1733332878826'}
{'asset_id': '114416409796971863099144323163249651172534872992222856507897414949637892047507', 'changes': [{'price': '0.51', 'side': 'BUY', 'size': '3286.18'}], 'event_type': 'price_change', 'hash': '5036ea7bc4ce1519408d2d4a1a246d1541b546f5', 'market': '0x7aa4a910b31b2c4ddb09d1e3408e52aa8e09a14402f376070a44b1b85cb36d13', 'timestamp': '1733332879192'}
{'asset_id': '114416409796971863099144323163249651172534872992222856507897414949637892047507', 'changes': [{'price': '0.51', 'side': 'BUY', 'size': '3286.18'}], 'event_type': 'price_change', 'hash': '5036ea7bc4ce1519408d2d4a1a246d1541b546f5', 'market': '0x7aa4a910b31b2c4ddb09d1e3408e52aa8e09a14402f376070a44b1b85cb36d13', 'timestamp': '1733332879192'}
{'asset_id': '114416409796971863099144323163249651172534872992222856507897414949637892047507', 'changes': [{'price': '0.5', 'side': 'BUY', 'size': '1615'}], 'event_type': 'price_change', 'hash': '13ebad0c4ec8aa8f52df8073bba72414ab06c767', 'market': '0x7aa4a910b31b2c4ddb09d1e3408e52aa8e09a14402f376070a44b1b85cb36d13', 'timestamp': '1733332880259'}
{'asset_id': '114416409796971863099144323163249651172534872992222856507897414949637892047507', 'changes': [{'price': '0.5', 'side': 'BUY', 'size': '1615'}], 'event_type': 'price_change', 'hash': '13ebad0c4ec8aa8f52df8073bba72414ab06c767', 'market': '0x7aa4a910b31b2c4ddb09d1e3408e52aa8e09a14402f376070a44b1b85cb36d13', 'timestamp': '1733332880259'}
{'asset_id': '114416409796971863099144323163249651172534872992222856507897414949637892047507', 'changes': [{'price': '0.47', 'side': 'BUY', 'size': '3050'}], 'event_type': 'price_change', 'hash': 'be8952252d727b483ed4d7dd8a0e67925dae2874', 'market': '0x7aa4a910b31b2c4ddb09d1e3408e52aa8e09a14402f376070a44b1b85cb36d13', 'timestamp': '1733332880276'}
{'asset_id': '114416409796971863099144323163249651172534872992222856507897414949637892047507', 'changes': [{'price': '0.47', 'side': 'BUY', 'size': '3050'}], 'event_type': 'price_change', 'hash': 'be8952252d727b483ed4d7dd8a0e67925dae2874', 'market': '0x7aa4a910b31b2c4ddb09d1e3408e52aa8e09a14402f376070a44b1b85cb36d13', 'timestamp': '1733332880276'}
{'asset_id': '114416409796971863099144323163249651172534872992222856507897414949637892047507', 'changes': [{'price': '0.55', 'side': 'SELL', 'size': '1248.4'}], 'event_type': 'price_change', 'hash': 'bddf951f986c59063c420e2e8bbc623b29a46124', 'market': '0x7aa4a910b31b2c4ddb09d1e3408e52aa8e09a14402f376070a44b1b85cb36d13', 'timestamp': '1733332887734'}
{'asset_id': '114416409796971863099144323163249651172534872992222856507897414949637892047507', 'changes': [{'price': '0.55', 'side': 'SELL', 'size': '1248.4'}], 'event_type': 'price_change', 'hash': 'bddf951f986c59063c420e2e8bbc623b29a46124', 'market': '0x7aa4a910b31b2c4ddb09d1e3408e52aa8e09a14402f376070a44b1b85cb36d13', 'timestamp': '1733332887734'}
{'asset_id': '114416409796971863099144323163249651172534872992222856507897414949637892047507', 'changes': [{'price': '0.56', 'side': 'SELL', 'size': '2810.1'}], 'event_type': 'price_change', 'hash': '8f29bf95fe26e95aceee52a9b98515831bf8c2e9', 'market': '0x7aa4a910b31b2c4ddb09d1e3408e52aa8e09a14402f376070a44b1b85cb36d13', 'timestamp': '1733332888931'}
{'asset_id': '114416409796971863099144323163249651172534872992222856507897414949637892047507', 'changes': [{'price': '0.56', 'side': 'SELL', 'size': '2810.1'}], 'event_type': 'price_change', 'hash': '8f29bf95fe26e95aceee52a9b98515831bf8c2e9', 'market': '0x7aa4a910b31b2c4ddb09d1e3408e52aa8e09a14402f376070a44b1b85cb36d13', 'timestamp': '1733332888931'}
{'asset_id': '114416409796971863099144323163249651172534872992222856507897414949637892047507', 'changes': [{'price': '0.58', 'side': 'SELL', 'size': '3688.1'}], 'event_type': 'price_change', 'hash': '2476f32fc2f8b2f9607e3777abb436218d4042ba', 'market': '0x7aa4a910b31b2c4ddb09d1e3408e52aa8e09a14402f376070a44b1b85cb36d13', 'timestamp': '1733332889264'}
{'asset_id': '114416409796971863099144323163249651172534872992222856507897414949637892047507', 'changes': [{'price': '0.58', 'side': 'SELL', 'size': '3688.1'}], 'event_type': 'price_change', 'hash': '2476f32fc2f8b2f9607e3777abb436218d4042ba', 'market': '0x7aa4a910b31b2c4ddb09d1e3408e52aa8e09a14402f376070a44b1b85cb36d13', 'timestamp': '1733332889264'}
{'asset_id': '114416409796971863099144323163249651172534872992222856507897414949637892047507', 'changes': [{'price': '0.55', 'side': 'SELL', 'size': '1348.4'}], 'event_type': 'price_change', 'hash': '8e020f9b9946ab8e00eb0af40677a1a8d41813e5', 'market': '0x7aa4a910b31b2c4ddb09d1e3408e52aa8e09a14402f376070a44b1b85cb36d13', 'timestamp': '1733332889659'}
{'asset_id': '114416409796971863099144323163249651172534872992222856507897414949637892047507', 'changes': [{'price': '0.55', 'side': 'SELL', 'size': '1348.4'}], 'event_type': 'price_change', 'hash': '8e020f9b9946ab8e00eb0af40677a1a8d41813e5', 'market': '0x7aa4a910b31b2c4ddb09d1e3408e52aa8e09a14402f376070a44b1b85cb36d13', 'timestamp': '1733332889659'}
{'asset_id': '114416409796971863099144323163249651172534872992222856507897414949637892047507', 'changes': [{'price': '0.53', 'side': 'SELL', 'size': '10.1'}], 'event_type': 'price_change', 'hash': '43b951c200bd42f0f4089b0b09036c69b5073e8e', 'market': '0x7aa4a910b31b2c4ddb09d1e3408e52aa8e09a14402f376070a44b1b85cb36d13', 'timestamp': '1733332896850'}
{'asset_id': '114416409796971863099144323163249651172534872992222856507897414949637892047507', 'changes': [{'price': '0.47', 'side': 'BUY', 'size': '2550'}, {'price': '0.51', 'side': 'BUY', 'size': '2286.18'}, {'price': '0.56', 'side': 'SELL', 'size': '2310.1'}], 'event_type': 'price_change', 'hash': '2c69f9407e51337a7e0c4c7228def426c35d2e9f', 'market': '0x7aa4a910b31b2c4ddb09d1e3408e52aa8e09a14402f376070a44b1b85cb36d13', 'timestamp': '1733332899856'}
{'asset_id': '114416409796971863099144323163249651172534872992222856507897414949637892047507', 'changes': [{'price': '0.47', 'side': 'BUY', 'size': '2550'}, {'price': '0.51', 'side': 'BUY', 'size': '2286.18'}, {'price': '0.56', 'side': 'SELL', 'size': '2310.1'}], 'event_type': 'price_change', 'hash': '2c69f9407e51337a7e0c4c7228def426c35d2e9f', 'market': '0x7aa4a910b31b2c4ddb09d1e3408e52aa8e09a14402f376070a44b1b85cb36d13', 'timestamp': '1733332899856'}
{'asset_id': '114416409796971863099144323163249651172534872992222856507897414949637892047507', 'changes': [{'price': '0.46', 'side': 'BUY', 'size': '500'}], 'event_type': 'price_change', 'hash': 'b63bc83ffe222ffc2b54af58320931f889cda404', 'market': '0x7aa4a910b31b2c4ddb09d1e3408e52aa8e09a14402f376070a44b1b85cb36d13', 'timestamp': '1733332900906'}
{'asset_id': '114416409796971863099144323163249651172534872992222856507897414949637892047507', 'changes': [{'price': '0.46', 'side': 'BUY', 'size': '500'}], 'event_type': 'price_change', 'hash': 'b63bc83ffe222ffc2b54af58320931f889cda404', 'market': '0x7aa4a910b31b2c4ddb09d1e3408e52aa8e09a14402f376070a44b1b85cb36d13', 'timestamp': '1733332900906'}
{'asset_id': '114416409796971863099144323163249651172534872992222856507897414949637892047507', 'changes': [{'price': '0.55', 'side': 'SELL', 'size': '1848.4'}], 'event_type': 'price_change', 'hash': 'bafd3f160d4dac2baf0432870fb54fd248317b0b', 'market': '0x7aa4a910b31b2c4ddb09d1e3408e52aa8e09a14402f376070a44b1b85cb36d13', 'timestamp': '1733332901278'}
{'asset_id': '114416409796971863099144323163249651172534872992222856507897414949637892047507', 'changes': [{'price': '0.55', 'side': 'SELL', 'size': '1848.4'}], 'event_type': 'price_change', 'hash': 'bafd3f160d4dac2baf0432870fb54fd248317b0b', 'market': '0x7aa4a910b31b2c4ddb09d1e3408e52aa8e09a14402f376070a44b1b85cb36d13', 'timestamp': '1733332901278'}
{'asset_id': '114416409796971863099144323163249651172534872992222856507897414949637892047507', 'changes': [{'price': '0.51', 'side': 'BUY', 'size': '3286.18'}], 'event_type': 'price_change', 'hash': '545e0db2c1e0e4ea038f4360d1730306387c700c', 'market': '0x7aa4a910b31b2c4ddb09d1e3408e52aa8e09a14402f376070a44b1b85cb36d13', 'timestamp': '1733332901645'}
{'asset_id': '114416409796971863099144323163249651172534872992222856507897414949637892047507', 'changes': [{'price': '0.51', 'side': 'BUY', 'size': '3286.18'}], 'event_type': 'price_change', 'hash': '545e0db2c1e0e4ea038f4360d1730306387c700c', 'market': '0x7aa4a910b31b2c4ddb09d1e3408e52aa8e09a14402f376070a44b1b85cb36d13', 'timestamp': '1733332901645'}
{'asset_id': '114416409796971863099144323163249651172534872992222856507897414949637892047507', 'changes': [{'price': '0.53', 'side': 'SELL', 'size': '35.09'}], 'event_type': 'price_change', 'hash': 'd30c9140f5383f35247ef2b2db6a0dc91526a5ec', 'market': '0x7aa4a910b31b2c4ddb09d1e3408e52aa8e09a14402f376070a44b1b85cb36d13', 'timestamp': '1733332902335'}
{'asset_id': '114416409796971863099144323163249651172534872992222856507897414949637892047507', 'changes': [{'price': '0.53', 'side': 'SELL', 'size': '35.09'}], 'event_type': 'price_change', 'hash': 'd30c9140f5383f35247ef2b2db6a0dc91526a5ec', 'market': '0x7aa4a910b31b2c4ddb09d1e3408e52aa8e09a14402f376070a44b1b85cb36d13', 'timestamp': '1733332902335'}
{'asset_id': '114416409796971863099144323163249651172534872992222856507897414949637892047507', 'changes': [{'price': '0.57', 'side': 'SELL', 'size': '161.75'}, {'price': '0.48', 'side': 'BUY', 'size': '2342.18'}], 'event_type': 'price_change', 'hash': '98e5d9d9eaffe435bd7c05a4e76ca35d46b84691', 'market': '0x7aa4a910b31b2c4ddb09d1e3408e52aa8e09a14402f376070a44b1b85cb36d13', 'timestamp': '1733332904634'}
{'asset_id': '114416409796971863099144323163249651172534872992222856507897414949637892047507', 'changes': [{'price': '0.57', 'side': 'SELL', 'size': '161.75'}, {'price': '0.48', 'side': 'BUY', 'size': '2342.18'}], 'event_type': 'price_change', 'hash': '98e5d9d9eaffe435bd7c05a4e76ca35d46b84691', 'market': '0x7aa4a910b31b2c4ddb09d1e3408e52aa8e09a14402f376070a44b1b85cb36d13', 'timestamp': '1733332904634'}
{'asset_id': '114416409796971863099144323163249651172534872992222856507897414949637892047507', 'changes': [{'price': '0.57', 'side': 'SELL', 'size': '401.75'}, {'price': '0.49', 'side': 'BUY', 'size': '360'}], 'event_type': 'price_change', 'hash': 'b24a02c0d83c11c9de773eb56ad90498f1bc4912', 'market': '0x7aa4a910b31b2c4ddb09d1e3408e52aa8e09a14402f376070a44b1b85cb36d13', 'timestamp': '1733332904954'}
{'asset_id': '114416409796971863099144323163249651172534872992222856507897414949637892047507', 'changes': [{'price': '0.57', 'side': 'SELL', 'size': '401.75'}, {'price': '0.49', 'side': 'BUY', 'size': '360'}], 'event_type': 'price_change', 'hash': 'b24a02c0d83c11c9de773eb56ad90498f1bc4912', 'market': '0x7aa4a910b31b2c4ddb09d1e3408e52aa8e09a14402f376070a44b1b85cb36d13', 'timestamp': '1733332904954'}
{'asset_id': '114416409796971863099144323163249651172534872992222856507897414949637892047507', 'changes': [{'price': '0.55', 'side': 'SELL', 'size': '1748.4'}], 'event_type': 'price_change', 'hash': '67abfa4abd59d3b4915a57338dd64d320cb98e6c', 'market': '0x7aa4a910b31b2c4ddb09d1e3408e52aa8e09a14402f376070a44b1b85cb36d13', 'timestamp': '1733332907053'}
{'asset_id': '114416409796971863099144323163249651172534872992222856507897414949637892047507', 'changes': [{'price': '0.55', 'side': 'SELL', 'size': '1748.4'}], 'event_type': 'price_change', 'hash': '67abfa4abd59d3b4915a57338dd64d320cb98e6c', 'market': '0x7aa4a910b31b2c4ddb09d1e3408e52aa8e09a14402f376070a44b1b85cb36d13', 'timestamp': '1733332907053'}
{'asset_id': '114416409796971863099144323163249651172534872992222856507897414949637892047507', 'changes': [{'price': '0.54', 'side': 'SELL', 'size': '170.1'}], 'event_type': 'price_change', 'hash': 'f4fffb21b37a3213465d8ab086193bceae812e94', 'market': '0x7aa4a910b31b2c4ddb09d1e3408e52aa8e09a14402f376070a44b1b85cb36d13', 'timestamp': '1733332907928'}
{'asset_id': '114416409796971863099144323163249651172534872992222856507897414949637892047507', 'changes': [{'price': '0.54', 'side': 'SELL', 'size': '170.1'}], 'event_type': 'price_change', 'hash': 'f4fffb21b37a3213465d8ab086193bceae812e94', 'market': '0x7aa4a910b31b2c4ddb09d1e3408e52aa8e09a14402f376070a44b1b85cb36d13', 'timestamp': '1733332907928'}
{'asset_id': '114416409796971863099144323163249651172534872992222856507897414949637892047507', 'changes': [{'price': '0.57', 'side': 'SELL', 'size': '161.75'}, {'price': '0.49', 'side': 'BUY', 'size': '140'}], 'event_type': 'price_change', 'hash': '17f5c9b3a822b8f1c658069045a9df5f124d0415', 'market': '0x7aa4a910b31b2c4ddb09d1e3408e52aa8e09a14402f376070a44b1b85cb36d13', 'timestamp': '1733332908674'}
{'asset_id': '114416409796971863099144323163249651172534872992222856507897414949637892047507', 'changes': [{'price': '0.57', 'side': 'SELL', 'size': '161.75'}, {'price': '0.49', 'side': 'BUY', 'size': '140'}], 'event_type': 'price_change', 'hash': '17f5c9b3a822b8f1c658069045a9df5f124d0415', 'market': '0x7aa4a910b31b2c4ddb09d1e3408e52aa8e09a14402f376070a44b1b85cb36d13', 'timestamp': '1733332908674'}
{'asset_id': '114416409796971863099144323163249651172534872992222856507897414949637892047507', 'changes': [{'price': '0.57', 'side': 'SELL', 'size': '431.75'}, {'price': '0.48', 'side': 'BUY', 'size': '2592.18'}], 'event_type': 'price_change', 'hash': 'f566aa8cce04bfb727a0d31f5cf0d116595e7199', 'market': '0x7aa4a910b31b2c4ddb09d1e3408e52aa8e09a14402f376070a44b1b85cb36d13', 'timestamp': '1733332908951'}
{'asset_id': '114416409796971863099144323163249651172534872992222856507897414949637892047507', 'changes': [{'price': '0.57', 'side': 'SELL', 'size': '431.75'}, {'price': '0.48', 'side': 'BUY', 'size': '2592.18'}], 'event_type': 'price_change', 'hash': 'f566aa8cce04bfb727a0d31f5cf0d116595e7199', 'market': '0x7aa4a910b31b2c4ddb09d1e3408e52aa8e09a14402f376070a44b1b85cb36d13', 'timestamp': '1733332908951'}
{'asset_id': '114416409796971863099144323163249651172534872992222856507897414949637892047507', 'changes': [{'price': '0.51', 'side': 'BUY', 'size': '2086.18'}], 'event_type': 'price_change', 'hash': '71d17560fcb8397861d3170356f793d50c18fe9b', 'market': '0x7aa4a910b31b2c4ddb09d1e3408e52aa8e09a14402f376070a44b1b85cb36d13', 'timestamp': '1733332913733'}
{'asset_id': '114416409796971863099144323163249651172534872992222856507897414949637892047507', 'changes': [{'price': '0.51', 'side': 'BUY', 'size': '2086.18'}], 'event_type': 'price_change', 'hash': '71d17560fcb8397861d3170356f793d50c18fe9b', 'market': '0x7aa4a910b31b2c4ddb09d1e3408e52aa8e09a14402f376070a44b1b85cb36d13', 'timestamp': '1733332913733'}
{'asset_id': '114416409796971863099144323163249651172534872992222856507897414949637892047507', 'changes': [{'price': '0.57', 'side': 'SELL', 'size': '380.1'}], 'event_type': 'price_change', 'hash': 'd23503d14e690b0f0bfeeb8bcc446fe23a6df628', 'market': '0x7aa4a910b31b2c4ddb09d1e3408e52aa8e09a14402f376070a44b1b85cb36d13', 'timestamp': '1733332918531'}
{'asset_id': '114416409796971863099144323163249651172534872992222856507897414949637892047507', 'changes': [{'price': '0.57', 'side': 'SELL', 'size': '380.1'}], 'event_type': 'price_change', 'hash': 'd23503d14e690b0f0bfeeb8bcc446fe23a6df628', 'market': '0x7aa4a910b31b2c4ddb09d1e3408e52aa8e09a14402f376070a44b1b85cb36d13', 'timestamp': '1733332918531'}
{'asset_id': '114416409796971863099144323163249651172534872992222856507897414949637892047507', 'changes': [{'price': '0.56', 'side': 'SELL', 'size': '2361.75'}], 'event_type': 'price_change', 'hash': '84f4e125bfd255a6a6c4c14b8efc5cb2cec6e825', 'market': '0x7aa4a910b31b2c4ddb09d1e3408e52aa8e09a14402f376070a44b1b85cb36d13', 'timestamp': '1733332919431'}
{'asset_id': '114416409796971863099144323163249651172534872992222856507897414949637892047507', 'changes': [{'price': '0.56', 'side': 'SELL', 'size': '2361.75'}], 'event_type': 'price_change', 'hash': '84f4e125bfd255a6a6c4c14b8efc5cb2cec6e825', 'market': '0x7aa4a910b31b2c4ddb09d1e3408e52aa8e09a14402f376070a44b1b85cb36d13', 'timestamp': '1733332919431'}
{'asset_id': '114416409796971863099144323163249651172534872992222856507897414949637892047507', 'changes': [{'price': '0.5', 'side': 'BUY', 'size': '2815'}], 'event_type': 'price_change', 'hash': '28ead10830b3e98e7bb47e61ea02cc8a623b44dc', 'market': '0x7aa4a910b31b2c4ddb09d1e3408e52aa8e09a14402f376070a44b1b85cb36d13', 'timestamp': '1733332920330'}
{'asset_id': '114416409796971863099144323163249651172534872992222856507897414949637892047507', 'changes': [{'price': '0.5', 'side': 'BUY', 'size': '2815'}], 'event_type': 'price_change', 'hash': '28ead10830b3e98e7bb47e61ea02cc8a623b44dc', 'market': '0x7aa4a910b31b2c4ddb09d1e3408e52aa8e09a14402f376070a44b1b85cb36d13', 'timestamp': '1733332920330'}
{'asks': [{'price': '0.99', 'size': '4217.01'}, {'price': '0.98', 'size': '505'}, {'price': '0.97', 'size': '511.03'}, {'price': '0.96', 'size': '300'}, {'price': '0.95', 'size': '657.12'}, {'price': '0.94', 'size': '300'}, {'price': '0.92', 'size': '20000.45'}, {'price': '0.91', 'size': '10406.3'}, {'price': '0.9', 'size': '4587.5'}, {'price': '0.89', 'size': '13017.18'}, {'price': '0.88', 'size': '200'}, {'price': '0.87', 'size': '3229'}, {'price': '0.86', 'size': '17.1'}, {'price': '0.85', 'size': '109.68'}, {'price': '0.84', 'size': '250'}, {'price': '0.83', 'size': '100'}, {'price': '0.82', 'size': '16029'}, {'price': '0.81', 'size': '45721.39'}, {'price': '0.8', 'size': '26531'}, {'price': '0.79', 'size': '7110'}, {'price': '0.78', 'size': '10350'}, {'price': '0.77', 'size': '67'}, {'price': '0.76', 'size': '200'}, {'price': '0.75', 'size': '18329.25'}, {'price': '0.74', 'size': '11370.7'}, {'price': '0.73', 'size': '5020.1'}, {'price': '0.72', 'size': '380.52'}, {'price': '0.71', 'size': '15073.2'}, {'price': '0.7', 'size': '5570.1'}, {'price': '0.69', 'size': '6088.6'}, {'price': '0.68', 'size': '2131.34'}, {'price': '0.67', 'size': '3010.1'}, {'price': '0.66', 'size': '4510.1'}, {'price': '0.65', 'size': '1010.1'}, {'price': '0.64', 'size': '1230.1'}, {'price': '0.63', 'size': '210.1'}, {'price': '0.62', 'size': '300.1'}, {'price': '0.61', 'size': '511.06'}, {'price': '0.6', 'size': '467.85'}, {'price': '0.59', 'size': '5510'}, {'price': '0.58', 'size': '3688.1'}, {'price': '0.57', 'size': '380.1'}, {'price': '0.56', 'size': '2361.75'}, {'price': '0.55', 'size': '1714.23'}], 'asset_id': '114416409796971863099144323163249651172534872992222856507897414949637892047507', 'bids': [{'price': '0.01', 'size': '2850.27'}, {'price': '0.02', 'size': '500'}, {'price': '0.03', 'size': '500'}, {'price': '0.04', 'size': '300'}, {'price': '0.05', 'size': '320'}, {'price': '0.06', 'size': '300'}, {'price': '0.08', 'size': '250'}, {'price': '0.09', 'size': '300'}, {'price': '0.1', 'size': '205'}, {'price': '0.11', 'size': '5454'}, {'price': '0.12', 'size': '200'}, {'price': '0.13', 'size': '426.92'}, {'price': '0.14', 'size': '15'}, {'price': '0.15', 'size': '110'}, {'price': '0.16', 'size': '4709.51'}, {'price': '0.18', 'size': '19.13'}, {'price': '0.19', 'size': '120'}, {'price': '0.2', 'size': '691.17'}, {'price': '0.24', 'size': '5027'}, {'price': '0.25', 'size': '86.66'}, {'price': '0.27', 'size': '215.25'}, {'price': '0.29', 'size': '1102.28'}, {'price': '0.31', 'size': '1130.65'}, {'price': '0.32', 'size': '200'}, {'price': '0.33', 'size': '4620'}, {'price': '0.35', 'size': '232'}, {'price': '0.39', 'size': '10.5'}, {'price': '0.4', 'size': '3135'}, {'price': '0.41', 'size': '20'}, {'price': '0.42', 'size': '3050'}, {'price': '0.43', 'size': '50'}, {'price': '0.44', 'size': '3660'}, {'price': '0.45', 'size': '478'}, {'price': '0.46', 'size': '500'}, {'price': '0.47', 'size': '2550'}, {'price': '0.48', 'size': '2592.18'}, {'price': '0.49', 'size': '140'}, {'price': '0.5', 'size': '2815'}, {'price': '0.51', 'size': '2086.18'}, {'price': '0.52', 'size': '1000'}], 'event_type': 'book', 'hash': 'e1048d3bb8a49856a545d74af04fe371339f629f', 'market': '0x7aa4a910b31b2c4ddb09d1e3408e52aa8e09a14402f376070a44b1b85cb36d13', 'timestamp': '1733332922163'}
{'asset_id': '114416409796971863099144323163249651172534872992222856507897414949637892047507', 'event_type': 'last_trade_price', 'fee_rate_bps': '0', 'market': '0x7aa4a910b31b2c4ddb09d1e3408e52aa8e09a14402f376070a44b1b85cb36d13', 'price': '0.54', 'side': 'BUY', 'size': '239.350544', 'timestamp': '1733332922192'}
{'asks': [{'price': '0.99', 'size': '4217.01'}, {'price': '0.98', 'size': '505'}, {'price': '0.97', 'size': '511.03'}, {'price': '0.96', 'size': '300'}, {'price': '0.95', 'size': '657.12'}, {'price': '0.94', 'size': '300'}, {'price': '0.92', 'size': '20000.45'}, {'price': '0.91', 'size': '10406.3'}, {'price': '0.9', 'size': '4587.5'}, {'price': '0.89', 'size': '13017.18'}, {'price': '0.88', 'size': '200'}, {'price': '0.87', 'size': '3229'}, {'price': '0.86', 'size': '17.1'}, {'price': '0.85', 'size': '109.68'}, {'price': '0.84', 'size': '250'}, {'price': '0.83', 'size': '100'}, {'price': '0.82', 'size': '16029'}, {'price': '0.81', 'size': '45721.39'}, {'price': '0.8', 'size': '26531'}, {'price': '0.79', 'size': '7110'}, {'price': '0.78', 'size': '10350'}, {'price': '0.77', 'size': '67'}, {'price': '0.76', 'size': '200'}, {'price': '0.75', 'size': '18329.25'}, {'price': '0.74', 'size': '11370.7'}, {'price': '0.73', 'size': '5020.1'}, {'price': '0.72', 'size': '380.52'}, {'price': '0.71', 'size': '15073.2'}, {'price': '0.7', 'size': '5570.1'}, {'price': '0.69', 'size': '6088.6'}, {'price': '0.68', 'size': '2131.34'}, {'price': '0.67', 'size': '3010.1'}, {'price': '0.66', 'size': '4510.1'}, {'price': '0.65', 'size': '1010.1'}, {'price': '0.64', 'size': '1230.1'}, {'price': '0.63', 'size': '210.1'}, {'price': '0.62', 'size': '300.1'}, {'price': '0.61', 'size': '511.06'}, {'price': '0.6', 'size': '467.85'}, {'price': '0.59', 'size': '5510'}, {'price': '0.58', 'size': '3688.1'}, {'price': '0.57', 'size': '380.1'}, {'price': '0.56', 'size': '2361.75'}, {'price': '0.55', 'size': '1714.23'}], 'asset_id': '114416409796971863099144323163249651172534872992222856507897414949637892047507', 'bids': [{'price': '0.01', 'size': '2850.27'}, {'price': '0.02', 'size': '500'}, {'price': '0.03', 'size': '500'}, {'price': '0.04', 'size': '300'}, {'price': '0.05', 'size': '320'}, {'price': '0.06', 'size': '300'}, {'price': '0.08', 'size': '250'}, {'price': '0.09', 'size': '300'}, {'price': '0.1', 'size': '205'}, {'price': '0.11', 'size': '5454'}, {'price': '0.12', 'size': '200'}, {'price': '0.13', 'size': '426.92'}, {'price': '0.14', 'size': '15'}, {'price': '0.15', 'size': '110'}, {'price': '0.16', 'size': '4709.51'}, {'price': '0.18', 'size': '19.13'}, {'price': '0.19', 'size': '120'}, {'price': '0.2', 'size': '691.17'}, {'price': '0.24', 'size': '5027'}, {'price': '0.25', 'size': '86.66'}, {'price': '0.27', 'size': '215.25'}, {'price': '0.29', 'size': '1102.28'}, {'price': '0.31', 'size': '1130.65'}, {'price': '0.32', 'size': '200'}, {'price': '0.33', 'size': '4620'}, {'price': '0.35', 'size': '232'}, {'price': '0.39', 'size': '10.5'}, {'price': '0.4', 'size': '3135'}, {'price': '0.41', 'size': '20'}, {'price': '0.42', 'size': '3050'}, {'price': '0.43', 'size': '50'}, {'price': '0.44', 'size': '3660'}, {'price': '0.45', 'size': '478'}, {'price': '0.46', 'size': '500'}, {'price': '0.47', 'size': '2550'}, {'price': '0.48', 'size': '2592.18'}, {'price': '0.49', 'size': '140'}, {'price': '0.5', 'size': '2815'}, {'price': '0.51', 'size': '2086.18'}, {'price': '0.52', 'size': '1000'}], 'event_type': 'book', 'hash': 'e1048d3bb8a49856a545d74af04fe371339f629f', 'market': '0x7aa4a910b31b2c4ddb09d1e3408e52aa8e09a14402f376070a44b1b85cb36d13', 'timestamp': '1733332922163'}
{'asset_id': '114416409796971863099144323163249651172534872992222856507897414949637892047507', 'event_type': 'last_trade_price', 'fee_rate_bps': '0', 'market': '0x7aa4a910b31b2c4ddb09d1e3408e52aa8e09a14402f376070a44b1b85cb36d13', 'price': '0.54', 'side': 'BUY', 'size': '239.350544', 'timestamp': '1733332922192'}
{'asset_id': '114416409796971863099144323163249651172534872992222856507897414949637892047507', 'changes': [{'price': '0.57', 'side': 'SELL', 'size': '110.1'}, {'price': '0.48', 'side': 'BUY', 'size': '2342.18'}], 'event_type': 'price_change', 'hash': '567b42d8bb49fc62d8747515adfad104f6bf7e44', 'market': '0x7aa4a910b31b2c4ddb09d1e3408e52aa8e09a14402f376070a44b1b85cb36d13', 'timestamp': '1733332927315'}
{'asset_id': '114416409796971863099144323163249651172534872992222856507897414949637892047507', 'changes': [{'price': '0.57', 'side': 'SELL', 'size': '110.1'}, {'price': '0.48', 'side': 'BUY', 'size': '2342.18'}], 'event_type': 'price_change', 'hash': '567b42d8bb49fc62d8747515adfad104f6bf7e44', 'market': '0x7aa4a910b31b2c4ddb09d1e3408e52aa8e09a14402f376070a44b1b85cb36d13', 'timestamp': '1733332927315'}
{'asset_id': '114416409796971863099144323163249651172534872992222856507897414949637892047507', 'changes': [{'price': '0.49', 'side': 'BUY', 'size': '390'}], 'event_type': 'price_change', 'hash': '5b22371b1856285b9e8df5469ef5595e7f2105d4', 'market': '0x7aa4a910b31b2c4ddb09d1e3408e52aa8e09a14402f376070a44b1b85cb36d13', 'timestamp': '1733332927578'}
{'asset_id': '114416409796971863099144323163249651172534872992222856507897414949637892047507', 'changes': [{'price': '0.49', 'side': 'BUY', 'size': '390'}], 'event_type': 'price_change', 'hash': '5b22371b1856285b9e8df5469ef5595e7f2105d4', 'market': '0x7aa4a910b31b2c4ddb09d1e3408e52aa8e09a14402f376070a44b1b85cb36d13', 'timestamp': '1733332927578'}
{'asset_id': '114416409796971863099144323163249651172534872992222856507897414949637892047507', 'changes': [{'price': '0.58', 'side': 'SELL', 'size': '3958.1'}], 'event_type': 'price_change', 'hash': 'a91480184be6b39e42027108d3c176686a6c02f0', 'market': '0x7aa4a910b31b2c4ddb09d1e3408e52aa8e09a14402f376070a44b1b85cb36d13', 'timestamp': '1733332927884'}
{'asset_id': '114416409796971863099144323163249651172534872992222856507897414949637892047507', 'changes': [{'price': '0.58', 'side': 'SELL', 'size': '3958.1'}], 'event_type': 'price_change', 'hash': 'a91480184be6b39e42027108d3c176686a6c02f0', 'market': '0x7aa4a910b31b2c4ddb09d1e3408e52aa8e09a14402f376070a44b1b85cb36d13', 'timestamp': '1733332927884'}
{'asset_id': '114416409796971863099144323163249651172534872992222856507897414949637892047507', 'changes': [{'price': '0.51', 'side': 'BUY', 'size': '2186.18'}], 'event_type': 'price_change', 'hash': '89d9f06199c1964e2c64aa69b2c793bf8ec0e703', 'market': '0x7aa4a910b31b2c4ddb09d1e3408e52aa8e09a14402f376070a44b1b85cb36d13', 'timestamp': '1733332932766'}
{'asset_id': '114416409796971863099144323163249651172534872992222856507897414949637892047507', 'changes': [{'price': '0.51', 'side': 'BUY', 'size': '2186.18'}], 'event_type': 'price_change', 'hash': '89d9f06199c1964e2c64aa69b2c793bf8ec0e703', 'market': '0x7aa4a910b31b2c4ddb09d1e3408e52aa8e09a14402f376070a44b1b85cb36d13', 'timestamp': '1733332932766'}
{'asset_id': '114416409796971863099144323163249651172534872992222856507897414949637892047507', 'changes': [{'price': '0.51', 'side': 'BUY', 'size': '2086.18'}], 'event_type': 'price_change', 'hash': '7742fbc8eb5128dfa3ea7a9399c1b37ce3577994', 'market': '0x7aa4a910b31b2c4ddb09d1e3408e52aa8e09a14402f376070a44b1b85cb36d13', 'timestamp': '1733332934552'}
{'asset_id': '114416409796971863099144323163249651172534872992222856507897414949637892047507', 'changes': [{'price': '0.51', 'side': 'BUY', 'size': '2086.18'}], 'event_type': 'price_change', 'hash': '7742fbc8eb5128dfa3ea7a9399c1b37ce3577994', 'market': '0x7aa4a910b31b2c4ddb09d1e3408e52aa8e09a14402f376070a44b1b85cb36d13', 'timestamp': '1733332934552'}
{'asset_id': '114416409796971863099144323163249651172534872992222856507897414949637892047507', 'changes': [{'price': '0.56', 'side': 'SELL', 'size': '1161.75'}], 'event_type': 'price_change', 'hash': '396ab7be7b22a6498699737ce7d8bfc1808ea290', 'market': '0x7aa4a910b31b2c4ddb09d1e3408e52aa8e09a14402f376070a44b1b85cb36d13', 'timestamp': '1733332937010'}
{'asset_id': '114416409796971863099144323163249651172534872992222856507897414949637892047507', 'changes': [{'price': '0.46', 'side': 'BUY', 'size': '0'}, {'price': '0.55', 'side': 'SELL', 'size': '1214.23'}, {'price': '0.51', 'side': 'BUY', 'size': '1086.18'}], 'event_type': 'price_change', 'hash': 'bc4acd2ea7ecf31a3429198ffd1ec9333fa084ca', 'market': '0x7aa4a910b31b2c4ddb09d1e3408e52aa8e09a14402f376070a44b1b85cb36d13', 'timestamp': '1733332937090'}
{'asset_id': '114416409796971863099144323163249651172534872992222856507897414949637892047507', 'changes': [{'price': '0.46', 'side': 'BUY', 'size': '0'}, {'price': '0.55', 'side': 'SELL', 'size': '1214.23'}, {'price': '0.51', 'side': 'BUY', 'size': '1086.18'}], 'event_type': 'price_change', 'hash': 'bc4acd2ea7ecf31a3429198ffd1ec9333fa084ca', 'market': '0x7aa4a910b31b2c4ddb09d1e3408e52aa8e09a14402f376070a44b1b85cb36d13', 'timestamp': '1733332937090'}
{'asset_id': '114416409796971863099144323163249651172534872992222856507897414949637892047507', 'changes': [{'price': '0.46', 'side': 'BUY', 'size': '500'}], 'event_type': 'price_change', 'hash': 'b2bb26d740bc5d4b725a4f7e206b215bfb34f4fa', 'market': '0x7aa4a910b31b2c4ddb09d1e3408e52aa8e09a14402f376070a44b1b85cb36d13', 'timestamp': '1733332938173'}
{'asset_id': '114416409796971863099144323163249651172534872992222856507897414949637892047507', 'changes': [{'price': '0.46', 'side': 'BUY', 'size': '500'}], 'event_type': 'price_change', 'hash': 'b2bb26d740bc5d4b725a4f7e206b215bfb34f4fa', 'market': '0x7aa4a910b31b2c4ddb09d1e3408e52aa8e09a14402f376070a44b1b85cb36d13', 'timestamp': '1733332938173'}
{'asset_id': '114416409796971863099144323163249651172534872992222856507897414949637892047507', 'changes': [{'price': '0.55', 'side': 'SELL', 'size': '1714.23'}], 'event_type': 'price_change', 'hash': '0d717943382ab673f4fadeb2ac38b319b906d3d6', 'market': '0x7aa4a910b31b2c4ddb09d1e3408e52aa8e09a14402f376070a44b1b85cb36d13', 'timestamp': '1733332938547'}
{'asset_id': '114416409796971863099144323163249651172534872992222856507897414949637892047507', 'changes': [{'price': '0.55', 'side': 'SELL', 'size': '1714.23'}], 'event_type': 'price_change', 'hash': '0d717943382ab673f4fadeb2ac38b319b906d3d6', 'market': '0x7aa4a910b31b2c4ddb09d1e3408e52aa8e09a14402f376070a44b1b85cb36d13', 'timestamp': '1733332938547'}
{'asset_id': '114416409796971863099144323163249651172534872992222856507897414949637892047507', 'changes': [{'price': '0.5', 'side': 'BUY', 'size': '3815'}], 'event_type': 'price_change', 'hash': '5275adedadde399d18f89dfa4859215ba5abcd6c', 'market': '0x7aa4a910b31b2c4ddb09d1e3408e52aa8e09a14402f376070a44b1b85cb36d13', 'timestamp': '1733332938919'}
{'asset_id': '114416409796971863099144323163249651172534872992222856507897414949637892047507', 'changes': [{'price': '0.5', 'side': 'BUY', 'size': '3815'}], 'event_type': 'price_change', 'hash': '5275adedadde399d18f89dfa4859215ba5abcd6c', 'market': '0x7aa4a910b31b2c4ddb09d1e3408e52aa8e09a14402f376070a44b1b85cb36d13', 'timestamp': '1733332938919'}
{'asset_id': '114416409796971863099144323163249651172534872992222856507897414949637892047507', 'changes': [{'price': '0.58', 'side': 'SELL', 'size': '1958.1'}], 'event_type': 'price_change', 'hash': '3da1d19011d4030011fffaf7a1fbb3f624ae24fc', 'market': '0x7aa4a910b31b2c4ddb09d1e3408e52aa8e09a14402f376070a44b1b85cb36d13', 'timestamp': '1733332940012'}
{'asset_id': '114416409796971863099144323163249651172534872992222856507897414949637892047507', 'changes': [{'price': '0.51', 'side': 'BUY', 'size': '1186.18'}], 'event_type': 'price_change', 'hash': '5d9a92667edecdd91af4b38f72fac05f9ed0ee2b', 'market': '0x7aa4a910b31b2c4ddb09d1e3408e52aa8e09a14402f376070a44b1b85cb36d13', 'timestamp': '1733332942201'}
{'asset_id': '114416409796971863099144323163249651172534872992222856507897414949637892047507', 'changes': [{'price': '0.51', 'side': 'BUY', 'size': '1186.18'}], 'event_type': 'price_change', 'hash': '5d9a92667edecdd91af4b38f72fac05f9ed0ee2b', 'market': '0x7aa4a910b31b2c4ddb09d1e3408e52aa8e09a14402f376070a44b1b85cb36d13', 'timestamp': '1733332942201'}
