{'asks': [{'price': '0.99', 'size': '4217.01'}, {'price': '0.98', 'size': '505'}, {'price': '0.97', 'size': '511.03'}, {'price': '0.96', 'size': '300'}, {'price': '0.95', 'size': '657.12'}, {'price': '0.94', 'size': '300'}, {'price': '0.92', 'size': '20000.45'}, {'price': '0.91', 'size': '10406.3'}, {'price': '0.9', 'size': '4587.5'}, {'price': '0.89', 'size': '13017.18'}, {'price': '0.88', 'size': '200'}, {'price': '0.87', 'size': '3229'}, {'price': '0.86', 'size': '17.1'}, {'price': '0.85', 'size': '109.68'}, {'price': '0.84', 'size': '250'}, {'price': '0.83', 'size': '100'}, {'price': '0.82', 'size': '16029'}, {'price': '0.81', 'size': '45721.39'}, {'price': '0.8', 'size': '26531'}, {'price': '0.79', 'size': '7110'}, {'price': '0.78', 'size': '15350'}, {'price': '0.77', 'size': '67'}, {'price': '0.76', 'size': '200'}, {'price': '0.75', 'size': '13329.25'}, {'price': '0.74', 'size': '11370.7'}, {'price': '0.73', 'size': '5020.1'}, {'price': '0.72', 'size': '380.52'}, {'price': '0.71', 'size': '15073.2'}, {'price': '0.7', 'size': '5570.1'}, {'price': '0.69', 'size': '6088.6'}, {'price': '0.68', 'size': '6131.34'}, {'price': '0.67', 'size': '3010.1'}, {'price': '0.66', 'size': '510.1'}, {'price': '0.65', 'size': '1010.1'}, {'price': '0.64', 'size': '4230.1'}, {'price': '0.63', 'size': '210.1'}, {'price': '0.62', 'size': '400.1'}, {'price': '0.61', 'size': '861.06'}, {'price': '0.6', 'size': '3067.85'}, {'price': '0.59', 'size': '3610'}, {'price': '0.58', 'size': '50.47'}, {'price': '0.57', 'size': '1700'}], 'asset_id': '114416409796971863099144323163249651172534872992222856507897414949637892047507', 'bids': [{'price': '0.01', 'size': '2850.27'}, {'price': '0.02', 'size': '500'}, {'price': '0.03', 'size': '500'}, {'price': '0.04', 'size': '300'}, {'price': '0.05', 'size': '320'}, {'price': '0.06', 'size': '300'}, {'price': '0.08', 'size': '250'}, {'price': '0.09', 'size': '300'}, {'price': '0.1', 'size': '6205'}, {'price': '0.12', 'size': '200'}, {'price': '0.13', 'size': '426.92'}, {'price': '0.14', 'size': '15'}, {'price': '0.15', 'size': '110'}, {'price': '0.16', 'size': '4709.51'}, {'price': '0.18', 'size': '19.13'}, {'price': '0.19', 'size': '120'}, {'price': '0.2', 'size': '691.17'}, {'price': '0.24', 'size': '5027'}, {'price': '0.25', 'size': '86.66'}, {'price': '0.27', 'size': '215.25'}, {'price': '0.29', 'size': '1102.28'}, {'price': '0.31', 'size': '1130.65'}, {'price': '0.32', 'size': '200'}, {'price': '0.33', 'size': '620'}, {'price': '0.35', 'size': '232'}, {'price': '0.37', 'size': '4000'}, {'price': '0.39', 'size': '10.5'}, {'price': '0.4', 'size': '3135'}, {'price': '0.41', 'size': '20'}, {'price': '0.42', 'size': '3050'}, {'price': '0.43', 'size': '50'}, {'price': '0.44', 'size': '3660'}, {'price': '0.45', 'size': '478'}, {'price': '0.47', 'size': '797.23'}, {'price': '0.48', 'size': '2742.18'}, {'price': '0.49', 'size': '40'}, {'price': '0.5', 'size': '2015'}, {'price': '0.51', 'size': '3686.18'}, {'price': '0.52', 'size': '885.92'}, {'price': '0.53', 'size': '2318.99'}, {'price': '0.54', 'size': '131.19'}, {'price': '0.55', 'size': '3972.77'}, {'price': '0.56', 'size': '3653.28'}], 'event_type': 'book', 'hash': '2416d75d1e88c1bf40ba9cafe645f709f8b2b50e', 'market': '0x7aa4a910b31b2c4ddb09d1e3408e52aa8e09a14402f376070a44b1b85cb36d13', 'timestamp': '1733334402890'}
{'asks': [{'price': '0.99', 'size': '4217.01'}, {'price': '0.98', 'size': '505'}, {'price': '0.97', 'size': '511.03'}, {'price': '0.96', 'size': '300'}, {'price': '0.95', 'size': '657.12'}, {'price': '0.94', 'size': '300'}, {'price': '0.92', 'size': '20000.45'}, {'price': '0.91', 'size': '10406.3'}, {'price': '0.9', 'size': '4587.5'}, {'price': '0.89', 'size': '13017.18'}, {'price': '0.88', 'size': '200'}, {'price': '0.87', 'size': '3229'}, {'price': '0.86', 'size': '17.1'}, {'price': '0.85', 'size': '109.68'}, {'price': '0.84', 'size': '250'}, {'price': '0.83', 'size': '100'}, {'price': '0.82', 'size': '16029'}, {'price': '0.81', 'size': '45721.39'}, {'price': '0.8', 'size': '26531'}, {'price': '0.79', 'size': '7110'}, {'price': '0.78', 'size': '15350'}, {'price': '0.77', 'size': '67'}, {'price': '0.76', 'size': '200'}, {'price': '0.75', 'size': '13329.25'}, {'price': '0.74', 'size': '11370.7'}, {'price': '0.73', 'size': '5020.1'}, {'price': '0.72', 'size': '380.52'}, {'price': '0.71', 'size': '15073.2'}, {'price': '0.7', 'size': '5570.1'}, {'price': '0.69', 'size': '6088.6'}, {'price': '0.68', 'size': '6131.34'}, {'price': '0.67', 'size': '3010.1'}, {'price': '0.66', 'size': '510.1'}, {'price': '0.65', 'size': '1010.1'}, {'price': '0.64', 'size': '4230.1'}, {'price': '0.63', 'size': '210.1'}, {'price': '0.62', 'size': '400.1'}, {'price': '0.61', 'size': '861.06'}, {'price': '0.6', 'size': '3067.85'}, {'price': '0.59', 'size': '3610'}, {'price': '0.58', 'size': '50.47'}, {'price': '0.57', 'size': '1690'}], 'asset_id': '114416409796971863099144323163249651172534872992222856507897414949637892047507', 'bids': [{'price': '0.01', 'size': '2850.27'}, {'price': '0.02', 'size': '500'}, {'price': '0.03', 'size': '500'}, {'price': '0.04', 'size': '300'}, {'price': '0.05', 'size': '320'}, {'price': '0.06', 'size': '300'}, {'price': '0.08', 'size': '250'}, {'price': '0.09', 'size': '300'}, {'price': '0.1', 'size': '6205'}, {'price': '0.12', 'size': '200'}, {'price': '0.13', 'size': '426.92'}, {'price': '0.14', 'size': '15'}, {'price': '0.15', 'size': '110'}, {'price': '0.16', 'size': '4709.51'}, {'price': '0.18', 'size': '19.13'}, {'price': '0.19', 'size': '120'}, {'price': '0.2', 'size': '691.17'}, {'price': '0.24', 'size': '5027'}, {'price': '0.25', 'size': '86.66'}, {'price': '0.27', 'size': '215.25'}, {'price': '0.29', 'size': '1102.28'}, {'price': '0.31', 'size': '1130.65'}, {'price': '0.32', 'size': '200'}, {'price': '0.33', 'size': '620'}, {'price': '0.35', 'size': '232'}, {'price': '0.37', 'size': '4000'}, {'price': '0.39', 'size': '10.5'}, {'price': '0.4', 'size': '3135'}, {'price': '0.41', 'size': '20'}, {'price': '0.42', 'size': '3050'}, {'price': '0.43', 'size': '50'}, {'price': '0.44', 'size': '3660'}, {'price': '0.45', 'size': '478'}, {'price': '0.47', 'size': '797.23'}, {'price': '0.48', 'size': '2742.18'}, {'price': '0.49', 'size': '40'}, {'price': '0.5', 'size': '2015'}, {'price': '0.51', 'size': '3686.18'}, {'price': '0.52', 'size': '885.92'}, {'price': '0.53', 'size': '2318.99'}, {'price': '0.54', 'size': '131.19'}, {'price': '0.55', 'size': '3972.77'}, {'price': '0.56', 'size': '3653.28'}], 'event_type': 'book', 'hash': 'c413a628ef5070262d9b8dfce78bc773aee343ba', 'market': '0x7aa4a910b31b2c4ddb09d1e3408e52aa8e09a14402f376070a44b1b85cb36d13', 'timestamp': '1733334405713'}
{'asks': [{'price': '0.99', 'size': '4217.01'}, {'price': '0.98', 'size': '505'}, {'price': '0.97', 'size': '511.03'}, {'price': '0.96', 'size': '300'}, {'price': '0.95', 'size': '657.12'}, {'price': '0.94', 'size': '300'}, {'price': '0.92', 'size': '20000.45'}, {'price': '0.91', 'size': '10406.3'}, {'price': '0.9', 'size': '4587.5'}, {'price': '0.89', 'size': '13017.18'}, {'price': '0.88', 'size': '200'}, {'price': '0.87', 'size': '3229'}, {'price': '0.86', 'size': '17.1'}, {'price': '0.85', 'size': '109.68'}, {'price': '0.84', 'size': '250'}, {'price': '0.83', 'size': '100'}, {'price': '0.82', 'size': '16029'}, {'price': '0.81', 'size': '45721.39'}, {'price': '0.8', 'size': '26531'}, {'price': '0.79', 'size': '7110'}, {'price': '0.78', 'size': '15350'}, {'price': '0.77', 'size': '67'}, {'price': '0.76', 'size': '200'}, {'price': '0.75', 'size': '13329.25'}, {'price': '0.74', 'size': '11370.7'}, {'price': '0.73', 'size': '5020.1'}, {'price': '0.72', 'size': '380.52'}, {'price': '0.71', 'size': '15073.2'}, {'price': '0.7', 'size': '5570.1'}, {'price': '0.69', 'size': '6088.6'}, {'price': '0.68', 'size': '6131.34'}, {'price': '0.67', 'size': '3010.1'}, {'price': '0.66', 'size': '510.1'}, {'price': '0.65', 'size': '1010.1'}, {'price': '0.64', 'size': '4230.1'}, {'price': '0.63', 'size': '210.1'}, {'price': '0.62', 'size': '400.1'}, {'price': '0.61', 'size': '861.06'}, {'price': '0.6', 'size': '3067.85'}, {'price': '0.59', 'size': '3610'}, {'price': '0.58', 'size': '50.47'}, {'price': '0.57', 'size': '1690'}], 'asset_id': '114416409796971863099144323163249651172534872992222856507897414949637892047507', 'bids': [{'price': '0.01', 'size': '2850.27'}, {'price': '0.02', 'size': '500'}, {'price': '0.03', 'size': '500'}, {'price': '0.04', 'size': '300'}, {'price': '0.05', 'size': '320'}, {'price': '0.06', 'size': '300'}, {'price': '0.08', 'size': '250'}, {'price': '0.09', 'size': '300'}, {'price': '0.1', 'size': '6205'}, {'price': '0.12', 'size': '200'}, {'price': '0.13', 'size': '426.92'}, {'price': '0.14', 'size': '15'}, {'price': '0.15', 'size': '110'}, {'price': '0.16', 'size': '4709.51'}, {'price': '0.18', 'size': '19.13'}, {'price': '0.19', 'size': '120'}, {'price': '0.2', 'size': '691.17'}, {'price': '0.24', 'size': '5027'}, {'price': '0.25', 'size': '86.66'}, {'price': '0.27', 'size': '215.25'}, {'price': '0.29', 'size': '1102.28'}, {'price': '0.31', 'size': '1130.65'}, {'price': '0.32', 'size': '200'}, {'price': '0.33', 'size': '620'}, {'price': '0.35', 'size': '232'}, {'price': '0.37', 'size': '4000'}, {'price': '0.39', 'size': '10.5'}, {'price': '0.4', 'size': '3135'}, {'price': '0.41', 'size': '20'}, {'price': '0.42', 'size': '3050'}, {'price': '0.43', 'size': '50'}, {'price': '0.44', 'size': '3660'}, {'price': '0.45', 'size': '478'}, {'price': '0.47', 'size': '797.23'}, {'price': '0.48', 'size': '2742.18'}, {'price': '0.49', 'size': '40'}, {'price': '0.5', 'size': '2015'}, {'price': '0.51', 'size': '3686.18'}, {'price': '0.52', 'size': '885.92'}, {'price': '0.53', 'size': '2318.99'}, {'price': '0.54', 'size': '131.19'}, {'price': '0.55', 'size': '3972.77'}, {'price': '0.56', 'size': '3653.28'}], 'event_type': 'book', 'hash': 'c413a628ef5070262d9b8dfce78bc773aee343ba', 'market': '0x7aa4a910b31b2c4ddb09d1e3408e52aa8e09a14402f376070a44b1b85cb36d13', 'timestamp': '1733334405713'}
{'asset_id': '114416409796971863099144323163249651172534872992222856507897414949637892047507', 'changes': [{'price': '0.47', 'side': 'BUY', 'size': '297.23'}, {'price': '0.53', 'side': 'BUY', 'size': '1318.99'}, {'price': '0.57', 'side': 'SELL', 'size': '1200'}], 'event_type': 'price_change', 'hash': '1991e56828a7eaac45d183e36f06379636a6b5f1', 'market': '0x7aa4a910b31b2c4ddb09d1e3408e52aa8e09a14402f376070a44b1b85cb36d13', 'timestamp': '1733334408597'}
{'asset_id': '114416409796971863099144323163249651172534872992222856507897414949637892047507', 'changes': [{'price': '0.47', 'side': 'BUY', 'size': '297.23'}, {'price': '0.53', 'side': 'BUY', 'size': '1318.99'}, {'price': '0.57', 'side': 'SELL', 'size': '1200'}], 'event_type': 'price_change', 'hash': '1991e56828a7eaac45d183e36f06379636a6b5f1', 'market': '0x7aa4a910b31b2c4ddb09d1e3408e52aa8e09a14402f376070a44b1b85cb36d13', 'timestamp': '1733334408597'}
{'asset_id': '114416409796971863099144323163249651172534872992222856507897414949637892047507', 'changes': [{'price': '0.47', 'side': 'BUY', 'size': '797.23'}], 'event_type': 'price_change', 'hash': '8cf3e5ffa00d3a488def45f9ee0bea24f9e3a042', 'market': '0x7aa4a910b31b2c4ddb09d1e3408e52aa8e09a14402f376070a44b1b85cb36d13', 'timestamp': '1733334409648'}
{'asset_id': '114416409796971863099144323163249651172534872992222856507897414949637892047507', 'changes': [{'price': '0.47', 'side': 'BUY', 'size': '797.23'}], 'event_type': 'price_change', 'hash': '8cf3e5ffa00d3a488def45f9ee0bea24f9e3a042', 'market': '0x7aa4a910b31b2c4ddb09d1e3408e52aa8e09a14402f376070a44b1b85cb36d13', 'timestamp': '1733334409648'}
{'asks': [{'price': '0.99', 'size': '4217.01'}, {'price': '0.98', 'size': '505'}, {'price': '0.97', 'size': '511.03'}, {'price': '0.96', 'size': '300'}, {'price': '0.95', 'size': '657.12'}, {'price': '0.94', 'size': '300'}, {'price': '0.92', 'size': '20000.45'}, {'price': '0.91', 'size': '10406.3'}, {'price': '0.9', 'size': '4587.5'}, {'price': '0.89', 'size': '13017.18'}, {'price': '0.88', 'size': '200'}, {'price': '0.87', 'size': '3229'}, {'price': '0.86', 'size': '17.1'}, {'price': '0.85', 'size': '109.68'}, {'price': '0.84', 'size': '250'}, {'price': '0.83', 'size': '100'}, {'price': '0.82', 'size': '16029'}, {'price': '0.81', 'size': '45721.39'}, {'price': '0.8', 'size': '26531'}, {'price': '0.79', 'size': '7110'}, {'price': '0.78', 'size': '15350'}, {'price': '0.77', 'size': '67'}, {'price': '0.76', 'size': '200'}, {'price': '0.75', 'size': '13329.25'}, {'price': '0.74', 'size': '11370.7'}, {'price': '0.73', 'size': '5020.1'}, {'price': '0.72', 'size': '380.52'}, {'price': '0.71', 'size': '15073.2'}, {'price': '0.7', 'size': '5570.1'}, {'price': '0.69', 'size': '6088.6'}, {'price': '0.68', 'size': '6131.34'}, {'price': '0.67', 'size': '3010.1'}, {'price': '0.66', 'size': '510.1'}, {'price': '0.65', 'size': '1010.1'}, {'price': '0.64', 'size': '4230.1'}, {'price': '0.63', 'size': '210.1'}, {'price': '0.62', 'size': '400.1'}, {'price': '0.61', 'size': '861.06'}, {'price': '0.6', 'size': '3067.85'}, {'price': '0.59', 'size': '3610'}, {'price': '0.58', 'size': '50.47'}, {'price': '0.57', 'size': '1200'}], 'asset_id': '114416409796971863099144323163249651172534872992222856507897414949637892047507', 'bids': [{'price': '0.01', 'size': '2850.27'}, {'price': '0.02', 'size': '500'}, {'price': '0.03', 'size': '500'}, {'price': '0.04', 'size': '300'}, {'price': '0.05', 'size': '320'}, {'price': '0.06', 'size': '300'}, {'price': '0.08', 'size': '250'}, {'price': '0.09', 'size': '300'}, {'price': '0.1', 'size': '6205'}, {'price': '0.12', 'size': '200'}, {'price': '0.13', 'size': '426.92'}, {'price': '0.14', 'size': '15'}, {'price': '0.15', 'size': '110'}, {'price': '0.16', 'size': '4709.51'}, {'price': '0.18', 'size': '19.13'}, {'price': '0.19', 'size': '120'}, {'price': '0.2', 'size': '691.17'}, {'price': '0.24', 'size': '5027'}, {'price': '0.25', 'size': '86.66'}, {'price': '0.27', 'size': '215.25'}, {'price': '0.29', 'size': '1102.28'}, {'price': '0.31', 'size': '1130.65'}, {'price': '0.32', 'size': '200'}, {'price': '0.33', 'size': '620'}, {'price': '0.35', 'size': '232'}, {'price': '0.37', 'size': '4000'}, {'price': '0.39', 'size': '10.5'}, {'price': '0.4', 'size': '3135'}, {'price': '0.41', 'size': '20'}, {'price': '0.42', 'size': '3050'}, {'price': '0.43', 'size': '50'}, {'price': '0.44', 'size': '3660'}, {'price': '0.45', 'size': '478'}, {'price': '0.47', 'size': '797.23'}, {'price': '0.48', 'size': '2742.18'}, {'price': '0.49', 'size': '40'}, {'price': '0.5', 'size': '2015'}, {'price': '0.51', 'size': '3686.18'}, {'price': '0.52', 'size': '885.92'}, {'price': '0.53', 'size': '1318.99'}, {'price': '0.54', 'size': '131.19'}, {'price': '0.55', 'size': '3972.77'}, {'price': '0.56', 'size': '3153.28'}], 'event_type': 'book', 'hash': 'c8d5c3ce03e24b4ae732a9fa25f20a80204a3b4e', 'market': '0x7aa4a910b31b2c4ddb09d1e3408e52aa8e09a14402f376070a44b1b85cb36d13', 'timestamp': '1733334410326'}
{'asks': [{'price': '0.99', 'size': '4217.01'}, {'price': '0.98', 'size': '505'}, {'price': '0.97', 'size': '511.03'}, {'price': '0.96', 'size': '300'}, {'price': '0.95', 'size': '657.12'}, {'price': '0.94', 'size': '300'}, {'price': '0.92', 'size': '20000.45'}, {'price': '0.91', 'size': '10406.3'}, {'price': '0.9', 'size': '4587.5'}, {'price': '0.89', 'size': '13017.18'}, {'price': '0.88', 'size': '200'}, {'price': '0.87', 'size': '3229'}, {'price': '0.86', 'size': '17.1'}, {'price': '0.85', 'size': '109.68'}, {'price': '0.84', 'size': '250'}, {'price': '0.83', 'size': '100'}, {'price': '0.82', 'size': '16029'}, {'price': '0.81', 'size': '45721.39'}, {'price': '0.8', 'size': '26531'}, {'price': '0.79', 'size': '7110'}, {'price': '0.78', 'size': '15350'}, {'price': '0.77', 'size': '67'}, {'price': '0.76', 'size': '200'}, {'price': '0.75', 'size': '13329.25'}, {'price': '0.74', 'size': '11370.7'}, {'price': '0.73', 'size': '5020.1'}, {'price': '0.72', 'size': '380.52'}, {'price': '0.71', 'size': '15073.2'}, {'price': '0.7', 'size': '5570.1'}, {'price': '0.69', 'size': '6088.6'}, {'price': '0.68', 'size': '6131.34'}, {'price': '0.67', 'size': '3010.1'}, {'price': '0.66', 'size': '510.1'}, {'price': '0.65', 'size': '1010.1'}, {'price': '0.64', 'size': '4230.1'}, {'price': '0.63', 'size': '210.1'}, {'price': '0.62', 'size': '400.1'}, {'price': '0.61', 'size': '861.06'}, {'price': '0.6', 'size': '3067.85'}, {'price': '0.59', 'size': '3610'}, {'price': '0.58', 'size': '50.47'}, {'price': '0.57', 'size': '1200'}], 'asset_id': '114416409796971863099144323163249651172534872992222856507897414949637892047507', 'bids': [{'price': '0.01', 'size': '2850.27'}, {'price': '0.02', 'size': '500'}, {'price': '0.03', 'size': '500'}, {'price': '0.04', 'size': '300'}, {'price': '0.05', 'size': '320'}, {'price': '0.06', 'size': '300'}, {'price': '0.08', 'size': '250'}, {'price': '0.09', 'size': '300'}, {'price': '0.1', 'size': '6205'}, {'price': '0.12', 'size': '200'}, {'price': '0.13', 'size': '426.92'}, {'price': '0.14', 'size': '15'}, {'price': '0.15', 'size': '110'}, {'price': '0.16', 'size': '4709.51'}, {'price': '0.18', 'size': '19.13'}, {'price': '0.19', 'size': '120'}, {'price': '0.2', 'size': '691.17'}, {'price': '0.24', 'size': '5027'}, {'price': '0.25', 'size': '86.66'}, {'price': '0.27', 'size': '215.25'}, {'price': '0.29', 'size': '1102.28'}, {'price': '0.31', 'size': '1130.65'}, {'price': '0.32', 'size': '200'}, {'price': '0.33', 'size': '620'}, {'price': '0.35', 'size': '232'}, {'price': '0.37', 'size': '4000'}, {'price': '0.39', 'size': '10.5'}, {'price': '0.4', 'size': '3135'}, {'price': '0.41', 'size': '20'}, {'price': '0.42', 'size': '3050'}, {'price': '0.43', 'size': '50'}, {'price': '0.44', 'size': '3660'}, {'price': '0.45', 'size': '478'}, {'price': '0.47', 'size': '797.23'}, {'price': '0.48', 'size': '2742.18'}, {'price': '0.49', 'size': '40'}, {'price': '0.5', 'size': '2015'}, {'price': '0.51', 'size': '3686.18'}, {'price': '0.52', 'size': '885.92'}, {'price': '0.53', 'size': '1318.99'}, {'price': '0.54', 'size': '131.19'}, {'price': '0.55', 'size': '3972.77'}, {'price': '0.56', 'size': '3153.28'}], 'event_type': 'book', 'hash': 'c8d5c3ce03e24b4ae732a9fa25f20a80204a3b4e', 'market': '0x7aa4a910b31b2c4ddb09d1e3408e52aa8e09a14402f376070a44b1b85cb36d13', 'timestamp': '1733334410326'}
{'asset_id': '114416409796971863099144323163249651172534872992222856507897414949637892047507', 'changes': [{'price': '0.59', 'side': 'SELL', 'size': '2110'}, {'price': '0.51', 'side': 'BUY', 'size': '2186.18'}], 'event_type': 'price_change', 'hash': '62a7617f43cf5d00f7c76b7d4ccd1dedded6db98', 'market': '0x7aa4a910b31b2c4ddb09d1e3408e52aa8e09a14402f376070a44b1b85cb36d13', 'timestamp': '1733334410549'}
{'asset_id': '114416409796971863099144323163249651172534872992222856507897414949637892047507', 'changes': [{'price': '0.59', 'side': 'SELL', 'size': '2110'}, {'price': '0.51', 'side': 'BUY', 'size': '2186.18'}], 'event_type': 'price_change', 'hash': '62a7617f43cf5d00f7c76b7d4ccd1dedded6db98', 'market': '0x7aa4a910b31b2c4ddb09d1e3408e52aa8e09a14402f376070a44b1b85cb36d13', 'timestamp': '1733334410549'}
{'asset_id': '114416409796971863099144323163249651172534872992222856507897414949637892047507', 'changes': [{'price': '0.52', 'side': 'BUY', 'size': '1885.92'}], 'event_type': 'price_change', 'hash': '65fc894d040c75a3ff568b60f5717ed12948b7fd', 'market': '0x7aa4a910b31b2c4ddb09d1e3408e52aa8e09a14402f376070a44b1b85cb36d13', 'timestamp': '1733334410732'}
{'asset_id': '114416409796971863099144323163249651172534872992222856507897414949637892047507', 'changes': [{'price': '0.52', 'side': 'BUY', 'size': '1885.92'}], 'event_type': 'price_change', 'hash': '65fc894d040c75a3ff568b60f5717ed12948b7fd', 'market': '0x7aa4a910b31b2c4ddb09d1e3408e52aa8e09a14402f376070a44b1b85cb36d13', 'timestamp': '1733334410732'}
{'asset_id': '114416409796971863099144323163249651172534872992222856507897414949637892047507', 'changes': [{'price': '0.58', 'side': 'SELL', 'size': '1550.47'}], 'event_type': 'price_change', 'hash': '262311c74f46b0adce55d238b58fe1332eb25aa8', 'market': '0x7aa4a910b31b2c4ddb09d1e3408e52aa8e09a14402f376070a44b1b85cb36d13', 'timestamp': '1733334410989'}
{'asset_id': '114416409796971863099144323163249651172534872992222856507897414949637892047507', 'changes': [{'price': '0.58', 'side': 'SELL', 'size': '1550.47'}], 'event_type': 'price_change', 'hash': '262311c74f46b0adce55d238b58fe1332eb25aa8', 'market': '0x7aa4a910b31b2c4ddb09d1e3408e52aa8e09a14402f376070a44b1b85cb36d13', 'timestamp': '1733334410989'}
{'asset_id': '114416409796971863099144323163249651172534872992222856507897414949637892047507', 'changes': [{'price': '0.49', 'side': 'BUY', 'size': '1540'}], 'event_type': 'price_change', 'hash': '766d3883f9427be8ac0e03b8bfba6c8d91968a71', 'market': '0x7aa4a910b31b2c4ddb09d1e3408e52aa8e09a14402f376070a44b1b85cb36d13', 'timestamp': '1733334410996'}
{'asset_id': '114416409796971863099144323163249651172534872992222856507897414949637892047507', 'changes': [{'price': '0.49', 'side': 'BUY', 'size': '1540'}], 'event_type': 'price_change', 'hash': '766d3883f9427be8ac0e03b8bfba6c8d91968a71', 'market': '0x7aa4a910b31b2c4ddb09d1e3408e52aa8e09a14402f376070a44b1b85cb36d13', 'timestamp': '1733334410996'}
{'asks': [{'price': '0.99', 'size': '4217.01'}, {'price': '0.98', 'size': '505'}, {'price': '0.97', 'size': '511.03'}, {'price': '0.96', 'size': '300'}, {'price': '0.95', 'size': '657.12'}, {'price': '0.94', 'size': '300'}, {'price': '0.92', 'size': '20000.45'}, {'price': '0.91', 'size': '10406.3'}, {'price': '0.9', 'size': '4587.5'}, {'price': '0.89', 'size': '13017.18'}, {'price': '0.88', 'size': '200'}, {'price': '0.87', 'size': '3229'}, {'price': '0.86', 'size': '17.1'}, {'price': '0.85', 'size': '109.68'}, {'price': '0.84', 'size': '250'}, {'price': '0.83', 'size': '100'}, {'price': '0.82', 'size': '16029'}, {'price': '0.81', 'size': '45721.39'}, {'price': '0.8', 'size': '26531'}, {'price': '0.79', 'size': '7110'}, {'price': '0.78', 'size': '15350'}, {'price': '0.77', 'size': '67'}, {'price': '0.76', 'size': '200'}, {'price': '0.75', 'size': '13329.25'}, {'price': '0.74', 'size': '11370.7'}, {'price': '0.73', 'size': '5020.1'}, {'price': '0.72', 'size': '380.52'}, {'price': '0.71', 'size': '15073.2'}, {'price': '0.7', 'size': '5570.1'}, {'price': '0.69', 'size': '6088.6'}, {'price': '0.68', 'size': '6131.34'}, {'price': '0.67', 'size': '3010.1'}, {'price': '0.66', 'size': '510.1'}, {'price': '0.65', 'size': '1010.1'}, {'price': '0.64', 'size': '4230.1'}, {'price': '0.63', 'size': '210.1'}, {'price': '0.62', 'size': '400.1'}, {'price': '0.61', 'size': '861.06'}, {'price': '0.6', 'size': '3067.85'}, {'price': '0.59', 'size': '2110'}, {'price': '0.58', 'size': '1550.47'}, {'price': '0.57', 'size': '1200'}, {'price': '0.56', 'size': '515'}], 'asset_id': '114416409796971863099144323163249651172534872992222856507897414949637892047507', 'bids': [{'price': '0.01', 'size': '2850.27'}, {'price': '0.02', 'size': '500'}, {'price': '0.03', 'size': '500'}, {'price': '0.04', 'size': '300'}, {'price': '0.05', 'size': '320'}, {'price': '0.06', 'size': '300'}, {'price': '0.08', 'size': '250'}, {'price': '0.09', 'size': '300'}, {'price': '0.1', 'size': '6205'}, {'price': '0.12', 'size': '200'}, {'price': '0.13', 'size': '426.92'}, {'price': '0.14', 'size': '15'}, {'price': '0.15', 'size': '110'}, {'price': '0.16', 'size': '4709.51'}, {'price': '0.18', 'size': '19.13'}, {'price': '0.19', 'size': '120'}, {'price': '0.2', 'size': '691.17'}, {'price': '0.24', 'size': '5027'}, {'price': '0.25', 'size': '86.66'}, {'price': '0.27', 'size': '215.25'}, {'price': '0.29', 'size': '1102.28'}, {'price': '0.31', 'size': '1130.65'}, {'price': '0.32', 'size': '200'}, {'price': '0.33', 'size': '620'}, {'price': '0.35', 'size': '232'}, {'price': '0.37', 'size': '4000'}, {'price': '0.39', 'size': '10.5'}, {'price': '0.4', 'size': '3135'}, {'price': '0.41', 'size': '20'}, {'price': '0.42', 'size': '3050'}, {'price': '0.43', 'size': '50'}, {'price': '0.44', 'size': '3660'}, {'price': '0.45', 'size': '478'}, {'price': '0.47', 'size': '797.23'}, {'price': '0.48', 'size': '2742.18'}, {'price': '0.49', 'size': '1540'}, {'price': '0.5', 'size': '2015'}, {'price': '0.51', 'size': '2186.18'}, {'price': '0.52', 'size': '1885.92'}, {'price': '0.53', 'size': '1318.99'}, {'price': '0.54', 'size': '131.19'}, {'price': '0.55', 'size': '3972.77'}], 'event_type': 'book', 'hash': '4627decf8198a889825c991a179b5bd69333d6e6', 'market': '0x7aa4a910b31b2c4ddb09d1e3408e52aa8e09a14402f376070a44b1b85cb36d13', 'timestamp': '1733334412355'}
{'asset_id': '114416409796971863099144323163249651172534872992222856507897414949637892047507', 'changes': [{'price': '0.56', 'side': 'SELL', 'size': '515'}], 'event_type': 'price_change', 'hash': '4627decf8198a889825c991a179b5bd69333d6e6', 'market': '0x7aa4a910b31b2c4ddb09d1e3408e52aa8e09a14402f376070a44b1b85cb36d13', 'timestamp': '1733334412363'}
{'asks': [{'price': '0.99', 'size': '4217.01'}, {'price': '0.98', 'size': '505'}, {'price': '0.97', 'size': '511.03'}, {'price': '0.96', 'size': '300'}, {'price': '0.95', 'size': '657.12'}, {'price': '0.94', 'size': '300'}, {'price': '0.92', 'size': '20000.45'}, {'price': '0.91', 'size': '10406.3'}, {'price': '0.9', 'size': '4587.5'}, {'price': '0.89', 'size': '13017.18'}, {'price': '0.88', 'size': '200'}, {'price': '0.87', 'size': '3229'}, {'price': '0.86', 'size': '17.1'}, {'price': '0.85', 'size': '109.68'}, {'price': '0.84', 'size': '250'}, {'price': '0.83', 'size': '100'}, {'price': '0.82', 'size': '16029'}, {'price': '0.81', 'size': '45721.39'}, {'price': '0.8', 'size': '26531'}, {'price': '0.79', 'size': '7110'}, {'price': '0.78', 'size': '15350'}, {'price': '0.77', 'size': '67'}, {'price': '0.76', 'size': '200'}, {'price': '0.75', 'size': '13329.25'}, {'price': '0.74', 'size': '11370.7'}, {'price': '0.73', 'size': '5020.1'}, {'price': '0.72', 'size': '380.52'}, {'price': '0.71', 'size': '15073.2'}, {'price': '0.7', 'size': '5570.1'}, {'price': '0.69', 'size': '6088.6'}, {'price': '0.68', 'size': '6131.34'}, {'price': '0.67', 'size': '3010.1'}, {'price': '0.66', 'size': '510.1'}, {'price': '0.65', 'size': '1010.1'}, {'price': '0.64', 'size': '4230.1'}, {'price': '0.63', 'size': '210.1'}, {'price': '0.62', 'size': '400.1'}, {'price': '0.61', 'size': '861.06'}, {'price': '0.6', 'size': '3067.85'}, {'price': '0.59', 'size': '2110'}, {'price': '0.58', 'size': '1550.47'}, {'price': '0.57', 'size': '1200'}, {'price': '0.56', 'size': '515'}], 'asset_id': '114416409796971863099144323163249651172534872992222856507897414949637892047507', 'bids': [{'price': '0.01', 'size': '2850.27'}, {'price': '0.02', 'size': '500'}, {'price': '0.03', 'size': '500'}, {'price': '0.04', 'size': '300'}, {'price': '0.05', 'size': '320'}, {'price': '0.06', 'size': '300'}, {'price': '0.08', 'size': '250'}, {'price': '0.09', 'size': '300'}, {'price': '0.1', 'size': '6205'}, {'price': '0.12', 'size': '200'}, {'price': '0.13', 'size': '426.92'}, {'price': '0.14', 'size': '15'}, {'price': '0.15', 'size': '110'}, {'price': '0.16', 'size': '4709.51'}, {'price': '0.18', 'size': '19.13'}, {'price': '0.19', 'size': '120'}, {'price': '0.2', 'size': '691.17'}, {'price': '0.24', 'size': '5027'}, {'price': '0.25', 'size': '86.66'}, {'price': '0.27', 'size': '215.25'}, {'price': '0.29', 'size': '1102.28'}, {'price': '0.31', 'size': '1130.65'}, {'price': '0.32', 'size': '200'}, {'price': '0.33', 'size': '620'}, {'price': '0.35', 'size': '232'}, {'price': '0.37', 'size': '4000'}, {'price': '0.39', 'size': '10.5'}, {'price': '0.4', 'size': '3135'}, {'price': '0.41', 'size': '20'}, {'price': '0.42', 'size': '3050'}, {'price': '0.43', 'size': '50'}, {'price': '0.44', 'size': '3660'}, {'price': '0.45', 'size': '478'}, {'price': '0.47', 'size': '797.23'}, {'price': '0.48', 'size': '2742.18'}, {'price': '0.49', 'size': '1540'}, {'price': '0.5', 'size': '2015'}, {'price': '0.51', 'size': '2186.18'}, {'price': '0.52', 'size': '1885.92'}, {'price': '0.53', 'size': '1318.99'}, {'price': '0.54', 'size': '131.19'}, {'price': '0.55', 'size': '3972.77'}], 'event_type': 'book', 'hash': '4627decf8198a889825c991a179b5bd69333d6e6', 'market': '0x7aa4a910b31b2c4ddb09d1e3408e52aa8e09a14402f376070a44b1b85cb36d13', 'timestamp': '1733334412355'}
{'asset_id': '114416409796971863099144323163249651172534872992222856507897414949637892047507', 'changes': [{'price': '0.56', 'side': 'SELL', 'size': '515'}], 'event_type': 'price_change', 'hash': '4627decf8198a889825c991a179b5bd69333d6e6', 'market': '0x7aa4a910b31b2c4ddb09d1e3408e52aa8e09a14402f376070a44b1b85cb36d13', 'timestamp': '1733334412363'}
{'asset_id': '114416409796971863099144323163249651172534872992222856507897414949637892047507', 'changes': [{'price': '0.55', 'side': 'BUY', 'size': '4072.77'}], 'event_type': 'price_change', 'hash': '13c29516388844faa5d3fa4da6fea81be80d5f11', 'market': '0x7aa4a910b31b2c4ddb09d1e3408e52aa8e09a14402f376070a44b1b85cb36d13', 'timestamp': '1733334418479'}
{'asset_id': '114416409796971863099144323163249651172534872992222856507897414949637892047507', 'changes': [{'price': '0.55', 'side': 'BUY', 'size': '4072.77'}], 'event_type': 'price_change', 'hash': '13c29516388844faa5d3fa4da6fea81be80d5f11', 'market': '0x7aa4a910b31b2c4ddb09d1e3408e52aa8e09a14402f376070a44b1b85cb36d13', 'timestamp': '1733334418479'}
{'asset_id': '114416409796971863099144323163249651172534872992222856507897414949637892047507', 'changes': [{'price': '0.62', 'side': 'SELL', 'size': '350.1'}], 'event_type': 'price_change', 'hash': 'fbbe7c6a1352fbdabe9a8d395057d05a108801f8', 'market': '0x7aa4a910b31b2c4ddb09d1e3408e52aa8e09a14402f376070a44b1b85cb36d13', 'timestamp': '1733334419485'}
{'asset_id': '114416409796971863099144323163249651172534872992222856507897414949637892047507', 'changes': [{'price': '0.62', 'side': 'SELL', 'size': '350.1'}], 'event_type': 'price_change', 'hash': 'fbbe7c6a1352fbdabe9a8d395057d05a108801f8', 'market': '0x7aa4a910b31b2c4ddb09d1e3408e52aa8e09a14402f376070a44b1b85cb36d13', 'timestamp': '1733334419485'}
{'asset_id': '114416409796971863099144323163249651172534872992222856507897414949637892047507', 'changes': [{'price': '0.61', 'side': 'SELL', 'size': '811.06'}], 'event_type': 'price_change', 'hash': '6bf05079f369ecd77b07097105caee93ab623f7d', 'market': '0x7aa4a910b31b2c4ddb09d1e3408e52aa8e09a14402f376070a44b1b85cb36d13', 'timestamp': '1733334419964'}
{'asset_id': '114416409796971863099144323163249651172534872992222856507897414949637892047507', 'changes': [{'price': '0.61', 'side': 'SELL', 'size': '811.06'}], 'event_type': 'price_change', 'hash': '6bf05079f369ecd77b07097105caee93ab623f7d', 'market': '0x7aa4a910b31b2c4ddb09d1e3408e52aa8e09a14402f376070a44b1b85cb36d13', 'timestamp': '1733334419964'}
{'asset_id': '114416409796971863099144323163249651172534872992222856507897414949637892047507', 'changes': [{'price': '0.55', 'side': 'BUY', 'size': '4172.77'}], 'event_type': 'price_change', 'hash': '035d32bfb785b593b1c698faabdddb3aca4fd4c5', 'market': '0x7aa4a910b31b2c4ddb09d1e3408e52aa8e09a14402f376070a44b1b85cb36d13', 'timestamp': '1733334420221'}
{'asset_id': '114416409796971863099144323163249651172534872992222856507897414949637892047507', 'changes': [{'price': '0.55', 'side': 'BUY', 'size': '4172.77'}], 'event_type': 'price_change', 'hash': '035d32bfb785b593b1c698faabdddb3aca4fd4c5', 'market': '0x7aa4a910b31b2c4ddb09d1e3408e52aa8e09a14402f376070a44b1b85cb36d13', 'timestamp': '1733334420221'}
{'asset_id': '114416409796971863099144323163249651172534872992222856507897414949637892047507', 'changes': [{'price': '0.62', 'side': 'SELL', 'size': '300.1'}], 'event_type': 'price_change', 'hash': '74323db8d3289d5cb904cb90b46cb94d15347b81', 'market': '0x7aa4a910b31b2c4ddb09d1e3408e52aa8e09a14402f376070a44b1b85cb36d13', 'timestamp': '1733334420518'}
{'asset_id': '114416409796971863099144323163249651172534872992222856507897414949637892047507', 'changes': [{'price': '0.62', 'side': 'SELL', 'size': '300.1'}], 'event_type': 'price_change', 'hash': '74323db8d3289d5cb904cb90b46cb94d15347b81', 'market': '0x7aa4a910b31b2c4ddb09d1e3408e52aa8e09a14402f376070a44b1b85cb36d13', 'timestamp': '1733334420518'}
{'asset_id': '114416409796971863099144323163249651172534872992222856507897414949637892047507', 'changes': [{'price': '0.54', 'side': 'BUY', 'size': '81.19'}], 'event_type': 'price_change', 'hash': '5ab5aa33f619858ae055c2ee97b20cc2e8964380', 'market': '0x7aa4a910b31b2c4ddb09d1e3408e52aa8e09a14402f376070a44b1b85cb36d13', 'timestamp': '1733334420535'}
{'asset_id': '114416409796971863099144323163249651172534872992222856507897414949637892047507', 'changes': [{'price': '0.54', 'side': 'BUY', 'size': '81.19'}], 'event_type': 'price_change', 'hash': '5ab5aa33f619858ae055c2ee97b20cc2e8964380', 'market': '0x7aa4a910b31b2c4ddb09d1e3408e52aa8e09a14402f376070a44b1b85cb36d13', 'timestamp': '1733334420535'}
{'asset_id': '114416409796971863099144323163249651172534872992222856507897414949637892047507', 'changes': [{'price': '0.61', 'side': 'SELL', 'size': '761.06'}], 'event_type': 'price_change', 'hash': '26b8831bcac98e6f758888007df8bafc38eb9c2b', 'market': '0x7aa4a910b31b2c4ddb09d1e3408e52aa8e09a14402f376070a44b1b85cb36d13', 'timestamp': '1733334421017'}
{'asset_id': '114416409796971863099144323163249651172534872992222856507897414949637892047507', 'changes': [{'price': '0.61', 'side': 'SELL', 'size': '761.06'}], 'event_type': 'price_change', 'hash': '26b8831bcac98e6f758888007df8bafc38eb9c2b', 'market': '0x7aa4a910b31b2c4ddb09d1e3408e52aa8e09a14402f376070a44b1b85cb36d13', 'timestamp': '1733334421017'}
{'asset_id': '114416409796971863099144323163249651172534872992222856507897414949637892047507', 'changes': [{'price': '0.55', 'side': 'BUY', 'size': '4122.77'}], 'event_type': 'price_change', 'hash': 'adfdfed15774ff0a2d4069f9d730b2691ce77ffc', 'market': '0x7aa4a910b31b2c4ddb09d1e3408e52aa8e09a14402f376070a44b1b85cb36d13', 'timestamp': '1733334421070'}
{'asset_id': '114416409796971863099144323163249651172534872992222856507897414949637892047507', 'changes': [{'price': '0.55', 'side': 'BUY', 'size': '4122.77'}], 'event_type': 'price_change', 'hash': 'adfdfed15774ff0a2d4069f9d730b2691ce77ffc', 'market': '0x7aa4a910b31b2c4ddb09d1e3408e52aa8e09a14402f376070a44b1b85cb36d13', 'timestamp': '1733334421070'}
{'asset_id': '114416409796971863099144323163249651172534872992222856507897414949637892047507', 'changes': [{'price': '0.57', 'side': 'SELL', 'size': '1250'}], 'event_type': 'price_change', 'hash': 'bb9af707113d06b0f6e6f47d3c86ca64389045f2', 'market': '0x7aa4a910b31b2c4ddb09d1e3408e52aa8e09a14402f376070a44b1b85cb36d13', 'timestamp': '1733334421445'}
{'asset_id': '114416409796971863099144323163249651172534872992222856507897414949637892047507', 'changes': [{'price': '0.57', 'side': 'SELL', 'size': '1250'}], 'event_type': 'price_change', 'hash': 'bb9af707113d06b0f6e6f47d3c86ca64389045f2', 'market': '0x7aa4a910b31b2c4ddb09d1e3408e52aa8e09a14402f376070a44b1b85cb36d13', 'timestamp': '1733334421445'}
{'asset_id': '114416409796971863099144323163249651172534872992222856507897414949637892047507', 'changes': [{'price': '0.54', 'side': 'BUY', 'size': '31.19'}], 'event_type': 'price_change', 'hash': '0eba60a5527e507c346a5c77eb6ae39824ec1279', 'market': '0x7aa4a910b31b2c4ddb09d1e3408e52aa8e09a14402f376070a44b1b85cb36d13', 'timestamp': '1733334421559'}
{'asset_id': '114416409796971863099144323163249651172534872992222856507897414949637892047507', 'changes': [{'price': '0.54', 'side': 'BUY', 'size': '31.19'}], 'event_type': 'price_change', 'hash': '0eba60a5527e507c346a5c77eb6ae39824ec1279', 'market': '0x7aa4a910b31b2c4ddb09d1e3408e52aa8e09a14402f376070a44b1b85cb36d13', 'timestamp': '1733334421559'}
{'asset_id': '114416409796971863099144323163249651172534872992222856507897414949637892047507', 'changes': [{'price': '0.58', 'side': 'SELL', 'size': '1600.47'}], 'event_type': 'price_change', 'hash': '7951c401c27e5ae2cac1c5761059a28ab52da99b', 'market': '0x7aa4a910b31b2c4ddb09d1e3408e52aa8e09a14402f376070a44b1b85cb36d13', 'timestamp': '1733334421776'}
{'asset_id': '114416409796971863099144323163249651172534872992222856507897414949637892047507', 'changes': [{'price': '0.58', 'side': 'SELL', 'size': '1600.47'}], 'event_type': 'price_change', 'hash': '7951c401c27e5ae2cac1c5761059a28ab52da99b', 'market': '0x7aa4a910b31b2c4ddb09d1e3408e52aa8e09a14402f376070a44b1b85cb36d13', 'timestamp': '1733334421776'}
{'asset_id': '114416409796971863099144323163249651172534872992222856507897414949637892047507', 'changes': [{'price': '0.55', 'side': 'BUY', 'size': '4072.77'}, {'price': '0.51', 'side': 'BUY', 'size': '2236.18'}], 'event_type': 'price_change', 'hash': '81e527607d39eee3bf72bb0d8997eaaa93ff2184', 'market': '0x7aa4a910b31b2c4ddb09d1e3408e52aa8e09a14402f376070a44b1b85cb36d13', 'timestamp': '1733334422067'}
{'asset_id': '114416409796971863099144323163249651172534872992222856507897414949637892047507', 'changes': [{'price': '0.55', 'side': 'BUY', 'size': '4072.77'}, {'price': '0.51', 'side': 'BUY', 'size': '2236.18'}], 'event_type': 'price_change', 'hash': '81e527607d39eee3bf72bb0d8997eaaa93ff2184', 'market': '0x7aa4a910b31b2c4ddb09d1e3408e52aa8e09a14402f376070a44b1b85cb36d13', 'timestamp': '1733334422067'}
{'asset_id': '114416409796971863099144323163249651172534872992222856507897414949637892047507', 'changes': [{'price': '0.57', 'side': 'SELL', 'size': '1300'}], 'event_type': 'price_change', 'hash': 'a4d390d8a22dc13734ff3a2fc125acb49bf331f0', 'market': '0x7aa4a910b31b2c4ddb09d1e3408e52aa8e09a14402f376070a44b1b85cb36d13', 'timestamp': '1733334422315'}
{'asset_id': '114416409796971863099144323163249651172534872992222856507897414949637892047507', 'changes': [{'price': '0.57', 'side': 'SELL', 'size': '1300'}], 'event_type': 'price_change', 'hash': 'a4d390d8a22dc13734ff3a2fc125acb49bf331f0', 'market': '0x7aa4a910b31b2c4ddb09d1e3408e52aa8e09a14402f376070a44b1b85cb36d13', 'timestamp': '1733334422315'}
{'asset_id': '114416409796971863099144323163249651172534872992222856507897414949637892047507', 'changes': [{'price': '0.5', 'side': 'BUY', 'size': '2065'}], 'event_type': 'price_change', 'hash': '99f040beaacf54c0755eef2594d42a04cb6642f1', 'market': '0x7aa4a910b31b2c4ddb09d1e3408e52aa8e09a14402f376070a44b1b85cb36d13', 'timestamp': '1733334422354'}
{'asset_id': '114416409796971863099144323163249651172534872992222856507897414949637892047507', 'changes': [{'price': '0.5', 'side': 'BUY', 'size': '2065'}], 'event_type': 'price_change', 'hash': '99f040beaacf54c0755eef2594d42a04cb6642f1', 'market': '0x7aa4a910b31b2c4ddb09d1e3408e52aa8e09a14402f376070a44b1b85cb36d13', 'timestamp': '1733334422354'}
{'asset_id': '114416409796971863099144323163249651172534872992222856507897414949637892047507', 'changes': [{'price': '0.58', 'side': 'SELL', 'size': '1650.47'}, {'price': '0.55', 'side': 'BUY', 'size': '4042.77'}], 'event_type': 'price_change', 'hash': 'd6f4fd0f1b2c674c4f86b1c8f3252c823d004b0a', 'market': '0x7aa4a910b31b2c4ddb09d1e3408e52aa8e09a14402f376070a44b1b85cb36d13', 'timestamp': '1733334422579'}
{'asset_id': '114416409796971863099144323163249651172534872992222856507897414949637892047507', 'changes': [{'price': '0.58', 'side': 'SELL', 'size': '1650.47'}, {'price': '0.55', 'side': 'BUY', 'size': '4042.77'}], 'event_type': 'price_change', 'hash': 'd6f4fd0f1b2c674c4f86b1c8f3252c823d004b0a', 'market': '0x7aa4a910b31b2c4ddb09d1e3408e52aa8e09a14402f376070a44b1b85cb36d13', 'timestamp': '1733334422579'}
{'asset_id': '114416409796971863099144323163249651172534872992222856507897414949637892047507', 'changes': [{'price': '0.54', 'side': 'BUY', 'size': '61.19'}], 'event_type': 'price_change', 'hash': '85bb78656801dcff85f749b41adca0a8c8f6c366', 'market': '0x7aa4a910b31b2c4ddb09d1e3408e52aa8e09a14402f376070a44b1b85cb36d13', 'timestamp': '1733334422722'}
{'asset_id': '114416409796971863099144323163249651172534872992222856507897414949637892047507', 'changes': [{'price': '0.54', 'side': 'BUY', 'size': '61.19'}], 'event_type': 'price_change', 'hash': '85bb78656801dcff85f749b41adca0a8c8f6c366', 'market': '0x7aa4a910b31b2c4ddb09d1e3408e52aa8e09a14402f376070a44b1b85cb36d13', 'timestamp': '1733334422722'}
{'asset_id': '114416409796971863099144323163249651172534872992222856507897414949637892047507', 'changes': [{'price': '0.51', 'side': 'BUY', 'size': '2286.18'}], 'event_type': 'price_change', 'hash': 'cb44e9491642a39a40f252b8e0a2831df2d4572d', 'market': '0x7aa4a910b31b2c4ddb09d1e3408e52aa8e09a14402f376070a44b1b85cb36d13', 'timestamp': '1733334422790'}
{'asset_id': '114416409796971863099144323163249651172534872992222856507897414949637892047507', 'changes': [{'price': '0.51', 'side': 'BUY', 'size': '2286.18'}], 'event_type': 'price_change', 'hash': 'cb44e9491642a39a40f252b8e0a2831df2d4572d', 'market': '0x7aa4a910b31b2c4ddb09d1e3408e52aa8e09a14402f376070a44b1b85cb36d13', 'timestamp': '1733334422790'}
{'asset_id': '114416409796971863099144323163249651172534872992222856507897414949637892047507', 'changes': [{'price': '0.5', 'side': 'BUY', 'size': '2115'}], 'event_type': 'price_change', 'hash': 'ea2de963d57c244dc69cdd22d772d2dc7579149e', 'market': '0x7aa4a910b31b2c4ddb09d1e3408e52aa8e09a14402f376070a44b1b85cb36d13', 'timestamp': '1733334423009'}
{'asset_id': '114416409796971863099144323163249651172534872992222856507897414949637892047507', 'changes': [{'price': '0.5', 'side': 'BUY', 'size': '2115'}], 'event_type': 'price_change', 'hash': 'ea2de963d57c244dc69cdd22d772d2dc7579149e', 'market': '0x7aa4a910b31b2c4ddb09d1e3408e52aa8e09a14402f376070a44b1b85cb36d13', 'timestamp': '1733334423009'}
{'asset_id': '114416409796971863099144323163249651172534872992222856507897414949637892047507', 'changes': [{'price': '0.58', 'side': 'SELL', 'size': '1620.47'}], 'event_type': 'price_change', 'hash': 'd2cd508833fe262400d17d11f8bbadc8a1135879', 'market': '0x7aa4a910b31b2c4ddb09d1e3408e52aa8e09a14402f376070a44b1b85cb36d13', 'timestamp': '1733334423072'}
{'asset_id': '114416409796971863099144323163249651172534872992222856507897414949637892047507', 'changes': [{'price': '0.58', 'side': 'SELL', 'size': '1620.47'}], 'event_type': 'price_change', 'hash': 'd2cd508833fe262400d17d11f8bbadc8a1135879', 'market': '0x7aa4a910b31b2c4ddb09d1e3408e52aa8e09a14402f376070a44b1b85cb36d13', 'timestamp': '1733334423072'}
{'asset_id': '114416409796971863099144323163249651172534872992222856507897414949637892047507', 'changes': [{'price': '0.57', 'side': 'SELL', 'size': '1330'}], 'event_type': 'price_change', 'hash': '8be25cf54ed1d788a4d84c37068cc8495cd43a49', 'market': '0x7aa4a910b31b2c4ddb09d1e3408e52aa8e09a14402f376070a44b1b85cb36d13', 'timestamp': '1733334423208'}
{'asset_id': '114416409796971863099144323163249651172534872992222856507897414949637892047507', 'changes': [{'price': '0.57', 'side': 'SELL', 'size': '1330'}], 'event_type': 'price_change', 'hash': '8be25cf54ed1d788a4d84c37068cc8495cd43a49', 'market': '0x7aa4a910b31b2c4ddb09d1e3408e52aa8e09a14402f376070a44b1b85cb36d13', 'timestamp': '1733334423208'}
{'asset_id': '114416409796971863099144323163249651172534872992222856507897414949637892047507', 'changes': [{'price': '0.56', 'side': 'SELL', 'size': '0'}], 'event_type': 'price_change', 'hash': '54bcedc61aa6b31f350b8386bad960146357e1c1', 'market': '0x7aa4a910b31b2c4ddb09d1e3408e52aa8e09a14402f376070a44b1b85cb36d13', 'timestamp': '1733334425357'}
{'asset_id': '114416409796971863099144323163249651172534872992222856507897414949637892047507', 'changes': [{'price': '0.61', 'side': 'SELL', 'size': '511.06'}, {'price': '0.53', 'side': 'BUY', 'size': '1118.99'}], 'event_type': 'price_change', 'hash': 'c7997de99df7e1e4fc53364c52a16b3a22fc1484', 'market': '0x7aa4a910b31b2c4ddb09d1e3408e52aa8e09a14402f376070a44b1b85cb36d13', 'timestamp': '1733334428225'}
{'asset_id': '114416409796971863099144323163249651172534872992222856507897414949637892047507', 'changes': [{'price': '0.61', 'side': 'SELL', 'size': '511.06'}, {'price': '0.53', 'side': 'BUY', 'size': '1118.99'}], 'event_type': 'price_change', 'hash': 'c7997de99df7e1e4fc53364c52a16b3a22fc1484', 'market': '0x7aa4a910b31b2c4ddb09d1e3408e52aa8e09a14402f376070a44b1b85cb36d13', 'timestamp': '1733334428225'}
{'asset_id': '114416409796971863099144323163249651172534872992222856507897414949637892047507', 'changes': [{'price': '0.6', 'side': 'SELL', 'size': '3307.85'}, {'price': '0.52', 'side': 'BUY', 'size': '2085.92'}], 'event_type': 'price_change', 'hash': '6a51e7ed7996c090b70fe8544ce85d9c2337e61f', 'market': '0x7aa4a910b31b2c4ddb09d1e3408e52aa8e09a14402f376070a44b1b85cb36d13', 'timestamp': '1733334428557'}
{'asset_id': '114416409796971863099144323163249651172534872992222856507897414949637892047507', 'changes': [{'price': '0.6', 'side': 'SELL', 'size': '3307.85'}, {'price': '0.52', 'side': 'BUY', 'size': '2085.92'}], 'event_type': 'price_change', 'hash': '6a51e7ed7996c090b70fe8544ce85d9c2337e61f', 'market': '0x7aa4a910b31b2c4ddb09d1e3408e52aa8e09a14402f376070a44b1b85cb36d13', 'timestamp': '1733334428557'}
{'asset_id': '114416409796971863099144323163249651172534872992222856507897414949637892047507', 'changes': [{'price': '0.57', 'side': 'SELL', 'size': '1280'}], 'event_type': 'price_change', 'hash': 'eba2fc57a4bbfd6d056babea1ad1d77063807445', 'market': '0x7aa4a910b31b2c4ddb09d1e3408e52aa8e09a14402f376070a44b1b85cb36d13', 'timestamp': '1733334429503'}
{'asset_id': '114416409796971863099144323163249651172534872992222856507897414949637892047507', 'changes': [{'price': '0.57', 'side': 'SELL', 'size': '1280'}], 'event_type': 'price_change', 'hash': 'eba2fc57a4bbfd6d056babea1ad1d77063807445', 'market': '0x7aa4a910b31b2c4ddb09d1e3408e52aa8e09a14402f376070a44b1b85cb36d13', 'timestamp': '1733334429503'}
{'asset_id': '114416409796971863099144323163249651172534872992222856507897414949637892047507', 'changes': [{'price': '0.5', 'side': 'BUY', 'size': '2065'}], 'event_type': 'price_change', 'hash': '84339a915190558f104b986bf40e878240b48f5a', 'market': '0x7aa4a910b31b2c4ddb09d1e3408e52aa8e09a14402f376070a44b1b85cb36d13', 'timestamp': '1733334430451'}
{'asset_id': '114416409796971863099144323163249651172534872992222856507897414949637892047507', 'changes': [{'price': '0.5', 'side': 'BUY', 'size': '2065'}], 'event_type': 'price_change', 'hash': '84339a915190558f104b986bf40e878240b48f5a', 'market': '0x7aa4a910b31b2c4ddb09d1e3408e52aa8e09a14402f376070a44b1b85cb36d13', 'timestamp': '1733334430451'}
{'asset_id': '114416409796971863099144323163249651172534872992222856507897414949637892047507', 'changes': [{'price': '0.57', 'side': 'SELL', 'size': '1230'}], 'event_type': 'price_change', 'hash': '20982d3c40c1eeb1e52bd4c1b31f566a3130c639', 'market': '0x7aa4a910b31b2c4ddb09d1e3408e52aa8e09a14402f376070a44b1b85cb36d13', 'timestamp': '1733334430537'}
{'asset_id': '114416409796971863099144323163249651172534872992222856507897414949637892047507', 'changes': [{'price': '0.57', 'side': 'SELL', 'size': '1230'}], 'event_type': 'price_change', 'hash': '20982d3c40c1eeb1e52bd4c1b31f566a3130c639', 'market': '0x7aa4a910b31b2c4ddb09d1e3408e52aa8e09a14402f376070a44b1b85cb36d13', 'timestamp': '1733334430537'}
{'asset_id': '114416409796971863099144323163249651172534872992222856507897414949637892047507', 'changes': [{'price': '0.57', 'side': 'SELL', 'size': '1200'}, {'price': '0.61', 'side': 'SELL', 'size': '561.06'}], 'event_type': 'price_change', 'hash': '14cea76c1f96f3557bc37a3d507b8dc05cc89dc5', 'market': '0x7aa4a910b31b2c4ddb09d1e3408e52aa8e09a14402f376070a44b1b85cb36d13', 'timestamp': '1733334430686'}
{'asset_id': '114416409796971863099144323163249651172534872992222856507897414949637892047507', 'changes': [{'price': '0.57', 'side': 'SELL', 'size': '1200'}, {'price': '0.61', 'side': 'SELL', 'size': '561.06'}], 'event_type': 'price_change', 'hash': '14cea76c1f96f3557bc37a3d507b8dc05cc89dc5', 'market': '0x7aa4a910b31b2c4ddb09d1e3408e52aa8e09a14402f376070a44b1b85cb36d13', 'timestamp': '1733334430686'}
{'asset_id': '114416409796971863099144323163249651172534872992222856507897414949637892047507', 'changes': [{'price': '0.58', 'side': 'SELL', 'size': '1650.47'}], 'event_type': 'price_change', 'hash': '8cfebd011a1ff1a409d70be14aa0b0535e7445cf', 'market': '0x7aa4a910b31b2c4ddb09d1e3408e52aa8e09a14402f376070a44b1b85cb36d13', 'timestamp': '1733334430760'}
{'asset_id': '114416409796971863099144323163249651172534872992222856507897414949637892047507', 'changes': [{'price': '0.58', 'side': 'SELL', 'size': '1650.47'}], 'event_type': 'price_change', 'hash': '8cfebd011a1ff1a409d70be14aa0b0535e7445cf', 'market': '0x7aa4a910b31b2c4ddb09d1e3408e52aa8e09a14402f376070a44b1b85cb36d13', 'timestamp': '1733334430760'}
{'asset_id': '114416409796971863099144323163249651172534872992222856507897414949637892047507', 'changes': [{'price': '0.5', 'side': 'BUY', 'size': '2015'}], 'event_type': 'price_change', 'hash': '1f2ddf4908847b7afd45c9e273e2081fab955782', 'market': '0x7aa4a910b31b2c4ddb09d1e3408e52aa8e09a14402f376070a44b1b85cb36d13', 'timestamp': '1733334430991'}
{'asset_id': '114416409796971863099144323163249651172534872992222856507897414949637892047507', 'changes': [{'price': '0.5', 'side': 'BUY', 'size': '2015'}], 'event_type': 'price_change', 'hash': '1f2ddf4908847b7afd45c9e273e2081fab955782', 'market': '0x7aa4a910b31b2c4ddb09d1e3408e52aa8e09a14402f376070a44b1b85cb36d13', 'timestamp': '1733334430991'}
{'asset_id': '114416409796971863099144323163249651172534872992222856507897414949637892047507', 'changes': [{'price': '0.54', 'side': 'BUY', 'size': '31.19'}], 'event_type': 'price_change', 'hash': '20310acb2573320862b9421369628451e138f961', 'market': '0x7aa4a910b31b2c4ddb09d1e3408e52aa8e09a14402f376070a44b1b85cb36d13', 'timestamp': '1733334431129'}
{'asset_id': '114416409796971863099144323163249651172534872992222856507897414949637892047507', 'changes': [{'price': '0.54', 'side': 'BUY', 'size': '31.19'}], 'event_type': 'price_change', 'hash': '20310acb2573320862b9421369628451e138f961', 'market': '0x7aa4a910b31b2c4ddb09d1e3408e52aa8e09a14402f376070a44b1b85cb36d13', 'timestamp': '1733334431129'}
{'asset_id': '114416409796971863099144323163249651172534872992222856507897414949637892047507', 'changes': [{'price': '0.61', 'side': 'SELL', 'size': '611.06'}, {'price': '0.55', 'side': 'BUY', 'size': '4072.77'}], 'event_type': 'price_change', 'hash': 'eda93a6d16dd5ff42a8943ed4ca002d174f39454', 'market': '0x7aa4a910b31b2c4ddb09d1e3408e52aa8e09a14402f376070a44b1b85cb36d13', 'timestamp': '1733334431255'}
{'asset_id': '114416409796971863099144323163249651172534872992222856507897414949637892047507', 'changes': [{'price': '0.61', 'side': 'SELL', 'size': '611.06'}, {'price': '0.55', 'side': 'BUY', 'size': '4072.77'}], 'event_type': 'price_change', 'hash': 'eda93a6d16dd5ff42a8943ed4ca002d174f39454', 'market': '0x7aa4a910b31b2c4ddb09d1e3408e52aa8e09a14402f376070a44b1b85cb36d13', 'timestamp': '1733334431255'}
{'asset_id': '114416409796971863099144323163249651172534872992222856507897414949637892047507', 'changes': [{'price': '0.54', 'side': 'BUY', 'size': '81.19'}], 'event_type': 'price_change', 'hash': '9f0f9188ab8728d63a85ec256a1c4ce3addd68d3', 'market': '0x7aa4a910b31b2c4ddb09d1e3408e52aa8e09a14402f376070a44b1b85cb36d13', 'timestamp': '1733334431572'}
{'asset_id': '114416409796971863099144323163249651172534872992222856507897414949637892047507', 'changes': [{'price': '0.54', 'side': 'BUY', 'size': '81.19'}], 'event_type': 'price_change', 'hash': '9f0f9188ab8728d63a85ec256a1c4ce3addd68d3', 'market': '0x7aa4a910b31b2c4ddb09d1e3408e52aa8e09a14402f376070a44b1b85cb36d13', 'timestamp': '1733334431572'}
{'asset_id': '114416409796971863099144323163249651172534872992222856507897414949637892047507', 'changes': [{'price': '0.58', 'side': 'SELL', 'size': '1660.57'}], 'event_type': 'price_change', 'hash': 'dcfdcbabb1750de70f8df964a9cca615e8b79b1d', 'market': '0x7aa4a910b31b2c4ddb09d1e3408e52aa8e09a14402f376070a44b1b85cb36d13', 'timestamp': '1733334433208'}
{'asset_id': '114416409796971863099144323163249651172534872992222856507897414949637892047507', 'changes': [{'price': '0.58', 'side': 'SELL', 'size': '1660.57'}], 'event_type': 'price_change', 'hash': 'dcfdcbabb1750de70f8df964a9cca615e8b79b1d', 'market': '0x7aa4a910b31b2c4ddb09d1e3408e52aa8e09a14402f376070a44b1b85cb36d13', 'timestamp': '1733334433208'}
{'asset_id': '114416409796971863099144323163249651172534872992222856507897414949637892047507', 'changes': [{'price': '0.54', 'side': 'BUY', 'size': '131.19'}], 'event_type': 'price_change', 'hash': '36c08e0ccb3b68562a9e2935856b2e9ef78a7e57', 'market': '0x7aa4a910b31b2c4ddb09d1e3408e52aa8e09a14402f376070a44b1b85cb36d13', 'timestamp': '1733334439248'}
{'asset_id': '114416409796971863099144323163249651172534872992222856507897414949637892047507', 'changes': [{'price': '0.54', 'side': 'BUY', 'size': '131.19'}], 'event_type': 'price_change', 'hash': '36c08e0ccb3b68562a9e2935856b2e9ef78a7e57', 'market': '0x7aa4a910b31b2c4ddb09d1e3408e52aa8e09a14402f376070a44b1b85cb36d13', 'timestamp': '1733334439248'}
{'asset_id': '114416409796971863099144323163249651172534872992222856507897414949637892047507', 'changes': [{'price': '0.5', 'side': 'BUY', 'size': '15'}], 'event_type': 'price_change', 'hash': '37b935c787e70ae200df3f5c3cc94a7f19bf5bb2', 'market': '0x7aa4a910b31b2c4ddb09d1e3408e52aa8e09a14402f376070a44b1b85cb36d13', 'timestamp': '1733334463011'}
{'asset_id': '114416409796971863099144323163249651172534872992222856507897414949637892047507', 'changes': [{'price': '0.5', 'side': 'BUY', 'size': '15'}], 'event_type': 'price_change', 'hash': '37b935c787e70ae200df3f5c3cc94a7f19bf5bb2', 'market': '0x7aa4a910b31b2c4ddb09d1e3408e52aa8e09a14402f376070a44b1b85cb36d13', 'timestamp': '1733334463011'}
{'asks': [{'price': '0.99', 'size': '4217.01'}, {'price': '0.98', 'size': '505'}, {'price': '0.97', 'size': '511.03'}, {'price': '0.96', 'size': '300'}, {'price': '0.95', 'size': '657.12'}, {'price': '0.94', 'size': '300'}, {'price': '0.92', 'size': '20000.45'}, {'price': '0.91', 'size': '10406.3'}, {'price': '0.9', 'size': '4587.5'}, {'price': '0.89', 'size': '13017.18'}, {'price': '0.88', 'size': '200'}, {'price': '0.87', 'size': '3229'}, {'price': '0.86', 'size': '17.1'}, {'price': '0.85', 'size': '109.68'}, {'price': '0.84', 'size': '250'}, {'price': '0.83', 'size': '100'}, {'price': '0.82', 'size': '16029'}, {'price': '0.81', 'size': '45721.39'}, {'price': '0.8', 'size': '26531'}, {'price': '0.79', 'size': '7110'}, {'price': '0.78', 'size': '15350'}, {'price': '0.77', 'size': '67'}, {'price': '0.76', 'size': '200'}, {'price': '0.75', 'size': '13329.25'}, {'price': '0.74', 'size': '11370.7'}, {'price': '0.73', 'size': '5020.1'}, {'price': '0.72', 'size': '380.52'}, {'price': '0.71', 'size': '15073.2'}, {'price': '0.7', 'size': '5570.1'}, {'price': '0.69', 'size': '6088.6'}, {'price': '0.68', 'size': '6131.34'}, {'price': '0.67', 'size': '3010.1'}, {'price': '0.66', 'size': '510.1'}, {'price': '0.65', 'size': '1010.1'}, {'price': '0.64', 'size': '4230.1'}, {'price': '0.63', 'size': '210.1'}, {'price': '0.62', 'size': '300.1'}, {'price': '0.61', 'size': '611.06'}, {'price': '0.6', 'size': '3307.85'}, {'price': '0.59', 'size': '2110'}, {'price': '0.58', 'size': '1660.57'}, {'price': '0.57', 'size': '1200'}], 'asset_id': '114416409796971863099144323163249651172534872992222856507897414949637892047507', 'bids': [{'price': '0.01', 'size': '2850.27'}, {'price': '0.02', 'size': '500'}, {'price': '0.03', 'size': '500'}, {'price': '0.04', 'size': '300'}, {'price': '0.05', 'size': '320'}, {'price': '0.06', 'size': '300'}, {'price': '0.08', 'size': '250'}, {'price': '0.09', 'size': '300'}, {'price': '0.1', 'size': '6205'}, {'price': '0.12', 'size': '200'}, {'price': '0.13', 'size': '426.92'}, {'price': '0.14', 'size': '15'}, {'price': '0.15', 'size': '110'}, {'price': '0.16', 'size': '4709.51'}, {'price': '0.18', 'size': '19.13'}, {'price': '0.19', 'size': '120'}, {'price': '0.2', 'size': '691.17'}, {'price': '0.24', 'size': '5027'}, {'price': '0.25', 'size': '86.66'}, {'price': '0.27', 'size': '215.25'}, {'price': '0.29', 'size': '1102.28'}, {'price': '0.31', 'size': '1130.65'}, {'price': '0.32', 'size': '200'}, {'price': '0.33', 'size': '620'}, {'price': '0.35', 'size': '232'}, {'price': '0.37', 'size': '4000'}, {'price': '0.39', 'size': '10.5'}, {'price': '0.4', 'size': '3135'}, {'price': '0.41', 'size': '20'}, {'price': '0.42', 'size': '3050'}, {'price': '0.43', 'size': '50'}, {'price': '0.44', 'size': '3660'}, {'price': '0.45', 'size': '478'}, {'price': '0.47', 'size': '797.23'}, {'price': '0.48', 'size': '2742.18'}, {'price': '0.49', 'size': '1540'}, {'price': '0.5', 'size': '15'}, {'price': '0.51', 'size': '2286.18'}, {'price': '0.52', 'size': '2085.92'}, {'price': '0.53', 'size': '1118.99'}, {'price': '0.54', 'size': '131.19'}, {'price': '0.55', 'size': '3622.77'}], 'event_type': 'book', 'hash': '95e0823d5e5437a238894cbc67f6f373d2cd86be', 'market': '0x7aa4a910b31b2c4ddb09d1e3408e52aa8e09a14402f376070a44b1b85cb36d13', 'timestamp': '1733334468063'}
{'asks': [{'price': '0.99', 'size': '4217.01'}, {'price': '0.98', 'size': '505'}, {'price': '0.97', 'size': '511.03'}, {'price': '0.96', 'size': '300'}, {'price': '0.95', 'size': '657.12'}, {'price': '0.94', 'size': '300'}, {'price': '0.92', 'size': '20000.45'}, {'price': '0.91', 'size': '10406.3'}, {'price': '0.9', 'size': '4587.5'}, {'price': '0.89', 'size': '13017.18'}, {'price': '0.88', 'size': '200'}, {'price': '0.87', 'size': '3229'}, {'price': '0.86', 'size': '17.1'}, {'price': '0.85', 'size': '109.68'}, {'price': '0.84', 'size': '250'}, {'price': '0.83', 'size': '100'}, {'price': '0.82', 'size': '16029'}, {'price': '0.81', 'size': '45721.39'}, {'price': '0.8', 'size': '26531'}, {'price': '0.79', 'size': '7110'}, {'price': '0.78', 'size': '15350'}, {'price': '0.77', 'size': '67'}, {'price': '0.76', 'size': '200'}, {'price': '0.75', 'size': '13329.25'}, {'price': '0.74', 'size': '11370.7'}, {'price': '0.73', 'size': '5020.1'}, {'price': '0.72', 'size': '380.52'}, {'price': '0.71', 'size': '15073.2'}, {'price': '0.7', 'size': '5570.1'}, {'price': '0.69', 'size': '6088.6'}, {'price': '0.68', 'size': '6131.34'}, {'price': '0.67', 'size': '3010.1'}, {'price': '0.66', 'size': '510.1'}, {'price': '0.65', 'size': '1010.1'}, {'price': '0.64', 'size': '4230.1'}, {'price': '0.63', 'size': '210.1'}, {'price': '0.62', 'size': '300.1'}, {'price': '0.61', 'size': '611.06'}, {'price': '0.6', 'size': '3307.85'}, {'price': '0.59', 'size': '2110'}, {'price': '0.58', 'size': '1660.57'}, {'price': '0.57', 'size': '1200'}], 'asset_id': '114416409796971863099144323163249651172534872992222856507897414949637892047507', 'bids': [{'price': '0.01', 'size': '2850.27'}, {'price': '0.02', 'size': '500'}, {'price': '0.03', 'size': '500'}, {'price': '0.04', 'size': '300'}, {'price': '0.05', 'size': '320'}, {'price': '0.06', 'size': '300'}, {'price': '0.08', 'size': '250'}, {'price': '0.09', 'size': '300'}, {'price': '0.1', 'size': '6205'}, {'price': '0.12', 'size': '200'}, {'price': '0.13', 'size': '426.92'}, {'price': '0.14', 'size': '15'}, {'price': '0.15', 'size': '110'}, {'price': '0.16', 'size': '4709.51'}, {'price': '0.18', 'size': '19.13'}, {'price': '0.19', 'size': '120'}, {'price': '0.2', 'size': '691.17'}, {'price': '0.24', 'size': '5027'}, {'price': '0.25', 'size': '86.66'}, {'price': '0.27', 'size': '215.25'}, {'price': '0.29', 'size': '1102.28'}, {'price': '0.31', 'size': '1130.65'}, {'price': '0.32', 'size': '200'}, {'price': '0.33', 'size': '620'}, {'price': '0.35', 'size': '232'}, {'price': '0.37', 'size': '4000'}, {'price': '0.39', 'size': '10.5'}, {'price': '0.4', 'size': '3135'}, {'price': '0.41', 'size': '20'}, {'price': '0.42', 'size': '3050'}, {'price': '0.43', 'size': '50'}, {'price': '0.44', 'size': '3660'}, {'price': '0.45', 'size': '478'}, {'price': '0.47', 'size': '797.23'}, {'price': '0.48', 'size': '2742.18'}, {'price': '0.49', 'size': '1540'}, {'price': '0.5', 'size': '15'}, {'price': '0.51', 'size': '2286.18'}, {'price': '0.52', 'size': '2085.92'}, {'price': '0.53', 'size': '1118.99'}, {'price': '0.54', 'size': '131.19'}, {'price': '0.55', 'size': '3622.77'}], 'event_type': 'book', 'hash': '95e0823d5e5437a238894cbc67f6f373d2cd86be', 'market': '0x7aa4a910b31b2c4ddb09d1e3408e52aa8e09a14402f376070a44b1b85cb36d13', 'timestamp': '1733334468063'}
{'asset_id': '114416409796971863099144323163249651172534872992222856507897414949637892047507', 'changes': [{'price': '0.48', 'side': 'BUY', 'size': '4742.18'}], 'event_type': 'price_change', 'hash': '9a17f6f3d5ccd28584f92dbc67c43fd2762c1488', 'market': '0x7aa4a910b31b2c4ddb09d1e3408e52aa8e09a14402f376070a44b1b85cb36d13', 'timestamp': '1733334470374'}
{'asset_id': '114416409796971863099144323163249651172534872992222856507897414949637892047507', 'changes': [{'price': '0.48', 'side': 'BUY', 'size': '4742.18'}], 'event_type': 'price_change', 'hash': '9a17f6f3d5ccd28584f92dbc67c43fd2762c1488', 'market': '0x7aa4a910b31b2c4ddb09d1e3408e52aa8e09a14402f376070a44b1b85cb36d13', 'timestamp': '1733334470374'}
{'asset_id': '114416409796971863099144323163249651172534872992222856507897414949637892047507', 'changes': [{'price': '0.49', 'side': 'BUY', 'size': '40'}], 'event_type': 'price_change', 'hash': '3b9d6473ee53b6381c82715777b5678ac969b7a5', 'market': '0x7aa4a910b31b2c4ddb09d1e3408e52aa8e09a14402f376070a44b1b85cb36d13', 'timestamp': '1733334477971'}
{'asset_id': '114416409796971863099144323163249651172534872992222856507897414949637892047507', 'changes': [{'price': '0.49', 'side': 'BUY', 'size': '40'}], 'event_type': 'price_change', 'hash': '3b9d6473ee53b6381c82715777b5678ac969b7a5', 'market': '0x7aa4a910b31b2c4ddb09d1e3408e52aa8e09a14402f376070a44b1b85cb36d13', 'timestamp': '1733334477971'}
{'asset_id': '114416409796971863099144323163249651172534872992222856507897414949637892047507', 'changes': [{'price': '0.5', 'side': 'BUY', 'size': '1515'}], 'event_type': 'price_change', 'hash': 'b49e9aaac77b315546021f87d408c2d2541aac0d', 'market': '0x7aa4a910b31b2c4ddb09d1e3408e52aa8e09a14402f376070a44b1b85cb36d13', 'timestamp': '1733334478283'}
{'asset_id': '114416409796971863099144323163249651172534872992222856507897414949637892047507', 'changes': [{'price': '0.5', 'side': 'BUY', 'size': '1515'}], 'event_type': 'price_change', 'hash': 'b49e9aaac77b315546021f87d408c2d2541aac0d', 'market': '0x7aa4a910b31b2c4ddb09d1e3408e52aa8e09a14402f376070a44b1b85cb36d13', 'timestamp': '1733334478283'}
{'asset_id': '114416409796971863099144323163249651172534872992222856507897414949637892047507', 'changes': [{'price': '0.57', 'side': 'SELL', 'size': '1210.1'}], 'event_type': 'price_change', 'hash': '69750e298fcb3ec94aefed8bfeb4876be9115576', 'market': '0x7aa4a910b31b2c4ddb09d1e3408e52aa8e09a14402f376070a44b1b85cb36d13', 'timestamp': '1733334478984'}
{'asset_id': '114416409796971863099144323163249651172534872992222856507897414949637892047507', 'changes': [{'price': '0.57', 'side': 'SELL', 'size': '1210.1'}], 'event_type': 'price_change', 'hash': '69750e298fcb3ec94aefed8bfeb4876be9115576', 'market': '0x7aa4a910b31b2c4ddb09d1e3408e52aa8e09a14402f376070a44b1b85cb36d13', 'timestamp': '1733334478984'}
{'asks': [{'price': '0.99', 'size': '4217.01'}, {'price': '0.98', 'size': '505'}, {'price': '0.97', 'size': '511.03'}, {'price': '0.96', 'size': '300'}, {'price': '0.95', 'size': '657.12'}, {'price': '0.94', 'size': '300'}, {'price': '0.92', 'size': '20000.45'}, {'price': '0.91', 'size': '10406.3'}, {'price': '0.9', 'size': '4587.5'}, {'price': '0.89', 'size': '13017.18'}, {'price': '0.88', 'size': '200'}, {'price': '0.87', 'size': '3229'}, {'price': '0.86', 'size': '17.1'}, {'price': '0.85', 'size': '109.68'}, {'price': '0.84', 'size': '250'}, {'price': '0.83', 'size': '100'}, {'price': '0.82', 'size': '16029'}, {'price': '0.81', 'size': '45721.39'}, {'price': '0.8', 'size': '26531'}, {'price': '0.79', 'size': '7110'}, {'price': '0.78', 'size': '15350'}, {'price': '0.77', 'size': '67'}, {'price': '0.76', 'size': '200'}, {'price': '0.75', 'size': '13329.25'}, {'price': '0.74', 'size': '11370.7'}, {'price': '0.73', 'size': '5020.1'}, {'price': '0.72', 'size': '380.52'}, {'price': '0.71', 'size': '15073.2'}, {'price': '0.7', 'size': '5570.1'}, {'price': '0.69', 'size': '6088.6'}, {'price': '0.68', 'size': '6131.34'}, {'price': '0.67', 'size': '3010.1'}, {'price': '0.66', 'size': '510.1'}, {'price': '0.65', 'size': '1010.1'}, {'price': '0.64', 'size': '4230.1'}, {'price': '0.63', 'size': '210.1'}, {'price': '0.62', 'size': '300.1'}, {'price': '0.61', 'size': '611.06'}, {'price': '0.6', 'size': '3307.85'}, {'price': '0.59', 'size': '2110'}, {'price': '0.58', 'size': '1660.57'}, {'price': '0.57', 'size': '1210.1'}], 'asset_id': '114416409796971863099144323163249651172534872992222856507897414949637892047507', 'bids': [{'price': '0.01', 'size': '2850.27'}, {'price': '0.02', 'size': '500'}, {'price': '0.03', 'size': '500'}, {'price': '0.04', 'size': '300'}, {'price': '0.05', 'size': '320'}, {'price': '0.06', 'size': '300'}, {'price': '0.08', 'size': '250'}, {'price': '0.09', 'size': '300'}, {'price': '0.1', 'size': '6205'}, {'price': '0.12', 'size': '200'}, {'price': '0.13', 'size': '426.92'}, {'price': '0.14', 'size': '15'}, {'price': '0.15', 'size': '110'}, {'price': '0.16', 'size': '4709.51'}, {'price': '0.18', 'size': '19.13'}, {'price': '0.19', 'size': '120'}, {'price': '0.2', 'size': '691.17'}, {'price': '0.24', 'size': '5027'}, {'price': '0.25', 'size': '86.66'}, {'price': '0.27', 'size': '215.25'}, {'price': '0.29', 'size': '1102.28'}, {'price': '0.31', 'size': '1130.65'}, {'price': '0.32', 'size': '200'}, {'price': '0.33', 'size': '620'}, {'price': '0.35', 'size': '232'}, {'price': '0.37', 'size': '4000'}, {'price': '0.39', 'size': '10.5'}, {'price': '0.4', 'size': '3135'}, {'price': '0.41', 'size': '20'}, {'price': '0.42', 'size': '3050'}, {'price': '0.43', 'size': '50'}, {'price': '0.44', 'size': '3660'}, {'price': '0.45', 'size': '478'}, {'price': '0.47', 'size': '797.23'}, {'price': '0.48', 'size': '4742.18'}, {'price': '0.49', 'size': '40'}, {'price': '0.5', 'size': '1515'}, {'price': '0.51', 'size': '2286.18'}, {'price': '0.52', 'size': '2085.92'}, {'price': '0.53', 'size': '1118.99'}, {'price': '0.54', 'size': '131.19'}, {'price': '0.55', 'size': '3561.77'}], 'event_type': 'book', 'hash': '034b3809dacf9abee7ccbf650c86039e9f9c54d5', 'market': '0x7aa4a910b31b2c4ddb09d1e3408e52aa8e09a14402f376070a44b1b85cb36d13', 'timestamp': '1733334479405'}
{'asks': [{'price': '0.99', 'size': '4217.01'}, {'price': '0.98', 'size': '505'}, {'price': '0.97', 'size': '511.03'}, {'price': '0.96', 'size': '300'}, {'price': '0.95', 'size': '657.12'}, {'price': '0.94', 'size': '300'}, {'price': '0.92', 'size': '20000.45'}, {'price': '0.91', 'size': '10406.3'}, {'price': '0.9', 'size': '4587.5'}, {'price': '0.89', 'size': '13017.18'}, {'price': '0.88', 'size': '200'}, {'price': '0.87', 'size': '3229'}, {'price': '0.86', 'size': '17.1'}, {'price': '0.85', 'size': '109.68'}, {'price': '0.84', 'size': '250'}, {'price': '0.83', 'size': '100'}, {'price': '0.82', 'size': '16029'}, {'price': '0.81', 'size': '45721.39'}, {'price': '0.8', 'size': '26531'}, {'price': '0.79', 'size': '7110'}, {'price': '0.78', 'size': '15350'}, {'price': '0.77', 'size': '67'}, {'price': '0.76', 'size': '200'}, {'price': '0.75', 'size': '13329.25'}, {'price': '0.74', 'size': '11370.7'}, {'price': '0.73', 'size': '5020.1'}, {'price': '0.72', 'size': '380.52'}, {'price': '0.71', 'size': '15073.2'}, {'price': '0.7', 'size': '5570.1'}, {'price': '0.69', 'size': '6088.6'}, {'price': '0.68', 'size': '6131.34'}, {'price': '0.67', 'size': '3010.1'}, {'price': '0.66', 'size': '510.1'}, {'price': '0.65', 'size': '1010.1'}, {'price': '0.64', 'size': '4230.1'}, {'price': '0.63', 'size': '210.1'}, {'price': '0.62', 'size': '300.1'}, {'price': '0.61', 'size': '611.06'}, {'price': '0.6', 'size': '3307.85'}, {'price': '0.59', 'size': '2110'}, {'price': '0.58', 'size': '1660.57'}, {'price': '0.57', 'size': '1210.1'}], 'asset_id': '114416409796971863099144323163249651172534872992222856507897414949637892047507', 'bids': [{'price': '0.01', 'size': '2850.27'}, {'price': '0.02', 'size': '500'}, {'price': '0.03', 'size': '500'}, {'price': '0.04', 'size': '300'}, {'price': '0.05', 'size': '320'}, {'price': '0.06', 'size': '300'}, {'price': '0.08', 'size': '250'}, {'price': '0.09', 'size': '300'}, {'price': '0.1', 'size': '6205'}, {'price': '0.12', 'size': '200'}, {'price': '0.13', 'size': '426.92'}, {'price': '0.14', 'size': '15'}, {'price': '0.15', 'size': '110'}, {'price': '0.16', 'size': '4709.51'}, {'price': '0.18', 'size': '19.13'}, {'price': '0.19', 'size': '120'}, {'price': '0.2', 'size': '691.17'}, {'price': '0.24', 'size': '5027'}, {'price': '0.25', 'size': '86.66'}, {'price': '0.27', 'size': '215.25'}, {'price': '0.29', 'size': '1102.28'}, {'price': '0.31', 'size': '1130.65'}, {'price': '0.32', 'size': '200'}, {'price': '0.33', 'size': '620'}, {'price': '0.35', 'size': '232'}, {'price': '0.37', 'size': '4000'}, {'price': '0.39', 'size': '10.5'}, {'price': '0.4', 'size': '3135'}, {'price': '0.41', 'size': '20'}, {'price': '0.42', 'size': '3050'}, {'price': '0.43', 'size': '50'}, {'price': '0.44', 'size': '3660'}, {'price': '0.45', 'size': '478'}, {'price': '0.47', 'size': '797.23'}, {'price': '0.48', 'size': '4742.18'}, {'price': '0.49', 'size': '40'}, {'price': '0.5', 'size': '1515'}, {'price': '0.51', 'size': '2286.18'}, {'price': '0.52', 'size': '2085.92'}, {'price': '0.53', 'size': '1118.99'}, {'price': '0.54', 'size': '131.19'}, {'price': '0.55', 'size': '3561.77'}], 'event_type': 'book', 'hash': '034b3809dacf9abee7ccbf650c86039e9f9c54d5', 'market': '0x7aa4a910b31b2c4ddb09d1e3408e52aa8e09a14402f376070a44b1b85cb36d13', 'timestamp': '1733334479405'}
{'asset_id': '114416409796971863099144323163249651172534872992222856507897414949637892047507', 'changes': [{'price': '0.53', 'side': 'BUY', 'size': '1218.99'}], 'event_type': 'price_change', 'hash': '14bdf2b9c2b0bf8c6be9c19af4bba2451da43146', 'market': '0x7aa4a910b31b2c4ddb09d1e3408e52aa8e09a14402f376070a44b1b85cb36d13', 'timestamp': '1733334481810'}
{'asset_id': '114416409796971863099144323163249651172534872992222856507897414949637892047507', 'changes': [{'price': '0.53', 'side': 'BUY', 'size': '1218.99'}], 'event_type': 'price_change', 'hash': '14bdf2b9c2b0bf8c6be9c19af4bba2451da43146', 'market': '0x7aa4a910b31b2c4ddb09d1e3408e52aa8e09a14402f376070a44b1b85cb36d13', 'timestamp': '1733334481810'}
{'asset_id': '114416409796971863099144323163249651172534872992222856507897414949637892047507', 'changes': [{'price': '0.47', 'side': 'BUY', 'size': '297.23'}, {'price': '0.52', 'side': 'BUY', 'size': '1085.92'}], 'event_type': 'price_change', 'hash': '62f4a68b4f78f07f2efa0afb1d20ec3fbdc0bb0b', 'market': '0x7aa4a910b31b2c4ddb09d1e3408e52aa8e09a14402f376070a44b1b85cb36d13', 'timestamp': '1733334486455'}
{'asset_id': '114416409796971863099144323163249651172534872992222856507897414949637892047507', 'changes': [{'price': '0.47', 'side': 'BUY', 'size': '297.23'}, {'price': '0.52', 'side': 'BUY', 'size': '1085.92'}], 'event_type': 'price_change', 'hash': '62f4a68b4f78f07f2efa0afb1d20ec3fbdc0bb0b', 'market': '0x7aa4a910b31b2c4ddb09d1e3408e52aa8e09a14402f376070a44b1b85cb36d13', 'timestamp': '1733334486455'}
{'asset_id': '114416409796971863099144323163249651172534872992222856507897414949637892047507', 'changes': [{'price': '0.5', 'side': 'BUY', 'size': '15'}, {'price': '0.51', 'side': 'BUY', 'size': '1086.18'}, {'price': '0.48', 'side': 'BUY', 'size': '2742.18'}], 'event_type': 'price_change', 'hash': 'b78d94f9beea7302a144423d8ba9c919584b9ae7', 'market': '0x7aa4a910b31b2c4ddb09d1e3408e52aa8e09a14402f376070a44b1b85cb36d13', 'timestamp': '1733334487071'}
{'asset_id': '114416409796971863099144323163249651172534872992222856507897414949637892047507', 'changes': [{'price': '0.5', 'side': 'BUY', 'size': '15'}, {'price': '0.51', 'side': 'BUY', 'size': '1086.18'}, {'price': '0.48', 'side': 'BUY', 'size': '2742.18'}], 'event_type': 'price_change', 'hash': 'b78d94f9beea7302a144423d8ba9c919584b9ae7', 'market': '0x7aa4a910b31b2c4ddb09d1e3408e52aa8e09a14402f376070a44b1b85cb36d13', 'timestamp': '1733334487071'}
{'asset_id': '114416409796971863099144323163249651172534872992222856507897414949637892047507', 'changes': [{'price': '0.51', 'side': 'BUY', 'size': '2586.18'}, {'price': '0.52', 'side': 'BUY', 'size': '2285.92'}, {'price': '0.5', 'side': 'BUY', 'size': '2015'}], 'event_type': 'price_change', 'hash': 'b1d55532007e8a908714777bd56486c003e69819', 'market': '0x7aa4a910b31b2c4ddb09d1e3408e52aa8e09a14402f376070a44b1b85cb36d13', 'timestamp': '1733334487444'}
{'asset_id': '114416409796971863099144323163249651172534872992222856507897414949637892047507', 'changes': [{'price': '0.51', 'side': 'BUY', 'size': '2586.18'}, {'price': '0.52', 'side': 'BUY', 'size': '2285.92'}, {'price': '0.5', 'side': 'BUY', 'size': '2015'}], 'event_type': 'price_change', 'hash': 'b1d55532007e8a908714777bd56486c003e69819', 'market': '0x7aa4a910b31b2c4ddb09d1e3408e52aa8e09a14402f376070a44b1b85cb36d13', 'timestamp': '1733334487444'}
{'asset_id': '114416409796971863099144323163249651172534872992222856507897414949637892047507', 'changes': [{'price': '0.48', 'side': 'BUY', 'size': '3242.18'}], 'event_type': 'price_change', 'hash': 'd2b64421a0e79785914479641632c1abfa375aa0', 'market': '0x7aa4a910b31b2c4ddb09d1e3408e52aa8e09a14402f376070a44b1b85cb36d13', 'timestamp': '1733334487554'}
{'asset_id': '114416409796971863099144323163249651172534872992222856507897414949637892047507', 'changes': [{'price': '0.48', 'side': 'BUY', 'size': '3242.18'}], 'event_type': 'price_change', 'hash': 'd2b64421a0e79785914479641632c1abfa375aa0', 'market': '0x7aa4a910b31b2c4ddb09d1e3408e52aa8e09a14402f376070a44b1b85cb36d13', 'timestamp': '1733334487554'}
{'asset_id': '114416409796971863099144323163249651172534872992222856507897414949637892047507', 'changes': [{'price': '0.58', 'side': 'SELL', 'size': '2160.57'}], 'event_type': 'price_change', 'hash': '2be1b2f17ee119631dcf741c3b51338525eea660', 'market': '0x7aa4a910b31b2c4ddb09d1e3408e52aa8e09a14402f376070a44b1b85cb36d13', 'timestamp': '1733334487923'}
{'asset_id': '114416409796971863099144323163249651172534872992222856507897414949637892047507', 'changes': [{'price': '0.58', 'side': 'SELL', 'size': '2160.57'}], 'event_type': 'price_change', 'hash': '2be1b2f17ee119631dcf741c3b51338525eea660', 'market': '0x7aa4a910b31b2c4ddb09d1e3408e52aa8e09a14402f376070a44b1b85cb36d13', 'timestamp': '1733334487923'}
{'asset_id': '114416409796971863099144323163249651172534872992222856507897414949637892047507', 'changes': [{'price': '0.53', 'side': 'BUY', 'size': '2218.99'}], 'event_type': 'price_change', 'hash': '37674572d9d070a84243cf26c6462a1a4070285a', 'market': '0x7aa4a910b31b2c4ddb09d1e3408e52aa8e09a14402f376070a44b1b85cb36d13', 'timestamp': '1733334488305'}
{'asset_id': '114416409796971863099144323163249651172534872992222856507897414949637892047507', 'changes': [{'price': '0.53', 'side': 'BUY', 'size': '2218.99'}], 'event_type': 'price_change', 'hash': '37674572d9d070a84243cf26c6462a1a4070285a', 'market': '0x7aa4a910b31b2c4ddb09d1e3408e52aa8e09a14402f376070a44b1b85cb36d13', 'timestamp': '1733334488305'}
{'asks': [{'price': '0.99', 'size': '4217.01'}, {'price': '0.98', 'size': '505'}, {'price': '0.97', 'size': '511.03'}, {'price': '0.96', 'size': '300'}, {'price': '0.95', 'size': '657.12'}, {'price': '0.94', 'size': '300'}, {'price': '0.92', 'size': '20000.45'}, {'price': '0.91', 'size': '10406.3'}, {'price': '0.9', 'size': '4587.5'}, {'price': '0.89', 'size': '13017.18'}, {'price': '0.88', 'size': '200'}, {'price': '0.87', 'size': '3229'}, {'price': '0.86', 'size': '17.1'}, {'price': '0.85', 'size': '109.68'}, {'price': '0.84', 'size': '250'}, {'price': '0.83', 'size': '100'}, {'price': '0.82', 'size': '16029'}, {'price': '0.81', 'size': '45721.39'}, {'price': '0.8', 'size': '26531'}, {'price': '0.79', 'size': '7110'}, {'price': '0.78', 'size': '15350'}, {'price': '0.77', 'size': '67'}, {'price': '0.76', 'size': '200'}, {'price': '0.75', 'size': '13329.25'}, {'price': '0.74', 'size': '11370.7'}, {'price': '0.73', 'size': '5020.1'}, {'price': '0.72', 'size': '380.52'}, {'price': '0.71', 'size': '15073.2'}, {'price': '0.7', 'size': '5570.1'}, {'price': '0.69', 'size': '6088.6'}, {'price': '0.68', 'size': '6131.34'}, {'price': '0.67', 'size': '3010.1'}, {'price': '0.66', 'size': '510.1'}, {'price': '0.65', 'size': '1010.1'}, {'price': '0.64', 'size': '4230.1'}, {'price': '0.63', 'size': '210.1'}, {'price': '0.62', 'size': '300.1'}, {'price': '0.61', 'size': '611.06'}, {'price': '0.6', 'size': '3307.85'}, {'price': '0.59', 'size': '2110'}, {'price': '0.58', 'size': '1660.57'}, {'price': '0.57', 'size': '1165.11'}], 'asset_id': '114416409796971863099144323163249651172534872992222856507897414949637892047507', 'bids': [{'price': '0.01', 'size': '2850.27'}, {'price': '0.02', 'size': '500'}, {'price': '0.03', 'size': '500'}, {'price': '0.04', 'size': '300'}, {'price': '0.05', 'size': '320'}, {'price': '0.06', 'size': '300'}, {'price': '0.08', 'size': '250'}, {'price': '0.09', 'size': '300'}, {'price': '0.1', 'size': '6205'}, {'price': '0.12', 'size': '200'}, {'price': '0.13', 'size': '426.92'}, {'price': '0.14', 'size': '15'}, {'price': '0.15', 'size': '110'}, {'price': '0.16', 'size': '4709.51'}, {'price': '0.18', 'size': '19.13'}, {'price': '0.19', 'size': '120'}, {'price': '0.2', 'size': '691.17'}, {'price': '0.24', 'size': '5027'}, {'price': '0.25', 'size': '86.66'}, {'price': '0.27', 'size': '215.25'}, {'price': '0.29', 'size': '1102.28'}, {'price': '0.31', 'size': '1130.65'}, {'price': '0.32', 'size': '200'}, {'price': '0.33', 'size': '620'}, {'price': '0.35', 'size': '232'}, {'price': '0.37', 'size': '4000'}, {'price': '0.39', 'size': '10.5'}, {'price': '0.4', 'size': '3135'}, {'price': '0.41', 'size': '20'}, {'price': '0.42', 'size': '3050'}, {'price': '0.43', 'size': '50'}, {'price': '0.44', 'size': '3660'}, {'price': '0.45', 'size': '478'}, {'price': '0.47', 'size': '297.23'}, {'price': '0.48', 'size': '2742.18'}, {'price': '0.49', 'size': '40'}, {'price': '0.5', 'size': '2015'}, {'price': '0.51', 'size': '2586.18'}, {'price': '0.52', 'size': '2285.92'}, {'price': '0.53', 'size': '1218.99'}, {'price': '0.54', 'size': '131.19'}, {'price': '0.55', 'size': '3561.77'}], 'event_type': 'book', 'hash': '00d33c7a73b3f80b823c99ef36db9bf8b0e284f8', 'market': '0x7aa4a910b31b2c4ddb09d1e3408e52aa8e09a14402f376070a44b1b85cb36d13', 'timestamp': '1733334494797'}
{'asset_id': '114416409796971863099144323163249651172534872992222856507897414949637892047507', 'changes': [{'price': '0.48', 'side': 'BUY', 'size': '2742.18'}], 'event_type': 'price_change', 'hash': '0f2e951939238645a24f95e961267af6cdff815d', 'market': '0x7aa4a910b31b2c4ddb09d1e3408e52aa8e09a14402f376070a44b1b85cb36d13', 'timestamp': '1733334494798'}
{'asks': [{'price': '0.99', 'size': '4217.01'}, {'price': '0.98', 'size': '505'}, {'price': '0.97', 'size': '511.03'}, {'price': '0.96', 'size': '300'}, {'price': '0.95', 'size': '657.12'}, {'price': '0.94', 'size': '300'}, {'price': '0.92', 'size': '20000.45'}, {'price': '0.91', 'size': '10406.3'}, {'price': '0.9', 'size': '4587.5'}, {'price': '0.89', 'size': '13017.18'}, {'price': '0.88', 'size': '200'}, {'price': '0.87', 'size': '3229'}, {'price': '0.86', 'size': '17.1'}, {'price': '0.85', 'size': '109.68'}, {'price': '0.84', 'size': '250'}, {'price': '0.83', 'size': '100'}, {'price': '0.82', 'size': '16029'}, {'price': '0.81', 'size': '45721.39'}, {'price': '0.8', 'size': '26531'}, {'price': '0.79', 'size': '7110'}, {'price': '0.78', 'size': '15350'}, {'price': '0.77', 'size': '67'}, {'price': '0.76', 'size': '200'}, {'price': '0.75', 'size': '13329.25'}, {'price': '0.74', 'size': '11370.7'}, {'price': '0.73', 'size': '5020.1'}, {'price': '0.72', 'size': '380.52'}, {'price': '0.71', 'size': '15073.2'}, {'price': '0.7', 'size': '5570.1'}, {'price': '0.69', 'size': '6088.6'}, {'price': '0.68', 'size': '6131.34'}, {'price': '0.67', 'size': '3010.1'}, {'price': '0.66', 'size': '510.1'}, {'price': '0.65', 'size': '1010.1'}, {'price': '0.64', 'size': '4230.1'}, {'price': '0.63', 'size': '210.1'}, {'price': '0.62', 'size': '300.1'}, {'price': '0.61', 'size': '611.06'}, {'price': '0.6', 'size': '3307.85'}, {'price': '0.59', 'size': '2110'}, {'price': '0.58', 'size': '1660.57'}, {'price': '0.57', 'size': '1165.11'}], 'asset_id': '114416409796971863099144323163249651172534872992222856507897414949637892047507', 'bids': [{'price': '0.01', 'size': '2850.27'}, {'price': '0.02', 'size': '500'}, {'price': '0.03', 'size': '500'}, {'price': '0.04', 'size': '300'}, {'price': '0.05', 'size': '320'}, {'price': '0.06', 'size': '300'}, {'price': '0.08', 'size': '250'}, {'price': '0.09', 'size': '300'}, {'price': '0.1', 'size': '6205'}, {'price': '0.12', 'size': '200'}, {'price': '0.13', 'size': '426.92'}, {'price': '0.14', 'size': '15'}, {'price': '0.15', 'size': '110'}, {'price': '0.16', 'size': '4709.51'}, {'price': '0.18', 'size': '19.13'}, {'price': '0.19', 'size': '120'}, {'price': '0.2', 'size': '691.17'}, {'price': '0.24', 'size': '5027'}, {'price': '0.25', 'size': '86.66'}, {'price': '0.27', 'size': '215.25'}, {'price': '0.29', 'size': '1102.28'}, {'price': '0.31', 'size': '1130.65'}, {'price': '0.32', 'size': '200'}, {'price': '0.33', 'size': '620'}, {'price': '0.35', 'size': '232'}, {'price': '0.37', 'size': '4000'}, {'price': '0.39', 'size': '10.5'}, {'price': '0.4', 'size': '3135'}, {'price': '0.41', 'size': '20'}, {'price': '0.42', 'size': '3050'}, {'price': '0.43', 'size': '50'}, {'price': '0.44', 'size': '3660'}, {'price': '0.45', 'size': '478'}, {'price': '0.47', 'size': '297.23'}, {'price': '0.48', 'size': '2742.18'}, {'price': '0.49', 'size': '40'}, {'price': '0.5', 'size': '2015'}, {'price': '0.51', 'size': '2586.18'}, {'price': '0.52', 'size': '2285.92'}, {'price': '0.53', 'size': '1218.99'}, {'price': '0.54', 'size': '131.19'}, {'price': '0.55', 'size': '3561.77'}], 'event_type': 'book', 'hash': '00d33c7a73b3f80b823c99ef36db9bf8b0e284f8', 'market': '0x7aa4a910b31b2c4ddb09d1e3408e52aa8e09a14402f376070a44b1b85cb36d13', 'timestamp': '1733334494797'}
{'asset_id': '114416409796971863099144323163249651172534872992222856507897414949637892047507', 'changes': [{'price': '0.48', 'side': 'BUY', 'size': '2742.18'}], 'event_type': 'price_change', 'hash': '0f2e951939238645a24f95e961267af6cdff815d', 'market': '0x7aa4a910b31b2c4ddb09d1e3408e52aa8e09a14402f376070a44b1b85cb36d13', 'timestamp': '1733334494798'}
{'asset_id': '114416409796971863099144323163249651172534872992222856507897414949637892047507', 'changes': [{'price': '0.58', 'side': 'SELL', 'size': '1660.57'}, {'price': '0.53', 'side': 'BUY', 'size': '1218.99'}], 'event_type': 'price_change', 'hash': '00d33c7a73b3f80b823c99ef36db9bf8b0e284f8', 'market': '0x7aa4a910b31b2c4ddb09d1e3408e52aa8e09a14402f376070a44b1b85cb36d13', 'timestamp': '1733334494807'}
{'asset_id': '114416409796971863099144323163249651172534872992222856507897414949637892047507', 'changes': [{'price': '0.58', 'side': 'SELL', 'size': '1660.57'}, {'price': '0.53', 'side': 'BUY', 'size': '1218.99'}], 'event_type': 'price_change', 'hash': '00d33c7a73b3f80b823c99ef36db9bf8b0e284f8', 'market': '0x7aa4a910b31b2c4ddb09d1e3408e52aa8e09a14402f376070a44b1b85cb36d13', 'timestamp': '1733334494807'}
{'asset_id': '114416409796971863099144323163249651172534872992222856507897414949637892047507', 'changes': [{'price': '0.55', 'side': 'BUY', 'size': '3576.77'}], 'event_type': 'price_change', 'hash': '7e0df572551609c9223e091feb543cf8524ab466', 'market': '0x7aa4a910b31b2c4ddb09d1e3408e52aa8e09a14402f376070a44b1b85cb36d13', 'timestamp': '1733334495289'}
{'asset_id': '114416409796971863099144323163249651172534872992222856507897414949637892047507', 'changes': [{'price': '0.55', 'side': 'BUY', 'size': '3576.77'}], 'event_type': 'price_change', 'hash': '7e0df572551609c9223e091feb543cf8524ab466', 'market': '0x7aa4a910b31b2c4ddb09d1e3408e52aa8e09a14402f376070a44b1b85cb36d13', 'timestamp': '1733334495289'}
{'asset_id': '114416409796971863099144323163249651172534872992222856507897414949637892047507', 'changes': [{'price': '0.57', 'side': 'SELL', 'size': '10.1'}], 'event_type': 'price_change', 'hash': '453ca9f70fb52641a191ab8451efe7a496969d8c', 'market': '0x7aa4a910b31b2c4ddb09d1e3408e52aa8e09a14402f376070a44b1b85cb36d13', 'timestamp': '1733334495481'}
{'asset_id': '114416409796971863099144323163249651172534872992222856507897414949637892047507', 'changes': [{'price': '0.57', 'side': 'SELL', 'size': '10.1'}], 'event_type': 'price_change', 'hash': '453ca9f70fb52641a191ab8451efe7a496969d8c', 'market': '0x7aa4a910b31b2c4ddb09d1e3408e52aa8e09a14402f376070a44b1b85cb36d13', 'timestamp': '1733334495481'}
{'asset_id': '114416409796971863099144323163249651172534872992222856507897414949637892047507', 'changes': [{'price': '0.48', 'side': 'BUY', 'size': '3242.18'}], 'event_type': 'price_change', 'hash': '78aae27a2c2735f15d663f0607a96f529ff6fd35', 'market': '0x7aa4a910b31b2c4ddb09d1e3408e52aa8e09a14402f376070a44b1b85cb36d13', 'timestamp': '1733334495875'}
{'asset_id': '114416409796971863099144323163249651172534872992222856507897414949637892047507', 'changes': [{'price': '0.48', 'side': 'BUY', 'size': '3242.18'}], 'event_type': 'price_change', 'hash': '78aae27a2c2735f15d663f0607a96f529ff6fd35', 'market': '0x7aa4a910b31b2c4ddb09d1e3408e52aa8e09a14402f376070a44b1b85cb36d13', 'timestamp': '1733334495875'}
{'asset_id': '114416409796971863099144323163249651172534872992222856507897414949637892047507', 'changes': [{'price': '0.59', 'side': 'SELL', 'size': '2610'}], 'event_type': 'price_change', 'hash': '4c81c2bae826abea5fd84312b58da2392f252fdb', 'market': '0x7aa4a910b31b2c4ddb09d1e3408e52aa8e09a14402f376070a44b1b85cb36d13', 'timestamp': '1733334496278'}
{'asset_id': '114416409796971863099144323163249651172534872992222856507897414949637892047507', 'changes': [{'price': '0.59', 'side': 'SELL', 'size': '2610'}], 'event_type': 'price_change', 'hash': '4c81c2bae826abea5fd84312b58da2392f252fdb', 'market': '0x7aa4a910b31b2c4ddb09d1e3408e52aa8e09a14402f376070a44b1b85cb36d13', 'timestamp': '1733334496278'}
{'asset_id': '114416409796971863099144323163249651172534872992222856507897414949637892047507', 'changes': [{'price': '0.54', 'side': 'BUY', 'size': '1131.19'}, {'price': '0.59', 'side': 'SELL', 'size': '3810'}], 'event_type': 'price_change', 'hash': '97b982b5a4f0013a273c585efe60af85577bb02c', 'market': '0x7aa4a910b31b2c4ddb09d1e3408e52aa8e09a14402f376070a44b1b85cb36d13', 'timestamp': '1733334496693'}
{'asset_id': '114416409796971863099144323163249651172534872992222856507897414949637892047507', 'changes': [{'price': '0.54', 'side': 'BUY', 'size': '1131.19'}, {'price': '0.59', 'side': 'SELL', 'size': '3810'}], 'event_type': 'price_change', 'hash': '97b982b5a4f0013a273c585efe60af85577bb02c', 'market': '0x7aa4a910b31b2c4ddb09d1e3408e52aa8e09a14402f376070a44b1b85cb36d13', 'timestamp': '1733334496693'}
{'asset_id': '114416409796971863099144323163249651172534872992222856507897414949637892047507', 'changes': [{'price': '0.53', 'side': 'BUY', 'size': '1118.99'}], 'event_type': 'price_change', 'hash': '73c3853ba08e3b7a86c363bc6580600c1003286b', 'market': '0x7aa4a910b31b2c4ddb09d1e3408e52aa8e09a14402f376070a44b1b85cb36d13', 'timestamp': '1733334502213'}
{'asset_id': '114416409796971863099144323163249651172534872992222856507897414949637892047507', 'changes': [{'price': '0.53', 'side': 'BUY', 'size': '1118.99'}], 'event_type': 'price_change', 'hash': '73c3853ba08e3b7a86c363bc6580600c1003286b', 'market': '0x7aa4a910b31b2c4ddb09d1e3408e52aa8e09a14402f376070a44b1b85cb36d13', 'timestamp': '1733334502213'}
{'asset_id': '114416409796971863099144323163249651172534872992222856507897414949637892047507', 'changes': [{'price': '0.53', 'side': 'BUY', 'size': '1218.99'}], 'event_type': 'price_change', 'hash': '2aebf1077385fc59aa203fed528e050b2be200e1', 'market': '0x7aa4a910b31b2c4ddb09d1e3408e52aa8e09a14402f376070a44b1b85cb36d13', 'timestamp': '1733334504268'}
{'asset_id': '114416409796971863099144323163249651172534872992222856507897414949637892047507', 'changes': [{'price': '0.53', 'side': 'BUY', 'size': '1218.99'}], 'event_type': 'price_change', 'hash': '2aebf1077385fc59aa203fed528e050b2be200e1', 'market': '0x7aa4a910b31b2c4ddb09d1e3408e52aa8e09a14402f376070a44b1b85cb36d13', 'timestamp': '1733334504268'}
{'asset_id': '114416409796971863099144323163249651172534872992222856507897414949637892047507', 'changes': [{'price': '0.59', 'side': 'SELL', 'size': '1810'}], 'event_type': 'price_change', 'hash': '596e08b92dbee643ad146a3bb87376de936c3445', 'market': '0x7aa4a910b31b2c4ddb09d1e3408e52aa8e09a14402f376070a44b1b85cb36d13', 'timestamp': '1733334505010'}
{'asset_id': '114416409796971863099144323163249651172534872992222856507897414949637892047507', 'changes': [{'price': '0.59', 'side': 'SELL', 'size': '1810'}], 'event_type': 'price_change', 'hash': '596e08b92dbee643ad146a3bb87376de936c3445', 'market': '0x7aa4a910b31b2c4ddb09d1e3408e52aa8e09a14402f376070a44b1b85cb36d13', 'timestamp': '1733334505010'}
{'asset_id': '114416409796971863099144323163249651172534872992222856507897414949637892047507', 'changes': [{'price': '0.48', 'side': 'BUY', 'size': '2742.18'}, {'price': '0.54', 'side': 'BUY', 'size': '131.19'}, {'price': '0.59', 'side': 'SELL', 'size': '1310'}], 'event_type': 'price_change', 'hash': '80a415514c1a8aef7d8b87b179a12351a2ec6cdf', 'market': '0x7aa4a910b31b2c4ddb09d1e3408e52aa8e09a14402f376070a44b1b85cb36d13', 'timestamp': '1733334505583'}
{'asset_id': '114416409796971863099144323163249651172534872992222856507897414949637892047507', 'changes': [{'price': '0.48', 'side': 'BUY', 'size': '2742.18'}, {'price': '0.54', 'side': 'BUY', 'size': '131.19'}, {'price': '0.59', 'side': 'SELL', 'size': '1310'}], 'event_type': 'price_change', 'hash': '80a415514c1a8aef7d8b87b179a12351a2ec6cdf', 'market': '0x7aa4a910b31b2c4ddb09d1e3408e52aa8e09a14402f376070a44b1b85cb36d13', 'timestamp': '1733334505583'}
{'asset_id': '114416409796971863099144323163249651172534872992222856507897414949637892047507', 'changes': [{'price': '0.53', 'side': 'BUY', 'size': '1118.99'}], 'event_type': 'price_change', 'hash': 'aafcd9eb1e79ffb594d646d789be4bf0c6f4aa1f', 'market': '0x7aa4a910b31b2c4ddb09d1e3408e52aa8e09a14402f376070a44b1b85cb36d13', 'timestamp': '1733334505948'}
{'asset_id': '114416409796971863099144323163249651172534872992222856507897414949637892047507', 'changes': [{'price': '0.53', 'side': 'BUY', 'size': '1118.99'}], 'event_type': 'price_change', 'hash': 'aafcd9eb1e79ffb594d646d789be4bf0c6f4aa1f', 'market': '0x7aa4a910b31b2c4ddb09d1e3408e52aa8e09a14402f376070a44b1b85cb36d13', 'timestamp': '1733334505948'}
{'asset_id': '114416409796971863099144323163249651172534872992222856507897414949637892047507', 'changes': [{'price': '0.48', 'side': 'BUY', 'size': '3242.18'}], 'event_type': 'price_change', 'hash': '34c15c2133d02ab9b5911d36bd983a883d0fcad3', 'market': '0x7aa4a910b31b2c4ddb09d1e3408e52aa8e09a14402f376070a44b1b85cb36d13', 'timestamp': '1733334506628'}
{'asset_id': '114416409796971863099144323163249651172534872992222856507897414949637892047507', 'changes': [{'price': '0.48', 'side': 'BUY', 'size': '3242.18'}], 'event_type': 'price_change', 'hash': '34c15c2133d02ab9b5911d36bd983a883d0fcad3', 'market': '0x7aa4a910b31b2c4ddb09d1e3408e52aa8e09a14402f376070a44b1b85cb36d13', 'timestamp': '1733334506628'}
{'asset_id': '114416409796971863099144323163249651172534872992222856507897414949637892047507', 'changes': [{'price': '0.58', 'side': 'SELL', 'size': '2160.57'}], 'event_type': 'price_change', 'hash': '2c9f67c9038eed5239ff4a82786d64fed4762903', 'market': '0x7aa4a910b31b2c4ddb09d1e3408e52aa8e09a14402f376070a44b1b85cb36d13', 'timestamp': '1733334507001'}
{'asset_id': '114416409796971863099144323163249651172534872992222856507897414949637892047507', 'changes': [{'price': '0.58', 'side': 'SELL', 'size': '2160.57'}], 'event_type': 'price_change', 'hash': '2c9f67c9038eed5239ff4a82786d64fed4762903', 'market': '0x7aa4a910b31b2c4ddb09d1e3408e52aa8e09a14402f376070a44b1b85cb36d13', 'timestamp': '1733334507001'}
{'asset_id': '114416409796971863099144323163249651172534872992222856507897414949637892047507', 'changes': [{'price': '0.53', 'side': 'BUY', 'size': '2118.99'}], 'event_type': 'price_change', 'hash': '8a6aeb23da6b49ddc8fe64b310a901d14e7d6b18', 'market': '0x7aa4a910b31b2c4ddb09d1e3408e52aa8e09a14402f376070a44b1b85cb36d13', 'timestamp': '1733334507399'}
{'asset_id': '114416409796971863099144323163249651172534872992222856507897414949637892047507', 'changes': [{'price': '0.53', 'side': 'BUY', 'size': '2118.99'}], 'event_type': 'price_change', 'hash': '8a6aeb23da6b49ddc8fe64b310a901d14e7d6b18', 'market': '0x7aa4a910b31b2c4ddb09d1e3408e52aa8e09a14402f376070a44b1b85cb36d13', 'timestamp': '1733334507399'}
{'asset_id': '114416409796971863099144323163249651172534872992222856507897414949637892047507', 'changes': [{'price': '0.59', 'side': 'SELL', 'size': '110'}], 'event_type': 'price_change', 'hash': '17214dbc84f8de29801d613ee6541f37359ffc65', 'market': '0x7aa4a910b31b2c4ddb09d1e3408e52aa8e09a14402f376070a44b1b85cb36d13', 'timestamp': '1733334509007'}
{'asset_id': '114416409796971863099144323163249651172534872992222856507897414949637892047507', 'changes': [{'price': '0.59', 'side': 'SELL', 'size': '110'}], 'event_type': 'price_change', 'hash': '17214dbc84f8de29801d613ee6541f37359ffc65', 'market': '0x7aa4a910b31b2c4ddb09d1e3408e52aa8e09a14402f376070a44b1b85cb36d13', 'timestamp': '1733334509007'}
{'asset_id': '114416409796971863099144323163249651172534872992222856507897414949637892047507', 'changes': [{'price': '0.24', 'side': 'BUY', 'size': '27'}], 'event_type': 'price_change', 'hash': '3cf023fb50220b8824e5114cfb0c13fd5e753a46', 'market': '0x7aa4a910b31b2c4ddb09d1e3408e52aa8e09a14402f376070a44b1b85cb36d13', 'timestamp': '1733334511010'}
{'asset_id': '114416409796971863099144323163249651172534872992222856507897414949637892047507', 'changes': [{'price': '0.24', 'side': 'BUY', 'size': '27'}], 'event_type': 'price_change', 'hash': '3cf023fb50220b8824e5114cfb0c13fd5e753a46', 'market': '0x7aa4a910b31b2c4ddb09d1e3408e52aa8e09a14402f376070a44b1b85cb36d13', 'timestamp': '1733334511010'}
{'asset_id': '114416409796971863099144323163249651172534872992222856507897414949637892047507', 'changes': [{'price': '0.6', 'side': 'SELL', 'size': '5307.85'}], 'event_type': 'price_change', 'hash': '9e1ce753653171f38184e47ee0e59d6284872496', 'market': '0x7aa4a910b31b2c4ddb09d1e3408e52aa8e09a14402f376070a44b1b85cb36d13', 'timestamp': '1733334511339'}
{'asset_id': '114416409796971863099144323163249651172534872992222856507897414949637892047507', 'changes': [{'price': '0.6', 'side': 'SELL', 'size': '5307.85'}], 'event_type': 'price_change', 'hash': '9e1ce753653171f38184e47ee0e59d6284872496', 'market': '0x7aa4a910b31b2c4ddb09d1e3408e52aa8e09a14402f376070a44b1b85cb36d13', 'timestamp': '1733334511339'}
{'asset_id': '114416409796971863099144323163249651172534872992222856507897414949637892047507', 'changes': [{'price': '0.53', 'side': 'BUY', 'size': '2218.99'}], 'event_type': 'price_change', 'hash': '98aa4416fddaa22262368b3ad680a9088727122b', 'market': '0x7aa4a910b31b2c4ddb09d1e3408e52aa8e09a14402f376070a44b1b85cb36d13', 'timestamp': '1733334512377'}
{'asset_id': '114416409796971863099144323163249651172534872992222856507897414949637892047507', 'changes': [{'price': '0.53', 'side': 'BUY', 'size': '2218.99'}], 'event_type': 'price_change', 'hash': '98aa4416fddaa22262368b3ad680a9088727122b', 'market': '0x7aa4a910b31b2c4ddb09d1e3408e52aa8e09a14402f376070a44b1b85cb36d13', 'timestamp': '1733334512377'}
{'asset_id': '114416409796971863099144323163249651172534872992222856507897414949637892047507', 'changes': [{'price': '0.6', 'side': 'SELL', 'size': '5067.85'}, {'price': '0.52', 'side': 'BUY', 'size': '2085.92'}], 'event_type': 'price_change', 'hash': '0884168fce7d004f89cf335f9522986fb692f7fc', 'market': '0x7aa4a910b31b2c4ddb09d1e3408e52aa8e09a14402f376070a44b1b85cb36d13', 'timestamp': '1733334512805'}
{'asset_id': '114416409796971863099144323163249651172534872992222856507897414949637892047507', 'changes': [{'price': '0.6', 'side': 'SELL', 'size': '5067.85'}, {'price': '0.52', 'side': 'BUY', 'size': '2085.92'}], 'event_type': 'price_change', 'hash': '0884168fce7d004f89cf335f9522986fb692f7fc', 'market': '0x7aa4a910b31b2c4ddb09d1e3408e52aa8e09a14402f376070a44b1b85cb36d13', 'timestamp': '1733334512805'}
{'asset_id': '114416409796971863099144323163249651172534872992222856507897414949637892047507', 'changes': [{'price': '0.61', 'side': 'SELL', 'size': '891.06'}], 'event_type': 'price_change', 'hash': '645de01177ad919837820b376967c0afe3e76aee', 'market': '0x7aa4a910b31b2c4ddb09d1e3408e52aa8e09a14402f376070a44b1b85cb36d13', 'timestamp': '1733334513063'}
{'asset_id': '114416409796971863099144323163249651172534872992222856507897414949637892047507', 'changes': [{'price': '0.61', 'side': 'SELL', 'size': '891.06'}], 'event_type': 'price_change', 'hash': '645de01177ad919837820b376967c0afe3e76aee', 'market': '0x7aa4a910b31b2c4ddb09d1e3408e52aa8e09a14402f376070a44b1b85cb36d13', 'timestamp': '1733334513063'}
{'asset_id': '114416409796971863099144323163249651172534872992222856507897414949637892047507', 'changes': [{'price': '0.52', 'side': 'BUY', 'size': '2315.92'}], 'event_type': 'price_change', 'hash': 'ca803b8589cac085a3119d053b4bd2b92dd4f4e5', 'market': '0x7aa4a910b31b2c4ddb09d1e3408e52aa8e09a14402f376070a44b1b85cb36d13', 'timestamp': '1733334513310'}
{'asset_id': '114416409796971863099144323163249651172534872992222856507897414949637892047507', 'changes': [{'price': '0.52', 'side': 'BUY', 'size': '2315.92'}], 'event_type': 'price_change', 'hash': 'ca803b8589cac085a3119d053b4bd2b92dd4f4e5', 'market': '0x7aa4a910b31b2c4ddb09d1e3408e52aa8e09a14402f376070a44b1b85cb36d13', 'timestamp': '1733334513310'}
{'asset_id': '114416409796971863099144323163249651172534872992222856507897414949637892047507', 'changes': [{'price': '0.48', 'side': 'BUY', 'size': '2742.18'}], 'event_type': 'price_change', 'hash': '9be739291f103a561e85016add8941b003b83894', 'market': '0x7aa4a910b31b2c4ddb09d1e3408e52aa8e09a14402f376070a44b1b85cb36d13', 'timestamp': '1733334513893'}
{'asset_id': '114416409796971863099144323163249651172534872992222856507897414949637892047507', 'changes': [{'price': '0.48', 'side': 'BUY', 'size': '2742.18'}], 'event_type': 'price_change', 'hash': '9be739291f103a561e85016add8941b003b83894', 'market': '0x7aa4a910b31b2c4ddb09d1e3408e52aa8e09a14402f376070a44b1b85cb36d13', 'timestamp': '1733334513893'}
{'asset_id': '114416409796971863099144323163249651172534872992222856507897414949637892047507', 'changes': [{'price': '0.58', 'side': 'SELL', 'size': '1660.57'}, {'price': '0.53', 'side': 'BUY', 'size': '1218.99'}], 'event_type': 'price_change', 'hash': 'ed9753f7c451e43a8236295cae8aa588e22f6ccb', 'market': '0x7aa4a910b31b2c4ddb09d1e3408e52aa8e09a14402f376070a44b1b85cb36d13', 'timestamp': '1733334513903'}
{'asset_id': '114416409796971863099144323163249651172534872992222856507897414949637892047507', 'changes': [{'price': '0.58', 'side': 'SELL', 'size': '1660.57'}, {'price': '0.53', 'side': 'BUY', 'size': '1218.99'}], 'event_type': 'price_change', 'hash': 'ed9753f7c451e43a8236295cae8aa588e22f6ccb', 'market': '0x7aa4a910b31b2c4ddb09d1e3408e52aa8e09a14402f376070a44b1b85cb36d13', 'timestamp': '1733334513903'}
{'asset_id': '114416409796971863099144323163249651172534872992222856507897414949637892047507', 'changes': [{'price': '0.47', 'side': 'BUY', 'size': '797.23'}], 'event_type': 'price_change', 'hash': 'd616e625df2c79fd1b062e62cd12722904f5d846', 'market': '0x7aa4a910b31b2c4ddb09d1e3408e52aa8e09a14402f376070a44b1b85cb36d13', 'timestamp': '1733334515028'}
{'asset_id': '114416409796971863099144323163249651172534872992222856507897414949637892047507', 'changes': [{'price': '0.47', 'side': 'BUY', 'size': '797.23'}], 'event_type': 'price_change', 'hash': 'd616e625df2c79fd1b062e62cd12722904f5d846', 'market': '0x7aa4a910b31b2c4ddb09d1e3408e52aa8e09a14402f376070a44b1b85cb36d13', 'timestamp': '1733334515028'}
{'asset_id': '114416409796971863099144323163249651172534872992222856507897414949637892047507', 'changes': [{'price': '0.57', 'side': 'SELL', 'size': '510.1'}], 'event_type': 'price_change', 'hash': 'fa4aaa992679aa44c5279e98721fcd51fc7d46a4', 'market': '0x7aa4a910b31b2c4ddb09d1e3408e52aa8e09a14402f376070a44b1b85cb36d13', 'timestamp': '1733334515395'}
{'asset_id': '114416409796971863099144323163249651172534872992222856507897414949637892047507', 'changes': [{'price': '0.57', 'side': 'SELL', 'size': '510.1'}], 'event_type': 'price_change', 'hash': 'fa4aaa992679aa44c5279e98721fcd51fc7d46a4', 'market': '0x7aa4a910b31b2c4ddb09d1e3408e52aa8e09a14402f376070a44b1b85cb36d13', 'timestamp': '1733334515395'}
{'asset_id': '114416409796971863099144323163249651172534872992222856507897414949637892047507', 'changes': [{'price': '0.53', 'side': 'BUY', 'size': '2218.99'}], 'event_type': 'price_change', 'hash': '37e1048ec9579175a43791552718a9d6e083b978', 'market': '0x7aa4a910b31b2c4ddb09d1e3408e52aa8e09a14402f376070a44b1b85cb36d13', 'timestamp': '1733334515782'}
{'asset_id': '114416409796971863099144323163249651172534872992222856507897414949637892047507', 'changes': [{'price': '0.53', 'side': 'BUY', 'size': '2218.99'}], 'event_type': 'price_change', 'hash': '37e1048ec9579175a43791552718a9d6e083b978', 'market': '0x7aa4a910b31b2c4ddb09d1e3408e52aa8e09a14402f376070a44b1b85cb36d13', 'timestamp': '1733334515782'}
{'asset_id': '114416409796971863099144323163249651172534872992222856507897414949637892047507', 'changes': [{'price': '0.27', 'side': 'BUY', 'size': '5215.25'}], 'event_type': 'price_change', 'hash': 'be4f23cc225d78cd6f44bf758775b08a8d6a894c', 'market': '0x7aa4a910b31b2c4ddb09d1e3408e52aa8e09a14402f376070a44b1b85cb36d13', 'timestamp': '1733334519438'}
{'asset_id': '114416409796971863099144323163249651172534872992222856507897414949637892047507', 'changes': [{'price': '0.27', 'side': 'BUY', 'size': '5215.25'}], 'event_type': 'price_change', 'hash': 'be4f23cc225d78cd6f44bf758775b08a8d6a894c', 'market': '0x7aa4a910b31b2c4ddb09d1e3408e52aa8e09a14402f376070a44b1b85cb36d13', 'timestamp': '1733334519438'}
{'asset_id': '114416409796971863099144323163249651172534872992222856507897414949637892047507', 'changes': [{'price': '0.47', 'side': 'BUY', 'size': '297.23'}, {'price': '0.57', 'side': 'SELL', 'size': '10.1'}, {'price': '0.53', 'side': 'BUY', 'size': '1218.99'}], 'event_type': 'price_change', 'hash': 'e6f140d6a195f07f9ba93eea5194f443b529ca06', 'market': '0x7aa4a910b31b2c4ddb09d1e3408e52aa8e09a14402f376070a44b1b85cb36d13', 'timestamp': '1733334522357'}
{'asset_id': '114416409796971863099144323163249651172534872992222856507897414949637892047507', 'changes': [{'price': '0.47', 'side': 'BUY', 'size': '297.23'}, {'price': '0.57', 'side': 'SELL', 'size': '10.1'}, {'price': '0.53', 'side': 'BUY', 'size': '1218.99'}], 'event_type': 'price_change', 'hash': 'e6f140d6a195f07f9ba93eea5194f443b529ca06', 'market': '0x7aa4a910b31b2c4ddb09d1e3408e52aa8e09a14402f376070a44b1b85cb36d13', 'timestamp': '1733334522357'}
{'asset_id': '114416409796971863099144323163249651172534872992222856507897414949637892047507', 'changes': [{'price': '0.55', 'side': 'BUY', 'size': '3561.77'}], 'event_type': 'price_change', 'hash': 'afdb76d2dfade60238ac046fd2f3576dd8eb6ab2', 'market': '0x7aa4a910b31b2c4ddb09d1e3408e52aa8e09a14402f376070a44b1b85cb36d13', 'timestamp': '1733334522791'}
{'asset_id': '114416409796971863099144323163249651172534872992222856507897414949637892047507', 'changes': [{'price': '0.55', 'side': 'BUY', 'size': '3561.77'}], 'event_type': 'price_change', 'hash': 'afdb76d2dfade60238ac046fd2f3576dd8eb6ab2', 'market': '0x7aa4a910b31b2c4ddb09d1e3408e52aa8e09a14402f376070a44b1b85cb36d13', 'timestamp': '1733334522791'}
{'asset_id': '114416409796971863099144323163249651172534872992222856507897414949637892047507', 'changes': [{'price': '0.48', 'side': 'BUY', 'size': '3242.18'}], 'event_type': 'price_change', 'hash': '68cc20b8d78b95e2129f4a6350011874315ee0b2', 'market': '0x7aa4a910b31b2c4ddb09d1e3408e52aa8e09a14402f376070a44b1b85cb36d13', 'timestamp': '1733334523424'}
{'asset_id': '114416409796971863099144323163249651172534872992222856507897414949637892047507', 'changes': [{'price': '0.48', 'side': 'BUY', 'size': '3242.18'}], 'event_type': 'price_change', 'hash': '68cc20b8d78b95e2129f4a6350011874315ee0b2', 'market': '0x7aa4a910b31b2c4ddb09d1e3408e52aa8e09a14402f376070a44b1b85cb36d13', 'timestamp': '1733334523424'}
{'asset_id': '114416409796971863099144323163249651172534872992222856507897414949637892047507', 'changes': [{'price': '0.59', 'side': 'SELL', 'size': '610'}], 'event_type': 'price_change', 'hash': 'b0f2c5df2fe18297c2d808742dd70167d6d60842', 'market': '0x7aa4a910b31b2c4ddb09d1e3408e52aa8e09a14402f376070a44b1b85cb36d13', 'timestamp': '1733334523826'}
{'asset_id': '114416409796971863099144323163249651172534872992222856507897414949637892047507', 'changes': [{'price': '0.59', 'side': 'SELL', 'size': '610'}], 'event_type': 'price_change', 'hash': 'b0f2c5df2fe18297c2d808742dd70167d6d60842', 'market': '0x7aa4a910b31b2c4ddb09d1e3408e52aa8e09a14402f376070a44b1b85cb36d13', 'timestamp': '1733334523826'}
{'asset_id': '114416409796971863099144323163249651172534872992222856507897414949637892047507', 'changes': [{'price': '0.54', 'side': 'BUY', 'size': '1131.19'}], 'event_type': 'price_change', 'hash': '28134111c319938ab8f2a240b8bd7bf1f069efd8', 'market': '0x7aa4a910b31b2c4ddb09d1e3408e52aa8e09a14402f376070a44b1b85cb36d13', 'timestamp': '1733334524189'}
{'asset_id': '114416409796971863099144323163249651172534872992222856507897414949637892047507', 'changes': [{'price': '0.54', 'side': 'BUY', 'size': '1131.19'}], 'event_type': 'price_change', 'hash': '28134111c319938ab8f2a240b8bd7bf1f069efd8', 'market': '0x7aa4a910b31b2c4ddb09d1e3408e52aa8e09a14402f376070a44b1b85cb36d13', 'timestamp': '1733334524189'}
{'asset_id': '114416409796971863099144323163249651172534872992222856507897414949637892047507', 'changes': [{'price': '0.53', 'side': 'BUY', 'size': '1118.99'}], 'event_type': 'price_change', 'hash': '20fed1420160c8a024894bbd313ed6144e1335c2', 'market': '0x7aa4a910b31b2c4ddb09d1e3408e52aa8e09a14402f376070a44b1b85cb36d13', 'timestamp': '1733334524864'}
{'asset_id': '114416409796971863099144323163249651172534872992222856507897414949637892047507', 'changes': [{'price': '0.53', 'side': 'BUY', 'size': '1118.99'}], 'event_type': 'price_change', 'hash': '20fed1420160c8a024894bbd313ed6144e1335c2', 'market': '0x7aa4a910b31b2c4ddb09d1e3408e52aa8e09a14402f376070a44b1b85cb36d13', 'timestamp': '1733334524864'}
{'asset_id': '114416409796971863099144323163249651172534872992222856507897414949637892047507', 'changes': [{'price': '0.54', 'side': 'BUY', 'size': '1231.19'}], 'event_type': 'price_change', 'hash': 'fd886b148973f1656d89150879865a7a50deecd7', 'market': '0x7aa4a910b31b2c4ddb09d1e3408e52aa8e09a14402f376070a44b1b85cb36d13', 'timestamp': '1733334525733'}
{'asset_id': '114416409796971863099144323163249651172534872992222856507897414949637892047507', 'changes': [{'price': '0.54', 'side': 'BUY', 'size': '1231.19'}], 'event_type': 'price_change', 'hash': 'fd886b148973f1656d89150879865a7a50deecd7', 'market': '0x7aa4a910b31b2c4ddb09d1e3408e52aa8e09a14402f376070a44b1b85cb36d13', 'timestamp': '1733334525733'}
{'asset_id': '114416409796971863099144323163249651172534872992222856507897414949637892047507', 'changes': [{'price': '0.55', 'side': 'BUY', 'size': '3576.77'}], 'event_type': 'price_change', 'hash': '891cd5acf04d69cd7aed0d81be314796134797b3', 'market': '0x7aa4a910b31b2c4ddb09d1e3408e52aa8e09a14402f376070a44b1b85cb36d13', 'timestamp': '1733334526416'}
{'asset_id': '114416409796971863099144323163249651172534872992222856507897414949637892047507', 'changes': [{'price': '0.55', 'side': 'BUY', 'size': '3576.77'}], 'event_type': 'price_change', 'hash': '891cd5acf04d69cd7aed0d81be314796134797b3', 'market': '0x7aa4a910b31b2c4ddb09d1e3408e52aa8e09a14402f376070a44b1b85cb36d13', 'timestamp': '1733334526416'}
{'asset_id': '114416409796971863099144323163249651172534872992222856507897414949637892047507', 'changes': [{'price': '0.6', 'side': 'SELL', 'size': '2567.85'}, {'price': '0.58', 'side': 'SELL', 'size': '160.57'}, {'price': '0.52', 'side': 'BUY', 'size': '1115.92'}, {'price': '0.51', 'side': 'BUY', 'size': '1086.18'}, {'price': '0.42', 'side': 'BUY', 'size': '50'}], 'event_type': 'price_change', 'hash': '1d1a6396051d0408356160ec4bab517199f6d279', 'market': '0x7aa4a910b31b2c4ddb09d1e3408e52aa8e09a14402f376070a44b1b85cb36d13', 'timestamp': '1733334529591'}
{'asset_id': '114416409796971863099144323163249651172534872992222856507897414949637892047507', 'changes': [{'price': '0.6', 'side': 'SELL', 'size': '2567.85'}, {'price': '0.58', 'side': 'SELL', 'size': '160.57'}, {'price': '0.52', 'side': 'BUY', 'size': '1115.92'}, {'price': '0.51', 'side': 'BUY', 'size': '1086.18'}, {'price': '0.42', 'side': 'BUY', 'size': '50'}], 'event_type': 'price_change', 'hash': '1d1a6396051d0408356160ec4bab517199f6d279', 'market': '0x7aa4a910b31b2c4ddb09d1e3408e52aa8e09a14402f376070a44b1b85cb36d13', 'timestamp': '1733334529591'}
{'asset_id': '114416409796971863099144323163249651172534872992222856507897414949637892047507', 'changes': [{'price': '0.48', 'side': 'BUY', 'size': '2742.18'}, {'price': '0.59', 'side': 'SELL', 'size': '110'}, {'price': '0.54', 'side': 'BUY', 'size': '231.19'}], 'event_type': 'price_change', 'hash': 'd53bec60bc3c133813d0bb133ac3d01460f237ac', 'market': '0x7aa4a910b31b2c4ddb09d1e3408e52aa8e09a14402f376070a44b1b85cb36d13', 'timestamp': '1733334530602'}
{'asset_id': '114416409796971863099144323163249651172534872992222856507897414949637892047507', 'changes': [{'price': '0.48', 'side': 'BUY', 'size': '2742.18'}, {'price': '0.59', 'side': 'SELL', 'size': '110'}, {'price': '0.54', 'side': 'BUY', 'size': '231.19'}], 'event_type': 'price_change', 'hash': 'd53bec60bc3c133813d0bb133ac3d01460f237ac', 'market': '0x7aa4a910b31b2c4ddb09d1e3408e52aa8e09a14402f376070a44b1b85cb36d13', 'timestamp': '1733334530602'}
{'asset_id': '114416409796971863099144323163249651172534872992222856507897414949637892047507', 'changes': [{'price': '0.49', 'side': 'BUY', 'size': '540'}], 'event_type': 'price_change', 'hash': 'd029d6510643b4434f27504ff0ccadf117198030', 'market': '0x7aa4a910b31b2c4ddb09d1e3408e52aa8e09a14402f376070a44b1b85cb36d13', 'timestamp': '1733334531690'}
{'asset_id': '114416409796971863099144323163249651172534872992222856507897414949637892047507', 'changes': [{'price': '0.49', 'side': 'BUY', 'size': '540'}], 'event_type': 'price_change', 'hash': 'd029d6510643b4434f27504ff0ccadf117198030', 'market': '0x7aa4a910b31b2c4ddb09d1e3408e52aa8e09a14402f376070a44b1b85cb36d13', 'timestamp': '1733334531690'}
{'asset_id': '114416409796971863099144323163249651172534872992222856507897414949637892047507', 'changes': [{'price': '0.59', 'side': 'SELL', 'size': '610'}], 'event_type': 'price_change', 'hash': 'cc1cdc6c882f1b1bcec0136d290da4b9d03f3abe', 'market': '0x7aa4a910b31b2c4ddb09d1e3408e52aa8e09a14402f376070a44b1b85cb36d13', 'timestamp': '1733334532067'}
{'asset_id': '114416409796971863099144323163249651172534872992222856507897414949637892047507', 'changes': [{'price': '0.59', 'side': 'SELL', 'size': '610'}], 'event_type': 'price_change', 'hash': 'cc1cdc6c882f1b1bcec0136d290da4b9d03f3abe', 'market': '0x7aa4a910b31b2c4ddb09d1e3408e52aa8e09a14402f376070a44b1b85cb36d13', 'timestamp': '1733334532067'}
{'asset_id': '114416409796971863099144323163249651172534872992222856507897414949637892047507', 'changes': [{'price': '0.55', 'side': 'BUY', 'size': '4576.77'}], 'event_type': 'price_change', 'hash': '4c06f9a77ad29923e47147a90027c481d49e8fc4', 'market': '0x7aa4a910b31b2c4ddb09d1e3408e52aa8e09a14402f376070a44b1b85cb36d13', 'timestamp': '1733334532438'}
{'asset_id': '114416409796971863099144323163249651172534872992222856507897414949637892047507', 'changes': [{'price': '0.55', 'side': 'BUY', 'size': '4576.77'}], 'event_type': 'price_change', 'hash': '4c06f9a77ad29923e47147a90027c481d49e8fc4', 'market': '0x7aa4a910b31b2c4ddb09d1e3408e52aa8e09a14402f376070a44b1b85cb36d13', 'timestamp': '1733334532438'}
{'asset_id': '114416409796971863099144323163249651172534872992222856507897414949637892047507', 'changes': [{'price': '0.61', 'side': 'SELL', 'size': '2391.06'}, {'price': '0.52', 'side': 'BUY', 'size': '2615.92'}], 'event_type': 'price_change', 'hash': 'b456792fece419862247de6fd24e283cccedfbee', 'market': '0x7aa4a910b31b2c4ddb09d1e3408e52aa8e09a14402f376070a44b1b85cb36d13', 'timestamp': '1733334538313'}
{'asset_id': '114416409796971863099144323163249651172534872992222856507897414949637892047507', 'changes': [{'price': '0.61', 'side': 'SELL', 'size': '2391.06'}, {'price': '0.52', 'side': 'BUY', 'size': '2615.92'}], 'event_type': 'price_change', 'hash': 'b456792fece419862247de6fd24e283cccedfbee', 'market': '0x7aa4a910b31b2c4ddb09d1e3408e52aa8e09a14402f376070a44b1b85cb36d13', 'timestamp': '1733334538313'}
{'asset_id': '114416409796971863099144323163249651172534872992222856507897414949637892047507', 'changes': [{'price': '0.45', 'side': 'BUY', 'size': '3478'}], 'event_type': 'price_change', 'hash': 'c91402472fb2148cf15c9f9d90aadc8a399a96c4', 'market': '0x7aa4a910b31b2c4ddb09d1e3408e52aa8e09a14402f376070a44b1b85cb36d13', 'timestamp': '1733334538321'}
{'asset_id': '114416409796971863099144323163249651172534872992222856507897414949637892047507', 'changes': [{'price': '0.45', 'side': 'BUY', 'size': '3478'}], 'event_type': 'price_change', 'hash': 'c91402472fb2148cf15c9f9d90aadc8a399a96c4', 'market': '0x7aa4a910b31b2c4ddb09d1e3408e52aa8e09a14402f376070a44b1b85cb36d13', 'timestamp': '1733334538321'}
{'asset_id': '114416409796971863099144323163249651172534872992222856507897414949637892047507', 'changes': [{'price': '0.63', 'side': 'SELL', 'size': '2710.1'}], 'event_type': 'price_change', 'hash': '9e55cfad809fd96db3f58392f1fe85460a66f136', 'market': '0x7aa4a910b31b2c4ddb09d1e3408e52aa8e09a14402f376070a44b1b85cb36d13', 'timestamp': '1733334538541'}
{'asset_id': '114416409796971863099144323163249651172534872992222856507897414949637892047507', 'changes': [{'price': '0.63', 'side': 'SELL', 'size': '2710.1'}], 'event_type': 'price_change', 'hash': '9e55cfad809fd96db3f58392f1fe85460a66f136', 'market': '0x7aa4a910b31b2c4ddb09d1e3408e52aa8e09a14402f376070a44b1b85cb36d13', 'timestamp': '1733334538541'}
{'asset_id': '114416409796971863099144323163249651172534872992222856507897414949637892047507', 'changes': [{'price': '0.54', 'side': 'BUY', 'size': '131.19'}], 'event_type': 'price_change', 'hash': '60efb5dbebf75f064302b5f4fe8a015bf694eab7', 'market': '0x7aa4a910b31b2c4ddb09d1e3408e52aa8e09a14402f376070a44b1b85cb36d13', 'timestamp': '1733334548046'}
{'asset_id': '114416409796971863099144323163249651172534872992222856507897414949637892047507', 'changes': [{'price': '0.54', 'side': 'BUY', 'size': '131.19'}], 'event_type': 'price_change', 'hash': '60efb5dbebf75f064302b5f4fe8a015bf694eab7', 'market': '0x7aa4a910b31b2c4ddb09d1e3408e52aa8e09a14402f376070a44b1b85cb36d13', 'timestamp': '1733334548046'}
{'asset_id': '114416409796971863099144323163249651172534872992222856507897414949637892047507', 'changes': [{'price': '0.53', 'side': 'BUY', 'size': '1218.99'}], 'event_type': 'price_change', 'hash': '34376a44976da70afae77d140b3d680d3440760b', 'market': '0x7aa4a910b31b2c4ddb09d1e3408e52aa8e09a14402f376070a44b1b85cb36d13', 'timestamp': '1733334548967'}
{'asset_id': '114416409796971863099144323163249651172534872992222856507897414949637892047507', 'changes': [{'price': '0.53', 'side': 'BUY', 'size': '1218.99'}], 'event_type': 'price_change', 'hash': '34376a44976da70afae77d140b3d680d3440760b', 'market': '0x7aa4a910b31b2c4ddb09d1e3408e52aa8e09a14402f376070a44b1b85cb36d13', 'timestamp': '1733334548967'}
{'asset_id': '114416409796971863099144323163249651172534872992222856507897414949637892047507', 'changes': [{'price': '0.53', 'side': 'BUY', 'size': '1118.99'}], 'event_type': 'price_change', 'hash': '015a3e41080ef1b5a303798cccf1bfc325bea3dc', 'market': '0x7aa4a910b31b2c4ddb09d1e3408e52aa8e09a14402f376070a44b1b85cb36d13', 'timestamp': '1733334549613'}
{'asset_id': '114416409796971863099144323163249651172534872992222856507897414949637892047507', 'changes': [{'price': '0.53', 'side': 'BUY', 'size': '1118.99'}], 'event_type': 'price_change', 'hash': '015a3e41080ef1b5a303798cccf1bfc325bea3dc', 'market': '0x7aa4a910b31b2c4ddb09d1e3408e52aa8e09a14402f376070a44b1b85cb36d13', 'timestamp': '1733334549613'}
{'asset_id': '114416409796971863099144323163249651172534872992222856507897414949637892047507', 'changes': [{'price': '0.54', 'side': 'BUY', 'size': '231.19'}], 'event_type': 'price_change', 'hash': '77b6afb74a7d171ac1708da330b30a121ca5fa89', 'market': '0x7aa4a910b31b2c4ddb09d1e3408e52aa8e09a14402f376070a44b1b85cb36d13', 'timestamp': '1733334550526'}
{'asset_id': '114416409796971863099144323163249651172534872992222856507897414949637892047507', 'changes': [{'price': '0.54', 'side': 'BUY', 'size': '231.19'}], 'event_type': 'price_change', 'hash': '77b6afb74a7d171ac1708da330b30a121ca5fa89', 'market': '0x7aa4a910b31b2c4ddb09d1e3408e52aa8e09a14402f376070a44b1b85cb36d13', 'timestamp': '1733334550526'}
{'asset_id': '114416409796971863099144323163249651172534872992222856507897414949637892047507', 'changes': [{'price': '0.54', 'side': 'BUY', 'size': '131.19'}], 'event_type': 'price_change', 'hash': 'c523bf4e2eaee1d1c09db2ea7556f88c499c4761', 'market': '0x7aa4a910b31b2c4ddb09d1e3408e52aa8e09a14402f376070a44b1b85cb36d13', 'timestamp': '1733334551730'}
{'asset_id': '114416409796971863099144323163249651172534872992222856507897414949637892047507', 'changes': [{'price': '0.54', 'side': 'BUY', 'size': '131.19'}], 'event_type': 'price_change', 'hash': 'c523bf4e2eaee1d1c09db2ea7556f88c499c4761', 'market': '0x7aa4a910b31b2c4ddb09d1e3408e52aa8e09a14402f376070a44b1b85cb36d13', 'timestamp': '1733334551730'}
{'asset_id': '114416409796971863099144323163249651172534872992222856507897414949637892047507', 'changes': [{'price': '0.53', 'side': 'BUY', 'size': '1218.99'}], 'event_type': 'price_change', 'hash': '6f39cad832504868a336da206de495e205cd30f0', 'market': '0x7aa4a910b31b2c4ddb09d1e3408e52aa8e09a14402f376070a44b1b85cb36d13', 'timestamp': '1733334552512'}
{'asset_id': '114416409796971863099144323163249651172534872992222856507897414949637892047507', 'changes': [{'price': '0.53', 'side': 'BUY', 'size': '1218.99'}], 'event_type': 'price_change', 'hash': '6f39cad832504868a336da206de495e205cd30f0', 'market': '0x7aa4a910b31b2c4ddb09d1e3408e52aa8e09a14402f376070a44b1b85cb36d13', 'timestamp': '1733334552512'}
{'asset_id': '114416409796971863099144323163249651172534872992222856507897414949637892047507', 'changes': [{'price': '0.53', 'side': 'BUY', 'size': '1118.99'}], 'event_type': 'price_change', 'hash': 'a5b0879f08b510e4e2544bbd23b7cb43ed5fbbda', 'market': '0x7aa4a910b31b2c4ddb09d1e3408e52aa8e09a14402f376070a44b1b85cb36d13', 'timestamp': '1733334553245'}
{'asset_id': '114416409796971863099144323163249651172534872992222856507897414949637892047507', 'changes': [{'price': '0.53', 'side': 'BUY', 'size': '1118.99'}], 'event_type': 'price_change', 'hash': 'a5b0879f08b510e4e2544bbd23b7cb43ed5fbbda', 'market': '0x7aa4a910b31b2c4ddb09d1e3408e52aa8e09a14402f376070a44b1b85cb36d13', 'timestamp': '1733334553245'}
{'asset_id': '114416409796971863099144323163249651172534872992222856507897414949637892047507', 'changes': [{'price': '0.54', 'side': 'BUY', 'size': '231.19'}], 'event_type': 'price_change', 'hash': '3c117dce205b1f65816e32edfafa70bd9e09f2fd', 'market': '0x7aa4a910b31b2c4ddb09d1e3408e52aa8e09a14402f376070a44b1b85cb36d13', 'timestamp': '1733334554513'}
{'asset_id': '114416409796971863099144323163249651172534872992222856507897414949637892047507', 'changes': [{'price': '0.54', 'side': 'BUY', 'size': '231.19'}], 'event_type': 'price_change', 'hash': '3c117dce205b1f65816e32edfafa70bd9e09f2fd', 'market': '0x7aa4a910b31b2c4ddb09d1e3408e52aa8e09a14402f376070a44b1b85cb36d13', 'timestamp': '1733334554513'}
{'asset_id': '114416409796971863099144323163249651172534872992222856507897414949637892047507', 'changes': [{'price': '0.59', 'side': 'SELL', 'size': '1810'}, {'price': '0.53', 'side': 'BUY', 'size': '2318.99'}], 'event_type': 'price_change', 'hash': '0e2d0c1a7540e8062814138806097b24abed5207', 'market': '0x7aa4a910b31b2c4ddb09d1e3408e52aa8e09a14402f376070a44b1b85cb36d13', 'timestamp': '1733334565796'}
{'asset_id': '114416409796971863099144323163249651172534872992222856507897414949637892047507', 'changes': [{'price': '0.59', 'side': 'SELL', 'size': '1810'}, {'price': '0.53', 'side': 'BUY', 'size': '2318.99'}], 'event_type': 'price_change', 'hash': '0e2d0c1a7540e8062814138806097b24abed5207', 'market': '0x7aa4a910b31b2c4ddb09d1e3408e52aa8e09a14402f376070a44b1b85cb36d13', 'timestamp': '1733334565796'}
{'asks': [{'price': '0.99', 'size': '4217.01'}, {'price': '0.98', 'size': '505'}, {'price': '0.97', 'size': '511.03'}, {'price': '0.96', 'size': '300'}, {'price': '0.95', 'size': '657.12'}, {'price': '0.94', 'size': '300'}, {'price': '0.92', 'size': '20000.45'}, {'price': '0.91', 'size': '10406.3'}, {'price': '0.9', 'size': '4587.5'}, {'price': '0.89', 'size': '13017.18'}, {'price': '0.88', 'size': '200'}, {'price': '0.87', 'size': '3229'}, {'price': '0.86', 'size': '17.1'}, {'price': '0.85', 'size': '109.68'}, {'price': '0.84', 'size': '250'}, {'price': '0.83', 'size': '100'}, {'price': '0.82', 'size': '16029'}, {'price': '0.81', 'size': '45721.39'}, {'price': '0.8', 'size': '26531'}, {'price': '0.79', 'size': '7110'}, {'price': '0.78', 'size': '15350'}, {'price': '0.77', 'size': '67'}, {'price': '0.76', 'size': '200'}, {'price': '0.75', 'size': '13329.25'}, {'price': '0.74', 'size': '11370.7'}, {'price': '0.73', 'size': '5020.1'}, {'price': '0.72', 'size': '380.52'}, {'price': '0.71', 'size': '15073.2'}, {'price': '0.7', 'size': '5570.1'}, {'price': '0.69', 'size': '6088.6'}, {'price': '0.68', 'size': '6131.34'}, {'price': '0.67', 'size': '3010.1'}, {'price': '0.66', 'size': '510.1'}, {'price': '0.65', 'size': '1010.1'}, {'price': '0.64', 'size': '4230.1'}, {'price': '0.63', 'size': '2710.1'}, {'price': '0.62', 'size': '300.1'}, {'price': '0.61', 'size': '2391.06'}, {'price': '0.6', 'size': '2567.85'}, {'price': '0.59', 'size': '1810'}, {'price': '0.58', 'size': '160.57'}, {'price': '0.57', 'size': '10.1'}], 'asset_id': '114416409796971863099144323163249651172534872992222856507897414949637892047507', 'bids': [{'price': '0.01', 'size': '2850.27'}, {'price': '0.02', 'size': '500'}, {'price': '0.03', 'size': '500'}, {'price': '0.04', 'size': '300'}, {'price': '0.05', 'size': '320'}, {'price': '0.06', 'size': '300'}, {'price': '0.08', 'size': '250'}, {'price': '0.09', 'size': '300'}, {'price': '0.1', 'size': '6205'}, {'price': '0.12', 'size': '200'}, {'price': '0.13', 'size': '426.92'}, {'price': '0.14', 'size': '15'}, {'price': '0.15', 'size': '110'}, {'price': '0.16', 'size': '4709.51'}, {'price': '0.18', 'size': '19.13'}, {'price': '0.19', 'size': '120'}, {'price': '0.2', 'size': '691.17'}, {'price': '0.24', 'size': '27'}, {'price': '0.25', 'size': '86.66'}, {'price': '0.27', 'size': '5215.25'}, {'price': '0.29', 'size': '1102.28'}, {'price': '0.31', 'size': '1130.65'}, {'price': '0.32', 'size': '200'}, {'price': '0.33', 'size': '620'}, {'price': '0.35', 'size': '232'}, {'price': '0.37', 'size': '4000'}, {'price': '0.39', 'size': '10.5'}, {'price': '0.4', 'size': '3135'}, {'price': '0.41', 'size': '20'}, {'price': '0.42', 'size': '50'}, {'price': '0.43', 'size': '50'}, {'price': '0.44', 'size': '3660'}, {'price': '0.45', 'size': '3478'}, {'price': '0.47', 'size': '297.23'}, {'price': '0.48', 'size': '2742.18'}, {'price': '0.49', 'size': '540'}, {'price': '0.5', 'size': '2015'}, {'price': '0.51', 'size': '1086.18'}, {'price': '0.52', 'size': '2615.92'}, {'price': '0.53', 'size': '2318.99'}, {'price': '0.54', 'size': '231.19'}, {'price': '0.55', 'size': '4570.1'}], 'event_type': 'book', 'hash': '97109792bb5c56ad4b4ad56871b315a841f3f7af', 'market': '0x7aa4a910b31b2c4ddb09d1e3408e52aa8e09a14402f376070a44b1b85cb36d13', 'timestamp': '1733334568015'}
{'asks': [{'price': '0.99', 'size': '4217.01'}, {'price': '0.98', 'size': '505'}, {'price': '0.97', 'size': '511.03'}, {'price': '0.96', 'size': '300'}, {'price': '0.95', 'size': '657.12'}, {'price': '0.94', 'size': '300'}, {'price': '0.92', 'size': '20000.45'}, {'price': '0.91', 'size': '10406.3'}, {'price': '0.9', 'size': '4587.5'}, {'price': '0.89', 'size': '13017.18'}, {'price': '0.88', 'size': '200'}, {'price': '0.87', 'size': '3229'}, {'price': '0.86', 'size': '17.1'}, {'price': '0.85', 'size': '109.68'}, {'price': '0.84', 'size': '250'}, {'price': '0.83', 'size': '100'}, {'price': '0.82', 'size': '16029'}, {'price': '0.81', 'size': '45721.39'}, {'price': '0.8', 'size': '26531'}, {'price': '0.79', 'size': '7110'}, {'price': '0.78', 'size': '15350'}, {'price': '0.77', 'size': '67'}, {'price': '0.76', 'size': '200'}, {'price': '0.75', 'size': '13329.25'}, {'price': '0.74', 'size': '11370.7'}, {'price': '0.73', 'size': '5020.1'}, {'price': '0.72', 'size': '380.52'}, {'price': '0.71', 'size': '15073.2'}, {'price': '0.7', 'size': '5570.1'}, {'price': '0.69', 'size': '6088.6'}, {'price': '0.68', 'size': '6131.34'}, {'price': '0.67', 'size': '3010.1'}, {'price': '0.66', 'size': '510.1'}, {'price': '0.65', 'size': '1010.1'}, {'price': '0.64', 'size': '4230.1'}, {'price': '0.63', 'size': '2710.1'}, {'price': '0.62', 'size': '300.1'}, {'price': '0.61', 'size': '2391.06'}, {'price': '0.6', 'size': '2567.85'}, {'price': '0.59', 'size': '1810'}, {'price': '0.58', 'size': '160.57'}, {'price': '0.57', 'size': '10.1'}], 'asset_id': '114416409796971863099144323163249651172534872992222856507897414949637892047507', 'bids': [{'price': '0.01', 'size': '2850.27'}, {'price': '0.02', 'size': '500'}, {'price': '0.03', 'size': '500'}, {'price': '0.04', 'size': '300'}, {'price': '0.05', 'size': '320'}, {'price': '0.06', 'size': '300'}, {'price': '0.08', 'size': '250'}, {'price': '0.09', 'size': '300'}, {'price': '0.1', 'size': '6205'}, {'price': '0.12', 'size': '200'}, {'price': '0.13', 'size': '426.92'}, {'price': '0.14', 'size': '15'}, {'price': '0.15', 'size': '110'}, {'price': '0.16', 'size': '4709.51'}, {'price': '0.18', 'size': '19.13'}, {'price': '0.19', 'size': '120'}, {'price': '0.2', 'size': '691.17'}, {'price': '0.24', 'size': '27'}, {'price': '0.25', 'size': '86.66'}, {'price': '0.27', 'size': '5215.25'}, {'price': '0.29', 'size': '1102.28'}, {'price': '0.31', 'size': '1130.65'}, {'price': '0.32', 'size': '200'}, {'price': '0.33', 'size': '620'}, {'price': '0.35', 'size': '232'}, {'price': '0.37', 'size': '4000'}, {'price': '0.39', 'size': '10.5'}, {'price': '0.4', 'size': '3135'}, {'price': '0.41', 'size': '20'}, {'price': '0.42', 'size': '50'}, {'price': '0.43', 'size': '50'}, {'price': '0.44', 'size': '3660'}, {'price': '0.45', 'size': '3478'}, {'price': '0.47', 'size': '297.23'}, {'price': '0.48', 'size': '2742.18'}, {'price': '0.49', 'size': '540'}, {'price': '0.5', 'size': '2015'}, {'price': '0.51', 'size': '1086.18'}, {'price': '0.52', 'size': '2615.92'}, {'price': '0.53', 'size': '2318.99'}, {'price': '0.54', 'size': '231.19'}, {'price': '0.55', 'size': '4570.1'}], 'event_type': 'book', 'hash': '97109792bb5c56ad4b4ad56871b315a841f3f7af', 'market': '0x7aa4a910b31b2c4ddb09d1e3408e52aa8e09a14402f376070a44b1b85cb36d13', 'timestamp': '1733334568015'}
{'asset_id': '114416409796971863099144323163249651172534872992222856507897414949637892047507', 'changes': [{'price': '0.54', 'side': 'BUY', 'size': '131.19'}], 'event_type': 'price_change', 'hash': 'd390537a13a1f7f8eec9ebe55b587d1b3755c886', 'market': '0x7aa4a910b31b2c4ddb09d1e3408e52aa8e09a14402f376070a44b1b85cb36d13', 'timestamp': '1733334576482'}
{'asset_id': '114416409796971863099144323163249651172534872992222856507897414949637892047507', 'changes': [{'price': '0.54', 'side': 'BUY', 'size': '131.19'}], 'event_type': 'price_change', 'hash': 'd390537a13a1f7f8eec9ebe55b587d1b3755c886', 'market': '0x7aa4a910b31b2c4ddb09d1e3408e52aa8e09a14402f376070a44b1b85cb36d13', 'timestamp': '1733334576482'}
{'asset_id': '114416409796971863099144323163249651172534872992222856507897414949637892047507', 'changes': [{'price': '0.5', 'side': 'BUY', 'size': '15'}], 'event_type': 'price_change', 'hash': 'c4885c1fafe1bb228adf458ef215619f3c383a80', 'market': '0x7aa4a910b31b2c4ddb09d1e3408e52aa8e09a14402f376070a44b1b85cb36d13', 'timestamp': '1733334576544'}
{'asset_id': '114416409796971863099144323163249651172534872992222856507897414949637892047507', 'changes': [{'price': '0.5', 'side': 'BUY', 'size': '15'}], 'event_type': 'price_change', 'hash': 'c4885c1fafe1bb228adf458ef215619f3c383a80', 'market': '0x7aa4a910b31b2c4ddb09d1e3408e52aa8e09a14402f376070a44b1b85cb36d13', 'timestamp': '1733334576544'}
{'asset_id': '114416409796971863099144323163249651172534872992222856507897414949637892047507', 'changes': [{'price': '0.51', 'side': 'BUY', 'size': '3086.18'}], 'event_type': 'price_change', 'hash': '3af5b3df1008557f33771a93ec18afa2de07981a', 'market': '0x7aa4a910b31b2c4ddb09d1e3408e52aa8e09a14402f376070a44b1b85cb36d13', 'timestamp': '1733334576989'}
{'asset_id': '114416409796971863099144323163249651172534872992222856507897414949637892047507', 'changes': [{'price': '0.51', 'side': 'BUY', 'size': '3086.18'}], 'event_type': 'price_change', 'hash': '3af5b3df1008557f33771a93ec18afa2de07981a', 'market': '0x7aa4a910b31b2c4ddb09d1e3408e52aa8e09a14402f376070a44b1b85cb36d13', 'timestamp': '1733334576989'}
{'asset_id': '114416409796971863099144323163249651172534872992222856507897414949637892047507', 'changes': [{'price': '0.55', 'side': 'BUY', 'size': '4670.1'}], 'event_type': 'price_change', 'hash': '609651f9cca4587472eb79d20fd9c564e7e6ff8f', 'market': '0x7aa4a910b31b2c4ddb09d1e3408e52aa8e09a14402f376070a44b1b85cb36d13', 'timestamp': '1733334577393'}
{'asset_id': '114416409796971863099144323163249651172534872992222856507897414949637892047507', 'changes': [{'price': '0.55', 'side': 'BUY', 'size': '4670.1'}], 'event_type': 'price_change', 'hash': '609651f9cca4587472eb79d20fd9c564e7e6ff8f', 'market': '0x7aa4a910b31b2c4ddb09d1e3408e52aa8e09a14402f376070a44b1b85cb36d13', 'timestamp': '1733334577393'}
{'asset_id': '114416409796971863099144323163249651172534872992222856507897414949637892047507', 'changes': [{'price': '0.55', 'side': 'BUY', 'size': '4570.1'}], 'event_type': 'price_change', 'hash': 'aa5e4f1558db055a4cad4001a6f2bcd43eca56b2', 'market': '0x7aa4a910b31b2c4ddb09d1e3408e52aa8e09a14402f376070a44b1b85cb36d13', 'timestamp': '1733334578065'}
{'asset_id': '114416409796971863099144323163249651172534872992222856507897414949637892047507', 'changes': [{'price': '0.55', 'side': 'BUY', 'size': '4570.1'}], 'event_type': 'price_change', 'hash': 'aa5e4f1558db055a4cad4001a6f2bcd43eca56b2', 'market': '0x7aa4a910b31b2c4ddb09d1e3408e52aa8e09a14402f376070a44b1b85cb36d13', 'timestamp': '1733334578065'}
{'asset_id': '114416409796971863099144323163249651172534872992222856507897414949637892047507', 'changes': [{'price': '0.54', 'side': 'BUY', 'size': '231.19'}], 'event_type': 'price_change', 'hash': 'ab4a4ad0a4766cc0425596793579801d881f6807', 'market': '0x7aa4a910b31b2c4ddb09d1e3408e52aa8e09a14402f376070a44b1b85cb36d13', 'timestamp': '1733334578921'}
{'asset_id': '114416409796971863099144323163249651172534872992222856507897414949637892047507', 'changes': [{'price': '0.54', 'side': 'BUY', 'size': '231.19'}], 'event_type': 'price_change', 'hash': 'ab4a4ad0a4766cc0425596793579801d881f6807', 'market': '0x7aa4a910b31b2c4ddb09d1e3408e52aa8e09a14402f376070a44b1b85cb36d13', 'timestamp': '1733334578921'}
{'asset_id': '114416409796971863099144323163249651172534872992222856507897414949637892047507', 'changes': [{'price': '0.49', 'side': 'BUY', 'size': '40'}, {'price': '0.55', 'side': 'BUY', 'size': '3570.1'}, {'price': '0.59', 'side': 'SELL', 'size': '1310'}], 'event_type': 'price_change', 'hash': '56f7c006dbc00ff0bfa792fb60b78c2ed672aa65', 'market': '0x7aa4a910b31b2c4ddb09d1e3408e52aa8e09a14402f376070a44b1b85cb36d13', 'timestamp': '1733334581883'}
{'asset_id': '114416409796971863099144323163249651172534872992222856507897414949637892047507', 'changes': [{'price': '0.49', 'side': 'BUY', 'size': '40'}, {'price': '0.55', 'side': 'BUY', 'size': '3570.1'}, {'price': '0.59', 'side': 'SELL', 'size': '1310'}], 'event_type': 'price_change', 'hash': '56f7c006dbc00ff0bfa792fb60b78c2ed672aa65', 'market': '0x7aa4a910b31b2c4ddb09d1e3408e52aa8e09a14402f376070a44b1b85cb36d13', 'timestamp': '1733334581883'}
{'asset_id': '114416409796971863099144323163249651172534872992222856507897414949637892047507', 'changes': [{'price': '0.5', 'side': 'BUY', 'size': '515'}], 'event_type': 'price_change', 'hash': '0d079609b72fa1b26e7f70e430a9c35510099332', 'market': '0x7aa4a910b31b2c4ddb09d1e3408e52aa8e09a14402f376070a44b1b85cb36d13', 'timestamp': '1733334582935'}
{'asset_id': '114416409796971863099144323163249651172534872992222856507897414949637892047507', 'changes': [{'price': '0.5', 'side': 'BUY', 'size': '515'}], 'event_type': 'price_change', 'hash': '0d079609b72fa1b26e7f70e430a9c35510099332', 'market': '0x7aa4a910b31b2c4ddb09d1e3408e52aa8e09a14402f376070a44b1b85cb36d13', 'timestamp': '1733334582935'}
{'asset_id': '114416409796971863099144323163249651172534872992222856507897414949637892047507', 'changes': [{'price': '0.6', 'side': 'SELL', 'size': '3067.85'}], 'event_type': 'price_change', 'hash': 'a6cfa1dc50b733efa61a29d8cc411a825383e63d', 'market': '0x7aa4a910b31b2c4ddb09d1e3408e52aa8e09a14402f376070a44b1b85cb36d13', 'timestamp': '1733334583512'}
{'asset_id': '114416409796971863099144323163249651172534872992222856507897414949637892047507', 'changes': [{'price': '0.6', 'side': 'SELL', 'size': '3067.85'}], 'event_type': 'price_change', 'hash': 'a6cfa1dc50b733efa61a29d8cc411a825383e63d', 'market': '0x7aa4a910b31b2c4ddb09d1e3408e52aa8e09a14402f376070a44b1b85cb36d13', 'timestamp': '1733334583512'}
{'asset_id': '114416409796971863099144323163249651172534872992222856507897414949637892047507', 'changes': [{'price': '0.55', 'side': 'BUY', 'size': '4570.1'}], 'event_type': 'price_change', 'hash': '9c8dda96c06523fd20ff2e9a6ecaf13147720a87', 'market': '0x7aa4a910b31b2c4ddb09d1e3408e52aa8e09a14402f376070a44b1b85cb36d13', 'timestamp': '1733334583879'}
{'asset_id': '114416409796971863099144323163249651172534872992222856507897414949637892047507', 'changes': [{'price': '0.55', 'side': 'BUY', 'size': '4570.1'}], 'event_type': 'price_change', 'hash': '9c8dda96c06523fd20ff2e9a6ecaf13147720a87', 'market': '0x7aa4a910b31b2c4ddb09d1e3408e52aa8e09a14402f376070a44b1b85cb36d13', 'timestamp': '1733334583879'}
{'asset_id': '114416409796971863099144323163249651172534872992222856507897414949637892047507', 'changes': [{'price': '0.54', 'side': 'BUY', 'size': '131.19'}], 'event_type': 'price_change', 'hash': '4d8f59cf3721cbd89ab88472d970a4d32cd27838', 'market': '0x7aa4a910b31b2c4ddb09d1e3408e52aa8e09a14402f376070a44b1b85cb36d13', 'timestamp': '1733334587523'}
{'asset_id': '114416409796971863099144323163249651172534872992222856507897414949637892047507', 'changes': [{'price': '0.54', 'side': 'BUY', 'size': '131.19'}], 'event_type': 'price_change', 'hash': '4d8f59cf3721cbd89ab88472d970a4d32cd27838', 'market': '0x7aa4a910b31b2c4ddb09d1e3408e52aa8e09a14402f376070a44b1b85cb36d13', 'timestamp': '1733334587523'}
{'asset_id': '114416409796971863099144323163249651172534872992222856507897414949637892047507', 'changes': [{'price': '0.55', 'side': 'BUY', 'size': '4670.1'}], 'event_type': 'price_change', 'hash': 'd4678d7eb2c5abbdff5d041c83a3626b99552ce0', 'market': '0x7aa4a910b31b2c4ddb09d1e3408e52aa8e09a14402f376070a44b1b85cb36d13', 'timestamp': '1733334588520'}
{'asset_id': '114416409796971863099144323163249651172534872992222856507897414949637892047507', 'changes': [{'price': '0.55', 'side': 'BUY', 'size': '4670.1'}], 'event_type': 'price_change', 'hash': 'd4678d7eb2c5abbdff5d041c83a3626b99552ce0', 'market': '0x7aa4a910b31b2c4ddb09d1e3408e52aa8e09a14402f376070a44b1b85cb36d13', 'timestamp': '1733334588520'}
{'asset_id': '114416409796971863099144323163249651172534872992222856507897414949637892047507', 'changes': [{'price': '0.55', 'side': 'BUY', 'size': '4570.1'}], 'event_type': 'price_change', 'hash': '5081f24b0e41ac22db97ba406f943a79743b313d', 'market': '0x7aa4a910b31b2c4ddb09d1e3408e52aa8e09a14402f376070a44b1b85cb36d13', 'timestamp': '1733334589556'}
{'asset_id': '114416409796971863099144323163249651172534872992222856507897414949637892047507', 'changes': [{'price': '0.55', 'side': 'BUY', 'size': '4570.1'}], 'event_type': 'price_change', 'hash': '5081f24b0e41ac22db97ba406f943a79743b313d', 'market': '0x7aa4a910b31b2c4ddb09d1e3408e52aa8e09a14402f376070a44b1b85cb36d13', 'timestamp': '1733334589556'}
{'asset_id': '114416409796971863099144323163249651172534872992222856507897414949637892047507', 'changes': [{'price': '0.53', 'side': 'BUY', 'size': '1118.99'}, {'price': '0.52', 'side': 'BUY', 'size': '1115.92'}, {'price': '0.48', 'side': 'BUY', 'size': '242.18'}], 'event_type': 'price_change', 'hash': '7d2521c44f0d13d2bf5462bd85abe9054663f70e', 'market': '0x7aa4a910b31b2c4ddb09d1e3408e52aa8e09a14402f376070a44b1b85cb36d13', 'timestamp': '1733334589756'}
{'asset_id': '114416409796971863099144323163249651172534872992222856507897414949637892047507', 'changes': [{'price': '0.53', 'side': 'BUY', 'size': '1118.99'}, {'price': '0.52', 'side': 'BUY', 'size': '1115.92'}, {'price': '0.48', 'side': 'BUY', 'size': '242.18'}], 'event_type': 'price_change', 'hash': '7d2521c44f0d13d2bf5462bd85abe9054663f70e', 'market': '0x7aa4a910b31b2c4ddb09d1e3408e52aa8e09a14402f376070a44b1b85cb36d13', 'timestamp': '1733334589756'}
{'asset_id': '114416409796971863099144323163249651172534872992222856507897414949637892047507', 'changes': [{'price': '0.54', 'side': 'BUY', 'size': '231.19'}], 'event_type': 'price_change', 'hash': '13c4f50cbd00479729545b6848cf86fbc05262ac', 'market': '0x7aa4a910b31b2c4ddb09d1e3408e52aa8e09a14402f376070a44b1b85cb36d13', 'timestamp': '1733334590363'}
