{'asks': [{'price': '0.99', 'size': '4217.01'}, {'price': '0.98', 'size': '505'}, {'price': '0.97', 'size': '511.03'}, {'price': '0.96', 'size': '300'}, {'price': '0.95', 'size': '657.12'}, {'price': '0.94', 'size': '300'}, {'price': '0.92', 'size': '20000.45'}, {'price': '0.91', 'size': '10406.3'}, {'price': '0.9', 'size': '4587.5'}, {'price': '0.89', 'size': '13017.18'}, {'price': '0.88', 'size': '200'}, {'price': '0.86', 'size': '17.1'}, {'price': '0.85', 'size': '109.68'}, {'price': '0.84', 'size': '250'}, {'price': '0.83', 'size': '100'}, {'price': '0.82', 'size': '16029'}, {'price': '0.81', 'size': '45721.39'}, {'price': '0.8', 'size': '26531'}, {'price': '0.79', 'size': '7110'}, {'price': '0.78', 'size': '10350'}, {'price': '0.77', 'size': '67'}, {'price': '0.76', 'size': '200'}, {'price': '0.75', 'size': '18329.25'}, {'price': '0.74', 'size': '11370.7'}, {'price': '0.73', 'size': '5020.1'}, {'price': '0.72', 'size': '380.52'}, {'price': '0.71', 'size': '15073.2'}, {'price': '0.7', 'size': '5570.1'}, {'price': '0.69', 'size': '6088.6'}, {'price': '0.68', 'size': '2131.34'}, {'price': '0.67', 'size': '3010.1'}, {'price': '0.66', 'size': '4510.1'}, {'price': '0.65', 'size': '1010.1'}, {'price': '0.64', 'size': '1230.1'}, {'price': '0.63', 'size': '210.1'}, {'price': '0.62', 'size': '300.1'}, {'price': '0.61', 'size': '511.06'}, {'price': '0.6', 'size': '3467.85'}, {'price': '0.59', 'size': '2510'}, {'price': '0.58', 'size': '2188.1'}, {'price': '0.57', 'size': '350.1'}, {'price': '0.56', 'size': '2661.75'}, {'price': '0.55', 'size': '2914.23'}, {'price': '0.54', 'size': '23.06'}], 'asset_id': '114416409796971863099144323163249651172534872992222856507897414949637892047507', 'bids': [{'price': '0.01', 'size': '2850.27'}, {'price': '0.02', 'size': '500'}, {'price': '0.03', 'size': '500'}, {'price': '0.04', 'size': '300'}, {'price': '0.05', 'size': '320'}, {'price': '0.06', 'size': '300'}, {'price': '0.08', 'size': '250'}, {'price': '0.09', 'size': '300'}, {'price': '0.1', 'size': '205'}, {'price': '0.12', 'size': '200'}, {'price': '0.13', 'size': '426.92'}, {'price': '0.14', 'size': '15'}, {'price': '0.15', 'size': '110'}, {'price': '0.16', 'size': '1335.51'}, {'price': '0.18', 'size': '19.13'}, {'price': '0.19', 'size': '120'}, {'price': '0.2', 'size': '691.17'}, {'price': '0.24', 'size': '5027'}, {'price': '0.25', 'size': '86.66'}, {'price': '0.27', 'size': '215.25'}, {'price': '0.29', 'size': '1102.28'}, {'price': '0.31', 'size': '1130.65'}, {'price': '0.32', 'size': '200'}, {'price': '0.33', 'size': '620'}, {'price': '0.34', 'size': '4000'}, {'price': '0.35', 'size': '232'}, {'price': '0.39', 'size': '10.5'}, {'price': '0.4', 'size': '3135'}, {'price': '0.41', 'size': '20'}, {'price': '0.42', 'size': '3050'}, {'price': '0.43', 'size': '50'}, {'price': '0.44', 'size': '3660'}, {'price': '0.45', 'size': '2978'}, {'price': '0.46', 'size': '500'}, {'price': '0.47', 'size': '297.23'}, {'price': '0.48', 'size': '3842.18'}, {'price': '0.49', 'size': '360'}, {'price': '0.5', 'size': '2315'}, {'price': '0.51', 'size': '1086.18'}, {'price': '0.52', 'size': '762.77'}, {'price': '0.53', 'size': '9'}], 'event_type': 'book', 'hash': 'acdd2070adaa968e6878b10ce4a30edd24f3765f', 'market': '0x7aa4a910b31b2c4ddb09d1e3408e52aa8e09a14402f376070a44b1b85cb36d13', 'timestamp': '1733333492587'}
{'asset_id': '114416409796971863099144323163249651172534872992222856507897414949637892047507', 'event_type': 'last_trade_price', 'fee_rate_bps': '0', 'market': '0x7aa4a910b31b2c4ddb09d1e3408e52aa8e09a14402f376070a44b1b85cb36d13', 'price': '0.54', 'side': 'BUY', 'size': '37.037036', 'timestamp': '1733333492612'}
{'asset_id': '114416409796971863099144323163249651172534872992222856507897414949637892047507', 'changes': [{'price': '0.51', 'side': 'BUY', 'size': '1186.18'}], 'event_type': 'price_change', 'hash': 'bbfe85b0c9b479a69fbcd7c564e38a9b5da61a8a', 'market': '0x7aa4a910b31b2c4ddb09d1e3408e52aa8e09a14402f376070a44b1b85cb36d13', 'timestamp': '1733333492949'}
{'asset_id': '114416409796971863099144323163249651172534872992222856507897414949637892047507', 'changes': [{'price': '0.51', 'side': 'BUY', 'size': '1186.18'}], 'event_type': 'price_change', 'hash': 'bbfe85b0c9b479a69fbcd7c564e38a9b5da61a8a', 'market': '0x7aa4a910b31b2c4ddb09d1e3408e52aa8e09a14402f376070a44b1b85cb36d13', 'timestamp': '1733333492949'}
{'asset_id': '114416409796971863099144323163249651172534872992222856507897414949637892047507', 'changes': [{'price': '0.48', 'side': 'BUY', 'size': '2342.18'}], 'event_type': 'price_change', 'hash': '3bd080d5b1e7666a6aeef094a4be0430d483545a', 'market': '0x7aa4a910b31b2c4ddb09d1e3408e52aa8e09a14402f376070a44b1b85cb36d13', 'timestamp': '1733333498452'}
{'asset_id': '114416409796971863099144323163249651172534872992222856507897414949637892047507', 'changes': [{'price': '0.48', 'side': 'BUY', 'size': '2342.18'}], 'event_type': 'price_change', 'hash': '3bd080d5b1e7666a6aeef094a4be0430d483545a', 'market': '0x7aa4a910b31b2c4ddb09d1e3408e52aa8e09a14402f376070a44b1b85cb36d13', 'timestamp': '1733333498452'}
{'asset_id': '114416409796971863099144323163249651172534872992222856507897414949637892047507', 'changes': [{'price': '0.49', 'side': 'BUY', 'size': '1860'}], 'event_type': 'price_change', 'hash': 'd4eaf2d71fdd658925cdfc92b2b543811b474b59', 'market': '0x7aa4a910b31b2c4ddb09d1e3408e52aa8e09a14402f376070a44b1b85cb36d13', 'timestamp': '1733333499335'}
{'asset_id': '114416409796971863099144323163249651172534872992222856507897414949637892047507', 'changes': [{'price': '0.49', 'side': 'BUY', 'size': '1860'}], 'event_type': 'price_change', 'hash': 'd4eaf2d71fdd658925cdfc92b2b543811b474b59', 'market': '0x7aa4a910b31b2c4ddb09d1e3408e52aa8e09a14402f376070a44b1b85cb36d13', 'timestamp': '1733333499335'}
{'asset_id': '114416409796971863099144323163249651172534872992222856507897414949637892047507', 'changes': [{'price': '0.46', 'side': 'BUY', 'size': '0'}, {'price': '0.5', 'side': 'BUY', 'size': '1315'}, {'price': '0.55', 'side': 'SELL', 'size': '2414.23'}], 'event_type': 'price_change', 'hash': '0ebfc95517b073b23c28535c756d1c98c88068b4', 'market': '0x7aa4a910b31b2c4ddb09d1e3408e52aa8e09a14402f376070a44b1b85cb36d13', 'timestamp': '1733333502747'}
{'asset_id': '114416409796971863099144323163249651172534872992222856507897414949637892047507', 'changes': [{'price': '0.46', 'side': 'BUY', 'size': '0'}, {'price': '0.5', 'side': 'BUY', 'size': '1315'}, {'price': '0.55', 'side': 'SELL', 'size': '2414.23'}], 'event_type': 'price_change', 'hash': '0ebfc95517b073b23c28535c756d1c98c88068b4', 'market': '0x7aa4a910b31b2c4ddb09d1e3408e52aa8e09a14402f376070a44b1b85cb36d13', 'timestamp': '1733333502747'}
{'asset_id': '114416409796971863099144323163249651172534872992222856507897414949637892047507', 'changes': [{'price': '0.46', 'side': 'BUY', 'size': '500'}], 'event_type': 'price_change', 'hash': '964882ee02f50e0244139bd70d3245f2ebb1e46f', 'market': '0x7aa4a910b31b2c4ddb09d1e3408e52aa8e09a14402f376070a44b1b85cb36d13', 'timestamp': '1733333503787'}
{'asset_id': '114416409796971863099144323163249651172534872992222856507897414949637892047507', 'changes': [{'price': '0.46', 'side': 'BUY', 'size': '500'}], 'event_type': 'price_change', 'hash': '964882ee02f50e0244139bd70d3245f2ebb1e46f', 'market': '0x7aa4a910b31b2c4ddb09d1e3408e52aa8e09a14402f376070a44b1b85cb36d13', 'timestamp': '1733333503787'}
{'asset_id': '114416409796971863099144323163249651172534872992222856507897414949637892047507', 'changes': [{'price': '0.55', 'side': 'SELL', 'size': '2914.23'}], 'event_type': 'price_change', 'hash': '7867dd3e39901bc07a86fe7c8dc69c7cc52232a5', 'market': '0x7aa4a910b31b2c4ddb09d1e3408e52aa8e09a14402f376070a44b1b85cb36d13', 'timestamp': '1733333504158'}
{'asset_id': '114416409796971863099144323163249651172534872992222856507897414949637892047507', 'changes': [{'price': '0.55', 'side': 'SELL', 'size': '2914.23'}], 'event_type': 'price_change', 'hash': '7867dd3e39901bc07a86fe7c8dc69c7cc52232a5', 'market': '0x7aa4a910b31b2c4ddb09d1e3408e52aa8e09a14402f376070a44b1b85cb36d13', 'timestamp': '1733333504158'}
{'asset_id': '114416409796971863099144323163249651172534872992222856507897414949637892047507', 'changes': [{'price': '0.53', 'side': 'BUY', 'size': '39'}], 'event_type': 'price_change', 'hash': '494f99ad7a2a27ac6a34d69a2031d9fd990a938a', 'market': '0x7aa4a910b31b2c4ddb09d1e3408e52aa8e09a14402f376070a44b1b85cb36d13', 'timestamp': '1733333504242'}
{'asset_id': '114416409796971863099144323163249651172534872992222856507897414949637892047507', 'changes': [{'price': '0.53', 'side': 'BUY', 'size': '39'}], 'event_type': 'price_change', 'hash': '494f99ad7a2a27ac6a34d69a2031d9fd990a938a', 'market': '0x7aa4a910b31b2c4ddb09d1e3408e52aa8e09a14402f376070a44b1b85cb36d13', 'timestamp': '1733333504242'}
{'asset_id': '114416409796971863099144323163249651172534872992222856507897414949637892047507', 'changes': [{'price': '0.51', 'side': 'BUY', 'size': '2186.18'}], 'event_type': 'price_change', 'hash': '1958257c25b3adb25a9abd32d158f848d709a8cf', 'market': '0x7aa4a910b31b2c4ddb09d1e3408e52aa8e09a14402f376070a44b1b85cb36d13', 'timestamp': '1733333504526'}
{'asset_id': '114416409796971863099144323163249651172534872992222856507897414949637892047507', 'changes': [{'price': '0.51', 'side': 'BUY', 'size': '2186.18'}], 'event_type': 'price_change', 'hash': '1958257c25b3adb25a9abd32d158f848d709a8cf', 'market': '0x7aa4a910b31b2c4ddb09d1e3408e52aa8e09a14402f376070a44b1b85cb36d13', 'timestamp': '1733333504526'}
{'asset_id': '114416409796971863099144323163249651172534872992222856507897414949637892047507', 'changes': [{'price': '0.54', 'side': 'SELL', 'size': '53.06'}], 'event_type': 'price_change', 'hash': 'de05a36a8a399ede295c8b511c15d91eed8cba63', 'market': '0x7aa4a910b31b2c4ddb09d1e3408e52aa8e09a14402f376070a44b1b85cb36d13', 'timestamp': '1733333504634'}
{'asset_id': '114416409796971863099144323163249651172534872992222856507897414949637892047507', 'changes': [{'price': '0.54', 'side': 'SELL', 'size': '53.06'}], 'event_type': 'price_change', 'hash': 'de05a36a8a399ede295c8b511c15d91eed8cba63', 'market': '0x7aa4a910b31b2c4ddb09d1e3408e52aa8e09a14402f376070a44b1b85cb36d13', 'timestamp': '1733333504634'}
{'asset_id': '114416409796971863099144323163249651172534872992222856507897414949637892047507', 'changes': [{'price': '0.51', 'side': 'BUY', 'size': '2086.18'}], 'event_type': 'price_change', 'hash': 'c40bf225d920380d10a99ee786c3326ef8e2cf64', 'market': '0x7aa4a910b31b2c4ddb09d1e3408e52aa8e09a14402f376070a44b1b85cb36d13', 'timestamp': '1733333506316'}
{'asset_id': '114416409796971863099144323163249651172534872992222856507897414949637892047507', 'changes': [{'price': '0.51', 'side': 'BUY', 'size': '2086.18'}], 'event_type': 'price_change', 'hash': 'c40bf225d920380d10a99ee786c3326ef8e2cf64', 'market': '0x7aa4a910b31b2c4ddb09d1e3408e52aa8e09a14402f376070a44b1b85cb36d13', 'timestamp': '1733333506316'}
{'asset_id': '114416409796971863099144323163249651172534872992222856507897414949637892047507', 'changes': [{'price': '0.53', 'side': 'BUY', 'size': '53.99'}], 'event_type': 'price_change', 'hash': '0cd5f52c0acd4dcb13a1ba600ae8e19ef7c97e9c', 'market': '0x7aa4a910b31b2c4ddb09d1e3408e52aa8e09a14402f376070a44b1b85cb36d13', 'timestamp': '1733333506446'}
{'asset_id': '114416409796971863099144323163249651172534872992222856507897414949637892047507', 'changes': [{'price': '0.53', 'side': 'BUY', 'size': '53.99'}], 'event_type': 'price_change', 'hash': '0cd5f52c0acd4dcb13a1ba600ae8e19ef7c97e9c', 'market': '0x7aa4a910b31b2c4ddb09d1e3408e52aa8e09a14402f376070a44b1b85cb36d13', 'timestamp': '1733333506446'}
{'asset_id': '114416409796971863099144323163249651172534872992222856507897414949637892047507', 'changes': [{'price': '0.54', 'side': 'SELL', 'size': '23.06'}], 'event_type': 'price_change', 'hash': 'd4aad2f2bbdfe7ea366318dae0ec211eee110a34', 'market': '0x7aa4a910b31b2c4ddb09d1e3408e52aa8e09a14402f376070a44b1b85cb36d13', 'timestamp': '1733333510322'}
{'asset_id': '114416409796971863099144323163249651172534872992222856507897414949637892047507', 'changes': [{'price': '0.54', 'side': 'SELL', 'size': '23.06'}], 'event_type': 'price_change', 'hash': 'd4aad2f2bbdfe7ea366318dae0ec211eee110a34', 'market': '0x7aa4a910b31b2c4ddb09d1e3408e52aa8e09a14402f376070a44b1b85cb36d13', 'timestamp': '1733333510322'}
{'asset_id': '114416409796971863099144323163249651172534872992222856507897414949637892047507', 'changes': [{'price': '0.55', 'side': 'SELL', 'size': '2944.23'}], 'event_type': 'price_change', 'hash': 'afc95dd8225a720ad050c7e18f40f93722427880', 'market': '0x7aa4a910b31b2c4ddb09d1e3408e52aa8e09a14402f376070a44b1b85cb36d13', 'timestamp': '1733333510462'}
{'asset_id': '114416409796971863099144323163249651172534872992222856507897414949637892047507', 'changes': [{'price': '0.55', 'side': 'SELL', 'size': '2944.23'}], 'event_type': 'price_change', 'hash': 'afc95dd8225a720ad050c7e18f40f93722427880', 'market': '0x7aa4a910b31b2c4ddb09d1e3408e52aa8e09a14402f376070a44b1b85cb36d13', 'timestamp': '1733333510462'}
{'asset_id': '114416409796971863099144323163249651172534872992222856507897414949637892047507', 'changes': [{'price': '0.53', 'side': 'BUY', 'size': '39'}], 'event_type': 'price_change', 'hash': 'd74cdb15ebd09edbe4bebebf57b5ede07ef1f5dc', 'market': '0x7aa4a910b31b2c4ddb09d1e3408e52aa8e09a14402f376070a44b1b85cb36d13', 'timestamp': '1733333510631'}
{'asset_id': '114416409796971863099144323163249651172534872992222856507897414949637892047507', 'changes': [{'price': '0.53', 'side': 'BUY', 'size': '39'}], 'event_type': 'price_change', 'hash': 'd74cdb15ebd09edbe4bebebf57b5ede07ef1f5dc', 'market': '0x7aa4a910b31b2c4ddb09d1e3408e52aa8e09a14402f376070a44b1b85cb36d13', 'timestamp': '1733333510631'}
{'asset_id': '114416409796971863099144323163249651172534872992222856507897414949637892047507', 'changes': [{'price': '0.53', 'side': 'BUY', 'size': '9'}], 'event_type': 'price_change', 'hash': 'e541401ff28bd0c68dcf9d50d371a464812dc7ca', 'market': '0x7aa4a910b31b2c4ddb09d1e3408e52aa8e09a14402f376070a44b1b85cb36d13', 'timestamp': '1733333510831'}
{'asset_id': '114416409796971863099144323163249651172534872992222856507897414949637892047507', 'changes': [{'price': '0.53', 'side': 'BUY', 'size': '9'}], 'event_type': 'price_change', 'hash': 'e541401ff28bd0c68dcf9d50d371a464812dc7ca', 'market': '0x7aa4a910b31b2c4ddb09d1e3408e52aa8e09a14402f376070a44b1b85cb36d13', 'timestamp': '1733333510831'}
{'asset_id': '114416409796971863099144323163249651172534872992222856507897414949637892047507', 'changes': [{'price': '0.52', 'side': 'BUY', 'size': '792.77'}], 'event_type': 'price_change', 'hash': '3c5612b5e711953310a9bd9e81736cd8a2798419', 'market': '0x7aa4a910b31b2c4ddb09d1e3408e52aa8e09a14402f376070a44b1b85cb36d13', 'timestamp': '1733333510969'}
{'asset_id': '114416409796971863099144323163249651172534872992222856507897414949637892047507', 'changes': [{'price': '0.52', 'side': 'BUY', 'size': '792.77'}], 'event_type': 'price_change', 'hash': '3c5612b5e711953310a9bd9e81736cd8a2798419', 'market': '0x7aa4a910b31b2c4ddb09d1e3408e52aa8e09a14402f376070a44b1b85cb36d13', 'timestamp': '1733333510969'}
{'asset_id': '114416409796971863099144323163249651172534872992222856507897414949637892047507', 'changes': [{'price': '0.5', 'side': 'BUY', 'size': '1415'}], 'event_type': 'price_change', 'hash': '0b69eae8e6cfbaa82db0ef34f44994d38409e1c3', 'market': '0x7aa4a910b31b2c4ddb09d1e3408e52aa8e09a14402f376070a44b1b85cb36d13', 'timestamp': '1733333511343'}
{'asset_id': '114416409796971863099144323163249651172534872992222856507897414949637892047507', 'changes': [{'price': '0.5', 'side': 'BUY', 'size': '1415'}], 'event_type': 'price_change', 'hash': '0b69eae8e6cfbaa82db0ef34f44994d38409e1c3', 'market': '0x7aa4a910b31b2c4ddb09d1e3408e52aa8e09a14402f376070a44b1b85cb36d13', 'timestamp': '1733333511343'}
{'asset_id': '114416409796971863099144323163249651172534872992222856507897414949637892047507', 'changes': [{'price': '0.5', 'side': 'BUY', 'size': '1315'}], 'event_type': 'price_change', 'hash': '1afb8b4431a0d6dbe4d246ea1e812d32d7bd9d53', 'market': '0x7aa4a910b31b2c4ddb09d1e3408e52aa8e09a14402f376070a44b1b85cb36d13', 'timestamp': '1733333512266'}
{'asset_id': '114416409796971863099144323163249651172534872992222856507897414949637892047507', 'changes': [{'price': '0.5', 'side': 'BUY', 'size': '1315'}], 'event_type': 'price_change', 'hash': '1afb8b4431a0d6dbe4d246ea1e812d32d7bd9d53', 'market': '0x7aa4a910b31b2c4ddb09d1e3408e52aa8e09a14402f376070a44b1b85cb36d13', 'timestamp': '1733333512266'}
{'asset_id': '114416409796971863099144323163249651172534872992222856507897414949637892047507', 'changes': [{'price': '0.53', 'side': 'BUY', 'size': '23.99'}], 'event_type': 'price_change', 'hash': '9f4bd43ea33ff1200b868d139007a86bb7558efd', 'market': '0x7aa4a910b31b2c4ddb09d1e3408e52aa8e09a14402f376070a44b1b85cb36d13', 'timestamp': '1733333512443'}
{'asset_id': '114416409796971863099144323163249651172534872992222856507897414949637892047507', 'changes': [{'price': '0.53', 'side': 'BUY', 'size': '23.99'}], 'event_type': 'price_change', 'hash': '9f4bd43ea33ff1200b868d139007a86bb7558efd', 'market': '0x7aa4a910b31b2c4ddb09d1e3408e52aa8e09a14402f376070a44b1b85cb36d13', 'timestamp': '1733333512443'}
{'asset_id': '114416409796971863099144323163249651172534872992222856507897414949637892047507', 'changes': [{'price': '0.46', 'side': 'BUY', 'size': '0'}, {'price': '0.55', 'side': 'SELL', 'size': '2444.23'}, {'price': '0.51', 'side': 'BUY', 'size': '1086.18'}], 'event_type': 'price_change', 'hash': '278b1943530315c55c8eafa67300d4ac492819c2', 'market': '0x7aa4a910b31b2c4ddb09d1e3408e52aa8e09a14402f376070a44b1b85cb36d13', 'timestamp': '1733333512851'}
{'asset_id': '114416409796971863099144323163249651172534872992222856507897414949637892047507', 'changes': [{'price': '0.46', 'side': 'BUY', 'size': '0'}, {'price': '0.55', 'side': 'SELL', 'size': '2444.23'}, {'price': '0.51', 'side': 'BUY', 'size': '1086.18'}], 'event_type': 'price_change', 'hash': '278b1943530315c55c8eafa67300d4ac492819c2', 'market': '0x7aa4a910b31b2c4ddb09d1e3408e52aa8e09a14402f376070a44b1b85cb36d13', 'timestamp': '1733333512851'}
{'asset_id': '114416409796971863099144323163249651172534872992222856507897414949637892047507', 'changes': [{'price': '0.51', 'side': 'BUY', 'size': '1186.18'}], 'event_type': 'price_change', 'hash': '6c2e926ae7ad7768ba773b3b6d39017a6df2e7ec', 'market': '0x7aa4a910b31b2c4ddb09d1e3408e52aa8e09a14402f376070a44b1b85cb36d13', 'timestamp': '1733333513091'}
{'asset_id': '114416409796971863099144323163249651172534872992222856507897414949637892047507', 'changes': [{'price': '0.51', 'side': 'BUY', 'size': '1186.18'}], 'event_type': 'price_change', 'hash': '6c2e926ae7ad7768ba773b3b6d39017a6df2e7ec', 'market': '0x7aa4a910b31b2c4ddb09d1e3408e52aa8e09a14402f376070a44b1b85cb36d13', 'timestamp': '1733333513091'}
{'asset_id': '114416409796971863099144323163249651172534872992222856507897414949637892047507', 'changes': [{'price': '0.46', 'side': 'BUY', 'size': '500'}], 'event_type': 'price_change', 'hash': '5fef1a22b45f3fbcabcda22ca444ae85e1eb3b5f', 'market': '0x7aa4a910b31b2c4ddb09d1e3408e52aa8e09a14402f376070a44b1b85cb36d13', 'timestamp': '1733333513898'}
{'asset_id': '114416409796971863099144323163249651172534872992222856507897414949637892047507', 'changes': [{'price': '0.46', 'side': 'BUY', 'size': '500'}], 'event_type': 'price_change', 'hash': '5fef1a22b45f3fbcabcda22ca444ae85e1eb3b5f', 'market': '0x7aa4a910b31b2c4ddb09d1e3408e52aa8e09a14402f376070a44b1b85cb36d13', 'timestamp': '1733333513898'}
{'asset_id': '114416409796971863099144323163249651172534872992222856507897414949637892047507', 'changes': [{'price': '0.55', 'side': 'SELL', 'size': '2944.23'}], 'event_type': 'price_change', 'hash': '0de91d39cf43423bb2f2c76b5cbe2321ede2a344', 'market': '0x7aa4a910b31b2c4ddb09d1e3408e52aa8e09a14402f376070a44b1b85cb36d13', 'timestamp': '1733333514269'}
{'asset_id': '114416409796971863099144323163249651172534872992222856507897414949637892047507', 'changes': [{'price': '0.55', 'side': 'SELL', 'size': '2944.23'}], 'event_type': 'price_change', 'hash': '0de91d39cf43423bb2f2c76b5cbe2321ede2a344', 'market': '0x7aa4a910b31b2c4ddb09d1e3408e52aa8e09a14402f376070a44b1b85cb36d13', 'timestamp': '1733333514269'}
{'asset_id': '114416409796971863099144323163249651172534872992222856507897414949637892047507', 'changes': [{'price': '0.5', 'side': 'BUY', 'size': '2315'}], 'event_type': 'price_change', 'hash': 'f3c8525551fe92cecb2a0214ebb307c752655f57', 'market': '0x7aa4a910b31b2c4ddb09d1e3408e52aa8e09a14402f376070a44b1b85cb36d13', 'timestamp': '1733333514636'}
{'asset_id': '114416409796971863099144323163249651172534872992222856507897414949637892047507', 'changes': [{'price': '0.5', 'side': 'BUY', 'size': '2315'}], 'event_type': 'price_change', 'hash': 'f3c8525551fe92cecb2a0214ebb307c752655f57', 'market': '0x7aa4a910b31b2c4ddb09d1e3408e52aa8e09a14402f376070a44b1b85cb36d13', 'timestamp': '1733333514636'}
{'asset_id': '114416409796971863099144323163249651172534872992222856507897414949637892047507', 'changes': [{'price': '0.53', 'side': 'BUY', 'size': '9'}], 'event_type': 'price_change', 'hash': '702307e30366a0afafe6f32374169c00ff8576ff', 'market': '0x7aa4a910b31b2c4ddb09d1e3408e52aa8e09a14402f376070a44b1b85cb36d13', 'timestamp': '1733333514670'}
{'asset_id': '114416409796971863099144323163249651172534872992222856507897414949637892047507', 'changes': [{'price': '0.53', 'side': 'BUY', 'size': '9'}], 'event_type': 'price_change', 'hash': '702307e30366a0afafe6f32374169c00ff8576ff', 'market': '0x7aa4a910b31b2c4ddb09d1e3408e52aa8e09a14402f376070a44b1b85cb36d13', 'timestamp': '1733333514670'}
{'asset_id': '114416409796971863099144323163249651172534872992222856507897414949637892047507', 'changes': [{'price': '0.53', 'side': 'BUY', 'size': '23.99'}], 'event_type': 'price_change', 'hash': '772a7f3de4976ddee308cbe6ce975da7965c9c5b', 'market': '0x7aa4a910b31b2c4ddb09d1e3408e52aa8e09a14402f376070a44b1b85cb36d13', 'timestamp': '1733333516561'}
{'asset_id': '114416409796971863099144323163249651172534872992222856507897414949637892047507', 'changes': [{'price': '0.53', 'side': 'BUY', 'size': '23.99'}], 'event_type': 'price_change', 'hash': '772a7f3de4976ddee308cbe6ce975da7965c9c5b', 'market': '0x7aa4a910b31b2c4ddb09d1e3408e52aa8e09a14402f376070a44b1b85cb36d13', 'timestamp': '1733333516561'}
{'asset_id': '114416409796971863099144323163249651172534872992222856507897414949637892047507', 'changes': [{'price': '0.57', 'side': 'SELL', 'size': '110.1'}, {'price': '0.49', 'side': 'BUY', 'size': '1640'}], 'event_type': 'price_change', 'hash': '5bea0e8ef0bfb6dff964e63b07a543d1641923f5', 'market': '0x7aa4a910b31b2c4ddb09d1e3408e52aa8e09a14402f376070a44b1b85cb36d13', 'timestamp': '1733333518353'}
{'asset_id': '114416409796971863099144323163249651172534872992222856507897414949637892047507', 'changes': [{'price': '0.57', 'side': 'SELL', 'size': '110.1'}, {'price': '0.49', 'side': 'BUY', 'size': '1640'}], 'event_type': 'price_change', 'hash': '5bea0e8ef0bfb6dff964e63b07a543d1641923f5', 'market': '0x7aa4a910b31b2c4ddb09d1e3408e52aa8e09a14402f376070a44b1b85cb36d13', 'timestamp': '1733333518353'}
{'asset_id': '114416409796971863099144323163249651172534872992222856507897414949637892047507', 'changes': [{'price': '0.58', 'side': 'SELL', 'size': '2458.1'}], 'event_type': 'price_change', 'hash': 'e801af337237e41e7a188774bcb2b585dbf12c59', 'market': '0x7aa4a910b31b2c4ddb09d1e3408e52aa8e09a14402f376070a44b1b85cb36d13', 'timestamp': '1733333518677'}
{'asset_id': '114416409796971863099144323163249651172534872992222856507897414949637892047507', 'changes': [{'price': '0.58', 'side': 'SELL', 'size': '2458.1'}], 'event_type': 'price_change', 'hash': 'e801af337237e41e7a188774bcb2b585dbf12c59', 'market': '0x7aa4a910b31b2c4ddb09d1e3408e52aa8e09a14402f376070a44b1b85cb36d13', 'timestamp': '1733333518677'}
{'asset_id': '114416409796971863099144323163249651172534872992222856507897414949637892047507', 'changes': [{'price': '0.49', 'side': 'BUY', 'size': '1890'}], 'event_type': 'price_change', 'hash': '95b61408320f1531f89fe497bc65e16cc44dd0b2', 'market': '0x7aa4a910b31b2c4ddb09d1e3408e52aa8e09a14402f376070a44b1b85cb36d13', 'timestamp': '1733333518808'}
{'asset_id': '114416409796971863099144323163249651172534872992222856507897414949637892047507', 'changes': [{'price': '0.49', 'side': 'BUY', 'size': '1890'}], 'event_type': 'price_change', 'hash': '95b61408320f1531f89fe497bc65e16cc44dd0b2', 'market': '0x7aa4a910b31b2c4ddb09d1e3408e52aa8e09a14402f376070a44b1b85cb36d13', 'timestamp': '1733333518808'}
{'asset_id': '114416409796971863099144323163249651172534872992222856507897414949637892047507', 'changes': [{'price': '0.53', 'side': 'BUY', 'size': '9'}], 'event_type': 'price_change', 'hash': '23c984b2cef76b0d5f1f3aecd762f32b08d237fa', 'market': '0x7aa4a910b31b2c4ddb09d1e3408e52aa8e09a14402f376070a44b1b85cb36d13', 'timestamp': '1733333522705'}
{'asset_id': '114416409796971863099144323163249651172534872992222856507897414949637892047507', 'changes': [{'price': '0.53', 'side': 'BUY', 'size': '9'}], 'event_type': 'price_change', 'hash': '23c984b2cef76b0d5f1f3aecd762f32b08d237fa', 'market': '0x7aa4a910b31b2c4ddb09d1e3408e52aa8e09a14402f376070a44b1b85cb36d13', 'timestamp': '1733333522705'}
{'asset_id': '114416409796971863099144323163249651172534872992222856507897414949637892047507', 'changes': [{'price': '0.53', 'side': 'BUY', 'size': '23.99'}], 'event_type': 'price_change', 'hash': 'b2184f258100a9c3f3f61a16ca00f133bb6389e7', 'market': '0x7aa4a910b31b2c4ddb09d1e3408e52aa8e09a14402f376070a44b1b85cb36d13', 'timestamp': '1733333534507'}
{'asset_id': '114416409796971863099144323163249651172534872992222856507897414949637892047507', 'changes': [{'price': '0.53', 'side': 'BUY', 'size': '23.99'}], 'event_type': 'price_change', 'hash': 'b2184f258100a9c3f3f61a16ca00f133bb6389e7', 'market': '0x7aa4a910b31b2c4ddb09d1e3408e52aa8e09a14402f376070a44b1b85cb36d13', 'timestamp': '1733333534507'}
{'asset_id': '114416409796971863099144323163249651172534872992222856507897414949637892047507', 'changes': [{'price': '0.51', 'side': 'BUY', 'size': '1086.18'}], 'event_type': 'price_change', 'hash': 'e32d7efe882b4faa94e3c426392a973a0f662d7f', 'market': '0x7aa4a910b31b2c4ddb09d1e3408e52aa8e09a14402f376070a44b1b85cb36d13', 'timestamp': '1733333541604'}
{'asset_id': '114416409796971863099144323163249651172534872992222856507897414949637892047507', 'changes': [{'price': '0.51', 'side': 'BUY', 'size': '1086.18'}], 'event_type': 'price_change', 'hash': 'e32d7efe882b4faa94e3c426392a973a0f662d7f', 'market': '0x7aa4a910b31b2c4ddb09d1e3408e52aa8e09a14402f376070a44b1b85cb36d13', 'timestamp': '1733333541604'}
{'asset_id': '114416409796971863099144323163249651172534872992222856507897414949637892047507', 'changes': [{'price': '0.53', 'side': 'BUY', 'size': '9'}], 'event_type': 'price_change', 'hash': '402501ae591d760552fcdd3ff8903baf7e6b9f1f', 'market': '0x7aa4a910b31b2c4ddb09d1e3408e52aa8e09a14402f376070a44b1b85cb36d13', 'timestamp': '1733333554773'}
{'asset_id': '114416409796971863099144323163249651172534872992222856507897414949637892047507', 'changes': [{'price': '0.53', 'side': 'BUY', 'size': '9'}], 'event_type': 'price_change', 'hash': '402501ae591d760552fcdd3ff8903baf7e6b9f1f', 'market': '0x7aa4a910b31b2c4ddb09d1e3408e52aa8e09a14402f376070a44b1b85cb36d13', 'timestamp': '1733333554773'}
{'asset_id': '114416409796971863099144323163249651172534872992222856507897414949637892047507', 'changes': [{'price': '0.5', 'side': 'BUY', 'size': '2415'}], 'event_type': 'price_change', 'hash': '2146a3cb186382d2cad93edf9b799055d95afe43', 'market': '0x7aa4a910b31b2c4ddb09d1e3408e52aa8e09a14402f376070a44b1b85cb36d13', 'timestamp': '1733333555217'}
{'asset_id': '114416409796971863099144323163249651172534872992222856507897414949637892047507', 'changes': [{'price': '0.5', 'side': 'BUY', 'size': '2415'}], 'event_type': 'price_change', 'hash': '2146a3cb186382d2cad93edf9b799055d95afe43', 'market': '0x7aa4a910b31b2c4ddb09d1e3408e52aa8e09a14402f376070a44b1b85cb36d13', 'timestamp': '1733333555217'}
{'asset_id': '114416409796971863099144323163249651172534872992222856507897414949637892047507', 'changes': [{'price': '0.5', 'side': 'BUY', 'size': '2315'}], 'event_type': 'price_change', 'hash': 'fa59ca1d0af6f022099fcb13ebbc2af9f8361f5f', 'market': '0x7aa4a910b31b2c4ddb09d1e3408e52aa8e09a14402f376070a44b1b85cb36d13', 'timestamp': '1733333559618'}
{'asset_id': '114416409796971863099144323163249651172534872992222856507897414949637892047507', 'changes': [{'price': '0.5', 'side': 'BUY', 'size': '2315'}], 'event_type': 'price_change', 'hash': 'fa59ca1d0af6f022099fcb13ebbc2af9f8361f5f', 'market': '0x7aa4a910b31b2c4ddb09d1e3408e52aa8e09a14402f376070a44b1b85cb36d13', 'timestamp': '1733333559618'}
{'asset_id': '114416409796971863099144323163249651172534872992222856507897414949637892047507', 'changes': [{'price': '0.51', 'side': 'BUY', 'size': '1186.18'}], 'event_type': 'price_change', 'hash': '5398044b98830364eae325b551fcfdbbb1035b55', 'market': '0x7aa4a910b31b2c4ddb09d1e3408e52aa8e09a14402f376070a44b1b85cb36d13', 'timestamp': '1733333560380'}
{'asset_id': '114416409796971863099144323163249651172534872992222856507897414949637892047507', 'changes': [{'price': '0.51', 'side': 'BUY', 'size': '1186.18'}], 'event_type': 'price_change', 'hash': '5398044b98830364eae325b551fcfdbbb1035b55', 'market': '0x7aa4a910b31b2c4ddb09d1e3408e52aa8e09a14402f376070a44b1b85cb36d13', 'timestamp': '1733333560380'}
{'asset_id': '114416409796971863099144323163249651172534872992222856507897414949637892047507', 'changes': [{'price': '0.42', 'side': 'BUY', 'size': '50'}], 'event_type': 'price_change', 'hash': '1d9d69943de4c2c8d66f2eba5f54764cc47f4017', 'market': '0x7aa4a910b31b2c4ddb09d1e3408e52aa8e09a14402f376070a44b1b85cb36d13', 'timestamp': '1733333564012'}
{'asset_id': '114416409796971863099144323163249651172534872992222856507897414949637892047507', 'changes': [{'price': '0.42', 'side': 'BUY', 'size': '50'}], 'event_type': 'price_change', 'hash': '1d9d69943de4c2c8d66f2eba5f54764cc47f4017', 'market': '0x7aa4a910b31b2c4ddb09d1e3408e52aa8e09a14402f376070a44b1b85cb36d13', 'timestamp': '1733333564012'}
{'asset_id': '114416409796971863099144323163249651172534872992222856507897414949637892047507', 'changes': [{'price': '0.5', 'side': 'BUY', 'size': '1315'}, {'price': '0.55', 'side': 'SELL', 'size': '2444.23'}, {'price': '0.46', 'side': 'BUY', 'size': '0'}], 'event_type': 'price_change', 'hash': '50b55b6312ed9f12c6871f63d767b0c9d138eb32', 'market': '0x7aa4a910b31b2c4ddb09d1e3408e52aa8e09a14402f376070a44b1b85cb36d13', 'timestamp': '1733333565743'}
{'market': '0x7aa4a910b31b2c4ddb09d1e3408e52aa8e09a14402f376070a44b1b85cb36d13', 'asset_id': '114416409796971863099144323163249651172534872992222856507897414949637892047507', 'timestamp': '1733333565734', 'hash': '50b55b6312ed9f12c6871f63d767b0c9d138eb32', 'bids': [{'price': '0.01', 'size': '2850.27'}, {'price': '0.02', 'size': '500'}, {'price': '0.03', 'size': '500'}, {'price': '0.04', 'size': '300'}, {'price': '0.05', 'size': '320'}, {'price': '0.06', 'size': '300'}, {'price': '0.08', 'size': '250'}, {'price': '0.09', 'size': '300'}, {'price': '0.1', 'size': '205'}, {'price': '0.12', 'size': '200'}, {'price': '0.13', 'size': '426.92'}, {'price': '0.14', 'size': '15'}, {'price': '0.15', 'size': '110'}, {'price': '0.16', 'size': '1335.51'}, {'price': '0.18', 'size': '19.13'}, {'price': '0.19', 'size': '120'}, {'price': '0.2', 'size': '691.17'}, {'price': '0.24', 'size': '5027'}, {'price': '0.25', 'size': '86.66'}, {'price': '0.27', 'size': '215.25'}, {'price': '0.29', 'size': '1102.28'}, {'price': '0.31', 'size': '1130.65'}, {'price': '0.32', 'size': '200'}, {'price': '0.33', 'size': '620'}, {'price': '0.34', 'size': '4000'}, {'price': '0.35', 'size': '232'}, {'price': '0.39', 'size': '10.5'}, {'price': '0.4', 'size': '3135'}, {'price': '0.41', 'size': '20'}, {'price': '0.42', 'size': '50'}, {'price': '0.43', 'size': '50'}, {'price': '0.44', 'size': '3660'}, {'price': '0.45', 'size': '2978'}, {'price': '0.47', 'size': '297.23'}, {'price': '0.48', 'size': '2342.18'}, {'price': '0.49', 'size': '1890'}, {'price': '0.5', 'size': '1315'}, {'price': '0.51', 'size': '1186.18'}, {'price': '0.52', 'size': '792.77'}, {'price': '0.53', 'size': '9'}], 'asks': [{'price': '0.99', 'size': '4217.01'}, {'price': '0.98', 'size': '505'}, {'price': '0.97', 'size': '511.03'}, {'price': '0.96', 'size': '300'}, {'price': '0.95', 'size': '657.12'}, {'price': '0.94', 'size': '300'}, {'price': '0.92', 'size': '20000.45'}, {'price': '0.91', 'size': '10406.3'}, {'price': '0.9', 'size': '4587.5'}, {'price': '0.89', 'size': '13017.18'}, {'price': '0.88', 'size': '200'}, {'price': '0.86', 'size': '17.1'}, {'price': '0.85', 'size': '109.68'}, {'price': '0.84', 'size': '250'}, {'price': '0.83', 'size': '100'}, {'price': '0.82', 'size': '16029'}, {'price': '0.81', 'size': '45721.39'}, {'price': '0.8', 'size': '26531'}, {'price': '0.79', 'size': '7110'}, {'price': '0.78', 'size': '10350'}, {'price': '0.77', 'size': '67'}, {'price': '0.76', 'size': '200'}, {'price': '0.75', 'size': '18329.25'}, {'price': '0.74', 'size': '11370.7'}, {'price': '0.73', 'size': '5020.1'}, {'price': '0.72', 'size': '380.52'}, {'price': '0.71', 'size': '15073.2'}, {'price': '0.7', 'size': '5570.1'}, {'price': '0.69', 'size': '6088.6'}, {'price': '0.68', 'size': '2131.34'}, {'price': '0.67', 'size': '3010.1'}, {'price': '0.66', 'size': '4510.1'}, {'price': '0.65', 'size': '1010.1'}, {'price': '0.64', 'size': '1230.1'}, {'price': '0.63', 'size': '210.1'}, {'price': '0.62', 'size': '300.1'}, {'price': '0.61', 'size': '511.06'}, {'price': '0.6', 'size': '3467.85'}, {'price': '0.59', 'size': '2510'}, {'price': '0.58', 'size': '2458.1'}, {'price': '0.57', 'size': '110.1'}, {'price': '0.56', 'size': '2661.75'}, {'price': '0.55', 'size': '2444.23'}, {'price': '0.54', 'size': '23.06'}], 'event_type': 'book'}
{'asset_id': '114416409796971863099144323163249651172534872992222856507897414949637892047507', 'changes': [{'price': '0.46', 'side': 'BUY', 'size': '500'}], 'event_type': 'price_change', 'hash': '6feaa438b9c670df61da1916bc8061414d17a3f3', 'market': '0x7aa4a910b31b2c4ddb09d1e3408e52aa8e09a14402f376070a44b1b85cb36d13', 'timestamp': '1733333566797'}
{'asset_id': '114416409796971863099144323163249651172534872992222856507897414949637892047507', 'changes': [{'price': '0.46', 'side': 'BUY', 'size': '500'}], 'event_type': 'price_change', 'hash': '6feaa438b9c670df61da1916bc8061414d17a3f3', 'market': '0x7aa4a910b31b2c4ddb09d1e3408e52aa8e09a14402f376070a44b1b85cb36d13', 'timestamp': '1733333566797'}
{'asset_id': '114416409796971863099144323163249651172534872992222856507897414949637892047507', 'changes': [{'price': '0.56', 'side': 'SELL', 'size': '3161.75'}], 'event_type': 'price_change', 'hash': '36d0fa16f3247b372f1e75e9ab9ebc70a30773f7', 'market': '0x7aa4a910b31b2c4ddb09d1e3408e52aa8e09a14402f376070a44b1b85cb36d13', 'timestamp': '1733333567182'}
{'asset_id': '114416409796971863099144323163249651172534872992222856507897414949637892047507', 'changes': [{'price': '0.56', 'side': 'SELL', 'size': '3161.75'}], 'event_type': 'price_change', 'hash': '36d0fa16f3247b372f1e75e9ab9ebc70a30773f7', 'market': '0x7aa4a910b31b2c4ddb09d1e3408e52aa8e09a14402f376070a44b1b85cb36d13', 'timestamp': '1733333567182'}
{'asset_id': '114416409796971863099144323163249651172534872992222856507897414949637892047507', 'changes': [{'price': '0.51', 'side': 'BUY', 'size': '2186.18'}], 'event_type': 'price_change', 'hash': 'ac2c045f5084ec6e46d52c88f3275cbfd4d2fae0', 'market': '0x7aa4a910b31b2c4ddb09d1e3408e52aa8e09a14402f376070a44b1b85cb36d13', 'timestamp': '1733333567548'}
{'asset_id': '114416409796971863099144323163249651172534872992222856507897414949637892047507', 'changes': [{'price': '0.51', 'side': 'BUY', 'size': '2186.18'}], 'event_type': 'price_change', 'hash': 'ac2c045f5084ec6e46d52c88f3275cbfd4d2fae0', 'market': '0x7aa4a910b31b2c4ddb09d1e3408e52aa8e09a14402f376070a44b1b85cb36d13', 'timestamp': '1733333567548'}
{'asset_id': '114416409796971863099144323163249651172534872992222856507897414949637892047507', 'changes': [{'price': '0.42', 'side': 'BUY', 'size': '3050'}], 'event_type': 'price_change', 'hash': '3cb4e3e9c9402bf7107e71cb1f3c01c1ea6931c9', 'market': '0x7aa4a910b31b2c4ddb09d1e3408e52aa8e09a14402f376070a44b1b85cb36d13', 'timestamp': '1733333570475'}
{'asset_id': '114416409796971863099144323163249651172534872992222856507897414949637892047507', 'changes': [{'price': '0.42', 'side': 'BUY', 'size': '3050'}], 'event_type': 'price_change', 'hash': '3cb4e3e9c9402bf7107e71cb1f3c01c1ea6931c9', 'market': '0x7aa4a910b31b2c4ddb09d1e3408e52aa8e09a14402f376070a44b1b85cb36d13', 'timestamp': '1733333570475'}
{'asset_id': '114416409796971863099144323163249651172534872992222856507897414949637892047507', 'changes': [{'price': '0.53', 'side': 'BUY', 'size': '23.99'}], 'event_type': 'price_change', 'hash': '630c47317badcd175d36c7fed3e6b8fbaa5f60f7', 'market': '0x7aa4a910b31b2c4ddb09d1e3408e52aa8e09a14402f376070a44b1b85cb36d13', 'timestamp': '1733333570513'}
{'asset_id': '114416409796971863099144323163249651172534872992222856507897414949637892047507', 'changes': [{'price': '0.53', 'side': 'BUY', 'size': '23.99'}], 'event_type': 'price_change', 'hash': '630c47317badcd175d36c7fed3e6b8fbaa5f60f7', 'market': '0x7aa4a910b31b2c4ddb09d1e3408e52aa8e09a14402f376070a44b1b85cb36d13', 'timestamp': '1733333570513'}
{'asset_id': '114416409796971863099144323163249651172534872992222856507897414949637892047507', 'changes': [{'price': '0.56', 'side': 'SELL', 'size': '3110.1'}], 'event_type': 'price_change', 'hash': '9e33259a89880213b1a1e16ef808f911aafbb214', 'market': '0x7aa4a910b31b2c4ddb09d1e3408e52aa8e09a14402f376070a44b1b85cb36d13', 'timestamp': '1733333579423'}
{'asset_id': '114416409796971863099144323163249651172534872992222856507897414949637892047507', 'changes': [{'price': '0.56', 'side': 'SELL', 'size': '3110.1'}], 'event_type': 'price_change', 'hash': '9e33259a89880213b1a1e16ef808f911aafbb214', 'market': '0x7aa4a910b31b2c4ddb09d1e3408e52aa8e09a14402f376070a44b1b85cb36d13', 'timestamp': '1733333579423'}
{'asset_id': '114416409796971863099144323163249651172534872992222856507897414949637892047507', 'changes': [{'price': '0.55', 'side': 'SELL', 'size': '2495.88'}], 'event_type': 'price_change', 'hash': 'c5176e8a5802e894be5a0bb5a2e8f61d40221912', 'market': '0x7aa4a910b31b2c4ddb09d1e3408e52aa8e09a14402f376070a44b1b85cb36d13', 'timestamp': '1733333580186'}
{'asset_id': '114416409796971863099144323163249651172534872992222856507897414949637892047507', 'changes': [{'price': '0.55', 'side': 'SELL', 'size': '2495.88'}], 'event_type': 'price_change', 'hash': 'c5176e8a5802e894be5a0bb5a2e8f61d40221912', 'market': '0x7aa4a910b31b2c4ddb09d1e3408e52aa8e09a14402f376070a44b1b85cb36d13', 'timestamp': '1733333580186'}
{'asset_id': '114416409796971863099144323163249651172534872992222856507897414949637892047507', 'changes': [{'price': '0.51', 'side': 'BUY', 'size': '2086.18'}], 'event_type': 'price_change', 'hash': '86aaa83a1922b561c7fb29a8d5c7d3b272aaa37c', 'market': '0x7aa4a910b31b2c4ddb09d1e3408e52aa8e09a14402f376070a44b1b85cb36d13', 'timestamp': '1733333593124'}
{'asset_id': '114416409796971863099144323163249651172534872992222856507897414949637892047507', 'changes': [{'price': '0.51', 'side': 'BUY', 'size': '2086.18'}], 'event_type': 'price_change', 'hash': '86aaa83a1922b561c7fb29a8d5c7d3b272aaa37c', 'market': '0x7aa4a910b31b2c4ddb09d1e3408e52aa8e09a14402f376070a44b1b85cb36d13', 'timestamp': '1733333593124'}
{'asset_id': '114416409796971863099144323163249651172534872992222856507897414949637892047507', 'changes': [{'price': '0.5', 'side': 'BUY', 'size': '115'}], 'event_type': 'price_change', 'hash': '62172a4076c15e7dbd66988ecf59b65a3b73a7e4', 'market': '0x7aa4a910b31b2c4ddb09d1e3408e52aa8e09a14402f376070a44b1b85cb36d13', 'timestamp': '1733333594013'}
{'asset_id': '114416409796971863099144323163249651172534872992222856507897414949637892047507', 'changes': [{'price': '0.5', 'side': 'BUY', 'size': '115'}], 'event_type': 'price_change', 'hash': '62172a4076c15e7dbd66988ecf59b65a3b73a7e4', 'market': '0x7aa4a910b31b2c4ddb09d1e3408e52aa8e09a14402f376070a44b1b85cb36d13', 'timestamp': '1733333594013'}
{'asset_id': '114416409796971863099144323163249651172534872992222856507897414949637892047507', 'changes': [{'price': '0.52', 'side': 'BUY', 'size': '892.77'}], 'event_type': 'price_change', 'hash': 'a6f9a4df1e8acce052def819b3ef86f0c14eb436', 'market': '0x7aa4a910b31b2c4ddb09d1e3408e52aa8e09a14402f376070a44b1b85cb36d13', 'timestamp': '1733333594027'}
{'asset_id': '114416409796971863099144323163249651172534872992222856507897414949637892047507', 'changes': [{'price': '0.52', 'side': 'BUY', 'size': '892.77'}], 'event_type': 'price_change', 'hash': 'a6f9a4df1e8acce052def819b3ef86f0c14eb436', 'market': '0x7aa4a910b31b2c4ddb09d1e3408e52aa8e09a14402f376070a44b1b85cb36d13', 'timestamp': '1733333594027'}
{'asset_id': '114416409796971863099144323163249651172534872992222856507897414949637892047507', 'changes': [{'price': '0.55', 'side': 'SELL', 'size': '1295.88'}], 'event_type': 'price_change', 'hash': 'b12854245544970cb42605e188f0b0f63a223cf8', 'market': '0x7aa4a910b31b2c4ddb09d1e3408e52aa8e09a14402f376070a44b1b85cb36d13', 'timestamp': '1733333594577'}
{'asset_id': '114416409796971863099144323163249651172534872992222856507897414949637892047507', 'changes': [{'price': '0.55', 'side': 'SELL', 'size': '1295.88'}], 'event_type': 'price_change', 'hash': 'b12854245544970cb42605e188f0b0f63a223cf8', 'market': '0x7aa4a910b31b2c4ddb09d1e3408e52aa8e09a14402f376070a44b1b85cb36d13', 'timestamp': '1733333594577'}
{'asset_id': '114416409796971863099144323163249651172534872992222856507897414949637892047507', 'changes': [{'price': '0.54', 'side': 'BUY', 'size': '26.94'}], 'event_type': 'price_change', 'hash': '35020b4858e1427395cea0afdef1cebe8712bce1', 'market': '0x7aa4a910b31b2c4ddb09d1e3408e52aa8e09a14402f376070a44b1b85cb36d13', 'timestamp': '1733333599848'}
{'asset_id': '114416409796971863099144323163249651172534872992222856507897414949637892047507', 'event_type': 'last_trade_price', 'fee_rate_bps': '0', 'market': '0x7aa4a910b31b2c4ddb09d1e3408e52aa8e09a14402f376070a44b1b85cb36d13', 'price': '0.54', 'side': 'BUY', 'size': '23.06', 'timestamp': '1733333599854'}
{'asset_id': '114416409796971863099144323163249651172534872992222856507897414949637892047507', 'event_type': 'last_trade_price', 'fee_rate_bps': '0', 'market': '0x7aa4a910b31b2c4ddb09d1e3408e52aa8e09a14402f376070a44b1b85cb36d13', 'price': '0.54', 'side': 'BUY', 'size': '23.06', 'timestamp': '1733333599854'}
{'asset_id': '114416409796971863099144323163249651172534872992222856507897414949637892047507', 'changes': [{'price': '0.55', 'side': 'SELL', 'size': '1245.88'}, {'price': '0.53', 'side': 'BUY', 'size': '9'}], 'event_type': 'price_change', 'hash': 'c746462dd90c90115c6e67569e1724023b10c281', 'market': '0x7aa4a910b31b2c4ddb09d1e3408e52aa8e09a14402f376070a44b1b85cb36d13', 'timestamp': '1733333600333'}
{'asset_id': '114416409796971863099144323163249651172534872992222856507897414949637892047507', 'changes': [{'price': '0.55', 'side': 'SELL', 'size': '1245.88'}, {'price': '0.53', 'side': 'BUY', 'size': '9'}], 'event_type': 'price_change', 'hash': 'c746462dd90c90115c6e67569e1724023b10c281', 'market': '0x7aa4a910b31b2c4ddb09d1e3408e52aa8e09a14402f376070a44b1b85cb36d13', 'timestamp': '1733333600333'}
{'asset_id': '114416409796971863099144323163249651172534872992222856507897414949637892047507', 'changes': [{'price': '0.48', 'side': 'BUY', 'size': '2292.18'}], 'event_type': 'price_change', 'hash': 'a9f01246fc24c163080868b2cab684134a074917', 'market': '0x7aa4a910b31b2c4ddb09d1e3408e52aa8e09a14402f376070a44b1b85cb36d13', 'timestamp': '1733333600826'}
{'asset_id': '114416409796971863099144323163249651172534872992222856507897414949637892047507', 'changes': [{'price': '0.48', 'side': 'BUY', 'size': '2292.18'}], 'event_type': 'price_change', 'hash': 'a9f01246fc24c163080868b2cab684134a074917', 'market': '0x7aa4a910b31b2c4ddb09d1e3408e52aa8e09a14402f376070a44b1b85cb36d13', 'timestamp': '1733333600826'}
{'asset_id': '114416409796971863099144323163249651172534872992222856507897414949637892047507', 'changes': [{'price': '0.59', 'side': 'SELL', 'size': '2560'}], 'event_type': 'price_change', 'hash': 'e533967f4880fe13314c10722e8c65edeccfdd22', 'market': '0x7aa4a910b31b2c4ddb09d1e3408e52aa8e09a14402f376070a44b1b85cb36d13', 'timestamp': '1733333601103'}
{'asset_id': '114416409796971863099144323163249651172534872992222856507897414949637892047507', 'changes': [{'price': '0.59', 'side': 'SELL', 'size': '2560'}], 'event_type': 'price_change', 'hash': 'e533967f4880fe13314c10722e8c65edeccfdd22', 'market': '0x7aa4a910b31b2c4ddb09d1e3408e52aa8e09a14402f376070a44b1b85cb36d13', 'timestamp': '1733333601103'}
{'asset_id': '114416409796971863099144323163249651172534872992222856507897414949637892047507', 'changes': [{'price': '0.52', 'side': 'BUY', 'size': '942.77'}, {'price': '0.46', 'side': 'BUY', 'size': '0'}, {'price': '0.56', 'side': 'SELL', 'size': '2610.1'}, {'price': '0.51', 'side': 'BUY', 'size': '1086.18'}], 'event_type': 'price_change', 'hash': '439d72abce89a85c7856f1f3afb7cbd151231df1', 'market': '0x7aa4a910b31b2c4ddb09d1e3408e52aa8e09a14402f376070a44b1b85cb36d13', 'timestamp': '1733333601417'}
{'asset_id': '114416409796971863099144323163249651172534872992222856507897414949637892047507', 'changes': [{'price': '0.52', 'side': 'BUY', 'size': '942.77'}, {'price': '0.46', 'side': 'BUY', 'size': '0'}, {'price': '0.56', 'side': 'SELL', 'size': '2610.1'}, {'price': '0.51', 'side': 'BUY', 'size': '1086.18'}], 'event_type': 'price_change', 'hash': '439d72abce89a85c7856f1f3afb7cbd151231df1', 'market': '0x7aa4a910b31b2c4ddb09d1e3408e52aa8e09a14402f376070a44b1b85cb36d13', 'timestamp': '1733333601417'}
{'asset_id': '114416409796971863099144323163249651172534872992222856507897414949637892047507', 'changes': [{'price': '0.47', 'side': 'BUY', 'size': '797.23'}], 'event_type': 'price_change', 'hash': 'aa3f2f4bfb95b015f4c41ea9732aae19249d7113', 'market': '0x7aa4a910b31b2c4ddb09d1e3408e52aa8e09a14402f376070a44b1b85cb36d13', 'timestamp': '1733333602465'}
{'asset_id': '114416409796971863099144323163249651172534872992222856507897414949637892047507', 'changes': [{'price': '0.47', 'side': 'BUY', 'size': '797.23'}], 'event_type': 'price_change', 'hash': 'aa3f2f4bfb95b015f4c41ea9732aae19249d7113', 'market': '0x7aa4a910b31b2c4ddb09d1e3408e52aa8e09a14402f376070a44b1b85cb36d13', 'timestamp': '1733333602465'}
{'asset_id': '114416409796971863099144323163249651172534872992222856507897414949637892047507', 'changes': [{'price': '0.57', 'side': 'SELL', 'size': '610.1'}], 'event_type': 'price_change', 'hash': '6482a6014948feeb347e1616ae699ba3f624ea31', 'market': '0x7aa4a910b31b2c4ddb09d1e3408e52aa8e09a14402f376070a44b1b85cb36d13', 'timestamp': '1733333602819'}
{'asset_id': '114416409796971863099144323163249651172534872992222856507897414949637892047507', 'changes': [{'price': '0.57', 'side': 'SELL', 'size': '610.1'}], 'event_type': 'price_change', 'hash': '6482a6014948feeb347e1616ae699ba3f624ea31', 'market': '0x7aa4a910b31b2c4ddb09d1e3408e52aa8e09a14402f376070a44b1b85cb36d13', 'timestamp': '1733333602819'}
{'asset_id': '114416409796971863099144323163249651172534872992222856507897414949637892047507', 'changes': [{'price': '0.52', 'side': 'BUY', 'size': '1942.77'}], 'event_type': 'price_change', 'hash': '63f86178db3bbe32c1adbc415b56efb685ed9db0', 'market': '0x7aa4a910b31b2c4ddb09d1e3408e52aa8e09a14402f376070a44b1b85cb36d13', 'timestamp': '1733333603181'}
{'asset_id': '114416409796971863099144323163249651172534872992222856507897414949637892047507', 'changes': [{'price': '0.52', 'side': 'BUY', 'size': '1942.77'}], 'event_type': 'price_change', 'hash': '63f86178db3bbe32c1adbc415b56efb685ed9db0', 'market': '0x7aa4a910b31b2c4ddb09d1e3408e52aa8e09a14402f376070a44b1b85cb36d13', 'timestamp': '1733333603181'}
{'asset_id': '114416409796971863099144323163249651172534872992222856507897414949637892047507', 'changes': [{'price': '0.57', 'side': 'SELL', 'size': '1810.1'}], 'event_type': 'price_change', 'hash': '193c3dd740a0dfbd2490b2d62a0365d46676e1ed', 'market': '0x7aa4a910b31b2c4ddb09d1e3408e52aa8e09a14402f376070a44b1b85cb36d13', 'timestamp': '1733333603508'}
{'asset_id': '114416409796971863099144323163249651172534872992222856507897414949637892047507', 'changes': [{'price': '0.57', 'side': 'SELL', 'size': '1810.1'}], 'event_type': 'price_change', 'hash': '193c3dd740a0dfbd2490b2d62a0365d46676e1ed', 'market': '0x7aa4a910b31b2c4ddb09d1e3408e52aa8e09a14402f376070a44b1b85cb36d13', 'timestamp': '1733333603508'}
{'asset_id': '114416409796971863099144323163249651172534872992222856507897414949637892047507', 'changes': [{'price': '0.49', 'side': 'BUY', 'size': '1640'}, {'price': '0.58', 'side': 'SELL', 'size': '2188.1'}], 'event_type': 'price_change', 'hash': 'c3988a1be7647f69e2fe2dcd59676e6eb38015e8', 'market': '0x7aa4a910b31b2c4ddb09d1e3408e52aa8e09a14402f376070a44b1b85cb36d13', 'timestamp': '1733333605786'}
{'asset_id': '114416409796971863099144323163249651172534872992222856507897414949637892047507', 'changes': [{'price': '0.49', 'side': 'BUY', 'size': '1640'}, {'price': '0.58', 'side': 'SELL', 'size': '2188.1'}], 'event_type': 'price_change', 'hash': 'c3988a1be7647f69e2fe2dcd59676e6eb38015e8', 'market': '0x7aa4a910b31b2c4ddb09d1e3408e52aa8e09a14402f376070a44b1b85cb36d13', 'timestamp': '1733333605786'}
{'asset_id': '114416409796971863099144323163249651172534872992222856507897414949637892047507', 'changes': [{'price': '0.58', 'side': 'SELL', 'size': '2428.1'}], 'event_type': 'price_change', 'hash': '847e5f466eeb72ca2e5f8d80de9398670c0a8cbc', 'market': '0x7aa4a910b31b2c4ddb09d1e3408e52aa8e09a14402f376070a44b1b85cb36d13', 'timestamp': '1733333606113'}
{'asset_id': '114416409796971863099144323163249651172534872992222856507897414949637892047507', 'changes': [{'price': '0.58', 'side': 'SELL', 'size': '2428.1'}], 'event_type': 'price_change', 'hash': '847e5f466eeb72ca2e5f8d80de9398670c0a8cbc', 'market': '0x7aa4a910b31b2c4ddb09d1e3408e52aa8e09a14402f376070a44b1b85cb36d13', 'timestamp': '1733333606113'}
{'asset_id': '114416409796971863099144323163249651172534872992222856507897414949637892047507', 'changes': [{'price': '0.5', 'side': 'BUY', 'size': '325'}], 'event_type': 'price_change', 'hash': 'd7c3bdfbae96b21b15993e87213c00959c761131', 'market': '0x7aa4a910b31b2c4ddb09d1e3408e52aa8e09a14402f376070a44b1b85cb36d13', 'timestamp': '1733333606395'}
{'asset_id': '114416409796971863099144323163249651172534872992222856507897414949637892047507', 'changes': [{'price': '0.5', 'side': 'BUY', 'size': '325'}], 'event_type': 'price_change', 'hash': 'd7c3bdfbae96b21b15993e87213c00959c761131', 'market': '0x7aa4a910b31b2c4ddb09d1e3408e52aa8e09a14402f376070a44b1b85cb36d13', 'timestamp': '1733333606395'}
{'asks': [{'price': '0.99', 'size': '4217.01'}, {'price': '0.98', 'size': '505'}, {'price': '0.97', 'size': '511.03'}, {'price': '0.96', 'size': '300'}, {'price': '0.95', 'size': '657.12'}, {'price': '0.94', 'size': '300'}, {'price': '0.92', 'size': '20000.45'}, {'price': '0.91', 'size': '10406.3'}, {'price': '0.9', 'size': '4587.5'}, {'price': '0.89', 'size': '13017.18'}, {'price': '0.88', 'size': '200'}, {'price': '0.86', 'size': '17.1'}, {'price': '0.85', 'size': '109.68'}, {'price': '0.84', 'size': '250'}, {'price': '0.83', 'size': '100'}, {'price': '0.82', 'size': '16029'}, {'price': '0.81', 'size': '45721.39'}, {'price': '0.8', 'size': '26531'}, {'price': '0.79', 'size': '7110'}, {'price': '0.78', 'size': '10350'}, {'price': '0.77', 'size': '67'}, {'price': '0.76', 'size': '200'}, {'price': '0.75', 'size': '18329.25'}, {'price': '0.74', 'size': '11370.7'}, {'price': '0.73', 'size': '5020.1'}, {'price': '0.72', 'size': '380.52'}, {'price': '0.71', 'size': '15073.2'}, {'price': '0.7', 'size': '5570.1'}, {'price': '0.69', 'size': '6088.6'}, {'price': '0.68', 'size': '2131.34'}, {'price': '0.67', 'size': '3010.1'}, {'price': '0.66', 'size': '4510.1'}, {'price': '0.65', 'size': '1010.1'}, {'price': '0.64', 'size': '1230.1'}, {'price': '0.63', 'size': '210.1'}, {'price': '0.62', 'size': '300.1'}, {'price': '0.61', 'size': '511.06'}, {'price': '0.6', 'size': '3467.85'}, {'price': '0.59', 'size': '2560'}, {'price': '0.58', 'size': '2428.1'}, {'price': '0.57', 'size': '1810.1'}, {'price': '0.56', 'size': '2610.1'}, {'price': '0.55', 'size': '1245.88'}], 'asset_id': '114416409796971863099144323163249651172534872992222856507897414949637892047507', 'bids': [{'price': '0.01', 'size': '2850.27'}, {'price': '0.02', 'size': '500'}, {'price': '0.03', 'size': '500'}, {'price': '0.04', 'size': '300'}, {'price': '0.05', 'size': '320'}, {'price': '0.06', 'size': '300'}, {'price': '0.08', 'size': '250'}, {'price': '0.09', 'size': '300'}, {'price': '0.1', 'size': '205'}, {'price': '0.12', 'size': '200'}, {'price': '0.13', 'size': '426.92'}, {'price': '0.14', 'size': '15'}, {'price': '0.15', 'size': '110'}, {'price': '0.16', 'size': '1335.51'}, {'price': '0.18', 'size': '19.13'}, {'price': '0.19', 'size': '120'}, {'price': '0.2', 'size': '691.17'}, {'price': '0.24', 'size': '5027'}, {'price': '0.25', 'size': '86.66'}, {'price': '0.27', 'size': '215.25'}, {'price': '0.29', 'size': '1102.28'}, {'price': '0.31', 'size': '1130.65'}, {'price': '0.32', 'size': '200'}, {'price': '0.33', 'size': '620'}, {'price': '0.34', 'size': '4000'}, {'price': '0.35', 'size': '232'}, {'price': '0.39', 'size': '10.5'}, {'price': '0.4', 'size': '3135'}, {'price': '0.41', 'size': '20'}, {'price': '0.42', 'size': '3050'}, {'price': '0.43', 'size': '50'}, {'price': '0.44', 'size': '3660'}, {'price': '0.45', 'size': '2978'}, {'price': '0.47', 'size': '797.23'}, {'price': '0.48', 'size': '2292.18'}, {'price': '0.49', 'size': '1640'}, {'price': '0.5', 'size': '325'}, {'price': '0.51', 'size': '1086.18'}, {'price': '0.52', 'size': '1942.77'}, {'price': '0.53', 'size': '9'}], 'event_type': 'book', 'hash': '8913d5cc6f241c23200aace7123ab1fa4467d590', 'market': '0x7aa4a910b31b2c4ddb09d1e3408e52aa8e09a14402f376070a44b1b85cb36d13', 'timestamp': '1733333608532'}
{'asks': [{'price': '0.99', 'size': '4217.01'}, {'price': '0.98', 'size': '505'}, {'price': '0.97', 'size': '511.03'}, {'price': '0.96', 'size': '300'}, {'price': '0.95', 'size': '657.12'}, {'price': '0.94', 'size': '300'}, {'price': '0.92', 'size': '20000.45'}, {'price': '0.91', 'size': '10406.3'}, {'price': '0.9', 'size': '4587.5'}, {'price': '0.89', 'size': '13017.18'}, {'price': '0.88', 'size': '200'}, {'price': '0.86', 'size': '17.1'}, {'price': '0.85', 'size': '109.68'}, {'price': '0.84', 'size': '250'}, {'price': '0.83', 'size': '100'}, {'price': '0.82', 'size': '16029'}, {'price': '0.81', 'size': '45721.39'}, {'price': '0.8', 'size': '26531'}, {'price': '0.79', 'size': '7110'}, {'price': '0.78', 'size': '10350'}, {'price': '0.77', 'size': '67'}, {'price': '0.76', 'size': '200'}, {'price': '0.75', 'size': '18329.25'}, {'price': '0.74', 'size': '11370.7'}, {'price': '0.73', 'size': '5020.1'}, {'price': '0.72', 'size': '380.52'}, {'price': '0.71', 'size': '15073.2'}, {'price': '0.7', 'size': '5570.1'}, {'price': '0.69', 'size': '6088.6'}, {'price': '0.68', 'size': '2131.34'}, {'price': '0.67', 'size': '3010.1'}, {'price': '0.66', 'size': '4510.1'}, {'price': '0.65', 'size': '1010.1'}, {'price': '0.64', 'size': '1230.1'}, {'price': '0.63', 'size': '210.1'}, {'price': '0.62', 'size': '300.1'}, {'price': '0.61', 'size': '511.06'}, {'price': '0.6', 'size': '3467.85'}, {'price': '0.59', 'size': '2560'}, {'price': '0.58', 'size': '2428.1'}, {'price': '0.57', 'size': '1810.1'}, {'price': '0.56', 'size': '2610.1'}, {'price': '0.55', 'size': '1245.88'}], 'asset_id': '114416409796971863099144323163249651172534872992222856507897414949637892047507', 'bids': [{'price': '0.01', 'size': '2850.27'}, {'price': '0.02', 'size': '500'}, {'price': '0.03', 'size': '500'}, {'price': '0.04', 'size': '300'}, {'price': '0.05', 'size': '320'}, {'price': '0.06', 'size': '300'}, {'price': '0.08', 'size': '250'}, {'price': '0.09', 'size': '300'}, {'price': '0.1', 'size': '205'}, {'price': '0.12', 'size': '200'}, {'price': '0.13', 'size': '426.92'}, {'price': '0.14', 'size': '15'}, {'price': '0.15', 'size': '110'}, {'price': '0.16', 'size': '1335.51'}, {'price': '0.18', 'size': '19.13'}, {'price': '0.19', 'size': '120'}, {'price': '0.2', 'size': '691.17'}, {'price': '0.24', 'size': '5027'}, {'price': '0.25', 'size': '86.66'}, {'price': '0.27', 'size': '215.25'}, {'price': '0.29', 'size': '1102.28'}, {'price': '0.31', 'size': '1130.65'}, {'price': '0.32', 'size': '200'}, {'price': '0.33', 'size': '620'}, {'price': '0.34', 'size': '4000'}, {'price': '0.35', 'size': '232'}, {'price': '0.39', 'size': '10.5'}, {'price': '0.4', 'size': '3135'}, {'price': '0.41', 'size': '20'}, {'price': '0.42', 'size': '3050'}, {'price': '0.43', 'size': '50'}, {'price': '0.44', 'size': '3660'}, {'price': '0.45', 'size': '2978'}, {'price': '0.47', 'size': '797.23'}, {'price': '0.48', 'size': '2292.18'}, {'price': '0.49', 'size': '1640'}, {'price': '0.5', 'size': '325'}, {'price': '0.51', 'size': '1086.18'}, {'price': '0.52', 'size': '1942.77'}, {'price': '0.53', 'size': '9'}], 'event_type': 'book', 'hash': '8913d5cc6f241c23200aace7123ab1fa4467d590', 'market': '0x7aa4a910b31b2c4ddb09d1e3408e52aa8e09a14402f376070a44b1b85cb36d13', 'timestamp': '1733333608532'}
{'asset_id': '114416409796971863099144323163249651172534872992222856507897414949637892047507', 'changes': [{'price': '0.54', 'side': 'BUY', 'size': '14.99'}], 'event_type': 'price_change', 'hash': '5026c45e321512e660384ab25be5ad61b403a327', 'market': '0x7aa4a910b31b2c4ddb09d1e3408e52aa8e09a14402f376070a44b1b85cb36d13', 'timestamp': '1733333608591'}
{'asset_id': '114416409796971863099144323163249651172534872992222856507897414949637892047507', 'changes': [{'price': '0.54', 'side': 'BUY', 'size': '14.99'}], 'event_type': 'price_change', 'hash': '5026c45e321512e660384ab25be5ad61b403a327', 'market': '0x7aa4a910b31b2c4ddb09d1e3408e52aa8e09a14402f376070a44b1b85cb36d13', 'timestamp': '1733333608591'}
{'asset_id': '114416409796971863099144323163249651172534872992222856507897414949637892047507', 'changes': [{'price': '0.56', 'side': 'SELL', 'size': '1110.1'}, {'price': '0.49', 'side': 'BUY', 'size': '140'}, {'price': '0.45', 'side': 'BUY', 'size': '478'}], 'event_type': 'price_change', 'hash': 'a97a41d88379613521f4005ecfb87dee33524da9', 'market': '0x7aa4a910b31b2c4ddb09d1e3408e52aa8e09a14402f376070a44b1b85cb36d13', 'timestamp': '1733333609043'}
{'asset_id': '114416409796971863099144323163249651172534872992222856507897414949637892047507', 'changes': [{'price': '0.56', 'side': 'SELL', 'size': '1110.1'}, {'price': '0.49', 'side': 'BUY', 'size': '140'}, {'price': '0.45', 'side': 'BUY', 'size': '478'}], 'event_type': 'price_change', 'hash': 'a97a41d88379613521f4005ecfb87dee33524da9', 'market': '0x7aa4a910b31b2c4ddb09d1e3408e52aa8e09a14402f376070a44b1b85cb36d13', 'timestamp': '1733333609043'}
{'asset_id': '114416409796971863099144323163249651172534872992222856507897414949637892047507', 'changes': [{'price': '0.55', 'side': 'SELL', 'size': '1195.88'}], 'event_type': 'price_change', 'hash': 'bd583981e85dd0ba6caabf8bb1da46ffd069998c', 'market': '0x7aa4a910b31b2c4ddb09d1e3408e52aa8e09a14402f376070a44b1b85cb36d13', 'timestamp': '1733333609304'}
{'asset_id': '114416409796971863099144323163249651172534872992222856507897414949637892047507', 'changes': [{'price': '0.55', 'side': 'SELL', 'size': '1195.88'}], 'event_type': 'price_change', 'hash': 'bd583981e85dd0ba6caabf8bb1da46ffd069998c', 'market': '0x7aa4a910b31b2c4ddb09d1e3408e52aa8e09a14402f376070a44b1b85cb36d13', 'timestamp': '1733333609304'}
{'asset_id': '114416409796971863099144323163249651172534872992222856507897414949637892047507', 'changes': [{'price': '0.48', 'side': 'BUY', 'size': '2242.18'}], 'event_type': 'price_change', 'hash': 'dd4c42d4cf0575b02effe6b7ab6b2135b75395c3', 'market': '0x7aa4a910b31b2c4ddb09d1e3408e52aa8e09a14402f376070a44b1b85cb36d13', 'timestamp': '1733333609782'}
{'asset_id': '114416409796971863099144323163249651172534872992222856507897414949637892047507', 'changes': [{'price': '0.48', 'side': 'BUY', 'size': '2242.18'}], 'event_type': 'price_change', 'hash': 'dd4c42d4cf0575b02effe6b7ab6b2135b75395c3', 'market': '0x7aa4a910b31b2c4ddb09d1e3408e52aa8e09a14402f376070a44b1b85cb36d13', 'timestamp': '1733333609782'}
{'asset_id': '114416409796971863099144323163249651172534872992222856507897414949637892047507', 'changes': [{'price': '0.59', 'side': 'SELL', 'size': '2610'}], 'event_type': 'price_change', 'hash': '70cf7769dbf880efbcb9889f290e221d337ede71', 'market': '0x7aa4a910b31b2c4ddb09d1e3408e52aa8e09a14402f376070a44b1b85cb36d13', 'timestamp': '1733333610060'}
{'asset_id': '114416409796971863099144323163249651172534872992222856507897414949637892047507', 'changes': [{'price': '0.59', 'side': 'SELL', 'size': '2610'}], 'event_type': 'price_change', 'hash': '70cf7769dbf880efbcb9889f290e221d337ede71', 'market': '0x7aa4a910b31b2c4ddb09d1e3408e52aa8e09a14402f376070a44b1b85cb36d13', 'timestamp': '1733333610060'}
{'asset_id': '114416409796971863099144323163249651172534872992222856507897414949637892047507', 'changes': [{'price': '0.52', 'side': 'BUY', 'size': '1992.77'}], 'event_type': 'price_change', 'hash': 'd79e2fdcca7652815469559c6cd0cf9fd97006f6', 'market': '0x7aa4a910b31b2c4ddb09d1e3408e52aa8e09a14402f376070a44b1b85cb36d13', 'timestamp': '1733333610308'}
{'asset_id': '114416409796971863099144323163249651172534872992222856507897414949637892047507', 'changes': [{'price': '0.52', 'side': 'BUY', 'size': '1992.77'}], 'event_type': 'price_change', 'hash': 'd79e2fdcca7652815469559c6cd0cf9fd97006f6', 'market': '0x7aa4a910b31b2c4ddb09d1e3408e52aa8e09a14402f376070a44b1b85cb36d13', 'timestamp': '1733333610308'}
{'asset_id': '114416409796971863099144323163249651172534872992222856507897414949637892047507', 'changes': [{'price': '0.54', 'side': 'BUY', 'size': '0'}], 'event_type': 'price_change', 'hash': 'bf1f904d607064dbaf945b4f53325f813641e8f1', 'market': '0x7aa4a910b31b2c4ddb09d1e3408e52aa8e09a14402f376070a44b1b85cb36d13', 'timestamp': '1733333610706'}
{'asset_id': '114416409796971863099144323163249651172534872992222856507897414949637892047507', 'changes': [{'price': '0.54', 'side': 'BUY', 'size': '0'}], 'event_type': 'price_change', 'hash': 'bf1f904d607064dbaf945b4f53325f813641e8f1', 'market': '0x7aa4a910b31b2c4ddb09d1e3408e52aa8e09a14402f376070a44b1b85cb36d13', 'timestamp': '1733333610706'}
{'asset_id': '114416409796971863099144323163249651172534872992222856507897414949637892047507', 'changes': [{'price': '0.53', 'side': 'BUY', 'size': '23.99'}], 'event_type': 'price_change', 'hash': '47d844368737d4774bc04acb0ad43e60304bf90e', 'market': '0x7aa4a910b31b2c4ddb09d1e3408e52aa8e09a14402f376070a44b1b85cb36d13', 'timestamp': '1733333611223'}
{'asset_id': '114416409796971863099144323163249651172534872992222856507897414949637892047507', 'changes': [{'price': '0.53', 'side': 'BUY', 'size': '23.99'}], 'event_type': 'price_change', 'hash': '47d844368737d4774bc04acb0ad43e60304bf90e', 'market': '0x7aa4a910b31b2c4ddb09d1e3408e52aa8e09a14402f376070a44b1b85cb36d13', 'timestamp': '1733333611223'}
{'asset_id': '114416409796971863099144323163249651172534872992222856507897414949637892047507', 'changes': [{'price': '0.51', 'side': 'BUY', 'size': '2286.18'}, {'price': '0.5', 'side': 'BUY', 'size': '1825'}, {'price': '0.47', 'side': 'BUY', 'size': '3297.23'}, {'price': '0.58', 'side': 'SELL', 'size': '3928.1'}], 'event_type': 'price_change', 'hash': '21f7b6dbf7403c41caefc3f7ca57df9221120d71', 'market': '0x7aa4a910b31b2c4ddb09d1e3408e52aa8e09a14402f376070a44b1b85cb36d13', 'timestamp': '1733333612582'}
{'asset_id': '114416409796971863099144323163249651172534872992222856507897414949637892047507', 'changes': [{'price': '0.51', 'side': 'BUY', 'size': '2286.18'}, {'price': '0.5', 'side': 'BUY', 'size': '1825'}, {'price': '0.47', 'side': 'BUY', 'size': '3297.23'}, {'price': '0.58', 'side': 'SELL', 'size': '3928.1'}], 'event_type': 'price_change', 'hash': '21f7b6dbf7403c41caefc3f7ca57df9221120d71', 'market': '0x7aa4a910b31b2c4ddb09d1e3408e52aa8e09a14402f376070a44b1b85cb36d13', 'timestamp': '1733333612582'}
{'asset_id': '114416409796971863099144323163249651172534872992222856507897414949637892047507', 'changes': [{'price': '0.52', 'side': 'BUY', 'size': '1962.77'}], 'event_type': 'price_change', 'hash': '23c1aa151b2ad822139024e68918bd8c3a6676d1', 'market': '0x7aa4a910b31b2c4ddb09d1e3408e52aa8e09a14402f376070a44b1b85cb36d13', 'timestamp': '1733333612790'}
{'asset_id': '114416409796971863099144323163249651172534872992222856507897414949637892047507', 'changes': [{'price': '0.52', 'side': 'BUY', 'size': '1962.77'}], 'event_type': 'price_change', 'hash': '23c1aa151b2ad822139024e68918bd8c3a6676d1', 'market': '0x7aa4a910b31b2c4ddb09d1e3408e52aa8e09a14402f376070a44b1b85cb36d13', 'timestamp': '1733333612790'}
{'asset_id': '114416409796971863099144323163249651172534872992222856507897414949637892047507', 'changes': [{'price': '0.53', 'side': 'BUY', 'size': '53.99'}], 'event_type': 'price_change', 'hash': '813dc423009d1c4ccad398c54ab99a993cbef599', 'market': '0x7aa4a910b31b2c4ddb09d1e3408e52aa8e09a14402f376070a44b1b85cb36d13', 'timestamp': '1733333612929'}
{'asset_id': '114416409796971863099144323163249651172534872992222856507897414949637892047507', 'changes': [{'price': '0.53', 'side': 'BUY', 'size': '53.99'}], 'event_type': 'price_change', 'hash': '813dc423009d1c4ccad398c54ab99a993cbef599', 'market': '0x7aa4a910b31b2c4ddb09d1e3408e52aa8e09a14402f376070a44b1b85cb36d13', 'timestamp': '1733333612929'}
{'asset_id': '114416409796971863099144323163249651172534872992222856507897414949637892047507', 'changes': [{'price': '0.55', 'side': 'SELL', 'size': '1165.88'}], 'event_type': 'price_change', 'hash': 'ec96013a6b96a70425f5b3f183494a0e2c214a6c', 'market': '0x7aa4a910b31b2c4ddb09d1e3408e52aa8e09a14402f376070a44b1b85cb36d13', 'timestamp': '1733333613298'}
{'asset_id': '114416409796971863099144323163249651172534872992222856507897414949637892047507', 'changes': [{'price': '0.55', 'side': 'SELL', 'size': '1165.88'}], 'event_type': 'price_change', 'hash': 'ec96013a6b96a70425f5b3f183494a0e2c214a6c', 'market': '0x7aa4a910b31b2c4ddb09d1e3408e52aa8e09a14402f376070a44b1b85cb36d13', 'timestamp': '1733333613298'}
{'asset_id': '114416409796971863099144323163249651172534872992222856507897414949637892047507', 'changes': [{'price': '0.56', 'side': 'SELL', 'size': '1140.1'}], 'event_type': 'price_change', 'hash': '8df98e6bac1faa252c0baffcf3d1c51b23c0cdf8', 'market': '0x7aa4a910b31b2c4ddb09d1e3408e52aa8e09a14402f376070a44b1b85cb36d13', 'timestamp': '1733333613439'}
{'asset_id': '114416409796971863099144323163249651172534872992222856507897414949637892047507', 'changes': [{'price': '0.56', 'side': 'SELL', 'size': '1140.1'}], 'event_type': 'price_change', 'hash': '8df98e6bac1faa252c0baffcf3d1c51b23c0cdf8', 'market': '0x7aa4a910b31b2c4ddb09d1e3408e52aa8e09a14402f376070a44b1b85cb36d13', 'timestamp': '1733333613439'}
{'asset_id': '114416409796971863099144323163249651172534872992222856507897414949637892047507', 'changes': [{'price': '0.53', 'side': 'BUY', 'size': '23.99'}], 'event_type': 'price_change', 'hash': '8caf1c17a8e1fb7f8ea1cab8af524804e89b5309', 'market': '0x7aa4a910b31b2c4ddb09d1e3408e52aa8e09a14402f376070a44b1b85cb36d13', 'timestamp': '1733333619985'}
{'asset_id': '114416409796971863099144323163249651172534872992222856507897414949637892047507', 'changes': [{'price': '0.53', 'side': 'BUY', 'size': '23.99'}], 'event_type': 'price_change', 'hash': '8caf1c17a8e1fb7f8ea1cab8af524804e89b5309', 'market': '0x7aa4a910b31b2c4ddb09d1e3408e52aa8e09a14402f376070a44b1b85cb36d13', 'timestamp': '1733333619985'}
{'asset_id': '114416409796971863099144323163249651172534872992222856507897414949637892047507', 'changes': [{'price': '0.52', 'side': 'BUY', 'size': '1992.77'}], 'event_type': 'price_change', 'hash': '5ee4fc03863e1a5ef0f73b3eb97c7ec7ef36b33b', 'market': '0x7aa4a910b31b2c4ddb09d1e3408e52aa8e09a14402f376070a44b1b85cb36d13', 'timestamp': '1733333620114'}
{'asset_id': '114416409796971863099144323163249651172534872992222856507897414949637892047507', 'changes': [{'price': '0.52', 'side': 'BUY', 'size': '1992.77'}], 'event_type': 'price_change', 'hash': '5ee4fc03863e1a5ef0f73b3eb97c7ec7ef36b33b', 'market': '0x7aa4a910b31b2c4ddb09d1e3408e52aa8e09a14402f376070a44b1b85cb36d13', 'timestamp': '1733333620114'}
{'asset_id': '114416409796971863099144323163249651172534872992222856507897414949637892047507', 'changes': [{'price': '0.54', 'side': 'SELL', 'size': '100'}], 'event_type': 'price_change', 'hash': 'a8dc3a76130c0e55657f08b5f56bb76337f760d5', 'market': '0x7aa4a910b31b2c4ddb09d1e3408e52aa8e09a14402f376070a44b1b85cb36d13', 'timestamp': '1733333620487'}
{'asset_id': '114416409796971863099144323163249651172534872992222856507897414949637892047507', 'changes': [{'price': '0.54', 'side': 'SELL', 'size': '100'}], 'event_type': 'price_change', 'hash': 'a8dc3a76130c0e55657f08b5f56bb76337f760d5', 'market': '0x7aa4a910b31b2c4ddb09d1e3408e52aa8e09a14402f376070a44b1b85cb36d13', 'timestamp': '1733333620487'}
{'asset_id': '114416409796971863099144323163249651172534872992222856507897414949637892047507', 'changes': [{'price': '0.48', 'side': 'BUY', 'size': '242.18'}], 'event_type': 'price_change', 'hash': '5bdd1c69cfea80f24af537db69ad37b092e26101', 'market': '0x7aa4a910b31b2c4ddb09d1e3408e52aa8e09a14402f376070a44b1b85cb36d13', 'timestamp': '1733333621034'}
{'asset_id': '114416409796971863099144323163249651172534872992222856507897414949637892047507', 'changes': [{'price': '0.48', 'side': 'BUY', 'size': '242.18'}], 'event_type': 'price_change', 'hash': '5bdd1c69cfea80f24af537db69ad37b092e26101', 'market': '0x7aa4a910b31b2c4ddb09d1e3408e52aa8e09a14402f376070a44b1b85cb36d13', 'timestamp': '1733333621034'}
{'asset_id': '114416409796971863099144323163249651172534872992222856507897414949637892047507', 'changes': [{'price': '0.49', 'side': 'BUY', 'size': '2140'}], 'event_type': 'price_change', 'hash': '89c228c19424db8e5a1ebcf51e5a729c55a20fee', 'market': '0x7aa4a910b31b2c4ddb09d1e3408e52aa8e09a14402f376070a44b1b85cb36d13', 'timestamp': '1733333621344'}
{'asset_id': '114416409796971863099144323163249651172534872992222856507897414949637892047507', 'changes': [{'price': '0.49', 'side': 'BUY', 'size': '2140'}], 'event_type': 'price_change', 'hash': '89c228c19424db8e5a1ebcf51e5a729c55a20fee', 'market': '0x7aa4a910b31b2c4ddb09d1e3408e52aa8e09a14402f376070a44b1b85cb36d13', 'timestamp': '1733333621344'}
{'asset_id': '114416409796971863099144323163249651172534872992222856507897414949637892047507', 'changes': [{'price': '0.58', 'side': 'SELL', 'size': '3688.1'}, {'price': '0.5', 'side': 'BUY', 'size': '1615'}], 'event_type': 'price_change', 'hash': '7b5417c29eb840859700b9fe433c354e77f954dd', 'market': '0x7aa4a910b31b2c4ddb09d1e3408e52aa8e09a14402f376070a44b1b85cb36d13', 'timestamp': '1733333625240'}
{'asset_id': '114416409796971863099144323163249651172534872992222856507897414949637892047507', 'changes': [{'price': '0.58', 'side': 'SELL', 'size': '3688.1'}, {'price': '0.5', 'side': 'BUY', 'size': '1615'}], 'event_type': 'price_change', 'hash': '7b5417c29eb840859700b9fe433c354e77f954dd', 'market': '0x7aa4a910b31b2c4ddb09d1e3408e52aa8e09a14402f376070a44b1b85cb36d13', 'timestamp': '1733333625240'}
{'asset_id': '114416409796971863099144323163249651172534872992222856507897414949637892047507', 'changes': [{'price': '0.58', 'side': 'SELL', 'size': '3958.1'}, {'price': '0.49', 'side': 'BUY', 'size': '2390'}], 'event_type': 'price_change', 'hash': 'f8477e8bfa1a90c58f73e8575b4fa0b55afd510f', 'market': '0x7aa4a910b31b2c4ddb09d1e3408e52aa8e09a14402f376070a44b1b85cb36d13', 'timestamp': '1733333625541'}
{'asset_id': '114416409796971863099144323163249651172534872992222856507897414949637892047507', 'changes': [{'price': '0.58', 'side': 'SELL', 'size': '3958.1'}, {'price': '0.49', 'side': 'BUY', 'size': '2390'}], 'event_type': 'price_change', 'hash': 'f8477e8bfa1a90c58f73e8575b4fa0b55afd510f', 'market': '0x7aa4a910b31b2c4ddb09d1e3408e52aa8e09a14402f376070a44b1b85cb36d13', 'timestamp': '1733333625541'}
{'asset_id': '114416409796971863099144323163249651172534872992222856507897414949637892047507', 'changes': [{'price': '0.59', 'side': 'SELL', 'size': '2560'}], 'event_type': 'price_change', 'hash': '36293f0a8e78a1fc4167638b55d58f955cb644e3', 'market': '0x7aa4a910b31b2c4ddb09d1e3408e52aa8e09a14402f376070a44b1b85cb36d13', 'timestamp': '1733333629317'}
{'asset_id': '114416409796971863099144323163249651172534872992222856507897414949637892047507', 'changes': [{'price': '0.59', 'side': 'SELL', 'size': '2560'}], 'event_type': 'price_change', 'hash': '36293f0a8e78a1fc4167638b55d58f955cb644e3', 'market': '0x7aa4a910b31b2c4ddb09d1e3408e52aa8e09a14402f376070a44b1b85cb36d13', 'timestamp': '1733333629317'}
{'asset_id': '114416409796971863099144323163249651172534872992222856507897414949637892047507', 'changes': [{'price': '0.52', 'side': 'BUY', 'size': '1942.77'}], 'event_type': 'price_change', 'hash': 'b13c15e82e123966411d93a18f392467fded565f', 'market': '0x7aa4a910b31b2c4ddb09d1e3408e52aa8e09a14402f376070a44b1b85cb36d13', 'timestamp': '1733333629800'}
{'asset_id': '114416409796971863099144323163249651172534872992222856507897414949637892047507', 'changes': [{'price': '0.52', 'side': 'BUY', 'size': '1942.77'}], 'event_type': 'price_change', 'hash': 'b13c15e82e123966411d93a18f392467fded565f', 'market': '0x7aa4a910b31b2c4ddb09d1e3408e52aa8e09a14402f376070a44b1b85cb36d13', 'timestamp': '1733333629800'}
{'asset_id': '114416409796971863099144323163249651172534872992222856507897414949637892047507', 'changes': [{'price': '0.55', 'side': 'SELL', 'size': '1215.88'}], 'event_type': 'price_change', 'hash': 'e47f75384999765f95a1cf910a19892b71c71c2c', 'market': '0x7aa4a910b31b2c4ddb09d1e3408e52aa8e09a14402f376070a44b1b85cb36d13', 'timestamp': '1733333630070'}
{'asset_id': '114416409796971863099144323163249651172534872992222856507897414949637892047507', 'changes': [{'price': '0.55', 'side': 'SELL', 'size': '1215.88'}], 'event_type': 'price_change', 'hash': 'e47f75384999765f95a1cf910a19892b71c71c2c', 'market': '0x7aa4a910b31b2c4ddb09d1e3408e52aa8e09a14402f376070a44b1b85cb36d13', 'timestamp': '1733333630070'}
{'asset_id': '114416409796971863099144323163249651172534872992222856507897414949637892047507', 'changes': [{'price': '0.48', 'side': 'BUY', 'size': '292.18'}, {'price': '0.59', 'side': 'SELL', 'size': '2510'}], 'event_type': 'price_change', 'hash': '6e6c3807cf4602c5941eb47f21b7ddf1a746ab82', 'market': '0x7aa4a910b31b2c4ddb09d1e3408e52aa8e09a14402f376070a44b1b85cb36d13', 'timestamp': '1733333630329'}
{'asset_id': '114416409796971863099144323163249651172534872992222856507897414949637892047507', 'changes': [{'price': '0.48', 'side': 'BUY', 'size': '292.18'}, {'price': '0.59', 'side': 'SELL', 'size': '2510'}], 'event_type': 'price_change', 'hash': '6e6c3807cf4602c5941eb47f21b7ddf1a746ab82', 'market': '0x7aa4a910b31b2c4ddb09d1e3408e52aa8e09a14402f376070a44b1b85cb36d13', 'timestamp': '1733333630329'}
{'asset_id': '114416409796971863099144323163249651172534872992222856507897414949637892047507', 'changes': [{'price': '0.52', 'side': 'BUY', 'size': '1892.77'}], 'event_type': 'price_change', 'hash': '64619fdd0c4fa112731b2859562f4ef6633fc827', 'market': '0x7aa4a910b31b2c4ddb09d1e3408e52aa8e09a14402f376070a44b1b85cb36d13', 'timestamp': '1733333630808'}
{'asset_id': '114416409796971863099144323163249651172534872992222856507897414949637892047507', 'changes': [{'price': '0.52', 'side': 'BUY', 'size': '1892.77'}], 'event_type': 'price_change', 'hash': '64619fdd0c4fa112731b2859562f4ef6633fc827', 'market': '0x7aa4a910b31b2c4ddb09d1e3408e52aa8e09a14402f376070a44b1b85cb36d13', 'timestamp': '1733333630808'}
{'asset_id': '114416409796971863099144323163249651172534872992222856507897414949637892047507', 'changes': [{'price': '0.55', 'side': 'SELL', 'size': '1265.88'}], 'event_type': 'price_change', 'hash': '2c5d05017501a4d086183383b81c6106c3078647', 'market': '0x7aa4a910b31b2c4ddb09d1e3408e52aa8e09a14402f376070a44b1b85cb36d13', 'timestamp': '1733333631150'}
{'asset_id': '114416409796971863099144323163249651172534872992222856507897414949637892047507', 'changes': [{'price': '0.55', 'side': 'SELL', 'size': '1265.88'}], 'event_type': 'price_change', 'hash': '2c5d05017501a4d086183383b81c6106c3078647', 'market': '0x7aa4a910b31b2c4ddb09d1e3408e52aa8e09a14402f376070a44b1b85cb36d13', 'timestamp': '1733333631150'}
{'asset_id': '114416409796971863099144323163249651172534872992222856507897414949637892047507', 'changes': [{'price': '0.48', 'side': 'BUY', 'size': '342.18'}], 'event_type': 'price_change', 'hash': 'cc98adb6a9eb1251ce711153781eea7ddcb219fb', 'market': '0x7aa4a910b31b2c4ddb09d1e3408e52aa8e09a14402f376070a44b1b85cb36d13', 'timestamp': '1733333631413'}
{'asset_id': '114416409796971863099144323163249651172534872992222856507897414949637892047507', 'changes': [{'price': '0.48', 'side': 'BUY', 'size': '342.18'}], 'event_type': 'price_change', 'hash': 'cc98adb6a9eb1251ce711153781eea7ddcb219fb', 'market': '0x7aa4a910b31b2c4ddb09d1e3408e52aa8e09a14402f376070a44b1b85cb36d13', 'timestamp': '1733333631413'}
{'asset_id': '114416409796971863099144323163249651172534872992222856507897414949637892047507', 'changes': [{'price': '0.66', 'side': 'SELL', 'size': '510.1'}], 'event_type': 'price_change', 'hash': 'ac71de13c334df41060e871e0525caab25bb978e', 'market': '0x7aa4a910b31b2c4ddb09d1e3408e52aa8e09a14402f376070a44b1b85cb36d13', 'timestamp': '1733333636012'}
{'asset_id': '114416409796971863099144323163249651172534872992222856507897414949637892047507', 'changes': [{'price': '0.66', 'side': 'SELL', 'size': '510.1'}], 'event_type': 'price_change', 'hash': 'ac71de13c334df41060e871e0525caab25bb978e', 'market': '0x7aa4a910b31b2c4ddb09d1e3408e52aa8e09a14402f376070a44b1b85cb36d13', 'timestamp': '1733333636012'}
{'asset_id': '114416409796971863099144323163249651172534872992222856507897414949637892047507', 'changes': [{'price': '0.87', 'side': 'SELL', 'size': '2306'}], 'event_type': 'price_change', 'hash': 'a0de3d10722f3ef9f4ce38fc2ca48c75b0cbca0d', 'market': '0x7aa4a910b31b2c4ddb09d1e3408e52aa8e09a14402f376070a44b1b85cb36d13', 'timestamp': '1733333636866'}
{'asset_id': '114416409796971863099144323163249651172534872992222856507897414949637892047507', 'changes': [{'price': '0.87', 'side': 'SELL', 'size': '2306'}], 'event_type': 'price_change', 'hash': 'a0de3d10722f3ef9f4ce38fc2ca48c75b0cbca0d', 'market': '0x7aa4a910b31b2c4ddb09d1e3408e52aa8e09a14402f376070a44b1b85cb36d13', 'timestamp': '1733333636866'}
{'asset_id': '114416409796971863099144323163249651172534872992222856507897414949637892047507', 'changes': [{'price': '0.68', 'side': 'SELL', 'size': '6131.34'}], 'event_type': 'price_change', 'hash': 'ed32558f235ba8bb178b81b6f659ea920f612373', 'market': '0x7aa4a910b31b2c4ddb09d1e3408e52aa8e09a14402f376070a44b1b85cb36d13', 'timestamp': '1733333637475'}
{'asset_id': '114416409796971863099144323163249651172534872992222856507897414949637892047507', 'changes': [{'price': '0.68', 'side': 'SELL', 'size': '6131.34'}], 'event_type': 'price_change', 'hash': 'ed32558f235ba8bb178b81b6f659ea920f612373', 'market': '0x7aa4a910b31b2c4ddb09d1e3408e52aa8e09a14402f376070a44b1b85cb36d13', 'timestamp': '1733333637475'}
{'asset_id': '114416409796971863099144323163249651172534872992222856507897414949637892047507', 'changes': [{'price': '0.56', 'side': 'SELL', 'size': '1110.1'}], 'event_type': 'price_change', 'hash': 'c9fab0ced8cdae6519035048828e608cd956464d', 'market': '0x7aa4a910b31b2c4ddb09d1e3408e52aa8e09a14402f376070a44b1b85cb36d13', 'timestamp': '1733333639430'}
{'asset_id': '114416409796971863099144323163249651172534872992222856507897414949637892047507', 'changes': [{'price': '0.56', 'side': 'SELL', 'size': '1110.1'}], 'event_type': 'price_change', 'hash': 'c9fab0ced8cdae6519035048828e608cd956464d', 'market': '0x7aa4a910b31b2c4ddb09d1e3408e52aa8e09a14402f376070a44b1b85cb36d13', 'timestamp': '1733333639430'}
{'asset_id': '114416409796971863099144323163249651172534872992222856507897414949637892047507', 'changes': [{'price': '0.55', 'side': 'SELL', 'size': '1295.88'}], 'event_type': 'price_change', 'hash': '81067ff403a4eece02f90786b2719466a519230e', 'market': '0x7aa4a910b31b2c4ddb09d1e3408e52aa8e09a14402f376070a44b1b85cb36d13', 'timestamp': '1733333639549'}
{'asset_id': '114416409796971863099144323163249651172534872992222856507897414949637892047507', 'changes': [{'price': '0.55', 'side': 'SELL', 'size': '1295.88'}], 'event_type': 'price_change', 'hash': '81067ff403a4eece02f90786b2719466a519230e', 'market': '0x7aa4a910b31b2c4ddb09d1e3408e52aa8e09a14402f376070a44b1b85cb36d13', 'timestamp': '1733333639549'}
{'asset_id': '114416409796971863099144323163249651172534872992222856507897414949637892047507', 'changes': [{'price': '0.52', 'side': 'BUY', 'size': '1792.77'}], 'event_type': 'price_change', 'hash': '28194a252fb7bf638ab7b00d81d53b0e89c14ae1', 'market': '0x7aa4a910b31b2c4ddb09d1e3408e52aa8e09a14402f376070a44b1b85cb36d13', 'timestamp': '1733333646341'}
{'asset_id': '114416409796971863099144323163249651172534872992222856507897414949637892047507', 'changes': [{'price': '0.52', 'side': 'BUY', 'size': '1792.77'}], 'event_type': 'price_change', 'hash': '28194a252fb7bf638ab7b00d81d53b0e89c14ae1', 'market': '0x7aa4a910b31b2c4ddb09d1e3408e52aa8e09a14402f376070a44b1b85cb36d13', 'timestamp': '1733333646341'}
{'asset_id': '114416409796971863099144323163249651172534872992222856507897414949637892047507', 'changes': [{'price': '0.53', 'side': 'BUY', 'size': '123.99'}], 'event_type': 'price_change', 'hash': '4e175d53c7365ace51d549c83db79045b2016c7b', 'market': '0x7aa4a910b31b2c4ddb09d1e3408e52aa8e09a14402f376070a44b1b85cb36d13', 'timestamp': '1733333647242'}
{'asset_id': '114416409796971863099144323163249651172534872992222856507897414949637892047507', 'changes': [{'price': '0.53', 'side': 'BUY', 'size': '123.99'}], 'event_type': 'price_change', 'hash': '4e175d53c7365ace51d549c83db79045b2016c7b', 'market': '0x7aa4a910b31b2c4ddb09d1e3408e52aa8e09a14402f376070a44b1b85cb36d13', 'timestamp': '1733333647242'}
{'asset_id': '114416409796971863099144323163249651172534872992222856507897414949637892047507', 'changes': [{'price': '0.5', 'side': 'BUY', 'size': '115'}, {'price': '0.51', 'side': 'BUY', 'size': '1086.18'}], 'event_type': 'price_change', 'hash': '01084e87b39b55a68662e7e78a8d0de73821a73a', 'market': '0x7aa4a910b31b2c4ddb09d1e3408e52aa8e09a14402f376070a44b1b85cb36d13', 'timestamp': '1733333649921'}
{'asset_id': '114416409796971863099144323163249651172534872992222856507897414949637892047507', 'changes': [{'price': '0.5', 'side': 'BUY', 'size': '115'}, {'price': '0.51', 'side': 'BUY', 'size': '1086.18'}], 'event_type': 'price_change', 'hash': '01084e87b39b55a68662e7e78a8d0de73821a73a', 'market': '0x7aa4a910b31b2c4ddb09d1e3408e52aa8e09a14402f376070a44b1b85cb36d13', 'timestamp': '1733333649921'}
{'asset_id': '114416409796971863099144323163249651172534872992222856507897414949637892047507', 'changes': [{'price': '0.47', 'side': 'BUY', 'size': '2797.23'}], 'event_type': 'price_change', 'hash': '4023071cac460c3f886716fd8559e058379e62ec', 'market': '0x7aa4a910b31b2c4ddb09d1e3408e52aa8e09a14402f376070a44b1b85cb36d13', 'timestamp': '1733333650772'}
{'asset_id': '114416409796971863099144323163249651172534872992222856507897414949637892047507', 'changes': [{'price': '0.47', 'side': 'BUY', 'size': '2797.23'}], 'event_type': 'price_change', 'hash': '4023071cac460c3f886716fd8559e058379e62ec', 'market': '0x7aa4a910b31b2c4ddb09d1e3408e52aa8e09a14402f376070a44b1b85cb36d13', 'timestamp': '1733333650772'}
{'asset_id': '114416409796971863099144323163249651172534872992222856507897414949637892047507', 'changes': [{'price': '0.52', 'side': 'BUY', 'size': '792.77'}, {'price': '0.57', 'side': 'SELL', 'size': '1310.1'}], 'event_type': 'price_change', 'hash': 'c1fbf83cf1ca6fef1379d7348823ccf85bbed01d', 'market': '0x7aa4a910b31b2c4ddb09d1e3408e52aa8e09a14402f376070a44b1b85cb36d13', 'timestamp': '1733333650781'}
{'asset_id': '114416409796971863099144323163249651172534872992222856507897414949637892047507', 'changes': [{'price': '0.52', 'side': 'BUY', 'size': '792.77'}, {'price': '0.57', 'side': 'SELL', 'size': '1310.1'}], 'event_type': 'price_change', 'hash': 'c1fbf83cf1ca6fef1379d7348823ccf85bbed01d', 'market': '0x7aa4a910b31b2c4ddb09d1e3408e52aa8e09a14402f376070a44b1b85cb36d13', 'timestamp': '1733333650781'}
{'asset_id': '114416409796971863099144323163249651172534872992222856507897414949637892047507', 'changes': [{'price': '0.48', 'side': 'BUY', 'size': '842.18'}], 'event_type': 'price_change', 'hash': 'ab969285cfd63437d62ea334c95f5e528e32ae42', 'market': '0x7aa4a910b31b2c4ddb09d1e3408e52aa8e09a14402f376070a44b1b85cb36d13', 'timestamp': '1733333651892'}
{'asset_id': '114416409796971863099144323163249651172534872992222856507897414949637892047507', 'changes': [{'price': '0.48', 'side': 'BUY', 'size': '842.18'}], 'event_type': 'price_change', 'hash': 'ab969285cfd63437d62ea334c95f5e528e32ae42', 'market': '0x7aa4a910b31b2c4ddb09d1e3408e52aa8e09a14402f376070a44b1b85cb36d13', 'timestamp': '1733333651892'}
{'asset_id': '114416409796971863099144323163249651172534872992222856507897414949637892047507', 'changes': [{'price': '0.57', 'side': 'SELL', 'size': '1810.1'}], 'event_type': 'price_change', 'hash': '59f36a8e4dcf54f3bbea1e56cb3b33ad5d459336', 'market': '0x7aa4a910b31b2c4ddb09d1e3408e52aa8e09a14402f376070a44b1b85cb36d13', 'timestamp': '1733333652252'}
{'asset_id': '114416409796971863099144323163249651172534872992222856507897414949637892047507', 'changes': [{'price': '0.57', 'side': 'SELL', 'size': '1810.1'}], 'event_type': 'price_change', 'hash': '59f36a8e4dcf54f3bbea1e56cb3b33ad5d459336', 'market': '0x7aa4a910b31b2c4ddb09d1e3408e52aa8e09a14402f376070a44b1b85cb36d13', 'timestamp': '1733333652252'}
{'asset_id': '114416409796971863099144323163249651172534872992222856507897414949637892047507', 'changes': [{'price': '0.52', 'side': 'BUY', 'size': '1792.77'}], 'event_type': 'price_change', 'hash': '3a391a168bf6585359cbf439a56060388bc0ce36', 'market': '0x7aa4a910b31b2c4ddb09d1e3408e52aa8e09a14402f376070a44b1b85cb36d13', 'timestamp': '1733333652623'}
{'asset_id': '114416409796971863099144323163249651172534872992222856507897414949637892047507', 'changes': [{'price': '0.52', 'side': 'BUY', 'size': '1792.77'}], 'event_type': 'price_change', 'hash': '3a391a168bf6585359cbf439a56060388bc0ce36', 'market': '0x7aa4a910b31b2c4ddb09d1e3408e52aa8e09a14402f376070a44b1b85cb36d13', 'timestamp': '1733333652623'}
{'asset_id': '114416409796971863099144323163249651172534872992222856507897414949637892047507', 'changes': [{'price': '0.54', 'side': 'SELL', 'size': '0'}], 'event_type': 'price_change', 'hash': 'c0f3e365a0d05babb8c7adf5d5271095d9ba88f1', 'market': '0x7aa4a910b31b2c4ddb09d1e3408e52aa8e09a14402f376070a44b1b85cb36d13', 'timestamp': '1733333654668'}
{'asset_id': '114416409796971863099144323163249651172534872992222856507897414949637892047507', 'changes': [{'price': '0.54', 'side': 'SELL', 'size': '0'}], 'event_type': 'price_change', 'hash': 'c0f3e365a0d05babb8c7adf5d5271095d9ba88f1', 'market': '0x7aa4a910b31b2c4ddb09d1e3408e52aa8e09a14402f376070a44b1b85cb36d13', 'timestamp': '1733333654668'}
{'asset_id': '114416409796971863099144323163249651172534872992222856507897414949637892047507', 'changes': [{'price': '0.51', 'side': 'BUY', 'size': '2586.18'}, {'price': '0.52', 'side': 'BUY', 'size': '2992.77'}], 'event_type': 'price_change', 'hash': '20bdda18dee40c1b15d62c0520f813320efd35da', 'market': '0x7aa4a910b31b2c4ddb09d1e3408e52aa8e09a14402f376070a44b1b85cb36d13', 'timestamp': '1733333656609'}
{'asset_id': '114416409796971863099144323163249651172534872992222856507897414949637892047507', 'changes': [{'price': '0.51', 'side': 'BUY', 'size': '2586.18'}, {'price': '0.52', 'side': 'BUY', 'size': '2992.77'}], 'event_type': 'price_change', 'hash': '20bdda18dee40c1b15d62c0520f813320efd35da', 'market': '0x7aa4a910b31b2c4ddb09d1e3408e52aa8e09a14402f376070a44b1b85cb36d13', 'timestamp': '1733333656609'}
{'asset_id': '114416409796971863099144323163249651172534872992222856507897414949637892047507', 'changes': [{'price': '0.55', 'side': 'SELL', 'size': '1186.88'}], 'event_type': 'price_change', 'hash': '4ee3cc0e8a4f77f8d467f2234d1f43db5ea62c4e', 'market': '0x7aa4a910b31b2c4ddb09d1e3408e52aa8e09a14402f376070a44b1b85cb36d13', 'timestamp': '1733333658091'}
{'asset_id': '114416409796971863099144323163249651172534872992222856507897414949637892047507', 'changes': [{'price': '0.55', 'side': 'SELL', 'size': '1186.88'}], 'event_type': 'price_change', 'hash': '4ee3cc0e8a4f77f8d467f2234d1f43db5ea62c4e', 'market': '0x7aa4a910b31b2c4ddb09d1e3408e52aa8e09a14402f376070a44b1b85cb36d13', 'timestamp': '1733333658091'}
{'asset_id': '114416409796971863099144323163249651172534872992222856507897414949637892047507', 'changes': [{'price': '0.55', 'side': 'SELL', 'size': '1136.88'}], 'event_type': 'price_change', 'hash': 'c2ef400c024ebd0d0318687f084f5a0260021c1e', 'market': '0x7aa4a910b31b2c4ddb09d1e3408e52aa8e09a14402f376070a44b1b85cb36d13', 'timestamp': '1733333659283'}
{'asset_id': '114416409796971863099144323163249651172534872992222856507897414949637892047507', 'changes': [{'price': '0.55', 'side': 'SELL', 'size': '1136.88'}], 'event_type': 'price_change', 'hash': 'c2ef400c024ebd0d0318687f084f5a0260021c1e', 'market': '0x7aa4a910b31b2c4ddb09d1e3408e52aa8e09a14402f376070a44b1b85cb36d13', 'timestamp': '1733333659283'}
{'asset_id': '114416409796971863099144323163249651172534872992222856507897414949637892047507', 'changes': [{'price': '0.48', 'side': 'BUY', 'size': '792.18'}], 'event_type': 'price_change', 'hash': '1be24ef81c9cbea8aeae23c46d3d3e315cdc56a5', 'market': '0x7aa4a910b31b2c4ddb09d1e3408e52aa8e09a14402f376070a44b1b85cb36d13', 'timestamp': '1733333659776'}
{'asset_id': '114416409796971863099144323163249651172534872992222856507897414949637892047507', 'changes': [{'price': '0.48', 'side': 'BUY', 'size': '792.18'}], 'event_type': 'price_change', 'hash': '1be24ef81c9cbea8aeae23c46d3d3e315cdc56a5', 'market': '0x7aa4a910b31b2c4ddb09d1e3408e52aa8e09a14402f376070a44b1b85cb36d13', 'timestamp': '1733333659776'}
{'asset_id': '114416409796971863099144323163249651172534872992222856507897414949637892047507', 'changes': [{'price': '0.59', 'side': 'SELL', 'size': '2560'}], 'event_type': 'price_change', 'hash': 'b94a5f368bf1a2c0f0bdccdc8d7bec43bb5c28f2', 'market': '0x7aa4a910b31b2c4ddb09d1e3408e52aa8e09a14402f376070a44b1b85cb36d13', 'timestamp': '1733333660043'}
{'asset_id': '114416409796971863099144323163249651172534872992222856507897414949637892047507', 'changes': [{'price': '0.59', 'side': 'SELL', 'size': '2560'}], 'event_type': 'price_change', 'hash': 'b94a5f368bf1a2c0f0bdccdc8d7bec43bb5c28f2', 'market': '0x7aa4a910b31b2c4ddb09d1e3408e52aa8e09a14402f376070a44b1b85cb36d13', 'timestamp': '1733333660043'}
{'asset_id': '114416409796971863099144323163249651172534872992222856507897414949637892047507', 'changes': [{'price': '0.52', 'side': 'BUY', 'size': '3042.77'}, {'price': '0.55', 'side': 'SELL', 'size': '1086.88'}], 'event_type': 'price_change', 'hash': 'f4261070de08ade003d11659f6fa4c2c240e0d83', 'market': '0x7aa4a910b31b2c4ddb09d1e3408e52aa8e09a14402f376070a44b1b85cb36d13', 'timestamp': '1733333660309'}
{'asset_id': '114416409796971863099144323163249651172534872992222856507897414949637892047507', 'changes': [{'price': '0.52', 'side': 'BUY', 'size': '3042.77'}, {'price': '0.55', 'side': 'SELL', 'size': '1086.88'}], 'event_type': 'price_change', 'hash': 'f4261070de08ade003d11659f6fa4c2c240e0d83', 'market': '0x7aa4a910b31b2c4ddb09d1e3408e52aa8e09a14402f376070a44b1b85cb36d13', 'timestamp': '1733333660309'}
{'asset_id': '114416409796971863099144323163249651172534872992222856507897414949637892047507', 'changes': [{'price': '0.48', 'side': 'BUY', 'size': '742.18'}], 'event_type': 'price_change', 'hash': 'b373734c724ab692b2c23a7976903d3f1cbb4554', 'market': '0x7aa4a910b31b2c4ddb09d1e3408e52aa8e09a14402f376070a44b1b85cb36d13', 'timestamp': '1733333660801'}
{'asset_id': '114416409796971863099144323163249651172534872992222856507897414949637892047507', 'changes': [{'price': '0.48', 'side': 'BUY', 'size': '742.18'}], 'event_type': 'price_change', 'hash': 'b373734c724ab692b2c23a7976903d3f1cbb4554', 'market': '0x7aa4a910b31b2c4ddb09d1e3408e52aa8e09a14402f376070a44b1b85cb36d13', 'timestamp': '1733333660801'}
{'asset_id': '114416409796971863099144323163249651172534872992222856507897414949637892047507', 'changes': [{'price': '0.59', 'side': 'SELL', 'size': '2610'}], 'event_type': 'price_change', 'hash': 'aa94655e967f7735fc4f6ba728247d134171c8b0', 'market': '0x7aa4a910b31b2c4ddb09d1e3408e52aa8e09a14402f376070a44b1b85cb36d13', 'timestamp': '1733333661061'}
{'asset_id': '114416409796971863099144323163249651172534872992222856507897414949637892047507', 'changes': [{'price': '0.59', 'side': 'SELL', 'size': '2610'}], 'event_type': 'price_change', 'hash': 'aa94655e967f7735fc4f6ba728247d134171c8b0', 'market': '0x7aa4a910b31b2c4ddb09d1e3408e52aa8e09a14402f376070a44b1b85cb36d13', 'timestamp': '1733333661061'}
{'asset_id': '114416409796971863099144323163249651172534872992222856507897414949637892047507', 'changes': [{'price': '0.52', 'side': 'BUY', 'size': '3092.77'}], 'event_type': 'price_change', 'hash': 'd4020fe450405d1db45209f5ede72ee29157cf87', 'market': '0x7aa4a910b31b2c4ddb09d1e3408e52aa8e09a14402f376070a44b1b85cb36d13', 'timestamp': '1733333661311'}
{'asset_id': '114416409796971863099144323163249651172534872992222856507897414949637892047507', 'changes': [{'price': '0.52', 'side': 'BUY', 'size': '3092.77'}], 'event_type': 'price_change', 'hash': 'd4020fe450405d1db45209f5ede72ee29157cf87', 'market': '0x7aa4a910b31b2c4ddb09d1e3408e52aa8e09a14402f376070a44b1b85cb36d13', 'timestamp': '1733333661311'}
{'asset_id': '114416409796971863099144323163249651172534872992222856507897414949637892047507', 'changes': [{'price': '0.53', 'side': 'BUY', 'size': '23.99'}], 'event_type': 'price_change', 'hash': '08f58c0fa2fe23240b7299a8013f583e33c7b460', 'market': '0x7aa4a910b31b2c4ddb09d1e3408e52aa8e09a14402f376070a44b1b85cb36d13', 'timestamp': '1733333662290'}
{'asset_id': '114416409796971863099144323163249651172534872992222856507897414949637892047507', 'changes': [{'price': '0.53', 'side': 'BUY', 'size': '23.99'}], 'event_type': 'price_change', 'hash': '08f58c0fa2fe23240b7299a8013f583e33c7b460', 'market': '0x7aa4a910b31b2c4ddb09d1e3408e52aa8e09a14402f376070a44b1b85cb36d13', 'timestamp': '1733333662290'}
{'asset_id': '114416409796971863099144323163249651172534872992222856507897414949637892047507', 'changes': [{'price': '0.55', 'side': 'SELL', 'size': '1056.88'}], 'event_type': 'price_change', 'hash': '0c14d768b56e73cb8ad2f5322c8eba0ad2c6ef76', 'market': '0x7aa4a910b31b2c4ddb09d1e3408e52aa8e09a14402f376070a44b1b85cb36d13', 'timestamp': '1733333662824'}
{'asset_id': '114416409796971863099144323163249651172534872992222856507897414949637892047507', 'changes': [{'price': '0.55', 'side': 'SELL', 'size': '1056.88'}], 'event_type': 'price_change', 'hash': '0c14d768b56e73cb8ad2f5322c8eba0ad2c6ef76', 'market': '0x7aa4a910b31b2c4ddb09d1e3408e52aa8e09a14402f376070a44b1b85cb36d13', 'timestamp': '1733333662824'}
{'asset_id': '114416409796971863099144323163249651172534872992222856507897414949637892047507', 'changes': [{'price': '0.56', 'side': 'SELL', 'size': '1140.1'}], 'event_type': 'price_change', 'hash': '2eeac784f8ae3bd0504df0d4bc9f1b1da1085f8e', 'market': '0x7aa4a910b31b2c4ddb09d1e3408e52aa8e09a14402f376070a44b1b85cb36d13', 'timestamp': '1733333662985'}
{'asset_id': '114416409796971863099144323163249651172534872992222856507897414949637892047507', 'changes': [{'price': '0.56', 'side': 'SELL', 'size': '1140.1'}], 'event_type': 'price_change', 'hash': '2eeac784f8ae3bd0504df0d4bc9f1b1da1085f8e', 'market': '0x7aa4a910b31b2c4ddb09d1e3408e52aa8e09a14402f376070a44b1b85cb36d13', 'timestamp': '1733333662985'}
{'asset_id': '114416409796971863099144323163249651172534872992222856507897414949637892047507', 'changes': [{'price': '0.52', 'side': 'BUY', 'size': '3192.77'}], 'event_type': 'price_change', 'hash': '97c6a0040f9d600f81518ff134bdb0f78d624c69', 'market': '0x7aa4a910b31b2c4ddb09d1e3408e52aa8e09a14402f376070a44b1b85cb36d13', 'timestamp': '1733333663080'}
{'asset_id': '114416409796971863099144323163249651172534872992222856507897414949637892047507', 'changes': [{'price': '0.52', 'side': 'BUY', 'size': '3192.77'}], 'event_type': 'price_change', 'hash': '97c6a0040f9d600f81518ff134bdb0f78d624c69', 'market': '0x7aa4a910b31b2c4ddb09d1e3408e52aa8e09a14402f376070a44b1b85cb36d13', 'timestamp': '1733333663080'}
{'asset_id': '114416409796971863099144323163249651172534872992222856507897414949637892047507', 'changes': [{'price': '0.52', 'side': 'BUY', 'size': '3092.77'}], 'event_type': 'price_change', 'hash': '894d1a3944299a0414ceeea70373af6905d7e1c4', 'market': '0x7aa4a910b31b2c4ddb09d1e3408e52aa8e09a14402f376070a44b1b85cb36d13', 'timestamp': '1733333664177'}
{'asset_id': '114416409796971863099144323163249651172534872992222856507897414949637892047507', 'changes': [{'price': '0.52', 'side': 'BUY', 'size': '3092.77'}], 'event_type': 'price_change', 'hash': '894d1a3944299a0414ceeea70373af6905d7e1c4', 'market': '0x7aa4a910b31b2c4ddb09d1e3408e52aa8e09a14402f376070a44b1b85cb36d13', 'timestamp': '1733333664177'}
{'asset_id': '114416409796971863099144323163249651172534872992222856507897414949637892047507', 'changes': [{'price': '0.53', 'side': 'BUY', 'size': '123.99'}], 'event_type': 'price_change', 'hash': 'ba28377ded606aa0bff535802dfb830aca97b015', 'market': '0x7aa4a910b31b2c4ddb09d1e3408e52aa8e09a14402f376070a44b1b85cb36d13', 'timestamp': '1733333664752'}
{'asset_id': '114416409796971863099144323163249651172534872992222856507897414949637892047507', 'changes': [{'price': '0.53', 'side': 'BUY', 'size': '123.99'}], 'event_type': 'price_change', 'hash': 'ba28377ded606aa0bff535802dfb830aca97b015', 'market': '0x7aa4a910b31b2c4ddb09d1e3408e52aa8e09a14402f376070a44b1b85cb36d13', 'timestamp': '1733333664752'}
{'asset_id': '114416409796971863099144323163249651172534872992222856507897414949637892047507', 'changes': [{'price': '0.56', 'side': 'SELL', 'size': '1249.1'}], 'event_type': 'price_change', 'hash': 'abc5d8ad56a2bf37c70ccbeb329b26050a9abd68', 'market': '0x7aa4a910b31b2c4ddb09d1e3408e52aa8e09a14402f376070a44b1b85cb36d13', 'timestamp': '1733333672076'}
{'asset_id': '114416409796971863099144323163249651172534872992222856507897414949637892047507', 'changes': [{'price': '0.56', 'side': 'SELL', 'size': '1249.1'}], 'event_type': 'price_change', 'hash': 'abc5d8ad56a2bf37c70ccbeb329b26050a9abd68', 'market': '0x7aa4a910b31b2c4ddb09d1e3408e52aa8e09a14402f376070a44b1b85cb36d13', 'timestamp': '1733333672076'}
{'asset_id': '114416409796971863099144323163249651172534872992222856507897414949637892047507', 'changes': [{'price': '0.6', 'side': 'SELL', 'size': '467.85'}, {'price': '0.49', 'side': 'BUY', 'size': '390'}, {'price': '0.59', 'side': 'SELL', 'size': '110'}, {'price': '0.57', 'side': 'SELL', 'size': '610.1'}, {'price': '0.58', 'side': 'SELL', 'size': '1958.1'}], 'event_type': 'price_change', 'hash': 'ac5237afdade6ba662abba8daea4bd174c6570c9', 'market': '0x7aa4a910b31b2c4ddb09d1e3408e52aa8e09a14402f376070a44b1b85cb36d13', 'timestamp': '1733333672789'}
{'asset_id': '114416409796971863099144323163249651172534872992222856507897414949637892047507', 'changes': [{'price': '0.6', 'side': 'SELL', 'size': '467.85'}, {'price': '0.49', 'side': 'BUY', 'size': '390'}, {'price': '0.59', 'side': 'SELL', 'size': '110'}, {'price': '0.57', 'side': 'SELL', 'size': '610.1'}, {'price': '0.58', 'side': 'SELL', 'size': '1958.1'}], 'event_type': 'price_change', 'hash': 'ac5237afdade6ba662abba8daea4bd174c6570c9', 'market': '0x7aa4a910b31b2c4ddb09d1e3408e52aa8e09a14402f376070a44b1b85cb36d13', 'timestamp': '1733333672789'}
{'asset_id': '114416409796971863099144323163249651172534872992222856507897414949637892047507', 'changes': [{'price': '0.57', 'side': 'SELL', 'size': '110.1'}, {'price': '0.52', 'side': 'BUY', 'size': '2092.77'}, {'price': '0.48', 'side': 'BUY', 'size': '242.18'}], 'event_type': 'price_change', 'hash': '822f2d69b55732ba8329b099409b09ce01dbefd3', 'market': '0x7aa4a910b31b2c4ddb09d1e3408e52aa8e09a14402f376070a44b1b85cb36d13', 'timestamp': '1733333675550'}
{'asset_id': '114416409796971863099144323163249651172534872992222856507897414949637892047507', 'changes': [{'price': '0.57', 'side': 'SELL', 'size': '110.1'}, {'price': '0.52', 'side': 'BUY', 'size': '2092.77'}, {'price': '0.48', 'side': 'BUY', 'size': '242.18'}], 'event_type': 'price_change', 'hash': '822f2d69b55732ba8329b099409b09ce01dbefd3', 'market': '0x7aa4a910b31b2c4ddb09d1e3408e52aa8e09a14402f376070a44b1b85cb36d13', 'timestamp': '1733333675550'}
{'asset_id': '114416409796971863099144323163249651172534872992222856507897414949637892047507', 'changes': [{'price': '0.49', 'side': 'BUY', 'size': '890'}], 'event_type': 'price_change', 'hash': '00316c0bc58fe97e575736b6bfab3d09aa518792', 'market': '0x7aa4a910b31b2c4ddb09d1e3408e52aa8e09a14402f376070a44b1b85cb36d13', 'timestamp': '1733333676614'}
{'asset_id': '114416409796971863099144323163249651172534872992222856507897414949637892047507', 'changes': [{'price': '0.49', 'side': 'BUY', 'size': '890'}], 'event_type': 'price_change', 'hash': '00316c0bc58fe97e575736b6bfab3d09aa518792', 'market': '0x7aa4a910b31b2c4ddb09d1e3408e52aa8e09a14402f376070a44b1b85cb36d13', 'timestamp': '1733333676614'}
{'asset_id': '114416409796971863099144323163249651172534872992222856507897414949637892047507', 'changes': [{'price': '0.54', 'side': 'BUY', 'size': '50'}, {'price': '0.58', 'side': 'SELL', 'size': '2458.1'}], 'event_type': 'price_change', 'hash': 'f45bc94cbfffc1dc4c8f15af5a7e69a21ede7b14', 'market': '0x7aa4a910b31b2c4ddb09d1e3408e52aa8e09a14402f376070a44b1b85cb36d13', 'timestamp': '1733333676984'}
{'asset_id': '114416409796971863099144323163249651172534872992222856507897414949637892047507', 'changes': [{'price': '0.54', 'side': 'BUY', 'size': '50'}, {'price': '0.58', 'side': 'SELL', 'size': '2458.1'}], 'event_type': 'price_change', 'hash': 'f45bc94cbfffc1dc4c8f15af5a7e69a21ede7b14', 'market': '0x7aa4a910b31b2c4ddb09d1e3408e52aa8e09a14402f376070a44b1b85cb36d13', 'timestamp': '1733333676984'}
{'asset_id': '114416409796971863099144323163249651172534872992222856507897414949637892047507', 'changes': [{'price': '0.53', 'side': 'BUY', 'size': '1123.99'}], 'event_type': 'price_change', 'hash': '755eef97c0ea637cc0afd50cb7126c0da5af3d58', 'market': '0x7aa4a910b31b2c4ddb09d1e3408e52aa8e09a14402f376070a44b1b85cb36d13', 'timestamp': '1733333677348'}
{'asset_id': '114416409796971863099144323163249651172534872992222856507897414949637892047507', 'changes': [{'price': '0.53', 'side': 'BUY', 'size': '1123.99'}], 'event_type': 'price_change', 'hash': '755eef97c0ea637cc0afd50cb7126c0da5af3d58', 'market': '0x7aa4a910b31b2c4ddb09d1e3408e52aa8e09a14402f376070a44b1b85cb36d13', 'timestamp': '1733333677348'}
{'asset_id': '114416409796971863099144323163249651172534872992222856507897414949637892047507', 'changes': [{'price': '0.53', 'side': 'BUY', 'size': '1109'}, {'price': '0.54', 'side': 'BUY', 'size': '64.99'}], 'event_type': 'price_change', 'hash': 'a5ec5f8116a594b0010b3dc651fd233045acf3bf', 'market': '0x7aa4a910b31b2c4ddb09d1e3408e52aa8e09a14402f376070a44b1b85cb36d13', 'timestamp': '1733333677706'}
{'asset_id': '114416409796971863099144323163249651172534872992222856507897414949637892047507', 'changes': [{'price': '0.53', 'side': 'BUY', 'size': '1109'}, {'price': '0.54', 'side': 'BUY', 'size': '64.99'}], 'event_type': 'price_change', 'hash': 'a5ec5f8116a594b0010b3dc651fd233045acf3bf', 'market': '0x7aa4a910b31b2c4ddb09d1e3408e52aa8e09a14402f376070a44b1b85cb36d13', 'timestamp': '1733333677706'}
{'asset_id': '114416409796971863099144323163249651172534872992222856507897414949637892047507', 'changes': [{'price': '0.64', 'side': 'SELL', 'size': '4230.1'}, {'price': '0.62', 'side': 'SELL', 'size': '2800.1'}], 'event_type': 'price_change', 'hash': '87ec6f55196f8e181cc62d3a634c0672dbbc2f46', 'market': '0x7aa4a910b31b2c4ddb09d1e3408e52aa8e09a14402f376070a44b1b85cb36d13', 'timestamp': '1733333684243'}
{'asset_id': '114416409796971863099144323163249651172534872992222856507897414949637892047507', 'changes': [{'price': '0.64', 'side': 'SELL', 'size': '4230.1'}, {'price': '0.62', 'side': 'SELL', 'size': '2800.1'}], 'event_type': 'price_change', 'hash': '87ec6f55196f8e181cc62d3a634c0672dbbc2f46', 'market': '0x7aa4a910b31b2c4ddb09d1e3408e52aa8e09a14402f376070a44b1b85cb36d13', 'timestamp': '1733333684243'}
{'asset_id': '114416409796971863099144323163249651172534872992222856507897414949637892047507', 'changes': [{'price': '0.5', 'side': 'BUY', 'size': '2115'}, {'price': '0.61', 'side': 'SELL', 'size': '2511.06'}, {'price': '0.59', 'side': 'SELL', 'size': '1310'}], 'event_type': 'price_change', 'hash': 'e880770d4078e0acda879b36cb4c213ca89d7eda', 'market': '0x7aa4a910b31b2c4ddb09d1e3408e52aa8e09a14402f376070a44b1b85cb36d13', 'timestamp': '1733333684270'}
{'asset_id': '114416409796971863099144323163249651172534872992222856507897414949637892047507', 'changes': [{'price': '0.5', 'side': 'BUY', 'size': '2115'}, {'price': '0.61', 'side': 'SELL', 'size': '2511.06'}, {'price': '0.59', 'side': 'SELL', 'size': '1310'}], 'event_type': 'price_change', 'hash': 'e880770d4078e0acda879b36cb4c213ca89d7eda', 'market': '0x7aa4a910b31b2c4ddb09d1e3408e52aa8e09a14402f376070a44b1b85cb36d13', 'timestamp': '1733333684270'}
{'asset_id': '114416409796971863099144323163249651172534872992222856507897414949637892047507', 'changes': [{'price': '0.16', 'side': 'BUY', 'size': '3209.51'}], 'event_type': 'price_change', 'hash': '8d7738ca7c76a1d0cb073e7c0793c3e7836749a7', 'market': '0x7aa4a910b31b2c4ddb09d1e3408e52aa8e09a14402f376070a44b1b85cb36d13', 'timestamp': '1733333687837'}
{'asset_id': '114416409796971863099144323163249651172534872992222856507897414949637892047507', 'changes': [{'price': '0.16', 'side': 'BUY', 'size': '3209.51'}], 'event_type': 'price_change', 'hash': '8d7738ca7c76a1d0cb073e7c0793c3e7836749a7', 'market': '0x7aa4a910b31b2c4ddb09d1e3408e52aa8e09a14402f376070a44b1b85cb36d13', 'timestamp': '1733333687837'}
{'asset_id': '114416409796971863099144323163249651172534872992222856507897414949637892047507', 'changes': [{'price': '0.58', 'side': 'SELL', 'size': '2188.1'}, {'price': '0.49', 'side': 'BUY', 'size': '640'}], 'event_type': 'price_change', 'hash': '5516a796b3383f33661f40f7e0d04c8ab481604d', 'market': '0x7aa4a910b31b2c4ddb09d1e3408e52aa8e09a14402f376070a44b1b85cb36d13', 'timestamp': '1733333689751'}
{'asset_id': '114416409796971863099144323163249651172534872992222856507897414949637892047507', 'changes': [{'price': '0.58', 'side': 'SELL', 'size': '2188.1'}, {'price': '0.49', 'side': 'BUY', 'size': '640'}], 'event_type': 'price_change', 'hash': '5516a796b3383f33661f40f7e0d04c8ab481604d', 'market': '0x7aa4a910b31b2c4ddb09d1e3408e52aa8e09a14402f376070a44b1b85cb36d13', 'timestamp': '1733333689751'}
{'asset_id': '114416409796971863099144323163249651172534872992222856507897414949637892047507', 'changes': [{'price': '0.59', 'side': 'SELL', 'size': '1580'}], 'event_type': 'price_change', 'hash': '86e6f5dd5f67e529780a92742a3f77faadb58825', 'market': '0x7aa4a910b31b2c4ddb09d1e3408e52aa8e09a14402f376070a44b1b85cb36d13', 'timestamp': '1733333690018'}
{'asset_id': '114416409796971863099144323163249651172534872992222856507897414949637892047507', 'changes': [{'price': '0.59', 'side': 'SELL', 'size': '1580'}], 'event_type': 'price_change', 'hash': '86e6f5dd5f67e529780a92742a3f77faadb58825', 'market': '0x7aa4a910b31b2c4ddb09d1e3408e52aa8e09a14402f376070a44b1b85cb36d13', 'timestamp': '1733333690018'}
{'asset_id': '114416409796971863099144323163249651172534872992222856507897414949637892047507', 'changes': [{'price': '0.5', 'side': 'BUY', 'size': '2355'}], 'event_type': 'price_change', 'hash': '960a3bf4f3d50d8bd8e0f67b239fb9d654649724', 'market': '0x7aa4a910b31b2c4ddb09d1e3408e52aa8e09a14402f376070a44b1b85cb36d13', 'timestamp': '1733333690096'}
{'asset_id': '114416409796971863099144323163249651172534872992222856507897414949637892047507', 'changes': [{'price': '0.5', 'side': 'BUY', 'size': '2355'}], 'event_type': 'price_change', 'hash': '960a3bf4f3d50d8bd8e0f67b239fb9d654649724', 'market': '0x7aa4a910b31b2c4ddb09d1e3408e52aa8e09a14402f376070a44b1b85cb36d13', 'timestamp': '1733333690096'}
{'asset_id': '114416409796971863099144323163249651172534872992222856507897414949637892047507', 'changes': [{'price': '0.52', 'side': 'BUY', 'size': '2062.77'}], 'event_type': 'price_change', 'hash': '0385bc20440c6a01b17579bd6fbb332b52ecbc1b', 'market': '0x7aa4a910b31b2c4ddb09d1e3408e52aa8e09a14402f376070a44b1b85cb36d13', 'timestamp': '1733333693539'}
{'asset_id': '114416409796971863099144323163249651172534872992222856507897414949637892047507', 'changes': [{'price': '0.52', 'side': 'BUY', 'size': '2062.77'}], 'event_type': 'price_change', 'hash': '0385bc20440c6a01b17579bd6fbb332b52ecbc1b', 'market': '0x7aa4a910b31b2c4ddb09d1e3408e52aa8e09a14402f376070a44b1b85cb36d13', 'timestamp': '1733333693539'}
{'asset_id': '114416409796971863099144323163249651172534872992222856507897414949637892047507', 'changes': [{'price': '0.53', 'side': 'BUY', 'size': '1139'}], 'event_type': 'price_change', 'hash': '3a7658222531de9c20088aeaa214d4ea3eec6721', 'market': '0x7aa4a910b31b2c4ddb09d1e3408e52aa8e09a14402f376070a44b1b85cb36d13', 'timestamp': '1733333693657'}
{'asset_id': '114416409796971863099144323163249651172534872992222856507897414949637892047507', 'changes': [{'price': '0.53', 'side': 'BUY', 'size': '1139'}], 'event_type': 'price_change', 'hash': '3a7658222531de9c20088aeaa214d4ea3eec6721', 'market': '0x7aa4a910b31b2c4ddb09d1e3408e52aa8e09a14402f376070a44b1b85cb36d13', 'timestamp': '1733333693657'}
{'asset_id': '114416409796971863099144323163249651172534872992222856507897414949637892047507', 'changes': [{'price': '0.87', 'side': 'SELL', 'size': '3229'}], 'event_type': 'price_change', 'hash': '59ae172f44a341d40c121961152b361d3b4298b8', 'market': '0x7aa4a910b31b2c4ddb09d1e3408e52aa8e09a14402f376070a44b1b85cb36d13', 'timestamp': '1733333696487'}
{'asset_id': '114416409796971863099144323163249651172534872992222856507897414949637892047507', 'changes': [{'price': '0.87', 'side': 'SELL', 'size': '3229'}], 'event_type': 'price_change', 'hash': '59ae172f44a341d40c121961152b361d3b4298b8', 'market': '0x7aa4a910b31b2c4ddb09d1e3408e52aa8e09a14402f376070a44b1b85cb36d13', 'timestamp': '1733333696487'}
{'asset_id': '114416409796971863099144323163249651172534872992222856507897414949637892047507', 'changes': [{'price': '0.1', 'side': 'BUY', 'size': '6205'}], 'event_type': 'price_change', 'hash': '5108187f2557df09ce448811896bd2c25ddc9368', 'market': '0x7aa4a910b31b2c4ddb09d1e3408e52aa8e09a14402f376070a44b1b85cb36d13', 'timestamp': '1733333696634'}
{'asset_id': '114416409796971863099144323163249651172534872992222856507897414949637892047507', 'changes': [{'price': '0.1', 'side': 'BUY', 'size': '6205'}], 'event_type': 'price_change', 'hash': '5108187f2557df09ce448811896bd2c25ddc9368', 'market': '0x7aa4a910b31b2c4ddb09d1e3408e52aa8e09a14402f376070a44b1b85cb36d13', 'timestamp': '1733333696634'}
{'asset_id': '114416409796971863099144323163249651172534872992222856507897414949637892047507', 'changes': [{'price': '0.16', 'side': 'BUY', 'size': '4709.51'}], 'event_type': 'price_change', 'hash': 'e1932fc0d0fe0ef565091de765480d99ff3026a8', 'market': '0x7aa4a910b31b2c4ddb09d1e3408e52aa8e09a14402f376070a44b1b85cb36d13', 'timestamp': '1733333721972'}
{'asset_id': '114416409796971863099144323163249651172534872992222856507897414949637892047507', 'changes': [{'price': '0.16', 'side': 'BUY', 'size': '4709.51'}], 'event_type': 'price_change', 'hash': 'e1932fc0d0fe0ef565091de765480d99ff3026a8', 'market': '0x7aa4a910b31b2c4ddb09d1e3408e52aa8e09a14402f376070a44b1b85cb36d13', 'timestamp': '1733333721972'}
{'asset_id': '114416409796971863099144323163249651172534872992222856507897414949637892047507', 'changes': [{'price': '0.49', 'side': 'BUY', 'size': '140'}, {'price': '0.58', 'side': 'SELL', 'size': '1688.1'}, {'price': '0.53', 'side': 'BUY', 'size': '139'}], 'event_type': 'price_change', 'hash': 'd71892f516d70a4c2ca81ac0d02a124857be99e8', 'market': '0x7aa4a910b31b2c4ddb09d1e3408e52aa8e09a14402f376070a44b1b85cb36d13', 'timestamp': '1733333737155'}
{'asset_id': '114416409796971863099144323163249651172534872992222856507897414949637892047507', 'changes': [{'price': '0.49', 'side': 'BUY', 'size': '140'}, {'price': '0.58', 'side': 'SELL', 'size': '1688.1'}, {'price': '0.53', 'side': 'BUY', 'size': '139'}], 'event_type': 'price_change', 'hash': 'd71892f516d70a4c2ca81ac0d02a124857be99e8', 'market': '0x7aa4a910b31b2c4ddb09d1e3408e52aa8e09a14402f376070a44b1b85cb36d13', 'timestamp': '1733333737155'}
{'asset_id': '114416409796971863099144323163249651172534872992222856507897414949637892047507', 'changes': [{'price': '0.59', 'side': 'SELL', 'size': '380'}], 'event_type': 'price_change', 'hash': 'b7f614e05e50cf7320fcbf489c0074935b60e8ae', 'market': '0x7aa4a910b31b2c4ddb09d1e3408e52aa8e09a14402f376070a44b1b85cb36d13', 'timestamp': '1733333737253'}
{'asset_id': '114416409796971863099144323163249651172534872992222856507897414949637892047507', 'changes': [{'price': '0.59', 'side': 'SELL', 'size': '380'}], 'event_type': 'price_change', 'hash': 'b7f614e05e50cf7320fcbf489c0074935b60e8ae', 'market': '0x7aa4a910b31b2c4ddb09d1e3408e52aa8e09a14402f376070a44b1b85cb36d13', 'timestamp': '1733333737253'}
{'asset_id': '114416409796971863099144323163249651172534872992222856507897414949637892047507', 'changes': [{'price': '0.48', 'side': 'BUY', 'size': '742.18'}], 'event_type': 'price_change', 'hash': 'ecf56552bfd2e19aebb35e17bb2aa53f5e97c470', 'market': '0x7aa4a910b31b2c4ddb09d1e3408e52aa8e09a14402f376070a44b1b85cb36d13', 'timestamp': '1733333738207'}
{'asset_id': '114416409796971863099144323163249651172534872992222856507897414949637892047507', 'changes': [{'price': '0.48', 'side': 'BUY', 'size': '742.18'}], 'event_type': 'price_change', 'hash': 'ecf56552bfd2e19aebb35e17bb2aa53f5e97c470', 'market': '0x7aa4a910b31b2c4ddb09d1e3408e52aa8e09a14402f376070a44b1b85cb36d13', 'timestamp': '1733333738207'}
{'asset_id': '114416409796971863099144323163249651172534872992222856507897414949637892047507', 'changes': [{'price': '0.57', 'side': 'SELL', 'size': '610.1'}], 'event_type': 'price_change', 'hash': '1cf417a1214bd3b510de5eafb32952a21e870b1e', 'market': '0x7aa4a910b31b2c4ddb09d1e3408e52aa8e09a14402f376070a44b1b85cb36d13', 'timestamp': '1733333738630'}
{'asset_id': '114416409796971863099144323163249651172534872992222856507897414949637892047507', 'changes': [{'price': '0.57', 'side': 'SELL', 'size': '610.1'}], 'event_type': 'price_change', 'hash': '1cf417a1214bd3b510de5eafb32952a21e870b1e', 'market': '0x7aa4a910b31b2c4ddb09d1e3408e52aa8e09a14402f376070a44b1b85cb36d13', 'timestamp': '1733333738630'}
{'asset_id': '114416409796971863099144323163249651172534872992222856507897414949637892047507', 'changes': [{'price': '0.53', 'side': 'BUY', 'size': '1139'}], 'event_type': 'price_change', 'hash': 'd999fd9a7b22ec2d1513e53c4d980cd35c740eaf', 'market': '0x7aa4a910b31b2c4ddb09d1e3408e52aa8e09a14402f376070a44b1b85cb36d13', 'timestamp': '1733333738999'}
{'asset_id': '114416409796971863099144323163249651172534872992222856507897414949637892047507', 'changes': [{'price': '0.53', 'side': 'BUY', 'size': '1139'}], 'event_type': 'price_change', 'hash': 'd999fd9a7b22ec2d1513e53c4d980cd35c740eaf', 'market': '0x7aa4a910b31b2c4ddb09d1e3408e52aa8e09a14402f376070a44b1b85cb36d13', 'timestamp': '1733333738999'}
{'asset_id': '114416409796971863099144323163249651172534872992222856507897414949637892047507', 'changes': [{'price': '0.58', 'side': 'SELL', 'size': '2888.1'}], 'event_type': 'price_change', 'hash': '08e4671f0760a152ee3cdf41593b2cd8ff603392', 'market': '0x7aa4a910b31b2c4ddb09d1e3408e52aa8e09a14402f376070a44b1b85cb36d13', 'timestamp': '1733333742868'}
{'asset_id': '114416409796971863099144323163249651172534872992222856507897414949637892047507', 'changes': [{'price': '0.58', 'side': 'SELL', 'size': '2888.1'}], 'event_type': 'price_change', 'hash': '08e4671f0760a152ee3cdf41593b2cd8ff603392', 'market': '0x7aa4a910b31b2c4ddb09d1e3408e52aa8e09a14402f376070a44b1b85cb36d13', 'timestamp': '1733333742868'}
{'asset_id': '114416409796971863099144323163249651172534872992222856507897414949637892047507', 'changes': [{'price': '0.53', 'side': 'BUY', 'size': '1039'}], 'event_type': 'price_change', 'hash': '9578e227df26a85226b8dd912a220a8db5c59fda', 'market': '0x7aa4a910b31b2c4ddb09d1e3408e52aa8e09a14402f376070a44b1b85cb36d13', 'timestamp': '1733333749074'}
{'asset_id': '114416409796971863099144323163249651172534872992222856507897414949637892047507', 'changes': [{'price': '0.53', 'side': 'BUY', 'size': '1039'}], 'event_type': 'price_change', 'hash': '9578e227df26a85226b8dd912a220a8db5c59fda', 'market': '0x7aa4a910b31b2c4ddb09d1e3408e52aa8e09a14402f376070a44b1b85cb36d13', 'timestamp': '1733333749074'}
{'asks': [{'price': '0.99', 'size': '4217.01'}, {'price': '0.98', 'size': '505'}, {'price': '0.97', 'size': '511.03'}, {'price': '0.96', 'size': '300'}, {'price': '0.95', 'size': '657.12'}, {'price': '0.94', 'size': '300'}, {'price': '0.92', 'size': '20000.45'}, {'price': '0.91', 'size': '10406.3'}, {'price': '0.9', 'size': '4587.5'}, {'price': '0.89', 'size': '13017.18'}, {'price': '0.88', 'size': '200'}, {'price': '0.87', 'size': '3229'}, {'price': '0.86', 'size': '17.1'}, {'price': '0.85', 'size': '109.68'}, {'price': '0.84', 'size': '250'}, {'price': '0.83', 'size': '100'}, {'price': '0.82', 'size': '16029'}, {'price': '0.81', 'size': '45721.39'}, {'price': '0.8', 'size': '26531'}, {'price': '0.79', 'size': '7110'}, {'price': '0.78', 'size': '10350'}, {'price': '0.77', 'size': '67'}, {'price': '0.76', 'size': '200'}, {'price': '0.75', 'size': '18329.25'}, {'price': '0.74', 'size': '11370.7'}, {'price': '0.73', 'size': '5020.1'}, {'price': '0.72', 'size': '380.52'}, {'price': '0.71', 'size': '15073.2'}, {'price': '0.7', 'size': '5570.1'}, {'price': '0.69', 'size': '6088.6'}, {'price': '0.68', 'size': '6131.34'}, {'price': '0.67', 'size': '3010.1'}, {'price': '0.66', 'size': '510.1'}, {'price': '0.65', 'size': '1010.1'}, {'price': '0.64', 'size': '4230.1'}, {'price': '0.63', 'size': '210.1'}, {'price': '0.62', 'size': '2800.1'}, {'price': '0.61', 'size': '2511.06'}, {'price': '0.6', 'size': '467.85'}, {'price': '0.59', 'size': '380'}, {'price': '0.58', 'size': '2888.1'}, {'price': '0.57', 'size': '610.1'}, {'price': '0.56', 'size': '1249.1'}, {'price': '0.55', 'size': '1006.88'}], 'asset_id': '114416409796971863099144323163249651172534872992222856507897414949637892047507', 'bids': [{'price': '0.01', 'size': '2850.27'}, {'price': '0.02', 'size': '500'}, {'price': '0.03', 'size': '500'}, {'price': '0.04', 'size': '300'}, {'price': '0.05', 'size': '320'}, {'price': '0.06', 'size': '300'}, {'price': '0.08', 'size': '250'}, {'price': '0.09', 'size': '300'}, {'price': '0.1', 'size': '6205'}, {'price': '0.12', 'size': '200'}, {'price': '0.13', 'size': '426.92'}, {'price': '0.14', 'size': '15'}, {'price': '0.15', 'size': '110'}, {'price': '0.16', 'size': '4709.51'}, {'price': '0.18', 'size': '19.13'}, {'price': '0.19', 'size': '120'}, {'price': '0.2', 'size': '691.17'}, {'price': '0.24', 'size': '5027'}, {'price': '0.25', 'size': '86.66'}, {'price': '0.27', 'size': '215.25'}, {'price': '0.29', 'size': '1102.28'}, {'price': '0.31', 'size': '1130.65'}, {'price': '0.32', 'size': '200'}, {'price': '0.33', 'size': '620'}, {'price': '0.34', 'size': '4000'}, {'price': '0.35', 'size': '232'}, {'price': '0.39', 'size': '10.5'}, {'price': '0.4', 'size': '3135'}, {'price': '0.41', 'size': '20'}, {'price': '0.42', 'size': '3050'}, {'price': '0.43', 'size': '50'}, {'price': '0.44', 'size': '3660'}, {'price': '0.45', 'size': '478'}, {'price': '0.47', 'size': '2797.23'}, {'price': '0.48', 'size': '742.18'}, {'price': '0.49', 'size': '140'}, {'price': '0.5', 'size': '2355'}, {'price': '0.51', 'size': '2586.18'}, {'price': '0.52', 'size': '2062.77'}, {'price': '0.53', 'size': '1039'}, {'price': '0.54', 'size': '164.99'}], 'event_type': 'book', 'hash': 'ccbebe1c869238d63c82953b9287f8411f38974a', 'market': '0x7aa4a910b31b2c4ddb09d1e3408e52aa8e09a14402f376070a44b1b85cb36d13', 'timestamp': '1733333750296'}
{'asset_id': '114416409796971863099144323163249651172534872992222856507897414949637892047507', 'changes': [{'price': '0.54', 'side': 'BUY', 'size': '164.99'}], 'event_type': 'price_change', 'hash': 'ccbebe1c869238d63c82953b9287f8411f38974a', 'market': '0x7aa4a910b31b2c4ddb09d1e3408e52aa8e09a14402f376070a44b1b85cb36d13', 'timestamp': '1733333750304'}
{'asks': [{'price': '0.99', 'size': '4217.01'}, {'price': '0.98', 'size': '505'}, {'price': '0.97', 'size': '511.03'}, {'price': '0.96', 'size': '300'}, {'price': '0.95', 'size': '657.12'}, {'price': '0.94', 'size': '300'}, {'price': '0.92', 'size': '20000.45'}, {'price': '0.91', 'size': '10406.3'}, {'price': '0.9', 'size': '4587.5'}, {'price': '0.89', 'size': '13017.18'}, {'price': '0.88', 'size': '200'}, {'price': '0.87', 'size': '3229'}, {'price': '0.86', 'size': '17.1'}, {'price': '0.85', 'size': '109.68'}, {'price': '0.84', 'size': '250'}, {'price': '0.83', 'size': '100'}, {'price': '0.82', 'size': '16029'}, {'price': '0.81', 'size': '45721.39'}, {'price': '0.8', 'size': '26531'}, {'price': '0.79', 'size': '7110'}, {'price': '0.78', 'size': '10350'}, {'price': '0.77', 'size': '67'}, {'price': '0.76', 'size': '200'}, {'price': '0.75', 'size': '18329.25'}, {'price': '0.74', 'size': '11370.7'}, {'price': '0.73', 'size': '5020.1'}, {'price': '0.72', 'size': '380.52'}, {'price': '0.71', 'size': '15073.2'}, {'price': '0.7', 'size': '5570.1'}, {'price': '0.69', 'size': '6088.6'}, {'price': '0.68', 'size': '6131.34'}, {'price': '0.67', 'size': '3010.1'}, {'price': '0.66', 'size': '510.1'}, {'price': '0.65', 'size': '1010.1'}, {'price': '0.64', 'size': '4230.1'}, {'price': '0.63', 'size': '210.1'}, {'price': '0.62', 'size': '2800.1'}, {'price': '0.61', 'size': '2511.06'}, {'price': '0.6', 'size': '467.85'}, {'price': '0.59', 'size': '380'}, {'price': '0.58', 'size': '2888.1'}, {'price': '0.57', 'size': '610.1'}, {'price': '0.56', 'size': '1249.1'}, {'price': '0.55', 'size': '1006.88'}], 'asset_id': '114416409796971863099144323163249651172534872992222856507897414949637892047507', 'bids': [{'price': '0.01', 'size': '2850.27'}, {'price': '0.02', 'size': '500'}, {'price': '0.03', 'size': '500'}, {'price': '0.04', 'size': '300'}, {'price': '0.05', 'size': '320'}, {'price': '0.06', 'size': '300'}, {'price': '0.08', 'size': '250'}, {'price': '0.09', 'size': '300'}, {'price': '0.1', 'size': '6205'}, {'price': '0.12', 'size': '200'}, {'price': '0.13', 'size': '426.92'}, {'price': '0.14', 'size': '15'}, {'price': '0.15', 'size': '110'}, {'price': '0.16', 'size': '4709.51'}, {'price': '0.18', 'size': '19.13'}, {'price': '0.19', 'size': '120'}, {'price': '0.2', 'size': '691.17'}, {'price': '0.24', 'size': '5027'}, {'price': '0.25', 'size': '86.66'}, {'price': '0.27', 'size': '215.25'}, {'price': '0.29', 'size': '1102.28'}, {'price': '0.31', 'size': '1130.65'}, {'price': '0.32', 'size': '200'}, {'price': '0.33', 'size': '620'}, {'price': '0.34', 'size': '4000'}, {'price': '0.35', 'size': '232'}, {'price': '0.39', 'size': '10.5'}, {'price': '0.4', 'size': '3135'}, {'price': '0.41', 'size': '20'}, {'price': '0.42', 'size': '3050'}, {'price': '0.43', 'size': '50'}, {'price': '0.44', 'size': '3660'}, {'price': '0.45', 'size': '478'}, {'price': '0.47', 'size': '2797.23'}, {'price': '0.48', 'size': '742.18'}, {'price': '0.49', 'size': '140'}, {'price': '0.5', 'size': '2355'}, {'price': '0.51', 'size': '2586.18'}, {'price': '0.52', 'size': '2062.77'}, {'price': '0.53', 'size': '1039'}, {'price': '0.54', 'size': '164.99'}], 'event_type': 'book', 'hash': 'ccbebe1c869238d63c82953b9287f8411f38974a', 'market': '0x7aa4a910b31b2c4ddb09d1e3408e52aa8e09a14402f376070a44b1b85cb36d13', 'timestamp': '1733333750296'}
{'asset_id': '114416409796971863099144323163249651172534872992222856507897414949637892047507', 'changes': [{'price': '0.54', 'side': 'BUY', 'size': '164.99'}], 'event_type': 'price_change', 'hash': 'ccbebe1c869238d63c82953b9287f8411f38974a', 'market': '0x7aa4a910b31b2c4ddb09d1e3408e52aa8e09a14402f376070a44b1b85cb36d13', 'timestamp': '1733333750304'}
{'asset_id': '114416409796971863099144323163249651172534872992222856507897414949637892047507', 'changes': [{'price': '0.54', 'side': 'BUY', 'size': '64.99'}], 'event_type': 'price_change', 'hash': '81527d1c872d2c084ac601bd8afcd5f7fbf983ef', 'market': '0x7aa4a910b31b2c4ddb09d1e3408e52aa8e09a14402f376070a44b1b85cb36d13', 'timestamp': '1733333750901'}
{'asset_id': '114416409796971863099144323163249651172534872992222856507897414949637892047507', 'changes': [{'price': '0.54', 'side': 'BUY', 'size': '64.99'}], 'event_type': 'price_change', 'hash': '81527d1c872d2c084ac601bd8afcd5f7fbf983ef', 'market': '0x7aa4a910b31b2c4ddb09d1e3408e52aa8e09a14402f376070a44b1b85cb36d13', 'timestamp': '1733333750901'}
{'asset_id': '114416409796971863099144323163249651172534872992222856507897414949637892047507', 'changes': [{'price': '0.53', 'side': 'BUY', 'size': '1139'}], 'event_type': 'price_change', 'hash': '6d250fcacd9644df9a8453a662f94c1885e05f68', 'market': '0x7aa4a910b31b2c4ddb09d1e3408e52aa8e09a14402f376070a44b1b85cb36d13', 'timestamp': '1733333751795'}
{'asset_id': '114416409796971863099144323163249651172534872992222856507897414949637892047507', 'changes': [{'price': '0.53', 'side': 'BUY', 'size': '1139'}], 'event_type': 'price_change', 'hash': '6d250fcacd9644df9a8453a662f94c1885e05f68', 'market': '0x7aa4a910b31b2c4ddb09d1e3408e52aa8e09a14402f376070a44b1b85cb36d13', 'timestamp': '1733333751795'}
{'asset_id': '114416409796971863099144323163249651172534872992222856507897414949637892047507', 'changes': [{'price': '0.48', 'side': 'BUY', 'size': '242.18'}, {'price': '0.53', 'side': 'BUY', 'size': '139'}, {'price': '0.57', 'side': 'SELL', 'size': '110.1'}], 'event_type': 'price_change', 'hash': 'ae27f3d8e5fcde37758e718645e17ab66b54cbe6', 'market': '0x7aa4a910b31b2c4ddb09d1e3408e52aa8e09a14402f376070a44b1b85cb36d13', 'timestamp': '1733333753636'}
{'asset_id': '114416409796971863099144323163249651172534872992222856507897414949637892047507', 'changes': [{'price': '0.48', 'side': 'BUY', 'size': '242.18'}, {'price': '0.53', 'side': 'BUY', 'size': '139'}, {'price': '0.57', 'side': 'SELL', 'size': '110.1'}], 'event_type': 'price_change', 'hash': 'ae27f3d8e5fcde37758e718645e17ab66b54cbe6', 'market': '0x7aa4a910b31b2c4ddb09d1e3408e52aa8e09a14402f376070a44b1b85cb36d13', 'timestamp': '1733333753636'}
{'asset_id': '114416409796971863099144323163249651172534872992222856507897414949637892047507', 'changes': [{'price': '0.49', 'side': 'BUY', 'size': '640'}], 'event_type': 'price_change', 'hash': '8a275966a6bdecc88418f088f1be33029b05f56d', 'market': '0x7aa4a910b31b2c4ddb09d1e3408e52aa8e09a14402f376070a44b1b85cb36d13', 'timestamp': '1733333754703'}
{'asset_id': '114416409796971863099144323163249651172534872992222856507897414949637892047507', 'changes': [{'price': '0.49', 'side': 'BUY', 'size': '640'}], 'event_type': 'price_change', 'hash': '8a275966a6bdecc88418f088f1be33029b05f56d', 'market': '0x7aa4a910b31b2c4ddb09d1e3408e52aa8e09a14402f376070a44b1b85cb36d13', 'timestamp': '1733333754703'}
{'asset_id': '114416409796971863099144323163249651172534872992222856507897414949637892047507', 'changes': [{'price': '0.58', 'side': 'SELL', 'size': '3388.1'}], 'event_type': 'price_change', 'hash': '22103f4424b549a969bc06246d931e93b5b4e8a8', 'market': '0x7aa4a910b31b2c4ddb09d1e3408e52aa8e09a14402f376070a44b1b85cb36d13', 'timestamp': '1733333755068'}
{'asset_id': '114416409796971863099144323163249651172534872992222856507897414949637892047507', 'changes': [{'price': '0.58', 'side': 'SELL', 'size': '3388.1'}], 'event_type': 'price_change', 'hash': '22103f4424b549a969bc06246d931e93b5b4e8a8', 'market': '0x7aa4a910b31b2c4ddb09d1e3408e52aa8e09a14402f376070a44b1b85cb36d13', 'timestamp': '1733333755068'}
{'asset_id': '114416409796971863099144323163249651172534872992222856507897414949637892047507', 'changes': [{'price': '0.53', 'side': 'BUY', 'size': '1139'}], 'event_type': 'price_change', 'hash': '735c1a953589c6f2540debb7b06674cc6a61cafc', 'market': '0x7aa4a910b31b2c4ddb09d1e3408e52aa8e09a14402f376070a44b1b85cb36d13', 'timestamp': '1733333755432'}
{'asset_id': '114416409796971863099144323163249651172534872992222856507897414949637892047507', 'changes': [{'price': '0.53', 'side': 'BUY', 'size': '1139'}], 'event_type': 'price_change', 'hash': '735c1a953589c6f2540debb7b06674cc6a61cafc', 'market': '0x7aa4a910b31b2c4ddb09d1e3408e52aa8e09a14402f376070a44b1b85cb36d13', 'timestamp': '1733333755432'}
{'asset_id': '114416409796971863099144323163249651172534872992222856507897414949637892047507', 'changes': [{'price': '0.53', 'side': 'BUY', 'size': '1039'}], 'event_type': 'price_change', 'hash': 'bc84a049dfcc97cd53f032df0564df5d5ed2903b', 'market': '0x7aa4a910b31b2c4ddb09d1e3408e52aa8e09a14402f376070a44b1b85cb36d13', 'timestamp': '1733333756098'}
{'asset_id': '114416409796971863099144323163249651172534872992222856507897414949637892047507', 'changes': [{'price': '0.53', 'side': 'BUY', 'size': '1039'}], 'event_type': 'price_change', 'hash': 'bc84a049dfcc97cd53f032df0564df5d5ed2903b', 'market': '0x7aa4a910b31b2c4ddb09d1e3408e52aa8e09a14402f376070a44b1b85cb36d13', 'timestamp': '1733333756098'}
{'asset_id': '114416409796971863099144323163249651172534872992222856507897414949637892047507', 'changes': [{'price': '0.54', 'side': 'BUY', 'size': '164.99'}], 'event_type': 'price_change', 'hash': '4edadc70e70a36ba512a7884e57a99c2db5283c5', 'market': '0x7aa4a910b31b2c4ddb09d1e3408e52aa8e09a14402f376070a44b1b85cb36d13', 'timestamp': '1733333757092'}
{'asset_id': '114416409796971863099144323163249651172534872992222856507897414949637892047507', 'changes': [{'price': '0.54', 'side': 'BUY', 'size': '164.99'}], 'event_type': 'price_change', 'hash': '4edadc70e70a36ba512a7884e57a99c2db5283c5', 'market': '0x7aa4a910b31b2c4ddb09d1e3408e52aa8e09a14402f376070a44b1b85cb36d13', 'timestamp': '1733333757092'}
{'asset_id': '114416409796971863099144323163249651172534872992222856507897414949637892047507', 'changes': [{'price': '0.54', 'side': 'BUY', 'size': '64.99'}], 'event_type': 'price_change', 'hash': '99611f967ba026abd6edd2175f28e2512ed397bb', 'market': '0x7aa4a910b31b2c4ddb09d1e3408e52aa8e09a14402f376070a44b1b85cb36d13', 'timestamp': '1733333757722'}
{'asset_id': '114416409796971863099144323163249651172534872992222856507897414949637892047507', 'changes': [{'price': '0.54', 'side': 'BUY', 'size': '64.99'}], 'event_type': 'price_change', 'hash': '99611f967ba026abd6edd2175f28e2512ed397bb', 'market': '0x7aa4a910b31b2c4ddb09d1e3408e52aa8e09a14402f376070a44b1b85cb36d13', 'timestamp': '1733333757722'}
{'asset_id': '114416409796971863099144323163249651172534872992222856507897414949637892047507', 'changes': [{'price': '0.53', 'side': 'BUY', 'size': '1139'}], 'event_type': 'price_change', 'hash': '8a195d94deee0bd4d08cb62232f91bdfcc451b0b', 'market': '0x7aa4a910b31b2c4ddb09d1e3408e52aa8e09a14402f376070a44b1b85cb36d13', 'timestamp': '1733333758613'}
{'asset_id': '114416409796971863099144323163249651172534872992222856507897414949637892047507', 'changes': [{'price': '0.53', 'side': 'BUY', 'size': '1139'}], 'event_type': 'price_change', 'hash': '8a195d94deee0bd4d08cb62232f91bdfcc451b0b', 'market': '0x7aa4a910b31b2c4ddb09d1e3408e52aa8e09a14402f376070a44b1b85cb36d13', 'timestamp': '1733333758613'}
{'asks': [{'price': '0.99', 'size': '4217.01'}, {'price': '0.98', 'size': '505'}, {'price': '0.97', 'size': '511.03'}, {'price': '0.96', 'size': '300'}, {'price': '0.95', 'size': '657.12'}, {'price': '0.94', 'size': '300'}, {'price': '0.92', 'size': '20000.45'}, {'price': '0.91', 'size': '10406.3'}, {'price': '0.9', 'size': '4587.5'}, {'price': '0.89', 'size': '13017.18'}, {'price': '0.88', 'size': '200'}, {'price': '0.87', 'size': '3229'}, {'price': '0.86', 'size': '17.1'}, {'price': '0.85', 'size': '109.68'}, {'price': '0.84', 'size': '250'}, {'price': '0.83', 'size': '100'}, {'price': '0.82', 'size': '16029'}, {'price': '0.81', 'size': '45721.39'}, {'price': '0.8', 'size': '26531'}, {'price': '0.79', 'size': '7110'}, {'price': '0.78', 'size': '10350'}, {'price': '0.77', 'size': '67'}, {'price': '0.76', 'size': '200'}, {'price': '0.75', 'size': '18329.25'}, {'price': '0.74', 'size': '11370.7'}, {'price': '0.73', 'size': '5020.1'}, {'price': '0.72', 'size': '380.52'}, {'price': '0.71', 'size': '15073.2'}, {'price': '0.7', 'size': '5570.1'}, {'price': '0.69', 'size': '6088.6'}, {'price': '0.68', 'size': '6131.34'}, {'price': '0.67', 'size': '3010.1'}, {'price': '0.66', 'size': '510.1'}, {'price': '0.65', 'size': '1010.1'}, {'price': '0.64', 'size': '4230.1'}, {'price': '0.63', 'size': '210.1'}, {'price': '0.62', 'size': '2800.1'}, {'price': '0.61', 'size': '2511.06'}, {'price': '0.6', 'size': '467.85'}, {'price': '0.59', 'size': '380'}, {'price': '0.58', 'size': '3388.1'}, {'price': '0.57', 'size': '110.1'}, {'price': '0.56', 'size': '1249.1'}, {'price': '0.55', 'size': '996.99'}], 'asset_id': '114416409796971863099144323163249651172534872992222856507897414949637892047507', 'bids': [{'price': '0.01', 'size': '2850.27'}, {'price': '0.02', 'size': '500'}, {'price': '0.03', 'size': '500'}, {'price': '0.04', 'size': '300'}, {'price': '0.05', 'size': '320'}, {'price': '0.06', 'size': '300'}, {'price': '0.08', 'size': '250'}, {'price': '0.09', 'size': '300'}, {'price': '0.1', 'size': '6205'}, {'price': '0.12', 'size': '200'}, {'price': '0.13', 'size': '426.92'}, {'price': '0.14', 'size': '15'}, {'price': '0.15', 'size': '110'}, {'price': '0.16', 'size': '4709.51'}, {'price': '0.18', 'size': '19.13'}, {'price': '0.19', 'size': '120'}, {'price': '0.2', 'size': '691.17'}, {'price': '0.24', 'size': '5027'}, {'price': '0.25', 'size': '86.66'}, {'price': '0.27', 'size': '215.25'}, {'price': '0.29', 'size': '1102.28'}, {'price': '0.31', 'size': '1130.65'}, {'price': '0.32', 'size': '200'}, {'price': '0.33', 'size': '620'}, {'price': '0.34', 'size': '4000'}, {'price': '0.35', 'size': '232'}, {'price': '0.39', 'size': '10.5'}, {'price': '0.4', 'size': '3135'}, {'price': '0.41', 'size': '20'}, {'price': '0.42', 'size': '3050'}, {'price': '0.43', 'size': '50'}, {'price': '0.44', 'size': '3660'}, {'price': '0.45', 'size': '478'}, {'price': '0.47', 'size': '2797.23'}, {'price': '0.48', 'size': '242.18'}, {'price': '0.49', 'size': '640'}, {'price': '0.5', 'size': '2355'}, {'price': '0.51', 'size': '2586.18'}, {'price': '0.52', 'size': '2062.77'}, {'price': '0.53', 'size': '1139'}, {'price': '0.54', 'size': '64.99'}], 'event_type': 'book', 'hash': '710aec818cada969732420de02e9833422e3ad20', 'market': '0x7aa4a910b31b2c4ddb09d1e3408e52aa8e09a14402f376070a44b1b85cb36d13', 'timestamp': '1733333795308'}
{'asks': [{'price': '0.99', 'size': '4217.01'}, {'price': '0.98', 'size': '505'}, {'price': '0.97', 'size': '511.03'}, {'price': '0.96', 'size': '300'}, {'price': '0.95', 'size': '657.12'}, {'price': '0.94', 'size': '300'}, {'price': '0.92', 'size': '20000.45'}, {'price': '0.91', 'size': '10406.3'}, {'price': '0.9', 'size': '4587.5'}, {'price': '0.89', 'size': '13017.18'}, {'price': '0.88', 'size': '200'}, {'price': '0.87', 'size': '3229'}, {'price': '0.86', 'size': '17.1'}, {'price': '0.85', 'size': '109.68'}, {'price': '0.84', 'size': '250'}, {'price': '0.83', 'size': '100'}, {'price': '0.82', 'size': '16029'}, {'price': '0.81', 'size': '45721.39'}, {'price': '0.8', 'size': '26531'}, {'price': '0.79', 'size': '7110'}, {'price': '0.78', 'size': '10350'}, {'price': '0.77', 'size': '67'}, {'price': '0.76', 'size': '200'}, {'price': '0.75', 'size': '18329.25'}, {'price': '0.74', 'size': '11370.7'}, {'price': '0.73', 'size': '5020.1'}, {'price': '0.72', 'size': '380.52'}, {'price': '0.71', 'size': '15073.2'}, {'price': '0.7', 'size': '5570.1'}, {'price': '0.69', 'size': '6088.6'}, {'price': '0.68', 'size': '6131.34'}, {'price': '0.67', 'size': '3010.1'}, {'price': '0.66', 'size': '510.1'}, {'price': '0.65', 'size': '1010.1'}, {'price': '0.64', 'size': '4230.1'}, {'price': '0.63', 'size': '210.1'}, {'price': '0.62', 'size': '2800.1'}, {'price': '0.61', 'size': '2511.06'}, {'price': '0.6', 'size': '467.85'}, {'price': '0.59', 'size': '380'}, {'price': '0.58', 'size': '3388.1'}, {'price': '0.57', 'size': '110.1'}, {'price': '0.56', 'size': '1249.1'}, {'price': '0.55', 'size': '996.99'}], 'asset_id': '114416409796971863099144323163249651172534872992222856507897414949637892047507', 'bids': [{'price': '0.01', 'size': '2850.27'}, {'price': '0.02', 'size': '500'}, {'price': '0.03', 'size': '500'}, {'price': '0.04', 'size': '300'}, {'price': '0.05', 'size': '320'}, {'price': '0.06', 'size': '300'}, {'price': '0.08', 'size': '250'}, {'price': '0.09', 'size': '300'}, {'price': '0.1', 'size': '6205'}, {'price': '0.12', 'size': '200'}, {'price': '0.13', 'size': '426.92'}, {'price': '0.14', 'size': '15'}, {'price': '0.15', 'size': '110'}, {'price': '0.16', 'size': '4709.51'}, {'price': '0.18', 'size': '19.13'}, {'price': '0.19', 'size': '120'}, {'price': '0.2', 'size': '691.17'}, {'price': '0.24', 'size': '5027'}, {'price': '0.25', 'size': '86.66'}, {'price': '0.27', 'size': '215.25'}, {'price': '0.29', 'size': '1102.28'}, {'price': '0.31', 'size': '1130.65'}, {'price': '0.32', 'size': '200'}, {'price': '0.33', 'size': '620'}, {'price': '0.34', 'size': '4000'}, {'price': '0.35', 'size': '232'}, {'price': '0.39', 'size': '10.5'}, {'price': '0.4', 'size': '3135'}, {'price': '0.41', 'size': '20'}, {'price': '0.42', 'size': '3050'}, {'price': '0.43', 'size': '50'}, {'price': '0.44', 'size': '3660'}, {'price': '0.45', 'size': '478'}, {'price': '0.47', 'size': '2797.23'}, {'price': '0.48', 'size': '242.18'}, {'price': '0.49', 'size': '640'}, {'price': '0.5', 'size': '2355'}, {'price': '0.51', 'size': '2586.18'}, {'price': '0.52', 'size': '2062.77'}, {'price': '0.53', 'size': '1139'}, {'price': '0.54', 'size': '64.99'}], 'event_type': 'book', 'hash': '710aec818cada969732420de02e9833422e3ad20', 'market': '0x7aa4a910b31b2c4ddb09d1e3408e52aa8e09a14402f376070a44b1b85cb36d13', 'timestamp': '1733333795308'}
{'asset_id': '114416409796971863099144323163249651172534872992222856507897414949637892047507', 'changes': [{'price': '0.49', 'side': 'BUY', 'size': '140'}, {'price': '0.53', 'side': 'BUY', 'size': '139'}, {'price': '0.58', 'side': 'SELL', 'size': '2888.1'}], 'event_type': 'price_change', 'hash': '1aa69bb17c1bfdd70b3f12c001e2c5f1133b367d', 'market': '0x7aa4a910b31b2c4ddb09d1e3408e52aa8e09a14402f376070a44b1b85cb36d13', 'timestamp': '1733333803612'}
{'asset_id': '114416409796971863099144323163249651172534872992222856507897414949637892047507', 'changes': [{'price': '0.49', 'side': 'BUY', 'size': '140'}, {'price': '0.53', 'side': 'BUY', 'size': '139'}, {'price': '0.58', 'side': 'SELL', 'size': '2888.1'}], 'event_type': 'price_change', 'hash': '1aa69bb17c1bfdd70b3f12c001e2c5f1133b367d', 'market': '0x7aa4a910b31b2c4ddb09d1e3408e52aa8e09a14402f376070a44b1b85cb36d13', 'timestamp': '1733333803612'}
{'asset_id': '114416409796971863099144323163249651172534872992222856507897414949637892047507', 'changes': [{'price': '0.48', 'side': 'BUY', 'size': '742.18'}], 'event_type': 'price_change', 'hash': 'e45300445dea3d28b9e981d9b8dd925ee22ac25a', 'market': '0x7aa4a910b31b2c4ddb09d1e3408e52aa8e09a14402f376070a44b1b85cb36d13', 'timestamp': '1733333804677'}
{'asset_id': '114416409796971863099144323163249651172534872992222856507897414949637892047507', 'changes': [{'price': '0.48', 'side': 'BUY', 'size': '742.18'}], 'event_type': 'price_change', 'hash': 'e45300445dea3d28b9e981d9b8dd925ee22ac25a', 'market': '0x7aa4a910b31b2c4ddb09d1e3408e52aa8e09a14402f376070a44b1b85cb36d13', 'timestamp': '1733333804677'}
{'asset_id': '114416409796971863099144323163249651172534872992222856507897414949637892047507', 'changes': [{'price': '0.57', 'side': 'SELL', 'size': '610.1'}], 'event_type': 'price_change', 'hash': '079d9d8db28ea7d63f29eacbe285638887d4df58', 'market': '0x7aa4a910b31b2c4ddb09d1e3408e52aa8e09a14402f376070a44b1b85cb36d13', 'timestamp': '1733333805050'}
{'asset_id': '114416409796971863099144323163249651172534872992222856507897414949637892047507', 'changes': [{'price': '0.57', 'side': 'SELL', 'size': '610.1'}], 'event_type': 'price_change', 'hash': '079d9d8db28ea7d63f29eacbe285638887d4df58', 'market': '0x7aa4a910b31b2c4ddb09d1e3408e52aa8e09a14402f376070a44b1b85cb36d13', 'timestamp': '1733333805050'}
{'asset_id': '114416409796971863099144323163249651172534872992222856507897414949637892047507', 'changes': [{'price': '0.52', 'side': 'BUY', 'size': '3062.77'}], 'event_type': 'price_change', 'hash': 'b45a66dfa2c6a0ce1e0c439bcdd0ccd71babc859', 'market': '0x7aa4a910b31b2c4ddb09d1e3408e52aa8e09a14402f376070a44b1b85cb36d13', 'timestamp': '1733333805421'}
{'asset_id': '114416409796971863099144323163249651172534872992222856507897414949637892047507', 'changes': [{'price': '0.52', 'side': 'BUY', 'size': '3062.77'}], 'event_type': 'price_change', 'hash': 'b45a66dfa2c6a0ce1e0c439bcdd0ccd71babc859', 'market': '0x7aa4a910b31b2c4ddb09d1e3408e52aa8e09a14402f376070a44b1b85cb36d13', 'timestamp': '1733333805421'}
{'asset_id': '114416409796971863099144323163249651172534872992222856507897414949637892047507', 'changes': [{'price': '0.52', 'side': 'BUY', 'size': '1862.77'}], 'event_type': 'price_change', 'hash': 'b1de3ede93ec91ef0f1096825ec8ccd335898afa', 'market': '0x7aa4a910b31b2c4ddb09d1e3408e52aa8e09a14402f376070a44b1b85cb36d13', 'timestamp': '1733333806012'}
{'asset_id': '114416409796971863099144323163249651172534872992222856507897414949637892047507', 'changes': [{'price': '0.52', 'side': 'BUY', 'size': '1862.77'}], 'event_type': 'price_change', 'hash': 'b1de3ede93ec91ef0f1096825ec8ccd335898afa', 'market': '0x7aa4a910b31b2c4ddb09d1e3408e52aa8e09a14402f376070a44b1b85cb36d13', 'timestamp': '1733333806012'}
{'asset_id': '114416409796971863099144323163249651172534872992222856507897414949637892047507', 'changes': [{'price': '0.52', 'side': 'BUY', 'size': '3062.77'}], 'event_type': 'price_change', 'hash': 'e76de7efe602d268c38a5894bf7b54afe287e0bb', 'market': '0x7aa4a910b31b2c4ddb09d1e3408e52aa8e09a14402f376070a44b1b85cb36d13', 'timestamp': '1733333814942'}
{'asset_id': '114416409796971863099144323163249651172534872992222856507897414949637892047507', 'changes': [{'price': '0.52', 'side': 'BUY', 'size': '3062.77'}], 'event_type': 'price_change', 'hash': 'e76de7efe602d268c38a5894bf7b54afe287e0bb', 'market': '0x7aa4a910b31b2c4ddb09d1e3408e52aa8e09a14402f376070a44b1b85cb36d13', 'timestamp': '1733333814942'}
{'asset_id': '114416409796971863099144323163249651172534872992222856507897414949637892047507', 'changes': [{'price': '0.53', 'side': 'BUY', 'size': '149'}], 'event_type': 'price_change', 'hash': '71ee8efef90f477b63fe261e993e638d8437183f', 'market': '0x7aa4a910b31b2c4ddb09d1e3408e52aa8e09a14402f376070a44b1b85cb36d13', 'timestamp': '1733333821656'}
{'asset_id': '114416409796971863099144323163249651172534872992222856507897414949637892047507', 'changes': [{'price': '0.53', 'side': 'BUY', 'size': '149'}], 'event_type': 'price_change', 'hash': '71ee8efef90f477b63fe261e993e638d8437183f', 'market': '0x7aa4a910b31b2c4ddb09d1e3408e52aa8e09a14402f376070a44b1b85cb36d13', 'timestamp': '1733333821656'}
{'asks': [{'price': '0.99', 'size': '4217.01'}, {'price': '0.98', 'size': '505'}, {'price': '0.97', 'size': '511.03'}, {'price': '0.96', 'size': '300'}, {'price': '0.95', 'size': '657.12'}, {'price': '0.94', 'size': '300'}, {'price': '0.92', 'size': '20000.45'}, {'price': '0.91', 'size': '10406.3'}, {'price': '0.9', 'size': '4587.5'}, {'price': '0.89', 'size': '13017.18'}, {'price': '0.88', 'size': '200'}, {'price': '0.87', 'size': '3229'}, {'price': '0.86', 'size': '17.1'}, {'price': '0.85', 'size': '109.68'}, {'price': '0.84', 'size': '250'}, {'price': '0.83', 'size': '100'}, {'price': '0.82', 'size': '16029'}, {'price': '0.81', 'size': '45721.39'}, {'price': '0.8', 'size': '26531'}, {'price': '0.79', 'size': '7110'}, {'price': '0.78', 'size': '10350'}, {'price': '0.77', 'size': '67'}, {'price': '0.76', 'size': '200'}, {'price': '0.75', 'size': '18329.25'}, {'price': '0.74', 'size': '11370.7'}, {'price': '0.73', 'size': '5020.1'}, {'price': '0.72', 'size': '380.52'}, {'price': '0.71', 'size': '15073.2'}, {'price': '0.7', 'size': '5570.1'}, {'price': '0.69', 'size': '6088.6'}, {'price': '0.68', 'size': '6131.34'}, {'price': '0.67', 'size': '3010.1'}, {'price': '0.66', 'size': '510.1'}, {'price': '0.65', 'size': '1010.1'}, {'price': '0.64', 'size': '4230.1'}, {'price': '0.63', 'size': '210.1'}, {'price': '0.62', 'size': '2800.1'}, {'price': '0.61', 'size': '2511.06'}, {'price': '0.6', 'size': '467.85'}, {'price': '0.59', 'size': '380'}, {'price': '0.58', 'size': '2888.1'}, {'price': '0.57', 'size': '610.1'}, {'price': '0.56', 'size': '1249.1'}, {'price': '0.55', 'size': '942.44'}], 'asset_id': '114416409796971863099144323163249651172534872992222856507897414949637892047507', 'bids': [{'price': '0.01', 'size': '2850.27'}, {'price': '0.02', 'size': '500'}, {'price': '0.03', 'size': '500'}, {'price': '0.04', 'size': '300'}, {'price': '0.05', 'size': '320'}, {'price': '0.06', 'size': '300'}, {'price': '0.08', 'size': '250'}, {'price': '0.09', 'size': '300'}, {'price': '0.1', 'size': '6205'}, {'price': '0.12', 'size': '200'}, {'price': '0.13', 'size': '426.92'}, {'price': '0.14', 'size': '15'}, {'price': '0.15', 'size': '110'}, {'price': '0.16', 'size': '4709.51'}, {'price': '0.18', 'size': '19.13'}, {'price': '0.19', 'size': '120'}, {'price': '0.2', 'size': '691.17'}, {'price': '0.24', 'size': '5027'}, {'price': '0.25', 'size': '86.66'}, {'price': '0.27', 'size': '215.25'}, {'price': '0.29', 'size': '1102.28'}, {'price': '0.31', 'size': '1130.65'}, {'price': '0.32', 'size': '200'}, {'price': '0.33', 'size': '620'}, {'price': '0.34', 'size': '4000'}, {'price': '0.35', 'size': '232'}, {'price': '0.39', 'size': '10.5'}, {'price': '0.4', 'size': '3135'}, {'price': '0.41', 'size': '20'}, {'price': '0.42', 'size': '3050'}, {'price': '0.43', 'size': '50'}, {'price': '0.44', 'size': '3660'}, {'price': '0.45', 'size': '478'}, {'price': '0.47', 'size': '2797.23'}, {'price': '0.48', 'size': '742.18'}, {'price': '0.49', 'size': '140'}, {'price': '0.5', 'size': '2355'}, {'price': '0.51', 'size': '2586.18'}, {'price': '0.52', 'size': '3062.77'}, {'price': '0.53', 'size': '149'}, {'price': '0.54', 'size': '64.99'}], 'event_type': 'book', 'hash': 'fdc99749f675c362d4d73c0fb030f7247808536d', 'market': '0x7aa4a910b31b2c4ddb09d1e3408e52aa8e09a14402f376070a44b1b85cb36d13', 'timestamp': '1733333828739'}
{'asset_id': '114416409796971863099144323163249651172534872992222856507897414949637892047507', 'event_type': 'last_trade_price', 'fee_rate_bps': '0', 'market': '0x7aa4a910b31b2c4ddb09d1e3408e52aa8e09a14402f376070a44b1b85cb36d13', 'price': '0.55', 'side': 'BUY', 'size': '54.545453', 'timestamp': '1733333828758'}
{'asks': [{'price': '0.99', 'size': '4217.01'}, {'price': '0.98', 'size': '505'}, {'price': '0.97', 'size': '511.03'}, {'price': '0.96', 'size': '300'}, {'price': '0.95', 'size': '657.12'}, {'price': '0.94', 'size': '300'}, {'price': '0.92', 'size': '20000.45'}, {'price': '0.91', 'size': '10406.3'}, {'price': '0.9', 'size': '4587.5'}, {'price': '0.89', 'size': '13017.18'}, {'price': '0.88', 'size': '200'}, {'price': '0.87', 'size': '3229'}, {'price': '0.86', 'size': '17.1'}, {'price': '0.85', 'size': '109.68'}, {'price': '0.84', 'size': '250'}, {'price': '0.83', 'size': '100'}, {'price': '0.82', 'size': '16029'}, {'price': '0.81', 'size': '45721.39'}, {'price': '0.8', 'size': '26531'}, {'price': '0.79', 'size': '7110'}, {'price': '0.78', 'size': '10350'}, {'price': '0.77', 'size': '67'}, {'price': '0.76', 'size': '200'}, {'price': '0.75', 'size': '18329.25'}, {'price': '0.74', 'size': '11370.7'}, {'price': '0.73', 'size': '5020.1'}, {'price': '0.72', 'size': '380.52'}, {'price': '0.71', 'size': '15073.2'}, {'price': '0.7', 'size': '5570.1'}, {'price': '0.69', 'size': '6088.6'}, {'price': '0.68', 'size': '6131.34'}, {'price': '0.67', 'size': '3010.1'}, {'price': '0.66', 'size': '510.1'}, {'price': '0.65', 'size': '1010.1'}, {'price': '0.64', 'size': '4230.1'}, {'price': '0.63', 'size': '210.1'}, {'price': '0.62', 'size': '2800.1'}, {'price': '0.61', 'size': '2511.06'}, {'price': '0.6', 'size': '467.85'}, {'price': '0.59', 'size': '380'}, {'price': '0.58', 'size': '2888.1'}, {'price': '0.57', 'size': '610.1'}, {'price': '0.56', 'size': '1249.1'}, {'price': '0.55', 'size': '942.44'}], 'asset_id': '114416409796971863099144323163249651172534872992222856507897414949637892047507', 'bids': [{'price': '0.01', 'size': '2850.27'}, {'price': '0.02', 'size': '500'}, {'price': '0.03', 'size': '500'}, {'price': '0.04', 'size': '300'}, {'price': '0.05', 'size': '320'}, {'price': '0.06', 'size': '300'}, {'price': '0.08', 'size': '250'}, {'price': '0.09', 'size': '300'}, {'price': '0.1', 'size': '6205'}, {'price': '0.12', 'size': '200'}, {'price': '0.13', 'size': '426.92'}, {'price': '0.14', 'size': '15'}, {'price': '0.15', 'size': '110'}, {'price': '0.16', 'size': '4709.51'}, {'price': '0.18', 'size': '19.13'}, {'price': '0.19', 'size': '120'}, {'price': '0.2', 'size': '691.17'}, {'price': '0.24', 'size': '5027'}, {'price': '0.25', 'size': '86.66'}, {'price': '0.27', 'size': '215.25'}, {'price': '0.29', 'size': '1102.28'}, {'price': '0.31', 'size': '1130.65'}, {'price': '0.32', 'size': '200'}, {'price': '0.33', 'size': '620'}, {'price': '0.34', 'size': '4000'}, {'price': '0.35', 'size': '232'}, {'price': '0.39', 'size': '10.5'}, {'price': '0.4', 'size': '3135'}, {'price': '0.41', 'size': '20'}, {'price': '0.42', 'size': '3050'}, {'price': '0.43', 'size': '50'}, {'price': '0.44', 'size': '3660'}, {'price': '0.45', 'size': '478'}, {'price': '0.47', 'size': '2797.23'}, {'price': '0.48', 'size': '742.18'}, {'price': '0.49', 'size': '140'}, {'price': '0.5', 'size': '2355'}, {'price': '0.51', 'size': '2586.18'}, {'price': '0.52', 'size': '3062.77'}, {'price': '0.53', 'size': '149'}, {'price': '0.54', 'size': '64.99'}], 'event_type': 'book', 'hash': 'fdc99749f675c362d4d73c0fb030f7247808536d', 'market': '0x7aa4a910b31b2c4ddb09d1e3408e52aa8e09a14402f376070a44b1b85cb36d13', 'timestamp': '1733333828739'}
{'asset_id': '114416409796971863099144323163249651172534872992222856507897414949637892047507', 'event_type': 'last_trade_price', 'fee_rate_bps': '0', 'market': '0x7aa4a910b31b2c4ddb09d1e3408e52aa8e09a14402f376070a44b1b85cb36d13', 'price': '0.55', 'side': 'BUY', 'size': '54.545453', 'timestamp': '1733333828758'}
{'asks': [{'price': '0.99', 'size': '4217.01'}, {'price': '0.98', 'size': '505'}, {'price': '0.97', 'size': '511.03'}, {'price': '0.96', 'size': '300'}, {'price': '0.95', 'size': '657.12'}, {'price': '0.94', 'size': '300'}, {'price': '0.92', 'size': '20000.45'}, {'price': '0.91', 'size': '10406.3'}, {'price': '0.9', 'size': '4587.5'}, {'price': '0.89', 'size': '13017.18'}, {'price': '0.88', 'size': '200'}, {'price': '0.87', 'size': '3229'}, {'price': '0.86', 'size': '17.1'}, {'price': '0.85', 'size': '109.68'}, {'price': '0.84', 'size': '250'}, {'price': '0.83', 'size': '100'}, {'price': '0.82', 'size': '16029'}, {'price': '0.81', 'size': '45721.39'}, {'price': '0.8', 'size': '26531'}, {'price': '0.79', 'size': '7110'}, {'price': '0.78', 'size': '10350'}, {'price': '0.77', 'size': '67'}, {'price': '0.76', 'size': '200'}, {'price': '0.75', 'size': '18329.25'}, {'price': '0.74', 'size': '11370.7'}, {'price': '0.73', 'size': '5020.1'}, {'price': '0.72', 'size': '380.52'}, {'price': '0.71', 'size': '15073.2'}, {'price': '0.7', 'size': '5570.1'}, {'price': '0.69', 'size': '6088.6'}, {'price': '0.68', 'size': '6131.34'}, {'price': '0.67', 'size': '3010.1'}, {'price': '0.66', 'size': '510.1'}, {'price': '0.65', 'size': '1010.1'}, {'price': '0.64', 'size': '4230.1'}, {'price': '0.63', 'size': '210.1'}, {'price': '0.62', 'size': '2800.1'}, {'price': '0.61', 'size': '2511.06'}, {'price': '0.6', 'size': '467.85'}, {'price': '0.59', 'size': '380'}, {'price': '0.58', 'size': '2888.1'}, {'price': '0.57', 'size': '610.1'}, {'price': '0.56', 'size': '1249.1'}, {'price': '0.55', 'size': '942.44'}], 'asset_id': '114416409796971863099144323163249651172534872992222856507897414949637892047507', 'bids': [{'price': '0.01', 'size': '2850.27'}, {'price': '0.02', 'size': '500'}, {'price': '0.03', 'size': '500'}, {'price': '0.04', 'size': '300'}, {'price': '0.05', 'size': '320'}, {'price': '0.06', 'size': '300'}, {'price': '0.08', 'size': '250'}, {'price': '0.09', 'size': '300'}, {'price': '0.1', 'size': '6205'}, {'price': '0.12', 'size': '200'}, {'price': '0.13', 'size': '426.92'}, {'price': '0.14', 'size': '15'}, {'price': '0.15', 'size': '110'}, {'price': '0.16', 'size': '4709.51'}, {'price': '0.18', 'size': '19.13'}, {'price': '0.19', 'size': '120'}, {'price': '0.2', 'size': '691.17'}, {'price': '0.24', 'size': '5027'}, {'price': '0.25', 'size': '86.66'}, {'price': '0.27', 'size': '215.25'}, {'price': '0.29', 'size': '1102.28'}, {'price': '0.31', 'size': '1130.65'}, {'price': '0.32', 'size': '200'}, {'price': '0.33', 'size': '620'}, {'price': '0.34', 'size': '4000'}, {'price': '0.35', 'size': '232'}, {'price': '0.39', 'size': '10.5'}, {'price': '0.4', 'size': '3135'}, {'price': '0.41', 'size': '20'}, {'price': '0.42', 'size': '3050'}, {'price': '0.43', 'size': '50'}, {'price': '0.44', 'size': '3660'}, {'price': '0.45', 'size': '478'}, {'price': '0.47', 'size': '2797.23'}, {'price': '0.48', 'size': '742.18'}, {'price': '0.49', 'size': '140'}, {'price': '0.5', 'size': '2355'}, {'price': '0.51', 'size': '2586.18'}, {'price': '0.52', 'size': '3062.77'}, {'price': '0.53', 'size': '149'}, {'price': '0.54', 'size': '36.18'}], 'event_type': 'book', 'hash': '60b26b94297d2ebd3da7e3bd886cf9578dae0d95', 'market': '0x7aa4a910b31b2c4ddb09d1e3408e52aa8e09a14402f376070a44b1b85cb36d13', 'timestamp': '1733333851492'}
{'asks': [{'price': '0.99', 'size': '4217.01'}, {'price': '0.98', 'size': '505'}, {'price': '0.97', 'size': '511.03'}, {'price': '0.96', 'size': '300'}, {'price': '0.95', 'size': '657.12'}, {'price': '0.94', 'size': '300'}, {'price': '0.92', 'size': '20000.45'}, {'price': '0.91', 'size': '10406.3'}, {'price': '0.9', 'size': '4587.5'}, {'price': '0.89', 'size': '13017.18'}, {'price': '0.88', 'size': '200'}, {'price': '0.87', 'size': '3229'}, {'price': '0.86', 'size': '17.1'}, {'price': '0.85', 'size': '109.68'}, {'price': '0.84', 'size': '250'}, {'price': '0.83', 'size': '100'}, {'price': '0.82', 'size': '16029'}, {'price': '0.81', 'size': '45721.39'}, {'price': '0.8', 'size': '26531'}, {'price': '0.79', 'size': '7110'}, {'price': '0.78', 'size': '10350'}, {'price': '0.77', 'size': '67'}, {'price': '0.76', 'size': '200'}, {'price': '0.75', 'size': '18329.25'}, {'price': '0.74', 'size': '11370.7'}, {'price': '0.73', 'size': '5020.1'}, {'price': '0.72', 'size': '380.52'}, {'price': '0.71', 'size': '15073.2'}, {'price': '0.7', 'size': '5570.1'}, {'price': '0.69', 'size': '6088.6'}, {'price': '0.68', 'size': '6131.34'}, {'price': '0.67', 'size': '3010.1'}, {'price': '0.66', 'size': '510.1'}, {'price': '0.65', 'size': '1010.1'}, {'price': '0.64', 'size': '4230.1'}, {'price': '0.63', 'size': '210.1'}, {'price': '0.62', 'size': '2800.1'}, {'price': '0.61', 'size': '2511.06'}, {'price': '0.6', 'size': '467.85'}, {'price': '0.59', 'size': '380'}, {'price': '0.58', 'size': '2888.1'}, {'price': '0.57', 'size': '610.1'}, {'price': '0.56', 'size': '1249.1'}, {'price': '0.55', 'size': '942.44'}], 'asset_id': '114416409796971863099144323163249651172534872992222856507897414949637892047507', 'bids': [{'price': '0.01', 'size': '2850.27'}, {'price': '0.02', 'size': '500'}, {'price': '0.03', 'size': '500'}, {'price': '0.04', 'size': '300'}, {'price': '0.05', 'size': '320'}, {'price': '0.06', 'size': '300'}, {'price': '0.08', 'size': '250'}, {'price': '0.09', 'size': '300'}, {'price': '0.1', 'size': '6205'}, {'price': '0.12', 'size': '200'}, {'price': '0.13', 'size': '426.92'}, {'price': '0.14', 'size': '15'}, {'price': '0.15', 'size': '110'}, {'price': '0.16', 'size': '4709.51'}, {'price': '0.18', 'size': '19.13'}, {'price': '0.19', 'size': '120'}, {'price': '0.2', 'size': '691.17'}, {'price': '0.24', 'size': '5027'}, {'price': '0.25', 'size': '86.66'}, {'price': '0.27', 'size': '215.25'}, {'price': '0.29', 'size': '1102.28'}, {'price': '0.31', 'size': '1130.65'}, {'price': '0.32', 'size': '200'}, {'price': '0.33', 'size': '620'}, {'price': '0.34', 'size': '4000'}, {'price': '0.35', 'size': '232'}, {'price': '0.39', 'size': '10.5'}, {'price': '0.4', 'size': '3135'}, {'price': '0.41', 'size': '20'}, {'price': '0.42', 'size': '3050'}, {'price': '0.43', 'size': '50'}, {'price': '0.44', 'size': '3660'}, {'price': '0.45', 'size': '478'}, {'price': '0.47', 'size': '2797.23'}, {'price': '0.48', 'size': '742.18'}, {'price': '0.49', 'size': '140'}, {'price': '0.5', 'size': '2355'}, {'price': '0.51', 'size': '2586.18'}, {'price': '0.52', 'size': '3062.77'}, {'price': '0.53', 'size': '149'}, {'price': '0.54', 'size': '36.18'}], 'event_type': 'book', 'hash': '60b26b94297d2ebd3da7e3bd886cf9578dae0d95', 'market': '0x7aa4a910b31b2c4ddb09d1e3408e52aa8e09a14402f376070a44b1b85cb36d13', 'timestamp': '1733333851492'}
{'asks': [{'price': '0.99', 'size': '4217.01'}, {'price': '0.98', 'size': '505'}, {'price': '0.97', 'size': '511.03'}, {'price': '0.96', 'size': '300'}, {'price': '0.95', 'size': '657.12'}, {'price': '0.94', 'size': '300'}, {'price': '0.92', 'size': '20000.45'}, {'price': '0.91', 'size': '10406.3'}, {'price': '0.9', 'size': '4587.5'}, {'price': '0.89', 'size': '13017.18'}, {'price': '0.88', 'size': '200'}, {'price': '0.87', 'size': '3229'}, {'price': '0.86', 'size': '17.1'}, {'price': '0.85', 'size': '109.68'}, {'price': '0.84', 'size': '250'}, {'price': '0.83', 'size': '100'}, {'price': '0.82', 'size': '16029'}, {'price': '0.81', 'size': '45721.39'}, {'price': '0.8', 'size': '26531'}, {'price': '0.79', 'size': '7110'}, {'price': '0.78', 'size': '10350'}, {'price': '0.77', 'size': '67'}, {'price': '0.76', 'size': '200'}, {'price': '0.75', 'size': '18329.25'}, {'price': '0.74', 'size': '11370.7'}, {'price': '0.73', 'size': '5020.1'}, {'price': '0.72', 'size': '380.52'}, {'price': '0.71', 'size': '15073.2'}, {'price': '0.7', 'size': '5570.1'}, {'price': '0.69', 'size': '6088.6'}, {'price': '0.68', 'size': '6131.34'}, {'price': '0.67', 'size': '3010.1'}, {'price': '0.66', 'size': '510.1'}, {'price': '0.65', 'size': '1010.1'}, {'price': '0.64', 'size': '4230.1'}, {'price': '0.63', 'size': '210.1'}, {'price': '0.62', 'size': '2800.1'}, {'price': '0.61', 'size': '2511.06'}, {'price': '0.6', 'size': '467.85'}, {'price': '0.59', 'size': '380'}, {'price': '0.58', 'size': '2888.1'}, {'price': '0.57', 'size': '610.1'}, {'price': '0.56', 'size': '1249.1'}, {'price': '0.55', 'size': '913.71'}], 'asset_id': '114416409796971863099144323163249651172534872992222856507897414949637892047507', 'bids': [{'price': '0.01', 'size': '2850.27'}, {'price': '0.02', 'size': '500'}, {'price': '0.03', 'size': '500'}, {'price': '0.04', 'size': '300'}, {'price': '0.05', 'size': '320'}, {'price': '0.06', 'size': '300'}, {'price': '0.08', 'size': '250'}, {'price': '0.09', 'size': '300'}, {'price': '0.1', 'size': '6205'}, {'price': '0.12', 'size': '200'}, {'price': '0.13', 'size': '426.92'}, {'price': '0.14', 'size': '15'}, {'price': '0.15', 'size': '110'}, {'price': '0.16', 'size': '4709.51'}, {'price': '0.18', 'size': '19.13'}, {'price': '0.19', 'size': '120'}, {'price': '0.2', 'size': '691.17'}, {'price': '0.24', 'size': '5027'}, {'price': '0.25', 'size': '86.66'}, {'price': '0.27', 'size': '215.25'}, {'price': '0.29', 'size': '1102.28'}, {'price': '0.31', 'size': '1130.65'}, {'price': '0.32', 'size': '200'}, {'price': '0.33', 'size': '620'}, {'price': '0.34', 'size': '4000'}, {'price': '0.35', 'size': '232'}, {'price': '0.39', 'size': '10.5'}, {'price': '0.4', 'size': '3135'}, {'price': '0.41', 'size': '20'}, {'price': '0.42', 'size': '3050'}, {'price': '0.43', 'size': '50'}, {'price': '0.44', 'size': '3660'}, {'price': '0.45', 'size': '478'}, {'price': '0.47', 'size': '2797.23'}, {'price': '0.48', 'size': '742.18'}, {'price': '0.49', 'size': '140'}, {'price': '0.5', 'size': '2355'}, {'price': '0.51', 'size': '2586.18'}, {'price': '0.52', 'size': '3062.77'}, {'price': '0.53', 'size': '149'}, {'price': '0.54', 'size': '36.18'}], 'event_type': 'book', 'hash': '1edd527172922005386a38b1ae2b8189387488ce', 'market': '0x7aa4a910b31b2c4ddb09d1e3408e52aa8e09a14402f376070a44b1b85cb36d13', 'timestamp': '1733333851790'}
{'asset_id': '114416409796971863099144323163249651172534872992222856507897414949637892047507', 'event_type': 'last_trade_price', 'fee_rate_bps': '0', 'market': '0x7aa4a910b31b2c4ddb09d1e3408e52aa8e09a14402f376070a44b1b85cb36d13', 'price': '0.55', 'side': 'BUY', 'size': '28.727271', 'timestamp': '1733333851808'}
{'asks': [{'price': '0.99', 'size': '4217.01'}, {'price': '0.98', 'size': '505'}, {'price': '0.97', 'size': '511.03'}, {'price': '0.96', 'size': '300'}, {'price': '0.95', 'size': '657.12'}, {'price': '0.94', 'size': '300'}, {'price': '0.92', 'size': '20000.45'}, {'price': '0.91', 'size': '10406.3'}, {'price': '0.9', 'size': '4587.5'}, {'price': '0.89', 'size': '13017.18'}, {'price': '0.88', 'size': '200'}, {'price': '0.87', 'size': '3229'}, {'price': '0.86', 'size': '17.1'}, {'price': '0.85', 'size': '109.68'}, {'price': '0.84', 'size': '250'}, {'price': '0.83', 'size': '100'}, {'price': '0.82', 'size': '16029'}, {'price': '0.81', 'size': '45721.39'}, {'price': '0.8', 'size': '26531'}, {'price': '0.79', 'size': '7110'}, {'price': '0.78', 'size': '10350'}, {'price': '0.77', 'size': '67'}, {'price': '0.76', 'size': '200'}, {'price': '0.75', 'size': '18329.25'}, {'price': '0.74', 'size': '11370.7'}, {'price': '0.73', 'size': '5020.1'}, {'price': '0.72', 'size': '380.52'}, {'price': '0.71', 'size': '15073.2'}, {'price': '0.7', 'size': '5570.1'}, {'price': '0.69', 'size': '6088.6'}, {'price': '0.68', 'size': '6131.34'}, {'price': '0.67', 'size': '3010.1'}, {'price': '0.66', 'size': '510.1'}, {'price': '0.65', 'size': '1010.1'}, {'price': '0.64', 'size': '4230.1'}, {'price': '0.63', 'size': '210.1'}, {'price': '0.62', 'size': '2800.1'}, {'price': '0.61', 'size': '2511.06'}, {'price': '0.6', 'size': '467.85'}, {'price': '0.59', 'size': '380'}, {'price': '0.58', 'size': '2888.1'}, {'price': '0.57', 'size': '610.1'}, {'price': '0.56', 'size': '1249.1'}, {'price': '0.55', 'size': '913.71'}], 'asset_id': '114416409796971863099144323163249651172534872992222856507897414949637892047507', 'bids': [{'price': '0.01', 'size': '2850.27'}, {'price': '0.02', 'size': '500'}, {'price': '0.03', 'size': '500'}, {'price': '0.04', 'size': '300'}, {'price': '0.05', 'size': '320'}, {'price': '0.06', 'size': '300'}, {'price': '0.08', 'size': '250'}, {'price': '0.09', 'size': '300'}, {'price': '0.1', 'size': '6205'}, {'price': '0.12', 'size': '200'}, {'price': '0.13', 'size': '426.92'}, {'price': '0.14', 'size': '15'}, {'price': '0.15', 'size': '110'}, {'price': '0.16', 'size': '4709.51'}, {'price': '0.18', 'size': '19.13'}, {'price': '0.19', 'size': '120'}, {'price': '0.2', 'size': '691.17'}, {'price': '0.24', 'size': '5027'}, {'price': '0.25', 'size': '86.66'}, {'price': '0.27', 'size': '215.25'}, {'price': '0.29', 'size': '1102.28'}, {'price': '0.31', 'size': '1130.65'}, {'price': '0.32', 'size': '200'}, {'price': '0.33', 'size': '620'}, {'price': '0.34', 'size': '4000'}, {'price': '0.35', 'size': '232'}, {'price': '0.39', 'size': '10.5'}, {'price': '0.4', 'size': '3135'}, {'price': '0.41', 'size': '20'}, {'price': '0.42', 'size': '3050'}, {'price': '0.43', 'size': '50'}, {'price': '0.44', 'size': '3660'}, {'price': '0.45', 'size': '478'}, {'price': '0.47', 'size': '2797.23'}, {'price': '0.48', 'size': '742.18'}, {'price': '0.49', 'size': '140'}, {'price': '0.5', 'size': '2355'}, {'price': '0.51', 'size': '2586.18'}, {'price': '0.52', 'size': '3062.77'}, {'price': '0.53', 'size': '149'}, {'price': '0.54', 'size': '36.18'}], 'event_type': 'book', 'hash': '1edd527172922005386a38b1ae2b8189387488ce', 'market': '0x7aa4a910b31b2c4ddb09d1e3408e52aa8e09a14402f376070a44b1b85cb36d13', 'timestamp': '1733333851790'}
{'asset_id': '114416409796971863099144323163249651172534872992222856507897414949637892047507', 'event_type': 'last_trade_price', 'fee_rate_bps': '0', 'market': '0x7aa4a910b31b2c4ddb09d1e3408e52aa8e09a14402f376070a44b1b85cb36d13', 'price': '0.55', 'side': 'BUY', 'size': '28.727271', 'timestamp': '1733333851808'}
{'asset_id': '114416409796971863099144323163249651172534872992222856507897414949637892047507', 'changes': [{'price': '0.58', 'side': 'SELL', 'size': '1388.1'}], 'event_type': 'price_change', 'hash': 'a09db80adb2ca4ac00cc2c94b819ff7e1be87c01', 'market': '0x7aa4a910b31b2c4ddb09d1e3408e52aa8e09a14402f376070a44b1b85cb36d13', 'timestamp': '1733333862011'}
{'asset_id': '114416409796971863099144323163249651172534872992222856507897414949637892047507', 'changes': [{'price': '0.58', 'side': 'SELL', 'size': '1388.1'}], 'event_type': 'price_change', 'hash': 'a09db80adb2ca4ac00cc2c94b819ff7e1be87c01', 'market': '0x7aa4a910b31b2c4ddb09d1e3408e52aa8e09a14402f376070a44b1b85cb36d13', 'timestamp': '1733333862011'}
{'asset_id': '114416409796971863099144323163249651172534872992222856507897414949637892047507', 'changes': [{'price': '0.59', 'side': 'SELL', 'size': '1880'}], 'event_type': 'price_change', 'hash': 'f7aa09e6f4daac3895f24f05421cdb1baad0bd92', 'market': '0x7aa4a910b31b2c4ddb09d1e3408e52aa8e09a14402f376070a44b1b85cb36d13', 'timestamp': '1733333877242'}
{'asset_id': '114416409796971863099144323163249651172534872992222856507897414949637892047507', 'changes': [{'price': '0.59', 'side': 'SELL', 'size': '1880'}], 'event_type': 'price_change', 'hash': 'f7aa09e6f4daac3895f24f05421cdb1baad0bd92', 'market': '0x7aa4a910b31b2c4ddb09d1e3408e52aa8e09a14402f376070a44b1b85cb36d13', 'timestamp': '1733333877242'}
{'asset_id': '114416409796971863099144323163249651172534872992222856507897414949637892047507', 'changes': [{'price': '0.48', 'side': 'BUY', 'size': '242.18'}, {'price': '0.52', 'side': 'BUY', 'size': '2062.77'}, {'price': '0.57', 'side': 'SELL', 'size': '110.1'}], 'event_type': 'price_change', 'hash': '356f7988ea2922d9bbf6e2f23f614723f3b9250d', 'market': '0x7aa4a910b31b2c4ddb09d1e3408e52aa8e09a14402f376070a44b1b85cb36d13', 'timestamp': '1733333910613'}
{'asset_id': '114416409796971863099144323163249651172534872992222856507897414949637892047507', 'changes': [{'price': '0.48', 'side': 'BUY', 'size': '242.18'}, {'price': '0.52', 'side': 'BUY', 'size': '2062.77'}, {'price': '0.57', 'side': 'SELL', 'size': '110.1'}], 'event_type': 'price_change', 'hash': '356f7988ea2922d9bbf6e2f23f614723f3b9250d', 'market': '0x7aa4a910b31b2c4ddb09d1e3408e52aa8e09a14402f376070a44b1b85cb36d13', 'timestamp': '1733333910613'}
{'asset_id': '114416409796971863099144323163249651172534872992222856507897414949637892047507', 'changes': [{'price': '0.49', 'side': 'BUY', 'size': '640'}], 'event_type': 'price_change', 'hash': '937bbdaa91dd83151952982c5ef556c3d5cd73f9', 'market': '0x7aa4a910b31b2c4ddb09d1e3408e52aa8e09a14402f376070a44b1b85cb36d13', 'timestamp': '1733333911757'}
{'asset_id': '114416409796971863099144323163249651172534872992222856507897414949637892047507', 'changes': [{'price': '0.49', 'side': 'BUY', 'size': '640'}], 'event_type': 'price_change', 'hash': '937bbdaa91dd83151952982c5ef556c3d5cd73f9', 'market': '0x7aa4a910b31b2c4ddb09d1e3408e52aa8e09a14402f376070a44b1b85cb36d13', 'timestamp': '1733333911757'}
{'asset_id': '114416409796971863099144323163249651172534872992222856507897414949637892047507', 'changes': [{'price': '0.58', 'side': 'SELL', 'size': '1888.1'}], 'event_type': 'price_change', 'hash': 'd21755144947b81a7ede18b0876f199c0fde2ec6', 'market': '0x7aa4a910b31b2c4ddb09d1e3408e52aa8e09a14402f376070a44b1b85cb36d13', 'timestamp': '1733333912166'}
{'asset_id': '114416409796971863099144323163249651172534872992222856507897414949637892047507', 'changes': [{'price': '0.58', 'side': 'SELL', 'size': '1888.1'}], 'event_type': 'price_change', 'hash': 'd21755144947b81a7ede18b0876f199c0fde2ec6', 'market': '0x7aa4a910b31b2c4ddb09d1e3408e52aa8e09a14402f376070a44b1b85cb36d13', 'timestamp': '1733333912166'}
{'asset_id': '114416409796971863099144323163249651172534872992222856507897414949637892047507', 'changes': [{'price': '0.53', 'side': 'BUY', 'size': '1149'}], 'event_type': 'price_change', 'hash': '45357c1aaa7e798d7f2d46c8ce16d1ca88293fe1', 'market': '0x7aa4a910b31b2c4ddb09d1e3408e52aa8e09a14402f376070a44b1b85cb36d13', 'timestamp': '1733333912576'}
{'asset_id': '114416409796971863099144323163249651172534872992222856507897414949637892047507', 'changes': [{'price': '0.53', 'side': 'BUY', 'size': '1149'}], 'event_type': 'price_change', 'hash': '45357c1aaa7e798d7f2d46c8ce16d1ca88293fe1', 'market': '0x7aa4a910b31b2c4ddb09d1e3408e52aa8e09a14402f376070a44b1b85cb36d13', 'timestamp': '1733333912576'}
{'asset_id': '114416409796971863099144323163249651172534872992222856507897414949637892047507', 'changes': [{'price': '0.58', 'side': 'SELL', 'size': '688.1'}], 'event_type': 'price_change', 'hash': '886cd02ac45632612285bbb9546019299a61e7cb', 'market': '0x7aa4a910b31b2c4ddb09d1e3408e52aa8e09a14402f376070a44b1b85cb36d13', 'timestamp': '1733333922011'}
{'asset_id': '114416409796971863099144323163249651172534872992222856507897414949637892047507', 'changes': [{'price': '0.58', 'side': 'SELL', 'size': '688.1'}], 'event_type': 'price_change', 'hash': '886cd02ac45632612285bbb9546019299a61e7cb', 'market': '0x7aa4a910b31b2c4ddb09d1e3408e52aa8e09a14402f376070a44b1b85cb36d13', 'timestamp': '1733333922011'}
{'asset_id': '114416409796971863099144323163249651172534872992222856507897414949637892047507', 'changes': [{'price': '0.51', 'side': 'BUY', 'size': '1086.18'}], 'event_type': 'price_change', 'hash': 'ffa75a6d78f82769446f9dabf34b0b7db8564ea9', 'market': '0x7aa4a910b31b2c4ddb09d1e3408e52aa8e09a14402f376070a44b1b85cb36d13', 'timestamp': '1733333926012'}
{'asset_id': '114416409796971863099144323163249651172534872992222856507897414949637892047507', 'changes': [{'price': '0.51', 'side': 'BUY', 'size': '1086.18'}], 'event_type': 'price_change', 'hash': 'ffa75a6d78f82769446f9dabf34b0b7db8564ea9', 'market': '0x7aa4a910b31b2c4ddb09d1e3408e52aa8e09a14402f376070a44b1b85cb36d13', 'timestamp': '1733333926012'}
{'asset_id': '114416409796971863099144323163249651172534872992222856507897414949637892047507', 'changes': [{'price': '0.58', 'side': 'SELL', 'size': '188.1'}, {'price': '0.53', 'side': 'BUY', 'size': '149'}, {'price': '0.49', 'side': 'BUY', 'size': '140'}], 'event_type': 'price_change', 'hash': '9f6610b916331fd0a3bfb7669dbf05cd1584e244', 'market': '0x7aa4a910b31b2c4ddb09d1e3408e52aa8e09a14402f376070a44b1b85cb36d13', 'timestamp': '1733333927127'}
{'asset_id': '114416409796971863099144323163249651172534872992222856507897414949637892047507', 'changes': [{'price': '0.58', 'side': 'SELL', 'size': '188.1'}, {'price': '0.53', 'side': 'BUY', 'size': '149'}, {'price': '0.49', 'side': 'BUY', 'size': '140'}], 'event_type': 'price_change', 'hash': '9f6610b916331fd0a3bfb7669dbf05cd1584e244', 'market': '0x7aa4a910b31b2c4ddb09d1e3408e52aa8e09a14402f376070a44b1b85cb36d13', 'timestamp': '1733333927127'}
{'asset_id': '114416409796971863099144323163249651172534872992222856507897414949637892047507', 'changes': [{'price': '0.48', 'side': 'BUY', 'size': '742.18'}], 'event_type': 'price_change', 'hash': 'c4bcae3f9246a26e717664e0825060f69cf90df1', 'market': '0x7aa4a910b31b2c4ddb09d1e3408e52aa8e09a14402f376070a44b1b85cb36d13', 'timestamp': '1733333928168'}
{'asset_id': '114416409796971863099144323163249651172534872992222856507897414949637892047507', 'changes': [{'price': '0.48', 'side': 'BUY', 'size': '742.18'}], 'event_type': 'price_change', 'hash': 'c4bcae3f9246a26e717664e0825060f69cf90df1', 'market': '0x7aa4a910b31b2c4ddb09d1e3408e52aa8e09a14402f376070a44b1b85cb36d13', 'timestamp': '1733333928168'}
{'asset_id': '114416409796971863099144323163249651172534872992222856507897414949637892047507', 'changes': [{'price': '0.57', 'side': 'SELL', 'size': '610.1'}], 'event_type': 'price_change', 'hash': 'dcd6545350c42e06dafca3b616a48b811b284c13', 'market': '0x7aa4a910b31b2c4ddb09d1e3408e52aa8e09a14402f376070a44b1b85cb36d13', 'timestamp': '1733333928549'}
{'asset_id': '114416409796971863099144323163249651172534872992222856507897414949637892047507', 'changes': [{'price': '0.57', 'side': 'SELL', 'size': '610.1'}], 'event_type': 'price_change', 'hash': 'dcd6545350c42e06dafca3b616a48b811b284c13', 'market': '0x7aa4a910b31b2c4ddb09d1e3408e52aa8e09a14402f376070a44b1b85cb36d13', 'timestamp': '1733333928549'}
{'asset_id': '114416409796971863099144323163249651172534872992222856507897414949637892047507', 'changes': [{'price': '0.52', 'side': 'BUY', 'size': '3062.77'}], 'event_type': 'price_change', 'hash': '9156fd96fa7c0ffcaae328a5325fbe681e767efe', 'market': '0x7aa4a910b31b2c4ddb09d1e3408e52aa8e09a14402f376070a44b1b85cb36d13', 'timestamp': '1733333929022'}
{'asset_id': '114416409796971863099144323163249651172534872992222856507897414949637892047507', 'changes': [{'price': '0.52', 'side': 'BUY', 'size': '3062.77'}], 'event_type': 'price_change', 'hash': '9156fd96fa7c0ffcaae328a5325fbe681e767efe', 'market': '0x7aa4a910b31b2c4ddb09d1e3408e52aa8e09a14402f376070a44b1b85cb36d13', 'timestamp': '1733333929022'}
{'asset_id': '114416409796971863099144323163249651172534872992222856507897414949637892047507', 'changes': [{'price': '0.58', 'side': 'SELL', 'size': '1388.1'}], 'event_type': 'price_change', 'hash': 'd0853211aafb01501d827c1aadd44f3f41657df9', 'market': '0x7aa4a910b31b2c4ddb09d1e3408e52aa8e09a14402f376070a44b1b85cb36d13', 'timestamp': '1733333932261'}
{'asset_id': '114416409796971863099144323163249651172534872992222856507897414949637892047507', 'changes': [{'price': '0.58', 'side': 'SELL', 'size': '1388.1'}], 'event_type': 'price_change', 'hash': 'd0853211aafb01501d827c1aadd44f3f41657df9', 'market': '0x7aa4a910b31b2c4ddb09d1e3408e52aa8e09a14402f376070a44b1b85cb36d13', 'timestamp': '1733333932261'}
{'asset_id': '114416409796971863099144323163249651172534872992222856507897414949637892047507', 'changes': [{'price': '0.51', 'side': 'BUY', 'size': '2586.18'}], 'event_type': 'price_change', 'hash': '53bb0c75a978dca6b2560ed70d21a999afb5a4e0', 'market': '0x7aa4a910b31b2c4ddb09d1e3408e52aa8e09a14402f376070a44b1b85cb36d13', 'timestamp': '1733333939798'}
{'asset_id': '114416409796971863099144323163249651172534872992222856507897414949637892047507', 'changes': [{'price': '0.51', 'side': 'BUY', 'size': '2586.18'}], 'event_type': 'price_change', 'hash': '53bb0c75a978dca6b2560ed70d21a999afb5a4e0', 'market': '0x7aa4a910b31b2c4ddb09d1e3408e52aa8e09a14402f376070a44b1b85cb36d13', 'timestamp': '1733333939798'}
{'asks': [{'price': '0.99', 'size': '4217.01'}, {'price': '0.98', 'size': '505'}, {'price': '0.97', 'size': '511.03'}, {'price': '0.96', 'size': '300'}, {'price': '0.95', 'size': '657.12'}, {'price': '0.94', 'size': '300'}, {'price': '0.92', 'size': '20000.45'}, {'price': '0.91', 'size': '10406.3'}, {'price': '0.9', 'size': '4587.5'}, {'price': '0.89', 'size': '13017.18'}, {'price': '0.88', 'size': '200'}, {'price': '0.87', 'size': '3229'}, {'price': '0.86', 'size': '17.1'}, {'price': '0.85', 'size': '109.68'}, {'price': '0.84', 'size': '250'}, {'price': '0.83', 'size': '100'}, {'price': '0.82', 'size': '16029'}, {'price': '0.81', 'size': '45721.39'}, {'price': '0.8', 'size': '26531'}, {'price': '0.79', 'size': '7110'}, {'price': '0.78', 'size': '10350'}, {'price': '0.77', 'size': '67'}, {'price': '0.76', 'size': '200'}, {'price': '0.75', 'size': '18329.25'}, {'price': '0.74', 'size': '11370.7'}, {'price': '0.73', 'size': '5020.1'}, {'price': '0.72', 'size': '380.52'}, {'price': '0.71', 'size': '15073.2'}, {'price': '0.7', 'size': '5570.1'}, {'price': '0.69', 'size': '6088.6'}, {'price': '0.68', 'size': '6131.34'}, {'price': '0.67', 'size': '3010.1'}, {'price': '0.66', 'size': '510.1'}, {'price': '0.65', 'size': '1010.1'}, {'price': '0.64', 'size': '4230.1'}, {'price': '0.63', 'size': '210.1'}, {'price': '0.62', 'size': '2800.1'}, {'price': '0.61', 'size': '2511.06'}, {'price': '0.6', 'size': '467.85'}, {'price': '0.59', 'size': '1880'}, {'price': '0.58', 'size': '1388.1'}, {'price': '0.57', 'size': '610.1'}, {'price': '0.56', 'size': '1249.1'}], 'asset_id': '114416409796971863099144323163249651172534872992222856507897414949637892047507', 'bids': [{'price': '0.01', 'size': '2850.27'}, {'price': '0.02', 'size': '500'}, {'price': '0.03', 'size': '500'}, {'price': '0.04', 'size': '300'}, {'price': '0.05', 'size': '320'}, {'price': '0.06', 'size': '300'}, {'price': '0.08', 'size': '250'}, {'price': '0.09', 'size': '300'}, {'price': '0.1', 'size': '6205'}, {'price': '0.12', 'size': '200'}, {'price': '0.13', 'size': '426.92'}, {'price': '0.14', 'size': '15'}, {'price': '0.15', 'size': '110'}, {'price': '0.16', 'size': '4709.51'}, {'price': '0.18', 'size': '19.13'}, {'price': '0.19', 'size': '120'}, {'price': '0.2', 'size': '691.17'}, {'price': '0.24', 'size': '5027'}, {'price': '0.25', 'size': '86.66'}, {'price': '0.27', 'size': '215.25'}, {'price': '0.29', 'size': '1102.28'}, {'price': '0.31', 'size': '1130.65'}, {'price': '0.32', 'size': '200'}, {'price': '0.33', 'size': '620'}, {'price': '0.34', 'size': '4000'}, {'price': '0.35', 'size': '232'}, {'price': '0.39', 'size': '10.5'}, {'price': '0.4', 'size': '3135'}, {'price': '0.41', 'size': '20'}, {'price': '0.42', 'size': '3050'}, {'price': '0.43', 'size': '50'}, {'price': '0.44', 'size': '3660'}, {'price': '0.45', 'size': '478'}, {'price': '0.47', 'size': '2797.23'}, {'price': '0.48', 'size': '742.18'}, {'price': '0.49', 'size': '140'}, {'price': '0.5', 'size': '2355'}, {'price': '0.51', 'size': '2586.18'}, {'price': '0.52', 'size': '3062.77'}, {'price': '0.53', 'size': '149'}, {'price': '0.54', 'size': '36.18'}, {'price': '0.55', 'size': '4086.29'}], 'event_type': 'book', 'hash': '8b416babb5401c7cf66f3907e0f0d36f72a389e4', 'market': '0x7aa4a910b31b2c4ddb09d1e3408e52aa8e09a14402f376070a44b1b85cb36d13', 'timestamp': '1733333952671'}
{'asset_id': '114416409796971863099144323163249651172534872992222856507897414949637892047507', 'changes': [{'price': '0.55', 'side': 'BUY', 'size': '4086.29'}], 'event_type': 'price_change', 'hash': '8b416babb5401c7cf66f3907e0f0d36f72a389e4', 'market': '0x7aa4a910b31b2c4ddb09d1e3408e52aa8e09a14402f376070a44b1b85cb36d13', 'timestamp': '1733333952680'}
{'asset_id': '114416409796971863099144323163249651172534872992222856507897414949637892047507', 'event_type': 'last_trade_price', 'fee_rate_bps': '0', 'market': '0x7aa4a910b31b2c4ddb09d1e3408e52aa8e09a14402f376070a44b1b85cb36d13', 'price': '0.55', 'side': 'BUY', 'size': '913.71', 'timestamp': '1733333952690'}
