{'market': '0x9d1f0296f3a016727193d2b45704e0debc3b8048fe0715f8bb1e91550d321872', 'asset_id': '101669189743438912873361127612589311253202068943959811456820079057046819967115', 'timestamp': '1733967617173', 'hash': '4ae402c8ea07c1749abb3bab487041535c415b50', 'bids': [{'price': '0.001', 'size': '50000'}, {'price': '0.002', 'size': '500012'}, {'price': '0.003', 'size': '10000'}, {'price': '0.012', 'size': '90000'}, {'price': '0.013', 'size': '5000'}, {'price': '0.016', 'size': '50000'}, {'price': '0.021', 'size': '2000'}, {'price': '0.035', 'size': '30000'}, {'price': '0.039', 'size': '4000'}, {'price': '0.04', 'size': '14250'}, {'price': '0.351', 'size': '500'}, {'price': '0.352', 'size': '3692'}, {'price': '0.602', 'size': '420'}, {'price': '0.681', 'size': '800'}, {'price': '0.826', 'size': '111'}, {'price': '0.831', 'size': '5'}, {'price': '0.833', 'size': '2362.51'}, {'price': '0.847', 'size': '200.11'}, {'price': '0.89', 'size': '2115.19'}, {'price': '0.896', 'size': '1000'}, {'price': '0.901', 'size': '11000'}, {'price': '0.902', 'size': '450'}, {'price': '0.915', 'size': '2484.75'}, {'price': '0.917', 'size': '400'}, {'price': '0.919', 'size': '17.81'}, {'price': '0.922', 'size': '10000'}, {'price': '0.925', 'size': '10200'}, {'price': '0.926', 'size': '5000'}, {'price': '0.927', 'size': '5462'}, {'price': '0.93', 'size': '318'}, {'price': '0.931', 'size': '5'}, {'price': '0.933', 'size': '107'}], 'asks': [{'price': '0.999', 'size': '100000'}, {'price': '0.995', 'size': '180.38'}, {'price': '0.985', 'size': '168.56'}, {'price': '0.98', 'size': '1795'}, {'price': '0.968', 'size': '32115.44'}, {'price': '0.96', 'size': '5000'}, {'price': '0.957', 'size': '333'}, {'price': '0.955', 'size': '57000'}, {'price': '0.945', 'size': '10000'}, {'price': '0.944', 'size': '5720.36'}, {'price': '0.942', 'size': '2471'}, {'price': '0.941', 'size': '151'}], 'event_type': 'book'}
{'asset_id': '101669189743438912873361127612589311253202068943959811456820079057046819967115', 'changes': [{'price': '0.933', 'side': 'BUY', 'size': '0'}], 'event_type': 'price_change', 'hash': '4f0807351f631b5f689333b80571775e54f87287', 'market': '0x9d1f0296f3a016727193d2b45704e0debc3b8048fe0715f8bb1e91550d321872', 'timestamp': '1733967621124'}
{'asset_id': '101669189743438912873361127612589311253202068943959811456820079057046819967115', 'changes': [{'price': '0.932', 'side': 'BUY', 'size': '172.39'}], 'event_type': 'price_change', 'hash': 'b8b2e8cd02f49da9f4442889b0ba63d831a2e380', 'market': '0x9d1f0296f3a016727193d2b45704e0debc3b8048fe0715f8bb1e91550d321872', 'timestamp': '1733967621918'}
{'market': '0x9d1f0296f3a016727193d2b45704e0debc3b8048fe0715f8bb1e91550d321872', 'asset_id': '101669189743438912873361127612589311253202068943959811456820079057046819967115', 'timestamp': '1733967621914', 'hash': 'b8b2e8cd02f49da9f4442889b0ba63d831a2e380', 'bids': [{'price': '0.001', 'size': '50000'}, {'price': '0.002', 'size': '500012'}, {'price': '0.003', 'size': '10000'}, {'price': '0.012', 'size': '90000'}, {'price': '0.013', 'size': '5000'}, {'price': '0.016', 'size': '50000'}, {'price': '0.021', 'size': '2000'}, {'price': '0.035', 'size': '30000'}, {'price': '0.039', 'size': '4000'}, {'price': '0.04', 'size': '14250'}, {'price': '0.351', 'size': '500'}, {'price': '0.352', 'size': '3692'}, {'price': '0.602', 'size': '420'}, {'price': '0.681', 'size': '800'}, {'price': '0.826', 'size': '111'}, {'price': '0.831', 'size': '5'}, {'price': '0.833', 'size': '2362.51'}, {'price': '0.847', 'size': '200.11'}, {'price': '0.89', 'size': '2115.19'}, {'price': '0.896', 'size': '1000'}, {'price': '0.901', 'size': '11000'}, {'price': '0.902', 'size': '450'}, {'price': '0.915', 'size': '2484.75'}, {'price': '0.917', 'size': '400'}, {'price': '0.919', 'size': '17.81'}, {'price': '0.922', 'size': '10000'}, {'price': '0.925', 'size': '10200'}, {'price': '0.926', 'size': '5000'}, {'price': '0.927', 'size': '5462'}, {'price': '0.93', 'size': '318'}, {'price': '0.931', 'size': '5'}, {'price': '0.932', 'size': '172.39'}], 'asks': [{'price': '0.999', 'size': '100000'}, {'price': '0.995', 'size': '180.38'}, {'price': '0.985', 'size': '168.56'}, {'price': '0.98', 'size': '1795'}, {'price': '0.968', 'size': '32115.44'}, {'price': '0.96', 'size': '5000'}, {'price': '0.957', 'size': '333'}, {'price': '0.955', 'size': '57000'}, {'price': '0.945', 'size': '10000'}, {'price': '0.944', 'size': '5720.36'}, {'price': '0.942', 'size': '2471'}, {'price': '0.941', 'size': '151'}], 'event_type': 'book'}
{'asset_id': '101669189743438912873361127612589311253202068943959811456820079057046819967115', 'changes': [{'price': '0.933', 'side': 'BUY', 'size': '107'}], 'event_type': 'price_change', 'hash': '0c7e23d77bcd3e094109fb4ee372c914534044fb', 'market': '0x9d1f0296f3a016727193d2b45704e0debc3b8048fe0715f8bb1e91550d321872', 'timestamp': '1733967624937'}
{'asset_id': '101669189743438912873361127612589311253202068943959811456820079057046819967115', 'changes': [{'price': '0.933', 'side': 'BUY', 'size': '107'}], 'event_type': 'price_change', 'hash': '0c7e23d77bcd3e094109fb4ee372c914534044fb', 'market': '0x9d1f0296f3a016727193d2b45704e0debc3b8048fe0715f8bb1e91550d321872', 'timestamp': '1733967624937'}
{'asset_id': '101669189743438912873361127612589311253202068943959811456820079057046819967115', 'changes': [{'price': '0.932', 'side': 'BUY', 'size': '0'}], 'event_type': 'price_change', 'hash': '0088af7dfd139853ecba5c04b65b53e6f277cd83', 'market': '0x9d1f0296f3a016727193d2b45704e0debc3b8048fe0715f8bb1e91550d321872', 'timestamp': '1733967626205'}
{'asset_id': '101669189743438912873361127612589311253202068943959811456820079057046819967115', 'changes': [{'price': '0.932', 'side': 'BUY', 'size': '0'}], 'event_type': 'price_change', 'hash': '0088af7dfd139853ecba5c04b65b53e6f277cd83', 'market': '0x9d1f0296f3a016727193d2b45704e0debc3b8048fe0715f8bb1e91550d321872', 'timestamp': '1733967626205'}
{'asset_id': '101669189743438912873361127612589311253202068943959811456820079057046819967115', 'changes': [{'price': '0.933', 'side': 'BUY', 'size': '0'}], 'event_type': 'price_change', 'hash': 'c1c3ea49f53ca8c4de09cd85a751eb4b6dc4dc4e', 'market': '0x9d1f0296f3a016727193d2b45704e0debc3b8048fe0715f8bb1e91550d321872', 'timestamp': '1733967629173'}
{'asset_id': '101669189743438912873361127612589311253202068943959811456820079057046819967115', 'changes': [{'price': '0.933', 'side': 'BUY', 'size': '0'}], 'event_type': 'price_change', 'hash': 'c1c3ea49f53ca8c4de09cd85a751eb4b6dc4dc4e', 'market': '0x9d1f0296f3a016727193d2b45704e0debc3b8048fe0715f8bb1e91550d321872', 'timestamp': '1733967629173'}
{'asset_id': '101669189743438912873361127612589311253202068943959811456820079057046819967115', 'changes': [{'price': '0.932', 'side': 'BUY', 'size': '172.39'}], 'event_type': 'price_change', 'hash': '5fc849729f84a2bb25243236c8b373abdcc5b282', 'market': '0x9d1f0296f3a016727193d2b45704e0debc3b8048fe0715f8bb1e91550d321872', 'timestamp': '1733967629970'}
{'asset_id': '101669189743438912873361127612589311253202068943959811456820079057046819967115', 'changes': [{'price': '0.932', 'side': 'BUY', 'size': '172.39'}], 'event_type': 'price_change', 'hash': '5fc849729f84a2bb25243236c8b373abdcc5b282', 'market': '0x9d1f0296f3a016727193d2b45704e0debc3b8048fe0715f8bb1e91550d321872', 'timestamp': '1733967629970'}
{'asset_id': '101669189743438912873361127612589311253202068943959811456820079057046819967115', 'changes': [{'price': '0.933', 'side': 'BUY', 'size': '107'}], 'event_type': 'price_change', 'hash': '70e03a10b8695ff9b945257175b7ca310d81c582', 'market': '0x9d1f0296f3a016727193d2b45704e0debc3b8048fe0715f8bb1e91550d321872', 'timestamp': '1733967632927'}
{'asset_id': '101669189743438912873361127612589311253202068943959811456820079057046819967115', 'changes': [{'price': '0.933', 'side': 'BUY', 'size': '107'}], 'event_type': 'price_change', 'hash': '70e03a10b8695ff9b945257175b7ca310d81c582', 'market': '0x9d1f0296f3a016727193d2b45704e0debc3b8048fe0715f8bb1e91550d321872', 'timestamp': '1733967632927'}
{'asset_id': '101669189743438912873361127612589311253202068943959811456820079057046819967115', 'changes': [{'price': '0.932', 'side': 'BUY', 'size': '0'}], 'event_type': 'price_change', 'hash': 'cdaa5e7ea3c42b26a5ed60f1cc2fa8ac0c250ecd', 'market': '0x9d1f0296f3a016727193d2b45704e0debc3b8048fe0715f8bb1e91550d321872', 'timestamp': '1733967634190'}
{'asset_id': '101669189743438912873361127612589311253202068943959811456820079057046819967115', 'changes': [{'price': '0.932', 'side': 'BUY', 'size': '0'}], 'event_type': 'price_change', 'hash': 'cdaa5e7ea3c42b26a5ed60f1cc2fa8ac0c250ecd', 'market': '0x9d1f0296f3a016727193d2b45704e0debc3b8048fe0715f8bb1e91550d321872', 'timestamp': '1733967634190'}
{'asset_id': '101669189743438912873361127612589311253202068943959811456820079057046819967115', 'changes': [{'price': '0.933', 'side': 'BUY', 'size': '0'}], 'event_type': 'price_change', 'hash': '68bfe4433c2ecfdbb8516473dd2dd72dcd8019aa', 'market': '0x9d1f0296f3a016727193d2b45704e0debc3b8048fe0715f8bb1e91550d321872', 'timestamp': '1733967637180'}
{'asset_id': '101669189743438912873361127612589311253202068943959811456820079057046819967115', 'changes': [{'price': '0.933', 'side': 'BUY', 'size': '0'}], 'event_type': 'price_change', 'hash': '68bfe4433c2ecfdbb8516473dd2dd72dcd8019aa', 'market': '0x9d1f0296f3a016727193d2b45704e0debc3b8048fe0715f8bb1e91550d321872', 'timestamp': '1733967637180'}
{'asset_id': '101669189743438912873361127612589311253202068943959811456820079057046819967115', 'changes': [{'price': '0.95', 'side': 'SELL', 'size': '78'}], 'event_type': 'price_change', 'hash': '574454f35377de5db6786a5545ff61121158716a', 'market': '0x9d1f0296f3a016727193d2b45704e0debc3b8048fe0715f8bb1e91550d321872', 'timestamp': '1733967637738'}
{'asset_id': '101669189743438912873361127612589311253202068943959811456820079057046819967115', 'changes': [{'price': '0.95', 'side': 'SELL', 'size': '78'}], 'event_type': 'price_change', 'hash': '574454f35377de5db6786a5545ff61121158716a', 'market': '0x9d1f0296f3a016727193d2b45704e0debc3b8048fe0715f8bb1e91550d321872', 'timestamp': '1733967637738'}
{'asset_id': '101669189743438912873361127612589311253202068943959811456820079057046819967115', 'changes': [{'price': '0.932', 'side': 'BUY', 'size': '172.39'}], 'event_type': 'price_change', 'hash': '830d402ed272b10a009e12bcd6d2fa1753545551', 'market': '0x9d1f0296f3a016727193d2b45704e0debc3b8048fe0715f8bb1e91550d321872', 'timestamp': '1733967637976'}
{'asset_id': '101669189743438912873361127612589311253202068943959811456820079057046819967115', 'changes': [{'price': '0.932', 'side': 'BUY', 'size': '172.39'}], 'event_type': 'price_change', 'hash': '830d402ed272b10a009e12bcd6d2fa1753545551', 'market': '0x9d1f0296f3a016727193d2b45704e0debc3b8048fe0715f8bb1e91550d321872', 'timestamp': '1733967637976'}
{'asset_id': '101669189743438912873361127612589311253202068943959811456820079057046819967115', 'changes': [{'price': '0.933', 'side': 'BUY', 'size': '107'}], 'event_type': 'price_change', 'hash': '9b88123e91aec771112eebeda0eaa3329df3daaa', 'market': '0x9d1f0296f3a016727193d2b45704e0debc3b8048fe0715f8bb1e91550d321872', 'timestamp': '1733967640928'}
{'asset_id': '101669189743438912873361127612589311253202068943959811456820079057046819967115', 'changes': [{'price': '0.933', 'side': 'BUY', 'size': '107'}], 'event_type': 'price_change', 'hash': '9b88123e91aec771112eebeda0eaa3329df3daaa', 'market': '0x9d1f0296f3a016727193d2b45704e0debc3b8048fe0715f8bb1e91550d321872', 'timestamp': '1733967640928'}
{'asset_id': '101669189743438912873361127612589311253202068943959811456820079057046819967115', 'changes': [{'price': '0.932', 'side': 'BUY', 'size': '0'}], 'event_type': 'price_change', 'hash': 'bcee108bb74c41220b9b1f448f7155150dda0cc3', 'market': '0x9d1f0296f3a016727193d2b45704e0debc3b8048fe0715f8bb1e91550d321872', 'timestamp': '1733967642192'}
{'asset_id': '101669189743438912873361127612589311253202068943959811456820079057046819967115', 'changes': [{'price': '0.932', 'side': 'BUY', 'size': '0'}], 'event_type': 'price_change', 'hash': 'bcee108bb74c41220b9b1f448f7155150dda0cc3', 'market': '0x9d1f0296f3a016727193d2b45704e0debc3b8048fe0715f8bb1e91550d321872', 'timestamp': '1733967642192'}
{'asset_id': '101669189743438912873361127612589311253202068943959811456820079057046819967115', 'changes': [{'price': '0.933', 'side': 'BUY', 'size': '0'}], 'event_type': 'price_change', 'hash': '441ea055a226236f73cb53573419ab0028ab9b94', 'market': '0x9d1f0296f3a016727193d2b45704e0debc3b8048fe0715f8bb1e91550d321872', 'timestamp': '1733967645152'}
{'asset_id': '101669189743438912873361127612589311253202068943959811456820079057046819967115', 'changes': [{'price': '0.933', 'side': 'BUY', 'size': '0'}], 'event_type': 'price_change', 'hash': '441ea055a226236f73cb53573419ab0028ab9b94', 'market': '0x9d1f0296f3a016727193d2b45704e0debc3b8048fe0715f8bb1e91550d321872', 'timestamp': '1733967645152'}
{'asset_id': '101669189743438912873361127612589311253202068943959811456820079057046819967115', 'changes': [{'price': '0.98', 'side': 'SELL', 'size': '0'}], 'event_type': 'price_change', 'hash': '23e206c1916c8cc0f66d89351889bf23a15a28fd', 'market': '0x9d1f0296f3a016727193d2b45704e0debc3b8048fe0715f8bb1e91550d321872', 'timestamp': '1733967645492'}
{'asset_id': '101669189743438912873361127612589311253202068943959811456820079057046819967115', 'changes': [{'price': '0.98', 'side': 'SELL', 'size': '0'}], 'event_type': 'price_change', 'hash': '23e206c1916c8cc0f66d89351889bf23a15a28fd', 'market': '0x9d1f0296f3a016727193d2b45704e0debc3b8048fe0715f8bb1e91550d321872', 'timestamp': '1733967645492'}
{'asset_id': '101669189743438912873361127612589311253202068943959811456820079057046819967115', 'changes': [{'price': '0.95', 'side': 'SELL', 'size': '156'}], 'event_type': 'price_change', 'hash': 'a091a63e203f3707e07e5348db1b096f41c2dc22', 'market': '0x9d1f0296f3a016727193d2b45704e0debc3b8048fe0715f8bb1e91550d321872', 'timestamp': '1733967645602'}
{'asset_id': '101669189743438912873361127612589311253202068943959811456820079057046819967115', 'changes': [{'price': '0.95', 'side': 'SELL', 'size': '156'}], 'event_type': 'price_change', 'hash': 'a091a63e203f3707e07e5348db1b096f41c2dc22', 'market': '0x9d1f0296f3a016727193d2b45704e0debc3b8048fe0715f8bb1e91550d321872', 'timestamp': '1733967645602'}
{'asset_id': '101669189743438912873361127612589311253202068943959811456820079057046819967115', 'changes': [{'price': '0.932', 'side': 'BUY', 'size': '172.39'}], 'event_type': 'price_change', 'hash': '84af493ac7eed7f38857a34a23ee5608c4d15c56', 'market': '0x9d1f0296f3a016727193d2b45704e0debc3b8048fe0715f8bb1e91550d321872', 'timestamp': '1733967645926'}
{'asset_id': '101669189743438912873361127612589311253202068943959811456820079057046819967115', 'changes': [{'price': '0.932', 'side': 'BUY', 'size': '172.39'}], 'event_type': 'price_change', 'hash': '84af493ac7eed7f38857a34a23ee5608c4d15c56', 'market': '0x9d1f0296f3a016727193d2b45704e0debc3b8048fe0715f8bb1e91550d321872', 'timestamp': '1733967645926'}
{'asset_id': '101669189743438912873361127612589311253202068943959811456820079057046819967115', 'changes': [{'price': '0.933', 'side': 'BUY', 'size': '107'}], 'event_type': 'price_change', 'hash': '9c152b7bf39cb7c15068f0c90bc52ef80b7f3316', 'market': '0x9d1f0296f3a016727193d2b45704e0debc3b8048fe0715f8bb1e91550d321872', 'timestamp': '1733967648925'}
{'asset_id': '101669189743438912873361127612589311253202068943959811456820079057046819967115', 'changes': [{'price': '0.933', 'side': 'BUY', 'size': '107'}], 'event_type': 'price_change', 'hash': '9c152b7bf39cb7c15068f0c90bc52ef80b7f3316', 'market': '0x9d1f0296f3a016727193d2b45704e0debc3b8048fe0715f8bb1e91550d321872', 'timestamp': '1733967648925'}
{'asset_id': '101669189743438912873361127612589311253202068943959811456820079057046819967115', 'changes': [{'price': '0.932', 'side': 'BUY', 'size': '0'}], 'event_type': 'price_change', 'hash': 'a3f7f7ee6e8662b3f87f382da5c7ad2475dc8226', 'market': '0x9d1f0296f3a016727193d2b45704e0debc3b8048fe0715f8bb1e91550d321872', 'timestamp': '1733967651192'}
{'asset_id': '101669189743438912873361127612589311253202068943959811456820079057046819967115', 'changes': [{'price': '0.932', 'side': 'BUY', 'size': '0'}], 'event_type': 'price_change', 'hash': 'a3f7f7ee6e8662b3f87f382da5c7ad2475dc8226', 'market': '0x9d1f0296f3a016727193d2b45704e0debc3b8048fe0715f8bb1e91550d321872', 'timestamp': '1733967651192'}
{'asset_id': '101669189743438912873361127612589311253202068943959811456820079057046819967115', 'changes': [{'price': '0.933', 'side': 'BUY', 'size': '0'}], 'event_type': 'price_change', 'hash': '08c20a5889a9d03f39adc99bc1ddbaa1bf009aaa', 'market': '0x9d1f0296f3a016727193d2b45704e0debc3b8048fe0715f8bb1e91550d321872', 'timestamp': '1733967654222'}
{'asset_id': '101669189743438912873361127612589311253202068943959811456820079057046819967115', 'changes': [{'price': '0.933', 'side': 'BUY', 'size': '0'}], 'event_type': 'price_change', 'hash': '08c20a5889a9d03f39adc99bc1ddbaa1bf009aaa', 'market': '0x9d1f0296f3a016727193d2b45704e0debc3b8048fe0715f8bb1e91550d321872', 'timestamp': '1733967654222'}
{'asset_id': '101669189743438912873361127612589311253202068943959811456820079057046819967115', 'changes': [{'price': '0.932', 'side': 'BUY', 'size': '172.39'}], 'event_type': 'price_change', 'hash': 'e9e8ee45c3c280a81e7f56689c2d51b96e6849f0', 'market': '0x9d1f0296f3a016727193d2b45704e0debc3b8048fe0715f8bb1e91550d321872', 'timestamp': '1733967656833'}
{'asset_id': '101669189743438912873361127612589311253202068943959811456820079057046819967115', 'changes': [{'price': '0.932', 'side': 'BUY', 'size': '172.39'}], 'event_type': 'price_change', 'hash': 'e9e8ee45c3c280a81e7f56689c2d51b96e6849f0', 'market': '0x9d1f0296f3a016727193d2b45704e0debc3b8048fe0715f8bb1e91550d321872', 'timestamp': '1733967656833'}
{'asset_id': '101669189743438912873361127612589311253202068943959811456820079057046819967115', 'changes': [{'price': '0.933', 'side': 'BUY', 'size': '107'}], 'event_type': 'price_change', 'hash': 'f7b6b864767dd53f88ab6c7028ac479e3e039649', 'market': '0x9d1f0296f3a016727193d2b45704e0debc3b8048fe0715f8bb1e91550d321872', 'timestamp': '1733967660086'}
{'asset_id': '101669189743438912873361127612589311253202068943959811456820079057046819967115', 'changes': [{'price': '0.933', 'side': 'BUY', 'size': '107'}], 'event_type': 'price_change', 'hash': 'f7b6b864767dd53f88ab6c7028ac479e3e039649', 'market': '0x9d1f0296f3a016727193d2b45704e0debc3b8048fe0715f8bb1e91550d321872', 'timestamp': '1733967660086'}
{'asset_id': '101669189743438912873361127612589311253202068943959811456820079057046819967115', 'changes': [{'price': '0.932', 'side': 'BUY', 'size': '0'}], 'event_type': 'price_change', 'hash': '2edd548078b2e5e30c6aa0d5a96a12f6af6c8d66', 'market': '0x9d1f0296f3a016727193d2b45704e0debc3b8048fe0715f8bb1e91550d321872', 'timestamp': '1733967661321'}
{'asset_id': '101669189743438912873361127612589311253202068943959811456820079057046819967115', 'changes': [{'price': '0.932', 'side': 'BUY', 'size': '0'}], 'event_type': 'price_change', 'hash': '2edd548078b2e5e30c6aa0d5a96a12f6af6c8d66', 'market': '0x9d1f0296f3a016727193d2b45704e0debc3b8048fe0715f8bb1e91550d321872', 'timestamp': '1733967661321'}
{'asset_id': '101669189743438912873361127612589311253202068943959811456820079057046819967115', 'changes': [{'price': '0.933', 'side': 'BUY', 'size': '0'}], 'event_type': 'price_change', 'hash': 'b3a9117eb4471ef57941942aa39b96bce366d897', 'market': '0x9d1f0296f3a016727193d2b45704e0debc3b8048fe0715f8bb1e91550d321872', 'timestamp': '1733967664305'}
{'asset_id': '101669189743438912873361127612589311253202068943959811456820079057046819967115', 'changes': [{'price': '0.933', 'side': 'BUY', 'size': '0'}], 'event_type': 'price_change', 'hash': 'b3a9117eb4471ef57941942aa39b96bce366d897', 'market': '0x9d1f0296f3a016727193d2b45704e0debc3b8048fe0715f8bb1e91550d321872', 'timestamp': '1733967664305'}
{'asset_id': '101669189743438912873361127612589311253202068943959811456820079057046819967115', 'changes': [{'price': '0.932', 'side': 'BUY', 'size': '172.39'}], 'event_type': 'price_change', 'hash': 'f34d11343cbf1aa0aeeba520f41ecd06cd886ffa', 'market': '0x9d1f0296f3a016727193d2b45704e0debc3b8048fe0715f8bb1e91550d321872', 'timestamp': '1733967665077'}
{'asset_id': '101669189743438912873361127612589311253202068943959811456820079057046819967115', 'changes': [{'price': '0.932', 'side': 'BUY', 'size': '172.39'}], 'event_type': 'price_change', 'hash': 'f34d11343cbf1aa0aeeba520f41ecd06cd886ffa', 'market': '0x9d1f0296f3a016727193d2b45704e0debc3b8048fe0715f8bb1e91550d321872', 'timestamp': '1733967665077'}
{'asset_id': '101669189743438912873361127612589311253202068943959811456820079057046819967115', 'changes': [{'price': '0.933', 'side': 'BUY', 'size': '107'}], 'event_type': 'price_change', 'hash': '02ffde680d28d84c1c7c91e993fdac1d0372d064', 'market': '0x9d1f0296f3a016727193d2b45704e0debc3b8048fe0715f8bb1e91550d321872', 'timestamp': '1733967669057'}
{'asset_id': '101669189743438912873361127612589311253202068943959811456820079057046819967115', 'changes': [{'price': '0.933', 'side': 'BUY', 'size': '107'}], 'event_type': 'price_change', 'hash': '02ffde680d28d84c1c7c91e993fdac1d0372d064', 'market': '0x9d1f0296f3a016727193d2b45704e0debc3b8048fe0715f8bb1e91550d321872', 'timestamp': '1733967669057'}
{'asset_id': '101669189743438912873361127612589311253202068943959811456820079057046819967115', 'changes': [{'price': '0.932', 'side': 'BUY', 'size': '0'}], 'event_type': 'price_change', 'hash': '038a1ded99ae23b13f07bc1b1a79a2122844b5aa', 'market': '0x9d1f0296f3a016727193d2b45704e0debc3b8048fe0715f8bb1e91550d321872', 'timestamp': '1733967671100'}
{'asset_id': '101669189743438912873361127612589311253202068943959811456820079057046819967115', 'changes': [{'price': '0.932', 'side': 'BUY', 'size': '0'}], 'event_type': 'price_change', 'hash': '038a1ded99ae23b13f07bc1b1a79a2122844b5aa', 'market': '0x9d1f0296f3a016727193d2b45704e0debc3b8048fe0715f8bb1e91550d321872', 'timestamp': '1733967671100'}
{'asset_id': '101669189743438912873361127612589311253202068943959811456820079057046819967115', 'changes': [{'price': '0.933', 'side': 'BUY', 'size': '0'}], 'event_type': 'price_change', 'hash': '49d2bbd1c6843b7179d4952118e4a7d262ab40a0', 'market': '0x9d1f0296f3a016727193d2b45704e0debc3b8048fe0715f8bb1e91550d321872', 'timestamp': '1733967674313'}
{'asset_id': '101669189743438912873361127612589311253202068943959811456820079057046819967115', 'changes': [{'price': '0.933', 'side': 'BUY', 'size': '0'}], 'event_type': 'price_change', 'hash': '49d2bbd1c6843b7179d4952118e4a7d262ab40a0', 'market': '0x9d1f0296f3a016727193d2b45704e0debc3b8048fe0715f8bb1e91550d321872', 'timestamp': '1733967674313'}
{'asset_id': '101669189743438912873361127612589311253202068943959811456820079057046819967115', 'changes': [{'price': '0.932', 'side': 'BUY', 'size': '172.39'}], 'event_type': 'price_change', 'hash': '60e93e26ea7d0e08f13676233f7d56e804073de3', 'market': '0x9d1f0296f3a016727193d2b45704e0debc3b8048fe0715f8bb1e91550d321872', 'timestamp': '1733967675117'}
{'asset_id': '101669189743438912873361127612589311253202068943959811456820079057046819967115', 'changes': [{'price': '0.932', 'side': 'BUY', 'size': '172.39'}], 'event_type': 'price_change', 'hash': '60e93e26ea7d0e08f13676233f7d56e804073de3', 'market': '0x9d1f0296f3a016727193d2b45704e0debc3b8048fe0715f8bb1e91550d321872', 'timestamp': '1733967675117'}
{'asset_id': '101669189743438912873361127612589311253202068943959811456820079057046819967115', 'changes': [{'price': '0.933', 'side': 'BUY', 'size': '107'}], 'event_type': 'price_change', 'hash': '36f7cc2ba8824d1b0859e03d335be8ee5994f945', 'market': '0x9d1f0296f3a016727193d2b45704e0debc3b8048fe0715f8bb1e91550d321872', 'timestamp': '1733967678123'}
{'asset_id': '101669189743438912873361127612589311253202068943959811456820079057046819967115', 'changes': [{'price': '0.933', 'side': 'BUY', 'size': '107'}], 'event_type': 'price_change', 'hash': '36f7cc2ba8824d1b0859e03d335be8ee5994f945', 'market': '0x9d1f0296f3a016727193d2b45704e0debc3b8048fe0715f8bb1e91550d321872', 'timestamp': '1733967678123'}
{'asset_id': '101669189743438912873361127612589311253202068943959811456820079057046819967115', 'changes': [{'price': '0.932', 'side': 'BUY', 'size': '0'}], 'event_type': 'price_change', 'hash': '7d31f41ee13b8703b3e8ceda307ae6b4c87b2147', 'market': '0x9d1f0296f3a016727193d2b45704e0debc3b8048fe0715f8bb1e91550d321872', 'timestamp': '1733967679359'}
{'asset_id': '101669189743438912873361127612589311253202068943959811456820079057046819967115', 'changes': [{'price': '0.932', 'side': 'BUY', 'size': '0'}], 'event_type': 'price_change', 'hash': '7d31f41ee13b8703b3e8ceda307ae6b4c87b2147', 'market': '0x9d1f0296f3a016727193d2b45704e0debc3b8048fe0715f8bb1e91550d321872', 'timestamp': '1733967679359'}
{'asset_id': '101669189743438912873361127612589311253202068943959811456820079057046819967115', 'changes': [{'price': '0.933', 'side': 'BUY', 'size': '0'}], 'event_type': 'price_change', 'hash': '98689eb243a8844e1d2668fe869b4932ed6f2a52', 'market': '0x9d1f0296f3a016727193d2b45704e0debc3b8048fe0715f8bb1e91550d321872', 'timestamp': '1733967682304'}
{'asset_id': '101669189743438912873361127612589311253202068943959811456820079057046819967115', 'changes': [{'price': '0.933', 'side': 'BUY', 'size': '0'}], 'event_type': 'price_change', 'hash': '98689eb243a8844e1d2668fe869b4932ed6f2a52', 'market': '0x9d1f0296f3a016727193d2b45704e0debc3b8048fe0715f8bb1e91550d321872', 'timestamp': '1733967682304'}
{'asset_id': '101669189743438912873361127612589311253202068943959811456820079057046819967115', 'changes': [{'price': '0.932', 'side': 'BUY', 'size': '172.39'}], 'event_type': 'price_change', 'hash': '19bc1f5566f610500c535d72673d75897f349d84', 'market': '0x9d1f0296f3a016727193d2b45704e0debc3b8048fe0715f8bb1e91550d321872', 'timestamp': '1733967683061'}
{'asset_id': '101669189743438912873361127612589311253202068943959811456820079057046819967115', 'changes': [{'price': '0.932', 'side': 'BUY', 'size': '172.39'}], 'event_type': 'price_change', 'hash': '19bc1f5566f610500c535d72673d75897f349d84', 'market': '0x9d1f0296f3a016727193d2b45704e0debc3b8048fe0715f8bb1e91550d321872', 'timestamp': '1733967683061'}
{'asset_id': '101669189743438912873361127612589311253202068943959811456820079057046819967115', 'changes': [{'price': '0.933', 'side': 'BUY', 'size': '107'}], 'event_type': 'price_change', 'hash': 'c034f4330b360993fb3ef903cd47125727e467f5', 'market': '0x9d1f0296f3a016727193d2b45704e0debc3b8048fe0715f8bb1e91550d321872', 'timestamp': '1733967686858'}
{'asset_id': '101669189743438912873361127612589311253202068943959811456820079057046819967115', 'changes': [{'price': '0.933', 'side': 'BUY', 'size': '107'}], 'event_type': 'price_change', 'hash': 'c034f4330b360993fb3ef903cd47125727e467f5', 'market': '0x9d1f0296f3a016727193d2b45704e0debc3b8048fe0715f8bb1e91550d321872', 'timestamp': '1733967686858'}
{'asset_id': '101669189743438912873361127612589311253202068943959811456820079057046819967115', 'changes': [{'price': '0.932', 'side': 'BUY', 'size': '0'}], 'event_type': 'price_change', 'hash': 'a795cdfc73f5676272b9e15c66f4da954a84f1ca', 'market': '0x9d1f0296f3a016727193d2b45704e0debc3b8048fe0715f8bb1e91550d321872', 'timestamp': '1733967688071'}
{'asset_id': '101669189743438912873361127612589311253202068943959811456820079057046819967115', 'changes': [{'price': '0.932', 'side': 'BUY', 'size': '0'}], 'event_type': 'price_change', 'hash': 'a795cdfc73f5676272b9e15c66f4da954a84f1ca', 'market': '0x9d1f0296f3a016727193d2b45704e0debc3b8048fe0715f8bb1e91550d321872', 'timestamp': '1733967688071'}
{'asset_id': '101669189743438912873361127612589311253202068943959811456820079057046819967115', 'changes': [{'price': '0.95', 'side': 'SELL', 'size': '78'}], 'event_type': 'price_change', 'hash': '3fc70cdc7715d4884a9c318cb72460853dd9b7ce', 'market': '0x9d1f0296f3a016727193d2b45704e0debc3b8048fe0715f8bb1e91550d321872', 'timestamp': '1733967690278'}
{'asset_id': '101669189743438912873361127612589311253202068943959811456820079057046819967115', 'changes': [{'price': '0.95', 'side': 'SELL', 'size': '78'}], 'event_type': 'price_change', 'hash': '3fc70cdc7715d4884a9c318cb72460853dd9b7ce', 'market': '0x9d1f0296f3a016727193d2b45704e0debc3b8048fe0715f8bb1e91550d321872', 'timestamp': '1733967690278'}
{'asset_id': '101669189743438912873361127612589311253202068943959811456820079057046819967115', 'changes': [{'price': '0.933', 'side': 'BUY', 'size': '0'}], 'event_type': 'price_change', 'hash': '0509cc1372805d2c64c515d9477f63819702be9f', 'market': '0x9d1f0296f3a016727193d2b45704e0debc3b8048fe0715f8bb1e91550d321872', 'timestamp': '1733967691304'}
{'asset_id': '101669189743438912873361127612589311253202068943959811456820079057046819967115', 'changes': [{'price': '0.933', 'side': 'BUY', 'size': '0'}], 'event_type': 'price_change', 'hash': '0509cc1372805d2c64c515d9477f63819702be9f', 'market': '0x9d1f0296f3a016727193d2b45704e0debc3b8048fe0715f8bb1e91550d321872', 'timestamp': '1733967691304'}
{'asset_id': '101669189743438912873361127612589311253202068943959811456820079057046819967115', 'changes': [{'price': '0.932', 'side': 'BUY', 'size': '172.39'}], 'event_type': 'price_change', 'hash': 'bca71732e897f4b1a6beda9a8a01ecb4baeeb2b6', 'market': '0x9d1f0296f3a016727193d2b45704e0debc3b8048fe0715f8bb1e91550d321872', 'timestamp': '1733967692064'}
{'asset_id': '101669189743438912873361127612589311253202068943959811456820079057046819967115', 'changes': [{'price': '0.932', 'side': 'BUY', 'size': '172.39'}], 'event_type': 'price_change', 'hash': 'bca71732e897f4b1a6beda9a8a01ecb4baeeb2b6', 'market': '0x9d1f0296f3a016727193d2b45704e0debc3b8048fe0715f8bb1e91550d321872', 'timestamp': '1733967692064'}
{'asset_id': '101669189743438912873361127612589311253202068943959811456820079057046819967115', 'changes': [{'price': '0.933', 'side': 'BUY', 'size': '107'}], 'event_type': 'price_change', 'hash': '5fca30d196eea3a4d767cd4692f8accc28476e64', 'market': '0x9d1f0296f3a016727193d2b45704e0debc3b8048fe0715f8bb1e91550d321872', 'timestamp': '1733967695093'}
{'asset_id': '101669189743438912873361127612589311253202068943959811456820079057046819967115', 'changes': [{'price': '0.933', 'side': 'BUY', 'size': '107'}], 'event_type': 'price_change', 'hash': '5fca30d196eea3a4d767cd4692f8accc28476e64', 'market': '0x9d1f0296f3a016727193d2b45704e0debc3b8048fe0715f8bb1e91550d321872', 'timestamp': '1733967695093'}
{'asset_id': '101669189743438912873361127612589311253202068943959811456820079057046819967115', 'changes': [{'price': '0.932', 'side': 'BUY', 'size': '0'}], 'event_type': 'price_change', 'hash': '5990ccc94119a8457c85a5bccc7d2ce097058ceb', 'market': '0x9d1f0296f3a016727193d2b45704e0debc3b8048fe0715f8bb1e91550d321872', 'timestamp': '1733967696336'}
{'asset_id': '101669189743438912873361127612589311253202068943959811456820079057046819967115', 'changes': [{'price': '0.932', 'side': 'BUY', 'size': '0'}], 'event_type': 'price_change', 'hash': '5990ccc94119a8457c85a5bccc7d2ce097058ceb', 'market': '0x9d1f0296f3a016727193d2b45704e0debc3b8048fe0715f8bb1e91550d321872', 'timestamp': '1733967696336'}
{'asset_id': '101669189743438912873361127612589311253202068943959811456820079057046819967115', 'changes': [{'price': '0.933', 'side': 'BUY', 'size': '0'}], 'event_type': 'price_change', 'hash': '9bccb2dd7aeacdde7c14392eb44e4fe6e6f974a7', 'market': '0x9d1f0296f3a016727193d2b45704e0debc3b8048fe0715f8bb1e91550d321872', 'timestamp': '1733967700630'}
{'asset_id': '101669189743438912873361127612589311253202068943959811456820079057046819967115', 'changes': [{'price': '0.933', 'side': 'BUY', 'size': '0'}], 'event_type': 'price_change', 'hash': '9bccb2dd7aeacdde7c14392eb44e4fe6e6f974a7', 'market': '0x9d1f0296f3a016727193d2b45704e0debc3b8048fe0715f8bb1e91550d321872', 'timestamp': '1733967700630'}
{'asset_id': '101669189743438912873361127612589311253202068943959811456820079057046819967115', 'changes': [{'price': '0.932', 'side': 'BUY', 'size': '172.39'}], 'event_type': 'price_change', 'hash': '8206a4b3c15580dc4b1a4ab9d4a742b7b7947e32', 'market': '0x9d1f0296f3a016727193d2b45704e0debc3b8048fe0715f8bb1e91550d321872', 'timestamp': '1733967701420'}
{'asset_id': '101669189743438912873361127612589311253202068943959811456820079057046819967115', 'changes': [{'price': '0.932', 'side': 'BUY', 'size': '172.39'}], 'event_type': 'price_change', 'hash': '8206a4b3c15580dc4b1a4ab9d4a742b7b7947e32', 'market': '0x9d1f0296f3a016727193d2b45704e0debc3b8048fe0715f8bb1e91550d321872', 'timestamp': '1733967701420'}
{'asset_id': '101669189743438912873361127612589311253202068943959811456820079057046819967115', 'changes': [{'price': '0.98', 'side': 'SELL', 'size': '1795'}], 'event_type': 'price_change', 'hash': 'f24d005fa8419b701e68f0baf5404b45d810ab33', 'market': '0x9d1f0296f3a016727193d2b45704e0debc3b8048fe0715f8bb1e91550d321872', 'timestamp': '1733967703397'}
{'asset_id': '101669189743438912873361127612589311253202068943959811456820079057046819967115', 'changes': [{'price': '0.933', 'side': 'BUY', 'size': '107'}], 'event_type': 'price_change', 'hash': '1bff6ba0bbc0a3bb3191932119f981af24227b69', 'market': '0x9d1f0296f3a016727193d2b45704e0debc3b8048fe0715f8bb1e91550d321872', 'timestamp': '1733967704977'}
{'asset_id': '101669189743438912873361127612589311253202068943959811456820079057046819967115', 'changes': [{'price': '0.933', 'side': 'BUY', 'size': '107'}], 'event_type': 'price_change', 'hash': '1bff6ba0bbc0a3bb3191932119f981af24227b69', 'market': '0x9d1f0296f3a016727193d2b45704e0debc3b8048fe0715f8bb1e91550d321872', 'timestamp': '1733967704977'}
{'asset_id': '101669189743438912873361127612589311253202068943959811456820079057046819967115', 'changes': [{'price': '0.932', 'side': 'BUY', 'size': '0'}], 'event_type': 'price_change', 'hash': '75b20cee61d95aef6d8ffb0e325f61ece6704bd1', 'market': '0x9d1f0296f3a016727193d2b45704e0debc3b8048fe0715f8bb1e91550d321872', 'timestamp': '1733967706241'}
{'asset_id': '101669189743438912873361127612589311253202068943959811456820079057046819967115', 'changes': [{'price': '0.932', 'side': 'BUY', 'size': '0'}], 'event_type': 'price_change', 'hash': '75b20cee61d95aef6d8ffb0e325f61ece6704bd1', 'market': '0x9d1f0296f3a016727193d2b45704e0debc3b8048fe0715f8bb1e91550d321872', 'timestamp': '1733967706241'}
{'asset_id': '101669189743438912873361127612589311253202068943959811456820079057046819967115', 'changes': [{'price': '0.933', 'side': 'BUY', 'size': '0'}], 'event_type': 'price_change', 'hash': 'fcb7b8eae83508cafe34bf775f4e8875fe7e2096', 'market': '0x9d1f0296f3a016727193d2b45704e0debc3b8048fe0715f8bb1e91550d321872', 'timestamp': '1733967710470'}
{'asset_id': '101669189743438912873361127612589311253202068943959811456820079057046819967115', 'changes': [{'price': '0.933', 'side': 'BUY', 'size': '0'}], 'event_type': 'price_change', 'hash': 'fcb7b8eae83508cafe34bf775f4e8875fe7e2096', 'market': '0x9d1f0296f3a016727193d2b45704e0debc3b8048fe0715f8bb1e91550d321872', 'timestamp': '1733967710470'}
{'asset_id': '101669189743438912873361127612589311253202068943959811456820079057046819967115', 'changes': [{'price': '0.932', 'side': 'BUY', 'size': '172.39'}], 'event_type': 'price_change', 'hash': '0dddfee267ae50997a344be5685c642a1562683b', 'market': '0x9d1f0296f3a016727193d2b45704e0debc3b8048fe0715f8bb1e91550d321872', 'timestamp': '1733967711255'}
{'asset_id': '101669189743438912873361127612589311253202068943959811456820079057046819967115', 'changes': [{'price': '0.932', 'side': 'BUY', 'size': '172.39'}], 'event_type': 'price_change', 'hash': '0dddfee267ae50997a344be5685c642a1562683b', 'market': '0x9d1f0296f3a016727193d2b45704e0debc3b8048fe0715f8bb1e91550d321872', 'timestamp': '1733967711255'}
{'asset_id': '101669189743438912873361127612589311253202068943959811456820079057046819967115', 'changes': [{'price': '0.933', 'side': 'BUY', 'size': '107'}], 'event_type': 'price_change', 'hash': '8936f2b03e0b543195548acad9f3506bda1e8841', 'market': '0x9d1f0296f3a016727193d2b45704e0debc3b8048fe0715f8bb1e91550d321872', 'timestamp': '1733967714155'}
{'asset_id': '101669189743438912873361127612589311253202068943959811456820079057046819967115', 'changes': [{'price': '0.933', 'side': 'BUY', 'size': '107'}], 'event_type': 'price_change', 'hash': '8936f2b03e0b543195548acad9f3506bda1e8841', 'market': '0x9d1f0296f3a016727193d2b45704e0debc3b8048fe0715f8bb1e91550d321872', 'timestamp': '1733967714155'}
{'asset_id': '101669189743438912873361127612589311253202068943959811456820079057046819967115', 'changes': [{'price': '0.932', 'side': 'BUY', 'size': '0'}], 'event_type': 'price_change', 'hash': 'f65c80a6a4000fcae1a7a1047fdd70831b092d8a', 'market': '0x9d1f0296f3a016727193d2b45704e0debc3b8048fe0715f8bb1e91550d321872', 'timestamp': '1733967715458'}
{'asset_id': '101669189743438912873361127612589311253202068943959811456820079057046819967115', 'changes': [{'price': '0.932', 'side': 'BUY', 'size': '0'}], 'event_type': 'price_change', 'hash': 'f65c80a6a4000fcae1a7a1047fdd70831b092d8a', 'market': '0x9d1f0296f3a016727193d2b45704e0debc3b8048fe0715f8bb1e91550d321872', 'timestamp': '1733967715458'}
{'asset_id': '101669189743438912873361127612589311253202068943959811456820079057046819967115', 'changes': [{'price': '0.933', 'side': 'BUY', 'size': '0'}], 'event_type': 'price_change', 'hash': '58c16f475522e34b4f531e8e23262c0a2eb5510b', 'market': '0x9d1f0296f3a016727193d2b45704e0debc3b8048fe0715f8bb1e91550d321872', 'timestamp': '1733967719293'}
{'asset_id': '101669189743438912873361127612589311253202068943959811456820079057046819967115', 'changes': [{'price': '0.933', 'side': 'BUY', 'size': '0'}], 'event_type': 'price_change', 'hash': '58c16f475522e34b4f531e8e23262c0a2eb5510b', 'market': '0x9d1f0296f3a016727193d2b45704e0debc3b8048fe0715f8bb1e91550d321872', 'timestamp': '1733967719293'}
{'asset_id': '101669189743438912873361127612589311253202068943959811456820079057046819967115', 'changes': [{'price': '0.932', 'side': 'BUY', 'size': '172.39'}], 'event_type': 'price_change', 'hash': '2b9dd5cb01990079c66aeb54d5096d7492198d55', 'market': '0x9d1f0296f3a016727193d2b45704e0debc3b8048fe0715f8bb1e91550d321872', 'timestamp': '1733967720072'}
{'asset_id': '101669189743438912873361127612589311253202068943959811456820079057046819967115', 'changes': [{'price': '0.932', 'side': 'BUY', 'size': '172.39'}], 'event_type': 'price_change', 'hash': '2b9dd5cb01990079c66aeb54d5096d7492198d55', 'market': '0x9d1f0296f3a016727193d2b45704e0debc3b8048fe0715f8bb1e91550d321872', 'timestamp': '1733967720072'}
{'asset_id': '101669189743438912873361127612589311253202068943959811456820079057046819967115', 'changes': [{'price': '0.933', 'side': 'BUY', 'size': '107'}], 'event_type': 'price_change', 'hash': '27548ff53419ca47079163ab78635d9c3e57e672', 'market': '0x9d1f0296f3a016727193d2b45704e0debc3b8048fe0715f8bb1e91550d321872', 'timestamp': '1733967723069'}
{'asset_id': '101669189743438912873361127612589311253202068943959811456820079057046819967115', 'changes': [{'price': '0.933', 'side': 'BUY', 'size': '107'}], 'event_type': 'price_change', 'hash': '27548ff53419ca47079163ab78635d9c3e57e672', 'market': '0x9d1f0296f3a016727193d2b45704e0debc3b8048fe0715f8bb1e91550d321872', 'timestamp': '1733967723069'}
{'asset_id': '101669189743438912873361127612589311253202068943959811456820079057046819967115', 'changes': [{'price': '0.932', 'side': 'BUY', 'size': '0'}], 'event_type': 'price_change', 'hash': '0141cf5bc06f9663ef19c4376d2eb2d920d67018', 'market': '0x9d1f0296f3a016727193d2b45704e0debc3b8048fe0715f8bb1e91550d321872', 'timestamp': '1733967724323'}
{'asset_id': '101669189743438912873361127612589311253202068943959811456820079057046819967115', 'changes': [{'price': '0.932', 'side': 'BUY', 'size': '0'}], 'event_type': 'price_change', 'hash': '0141cf5bc06f9663ef19c4376d2eb2d920d67018', 'market': '0x9d1f0296f3a016727193d2b45704e0debc3b8048fe0715f8bb1e91550d321872', 'timestamp': '1733967724323'}
{'asset_id': '101669189743438912873361127612589311253202068943959811456820079057046819967115', 'changes': [{'price': '0.933', 'side': 'BUY', 'size': '0'}], 'event_type': 'price_change', 'hash': 'f3ed2223552cc4301a54a50ac69ebeefe262815b', 'market': '0x9d1f0296f3a016727193d2b45704e0debc3b8048fe0715f8bb1e91550d321872', 'timestamp': '1733967727320'}
{'asset_id': '101669189743438912873361127612589311253202068943959811456820079057046819967115', 'changes': [{'price': '0.933', 'side': 'BUY', 'size': '0'}], 'event_type': 'price_change', 'hash': 'f3ed2223552cc4301a54a50ac69ebeefe262815b', 'market': '0x9d1f0296f3a016727193d2b45704e0debc3b8048fe0715f8bb1e91550d321872', 'timestamp': '1733967727320'}
{'asset_id': '101669189743438912873361127612589311253202068943959811456820079057046819967115', 'changes': [{'price': '0.932', 'side': 'BUY', 'size': '172.39'}], 'event_type': 'price_change', 'hash': '2b59cd13125e5199451e094814da2e50be9cacd0', 'market': '0x9d1f0296f3a016727193d2b45704e0debc3b8048fe0715f8bb1e91550d321872', 'timestamp': '1733967728131'}
{'asset_id': '101669189743438912873361127612589311253202068943959811456820079057046819967115', 'changes': [{'price': '0.932', 'side': 'BUY', 'size': '172.39'}], 'event_type': 'price_change', 'hash': '2b59cd13125e5199451e094814da2e50be9cacd0', 'market': '0x9d1f0296f3a016727193d2b45704e0debc3b8048fe0715f8bb1e91550d321872', 'timestamp': '1733967728131'}
{'asset_id': '101669189743438912873361127612589311253202068943959811456820079057046819967115', 'changes': [{'price': '0.933', 'side': 'BUY', 'size': '107'}], 'event_type': 'price_change', 'hash': 'd72ce533018af9939a538f9e976e9f50eeb2e1b4', 'market': '0x9d1f0296f3a016727193d2b45704e0debc3b8048fe0715f8bb1e91550d321872', 'timestamp': '1733967732083'}
{'asset_id': '101669189743438912873361127612589311253202068943959811456820079057046819967115', 'changes': [{'price': '0.933', 'side': 'BUY', 'size': '107'}], 'event_type': 'price_change', 'hash': 'd72ce533018af9939a538f9e976e9f50eeb2e1b4', 'market': '0x9d1f0296f3a016727193d2b45704e0debc3b8048fe0715f8bb1e91550d321872', 'timestamp': '1733967732083'}
{'asset_id': '101669189743438912873361127612589311253202068943959811456820079057046819967115', 'changes': [{'price': '0.932', 'side': 'BUY', 'size': '0'}], 'event_type': 'price_change', 'hash': '48e4791e63c81d02dcc94cb9fd57946e6b562330', 'market': '0x9d1f0296f3a016727193d2b45704e0debc3b8048fe0715f8bb1e91550d321872', 'timestamp': '1733967733378'}
{'asset_id': '101669189743438912873361127612589311253202068943959811456820079057046819967115', 'changes': [{'price': '0.932', 'side': 'BUY', 'size': '0'}], 'event_type': 'price_change', 'hash': '48e4791e63c81d02dcc94cb9fd57946e6b562330', 'market': '0x9d1f0296f3a016727193d2b45704e0debc3b8048fe0715f8bb1e91550d321872', 'timestamp': '1733967733378'}
{'asset_id': '101669189743438912873361127612589311253202068943959811456820079057046819967115', 'changes': [{'price': '0.933', 'side': 'BUY', 'size': '0'}], 'event_type': 'price_change', 'hash': 'a550a12e82b49abee0e27f20c3a03d59aa491a6d', 'market': '0x9d1f0296f3a016727193d2b45704e0debc3b8048fe0715f8bb1e91550d321872', 'timestamp': '1733967736341'}
{'asset_id': '101669189743438912873361127612589311253202068943959811456820079057046819967115', 'changes': [{'price': '0.933', 'side': 'BUY', 'size': '0'}], 'event_type': 'price_change', 'hash': 'a550a12e82b49abee0e27f20c3a03d59aa491a6d', 'market': '0x9d1f0296f3a016727193d2b45704e0debc3b8048fe0715f8bb1e91550d321872', 'timestamp': '1733967736341'}
{'asset_id': '101669189743438912873361127612589311253202068943959811456820079057046819967115', 'changes': [{'price': '0.932', 'side': 'BUY', 'size': '172.39'}], 'event_type': 'price_change', 'hash': '25a9a1984293feed359f9ff109384bdc8a45998e', 'market': '0x9d1f0296f3a016727193d2b45704e0debc3b8048fe0715f8bb1e91550d321872', 'timestamp': '1733967737144'}
{'asset_id': '101669189743438912873361127612589311253202068943959811456820079057046819967115', 'changes': [{'price': '0.932', 'side': 'BUY', 'size': '172.39'}], 'event_type': 'price_change', 'hash': '25a9a1984293feed359f9ff109384bdc8a45998e', 'market': '0x9d1f0296f3a016727193d2b45704e0debc3b8048fe0715f8bb1e91550d321872', 'timestamp': '1733967737144'}
{'asset_id': '101669189743438912873361127612589311253202068943959811456820079057046819967115', 'changes': [{'price': '0.933', 'side': 'BUY', 'size': '107'}], 'event_type': 'price_change', 'hash': '94457d5af7a231624674f94f3b6956c4b679bf64', 'market': '0x9d1f0296f3a016727193d2b45704e0debc3b8048fe0715f8bb1e91550d321872', 'timestamp': '1733967740097'}
{'asset_id': '101669189743438912873361127612589311253202068943959811456820079057046819967115', 'changes': [{'price': '0.933', 'side': 'BUY', 'size': '107'}], 'event_type': 'price_change', 'hash': '94457d5af7a231624674f94f3b6956c4b679bf64', 'market': '0x9d1f0296f3a016727193d2b45704e0debc3b8048fe0715f8bb1e91550d321872', 'timestamp': '1733967740097'}
{'asset_id': '101669189743438912873361127612589311253202068943959811456820079057046819967115', 'changes': [{'price': '0.932', 'side': 'BUY', 'size': '0'}], 'event_type': 'price_change', 'hash': 'b00e806d5df294331ac89fb2682609168f2b23bb', 'market': '0x9d1f0296f3a016727193d2b45704e0debc3b8048fe0715f8bb1e91550d321872', 'timestamp': '1733967741359'}
{'asset_id': '101669189743438912873361127612589311253202068943959811456820079057046819967115', 'changes': [{'price': '0.932', 'side': 'BUY', 'size': '0'}], 'event_type': 'price_change', 'hash': 'b00e806d5df294331ac89fb2682609168f2b23bb', 'market': '0x9d1f0296f3a016727193d2b45704e0debc3b8048fe0715f8bb1e91550d321872', 'timestamp': '1733967741359'}
{'asset_id': '101669189743438912873361127612589311253202068943959811456820079057046819967115', 'changes': [{'price': '0.933', 'side': 'BUY', 'size': '0'}], 'event_type': 'price_change', 'hash': 'd7ab8bb0e5341f42fbf128c3cd2bf07cd6fecae5', 'market': '0x9d1f0296f3a016727193d2b45704e0debc3b8048fe0715f8bb1e91550d321872', 'timestamp': '1733967744309'}
{'asset_id': '101669189743438912873361127612589311253202068943959811456820079057046819967115', 'changes': [{'price': '0.933', 'side': 'BUY', 'size': '0'}], 'event_type': 'price_change', 'hash': 'd7ab8bb0e5341f42fbf128c3cd2bf07cd6fecae5', 'market': '0x9d1f0296f3a016727193d2b45704e0debc3b8048fe0715f8bb1e91550d321872', 'timestamp': '1733967744309'}
{'asset_id': '101669189743438912873361127612589311253202068943959811456820079057046819967115', 'changes': [{'price': '0.932', 'side': 'BUY', 'size': '172.39'}], 'event_type': 'price_change', 'hash': 'ca748da0f9c699e5311474af13ad2d282a587430', 'market': '0x9d1f0296f3a016727193d2b45704e0debc3b8048fe0715f8bb1e91550d321872', 'timestamp': '1733967745083'}
{'asset_id': '101669189743438912873361127612589311253202068943959811456820079057046819967115', 'changes': [{'price': '0.932', 'side': 'BUY', 'size': '172.39'}], 'event_type': 'price_change', 'hash': 'ca748da0f9c699e5311474af13ad2d282a587430', 'market': '0x9d1f0296f3a016727193d2b45704e0debc3b8048fe0715f8bb1e91550d321872', 'timestamp': '1733967745083'}
{'asset_id': '101669189743438912873361127612589311253202068943959811456820079057046819967115', 'changes': [{'price': '0.933', 'side': 'BUY', 'size': '107'}], 'event_type': 'price_change', 'hash': 'da8831d8bfc5a3a2427bcf4a5e1d18584b4a95b0', 'market': '0x9d1f0296f3a016727193d2b45704e0debc3b8048fe0715f8bb1e91550d321872', 'timestamp': '1733967748094'}
{'asset_id': '101669189743438912873361127612589311253202068943959811456820079057046819967115', 'changes': [{'price': '0.933', 'side': 'BUY', 'size': '107'}], 'event_type': 'price_change', 'hash': 'da8831d8bfc5a3a2427bcf4a5e1d18584b4a95b0', 'market': '0x9d1f0296f3a016727193d2b45704e0debc3b8048fe0715f8bb1e91550d321872', 'timestamp': '1733967748094'}
{'asset_id': '101669189743438912873361127612589311253202068943959811456820079057046819967115', 'changes': [{'price': '0.932', 'side': 'BUY', 'size': '0'}], 'event_type': 'price_change', 'hash': 'd66a43b3e917cd5fd4015e589a9cc8f54c2340c2', 'market': '0x9d1f0296f3a016727193d2b45704e0debc3b8048fe0715f8bb1e91550d321872', 'timestamp': '1733967749347'}
{'asset_id': '101669189743438912873361127612589311253202068943959811456820079057046819967115', 'changes': [{'price': '0.932', 'side': 'BUY', 'size': '0'}], 'event_type': 'price_change', 'hash': 'd66a43b3e917cd5fd4015e589a9cc8f54c2340c2', 'market': '0x9d1f0296f3a016727193d2b45704e0debc3b8048fe0715f8bb1e91550d321872', 'timestamp': '1733967749347'}
{'asset_id': '101669189743438912873361127612589311253202068943959811456820079057046819967115', 'changes': [{'price': '0.933', 'side': 'BUY', 'size': '0'}], 'event_type': 'price_change', 'hash': '9a9405af1e1c95165e404b6fc2fc9af9277da6ce', 'market': '0x9d1f0296f3a016727193d2b45704e0debc3b8048fe0715f8bb1e91550d321872', 'timestamp': '1733967753308'}
{'asset_id': '101669189743438912873361127612589311253202068943959811456820079057046819967115', 'changes': [{'price': '0.933', 'side': 'BUY', 'size': '0'}], 'event_type': 'price_change', 'hash': '9a9405af1e1c95165e404b6fc2fc9af9277da6ce', 'market': '0x9d1f0296f3a016727193d2b45704e0debc3b8048fe0715f8bb1e91550d321872', 'timestamp': '1733967753308'}
{'asset_id': '101669189743438912873361127612589311253202068943959811456820079057046819967115', 'changes': [{'price': '0.932', 'side': 'BUY', 'size': '172.39'}], 'event_type': 'price_change', 'hash': '4f93c9723820dd023f53d4370ba9bd525fce39c0', 'market': '0x9d1f0296f3a016727193d2b45704e0debc3b8048fe0715f8bb1e91550d321872', 'timestamp': '1733967754106'}
{'asset_id': '101669189743438912873361127612589311253202068943959811456820079057046819967115', 'changes': [{'price': '0.932', 'side': 'BUY', 'size': '172.39'}], 'event_type': 'price_change', 'hash': '4f93c9723820dd023f53d4370ba9bd525fce39c0', 'market': '0x9d1f0296f3a016727193d2b45704e0debc3b8048fe0715f8bb1e91550d321872', 'timestamp': '1733967754106'}
{'asset_id': '101669189743438912873361127612589311253202068943959811456820079057046819967115', 'changes': [{'price': '0.933', 'side': 'BUY', 'size': '107'}], 'event_type': 'price_change', 'hash': 'a3301394e2daf909d990e880326f0eb804e5589e', 'market': '0x9d1f0296f3a016727193d2b45704e0debc3b8048fe0715f8bb1e91550d321872', 'timestamp': '1733967757082'}
{'asset_id': '101669189743438912873361127612589311253202068943959811456820079057046819967115', 'changes': [{'price': '0.933', 'side': 'BUY', 'size': '107'}], 'event_type': 'price_change', 'hash': 'a3301394e2daf909d990e880326f0eb804e5589e', 'market': '0x9d1f0296f3a016727193d2b45704e0debc3b8048fe0715f8bb1e91550d321872', 'timestamp': '1733967757082'}
{'asset_id': '101669189743438912873361127612589311253202068943959811456820079057046819967115', 'changes': [{'price': '0.932', 'side': 'BUY', 'size': '0'}], 'event_type': 'price_change', 'hash': '3ea9563aeba44790adf1adbcf997c01c3e6f792f', 'market': '0x9d1f0296f3a016727193d2b45704e0debc3b8048fe0715f8bb1e91550d321872', 'timestamp': '1733967758318'}
{'asset_id': '101669189743438912873361127612589311253202068943959811456820079057046819967115', 'changes': [{'price': '0.932', 'side': 'BUY', 'size': '0'}], 'event_type': 'price_change', 'hash': '3ea9563aeba44790adf1adbcf997c01c3e6f792f', 'market': '0x9d1f0296f3a016727193d2b45704e0debc3b8048fe0715f8bb1e91550d321872', 'timestamp': '1733967758318'}
{'asset_id': '101669189743438912873361127612589311253202068943959811456820079057046819967115', 'changes': [{'price': '0.933', 'side': 'BUY', 'size': '0'}], 'event_type': 'price_change', 'hash': 'c74cbdd32f2955c6b14faf3551d2f178204c4808', 'market': '0x9d1f0296f3a016727193d2b45704e0debc3b8048fe0715f8bb1e91550d321872', 'timestamp': '1733967761313'}
{'asset_id': '101669189743438912873361127612589311253202068943959811456820079057046819967115', 'changes': [{'price': '0.933', 'side': 'BUY', 'size': '0'}], 'event_type': 'price_change', 'hash': 'c74cbdd32f2955c6b14faf3551d2f178204c4808', 'market': '0x9d1f0296f3a016727193d2b45704e0debc3b8048fe0715f8bb1e91550d321872', 'timestamp': '1733967761313'}
{'asset_id': '101669189743438912873361127612589311253202068943959811456820079057046819967115', 'changes': [{'price': '0.932', 'side': 'BUY', 'size': '172.39'}], 'event_type': 'price_change', 'hash': 'd23610c476922388b14aa03b49661617bd738484', 'market': '0x9d1f0296f3a016727193d2b45704e0debc3b8048fe0715f8bb1e91550d321872', 'timestamp': '1733967762112'}
{'asset_id': '101669189743438912873361127612589311253202068943959811456820079057046819967115', 'changes': [{'price': '0.932', 'side': 'BUY', 'size': '172.39'}], 'event_type': 'price_change', 'hash': 'd23610c476922388b14aa03b49661617bd738484', 'market': '0x9d1f0296f3a016727193d2b45704e0debc3b8048fe0715f8bb1e91550d321872', 'timestamp': '1733967762112'}
{'asks': [{'price': '0.999', 'size': '100000'}, {'price': '0.995', 'size': '180.38'}, {'price': '0.985', 'size': '168.56'}, {'price': '0.98', 'size': '1795'}, {'price': '0.968', 'size': '32115.44'}, {'price': '0.96', 'size': '5000'}, {'price': '0.957', 'size': '333'}, {'price': '0.955', 'size': '57000'}, {'price': '0.95', 'size': '78'}, {'price': '0.945', 'size': '10000'}, {'price': '0.944', 'size': '5720.36'}, {'price': '0.942', 'size': '2471'}, {'price': '0.941', 'size': '151'}], 'asset_id': '101669189743438912873361127612589311253202068943959811456820079057046819967115', 'bids': [{'price': '0.001', 'size': '50000'}, {'price': '0.002', 'size': '500012'}, {'price': '0.003', 'size': '10000'}, {'price': '0.012', 'size': '90000'}, {'price': '0.013', 'size': '5000'}, {'price': '0.016', 'size': '50000'}, {'price': '0.021', 'size': '2000'}, {'price': '0.035', 'size': '30000'}, {'price': '0.039', 'size': '4000'}, {'price': '0.04', 'size': '14250'}, {'price': '0.351', 'size': '500'}, {'price': '0.352', 'size': '3692'}, {'price': '0.602', 'size': '420'}, {'price': '0.681', 'size': '800'}, {'price': '0.826', 'size': '111'}, {'price': '0.831', 'size': '5'}, {'price': '0.833', 'size': '2362.51'}, {'price': '0.847', 'size': '200.11'}, {'price': '0.89', 'size': '2115.19'}, {'price': '0.896', 'size': '1000'}, {'price': '0.901', 'size': '11000'}, {'price': '0.902', 'size': '450'}, {'price': '0.915', 'size': '2484.75'}, {'price': '0.917', 'size': '400'}, {'price': '0.919', 'size': '17.81'}, {'price': '0.922', 'size': '10000'}, {'price': '0.925', 'size': '10200'}, {'price': '0.926', 'size': '5000'}, {'price': '0.927', 'size': '5462'}, {'price': '0.93', 'size': '318'}, {'price': '0.931', 'size': '5'}, {'price': '0.932', 'size': '149.39'}], 'event_type': 'book', 'hash': 'c8728afc5a28aec837927bb77416217c493e07fc', 'market': '0x9d1f0296f3a016727193d2b45704e0debc3b8048fe0715f8bb1e91550d321872', 'timestamp': '1733967763864'}
{'asks': [{'price': '0.999', 'size': '100000'}, {'price': '0.995', 'size': '180.38'}, {'price': '0.985', 'size': '168.56'}, {'price': '0.98', 'size': '1795'}, {'price': '0.968', 'size': '32115.44'}, {'price': '0.96', 'size': '5000'}, {'price': '0.957', 'size': '333'}, {'price': '0.955', 'size': '57000'}, {'price': '0.95', 'size': '78'}, {'price': '0.945', 'size': '10000'}, {'price': '0.944', 'size': '5720.36'}, {'price': '0.942', 'size': '2471'}, {'price': '0.941', 'size': '151'}], 'asset_id': '101669189743438912873361127612589311253202068943959811456820079057046819967115', 'bids': [{'price': '0.001', 'size': '50000'}, {'price': '0.002', 'size': '500012'}, {'price': '0.003', 'size': '10000'}, {'price': '0.012', 'size': '90000'}, {'price': '0.013', 'size': '5000'}, {'price': '0.016', 'size': '50000'}, {'price': '0.021', 'size': '2000'}, {'price': '0.035', 'size': '30000'}, {'price': '0.039', 'size': '4000'}, {'price': '0.04', 'size': '14250'}, {'price': '0.351', 'size': '500'}, {'price': '0.352', 'size': '3692'}, {'price': '0.602', 'size': '420'}, {'price': '0.681', 'size': '800'}, {'price': '0.826', 'size': '111'}, {'price': '0.831', 'size': '5'}, {'price': '0.833', 'size': '2362.51'}, {'price': '0.847', 'size': '200.11'}, {'price': '0.89', 'size': '2115.19'}, {'price': '0.896', 'size': '1000'}, {'price': '0.901', 'size': '11000'}, {'price': '0.902', 'size': '450'}, {'price': '0.915', 'size': '2484.75'}, {'price': '0.917', 'size': '400'}, {'price': '0.919', 'size': '17.81'}, {'price': '0.922', 'size': '10000'}, {'price': '0.925', 'size': '10200'}, {'price': '0.926', 'size': '5000'}, {'price': '0.927', 'size': '5462'}, {'price': '0.93', 'size': '318'}, {'price': '0.931', 'size': '5'}, {'price': '0.932', 'size': '149.39'}], 'event_type': 'book', 'hash': 'c8728afc5a28aec837927bb77416217c493e07fc', 'market': '0x9d1f0296f3a016727193d2b45704e0debc3b8048fe0715f8bb1e91550d321872', 'timestamp': '1733967763864'}
{'asset_id': '101669189743438912873361127612589311253202068943959811456820079057046819967115', 'changes': [{'price': '0.847', 'side': 'BUY', 'size': '0'}, {'price': '0.995', 'side': 'SELL', 'size': '0'}], 'event_type': 'price_change', 'hash': '933d5797d72ced44103490b3e69953763098eb43', 'market': '0x9d1f0296f3a016727193d2b45704e0debc3b8048fe0715f8bb1e91550d321872', 'timestamp': '1733967764408'}
{'asset_id': '101669189743438912873361127612589311253202068943959811456820079057046819967115', 'changes': [{'price': '0.847', 'side': 'BUY', 'size': '0'}, {'price': '0.995', 'side': 'SELL', 'size': '0'}], 'event_type': 'price_change', 'hash': '933d5797d72ced44103490b3e69953763098eb43', 'market': '0x9d1f0296f3a016727193d2b45704e0debc3b8048fe0715f8bb1e91550d321872', 'timestamp': '1733967764408'}
{'asset_id': '101669189743438912873361127612589311253202068943959811456820079057046819967115', 'changes': [{'price': '0.933', 'side': 'BUY', 'size': '107'}], 'event_type': 'price_change', 'hash': '80a721af1c0a3780d23c329978ed93b245060890', 'market': '0x9d1f0296f3a016727193d2b45704e0debc3b8048fe0715f8bb1e91550d321872', 'timestamp': '1733967765689'}
{'asset_id': '101669189743438912873361127612589311253202068943959811456820079057046819967115', 'changes': [{'price': '0.933', 'side': 'BUY', 'size': '107'}], 'event_type': 'price_change', 'hash': '80a721af1c0a3780d23c329978ed93b245060890', 'market': '0x9d1f0296f3a016727193d2b45704e0debc3b8048fe0715f8bb1e91550d321872', 'timestamp': '1733967765689'}
{'asset_id': '101669189743438912873361127612589311253202068943959811456820079057046819967115', 'changes': [{'price': '0.932', 'side': 'BUY', 'size': '0'}], 'event_type': 'price_change', 'hash': 'd7ff203cd857693783209283d967bc3653724405', 'market': '0x9d1f0296f3a016727193d2b45704e0debc3b8048fe0715f8bb1e91550d321872', 'timestamp': '1733967768179'}
{'asset_id': '101669189743438912873361127612589311253202068943959811456820079057046819967115', 'changes': [{'price': '0.932', 'side': 'BUY', 'size': '0'}], 'event_type': 'price_change', 'hash': 'd7ff203cd857693783209283d967bc3653724405', 'market': '0x9d1f0296f3a016727193d2b45704e0debc3b8048fe0715f8bb1e91550d321872', 'timestamp': '1733967768179'}
{'asset_id': '101669189743438912873361127612589311253202068943959811456820079057046819967115', 'changes': [{'price': '0.933', 'side': 'BUY', 'size': '0'}], 'event_type': 'price_change', 'hash': '7b5b6d328a2af09c8344bc9edd8c22ae6ceee7c5', 'market': '0x9d1f0296f3a016727193d2b45704e0debc3b8048fe0715f8bb1e91550d321872', 'timestamp': '1733967771333'}
{'asset_id': '101669189743438912873361127612589311253202068943959811456820079057046819967115', 'changes': [{'price': '0.933', 'side': 'BUY', 'size': '0'}], 'event_type': 'price_change', 'hash': '7b5b6d328a2af09c8344bc9edd8c22ae6ceee7c5', 'market': '0x9d1f0296f3a016727193d2b45704e0debc3b8048fe0715f8bb1e91550d321872', 'timestamp': '1733967771333'}
{'asset_id': '101669189743438912873361127612589311253202068943959811456820079057046819967115', 'changes': [{'price': '0.932', 'side': 'BUY', 'size': '149.38'}, {'price': '0.934', 'side': 'BUY', 'size': '24.99'}], 'event_type': 'price_change', 'hash': '8104ba84b7db28be4b51f2a157a0d152afe0bfba', 'market': '0x9d1f0296f3a016727193d2b45704e0debc3b8048fe0715f8bb1e91550d321872', 'timestamp': '1733967772113'}
{'asset_id': '101669189743438912873361127612589311253202068943959811456820079057046819967115', 'changes': [{'price': '0.932', 'side': 'BUY', 'size': '149.38'}, {'price': '0.934', 'side': 'BUY', 'size': '24.99'}], 'event_type': 'price_change', 'hash': '8104ba84b7db28be4b51f2a157a0d152afe0bfba', 'market': '0x9d1f0296f3a016727193d2b45704e0debc3b8048fe0715f8bb1e91550d321872', 'timestamp': '1733967772113'}
{'asset_id': '101669189743438912873361127612589311253202068943959811456820079057046819967115', 'changes': [{'price': '0.933', 'side': 'BUY', 'size': '107'}], 'event_type': 'price_change', 'hash': '9cf576ac1ec39d0fda236f9ad2f80d768bb6fa83', 'market': '0x9d1f0296f3a016727193d2b45704e0debc3b8048fe0715f8bb1e91550d321872', 'timestamp': '1733967775125'}
{'asset_id': '101669189743438912873361127612589311253202068943959811456820079057046819967115', 'changes': [{'price': '0.933', 'side': 'BUY', 'size': '107'}], 'event_type': 'price_change', 'hash': '9cf576ac1ec39d0fda236f9ad2f80d768bb6fa83', 'market': '0x9d1f0296f3a016727193d2b45704e0debc3b8048fe0715f8bb1e91550d321872', 'timestamp': '1733967775125'}
{'asset_id': '101669189743438912873361127612589311253202068943959811456820079057046819967115', 'changes': [{'price': '0.933', 'side': 'BUY', 'size': '0'}], 'event_type': 'price_change', 'hash': '47f5839b417e0d87401cd191f1daf38f633d0622', 'market': '0x9d1f0296f3a016727193d2b45704e0debc3b8048fe0715f8bb1e91550d321872', 'timestamp': '1733967775459'}
{'asset_id': '101669189743438912873361127612589311253202068943959811456820079057046819967115', 'changes': [{'price': '0.933', 'side': 'BUY', 'size': '0'}], 'event_type': 'price_change', 'hash': '47f5839b417e0d87401cd191f1daf38f633d0622', 'market': '0x9d1f0296f3a016727193d2b45704e0debc3b8048fe0715f8bb1e91550d321872', 'timestamp': '1733967775459'}
{'asset_id': '101669189743438912873361127612589311253202068943959811456820079057046819967115', 'changes': [{'price': '0.951', 'side': 'SELL', 'size': '200'}], 'event_type': 'price_change', 'hash': 'b795134cb562c6f1b81ded106713f404457088ea', 'market': '0x9d1f0296f3a016727193d2b45704e0debc3b8048fe0715f8bb1e91550d321872', 'timestamp': '1733967777100'}
{'asset_id': '101669189743438912873361127612589311253202068943959811456820079057046819967115', 'changes': [{'price': '0.951', 'side': 'SELL', 'size': '200'}], 'event_type': 'price_change', 'hash': 'b795134cb562c6f1b81ded106713f404457088ea', 'market': '0x9d1f0296f3a016727193d2b45704e0debc3b8048fe0715f8bb1e91550d321872', 'timestamp': '1733967777100'}
{'asset_id': '101669189743438912873361127612589311253202068943959811456820079057046819967115', 'changes': [{'price': '0.932', 'side': 'BUY', 'size': '0'}], 'event_type': 'price_change', 'hash': 'fb113eeee2511f0477d97a5efdfc7f643077ec9a', 'market': '0x9d1f0296f3a016727193d2b45704e0debc3b8048fe0715f8bb1e91550d321872', 'timestamp': '1733967777232'}
{'asset_id': '101669189743438912873361127612589311253202068943959811456820079057046819967115', 'changes': [{'price': '0.932', 'side': 'BUY', 'size': '0'}], 'event_type': 'price_change', 'hash': 'fb113eeee2511f0477d97a5efdfc7f643077ec9a', 'market': '0x9d1f0296f3a016727193d2b45704e0debc3b8048fe0715f8bb1e91550d321872', 'timestamp': '1733967777232'}
{'asset_id': '101669189743438912873361127612589311253202068943959811456820079057046819967115', 'changes': [{'price': '0.951', 'side': 'SELL', 'size': '0'}], 'event_type': 'price_change', 'hash': 'abdf5c55a123fc9042af63803e9600a41944c729', 'market': '0x9d1f0296f3a016727193d2b45704e0debc3b8048fe0715f8bb1e91550d321872', 'timestamp': '1733967780744'}
{'asset_id': '101669189743438912873361127612589311253202068943959811456820079057046819967115', 'changes': [{'price': '0.951', 'side': 'SELL', 'size': '0'}], 'event_type': 'price_change', 'hash': 'abdf5c55a123fc9042af63803e9600a41944c729', 'market': '0x9d1f0296f3a016727193d2b45704e0debc3b8048fe0715f8bb1e91550d321872', 'timestamp': '1733967780744'}
{'asset_id': '101669189743438912873361127612589311253202068943959811456820079057046819967115', 'changes': [{'price': '0.933', 'side': 'BUY', 'size': '107'}], 'event_type': 'price_change', 'hash': '0a3d87cd53fa06fc330bf785a73135451fe7e4aa', 'market': '0x9d1f0296f3a016727193d2b45704e0debc3b8048fe0715f8bb1e91550d321872', 'timestamp': '1733967781102'}
{'asset_id': '101669189743438912873361127612589311253202068943959811456820079057046819967115', 'changes': [{'price': '0.933', 'side': 'BUY', 'size': '107'}], 'event_type': 'price_change', 'hash': '0a3d87cd53fa06fc330bf785a73135451fe7e4aa', 'market': '0x9d1f0296f3a016727193d2b45704e0debc3b8048fe0715f8bb1e91550d321872', 'timestamp': '1733967781102'}
{'asset_id': '101669189743438912873361127612589311253202068943959811456820079057046819967115', 'changes': [{'price': '0.949', 'side': 'SELL', 'size': '219'}], 'event_type': 'price_change', 'hash': '5d8855c48ebed1f59dc7df50326892c91984835a', 'market': '0x9d1f0296f3a016727193d2b45704e0debc3b8048fe0715f8bb1e91550d321872', 'timestamp': '1733967781196'}
{'asset_id': '101669189743438912873361127612589311253202068943959811456820079057046819967115', 'changes': [{'price': '0.949', 'side': 'SELL', 'size': '219'}], 'event_type': 'price_change', 'hash': '5d8855c48ebed1f59dc7df50326892c91984835a', 'market': '0x9d1f0296f3a016727193d2b45704e0debc3b8048fe0715f8bb1e91550d321872', 'timestamp': '1733967781196'}
{'asset_id': '101669189743438912873361127612589311253202068943959811456820079057046819967115', 'changes': [{'price': '0.933', 'side': 'BUY', 'size': '0'}], 'event_type': 'price_change', 'hash': 'f00e73011ad5858cd4ca2690c3009af7bb5a4464', 'market': '0x9d1f0296f3a016727193d2b45704e0debc3b8048fe0715f8bb1e91550d321872', 'timestamp': '1733967781449'}
{'asset_id': '101669189743438912873361127612589311253202068943959811456820079057046819967115', 'changes': [{'price': '0.933', 'side': 'BUY', 'size': '0'}], 'event_type': 'price_change', 'hash': 'f00e73011ad5858cd4ca2690c3009af7bb5a4464', 'market': '0x9d1f0296f3a016727193d2b45704e0debc3b8048fe0715f8bb1e91550d321872', 'timestamp': '1733967781449'}
{'asset_id': '101669189743438912873361127612589311253202068943959811456820079057046819967115', 'changes': [{'price': '0.935', 'side': 'BUY', 'size': '149.38'}], 'event_type': 'price_change', 'hash': '3f7800b17de21d9e0e8f01b09ad52eb268179d1a', 'market': '0x9d1f0296f3a016727193d2b45704e0debc3b8048fe0715f8bb1e91550d321872', 'timestamp': '1733967782101'}
{'asset_id': '101669189743438912873361127612589311253202068943959811456820079057046819967115', 'changes': [{'price': '0.935', 'side': 'BUY', 'size': '149.38'}], 'event_type': 'price_change', 'hash': '3f7800b17de21d9e0e8f01b09ad52eb268179d1a', 'market': '0x9d1f0296f3a016727193d2b45704e0debc3b8048fe0715f8bb1e91550d321872', 'timestamp': '1733967782101'}
{'asset_id': '101669189743438912873361127612589311253202068943959811456820079057046819967115', 'changes': [{'price': '0.95', 'side': 'SELL', 'size': '0'}], 'event_type': 'price_change', 'hash': '7e4b73ae04093fb1cc38d8a918ec235222ebc1a2', 'market': '0x9d1f0296f3a016727193d2b45704e0debc3b8048fe0715f8bb1e91550d321872', 'timestamp': '1733967784301'}
{'asset_id': '101669189743438912873361127612589311253202068943959811456820079057046819967115', 'changes': [{'price': '0.95', 'side': 'SELL', 'size': '0'}], 'event_type': 'price_change', 'hash': '7e4b73ae04093fb1cc38d8a918ec235222ebc1a2', 'market': '0x9d1f0296f3a016727193d2b45704e0debc3b8048fe0715f8bb1e91550d321872', 'timestamp': '1733967784301'}
{'asset_id': '101669189743438912873361127612589311253202068943959811456820079057046819967115', 'changes': [{'price': '0.934', 'side': 'BUY', 'size': '131.99'}], 'event_type': 'price_change', 'hash': '0332cb9f9d27695dac8ac00250edc079c85d7f2c', 'market': '0x9d1f0296f3a016727193d2b45704e0debc3b8048fe0715f8bb1e91550d321872', 'timestamp': '1733967785081'}
{'asset_id': '101669189743438912873361127612589311253202068943959811456820079057046819967115', 'changes': [{'price': '0.934', 'side': 'BUY', 'size': '131.99'}], 'event_type': 'price_change', 'hash': '0332cb9f9d27695dac8ac00250edc079c85d7f2c', 'market': '0x9d1f0296f3a016727193d2b45704e0debc3b8048fe0715f8bb1e91550d321872', 'timestamp': '1733967785081'}
{'asset_id': '101669189743438912873361127612589311253202068943959811456820079057046819967115', 'changes': [{'price': '0.934', 'side': 'BUY', 'size': '24.99'}], 'event_type': 'price_change', 'hash': '7f389e66150072bce6cf1c2553f23206e865af6e', 'market': '0x9d1f0296f3a016727193d2b45704e0debc3b8048fe0715f8bb1e91550d321872', 'timestamp': '1733967785436'}
{'asset_id': '101669189743438912873361127612589311253202068943959811456820079057046819967115', 'changes': [{'price': '0.934', 'side': 'BUY', 'size': '24.99'}], 'event_type': 'price_change', 'hash': '7f389e66150072bce6cf1c2553f23206e865af6e', 'market': '0x9d1f0296f3a016727193d2b45704e0debc3b8048fe0715f8bb1e91550d321872', 'timestamp': '1733967785436'}
{'asset_id': '101669189743438912873361127612589311253202068943959811456820079057046819967115', 'changes': [{'price': '0.949', 'side': 'SELL', 'size': '424'}], 'event_type': 'price_change', 'hash': 'dd942e2c8cbc42ba9e5abf8013adac46b71c5664', 'market': '0x9d1f0296f3a016727193d2b45704e0debc3b8048fe0715f8bb1e91550d321872', 'timestamp': '1733967792539'}
{'asset_id': '101669189743438912873361127612589311253202068943959811456820079057046819967115', 'changes': [{'price': '0.949', 'side': 'SELL', 'size': '424'}], 'event_type': 'price_change', 'hash': 'dd942e2c8cbc42ba9e5abf8013adac46b71c5664', 'market': '0x9d1f0296f3a016727193d2b45704e0debc3b8048fe0715f8bb1e91550d321872', 'timestamp': '1733967792539'}
{'asset_id': '101669189743438912873361127612589311253202068943959811456820079057046819967115', 'changes': [{'price': '0.847', 'side': 'BUY', 'size': '200.11'}], 'event_type': 'price_change', 'hash': 'f745909c3885223f9f5f777c2e6eb81a0248c103', 'market': '0x9d1f0296f3a016727193d2b45704e0debc3b8048fe0715f8bb1e91550d321872', 'timestamp': '1733967814136'}
{'asset_id': '101669189743438912873361127612589311253202068943959811456820079057046819967115', 'changes': [{'price': '0.847', 'side': 'BUY', 'size': '200.11'}], 'event_type': 'price_change', 'hash': 'f745909c3885223f9f5f777c2e6eb81a0248c103', 'market': '0x9d1f0296f3a016727193d2b45704e0debc3b8048fe0715f8bb1e91550d321872', 'timestamp': '1733967814136'}
{'asset_id': '101669189743438912873361127612589311253202068943959811456820079057046819967115', 'changes': [{'price': '0.994', 'side': 'SELL', 'size': '180.38'}], 'event_type': 'price_change', 'hash': '922dfa2c80452fea1c4850cb59b64f5ffebb991b', 'market': '0x9d1f0296f3a016727193d2b45704e0debc3b8048fe0715f8bb1e91550d321872', 'timestamp': '1733967814397'}
{'asset_id': '101669189743438912873361127612589311253202068943959811456820079057046819967115', 'changes': [{'price': '0.994', 'side': 'SELL', 'size': '180.38'}], 'event_type': 'price_change', 'hash': '922dfa2c80452fea1c4850cb59b64f5ffebb991b', 'market': '0x9d1f0296f3a016727193d2b45704e0debc3b8048fe0715f8bb1e91550d321872', 'timestamp': '1733967814397'}
{'asset_id': '101669189743438912873361127612589311253202068943959811456820079057046819967115', 'changes': [{'price': '0.934', 'side': 'BUY', 'size': '0'}], 'event_type': 'price_change', 'hash': '17013d52d7c77823bdb841abcee7c041fb8f6cc0', 'market': '0x9d1f0296f3a016727193d2b45704e0debc3b8048fe0715f8bb1e91550d321872', 'timestamp': '1733967873530'}
{'asset_id': '101669189743438912873361127612589311253202068943959811456820079057046819967115', 'changes': [{'price': '0.934', 'side': 'BUY', 'size': '0'}], 'event_type': 'price_change', 'hash': '17013d52d7c77823bdb841abcee7c041fb8f6cc0', 'market': '0x9d1f0296f3a016727193d2b45704e0debc3b8048fe0715f8bb1e91550d321872', 'timestamp': '1733967873530'}
{'asset_id': '101669189743438912873361127612589311253202068943959811456820079057046819967115', 'changes': [{'price': '0.935', 'side': 'BUY', 'size': '0'}], 'event_type': 'price_change', 'hash': '3416f6611c13b2d3236d5a9f8c04bde8fe2f2a5c', 'market': '0x9d1f0296f3a016727193d2b45704e0debc3b8048fe0715f8bb1e91550d321872', 'timestamp': '1733967877346'}
{'asset_id': '101669189743438912873361127612589311253202068943959811456820079057046819967115', 'changes': [{'price': '0.935', 'side': 'BUY', 'size': '0'}], 'event_type': 'price_change', 'hash': '3416f6611c13b2d3236d5a9f8c04bde8fe2f2a5c', 'market': '0x9d1f0296f3a016727193d2b45704e0debc3b8048fe0715f8bb1e91550d321872', 'timestamp': '1733967877346'}
{'asset_id': '101669189743438912873361127612589311253202068943959811456820079057046819967115', 'changes': [{'price': '0.932', 'side': 'BUY', 'size': '149.38'}], 'event_type': 'price_change', 'hash': 'e430e15370309d0328494b6a00fc625729922bd7', 'market': '0x9d1f0296f3a016727193d2b45704e0debc3b8048fe0715f8bb1e91550d321872', 'timestamp': '1733967881860'}
{'asset_id': '101669189743438912873361127612589311253202068943959811456820079057046819967115', 'changes': [{'price': '0.932', 'side': 'BUY', 'size': '149.38'}], 'event_type': 'price_change', 'hash': 'e430e15370309d0328494b6a00fc625729922bd7', 'market': '0x9d1f0296f3a016727193d2b45704e0debc3b8048fe0715f8bb1e91550d321872', 'timestamp': '1733967881860'}
{'asset_id': '101669189743438912873361127612589311253202068943959811456820079057046819967115', 'changes': [{'price': '0.933', 'side': 'BUY', 'size': '107'}], 'event_type': 'price_change', 'hash': 'a55434767815b20ee78de889bb8412775a3af48a', 'market': '0x9d1f0296f3a016727193d2b45704e0debc3b8048fe0715f8bb1e91550d321872', 'timestamp': '1733967910102'}
{'asset_id': '101669189743438912873361127612589311253202068943959811456820079057046819967115', 'changes': [{'price': '0.933', 'side': 'BUY', 'size': '107'}], 'event_type': 'price_change', 'hash': 'a55434767815b20ee78de889bb8412775a3af48a', 'market': '0x9d1f0296f3a016727193d2b45704e0debc3b8048fe0715f8bb1e91550d321872', 'timestamp': '1733967910102'}
{'asset_id': '101669189743438912873361127612589311253202068943959811456820079057046819967115', 'changes': [{'price': '0.932', 'side': 'BUY', 'size': '0'}], 'event_type': 'price_change', 'hash': 'ce8629bfba0baa5f78004b49bb3772d1bc5d302a', 'market': '0x9d1f0296f3a016727193d2b45704e0debc3b8048fe0715f8bb1e91550d321872', 'timestamp': '1733967911346'}
{'asset_id': '101669189743438912873361127612589311253202068943959811456820079057046819967115', 'changes': [{'price': '0.932', 'side': 'BUY', 'size': '0'}], 'event_type': 'price_change', 'hash': 'ce8629bfba0baa5f78004b49bb3772d1bc5d302a', 'market': '0x9d1f0296f3a016727193d2b45704e0debc3b8048fe0715f8bb1e91550d321872', 'timestamp': '1733967911346'}
{'asset_id': '101669189743438912873361127612589311253202068943959811456820079057046819967115', 'changes': [{'price': '0.933', 'side': 'BUY', 'size': '0'}], 'event_type': 'price_change', 'hash': 'c1234eb9b894589ba065ac7a568050b8cac4c72d', 'market': '0x9d1f0296f3a016727193d2b45704e0debc3b8048fe0715f8bb1e91550d321872', 'timestamp': '1733967914336'}
{'asset_id': '101669189743438912873361127612589311253202068943959811456820079057046819967115', 'changes': [{'price': '0.933', 'side': 'BUY', 'size': '0'}], 'event_type': 'price_change', 'hash': 'c1234eb9b894589ba065ac7a568050b8cac4c72d', 'market': '0x9d1f0296f3a016727193d2b45704e0debc3b8048fe0715f8bb1e91550d321872', 'timestamp': '1733967914336'}
{'asset_id': '101669189743438912873361127612589311253202068943959811456820079057046819967115', 'changes': [{'price': '0.932', 'side': 'BUY', 'size': '149.38'}], 'event_type': 'price_change', 'hash': '5f851580f09b7c402d0511403454bc19a2ebe716', 'market': '0x9d1f0296f3a016727193d2b45704e0debc3b8048fe0715f8bb1e91550d321872', 'timestamp': '1733967915109'}
{'asset_id': '101669189743438912873361127612589311253202068943959811456820079057046819967115', 'changes': [{'price': '0.932', 'side': 'BUY', 'size': '149.38'}], 'event_type': 'price_change', 'hash': '5f851580f09b7c402d0511403454bc19a2ebe716', 'market': '0x9d1f0296f3a016727193d2b45704e0debc3b8048fe0715f8bb1e91550d321872', 'timestamp': '1733967915109'}
{'asset_id': '101669189743438912873361127612589311253202068943959811456820079057046819967115', 'changes': [{'price': '0.933', 'side': 'BUY', 'size': '107'}], 'event_type': 'price_change', 'hash': '674fcbb664f0f75e0401d2898df30dfdc1a20aef', 'market': '0x9d1f0296f3a016727193d2b45704e0debc3b8048fe0715f8bb1e91550d321872', 'timestamp': '1733967918053'}
{'asset_id': '101669189743438912873361127612589311253202068943959811456820079057046819967115', 'changes': [{'price': '0.933', 'side': 'BUY', 'size': '107'}], 'event_type': 'price_change', 'hash': '674fcbb664f0f75e0401d2898df30dfdc1a20aef', 'market': '0x9d1f0296f3a016727193d2b45704e0debc3b8048fe0715f8bb1e91550d321872', 'timestamp': '1733967918053'}
{'asset_id': '101669189743438912873361127612589311253202068943959811456820079057046819967115', 'changes': [{'price': '0.932', 'side': 'BUY', 'size': '0'}], 'event_type': 'price_change', 'hash': 'a461cb80724948dd5e6e80183a346f7021633d5b', 'market': '0x9d1f0296f3a016727193d2b45704e0debc3b8048fe0715f8bb1e91550d321872', 'timestamp': '1733967919296'}
{'asset_id': '101669189743438912873361127612589311253202068943959811456820079057046819967115', 'changes': [{'price': '0.932', 'side': 'BUY', 'size': '0'}], 'event_type': 'price_change', 'hash': 'a461cb80724948dd5e6e80183a346f7021633d5b', 'market': '0x9d1f0296f3a016727193d2b45704e0debc3b8048fe0715f8bb1e91550d321872', 'timestamp': '1733967919296'}
{'asset_id': '101669189743438912873361127612589311253202068943959811456820079057046819967115', 'changes': [{'price': '0.933', 'side': 'BUY', 'size': '0'}], 'event_type': 'price_change', 'hash': '58bf9d4a500accb170e3a389f1942dcff8cd4bb0', 'market': '0x9d1f0296f3a016727193d2b45704e0debc3b8048fe0715f8bb1e91550d321872', 'timestamp': '1733967922294'}
{'asset_id': '101669189743438912873361127612589311253202068943959811456820079057046819967115', 'changes': [{'price': '0.933', 'side': 'BUY', 'size': '0'}], 'event_type': 'price_change', 'hash': '58bf9d4a500accb170e3a389f1942dcff8cd4bb0', 'market': '0x9d1f0296f3a016727193d2b45704e0debc3b8048fe0715f8bb1e91550d321872', 'timestamp': '1733967922294'}
{'asset_id': '101669189743438912873361127612589311253202068943959811456820079057046819967115', 'changes': [{'price': '0.932', 'side': 'BUY', 'size': '149.38'}], 'event_type': 'price_change', 'hash': '310c3960dd82c29e5ad218df10795504426c62ee', 'market': '0x9d1f0296f3a016727193d2b45704e0debc3b8048fe0715f8bb1e91550d321872', 'timestamp': '1733967923062'}
{'asset_id': '101669189743438912873361127612589311253202068943959811456820079057046819967115', 'changes': [{'price': '0.932', 'side': 'BUY', 'size': '149.38'}], 'event_type': 'price_change', 'hash': '310c3960dd82c29e5ad218df10795504426c62ee', 'market': '0x9d1f0296f3a016727193d2b45704e0debc3b8048fe0715f8bb1e91550d321872', 'timestamp': '1733967923062'}
{'asset_id': '101669189743438912873361127612589311253202068943959811456820079057046819967115', 'changes': [{'price': '0.933', 'side': 'BUY', 'size': '107'}], 'event_type': 'price_change', 'hash': 'a14d44c59c2bd0e7dfb2c864e30c6ce243871189', 'market': '0x9d1f0296f3a016727193d2b45704e0debc3b8048fe0715f8bb1e91550d321872', 'timestamp': '1733967926079'}
{'asset_id': '101669189743438912873361127612589311253202068943959811456820079057046819967115', 'changes': [{'price': '0.933', 'side': 'BUY', 'size': '107'}], 'event_type': 'price_change', 'hash': 'a14d44c59c2bd0e7dfb2c864e30c6ce243871189', 'market': '0x9d1f0296f3a016727193d2b45704e0debc3b8048fe0715f8bb1e91550d321872', 'timestamp': '1733967926079'}
{'asset_id': '101669189743438912873361127612589311253202068943959811456820079057046819967115', 'changes': [{'price': '0.932', 'side': 'BUY', 'size': '0'}], 'event_type': 'price_change', 'hash': 'cedc222a5cb659f0e293830ed4aa9979f7518642', 'market': '0x9d1f0296f3a016727193d2b45704e0debc3b8048fe0715f8bb1e91550d321872', 'timestamp': '1733967927325'}
{'asset_id': '101669189743438912873361127612589311253202068943959811456820079057046819967115', 'changes': [{'price': '0.932', 'side': 'BUY', 'size': '0'}], 'event_type': 'price_change', 'hash': 'cedc222a5cb659f0e293830ed4aa9979f7518642', 'market': '0x9d1f0296f3a016727193d2b45704e0debc3b8048fe0715f8bb1e91550d321872', 'timestamp': '1733967927325'}
{'asset_id': '101669189743438912873361127612589311253202068943959811456820079057046819967115', 'changes': [{'price': '0.933', 'side': 'BUY', 'size': '0'}], 'event_type': 'price_change', 'hash': '6998040eef48f85dc8f8a4e2bc4e4f51d91829b9', 'market': '0x9d1f0296f3a016727193d2b45704e0debc3b8048fe0715f8bb1e91550d321872', 'timestamp': '1733967930306'}
{'asset_id': '101669189743438912873361127612589311253202068943959811456820079057046819967115', 'changes': [{'price': '0.933', 'side': 'BUY', 'size': '0'}], 'event_type': 'price_change', 'hash': '6998040eef48f85dc8f8a4e2bc4e4f51d91829b9', 'market': '0x9d1f0296f3a016727193d2b45704e0debc3b8048fe0715f8bb1e91550d321872', 'timestamp': '1733967930306'}
{'asset_id': '101669189743438912873361127612589311253202068943959811456820079057046819967115', 'changes': [{'price': '0.932', 'side': 'BUY', 'size': '149.38'}], 'event_type': 'price_change', 'hash': 'c2a30a93bf22ffd16d61cafd7ef4ad1e17351255', 'market': '0x9d1f0296f3a016727193d2b45704e0debc3b8048fe0715f8bb1e91550d321872', 'timestamp': '1733967931087'}
{'asset_id': '101669189743438912873361127612589311253202068943959811456820079057046819967115', 'changes': [{'price': '0.932', 'side': 'BUY', 'size': '149.38'}], 'event_type': 'price_change', 'hash': 'c2a30a93bf22ffd16d61cafd7ef4ad1e17351255', 'market': '0x9d1f0296f3a016727193d2b45704e0debc3b8048fe0715f8bb1e91550d321872', 'timestamp': '1733967931087'}
{'asset_id': '101669189743438912873361127612589311253202068943959811456820079057046819967115', 'changes': [{'price': '0.933', 'side': 'BUY', 'size': '107'}], 'event_type': 'price_change', 'hash': '78c7fff7d7e9b617c6e25e704f3767da23746278', 'market': '0x9d1f0296f3a016727193d2b45704e0debc3b8048fe0715f8bb1e91550d321872', 'timestamp': '1733967935049'}
{'asset_id': '101669189743438912873361127612589311253202068943959811456820079057046819967115', 'changes': [{'price': '0.933', 'side': 'BUY', 'size': '107'}], 'event_type': 'price_change', 'hash': '78c7fff7d7e9b617c6e25e704f3767da23746278', 'market': '0x9d1f0296f3a016727193d2b45704e0debc3b8048fe0715f8bb1e91550d321872', 'timestamp': '1733967935049'}
{'asset_id': '101669189743438912873361127612589311253202068943959811456820079057046819967115', 'changes': [{'price': '0.932', 'side': 'BUY', 'size': '0'}], 'event_type': 'price_change', 'hash': '52a46826e2e11991d4ae2d381e14c9f0819b9b8c', 'market': '0x9d1f0296f3a016727193d2b45704e0debc3b8048fe0715f8bb1e91550d321872', 'timestamp': '1733967936316'}
{'asset_id': '101669189743438912873361127612589311253202068943959811456820079057046819967115', 'changes': [{'price': '0.932', 'side': 'BUY', 'size': '0'}], 'event_type': 'price_change', 'hash': '52a46826e2e11991d4ae2d381e14c9f0819b9b8c', 'market': '0x9d1f0296f3a016727193d2b45704e0debc3b8048fe0715f8bb1e91550d321872', 'timestamp': '1733967936316'}
{'asset_id': '101669189743438912873361127612589311253202068943959811456820079057046819967115', 'changes': [{'price': '0.933', 'side': 'BUY', 'size': '0'}], 'event_type': 'price_change', 'hash': '830f3ced15fdfd81c1504ece2c88f6bb1d8d71e3', 'market': '0x9d1f0296f3a016727193d2b45704e0debc3b8048fe0715f8bb1e91550d321872', 'timestamp': '1733967939314'}
{'asset_id': '101669189743438912873361127612589311253202068943959811456820079057046819967115', 'changes': [{'price': '0.933', 'side': 'BUY', 'size': '0'}], 'event_type': 'price_change', 'hash': '830f3ced15fdfd81c1504ece2c88f6bb1d8d71e3', 'market': '0x9d1f0296f3a016727193d2b45704e0debc3b8048fe0715f8bb1e91550d321872', 'timestamp': '1733967939314'}
{'asset_id': '101669189743438912873361127612589311253202068943959811456820079057046819967115', 'changes': [{'price': '0.932', 'side': 'BUY', 'size': '149.38'}], 'event_type': 'price_change', 'hash': '439d30e8869b70420c633ac6679d2d2b22e4fe4d', 'market': '0x9d1f0296f3a016727193d2b45704e0debc3b8048fe0715f8bb1e91550d321872', 'timestamp': '1733967940113'}
{'asset_id': '101669189743438912873361127612589311253202068943959811456820079057046819967115', 'changes': [{'price': '0.932', 'side': 'BUY', 'size': '149.38'}], 'event_type': 'price_change', 'hash': '439d30e8869b70420c633ac6679d2d2b22e4fe4d', 'market': '0x9d1f0296f3a016727193d2b45704e0debc3b8048fe0715f8bb1e91550d321872', 'timestamp': '1733967940113'}
{'asset_id': '101669189743438912873361127612589311253202068943959811456820079057046819967115', 'changes': [{'price': '0.933', 'side': 'BUY', 'size': '107'}], 'event_type': 'price_change', 'hash': '777442527cc6fe36cedff488ef9f65950b33ff8f', 'market': '0x9d1f0296f3a016727193d2b45704e0debc3b8048fe0715f8bb1e91550d321872', 'timestamp': '1733967943749'}
{'asset_id': '101669189743438912873361127612589311253202068943959811456820079057046819967115', 'changes': [{'price': '0.933', 'side': 'BUY', 'size': '107'}], 'event_type': 'price_change', 'hash': '777442527cc6fe36cedff488ef9f65950b33ff8f', 'market': '0x9d1f0296f3a016727193d2b45704e0debc3b8048fe0715f8bb1e91550d321872', 'timestamp': '1733967943749'}
{'asset_id': '101669189743438912873361127612589311253202068943959811456820079057046819967115', 'changes': [{'price': '0.932', 'side': 'BUY', 'size': '0'}], 'event_type': 'price_change', 'hash': '7bb96c054b3d619c936f9ae266573f8ddc8cae43', 'market': '0x9d1f0296f3a016727193d2b45704e0debc3b8048fe0715f8bb1e91550d321872', 'timestamp': '1733967944996'}
{'asset_id': '101669189743438912873361127612589311253202068943959811456820079057046819967115', 'changes': [{'price': '0.932', 'side': 'BUY', 'size': '0'}], 'event_type': 'price_change', 'hash': '7bb96c054b3d619c936f9ae266573f8ddc8cae43', 'market': '0x9d1f0296f3a016727193d2b45704e0debc3b8048fe0715f8bb1e91550d321872', 'timestamp': '1733967944996'}
{'asset_id': '101669189743438912873361127612589311253202068943959811456820079057046819967115', 'changes': [{'price': '0.933', 'side': 'BUY', 'size': '0'}], 'event_type': 'price_change', 'hash': '0c254626ffdd696a28867cec9a3c8a22ce5130ae', 'market': '0x9d1f0296f3a016727193d2b45704e0debc3b8048fe0715f8bb1e91550d321872', 'timestamp': '1733967948308'}
{'asset_id': '101669189743438912873361127612589311253202068943959811456820079057046819967115', 'changes': [{'price': '0.933', 'side': 'BUY', 'size': '0'}], 'event_type': 'price_change', 'hash': '0c254626ffdd696a28867cec9a3c8a22ce5130ae', 'market': '0x9d1f0296f3a016727193d2b45704e0debc3b8048fe0715f8bb1e91550d321872', 'timestamp': '1733967948308'}
{'asset_id': '101669189743438912873361127612589311253202068943959811456820079057046819967115', 'changes': [{'price': '0.932', 'side': 'BUY', 'size': '149.38'}], 'event_type': 'price_change', 'hash': '368258201b0a02ee791c3255575e37d83fe9a5d5', 'market': '0x9d1f0296f3a016727193d2b45704e0debc3b8048fe0715f8bb1e91550d321872', 'timestamp': '1733967949093'}
{'asset_id': '101669189743438912873361127612589311253202068943959811456820079057046819967115', 'changes': [{'price': '0.932', 'side': 'BUY', 'size': '149.38'}], 'event_type': 'price_change', 'hash': '368258201b0a02ee791c3255575e37d83fe9a5d5', 'market': '0x9d1f0296f3a016727193d2b45704e0debc3b8048fe0715f8bb1e91550d321872', 'timestamp': '1733967949093'}
{'asset_id': '101669189743438912873361127612589311253202068943959811456820079057046819967115', 'changes': [{'price': '0.934', 'side': 'BUY', 'size': '18.24'}], 'event_type': 'price_change', 'hash': 'ba7e8d2993fd64cef2b0d9bb07d4c3bf259f8bc2', 'market': '0x9d1f0296f3a016727193d2b45704e0debc3b8048fe0715f8bb1e91550d321872', 'timestamp': '1733967949888'}
{'asset_id': '101669189743438912873361127612589311253202068943959811456820079057046819967115', 'changes': [{'price': '0.934', 'side': 'BUY', 'size': '18.24'}], 'event_type': 'price_change', 'hash': 'ba7e8d2993fd64cef2b0d9bb07d4c3bf259f8bc2', 'market': '0x9d1f0296f3a016727193d2b45704e0debc3b8048fe0715f8bb1e91550d321872', 'timestamp': '1733967949888'}
{'asset_id': '101669189743438912873361127612589311253202068943959811456820079057046819967115', 'changes': [{'price': '0.933', 'side': 'BUY', 'size': '107'}], 'event_type': 'price_change', 'hash': '338cdabfa5024b06bc985cbde1d73e76867567b6', 'market': '0x9d1f0296f3a016727193d2b45704e0debc3b8048fe0715f8bb1e91550d321872', 'timestamp': '1733967952085'}
{'asset_id': '101669189743438912873361127612589311253202068943959811456820079057046819967115', 'changes': [{'price': '0.933', 'side': 'BUY', 'size': '107'}], 'event_type': 'price_change', 'hash': '338cdabfa5024b06bc985cbde1d73e76867567b6', 'market': '0x9d1f0296f3a016727193d2b45704e0debc3b8048fe0715f8bb1e91550d321872', 'timestamp': '1733967952085'}
{'asset_id': '101669189743438912873361127612589311253202068943959811456820079057046819967115', 'changes': [{'price': '0.933', 'side': 'BUY', 'size': '0'}], 'event_type': 'price_change', 'hash': '52bf361519103dfc46d1bdb78f4905bd1bb705fa', 'market': '0x9d1f0296f3a016727193d2b45704e0debc3b8048fe0715f8bb1e91550d321872', 'timestamp': '1733967952439'}
{'asset_id': '101669189743438912873361127612589311253202068943959811456820079057046819967115', 'changes': [{'price': '0.933', 'side': 'BUY', 'size': '0'}], 'event_type': 'price_change', 'hash': '52bf361519103dfc46d1bdb78f4905bd1bb705fa', 'market': '0x9d1f0296f3a016727193d2b45704e0debc3b8048fe0715f8bb1e91550d321872', 'timestamp': '1733967952439'}
{'asset_id': '101669189743438912873361127612589311253202068943959811456820079057046819967115', 'changes': [{'price': '0.932', 'side': 'BUY', 'size': '0'}], 'event_type': 'price_change', 'hash': '7fadbe1c10c9db98eb147473703ac296c6006187', 'market': '0x9d1f0296f3a016727193d2b45704e0debc3b8048fe0715f8bb1e91550d321872', 'timestamp': '1733967953327'}
{'asset_id': '101669189743438912873361127612589311253202068943959811456820079057046819967115', 'changes': [{'price': '0.932', 'side': 'BUY', 'size': '0'}], 'event_type': 'price_change', 'hash': '7fadbe1c10c9db98eb147473703ac296c6006187', 'market': '0x9d1f0296f3a016727193d2b45704e0debc3b8048fe0715f8bb1e91550d321872', 'timestamp': '1733967953327'}
{'asset_id': '101669189743438912873361127612589311253202068943959811456820079057046819967115', 'changes': [{'price': '0.949', 'side': 'SELL', 'size': '205'}], 'event_type': 'price_change', 'hash': '4e3bc83f9db8848afa78a1bf040407e7b19b9bbc', 'market': '0x9d1f0296f3a016727193d2b45704e0debc3b8048fe0715f8bb1e91550d321872', 'timestamp': '1733967955394'}
{'asset_id': '101669189743438912873361127612589311253202068943959811456820079057046819967115', 'changes': [{'price': '0.949', 'side': 'SELL', 'size': '205'}], 'event_type': 'price_change', 'hash': '4e3bc83f9db8848afa78a1bf040407e7b19b9bbc', 'market': '0x9d1f0296f3a016727193d2b45704e0debc3b8048fe0715f8bb1e91550d321872', 'timestamp': '1733967955394'}
{'asset_id': '101669189743438912873361127612589311253202068943959811456820079057046819967115', 'changes': [{'price': '0.951', 'side': 'SELL', 'size': '200'}], 'event_type': 'price_change', 'hash': '7cbefa7d5ccb29b378d0466a49d22712e0643ab3', 'market': '0x9d1f0296f3a016727193d2b45704e0debc3b8048fe0715f8bb1e91550d321872', 'timestamp': '1733967955841'}
{'asset_id': '101669189743438912873361127612589311253202068943959811456820079057046819967115', 'changes': [{'price': '0.951', 'side': 'SELL', 'size': '200'}], 'event_type': 'price_change', 'hash': '7cbefa7d5ccb29b378d0466a49d22712e0643ab3', 'market': '0x9d1f0296f3a016727193d2b45704e0debc3b8048fe0715f8bb1e91550d321872', 'timestamp': '1733967955841'}
{'asset_id': '101669189743438912873361127612589311253202068943959811456820079057046819967115', 'changes': [{'price': '0.951', 'side': 'SELL', 'size': '0'}], 'event_type': 'price_change', 'hash': '0a5fbe7362a8613047ee08f8361c8fdc4df208f9', 'market': '0x9d1f0296f3a016727193d2b45704e0debc3b8048fe0715f8bb1e91550d321872', 'timestamp': '1733967956832'}
{'asset_id': '101669189743438912873361127612589311253202068943959811456820079057046819967115', 'changes': [{'price': '0.951', 'side': 'SELL', 'size': '0'}], 'event_type': 'price_change', 'hash': '0a5fbe7362a8613047ee08f8361c8fdc4df208f9', 'market': '0x9d1f0296f3a016727193d2b45704e0debc3b8048fe0715f8bb1e91550d321872', 'timestamp': '1733967956832'}
{'asset_id': '101669189743438912873361127612589311253202068943959811456820079057046819967115', 'changes': [{'price': '0.948', 'side': 'SELL', 'size': '219'}], 'event_type': 'price_change', 'hash': 'a1c313bdcfda4d3777a36df56e8ce20b7f5d6985', 'market': '0x9d1f0296f3a016727193d2b45704e0debc3b8048fe0715f8bb1e91550d321872', 'timestamp': '1733967956954'}
{'asset_id': '101669189743438912873361127612589311253202068943959811456820079057046819967115', 'changes': [{'price': '0.948', 'side': 'SELL', 'size': '219'}], 'event_type': 'price_change', 'hash': 'a1c313bdcfda4d3777a36df56e8ce20b7f5d6985', 'market': '0x9d1f0296f3a016727193d2b45704e0debc3b8048fe0715f8bb1e91550d321872', 'timestamp': '1733967956954'}
{'asset_id': '101669189743438912873361127612589311253202068943959811456820079057046819967115', 'changes': [{'price': '0.935', 'side': 'BUY', 'size': '149.38'}], 'event_type': 'price_change', 'hash': '83b3efbd43113543f0fc9c66d263b1e29d085c62', 'market': '0x9d1f0296f3a016727193d2b45704e0debc3b8048fe0715f8bb1e91550d321872', 'timestamp': '1733967958266'}
{'asset_id': '101669189743438912873361127612589311253202068943959811456820079057046819967115', 'changes': [{'price': '0.935', 'side': 'BUY', 'size': '149.38'}], 'event_type': 'price_change', 'hash': '83b3efbd43113543f0fc9c66d263b1e29d085c62', 'market': '0x9d1f0296f3a016727193d2b45704e0debc3b8048fe0715f8bb1e91550d321872', 'timestamp': '1733967958266'}
{'asset_id': '101669189743438912873361127612589311253202068943959811456820079057046819967115', 'changes': [{'price': '0.94', 'side': 'SELL', 'size': '100.61'}], 'event_type': 'price_change', 'hash': 'a107084654b3b98e03bfa561f9f789635b6af89e', 'market': '0x9d1f0296f3a016727193d2b45704e0debc3b8048fe0715f8bb1e91550d321872', 'timestamp': '1733967958375'}
{'asset_id': '101669189743438912873361127612589311253202068943959811456820079057046819967115', 'changes': [{'price': '0.94', 'side': 'SELL', 'size': '100.61'}], 'event_type': 'price_change', 'hash': 'a107084654b3b98e03bfa561f9f789635b6af89e', 'market': '0x9d1f0296f3a016727193d2b45704e0debc3b8048fe0715f8bb1e91550d321872', 'timestamp': '1733967958375'}
{'asset_id': '101669189743438912873361127612589311253202068943959811456820079057046819967115', 'changes': [{'price': '0.949', 'side': 'SELL', 'size': '0'}], 'event_type': 'price_change', 'hash': '06ee601e2c7e75a63374a69d3f9b3d67ce328327', 'market': '0x9d1f0296f3a016727193d2b45704e0debc3b8048fe0715f8bb1e91550d321872', 'timestamp': '1733967963531'}
{'asset_id': '101669189743438912873361127612589311253202068943959811456820079057046819967115', 'changes': [{'price': '0.949', 'side': 'SELL', 'size': '0'}], 'event_type': 'price_change', 'hash': '06ee601e2c7e75a63374a69d3f9b3d67ce328327', 'market': '0x9d1f0296f3a016727193d2b45704e0debc3b8048fe0715f8bb1e91550d321872', 'timestamp': '1733967963531'}
{'asset_id': '101669189743438912873361127612589311253202068943959811456820079057046819967115', 'changes': [{'price': '0.948', 'side': 'SELL', 'size': '424'}], 'event_type': 'price_change', 'hash': '132e4687f459947e465d1f185de2f696ff22d151', 'market': '0x9d1f0296f3a016727193d2b45704e0debc3b8048fe0715f8bb1e91550d321872', 'timestamp': '1733967980755'}
{'asset_id': '101669189743438912873361127612589311253202068943959811456820079057046819967115', 'changes': [{'price': '0.948', 'side': 'SELL', 'size': '424'}], 'event_type': 'price_change', 'hash': '132e4687f459947e465d1f185de2f696ff22d151', 'market': '0x9d1f0296f3a016727193d2b45704e0debc3b8048fe0715f8bb1e91550d321872', 'timestamp': '1733967980755'}
