{'asks': [{'price': '0.99', 'size': '4217.01'}, {'price': '0.98', 'size': '505'}, {'price': '0.97', 'size': '511.03'}, {'price': '0.96', 'size': '300'}, {'price': '0.95', 'size': '657.12'}, {'price': '0.94', 'size': '300'}, {'price': '0.92', 'size': '20000.45'}, {'price': '0.91', 'size': '10406.3'}, {'price': '0.9', 'size': '4587.5'}, {'price': '0.89', 'size': '13017.18'}, {'price': '0.88', 'size': '200'}, {'price': '0.87', 'size': '3229'}, {'price': '0.86', 'size': '17.1'}, {'price': '0.85', 'size': '109.68'}, {'price': '0.84', 'size': '250'}, {'price': '0.83', 'size': '100'}, {'price': '0.82', 'size': '16029'}, {'price': '0.81', 'size': '45721.39'}, {'price': '0.8', 'size': '26531'}, {'price': '0.79', 'size': '7110'}, {'price': '0.78', 'size': '10350'}, {'price': '0.77', 'size': '67'}, {'price': '0.76', 'size': '200'}, {'price': '0.75', 'size': '18329.25'}, {'price': '0.74', 'size': '11370.7'}, {'price': '0.73', 'size': '5020.1'}, {'price': '0.72', 'size': '380.52'}, {'price': '0.71', 'size': '15073.2'}, {'price': '0.7', 'size': '5570.1'}, {'price': '0.69', 'size': '6088.6'}, {'price': '0.68', 'size': '6131.34'}, {'price': '0.67', 'size': '3010.1'}, {'price': '0.66', 'size': '510.1'}, {'price': '0.65', 'size': '1010.1'}, {'price': '0.64', 'size': '4230.1'}, {'price': '0.63', 'size': '210.1'}, {'price': '0.62', 'size': '2800.1'}, {'price': '0.61', 'size': '2511.06'}, {'price': '0.6', 'size': '467.85'}, {'price': '0.59', 'size': '1880'}, {'price': '0.58', 'size': '1388.1'}, {'price': '0.57', 'size': '610.1'}, {'price': '0.56', 'size': '1249.1'}], 'asset_id': '114416409796971863099144323163249651172534872992222856507897414949637892047507', 'bids': [{'price': '0.01', 'size': '2850.27'}, {'price': '0.02', 'size': '500'}, {'price': '0.03', 'size': '500'}, {'price': '0.04', 'size': '300'}, {'price': '0.05', 'size': '320'}, {'price': '0.06', 'size': '300'}, {'price': '0.08', 'size': '250'}, {'price': '0.09', 'size': '300'}, {'price': '0.1', 'size': '6205'}, {'price': '0.12', 'size': '200'}, {'price': '0.13', 'size': '426.92'}, {'price': '0.14', 'size': '15'}, {'price': '0.15', 'size': '110'}, {'price': '0.16', 'size': '4709.51'}, {'price': '0.18', 'size': '19.13'}, {'price': '0.19', 'size': '120'}, {'price': '0.2', 'size': '691.17'}, {'price': '0.24', 'size': '5027'}, {'price': '0.25', 'size': '86.66'}, {'price': '0.27', 'size': '215.25'}, {'price': '0.29', 'size': '1102.28'}, {'price': '0.31', 'size': '1130.65'}, {'price': '0.32', 'size': '200'}, {'price': '0.33', 'size': '620'}, {'price': '0.34', 'size': '4000'}, {'price': '0.35', 'size': '232'}, {'price': '0.39', 'size': '10.5'}, {'price': '0.4', 'size': '3135'}, {'price': '0.41', 'size': '20'}, {'price': '0.42', 'size': '3050'}, {'price': '0.43', 'size': '50'}, {'price': '0.44', 'size': '3660'}, {'price': '0.45', 'size': '478'}, {'price': '0.47', 'size': '2797.23'}, {'price': '0.48', 'size': '742.18'}, {'price': '0.49', 'size': '140'}, {'price': '0.5', 'size': '2355'}, {'price': '0.51', 'size': '2586.18'}, {'price': '0.52', 'size': '3062.77'}, {'price': '0.53', 'size': '149'}, {'price': '0.54', 'size': '36.18'}, {'price': '0.55', 'size': '4086.29'}], 'event_type': 'book', 'hash': '8b416babb5401c7cf66f3907e0f0d36f72a389e4', 'market': '0x7aa4a910b31b2c4ddb09d1e3408e52aa8e09a14402f376070a44b1b85cb36d13', 'timestamp': '1733333952671'}
{'asset_id': '114416409796971863099144323163249651172534872992222856507897414949637892047507', 'changes': [{'price': '0.55', 'side': 'BUY', 'size': '4086.29'}], 'event_type': 'price_change', 'hash': '8b416babb5401c7cf66f3907e0f0d36f72a389e4', 'market': '0x7aa4a910b31b2c4ddb09d1e3408e52aa8e09a14402f376070a44b1b85cb36d13', 'timestamp': '1733333952680'}
{'asset_id': '114416409796971863099144323163249651172534872992222856507897414949637892047507', 'event_type': 'last_trade_price', 'fee_rate_bps': '0', 'market': '0x7aa4a910b31b2c4ddb09d1e3408e52aa8e09a14402f376070a44b1b85cb36d13', 'price': '0.55', 'side': 'BUY', 'size': '913.71', 'timestamp': '1733333952690'}
{'asset_id': '114416409796971863099144323163249651172534872992222856507897414949637892047507', 'changes': [{'price': '0.54', 'side': 'BUY', 'size': '21.19'}], 'event_type': 'price_change', 'hash': '36b52806ba01599967bb1a14233c496ee27d9fbe', 'market': '0x7aa4a910b31b2c4ddb09d1e3408e52aa8e09a14402f376070a44b1b85cb36d13', 'timestamp': '1733333953056'}
{'asset_id': '114416409796971863099144323163249651172534872992222856507897414949637892047507', 'changes': [{'price': '0.54', 'side': 'BUY', 'size': '21.19'}], 'event_type': 'price_change', 'hash': '36b52806ba01599967bb1a14233c496ee27d9fbe', 'market': '0x7aa4a910b31b2c4ddb09d1e3408e52aa8e09a14402f376070a44b1b85cb36d13', 'timestamp': '1733333953056'}
{'asset_id': '114416409796971863099144323163249651172534872992222856507897414949637892047507', 'changes': [{'price': '0.55', 'side': 'BUY', 'size': '4101.28'}], 'event_type': 'price_change', 'hash': '96dd798f395f006b198b2535951e2c200d2cd23f', 'market': '0x7aa4a910b31b2c4ddb09d1e3408e52aa8e09a14402f376070a44b1b85cb36d13', 'timestamp': '1733333953152'}
{'asset_id': '114416409796971863099144323163249651172534872992222856507897414949637892047507', 'changes': [{'price': '0.55', 'side': 'BUY', 'size': '4101.28'}], 'event_type': 'price_change', 'hash': '96dd798f395f006b198b2535951e2c200d2cd23f', 'market': '0x7aa4a910b31b2c4ddb09d1e3408e52aa8e09a14402f376070a44b1b85cb36d13', 'timestamp': '1733333953152'}
{'asset_id': '114416409796971863099144323163249651172534872992222856507897414949637892047507', 'changes': [{'price': '0.56', 'side': 'SELL', 'size': '1349.1'}], 'event_type': 'price_change', 'hash': '34217d175cef03a57885888ae58c217d5b2d1c88', 'market': '0x7aa4a910b31b2c4ddb09d1e3408e52aa8e09a14402f376070a44b1b85cb36d13', 'timestamp': '1733333956109'}
{'asset_id': '114416409796971863099144323163249651172534872992222856507897414949637892047507', 'changes': [{'price': '0.56', 'side': 'SELL', 'size': '1349.1'}], 'event_type': 'price_change', 'hash': '34217d175cef03a57885888ae58c217d5b2d1c88', 'market': '0x7aa4a910b31b2c4ddb09d1e3408e52aa8e09a14402f376070a44b1b85cb36d13', 'timestamp': '1733333956109'}
{'asset_id': '114416409796971863099144323163249651172534872992222856507897414949637892047507', 'changes': [{'price': '0.53', 'side': 'BUY', 'size': '119'}], 'event_type': 'price_change', 'hash': 'b2ace2c4c60ccaabf604a67483e2264fedb6e4cd', 'market': '0x7aa4a910b31b2c4ddb09d1e3408e52aa8e09a14402f376070a44b1b85cb36d13', 'timestamp': '1733333958691'}
{'asset_id': '114416409796971863099144323163249651172534872992222856507897414949637892047507', 'changes': [{'price': '0.54', 'side': 'BUY', 'size': '51.19'}], 'event_type': 'price_change', 'hash': '72dd18f906d339fbddaa0fbadc810a96e4a1791d', 'market': '0x7aa4a910b31b2c4ddb09d1e3408e52aa8e09a14402f376070a44b1b85cb36d13', 'timestamp': '1733333958818'}
{'asset_id': '114416409796971863099144323163249651172534872992222856507897414949637892047507', 'changes': [{'price': '0.54', 'side': 'BUY', 'size': '51.19'}], 'event_type': 'price_change', 'hash': '72dd18f906d339fbddaa0fbadc810a96e4a1791d', 'market': '0x7aa4a910b31b2c4ddb09d1e3408e52aa8e09a14402f376070a44b1b85cb36d13', 'timestamp': '1733333958818'}
{'asset_id': '114416409796971863099144323163249651172534872992222856507897414949637892047507', 'changes': [{'price': '0.59', 'side': 'SELL', 'size': '1610'}, {'price': '0.5', 'side': 'BUY', 'size': '2115'}], 'event_type': 'price_change', 'hash': '893f6738e1c2e2b7728daf756748b7b66bfba5cb', 'market': '0x7aa4a910b31b2c4ddb09d1e3408e52aa8e09a14402f376070a44b1b85cb36d13', 'timestamp': '1733333958883'}
{'asset_id': '114416409796971863099144323163249651172534872992222856507897414949637892047507', 'changes': [{'price': '0.59', 'side': 'SELL', 'size': '1610'}, {'price': '0.5', 'side': 'BUY', 'size': '2115'}], 'event_type': 'price_change', 'hash': '893f6738e1c2e2b7728daf756748b7b66bfba5cb', 'market': '0x7aa4a910b31b2c4ddb09d1e3408e52aa8e09a14402f376070a44b1b85cb36d13', 'timestamp': '1733333958883'}
{'asset_id': '114416409796971863099144323163249651172534872992222856507897414949637892047507', 'changes': [{'price': '0.51', 'side': 'BUY', 'size': '2826.18'}, {'price': '0.6', 'side': 'SELL', 'size': '747.85'}, {'price': '0.56', 'side': 'SELL', 'size': '1319.1'}], 'event_type': 'price_change', 'hash': '036654403ee711285cdd368b1d5fc438930b6dad', 'market': '0x7aa4a910b31b2c4ddb09d1e3408e52aa8e09a14402f376070a44b1b85cb36d13', 'timestamp': '1733333959208'}
{'asset_id': '114416409796971863099144323163249651172534872992222856507897414949637892047507', 'changes': [{'price': '0.51', 'side': 'BUY', 'size': '2826.18'}, {'price': '0.6', 'side': 'SELL', 'size': '747.85'}, {'price': '0.56', 'side': 'SELL', 'size': '1319.1'}], 'event_type': 'price_change', 'hash': '036654403ee711285cdd368b1d5fc438930b6dad', 'market': '0x7aa4a910b31b2c4ddb09d1e3408e52aa8e09a14402f376070a44b1b85cb36d13', 'timestamp': '1733333959208'}
{'asset_id': '114416409796971863099144323163249651172534872992222856507897414949637892047507', 'changes': [{'price': '0.57', 'side': 'SELL', 'size': '640.1'}, {'price': '0.56', 'side': 'SELL', 'size': '1269.1'}], 'event_type': 'price_change', 'hash': '7b083144b5163ccd14ddc72d2e9c8d31e9d1d733', 'market': '0x7aa4a910b31b2c4ddb09d1e3408e52aa8e09a14402f376070a44b1b85cb36d13', 'timestamp': '1733333959364'}
{'asset_id': '114416409796971863099144323163249651172534872992222856507897414949637892047507', 'changes': [{'price': '0.57', 'side': 'SELL', 'size': '640.1'}, {'price': '0.56', 'side': 'SELL', 'size': '1269.1'}], 'event_type': 'price_change', 'hash': '7b083144b5163ccd14ddc72d2e9c8d31e9d1d733', 'market': '0x7aa4a910b31b2c4ddb09d1e3408e52aa8e09a14402f376070a44b1b85cb36d13', 'timestamp': '1733333959364'}
{'asset_id': '114416409796971863099144323163249651172534872992222856507897414949637892047507', 'changes': [{'price': '0.49', 'side': 'BUY', 'size': '90'}], 'event_type': 'price_change', 'hash': '18443f646a9d5f09f5b1acd6bbb94f62d452c385', 'market': '0x7aa4a910b31b2c4ddb09d1e3408e52aa8e09a14402f376070a44b1b85cb36d13', 'timestamp': '1733333959865'}
{'asset_id': '114416409796971863099144323163249651172534872992222856507897414949637892047507', 'changes': [{'price': '0.49', 'side': 'BUY', 'size': '90'}], 'event_type': 'price_change', 'hash': '18443f646a9d5f09f5b1acd6bbb94f62d452c385', 'market': '0x7aa4a910b31b2c4ddb09d1e3408e52aa8e09a14402f376070a44b1b85cb36d13', 'timestamp': '1733333959865'}
{'asset_id': '114416409796971863099144323163249651172534872992222856507897414949637892047507', 'changes': [{'price': '0.6', 'side': 'SELL', 'size': '797.85'}], 'event_type': 'price_change', 'hash': '871b6ccb0bd7a8c49a2d2a997ce9be7095176ce2', 'market': '0x7aa4a910b31b2c4ddb09d1e3408e52aa8e09a14402f376070a44b1b85cb36d13', 'timestamp': '1733333960094'}
{'asset_id': '114416409796971863099144323163249651172534872992222856507897414949637892047507', 'changes': [{'price': '0.6', 'side': 'SELL', 'size': '797.85'}], 'event_type': 'price_change', 'hash': '871b6ccb0bd7a8c49a2d2a997ce9be7095176ce2', 'market': '0x7aa4a910b31b2c4ddb09d1e3408e52aa8e09a14402f376070a44b1b85cb36d13', 'timestamp': '1733333960094'}
{'asset_id': '114416409796971863099144323163249651172534872992222856507897414949637892047507', 'changes': [{'price': '0.53', 'side': 'BUY', 'size': '169'}], 'event_type': 'price_change', 'hash': 'c9b0632569570b7ac711d201e7ff4f086c16f5b9', 'market': '0x7aa4a910b31b2c4ddb09d1e3408e52aa8e09a14402f376070a44b1b85cb36d13', 'timestamp': '1733333960336'}
{'asset_id': '114416409796971863099144323163249651172534872992222856507897414949637892047507', 'changes': [{'price': '0.53', 'side': 'BUY', 'size': '169'}], 'event_type': 'price_change', 'hash': 'c9b0632569570b7ac711d201e7ff4f086c16f5b9', 'market': '0x7aa4a910b31b2c4ddb09d1e3408e52aa8e09a14402f376070a44b1b85cb36d13', 'timestamp': '1733333960336'}
{'asset_id': '114416409796971863099144323163249651172534872992222856507897414949637892047507', 'changes': [{'price': '0.56', 'side': 'SELL', 'size': '1219.1'}], 'event_type': 'price_change', 'hash': '33266af03bfdcf4e93fc77b98d50061237d5446c', 'market': '0x7aa4a910b31b2c4ddb09d1e3408e52aa8e09a14402f376070a44b1b85cb36d13', 'timestamp': '1733333960405'}
{'asset_id': '114416409796971863099144323163249651172534872992222856507897414949637892047507', 'changes': [{'price': '0.56', 'side': 'SELL', 'size': '1219.1'}], 'event_type': 'price_change', 'hash': '33266af03bfdcf4e93fc77b98d50061237d5446c', 'market': '0x7aa4a910b31b2c4ddb09d1e3408e52aa8e09a14402f376070a44b1b85cb36d13', 'timestamp': '1733333960405'}
{'asset_id': '114416409796971863099144323163249651172534872992222856507897414949637892047507', 'changes': [{'price': '0.49', 'side': 'BUY', 'size': '40'}], 'event_type': 'price_change', 'hash': '4ea9457bf4a5eaede34908070144fa0f3586c5f6', 'market': '0x7aa4a910b31b2c4ddb09d1e3408e52aa8e09a14402f376070a44b1b85cb36d13', 'timestamp': '1733333960922'}
{'asset_id': '114416409796971863099144323163249651172534872992222856507897414949637892047507', 'changes': [{'price': '0.49', 'side': 'BUY', 'size': '40'}], 'event_type': 'price_change', 'hash': '4ea9457bf4a5eaede34908070144fa0f3586c5f6', 'market': '0x7aa4a910b31b2c4ddb09d1e3408e52aa8e09a14402f376070a44b1b85cb36d13', 'timestamp': '1733333960922'}
{'asset_id': '114416409796971863099144323163249651172534872992222856507897414949637892047507', 'changes': [{'price': '0.6', 'side': 'SELL', 'size': '847.85'}], 'event_type': 'price_change', 'hash': '721cc6ae28c6a2e6accc3e488b7a723ae68d4639', 'market': '0x7aa4a910b31b2c4ddb09d1e3408e52aa8e09a14402f376070a44b1b85cb36d13', 'timestamp': '1733333961284'}
{'asset_id': '114416409796971863099144323163249651172534872992222856507897414949637892047507', 'changes': [{'price': '0.6', 'side': 'SELL', 'size': '847.85'}], 'event_type': 'price_change', 'hash': '721cc6ae28c6a2e6accc3e488b7a723ae68d4639', 'market': '0x7aa4a910b31b2c4ddb09d1e3408e52aa8e09a14402f376070a44b1b85cb36d13', 'timestamp': '1733333961284'}
{'asset_id': '114416409796971863099144323163249651172534872992222856507897414949637892047507', 'changes': [{'price': '0.53', 'side': 'BUY', 'size': '219'}], 'event_type': 'price_change', 'hash': '4b333dc5b7f59ddb1ad514b319940206d7401a34', 'market': '0x7aa4a910b31b2c4ddb09d1e3408e52aa8e09a14402f376070a44b1b85cb36d13', 'timestamp': '1733333961610'}
{'asset_id': '114416409796971863099144323163249651172534872992222856507897414949637892047507', 'changes': [{'price': '0.53', 'side': 'BUY', 'size': '219'}], 'event_type': 'price_change', 'hash': '4b333dc5b7f59ddb1ad514b319940206d7401a34', 'market': '0x7aa4a910b31b2c4ddb09d1e3408e52aa8e09a14402f376070a44b1b85cb36d13', 'timestamp': '1733333961610'}
{'asset_id': '114416409796971863099144323163249651172534872992222856507897414949637892047507', 'changes': [{'price': '0.55', 'side': 'BUY', 'size': '4201.28'}], 'event_type': 'price_change', 'hash': '5b609433be88e3782dca9cbc49e479dea9ee9a42', 'market': '0x7aa4a910b31b2c4ddb09d1e3408e52aa8e09a14402f376070a44b1b85cb36d13', 'timestamp': '1733333963373'}
{'asset_id': '114416409796971863099144323163249651172534872992222856507897414949637892047507', 'changes': [{'price': '0.55', 'side': 'BUY', 'size': '4201.28'}], 'event_type': 'price_change', 'hash': '5b609433be88e3782dca9cbc49e479dea9ee9a42', 'market': '0x7aa4a910b31b2c4ddb09d1e3408e52aa8e09a14402f376070a44b1b85cb36d13', 'timestamp': '1733333963373'}
{'asset_id': '114416409796971863099144323163249651172534872992222856507897414949637892047507', 'changes': [{'price': '0.52', 'side': 'BUY', 'size': '1862.77'}], 'event_type': 'price_change', 'hash': '68800fdc40a115016d3dfac281ef5a60155efcad', 'market': '0x7aa4a910b31b2c4ddb09d1e3408e52aa8e09a14402f376070a44b1b85cb36d13', 'timestamp': '1733333964010'}
{'asset_id': '114416409796971863099144323163249651172534872992222856507897414949637892047507', 'changes': [{'price': '0.52', 'side': 'BUY', 'size': '1862.77'}], 'event_type': 'price_change', 'hash': '68800fdc40a115016d3dfac281ef5a60155efcad', 'market': '0x7aa4a910b31b2c4ddb09d1e3408e52aa8e09a14402f376070a44b1b85cb36d13', 'timestamp': '1733333964010'}
{'asset_id': '114416409796971863099144323163249651172534872992222856507897414949637892047507', 'changes': [{'price': '0.52', 'side': 'BUY', 'size': '3062.77'}], 'event_type': 'price_change', 'hash': '4b9543b1b6777871fbe899c34c145e3fb9fce9f5', 'market': '0x7aa4a910b31b2c4ddb09d1e3408e52aa8e09a14402f376070a44b1b85cb36d13', 'timestamp': '1733333971911'}
{'asset_id': '114416409796971863099144323163249651172534872992222856507897414949637892047507', 'changes': [{'price': '0.52', 'side': 'BUY', 'size': '3062.77'}], 'event_type': 'price_change', 'hash': '4b9543b1b6777871fbe899c34c145e3fb9fce9f5', 'market': '0x7aa4a910b31b2c4ddb09d1e3408e52aa8e09a14402f376070a44b1b85cb36d13', 'timestamp': '1733333971911'}
{'asset_id': '114416409796971863099144323163249651172534872992222856507897414949637892047507', 'changes': [{'price': '0.52', 'side': 'BUY', 'size': '3085.92'}], 'event_type': 'price_change', 'hash': '2883d6ecc666e3dfc24a6ba254f1b97e10aa62b9', 'market': '0x7aa4a910b31b2c4ddb09d1e3408e52aa8e09a14402f376070a44b1b85cb36d13', 'timestamp': '1733333995866'}
{'asset_id': '114416409796971863099144323163249651172534872992222856507897414949637892047507', 'changes': [{'price': '0.52', 'side': 'BUY', 'size': '3085.92'}], 'event_type': 'price_change', 'hash': '2883d6ecc666e3dfc24a6ba254f1b97e10aa62b9', 'market': '0x7aa4a910b31b2c4ddb09d1e3408e52aa8e09a14402f376070a44b1b85cb36d13', 'timestamp': '1733333995866'}
{'asset_id': '114416409796971863099144323163249651172534872992222856507897414949637892047507', 'changes': [{'price': '0.53', 'side': 'BUY', 'size': '1218.99'}], 'event_type': 'price_change', 'hash': 'aa16d7a9ccd698c9279540f4adb392aeddcc615e', 'market': '0x7aa4a910b31b2c4ddb09d1e3408e52aa8e09a14402f376070a44b1b85cb36d13', 'timestamp': '1733334002038'}
{'asset_id': '114416409796971863099144323163249651172534872992222856507897414949637892047507', 'changes': [{'price': '0.53', 'side': 'BUY', 'size': '1218.99'}], 'event_type': 'price_change', 'hash': 'aa16d7a9ccd698c9279540f4adb392aeddcc615e', 'market': '0x7aa4a910b31b2c4ddb09d1e3408e52aa8e09a14402f376070a44b1b85cb36d13', 'timestamp': '1733334002038'}
{'asset_id': '114416409796971863099144323163249651172534872992222856507897414949637892047507', 'changes': [{'price': '0.6', 'side': 'SELL', 'size': '567.85'}, {'price': '0.51', 'side': 'BUY', 'size': '2586.18'}], 'event_type': 'price_change', 'hash': '5d0844ac3a6d1b2e9595d4de85fdf38ef048416b', 'market': '0x7aa4a910b31b2c4ddb09d1e3408e52aa8e09a14402f376070a44b1b85cb36d13', 'timestamp': '1733334009601'}
{'asset_id': '114416409796971863099144323163249651172534872992222856507897414949637892047507', 'changes': [{'price': '0.6', 'side': 'SELL', 'size': '567.85'}, {'price': '0.51', 'side': 'BUY', 'size': '2586.18'}], 'event_type': 'price_change', 'hash': '5d0844ac3a6d1b2e9595d4de85fdf38ef048416b', 'market': '0x7aa4a910b31b2c4ddb09d1e3408e52aa8e09a14402f376070a44b1b85cb36d13', 'timestamp': '1733334009601'}
{'asset_id': '114416409796971863099144323163249651172534872992222856507897414949637892047507', 'changes': [{'price': '0.52', 'side': 'BUY', 'size': '3295.92'}], 'event_type': 'price_change', 'hash': '6837f9bbdc9326c59a985abdb1cc135712d55058', 'market': '0x7aa4a910b31b2c4ddb09d1e3408e52aa8e09a14402f376070a44b1b85cb36d13', 'timestamp': '1733334009891'}
{'asset_id': '114416409796971863099144323163249651172534872992222856507897414949637892047507', 'changes': [{'price': '0.52', 'side': 'BUY', 'size': '3295.92'}], 'event_type': 'price_change', 'hash': '6837f9bbdc9326c59a985abdb1cc135712d55058', 'market': '0x7aa4a910b31b2c4ddb09d1e3408e52aa8e09a14402f376070a44b1b85cb36d13', 'timestamp': '1733334009891'}
{'asset_id': '114416409796971863099144323163249651172534872992222856507897414949637892047507', 'changes': [{'price': '0.6', 'side': 'SELL', 'size': '817.85'}], 'event_type': 'price_change', 'hash': '8f12c634e7ea6bcc6dcd6334496107a58c46b4fc', 'market': '0x7aa4a910b31b2c4ddb09d1e3408e52aa8e09a14402f376070a44b1b85cb36d13', 'timestamp': '1733334010138'}
{'asset_id': '114416409796971863099144323163249651172534872992222856507897414949637892047507', 'changes': [{'price': '0.6', 'side': 'SELL', 'size': '817.85'}], 'event_type': 'price_change', 'hash': '8f12c634e7ea6bcc6dcd6334496107a58c46b4fc', 'market': '0x7aa4a910b31b2c4ddb09d1e3408e52aa8e09a14402f376070a44b1b85cb36d13', 'timestamp': '1733334010138'}
{'asset_id': '114416409796971863099144323163249651172534872992222856507897414949637892047507', 'changes': [{'price': '0.55', 'side': 'BUY', 'size': '4186.29'}], 'event_type': 'price_change', 'hash': '959114104f52d63118e1a22a58a921caba3f4323', 'market': '0x7aa4a910b31b2c4ddb09d1e3408e52aa8e09a14402f376070a44b1b85cb36d13', 'timestamp': '1733334034602'}
{'asset_id': '114416409796971863099144323163249651172534872992222856507897414949637892047507', 'changes': [{'price': '0.55', 'side': 'BUY', 'size': '4186.29'}], 'event_type': 'price_change', 'hash': '959114104f52d63118e1a22a58a921caba3f4323', 'market': '0x7aa4a910b31b2c4ddb09d1e3408e52aa8e09a14402f376070a44b1b85cb36d13', 'timestamp': '1733334034602'}
{'asset_id': '114416409796971863099144323163249651172534872992222856507897414949637892047507', 'changes': [{'price': '0.55', 'side': 'BUY', 'size': '4201.28'}], 'event_type': 'price_change', 'hash': '34ef477fe582f00cebf83002959680744a0f2183', 'market': '0x7aa4a910b31b2c4ddb09d1e3408e52aa8e09a14402f376070a44b1b85cb36d13', 'timestamp': '1733334036479'}
{'asset_id': '114416409796971863099144323163249651172534872992222856507897414949637892047507', 'changes': [{'price': '0.55', 'side': 'BUY', 'size': '4201.28'}], 'event_type': 'price_change', 'hash': '34ef477fe582f00cebf83002959680744a0f2183', 'market': '0x7aa4a910b31b2c4ddb09d1e3408e52aa8e09a14402f376070a44b1b85cb36d13', 'timestamp': '1733334036479'}
{'asset_id': '114416409796971863099144323163249651172534872992222856507897414949637892047507', 'changes': [{'price': '0.55', 'side': 'BUY', 'size': '4186.29'}], 'event_type': 'price_change', 'hash': 'a80eb7b9eeb93c0e651d0d02d24ad5ecedd236ae', 'market': '0x7aa4a910b31b2c4ddb09d1e3408e52aa8e09a14402f376070a44b1b85cb36d13', 'timestamp': '1733334038601'}
{'asset_id': '114416409796971863099144323163249651172534872992222856507897414949637892047507', 'changes': [{'price': '0.55', 'side': 'BUY', 'size': '4186.29'}], 'event_type': 'price_change', 'hash': 'a80eb7b9eeb93c0e651d0d02d24ad5ecedd236ae', 'market': '0x7aa4a910b31b2c4ddb09d1e3408e52aa8e09a14402f376070a44b1b85cb36d13', 'timestamp': '1733334038601'}
{'asks': [{'price': '0.99', 'size': '4217.01'}, {'price': '0.98', 'size': '505'}, {'price': '0.97', 'size': '511.03'}, {'price': '0.96', 'size': '300'}, {'price': '0.95', 'size': '657.12'}, {'price': '0.94', 'size': '300'}, {'price': '0.92', 'size': '20000.45'}, {'price': '0.91', 'size': '10406.3'}, {'price': '0.9', 'size': '4587.5'}, {'price': '0.89', 'size': '13017.18'}, {'price': '0.88', 'size': '200'}, {'price': '0.87', 'size': '3229'}, {'price': '0.86', 'size': '17.1'}, {'price': '0.85', 'size': '109.68'}, {'price': '0.84', 'size': '250'}, {'price': '0.83', 'size': '100'}, {'price': '0.82', 'size': '16029'}, {'price': '0.81', 'size': '45721.39'}, {'price': '0.8', 'size': '26531'}, {'price': '0.79', 'size': '7110'}, {'price': '0.78', 'size': '10350'}, {'price': '0.77', 'size': '67'}, {'price': '0.76', 'size': '200'}, {'price': '0.75', 'size': '18329.25'}, {'price': '0.74', 'size': '11370.7'}, {'price': '0.73', 'size': '5020.1'}, {'price': '0.72', 'size': '380.52'}, {'price': '0.71', 'size': '15073.2'}, {'price': '0.7', 'size': '5570.1'}, {'price': '0.69', 'size': '6088.6'}, {'price': '0.68', 'size': '6131.34'}, {'price': '0.67', 'size': '3010.1'}, {'price': '0.66', 'size': '510.1'}, {'price': '0.65', 'size': '1010.1'}, {'price': '0.64', 'size': '4230.1'}, {'price': '0.63', 'size': '210.1'}, {'price': '0.62', 'size': '2800.1'}, {'price': '0.61', 'size': '2511.06'}, {'price': '0.6', 'size': '817.85'}, {'price': '0.59', 'size': '1610'}, {'price': '0.58', 'size': '1388.1'}, {'price': '0.57', 'size': '640.1'}, {'price': '0.56', 'size': '1219.08'}], 'asset_id': '114416409796971863099144323163249651172534872992222856507897414949637892047507', 'bids': [{'price': '0.01', 'size': '2850.27'}, {'price': '0.02', 'size': '500'}, {'price': '0.03', 'size': '500'}, {'price': '0.04', 'size': '300'}, {'price': '0.05', 'size': '320'}, {'price': '0.06', 'size': '300'}, {'price': '0.08', 'size': '250'}, {'price': '0.09', 'size': '300'}, {'price': '0.1', 'size': '6205'}, {'price': '0.12', 'size': '200'}, {'price': '0.13', 'size': '426.92'}, {'price': '0.14', 'size': '15'}, {'price': '0.15', 'size': '110'}, {'price': '0.16', 'size': '4709.51'}, {'price': '0.18', 'size': '19.13'}, {'price': '0.19', 'size': '120'}, {'price': '0.2', 'size': '691.17'}, {'price': '0.24', 'size': '5027'}, {'price': '0.25', 'size': '86.66'}, {'price': '0.27', 'size': '215.25'}, {'price': '0.29', 'size': '1102.28'}, {'price': '0.31', 'size': '1130.65'}, {'price': '0.32', 'size': '200'}, {'price': '0.33', 'size': '620'}, {'price': '0.34', 'size': '4000'}, {'price': '0.35', 'size': '232'}, {'price': '0.39', 'size': '10.5'}, {'price': '0.4', 'size': '3135'}, {'price': '0.41', 'size': '20'}, {'price': '0.42', 'size': '3050'}, {'price': '0.43', 'size': '50'}, {'price': '0.44', 'size': '3660'}, {'price': '0.45', 'size': '478'}, {'price': '0.47', 'size': '2797.23'}, {'price': '0.48', 'size': '742.18'}, {'price': '0.49', 'size': '40'}, {'price': '0.5', 'size': '2115'}, {'price': '0.51', 'size': '2586.18'}, {'price': '0.52', 'size': '3295.92'}, {'price': '0.53', 'size': '1218.99'}, {'price': '0.54', 'size': '51.19'}, {'price': '0.55', 'size': '4186.29'}], 'event_type': 'book', 'hash': '1a7346cce430234ee527d4e96cd85480e6862e6b', 'market': '0x7aa4a910b31b2c4ddb09d1e3408e52aa8e09a14402f376070a44b1b85cb36d13', 'timestamp': '1733334039922'}
{'asset_id': '114416409796971863099144323163249651172534872992222856507897414949637892047507', 'event_type': 'last_trade_price', 'fee_rate_bps': '0', 'market': '0x7aa4a910b31b2c4ddb09d1e3408e52aa8e09a14402f376070a44b1b85cb36d13', 'price': '0.56', 'side': 'BUY', 'size': '0.017856', 'timestamp': '1733334039943'}
{'asks': [{'price': '0.99', 'size': '4217.01'}, {'price': '0.98', 'size': '505'}, {'price': '0.97', 'size': '511.03'}, {'price': '0.96', 'size': '300'}, {'price': '0.95', 'size': '657.12'}, {'price': '0.94', 'size': '300'}, {'price': '0.92', 'size': '20000.45'}, {'price': '0.91', 'size': '10406.3'}, {'price': '0.9', 'size': '4587.5'}, {'price': '0.89', 'size': '13017.18'}, {'price': '0.88', 'size': '200'}, {'price': '0.87', 'size': '3229'}, {'price': '0.86', 'size': '17.1'}, {'price': '0.85', 'size': '109.68'}, {'price': '0.84', 'size': '250'}, {'price': '0.83', 'size': '100'}, {'price': '0.82', 'size': '16029'}, {'price': '0.81', 'size': '45721.39'}, {'price': '0.8', 'size': '26531'}, {'price': '0.79', 'size': '7110'}, {'price': '0.78', 'size': '10350'}, {'price': '0.77', 'size': '67'}, {'price': '0.76', 'size': '200'}, {'price': '0.75', 'size': '18329.25'}, {'price': '0.74', 'size': '11370.7'}, {'price': '0.73', 'size': '5020.1'}, {'price': '0.72', 'size': '380.52'}, {'price': '0.71', 'size': '15073.2'}, {'price': '0.7', 'size': '5570.1'}, {'price': '0.69', 'size': '6088.6'}, {'price': '0.68', 'size': '6131.34'}, {'price': '0.67', 'size': '3010.1'}, {'price': '0.66', 'size': '510.1'}, {'price': '0.65', 'size': '1010.1'}, {'price': '0.64', 'size': '4230.1'}, {'price': '0.63', 'size': '210.1'}, {'price': '0.62', 'size': '2800.1'}, {'price': '0.61', 'size': '2511.06'}, {'price': '0.6', 'size': '817.85'}, {'price': '0.59', 'size': '1610'}, {'price': '0.58', 'size': '1388.1'}, {'price': '0.57', 'size': '640.1'}, {'price': '0.56', 'size': '1219.08'}], 'asset_id': '114416409796971863099144323163249651172534872992222856507897414949637892047507', 'bids': [{'price': '0.01', 'size': '2850.27'}, {'price': '0.02', 'size': '500'}, {'price': '0.03', 'size': '500'}, {'price': '0.04', 'size': '300'}, {'price': '0.05', 'size': '320'}, {'price': '0.06', 'size': '300'}, {'price': '0.08', 'size': '250'}, {'price': '0.09', 'size': '300'}, {'price': '0.1', 'size': '6205'}, {'price': '0.12', 'size': '200'}, {'price': '0.13', 'size': '426.92'}, {'price': '0.14', 'size': '15'}, {'price': '0.15', 'size': '110'}, {'price': '0.16', 'size': '4709.51'}, {'price': '0.18', 'size': '19.13'}, {'price': '0.19', 'size': '120'}, {'price': '0.2', 'size': '691.17'}, {'price': '0.24', 'size': '5027'}, {'price': '0.25', 'size': '86.66'}, {'price': '0.27', 'size': '215.25'}, {'price': '0.29', 'size': '1102.28'}, {'price': '0.31', 'size': '1130.65'}, {'price': '0.32', 'size': '200'}, {'price': '0.33', 'size': '620'}, {'price': '0.34', 'size': '4000'}, {'price': '0.35', 'size': '232'}, {'price': '0.39', 'size': '10.5'}, {'price': '0.4', 'size': '3135'}, {'price': '0.41', 'size': '20'}, {'price': '0.42', 'size': '3050'}, {'price': '0.43', 'size': '50'}, {'price': '0.44', 'size': '3660'}, {'price': '0.45', 'size': '478'}, {'price': '0.47', 'size': '2797.23'}, {'price': '0.48', 'size': '742.18'}, {'price': '0.49', 'size': '40'}, {'price': '0.5', 'size': '2115'}, {'price': '0.51', 'size': '2586.18'}, {'price': '0.52', 'size': '3295.92'}, {'price': '0.53', 'size': '1218.99'}, {'price': '0.54', 'size': '51.19'}, {'price': '0.55', 'size': '4186.29'}], 'event_type': 'book', 'hash': '1a7346cce430234ee527d4e96cd85480e6862e6b', 'market': '0x7aa4a910b31b2c4ddb09d1e3408e52aa8e09a14402f376070a44b1b85cb36d13', 'timestamp': '1733334039922'}
{'asset_id': '114416409796971863099144323163249651172534872992222856507897414949637892047507', 'event_type': 'last_trade_price', 'fee_rate_bps': '0', 'market': '0x7aa4a910b31b2c4ddb09d1e3408e52aa8e09a14402f376070a44b1b85cb36d13', 'price': '0.56', 'side': 'BUY', 'size': '0.017856', 'timestamp': '1733334039943'}
{'asks': [{'price': '0.99', 'size': '4217.01'}, {'price': '0.98', 'size': '505'}, {'price': '0.97', 'size': '511.03'}, {'price': '0.96', 'size': '300'}, {'price': '0.95', 'size': '657.12'}, {'price': '0.94', 'size': '300'}, {'price': '0.92', 'size': '20000.45'}, {'price': '0.91', 'size': '10406.3'}, {'price': '0.9', 'size': '4587.5'}, {'price': '0.89', 'size': '13017.18'}, {'price': '0.88', 'size': '200'}, {'price': '0.87', 'size': '3229'}, {'price': '0.86', 'size': '17.1'}, {'price': '0.85', 'size': '109.68'}, {'price': '0.84', 'size': '250'}, {'price': '0.83', 'size': '100'}, {'price': '0.82', 'size': '16029'}, {'price': '0.81', 'size': '45721.39'}, {'price': '0.8', 'size': '26531'}, {'price': '0.79', 'size': '7110'}, {'price': '0.78', 'size': '10350'}, {'price': '0.77', 'size': '67'}, {'price': '0.76', 'size': '200'}, {'price': '0.75', 'size': '18329.25'}, {'price': '0.74', 'size': '11370.7'}, {'price': '0.73', 'size': '5020.1'}, {'price': '0.72', 'size': '380.52'}, {'price': '0.71', 'size': '15073.2'}, {'price': '0.7', 'size': '5570.1'}, {'price': '0.69', 'size': '6088.6'}, {'price': '0.68', 'size': '6131.34'}, {'price': '0.67', 'size': '3010.1'}, {'price': '0.66', 'size': '510.1'}, {'price': '0.65', 'size': '1010.1'}, {'price': '0.64', 'size': '4230.1'}, {'price': '0.63', 'size': '210.1'}, {'price': '0.62', 'size': '2800.1'}, {'price': '0.61', 'size': '2511.06'}, {'price': '0.6', 'size': '817.85'}, {'price': '0.59', 'size': '1610'}, {'price': '0.58', 'size': '1388.1'}, {'price': '0.57', 'size': '640.1'}, {'price': '0.56', 'size': '1219.08'}], 'asset_id': '114416409796971863099144323163249651172534872992222856507897414949637892047507', 'bids': [{'price': '0.01', 'size': '2850.27'}, {'price': '0.02', 'size': '500'}, {'price': '0.03', 'size': '500'}, {'price': '0.04', 'size': '300'}, {'price': '0.05', 'size': '320'}, {'price': '0.06', 'size': '300'}, {'price': '0.08', 'size': '250'}, {'price': '0.09', 'size': '300'}, {'price': '0.1', 'size': '6205'}, {'price': '0.12', 'size': '200'}, {'price': '0.13', 'size': '426.92'}, {'price': '0.14', 'size': '15'}, {'price': '0.15', 'size': '110'}, {'price': '0.16', 'size': '4709.51'}, {'price': '0.18', 'size': '19.13'}, {'price': '0.19', 'size': '120'}, {'price': '0.2', 'size': '691.17'}, {'price': '0.24', 'size': '5027'}, {'price': '0.25', 'size': '86.66'}, {'price': '0.27', 'size': '215.25'}, {'price': '0.29', 'size': '1102.28'}, {'price': '0.31', 'size': '1130.65'}, {'price': '0.32', 'size': '200'}, {'price': '0.33', 'size': '620'}, {'price': '0.34', 'size': '4000'}, {'price': '0.35', 'size': '232'}, {'price': '0.39', 'size': '10.5'}, {'price': '0.4', 'size': '3135'}, {'price': '0.41', 'size': '20'}, {'price': '0.42', 'size': '3050'}, {'price': '0.43', 'size': '50'}, {'price': '0.44', 'size': '3660'}, {'price': '0.45', 'size': '478'}, {'price': '0.47', 'size': '2797.23'}, {'price': '0.48', 'size': '742.18'}, {'price': '0.49', 'size': '40'}, {'price': '0.5', 'size': '2115'}, {'price': '0.51', 'size': '2586.18'}, {'price': '0.52', 'size': '3295.92'}, {'price': '0.53', 'size': '1218.99'}, {'price': '0.54', 'size': '51.19'}, {'price': '0.55', 'size': '4186.26'}], 'event_type': 'book', 'hash': '2df1075152583bca694b06ad9536cee11f42f8be', 'market': '0x7aa4a910b31b2c4ddb09d1e3408e52aa8e09a14402f376070a44b1b85cb36d13', 'timestamp': '1733334040388'}
{'asks': [{'price': '0.99', 'size': '4217.01'}, {'price': '0.98', 'size': '505'}, {'price': '0.97', 'size': '511.03'}, {'price': '0.96', 'size': '300'}, {'price': '0.95', 'size': '657.12'}, {'price': '0.94', 'size': '300'}, {'price': '0.92', 'size': '20000.45'}, {'price': '0.91', 'size': '10406.3'}, {'price': '0.9', 'size': '4587.5'}, {'price': '0.89', 'size': '13017.18'}, {'price': '0.88', 'size': '200'}, {'price': '0.87', 'size': '3229'}, {'price': '0.86', 'size': '17.1'}, {'price': '0.85', 'size': '109.68'}, {'price': '0.84', 'size': '250'}, {'price': '0.83', 'size': '100'}, {'price': '0.82', 'size': '16029'}, {'price': '0.81', 'size': '45721.39'}, {'price': '0.8', 'size': '26531'}, {'price': '0.79', 'size': '7110'}, {'price': '0.78', 'size': '10350'}, {'price': '0.77', 'size': '67'}, {'price': '0.76', 'size': '200'}, {'price': '0.75', 'size': '18329.25'}, {'price': '0.74', 'size': '11370.7'}, {'price': '0.73', 'size': '5020.1'}, {'price': '0.72', 'size': '380.52'}, {'price': '0.71', 'size': '15073.2'}, {'price': '0.7', 'size': '5570.1'}, {'price': '0.69', 'size': '6088.6'}, {'price': '0.68', 'size': '6131.34'}, {'price': '0.67', 'size': '3010.1'}, {'price': '0.66', 'size': '510.1'}, {'price': '0.65', 'size': '1010.1'}, {'price': '0.64', 'size': '4230.1'}, {'price': '0.63', 'size': '210.1'}, {'price': '0.62', 'size': '2800.1'}, {'price': '0.61', 'size': '2511.06'}, {'price': '0.6', 'size': '817.85'}, {'price': '0.59', 'size': '1610'}, {'price': '0.58', 'size': '1388.1'}, {'price': '0.57', 'size': '640.1'}, {'price': '0.56', 'size': '1219.08'}], 'asset_id': '114416409796971863099144323163249651172534872992222856507897414949637892047507', 'bids': [{'price': '0.01', 'size': '2850.27'}, {'price': '0.02', 'size': '500'}, {'price': '0.03', 'size': '500'}, {'price': '0.04', 'size': '300'}, {'price': '0.05', 'size': '320'}, {'price': '0.06', 'size': '300'}, {'price': '0.08', 'size': '250'}, {'price': '0.09', 'size': '300'}, {'price': '0.1', 'size': '6205'}, {'price': '0.12', 'size': '200'}, {'price': '0.13', 'size': '426.92'}, {'price': '0.14', 'size': '15'}, {'price': '0.15', 'size': '110'}, {'price': '0.16', 'size': '4709.51'}, {'price': '0.18', 'size': '19.13'}, {'price': '0.19', 'size': '120'}, {'price': '0.2', 'size': '691.17'}, {'price': '0.24', 'size': '5027'}, {'price': '0.25', 'size': '86.66'}, {'price': '0.27', 'size': '215.25'}, {'price': '0.29', 'size': '1102.28'}, {'price': '0.31', 'size': '1130.65'}, {'price': '0.32', 'size': '200'}, {'price': '0.33', 'size': '620'}, {'price': '0.34', 'size': '4000'}, {'price': '0.35', 'size': '232'}, {'price': '0.39', 'size': '10.5'}, {'price': '0.4', 'size': '3135'}, {'price': '0.41', 'size': '20'}, {'price': '0.42', 'size': '3050'}, {'price': '0.43', 'size': '50'}, {'price': '0.44', 'size': '3660'}, {'price': '0.45', 'size': '478'}, {'price': '0.47', 'size': '2797.23'}, {'price': '0.48', 'size': '742.18'}, {'price': '0.49', 'size': '40'}, {'price': '0.5', 'size': '2115'}, {'price': '0.51', 'size': '2586.18'}, {'price': '0.52', 'size': '3295.92'}, {'price': '0.53', 'size': '1218.99'}, {'price': '0.54', 'size': '51.19'}, {'price': '0.55', 'size': '4186.26'}], 'event_type': 'book', 'hash': '2df1075152583bca694b06ad9536cee11f42f8be', 'market': '0x7aa4a910b31b2c4ddb09d1e3408e52aa8e09a14402f376070a44b1b85cb36d13', 'timestamp': '1733334040388'}
{'asset_id': '114416409796971863099144323163249651172534872992222856507897414949637892047507', 'changes': [{'price': '0.55', 'side': 'BUY', 'size': '4201.25'}], 'event_type': 'price_change', 'hash': '796badba10e1d2cc2bc659c0d35201e1f78d3f5e', 'market': '0x7aa4a910b31b2c4ddb09d1e3408e52aa8e09a14402f376070a44b1b85cb36d13', 'timestamp': '1733334044680'}
{'asset_id': '114416409796971863099144323163249651172534872992222856507897414949637892047507', 'changes': [{'price': '0.55', 'side': 'BUY', 'size': '4201.25'}], 'event_type': 'price_change', 'hash': '796badba10e1d2cc2bc659c0d35201e1f78d3f5e', 'market': '0x7aa4a910b31b2c4ddb09d1e3408e52aa8e09a14402f376070a44b1b85cb36d13', 'timestamp': '1733334044680'}
{'asset_id': '114416409796971863099144323163249651172534872992222856507897414949637892047507', 'changes': [{'price': '0.53', 'side': 'BUY', 'size': '1118.99'}], 'event_type': 'price_change', 'hash': '4e27865c6c80ab76210057e794a68767e6fb7de5', 'market': '0x7aa4a910b31b2c4ddb09d1e3408e52aa8e09a14402f376070a44b1b85cb36d13', 'timestamp': '1733334064532'}
{'asset_id': '114416409796971863099144323163249651172534872992222856507897414949637892047507', 'changes': [{'price': '0.53', 'side': 'BUY', 'size': '1118.99'}], 'event_type': 'price_change', 'hash': '4e27865c6c80ab76210057e794a68767e6fb7de5', 'market': '0x7aa4a910b31b2c4ddb09d1e3408e52aa8e09a14402f376070a44b1b85cb36d13', 'timestamp': '1733334064532'}
{'asset_id': '114416409796971863099144323163249651172534872992222856507897414949637892047507', 'changes': [{'price': '0.53', 'side': 'BUY', 'size': '1218.99'}], 'event_type': 'price_change', 'hash': 'a1b3b982c754f9758ff097caaf06ae54e8b72aca', 'market': '0x7aa4a910b31b2c4ddb09d1e3408e52aa8e09a14402f376070a44b1b85cb36d13', 'timestamp': '1733334066610'}
{'asset_id': '114416409796971863099144323163249651172534872992222856507897414949637892047507', 'changes': [{'price': '0.53', 'side': 'BUY', 'size': '1218.99'}], 'event_type': 'price_change', 'hash': 'a1b3b982c754f9758ff097caaf06ae54e8b72aca', 'market': '0x7aa4a910b31b2c4ddb09d1e3408e52aa8e09a14402f376070a44b1b85cb36d13', 'timestamp': '1733334066610'}
{'asset_id': '114416409796971863099144323163249651172534872992222856507897414949637892047507', 'changes': [{'price': '0.75', 'side': 'SELL', 'size': '13329.25'}], 'event_type': 'price_change', 'hash': '0650698e608ea6000804aadb2cd92d8ab45d5172', 'market': '0x7aa4a910b31b2c4ddb09d1e3408e52aa8e09a14402f376070a44b1b85cb36d13', 'timestamp': '1733334068010'}
{'asset_id': '114416409796971863099144323163249651172534872992222856507897414949637892047507', 'changes': [{'price': '0.75', 'side': 'SELL', 'size': '13329.25'}], 'event_type': 'price_change', 'hash': '0650698e608ea6000804aadb2cd92d8ab45d5172', 'market': '0x7aa4a910b31b2c4ddb09d1e3408e52aa8e09a14402f376070a44b1b85cb36d13', 'timestamp': '1733334068010'}
{'asks': [{'price': '0.99', 'size': '4217.01'}, {'price': '0.98', 'size': '505'}, {'price': '0.97', 'size': '511.03'}, {'price': '0.96', 'size': '300'}, {'price': '0.95', 'size': '657.12'}, {'price': '0.94', 'size': '300'}, {'price': '0.92', 'size': '20000.45'}, {'price': '0.91', 'size': '10406.3'}, {'price': '0.9', 'size': '4587.5'}, {'price': '0.89', 'size': '13017.18'}, {'price': '0.88', 'size': '200'}, {'price': '0.87', 'size': '3229'}, {'price': '0.86', 'size': '17.1'}, {'price': '0.85', 'size': '109.68'}, {'price': '0.84', 'size': '250'}, {'price': '0.83', 'size': '100'}, {'price': '0.82', 'size': '16029'}, {'price': '0.81', 'size': '45721.39'}, {'price': '0.8', 'size': '26531'}, {'price': '0.79', 'size': '7110'}, {'price': '0.78', 'size': '10350'}, {'price': '0.77', 'size': '67'}, {'price': '0.76', 'size': '200'}, {'price': '0.75', 'size': '13329.25'}, {'price': '0.74', 'size': '11370.7'}, {'price': '0.73', 'size': '5020.1'}, {'price': '0.72', 'size': '380.52'}, {'price': '0.71', 'size': '15073.2'}, {'price': '0.7', 'size': '5570.1'}, {'price': '0.69', 'size': '6088.6'}, {'price': '0.68', 'size': '6131.34'}, {'price': '0.67', 'size': '3010.1'}, {'price': '0.66', 'size': '510.1'}, {'price': '0.65', 'size': '1010.1'}, {'price': '0.64', 'size': '4230.1'}, {'price': '0.63', 'size': '210.1'}, {'price': '0.62', 'size': '2800.1'}, {'price': '0.61', 'size': '2511.06'}, {'price': '0.6', 'size': '817.85'}, {'price': '0.59', 'size': '1610'}, {'price': '0.58', 'size': '1388.1'}, {'price': '0.57', 'size': '640.1'}, {'price': '0.56', 'size': '1219.08'}], 'asset_id': '114416409796971863099144323163249651172534872992222856507897414949637892047507', 'bids': [{'price': '0.01', 'size': '2850.27'}, {'price': '0.02', 'size': '500'}, {'price': '0.03', 'size': '500'}, {'price': '0.04', 'size': '300'}, {'price': '0.05', 'size': '320'}, {'price': '0.06', 'size': '300'}, {'price': '0.08', 'size': '250'}, {'price': '0.09', 'size': '300'}, {'price': '0.1', 'size': '6205'}, {'price': '0.12', 'size': '200'}, {'price': '0.13', 'size': '426.92'}, {'price': '0.14', 'size': '15'}, {'price': '0.15', 'size': '110'}, {'price': '0.16', 'size': '4709.51'}, {'price': '0.18', 'size': '19.13'}, {'price': '0.19', 'size': '120'}, {'price': '0.2', 'size': '691.17'}, {'price': '0.24', 'size': '5027'}, {'price': '0.25', 'size': '86.66'}, {'price': '0.27', 'size': '215.25'}, {'price': '0.29', 'size': '1102.28'}, {'price': '0.31', 'size': '1130.65'}, {'price': '0.32', 'size': '200'}, {'price': '0.33', 'size': '620'}, {'price': '0.34', 'size': '4000'}, {'price': '0.35', 'size': '232'}, {'price': '0.39', 'size': '10.5'}, {'price': '0.4', 'size': '3135'}, {'price': '0.41', 'size': '20'}, {'price': '0.42', 'size': '3050'}, {'price': '0.43', 'size': '50'}, {'price': '0.44', 'size': '3660'}, {'price': '0.45', 'size': '478'}, {'price': '0.47', 'size': '2797.23'}, {'price': '0.48', 'size': '742.18'}, {'price': '0.49', 'size': '40'}, {'price': '0.5', 'size': '2115'}, {'price': '0.51', 'size': '2586.18'}, {'price': '0.52', 'size': '3295.92'}, {'price': '0.53', 'size': '1218.99'}, {'price': '0.54', 'size': '51.19'}, {'price': '0.55', 'size': '3954.02'}], 'event_type': 'book', 'hash': 'ece702e2a4aa64981a5d63988900fe536be5dd5b', 'market': '0x7aa4a910b31b2c4ddb09d1e3408e52aa8e09a14402f376070a44b1b85cb36d13', 'timestamp': '1733334069674'}
{'asset_id': '114416409796971863099144323163249651172534872992222856507897414949637892047507', 'event_type': 'last_trade_price', 'fee_rate_bps': '0', 'market': '0x7aa4a910b31b2c4ddb09d1e3408e52aa8e09a14402f376070a44b1b85cb36d13', 'price': '0.55', 'side': 'SELL', 'size': '247.23', 'timestamp': '1733334069696'}
{'asks': [{'price': '0.99', 'size': '4217.01'}, {'price': '0.98', 'size': '505'}, {'price': '0.97', 'size': '511.03'}, {'price': '0.96', 'size': '300'}, {'price': '0.95', 'size': '657.12'}, {'price': '0.94', 'size': '300'}, {'price': '0.92', 'size': '20000.45'}, {'price': '0.91', 'size': '10406.3'}, {'price': '0.9', 'size': '4587.5'}, {'price': '0.89', 'size': '13017.18'}, {'price': '0.88', 'size': '200'}, {'price': '0.87', 'size': '3229'}, {'price': '0.86', 'size': '17.1'}, {'price': '0.85', 'size': '109.68'}, {'price': '0.84', 'size': '250'}, {'price': '0.83', 'size': '100'}, {'price': '0.82', 'size': '16029'}, {'price': '0.81', 'size': '45721.39'}, {'price': '0.8', 'size': '26531'}, {'price': '0.79', 'size': '7110'}, {'price': '0.78', 'size': '10350'}, {'price': '0.77', 'size': '67'}, {'price': '0.76', 'size': '200'}, {'price': '0.75', 'size': '13329.25'}, {'price': '0.74', 'size': '11370.7'}, {'price': '0.73', 'size': '5020.1'}, {'price': '0.72', 'size': '380.52'}, {'price': '0.71', 'size': '15073.2'}, {'price': '0.7', 'size': '5570.1'}, {'price': '0.69', 'size': '6088.6'}, {'price': '0.68', 'size': '6131.34'}, {'price': '0.67', 'size': '3010.1'}, {'price': '0.66', 'size': '510.1'}, {'price': '0.65', 'size': '1010.1'}, {'price': '0.64', 'size': '4230.1'}, {'price': '0.63', 'size': '210.1'}, {'price': '0.62', 'size': '2800.1'}, {'price': '0.61', 'size': '2511.06'}, {'price': '0.6', 'size': '817.85'}, {'price': '0.59', 'size': '1610'}, {'price': '0.58', 'size': '1388.1'}, {'price': '0.57', 'size': '640.1'}, {'price': '0.56', 'size': '1219.08'}], 'asset_id': '114416409796971863099144323163249651172534872992222856507897414949637892047507', 'bids': [{'price': '0.01', 'size': '2850.27'}, {'price': '0.02', 'size': '500'}, {'price': '0.03', 'size': '500'}, {'price': '0.04', 'size': '300'}, {'price': '0.05', 'size': '320'}, {'price': '0.06', 'size': '300'}, {'price': '0.08', 'size': '250'}, {'price': '0.09', 'size': '300'}, {'price': '0.1', 'size': '6205'}, {'price': '0.12', 'size': '200'}, {'price': '0.13', 'size': '426.92'}, {'price': '0.14', 'size': '15'}, {'price': '0.15', 'size': '110'}, {'price': '0.16', 'size': '4709.51'}, {'price': '0.18', 'size': '19.13'}, {'price': '0.19', 'size': '120'}, {'price': '0.2', 'size': '691.17'}, {'price': '0.24', 'size': '5027'}, {'price': '0.25', 'size': '86.66'}, {'price': '0.27', 'size': '215.25'}, {'price': '0.29', 'size': '1102.28'}, {'price': '0.31', 'size': '1130.65'}, {'price': '0.32', 'size': '200'}, {'price': '0.33', 'size': '620'}, {'price': '0.34', 'size': '4000'}, {'price': '0.35', 'size': '232'}, {'price': '0.39', 'size': '10.5'}, {'price': '0.4', 'size': '3135'}, {'price': '0.41', 'size': '20'}, {'price': '0.42', 'size': '3050'}, {'price': '0.43', 'size': '50'}, {'price': '0.44', 'size': '3660'}, {'price': '0.45', 'size': '478'}, {'price': '0.47', 'size': '2797.23'}, {'price': '0.48', 'size': '742.18'}, {'price': '0.49', 'size': '40'}, {'price': '0.5', 'size': '2115'}, {'price': '0.51', 'size': '2586.18'}, {'price': '0.52', 'size': '3295.92'}, {'price': '0.53', 'size': '1218.99'}, {'price': '0.54', 'size': '51.19'}, {'price': '0.55', 'size': '3954.02'}], 'event_type': 'book', 'hash': 'ece702e2a4aa64981a5d63988900fe536be5dd5b', 'market': '0x7aa4a910b31b2c4ddb09d1e3408e52aa8e09a14402f376070a44b1b85cb36d13', 'timestamp': '1733334069674'}
{'asset_id': '114416409796971863099144323163249651172534872992222856507897414949637892047507', 'event_type': 'last_trade_price', 'fee_rate_bps': '0', 'market': '0x7aa4a910b31b2c4ddb09d1e3408e52aa8e09a14402f376070a44b1b85cb36d13', 'price': '0.55', 'side': 'SELL', 'size': '247.23', 'timestamp': '1733334069696'}
{'asset_id': '114416409796971863099144323163249651172534872992222856507897414949637892047507', 'changes': [{'price': '0.5', 'side': 'BUY', 'size': '115'}], 'event_type': 'price_change', 'hash': 'f3ff99a04f41c33df6ab3b04f1a667a2c4f33908', 'market': '0x7aa4a910b31b2c4ddb09d1e3408e52aa8e09a14402f376070a44b1b85cb36d13', 'timestamp': '1733334071010'}
{'asset_id': '114416409796971863099144323163249651172534872992222856507897414949637892047507', 'changes': [{'price': '0.5', 'side': 'BUY', 'size': '115'}], 'event_type': 'price_change', 'hash': 'f3ff99a04f41c33df6ab3b04f1a667a2c4f33908', 'market': '0x7aa4a910b31b2c4ddb09d1e3408e52aa8e09a14402f376070a44b1b85cb36d13', 'timestamp': '1733334071010'}
{'asset_id': '114416409796971863099144323163249651172534872992222856507897414949637892047507', 'changes': [{'price': '0.5', 'side': 'BUY', 'size': '2115'}, {'price': '0.78', 'side': 'SELL', 'size': '15350'}], 'event_type': 'price_change', 'hash': '5eae6718d7484f72cae43ba090ad544f8f2ea4a5', 'market': '0x7aa4a910b31b2c4ddb09d1e3408e52aa8e09a14402f376070a44b1b85cb36d13', 'timestamp': '1733334077975'}
{'asset_id': '114416409796971863099144323163249651172534872992222856507897414949637892047507', 'changes': [{'price': '0.5', 'side': 'BUY', 'size': '2115'}, {'price': '0.78', 'side': 'SELL', 'size': '15350'}], 'event_type': 'price_change', 'hash': '5eae6718d7484f72cae43ba090ad544f8f2ea4a5', 'market': '0x7aa4a910b31b2c4ddb09d1e3408e52aa8e09a14402f376070a44b1b85cb36d13', 'timestamp': '1733334077975'}
{'asset_id': '114416409796971863099144323163249651172534872992222856507897414949637892047507', 'changes': [{'price': '0.53', 'side': 'BUY', 'size': '1118.99'}], 'event_type': 'price_change', 'hash': '264f776d6d5dfe8c761acfc6472d98b93dd14e24', 'market': '0x7aa4a910b31b2c4ddb09d1e3408e52aa8e09a14402f376070a44b1b85cb36d13', 'timestamp': '1733334079495'}
{'asset_id': '114416409796971863099144323163249651172534872992222856507897414949637892047507', 'changes': [{'price': '0.53', 'side': 'BUY', 'size': '1118.99'}], 'event_type': 'price_change', 'hash': '264f776d6d5dfe8c761acfc6472d98b93dd14e24', 'market': '0x7aa4a910b31b2c4ddb09d1e3408e52aa8e09a14402f376070a44b1b85cb36d13', 'timestamp': '1733334079495'}
{'asset_id': '114416409796971863099144323163249651172534872992222856507897414949637892047507', 'changes': [{'price': '0.53', 'side': 'BUY', 'size': '1218.99'}], 'event_type': 'price_change', 'hash': 'adb0bcaaf406714a292a5c6a338bcda7a2ca0366', 'market': '0x7aa4a910b31b2c4ddb09d1e3408e52aa8e09a14402f376070a44b1b85cb36d13', 'timestamp': '1733334081444'}
{'asset_id': '114416409796971863099144323163249651172534872992222856507897414949637892047507', 'changes': [{'price': '0.53', 'side': 'BUY', 'size': '1218.99'}], 'event_type': 'price_change', 'hash': 'adb0bcaaf406714a292a5c6a338bcda7a2ca0366', 'market': '0x7aa4a910b31b2c4ddb09d1e3408e52aa8e09a14402f376070a44b1b85cb36d13', 'timestamp': '1733334081444'}
{'asset_id': '114416409796971863099144323163249651172534872992222856507897414949637892047507', 'changes': [{'price': '0.53', 'side': 'BUY', 'size': '1118.99'}], 'event_type': 'price_change', 'hash': 'dfbc8d2cc48135c57cba8ceb5db25ade965721bd', 'market': '0x7aa4a910b31b2c4ddb09d1e3408e52aa8e09a14402f376070a44b1b85cb36d13', 'timestamp': '1733334082083'}
{'asset_id': '114416409796971863099144323163249651172534872992222856507897414949637892047507', 'changes': [{'price': '0.53', 'side': 'BUY', 'size': '1118.99'}], 'event_type': 'price_change', 'hash': 'dfbc8d2cc48135c57cba8ceb5db25ade965721bd', 'market': '0x7aa4a910b31b2c4ddb09d1e3408e52aa8e09a14402f376070a44b1b85cb36d13', 'timestamp': '1733334082083'}
{'asset_id': '114416409796971863099144323163249651172534872992222856507897414949637892047507', 'changes': [{'price': '0.48', 'side': 'BUY', 'size': '242.18'}, {'price': '0.57', 'side': 'SELL', 'size': '140.1'}, {'price': '0.52', 'side': 'BUY', 'size': '2295.92'}], 'event_type': 'price_change', 'hash': 'aa1db96ad1710cb98f12a6dc76189bc688e7d71d', 'market': '0x7aa4a910b31b2c4ddb09d1e3408e52aa8e09a14402f376070a44b1b85cb36d13', 'timestamp': '1733334090328'}
{'asset_id': '114416409796971863099144323163249651172534872992222856507897414949637892047507', 'changes': [{'price': '0.48', 'side': 'BUY', 'size': '242.18'}, {'price': '0.57', 'side': 'SELL', 'size': '140.1'}, {'price': '0.52', 'side': 'BUY', 'size': '2295.92'}], 'event_type': 'price_change', 'hash': 'aa1db96ad1710cb98f12a6dc76189bc688e7d71d', 'market': '0x7aa4a910b31b2c4ddb09d1e3408e52aa8e09a14402f376070a44b1b85cb36d13', 'timestamp': '1733334090328'}
{'asset_id': '114416409796971863099144323163249651172534872992222856507897414949637892047507', 'changes': [{'price': '0.61', 'side': 'SELL', 'size': '511.06'}], 'event_type': 'price_change', 'hash': 'fc2b52e075326f176e9738517f7cd68512cf37c1', 'market': '0x7aa4a910b31b2c4ddb09d1e3408e52aa8e09a14402f376070a44b1b85cb36d13', 'timestamp': '1733334091010'}
{'asset_id': '114416409796971863099144323163249651172534872992222856507897414949637892047507', 'changes': [{'price': '0.61', 'side': 'SELL', 'size': '511.06'}], 'event_type': 'price_change', 'hash': 'fc2b52e075326f176e9738517f7cd68512cf37c1', 'market': '0x7aa4a910b31b2c4ddb09d1e3408e52aa8e09a14402f376070a44b1b85cb36d13', 'timestamp': '1733334091010'}
{'asset_id': '114416409796971863099144323163249651172534872992222856507897414949637892047507', 'changes': [{'price': '0.47', 'side': 'BUY', 'size': '3297.23'}], 'event_type': 'price_change', 'hash': '5db805ce2cc0971d66f08354125f77751be0e934', 'market': '0x7aa4a910b31b2c4ddb09d1e3408e52aa8e09a14402f376070a44b1b85cb36d13', 'timestamp': '1733334091369'}
{'asset_id': '114416409796971863099144323163249651172534872992222856507897414949637892047507', 'changes': [{'price': '0.47', 'side': 'BUY', 'size': '3297.23'}], 'event_type': 'price_change', 'hash': '5db805ce2cc0971d66f08354125f77751be0e934', 'market': '0x7aa4a910b31b2c4ddb09d1e3408e52aa8e09a14402f376070a44b1b85cb36d13', 'timestamp': '1733334091369'}
{'asset_id': '114416409796971863099144323163249651172534872992222856507897414949637892047507', 'changes': [{'price': '0.57', 'side': 'SELL', 'size': '640.1'}], 'event_type': 'price_change', 'hash': '5b745ea577891c1bf7405614b59127668a482bc4', 'market': '0x7aa4a910b31b2c4ddb09d1e3408e52aa8e09a14402f376070a44b1b85cb36d13', 'timestamp': '1733334091758'}
{'asset_id': '114416409796971863099144323163249651172534872992222856507897414949637892047507', 'changes': [{'price': '0.57', 'side': 'SELL', 'size': '640.1'}], 'event_type': 'price_change', 'hash': '5b745ea577891c1bf7405614b59127668a482bc4', 'market': '0x7aa4a910b31b2c4ddb09d1e3408e52aa8e09a14402f376070a44b1b85cb36d13', 'timestamp': '1733334091758'}
{'asset_id': '114416409796971863099144323163249651172534872992222856507897414949637892047507', 'changes': [{'price': '0.52', 'side': 'BUY', 'size': '3295.92'}], 'event_type': 'price_change', 'hash': '7b10ff10c1bb8a0766d31ce12ac51229a38b338c', 'market': '0x7aa4a910b31b2c4ddb09d1e3408e52aa8e09a14402f376070a44b1b85cb36d13', 'timestamp': '1733334092130'}
{'asset_id': '114416409796971863099144323163249651172534872992222856507897414949637892047507', 'changes': [{'price': '0.52', 'side': 'BUY', 'size': '3295.92'}], 'event_type': 'price_change', 'hash': '7b10ff10c1bb8a0766d31ce12ac51229a38b338c', 'market': '0x7aa4a910b31b2c4ddb09d1e3408e52aa8e09a14402f376070a44b1b85cb36d13', 'timestamp': '1733334092130'}
{'asset_id': '114416409796971863099144323163249651172534872992222856507897414949637892047507', 'changes': [{'price': '0.62', 'side': 'SELL', 'size': '300.1'}, {'price': '0.58', 'side': 'SELL', 'size': '188.1'}], 'event_type': 'price_change', 'hash': 'b972fcbdf47b2f0b635b306f9e4e78e28f6f844d', 'market': '0x7aa4a910b31b2c4ddb09d1e3408e52aa8e09a14402f376070a44b1b85cb36d13', 'timestamp': '1733334095609'}
{'asset_id': '114416409796971863099144323163249651172534872992222856507897414949637892047507', 'changes': [{'price': '0.62', 'side': 'SELL', 'size': '300.1'}, {'price': '0.58', 'side': 'SELL', 'size': '188.1'}], 'event_type': 'price_change', 'hash': 'b972fcbdf47b2f0b635b306f9e4e78e28f6f844d', 'market': '0x7aa4a910b31b2c4ddb09d1e3408e52aa8e09a14402f376070a44b1b85cb36d13', 'timestamp': '1733334095609'}
{'asset_id': '114416409796971863099144323163249651172534872992222856507897414949637892047507', 'changes': [{'price': '0.59', 'side': 'SELL', 'size': '3610'}, {'price': '0.6', 'side': 'SELL', 'size': '3317.85'}, {'price': '0.57', 'side': 'SELL', 'size': '1840.1'}], 'event_type': 'price_change', 'hash': '779c40c49589cc17ce27f09ad922c0409a589e3b', 'market': '0x7aa4a910b31b2c4ddb09d1e3408e52aa8e09a14402f376070a44b1b85cb36d13', 'timestamp': '1733334096136'}
{'asset_id': '114416409796971863099144323163249651172534872992222856507897414949637892047507', 'changes': [{'price': '0.59', 'side': 'SELL', 'size': '3610'}, {'price': '0.6', 'side': 'SELL', 'size': '3317.85'}, {'price': '0.57', 'side': 'SELL', 'size': '1840.1'}], 'event_type': 'price_change', 'hash': '779c40c49589cc17ce27f09ad922c0409a589e3b', 'market': '0x7aa4a910b31b2c4ddb09d1e3408e52aa8e09a14402f376070a44b1b85cb36d13', 'timestamp': '1733334096136'}
{'asset_id': '114416409796971863099144323163249651172534872992222856507897414949637892047507', 'changes': [{'price': '0.55', 'side': 'BUY', 'size': '3939.03'}], 'event_type': 'price_change', 'hash': 'c22cff8123ae125c371929476cfea108aede098f', 'market': '0x7aa4a910b31b2c4ddb09d1e3408e52aa8e09a14402f376070a44b1b85cb36d13', 'timestamp': '1733334096618'}
{'asset_id': '114416409796971863099144323163249651172534872992222856507897414949637892047507', 'changes': [{'price': '0.55', 'side': 'BUY', 'size': '3939.03'}], 'event_type': 'price_change', 'hash': 'c22cff8123ae125c371929476cfea108aede098f', 'market': '0x7aa4a910b31b2c4ddb09d1e3408e52aa8e09a14402f376070a44b1b85cb36d13', 'timestamp': '1733334096618'}
{'asks': [{'price': '0.99', 'size': '4217.01'}, {'price': '0.98', 'size': '505'}, {'price': '0.97', 'size': '511.03'}, {'price': '0.96', 'size': '300'}, {'price': '0.95', 'size': '657.12'}, {'price': '0.94', 'size': '300'}, {'price': '0.92', 'size': '20000.45'}, {'price': '0.91', 'size': '10406.3'}, {'price': '0.9', 'size': '4587.5'}, {'price': '0.89', 'size': '13017.18'}, {'price': '0.88', 'size': '200'}, {'price': '0.87', 'size': '3229'}, {'price': '0.86', 'size': '17.1'}, {'price': '0.85', 'size': '109.68'}, {'price': '0.84', 'size': '250'}, {'price': '0.83', 'size': '100'}, {'price': '0.82', 'size': '16029'}, {'price': '0.81', 'size': '45721.39'}, {'price': '0.8', 'size': '26531'}, {'price': '0.79', 'size': '7110'}, {'price': '0.78', 'size': '15350'}, {'price': '0.77', 'size': '67'}, {'price': '0.76', 'size': '200'}, {'price': '0.75', 'size': '13329.25'}, {'price': '0.74', 'size': '11370.7'}, {'price': '0.73', 'size': '5020.1'}, {'price': '0.72', 'size': '380.52'}, {'price': '0.71', 'size': '15073.2'}, {'price': '0.7', 'size': '5570.1'}, {'price': '0.69', 'size': '6088.6'}, {'price': '0.68', 'size': '6131.34'}, {'price': '0.67', 'size': '3010.1'}, {'price': '0.66', 'size': '510.1'}, {'price': '0.65', 'size': '1010.1'}, {'price': '0.64', 'size': '4230.1'}, {'price': '0.63', 'size': '210.1'}, {'price': '0.62', 'size': '300.1'}, {'price': '0.61', 'size': '511.06'}, {'price': '0.6', 'size': '3317.85'}, {'price': '0.59', 'size': '3610'}, {'price': '0.58', 'size': '188.1'}, {'price': '0.57', 'size': '1840.1'}, {'price': '0.56', 'size': '1219.06'}], 'asset_id': '114416409796971863099144323163249651172534872992222856507897414949637892047507', 'bids': [{'price': '0.01', 'size': '2850.27'}, {'price': '0.02', 'size': '500'}, {'price': '0.03', 'size': '500'}, {'price': '0.04', 'size': '300'}, {'price': '0.05', 'size': '320'}, {'price': '0.06', 'size': '300'}, {'price': '0.08', 'size': '250'}, {'price': '0.09', 'size': '300'}, {'price': '0.1', 'size': '6205'}, {'price': '0.12', 'size': '200'}, {'price': '0.13', 'size': '426.92'}, {'price': '0.14', 'size': '15'}, {'price': '0.15', 'size': '110'}, {'price': '0.16', 'size': '4709.51'}, {'price': '0.18', 'size': '19.13'}, {'price': '0.19', 'size': '120'}, {'price': '0.2', 'size': '691.17'}, {'price': '0.24', 'size': '5027'}, {'price': '0.25', 'size': '86.66'}, {'price': '0.27', 'size': '215.25'}, {'price': '0.29', 'size': '1102.28'}, {'price': '0.31', 'size': '1130.65'}, {'price': '0.32', 'size': '200'}, {'price': '0.33', 'size': '620'}, {'price': '0.34', 'size': '4000'}, {'price': '0.35', 'size': '232'}, {'price': '0.39', 'size': '10.5'}, {'price': '0.4', 'size': '3135'}, {'price': '0.41', 'size': '20'}, {'price': '0.42', 'size': '3050'}, {'price': '0.43', 'size': '50'}, {'price': '0.44', 'size': '3660'}, {'price': '0.45', 'size': '478'}, {'price': '0.47', 'size': '3297.23'}, {'price': '0.48', 'size': '242.18'}, {'price': '0.49', 'size': '40'}, {'price': '0.5', 'size': '2115'}, {'price': '0.51', 'size': '2586.18'}, {'price': '0.52', 'size': '3295.92'}, {'price': '0.53', 'size': '1118.99'}, {'price': '0.54', 'size': '51.19'}, {'price': '0.55', 'size': '3939.03'}], 'event_type': 'book', 'hash': '5b7960dae365904f5d4ab8daab82d6a1ea4c5f50', 'market': '0x7aa4a910b31b2c4ddb09d1e3408e52aa8e09a14402f376070a44b1b85cb36d13', 'timestamp': '1733334111698'}
{'asset_id': '114416409796971863099144323163249651172534872992222856507897414949637892047507', 'event_type': 'last_trade_price', 'fee_rate_bps': '0', 'market': '0x7aa4a910b31b2c4ddb09d1e3408e52aa8e09a14402f376070a44b1b85cb36d13', 'price': '0.56', 'side': 'BUY', 'size': '0.017856', 'timestamp': '1733334111718'}
{'asks': [{'price': '0.99', 'size': '4217.01'}, {'price': '0.98', 'size': '505'}, {'price': '0.97', 'size': '511.03'}, {'price': '0.96', 'size': '300'}, {'price': '0.95', 'size': '657.12'}, {'price': '0.94', 'size': '300'}, {'price': '0.92', 'size': '20000.45'}, {'price': '0.91', 'size': '10406.3'}, {'price': '0.9', 'size': '4587.5'}, {'price': '0.89', 'size': '13017.18'}, {'price': '0.88', 'size': '200'}, {'price': '0.87', 'size': '3229'}, {'price': '0.86', 'size': '17.1'}, {'price': '0.85', 'size': '109.68'}, {'price': '0.84', 'size': '250'}, {'price': '0.83', 'size': '100'}, {'price': '0.82', 'size': '16029'}, {'price': '0.81', 'size': '45721.39'}, {'price': '0.8', 'size': '26531'}, {'price': '0.79', 'size': '7110'}, {'price': '0.78', 'size': '15350'}, {'price': '0.77', 'size': '67'}, {'price': '0.76', 'size': '200'}, {'price': '0.75', 'size': '13329.25'}, {'price': '0.74', 'size': '11370.7'}, {'price': '0.73', 'size': '5020.1'}, {'price': '0.72', 'size': '380.52'}, {'price': '0.71', 'size': '15073.2'}, {'price': '0.7', 'size': '5570.1'}, {'price': '0.69', 'size': '6088.6'}, {'price': '0.68', 'size': '6131.34'}, {'price': '0.67', 'size': '3010.1'}, {'price': '0.66', 'size': '510.1'}, {'price': '0.65', 'size': '1010.1'}, {'price': '0.64', 'size': '4230.1'}, {'price': '0.63', 'size': '210.1'}, {'price': '0.62', 'size': '300.1'}, {'price': '0.61', 'size': '511.06'}, {'price': '0.6', 'size': '3317.85'}, {'price': '0.59', 'size': '3610'}, {'price': '0.58', 'size': '188.1'}, {'price': '0.57', 'size': '1840.1'}, {'price': '0.56', 'size': '1219.06'}], 'asset_id': '114416409796971863099144323163249651172534872992222856507897414949637892047507', 'bids': [{'price': '0.01', 'size': '2850.27'}, {'price': '0.02', 'size': '500'}, {'price': '0.03', 'size': '500'}, {'price': '0.04', 'size': '300'}, {'price': '0.05', 'size': '320'}, {'price': '0.06', 'size': '300'}, {'price': '0.08', 'size': '250'}, {'price': '0.09', 'size': '300'}, {'price': '0.1', 'size': '6205'}, {'price': '0.12', 'size': '200'}, {'price': '0.13', 'size': '426.92'}, {'price': '0.14', 'size': '15'}, {'price': '0.15', 'size': '110'}, {'price': '0.16', 'size': '4709.51'}, {'price': '0.18', 'size': '19.13'}, {'price': '0.19', 'size': '120'}, {'price': '0.2', 'size': '691.17'}, {'price': '0.24', 'size': '5027'}, {'price': '0.25', 'size': '86.66'}, {'price': '0.27', 'size': '215.25'}, {'price': '0.29', 'size': '1102.28'}, {'price': '0.31', 'size': '1130.65'}, {'price': '0.32', 'size': '200'}, {'price': '0.33', 'size': '620'}, {'price': '0.34', 'size': '4000'}, {'price': '0.35', 'size': '232'}, {'price': '0.39', 'size': '10.5'}, {'price': '0.4', 'size': '3135'}, {'price': '0.41', 'size': '20'}, {'price': '0.42', 'size': '3050'}, {'price': '0.43', 'size': '50'}, {'price': '0.44', 'size': '3660'}, {'price': '0.45', 'size': '478'}, {'price': '0.47', 'size': '3297.23'}, {'price': '0.48', 'size': '242.18'}, {'price': '0.49', 'size': '40'}, {'price': '0.5', 'size': '2115'}, {'price': '0.51', 'size': '2586.18'}, {'price': '0.52', 'size': '3295.92'}, {'price': '0.53', 'size': '1118.99'}, {'price': '0.54', 'size': '51.19'}, {'price': '0.55', 'size': '3939.03'}], 'event_type': 'book', 'hash': '5b7960dae365904f5d4ab8daab82d6a1ea4c5f50', 'market': '0x7aa4a910b31b2c4ddb09d1e3408e52aa8e09a14402f376070a44b1b85cb36d13', 'timestamp': '1733334111698'}
{'asset_id': '114416409796971863099144323163249651172534872992222856507897414949637892047507', 'event_type': 'last_trade_price', 'fee_rate_bps': '0', 'market': '0x7aa4a910b31b2c4ddb09d1e3408e52aa8e09a14402f376070a44b1b85cb36d13', 'price': '0.56', 'side': 'BUY', 'size': '0.017856', 'timestamp': '1733334111718'}
{'asks': [{'price': '0.99', 'size': '4217.01'}, {'price': '0.98', 'size': '505'}, {'price': '0.97', 'size': '511.03'}, {'price': '0.96', 'size': '300'}, {'price': '0.95', 'size': '657.12'}, {'price': '0.94', 'size': '300'}, {'price': '0.92', 'size': '20000.45'}, {'price': '0.91', 'size': '10406.3'}, {'price': '0.9', 'size': '4587.5'}, {'price': '0.89', 'size': '13017.18'}, {'price': '0.88', 'size': '200'}, {'price': '0.87', 'size': '3229'}, {'price': '0.86', 'size': '17.1'}, {'price': '0.85', 'size': '109.68'}, {'price': '0.84', 'size': '250'}, {'price': '0.83', 'size': '100'}, {'price': '0.82', 'size': '16029'}, {'price': '0.81', 'size': '45721.39'}, {'price': '0.8', 'size': '26531'}, {'price': '0.79', 'size': '7110'}, {'price': '0.78', 'size': '15350'}, {'price': '0.77', 'size': '67'}, {'price': '0.76', 'size': '200'}, {'price': '0.75', 'size': '13329.25'}, {'price': '0.74', 'size': '11370.7'}, {'price': '0.73', 'size': '5020.1'}, {'price': '0.72', 'size': '380.52'}, {'price': '0.71', 'size': '15073.2'}, {'price': '0.7', 'size': '5570.1'}, {'price': '0.69', 'size': '6088.6'}, {'price': '0.68', 'size': '6131.34'}, {'price': '0.67', 'size': '3010.1'}, {'price': '0.66', 'size': '510.1'}, {'price': '0.65', 'size': '1010.1'}, {'price': '0.64', 'size': '4230.1'}, {'price': '0.63', 'size': '210.1'}, {'price': '0.62', 'size': '300.1'}, {'price': '0.61', 'size': '511.06'}, {'price': '0.6', 'size': '3317.85'}, {'price': '0.59', 'size': '3610'}, {'price': '0.58', 'size': '188.1'}, {'price': '0.57', 'size': '1840.1'}, {'price': '0.56', 'size': '1219.06'}], 'asset_id': '114416409796971863099144323163249651172534872992222856507897414949637892047507', 'bids': [{'price': '0.01', 'size': '2850.27'}, {'price': '0.02', 'size': '500'}, {'price': '0.03', 'size': '500'}, {'price': '0.04', 'size': '300'}, {'price': '0.05', 'size': '320'}, {'price': '0.06', 'size': '300'}, {'price': '0.08', 'size': '250'}, {'price': '0.09', 'size': '300'}, {'price': '0.1', 'size': '6205'}, {'price': '0.12', 'size': '200'}, {'price': '0.13', 'size': '426.92'}, {'price': '0.14', 'size': '15'}, {'price': '0.15', 'size': '110'}, {'price': '0.16', 'size': '4709.51'}, {'price': '0.18', 'size': '19.13'}, {'price': '0.19', 'size': '120'}, {'price': '0.2', 'size': '691.17'}, {'price': '0.24', 'size': '5027'}, {'price': '0.25', 'size': '86.66'}, {'price': '0.27', 'size': '215.25'}, {'price': '0.29', 'size': '1102.28'}, {'price': '0.31', 'size': '1130.65'}, {'price': '0.32', 'size': '200'}, {'price': '0.33', 'size': '620'}, {'price': '0.34', 'size': '4000'}, {'price': '0.35', 'size': '232'}, {'price': '0.39', 'size': '10.5'}, {'price': '0.4', 'size': '3135'}, {'price': '0.41', 'size': '20'}, {'price': '0.42', 'size': '3050'}, {'price': '0.43', 'size': '50'}, {'price': '0.44', 'size': '3660'}, {'price': '0.45', 'size': '478'}, {'price': '0.47', 'size': '3297.23'}, {'price': '0.48', 'size': '242.18'}, {'price': '0.49', 'size': '40'}, {'price': '0.5', 'size': '2115'}, {'price': '0.51', 'size': '2586.18'}, {'price': '0.52', 'size': '3295.92'}, {'price': '0.53', 'size': '1118.99'}, {'price': '0.54', 'size': '51.19'}, {'price': '0.55', 'size': '3939'}], 'event_type': 'book', 'hash': 'c497dcbab5b93062b60c1a2bc170a2276ae2ada3', 'market': '0x7aa4a910b31b2c4ddb09d1e3408e52aa8e09a14402f376070a44b1b85cb36d13', 'timestamp': '1733334111864'}
{'asks': [{'price': '0.99', 'size': '4217.01'}, {'price': '0.98', 'size': '505'}, {'price': '0.97', 'size': '511.03'}, {'price': '0.96', 'size': '300'}, {'price': '0.95', 'size': '657.12'}, {'price': '0.94', 'size': '300'}, {'price': '0.92', 'size': '20000.45'}, {'price': '0.91', 'size': '10406.3'}, {'price': '0.9', 'size': '4587.5'}, {'price': '0.89', 'size': '13017.18'}, {'price': '0.88', 'size': '200'}, {'price': '0.87', 'size': '3229'}, {'price': '0.86', 'size': '17.1'}, {'price': '0.85', 'size': '109.68'}, {'price': '0.84', 'size': '250'}, {'price': '0.83', 'size': '100'}, {'price': '0.82', 'size': '16029'}, {'price': '0.81', 'size': '45721.39'}, {'price': '0.8', 'size': '26531'}, {'price': '0.79', 'size': '7110'}, {'price': '0.78', 'size': '15350'}, {'price': '0.77', 'size': '67'}, {'price': '0.76', 'size': '200'}, {'price': '0.75', 'size': '13329.25'}, {'price': '0.74', 'size': '11370.7'}, {'price': '0.73', 'size': '5020.1'}, {'price': '0.72', 'size': '380.52'}, {'price': '0.71', 'size': '15073.2'}, {'price': '0.7', 'size': '5570.1'}, {'price': '0.69', 'size': '6088.6'}, {'price': '0.68', 'size': '6131.34'}, {'price': '0.67', 'size': '3010.1'}, {'price': '0.66', 'size': '510.1'}, {'price': '0.65', 'size': '1010.1'}, {'price': '0.64', 'size': '4230.1'}, {'price': '0.63', 'size': '210.1'}, {'price': '0.62', 'size': '300.1'}, {'price': '0.61', 'size': '511.06'}, {'price': '0.6', 'size': '3317.85'}, {'price': '0.59', 'size': '3610'}, {'price': '0.58', 'size': '188.1'}, {'price': '0.57', 'size': '1840.1'}, {'price': '0.56', 'size': '1219.06'}], 'asset_id': '114416409796971863099144323163249651172534872992222856507897414949637892047507', 'bids': [{'price': '0.01', 'size': '2850.27'}, {'price': '0.02', 'size': '500'}, {'price': '0.03', 'size': '500'}, {'price': '0.04', 'size': '300'}, {'price': '0.05', 'size': '320'}, {'price': '0.06', 'size': '300'}, {'price': '0.08', 'size': '250'}, {'price': '0.09', 'size': '300'}, {'price': '0.1', 'size': '6205'}, {'price': '0.12', 'size': '200'}, {'price': '0.13', 'size': '426.92'}, {'price': '0.14', 'size': '15'}, {'price': '0.15', 'size': '110'}, {'price': '0.16', 'size': '4709.51'}, {'price': '0.18', 'size': '19.13'}, {'price': '0.19', 'size': '120'}, {'price': '0.2', 'size': '691.17'}, {'price': '0.24', 'size': '5027'}, {'price': '0.25', 'size': '86.66'}, {'price': '0.27', 'size': '215.25'}, {'price': '0.29', 'size': '1102.28'}, {'price': '0.31', 'size': '1130.65'}, {'price': '0.32', 'size': '200'}, {'price': '0.33', 'size': '620'}, {'price': '0.34', 'size': '4000'}, {'price': '0.35', 'size': '232'}, {'price': '0.39', 'size': '10.5'}, {'price': '0.4', 'size': '3135'}, {'price': '0.41', 'size': '20'}, {'price': '0.42', 'size': '3050'}, {'price': '0.43', 'size': '50'}, {'price': '0.44', 'size': '3660'}, {'price': '0.45', 'size': '478'}, {'price': '0.47', 'size': '3297.23'}, {'price': '0.48', 'size': '242.18'}, {'price': '0.49', 'size': '40'}, {'price': '0.5', 'size': '2115'}, {'price': '0.51', 'size': '2586.18'}, {'price': '0.52', 'size': '3295.92'}, {'price': '0.53', 'size': '1118.99'}, {'price': '0.54', 'size': '51.19'}, {'price': '0.55', 'size': '3939'}], 'event_type': 'book', 'hash': 'c497dcbab5b93062b60c1a2bc170a2276ae2ada3', 'market': '0x7aa4a910b31b2c4ddb09d1e3408e52aa8e09a14402f376070a44b1b85cb36d13', 'timestamp': '1733334111864'}
{'asks': [{'price': '0.99', 'size': '4217.01'}, {'price': '0.98', 'size': '505'}, {'price': '0.97', 'size': '511.03'}, {'price': '0.96', 'size': '300'}, {'price': '0.95', 'size': '657.12'}, {'price': '0.94', 'size': '300'}, {'price': '0.92', 'size': '20000.45'}, {'price': '0.91', 'size': '10406.3'}, {'price': '0.9', 'size': '4587.5'}, {'price': '0.89', 'size': '13017.18'}, {'price': '0.88', 'size': '200'}, {'price': '0.87', 'size': '3229'}, {'price': '0.86', 'size': '17.1'}, {'price': '0.85', 'size': '109.68'}, {'price': '0.84', 'size': '250'}, {'price': '0.83', 'size': '100'}, {'price': '0.82', 'size': '16029'}, {'price': '0.81', 'size': '45721.39'}, {'price': '0.8', 'size': '26531'}, {'price': '0.79', 'size': '7110'}, {'price': '0.78', 'size': '15350'}, {'price': '0.77', 'size': '67'}, {'price': '0.76', 'size': '200'}, {'price': '0.75', 'size': '13329.25'}, {'price': '0.74', 'size': '11370.7'}, {'price': '0.73', 'size': '5020.1'}, {'price': '0.72', 'size': '380.52'}, {'price': '0.71', 'size': '15073.2'}, {'price': '0.7', 'size': '5570.1'}, {'price': '0.69', 'size': '6088.6'}, {'price': '0.68', 'size': '6131.34'}, {'price': '0.67', 'size': '3010.1'}, {'price': '0.66', 'size': '510.1'}, {'price': '0.65', 'size': '1010.1'}, {'price': '0.64', 'size': '4230.1'}, {'price': '0.63', 'size': '210.1'}, {'price': '0.62', 'size': '300.1'}, {'price': '0.61', 'size': '511.06'}, {'price': '0.6', 'size': '3317.85'}, {'price': '0.59', 'size': '3610'}, {'price': '0.58', 'size': '188.1'}, {'price': '0.57', 'size': '1840.1'}, {'price': '0.56', 'size': '1219.06'}], 'asset_id': '114416409796971863099144323163249651172534872992222856507897414949637892047507', 'bids': [{'price': '0.01', 'size': '2850.27'}, {'price': '0.02', 'size': '500'}, {'price': '0.03', 'size': '500'}, {'price': '0.04', 'size': '300'}, {'price': '0.05', 'size': '320'}, {'price': '0.06', 'size': '300'}, {'price': '0.08', 'size': '250'}, {'price': '0.09', 'size': '300'}, {'price': '0.1', 'size': '6205'}, {'price': '0.12', 'size': '200'}, {'price': '0.13', 'size': '426.92'}, {'price': '0.14', 'size': '15'}, {'price': '0.15', 'size': '110'}, {'price': '0.16', 'size': '4709.51'}, {'price': '0.18', 'size': '19.13'}, {'price': '0.19', 'size': '120'}, {'price': '0.2', 'size': '691.17'}, {'price': '0.24', 'size': '5027'}, {'price': '0.25', 'size': '86.66'}, {'price': '0.27', 'size': '215.25'}, {'price': '0.29', 'size': '1102.28'}, {'price': '0.31', 'size': '1130.65'}, {'price': '0.32', 'size': '200'}, {'price': '0.33', 'size': '620'}, {'price': '0.34', 'size': '4000'}, {'price': '0.35', 'size': '232'}, {'price': '0.39', 'size': '10.5'}, {'price': '0.4', 'size': '3135'}, {'price': '0.41', 'size': '20'}, {'price': '0.42', 'size': '3050'}, {'price': '0.43', 'size': '50'}, {'price': '0.44', 'size': '3660'}, {'price': '0.45', 'size': '478'}, {'price': '0.47', 'size': '3297.23'}, {'price': '0.48', 'size': '242.18'}, {'price': '0.49', 'size': '40'}, {'price': '0.5', 'size': '2115'}, {'price': '0.51', 'size': '2586.18'}, {'price': '0.52', 'size': '3295.92'}, {'price': '0.53', 'size': '1118.99'}, {'price': '0.54', 'size': '51.19'}, {'price': '0.55', 'size': '3932.77'}], 'event_type': 'book', 'hash': '699f0a991370539e73d37afa7fe2210f10f17db6', 'market': '0x7aa4a910b31b2c4ddb09d1e3408e52aa8e09a14402f376070a44b1b85cb36d13', 'timestamp': '1733334119434'}
{'asks': [{'price': '0.99', 'size': '4217.01'}, {'price': '0.98', 'size': '505'}, {'price': '0.97', 'size': '511.03'}, {'price': '0.96', 'size': '300'}, {'price': '0.95', 'size': '657.12'}, {'price': '0.94', 'size': '300'}, {'price': '0.92', 'size': '20000.45'}, {'price': '0.91', 'size': '10406.3'}, {'price': '0.9', 'size': '4587.5'}, {'price': '0.89', 'size': '13017.18'}, {'price': '0.88', 'size': '200'}, {'price': '0.87', 'size': '3229'}, {'price': '0.86', 'size': '17.1'}, {'price': '0.85', 'size': '109.68'}, {'price': '0.84', 'size': '250'}, {'price': '0.83', 'size': '100'}, {'price': '0.82', 'size': '16029'}, {'price': '0.81', 'size': '45721.39'}, {'price': '0.8', 'size': '26531'}, {'price': '0.79', 'size': '7110'}, {'price': '0.78', 'size': '15350'}, {'price': '0.77', 'size': '67'}, {'price': '0.76', 'size': '200'}, {'price': '0.75', 'size': '13329.25'}, {'price': '0.74', 'size': '11370.7'}, {'price': '0.73', 'size': '5020.1'}, {'price': '0.72', 'size': '380.52'}, {'price': '0.71', 'size': '15073.2'}, {'price': '0.7', 'size': '5570.1'}, {'price': '0.69', 'size': '6088.6'}, {'price': '0.68', 'size': '6131.34'}, {'price': '0.67', 'size': '3010.1'}, {'price': '0.66', 'size': '510.1'}, {'price': '0.65', 'size': '1010.1'}, {'price': '0.64', 'size': '4230.1'}, {'price': '0.63', 'size': '210.1'}, {'price': '0.62', 'size': '300.1'}, {'price': '0.61', 'size': '511.06'}, {'price': '0.6', 'size': '3317.85'}, {'price': '0.59', 'size': '3610'}, {'price': '0.58', 'size': '188.1'}, {'price': '0.57', 'size': '1840.1'}, {'price': '0.56', 'size': '1219.06'}], 'asset_id': '114416409796971863099144323163249651172534872992222856507897414949637892047507', 'bids': [{'price': '0.01', 'size': '2850.27'}, {'price': '0.02', 'size': '500'}, {'price': '0.03', 'size': '500'}, {'price': '0.04', 'size': '300'}, {'price': '0.05', 'size': '320'}, {'price': '0.06', 'size': '300'}, {'price': '0.08', 'size': '250'}, {'price': '0.09', 'size': '300'}, {'price': '0.1', 'size': '6205'}, {'price': '0.12', 'size': '200'}, {'price': '0.13', 'size': '426.92'}, {'price': '0.14', 'size': '15'}, {'price': '0.15', 'size': '110'}, {'price': '0.16', 'size': '4709.51'}, {'price': '0.18', 'size': '19.13'}, {'price': '0.19', 'size': '120'}, {'price': '0.2', 'size': '691.17'}, {'price': '0.24', 'size': '5027'}, {'price': '0.25', 'size': '86.66'}, {'price': '0.27', 'size': '215.25'}, {'price': '0.29', 'size': '1102.28'}, {'price': '0.31', 'size': '1130.65'}, {'price': '0.32', 'size': '200'}, {'price': '0.33', 'size': '620'}, {'price': '0.34', 'size': '4000'}, {'price': '0.35', 'size': '232'}, {'price': '0.39', 'size': '10.5'}, {'price': '0.4', 'size': '3135'}, {'price': '0.41', 'size': '20'}, {'price': '0.42', 'size': '3050'}, {'price': '0.43', 'size': '50'}, {'price': '0.44', 'size': '3660'}, {'price': '0.45', 'size': '478'}, {'price': '0.47', 'size': '3297.23'}, {'price': '0.48', 'size': '242.18'}, {'price': '0.49', 'size': '40'}, {'price': '0.5', 'size': '2115'}, {'price': '0.51', 'size': '2586.18'}, {'price': '0.52', 'size': '3295.92'}, {'price': '0.53', 'size': '1118.99'}, {'price': '0.54', 'size': '51.19'}, {'price': '0.55', 'size': '3932.77'}], 'event_type': 'book', 'hash': '699f0a991370539e73d37afa7fe2210f10f17db6', 'market': '0x7aa4a910b31b2c4ddb09d1e3408e52aa8e09a14402f376070a44b1b85cb36d13', 'timestamp': '1733334119434'}
{'asset_id': '114416409796971863099144323163249651172534872992222856507897414949637892047507', 'changes': [{'price': '0.52', 'side': 'BUY', 'size': '2095.92'}], 'event_type': 'price_change', 'hash': '76694aa1ee6d8d6e30e4f9abf9e87a55f2b16817', 'market': '0x7aa4a910b31b2c4ddb09d1e3408e52aa8e09a14402f376070a44b1b85cb36d13', 'timestamp': '1733334121011'}
{'asset_id': '114416409796971863099144323163249651172534872992222856507897414949637892047507', 'changes': [{'price': '0.52', 'side': 'BUY', 'size': '2095.92'}], 'event_type': 'price_change', 'hash': '76694aa1ee6d8d6e30e4f9abf9e87a55f2b16817', 'market': '0x7aa4a910b31b2c4ddb09d1e3408e52aa8e09a14402f376070a44b1b85cb36d13', 'timestamp': '1733334121011'}
{'asset_id': '114416409796971863099144323163249651172534872992222856507897414949637892047507', 'changes': [{'price': '0.59', 'side': 'SELL', 'size': '2110'}], 'event_type': 'price_change', 'hash': 'ca27908e37b88b370673498027c67c279d836c15', 'market': '0x7aa4a910b31b2c4ddb09d1e3408e52aa8e09a14402f376070a44b1b85cb36d13', 'timestamp': '1733334123012'}
{'asset_id': '114416409796971863099144323163249651172534872992222856507897414949637892047507', 'changes': [{'price': '0.59', 'side': 'SELL', 'size': '2110'}], 'event_type': 'price_change', 'hash': 'ca27908e37b88b370673498027c67c279d836c15', 'market': '0x7aa4a910b31b2c4ddb09d1e3408e52aa8e09a14402f376070a44b1b85cb36d13', 'timestamp': '1733334123012'}
{'asset_id': '114416409796971863099144323163249651172534872992222856507897414949637892047507', 'changes': [{'price': '0.53', 'side': 'BUY', 'size': '1218.99'}], 'event_type': 'price_change', 'hash': '373c2fefaedf2a07c7fa615cfdd1a496cc519425', 'market': '0x7aa4a910b31b2c4ddb09d1e3408e52aa8e09a14402f376070a44b1b85cb36d13', 'timestamp': '1733334125820'}
{'asset_id': '114416409796971863099144323163249651172534872992222856507897414949637892047507', 'changes': [{'price': '0.53', 'side': 'BUY', 'size': '1218.99'}], 'event_type': 'price_change', 'hash': '373c2fefaedf2a07c7fa615cfdd1a496cc519425', 'market': '0x7aa4a910b31b2c4ddb09d1e3408e52aa8e09a14402f376070a44b1b85cb36d13', 'timestamp': '1733334125820'}
{'asset_id': '114416409796971863099144323163249651172534872992222856507897414949637892047507', 'changes': [{'price': '0.6', 'side': 'SELL', 'size': '3067.85'}, {'price': '0.52', 'side': 'BUY', 'size': '1885.92'}], 'event_type': 'price_change', 'hash': '8e0520ea86e5db0064bb085de71b1b9261b6e29f', 'market': '0x7aa4a910b31b2c4ddb09d1e3408e52aa8e09a14402f376070a44b1b85cb36d13', 'timestamp': '1733334126809'}
{'asset_id': '114416409796971863099144323163249651172534872992222856507897414949637892047507', 'changes': [{'price': '0.6', 'side': 'SELL', 'size': '3067.85'}, {'price': '0.52', 'side': 'BUY', 'size': '1885.92'}], 'event_type': 'price_change', 'hash': '8e0520ea86e5db0064bb085de71b1b9261b6e29f', 'market': '0x7aa4a910b31b2c4ddb09d1e3408e52aa8e09a14402f376070a44b1b85cb36d13', 'timestamp': '1733334126809'}
{'asset_id': '114416409796971863099144323163249651172534872992222856507897414949637892047507', 'changes': [{'price': '0.51', 'side': 'BUY', 'size': '2826.18'}, {'price': '0.6', 'side': 'SELL', 'size': '3347.85'}], 'event_type': 'price_change', 'hash': '0b94b7999e6c55934be9ab93eece1aed4f1ea954', 'market': '0x7aa4a910b31b2c4ddb09d1e3408e52aa8e09a14402f376070a44b1b85cb36d13', 'timestamp': '1733334127121'}
{'asset_id': '114416409796971863099144323163249651172534872992222856507897414949637892047507', 'changes': [{'price': '0.51', 'side': 'BUY', 'size': '2826.18'}, {'price': '0.6', 'side': 'SELL', 'size': '3347.85'}], 'event_type': 'price_change', 'hash': '0b94b7999e6c55934be9ab93eece1aed4f1ea954', 'market': '0x7aa4a910b31b2c4ddb09d1e3408e52aa8e09a14402f376070a44b1b85cb36d13', 'timestamp': '1733334127121'}
{'asks': [{'price': '0.99', 'size': '4217.01'}, {'price': '0.98', 'size': '505'}, {'price': '0.97', 'size': '511.03'}, {'price': '0.96', 'size': '300'}, {'price': '0.95', 'size': '657.12'}, {'price': '0.94', 'size': '300'}, {'price': '0.92', 'size': '20000.45'}, {'price': '0.91', 'size': '10406.3'}, {'price': '0.9', 'size': '4587.5'}, {'price': '0.89', 'size': '13017.18'}, {'price': '0.88', 'size': '200'}, {'price': '0.87', 'size': '3229'}, {'price': '0.86', 'size': '17.1'}, {'price': '0.85', 'size': '109.68'}, {'price': '0.84', 'size': '250'}, {'price': '0.83', 'size': '100'}, {'price': '0.82', 'size': '16029'}, {'price': '0.81', 'size': '45721.39'}, {'price': '0.8', 'size': '26531'}, {'price': '0.79', 'size': '7110'}, {'price': '0.78', 'size': '15350'}, {'price': '0.77', 'size': '67'}, {'price': '0.76', 'size': '200'}, {'price': '0.75', 'size': '13329.25'}, {'price': '0.74', 'size': '11370.7'}, {'price': '0.73', 'size': '5020.1'}, {'price': '0.72', 'size': '380.52'}, {'price': '0.71', 'size': '15073.2'}, {'price': '0.7', 'size': '5570.1'}, {'price': '0.69', 'size': '6088.6'}, {'price': '0.68', 'size': '6131.34'}, {'price': '0.67', 'size': '3010.1'}, {'price': '0.66', 'size': '510.1'}, {'price': '0.65', 'size': '1010.1'}, {'price': '0.64', 'size': '4230.1'}, {'price': '0.63', 'size': '210.1'}, {'price': '0.62', 'size': '300.1'}, {'price': '0.61', 'size': '511.06'}, {'price': '0.6', 'size': '3347.85'}, {'price': '0.59', 'size': '3610'}, {'price': '0.58', 'size': '188.1'}, {'price': '0.57', 'size': '1840.1'}], 'asset_id': '114416409796971863099144323163249651172534872992222856507897414949637892047507', 'bids': [{'price': '0.01', 'size': '2850.27'}, {'price': '0.02', 'size': '500'}, {'price': '0.03', 'size': '500'}, {'price': '0.04', 'size': '300'}, {'price': '0.05', 'size': '320'}, {'price': '0.06', 'size': '300'}, {'price': '0.08', 'size': '250'}, {'price': '0.09', 'size': '300'}, {'price': '0.1', 'size': '6205'}, {'price': '0.12', 'size': '200'}, {'price': '0.13', 'size': '426.92'}, {'price': '0.14', 'size': '15'}, {'price': '0.15', 'size': '110'}, {'price': '0.16', 'size': '4709.51'}, {'price': '0.18', 'size': '19.13'}, {'price': '0.19', 'size': '120'}, {'price': '0.2', 'size': '691.17'}, {'price': '0.24', 'size': '5027'}, {'price': '0.25', 'size': '86.66'}, {'price': '0.27', 'size': '215.25'}, {'price': '0.29', 'size': '1102.28'}, {'price': '0.31', 'size': '1130.65'}, {'price': '0.32', 'size': '200'}, {'price': '0.33', 'size': '620'}, {'price': '0.34', 'size': '4000'}, {'price': '0.35', 'size': '232'}, {'price': '0.39', 'size': '10.5'}, {'price': '0.4', 'size': '3135'}, {'price': '0.41', 'size': '20'}, {'price': '0.42', 'size': '3050'}, {'price': '0.43', 'size': '50'}, {'price': '0.44', 'size': '3660'}, {'price': '0.45', 'size': '478'}, {'price': '0.47', 'size': '3297.23'}, {'price': '0.48', 'size': '242.18'}, {'price': '0.49', 'size': '40'}, {'price': '0.5', 'size': '2115'}, {'price': '0.51', 'size': '2826.18'}, {'price': '0.52', 'size': '1885.92'}, {'price': '0.53', 'size': '1218.99'}, {'price': '0.54', 'size': '51.19'}, {'price': '0.55', 'size': '3932.77'}, {'price': '0.56', 'size': '3780.94'}], 'event_type': 'book', 'hash': 'dfc9ceda582ebb42e92f2401b03a1e74dbed79f4', 'market': '0x7aa4a910b31b2c4ddb09d1e3408e52aa8e09a14402f376070a44b1b85cb36d13', 'timestamp': '1733334132771'}
{'asset_id': '114416409796971863099144323163249651172534872992222856507897414949637892047507', 'event_type': 'last_trade_price', 'fee_rate_bps': '0', 'market': '0x7aa4a910b31b2c4ddb09d1e3408e52aa8e09a14402f376070a44b1b85cb36d13', 'price': '0.56', 'side': 'BUY', 'size': '1219.06', 'timestamp': '1733334132773'}
{'asset_id': '114416409796971863099144323163249651172534872992222856507897414949637892047507', 'changes': [{'price': '0.56', 'side': 'BUY', 'size': '3780.94'}, {'price': '0.59', 'side': 'SELL', 'size': '3610'}, {'price': '0.51', 'side': 'BUY', 'size': '4026.18'}], 'event_type': 'price_change', 'hash': 'de0ab895933080d2d79e7c7773605f45ce56c42f', 'market': '0x7aa4a910b31b2c4ddb09d1e3408e52aa8e09a14402f376070a44b1b85cb36d13', 'timestamp': '1733334132787'}
{'asks': [{'price': '0.99', 'size': '4217.01'}, {'price': '0.98', 'size': '505'}, {'price': '0.97', 'size': '511.03'}, {'price': '0.96', 'size': '300'}, {'price': '0.95', 'size': '657.12'}, {'price': '0.94', 'size': '300'}, {'price': '0.92', 'size': '20000.45'}, {'price': '0.91', 'size': '10406.3'}, {'price': '0.9', 'size': '4587.5'}, {'price': '0.89', 'size': '13017.18'}, {'price': '0.88', 'size': '200'}, {'price': '0.87', 'size': '3229'}, {'price': '0.86', 'size': '17.1'}, {'price': '0.85', 'size': '109.68'}, {'price': '0.84', 'size': '250'}, {'price': '0.83', 'size': '100'}, {'price': '0.82', 'size': '16029'}, {'price': '0.81', 'size': '45721.39'}, {'price': '0.8', 'size': '26531'}, {'price': '0.79', 'size': '7110'}, {'price': '0.78', 'size': '15350'}, {'price': '0.77', 'size': '67'}, {'price': '0.76', 'size': '200'}, {'price': '0.75', 'size': '13329.25'}, {'price': '0.74', 'size': '11370.7'}, {'price': '0.73', 'size': '5020.1'}, {'price': '0.72', 'size': '380.52'}, {'price': '0.71', 'size': '15073.2'}, {'price': '0.7', 'size': '5570.1'}, {'price': '0.69', 'size': '6088.6'}, {'price': '0.68', 'size': '6131.34'}, {'price': '0.67', 'size': '3010.1'}, {'price': '0.66', 'size': '510.1'}, {'price': '0.65', 'size': '1010.1'}, {'price': '0.64', 'size': '4230.1'}, {'price': '0.63', 'size': '210.1'}, {'price': '0.62', 'size': '300.1'}, {'price': '0.61', 'size': '511.06'}, {'price': '0.6', 'size': '3347.85'}, {'price': '0.59', 'size': '3610'}, {'price': '0.58', 'size': '188.1'}, {'price': '0.57', 'size': '1840.1'}], 'asset_id': '114416409796971863099144323163249651172534872992222856507897414949637892047507', 'bids': [{'price': '0.01', 'size': '2850.27'}, {'price': '0.02', 'size': '500'}, {'price': '0.03', 'size': '500'}, {'price': '0.04', 'size': '300'}, {'price': '0.05', 'size': '320'}, {'price': '0.06', 'size': '300'}, {'price': '0.08', 'size': '250'}, {'price': '0.09', 'size': '300'}, {'price': '0.1', 'size': '6205'}, {'price': '0.12', 'size': '200'}, {'price': '0.13', 'size': '426.92'}, {'price': '0.14', 'size': '15'}, {'price': '0.15', 'size': '110'}, {'price': '0.16', 'size': '4709.51'}, {'price': '0.18', 'size': '19.13'}, {'price': '0.19', 'size': '120'}, {'price': '0.2', 'size': '691.17'}, {'price': '0.24', 'size': '5027'}, {'price': '0.25', 'size': '86.66'}, {'price': '0.27', 'size': '215.25'}, {'price': '0.29', 'size': '1102.28'}, {'price': '0.31', 'size': '1130.65'}, {'price': '0.32', 'size': '200'}, {'price': '0.33', 'size': '620'}, {'price': '0.34', 'size': '4000'}, {'price': '0.35', 'size': '232'}, {'price': '0.39', 'size': '10.5'}, {'price': '0.4', 'size': '3135'}, {'price': '0.41', 'size': '20'}, {'price': '0.42', 'size': '3050'}, {'price': '0.43', 'size': '50'}, {'price': '0.44', 'size': '3660'}, {'price': '0.45', 'size': '478'}, {'price': '0.47', 'size': '3297.23'}, {'price': '0.48', 'size': '242.18'}, {'price': '0.49', 'size': '40'}, {'price': '0.5', 'size': '2115'}, {'price': '0.51', 'size': '2826.18'}, {'price': '0.52', 'size': '1885.92'}, {'price': '0.53', 'size': '1218.99'}, {'price': '0.54', 'size': '51.19'}, {'price': '0.55', 'size': '3932.77'}, {'price': '0.56', 'size': '3780.94'}], 'event_type': 'book', 'hash': 'dfc9ceda582ebb42e92f2401b03a1e74dbed79f4', 'market': '0x7aa4a910b31b2c4ddb09d1e3408e52aa8e09a14402f376070a44b1b85cb36d13', 'timestamp': '1733334132771'}
{'asset_id': '114416409796971863099144323163249651172534872992222856507897414949637892047507', 'event_type': 'last_trade_price', 'fee_rate_bps': '0', 'market': '0x7aa4a910b31b2c4ddb09d1e3408e52aa8e09a14402f376070a44b1b85cb36d13', 'price': '0.56', 'side': 'BUY', 'size': '1219.06', 'timestamp': '1733334132773'}
{'asset_id': '114416409796971863099144323163249651172534872992222856507897414949637892047507', 'changes': [{'price': '0.56', 'side': 'BUY', 'size': '3780.94'}, {'price': '0.59', 'side': 'SELL', 'size': '3610'}, {'price': '0.51', 'side': 'BUY', 'size': '4026.18'}], 'event_type': 'price_change', 'hash': 'de0ab895933080d2d79e7c7773605f45ce56c42f', 'market': '0x7aa4a910b31b2c4ddb09d1e3408e52aa8e09a14402f376070a44b1b85cb36d13', 'timestamp': '1733334132787'}
{'asks': [{'price': '0.99', 'size': '4217.01'}, {'price': '0.98', 'size': '505'}, {'price': '0.97', 'size': '511.03'}, {'price': '0.96', 'size': '300'}, {'price': '0.95', 'size': '657.12'}, {'price': '0.94', 'size': '300'}, {'price': '0.92', 'size': '20000.45'}, {'price': '0.91', 'size': '10406.3'}, {'price': '0.9', 'size': '4587.5'}, {'price': '0.89', 'size': '13017.18'}, {'price': '0.88', 'size': '200'}, {'price': '0.87', 'size': '3229'}, {'price': '0.86', 'size': '17.1'}, {'price': '0.85', 'size': '109.68'}, {'price': '0.84', 'size': '250'}, {'price': '0.83', 'size': '100'}, {'price': '0.82', 'size': '16029'}, {'price': '0.81', 'size': '45721.39'}, {'price': '0.8', 'size': '26531'}, {'price': '0.79', 'size': '7110'}, {'price': '0.78', 'size': '15350'}, {'price': '0.77', 'size': '67'}, {'price': '0.76', 'size': '200'}, {'price': '0.75', 'size': '13329.25'}, {'price': '0.74', 'size': '11370.7'}, {'price': '0.73', 'size': '5020.1'}, {'price': '0.72', 'size': '380.52'}, {'price': '0.71', 'size': '15073.2'}, {'price': '0.7', 'size': '5570.1'}, {'price': '0.69', 'size': '6088.6'}, {'price': '0.68', 'size': '6131.34'}, {'price': '0.67', 'size': '3010.1'}, {'price': '0.66', 'size': '510.1'}, {'price': '0.65', 'size': '1010.1'}, {'price': '0.64', 'size': '4230.1'}, {'price': '0.63', 'size': '210.1'}, {'price': '0.62', 'size': '300.1'}, {'price': '0.61', 'size': '511.06'}, {'price': '0.6', 'size': '3347.85'}, {'price': '0.59', 'size': '3610'}, {'price': '0.58', 'size': '188.1'}, {'price': '0.57', 'size': '1840.1'}], 'asset_id': '114416409796971863099144323163249651172534872992222856507897414949637892047507', 'bids': [{'price': '0.01', 'size': '2850.27'}, {'price': '0.02', 'size': '500'}, {'price': '0.03', 'size': '500'}, {'price': '0.04', 'size': '300'}, {'price': '0.05', 'size': '320'}, {'price': '0.06', 'size': '300'}, {'price': '0.08', 'size': '250'}, {'price': '0.09', 'size': '300'}, {'price': '0.1', 'size': '6205'}, {'price': '0.12', 'size': '200'}, {'price': '0.13', 'size': '426.92'}, {'price': '0.14', 'size': '15'}, {'price': '0.15', 'size': '110'}, {'price': '0.16', 'size': '4709.51'}, {'price': '0.18', 'size': '19.13'}, {'price': '0.19', 'size': '120'}, {'price': '0.2', 'size': '691.17'}, {'price': '0.24', 'size': '5027'}, {'price': '0.25', 'size': '86.66'}, {'price': '0.27', 'size': '215.25'}, {'price': '0.29', 'size': '1102.28'}, {'price': '0.31', 'size': '1130.65'}, {'price': '0.32', 'size': '200'}, {'price': '0.33', 'size': '620'}, {'price': '0.34', 'size': '4000'}, {'price': '0.35', 'size': '232'}, {'price': '0.39', 'size': '10.5'}, {'price': '0.4', 'size': '3135'}, {'price': '0.41', 'size': '20'}, {'price': '0.42', 'size': '3050'}, {'price': '0.43', 'size': '50'}, {'price': '0.44', 'size': '3660'}, {'price': '0.45', 'size': '478'}, {'price': '0.47', 'size': '3297.23'}, {'price': '0.48', 'size': '242.18'}, {'price': '0.49', 'size': '40'}, {'price': '0.5', 'size': '2115'}, {'price': '0.51', 'size': '4026.18'}, {'price': '0.52', 'size': '1885.92'}, {'price': '0.53', 'size': '1218.99'}, {'price': '0.54', 'size': '51.19'}, {'price': '0.55', 'size': '3932.77'}, {'price': '0.56', 'size': '3750.94'}], 'event_type': 'book', 'hash': 'b0298713962d62c72c367dfb8768e6ab223c44dc', 'market': '0x7aa4a910b31b2c4ddb09d1e3408e52aa8e09a14402f376070a44b1b85cb36d13', 'timestamp': '1733334133268'}
{'asks': [{'price': '0.99', 'size': '4217.01'}, {'price': '0.98', 'size': '505'}, {'price': '0.97', 'size': '511.03'}, {'price': '0.96', 'size': '300'}, {'price': '0.95', 'size': '657.12'}, {'price': '0.94', 'size': '300'}, {'price': '0.92', 'size': '20000.45'}, {'price': '0.91', 'size': '10406.3'}, {'price': '0.9', 'size': '4587.5'}, {'price': '0.89', 'size': '13017.18'}, {'price': '0.88', 'size': '200'}, {'price': '0.87', 'size': '3229'}, {'price': '0.86', 'size': '17.1'}, {'price': '0.85', 'size': '109.68'}, {'price': '0.84', 'size': '250'}, {'price': '0.83', 'size': '100'}, {'price': '0.82', 'size': '16029'}, {'price': '0.81', 'size': '45721.39'}, {'price': '0.8', 'size': '26531'}, {'price': '0.79', 'size': '7110'}, {'price': '0.78', 'size': '15350'}, {'price': '0.77', 'size': '67'}, {'price': '0.76', 'size': '200'}, {'price': '0.75', 'size': '13329.25'}, {'price': '0.74', 'size': '11370.7'}, {'price': '0.73', 'size': '5020.1'}, {'price': '0.72', 'size': '380.52'}, {'price': '0.71', 'size': '15073.2'}, {'price': '0.7', 'size': '5570.1'}, {'price': '0.69', 'size': '6088.6'}, {'price': '0.68', 'size': '6131.34'}, {'price': '0.67', 'size': '3010.1'}, {'price': '0.66', 'size': '510.1'}, {'price': '0.65', 'size': '1010.1'}, {'price': '0.64', 'size': '4230.1'}, {'price': '0.63', 'size': '210.1'}, {'price': '0.62', 'size': '300.1'}, {'price': '0.61', 'size': '511.06'}, {'price': '0.6', 'size': '3347.85'}, {'price': '0.59', 'size': '3610'}, {'price': '0.58', 'size': '188.1'}, {'price': '0.57', 'size': '1840.1'}], 'asset_id': '114416409796971863099144323163249651172534872992222856507897414949637892047507', 'bids': [{'price': '0.01', 'size': '2850.27'}, {'price': '0.02', 'size': '500'}, {'price': '0.03', 'size': '500'}, {'price': '0.04', 'size': '300'}, {'price': '0.05', 'size': '320'}, {'price': '0.06', 'size': '300'}, {'price': '0.08', 'size': '250'}, {'price': '0.09', 'size': '300'}, {'price': '0.1', 'size': '6205'}, {'price': '0.12', 'size': '200'}, {'price': '0.13', 'size': '426.92'}, {'price': '0.14', 'size': '15'}, {'price': '0.15', 'size': '110'}, {'price': '0.16', 'size': '4709.51'}, {'price': '0.18', 'size': '19.13'}, {'price': '0.19', 'size': '120'}, {'price': '0.2', 'size': '691.17'}, {'price': '0.24', 'size': '5027'}, {'price': '0.25', 'size': '86.66'}, {'price': '0.27', 'size': '215.25'}, {'price': '0.29', 'size': '1102.28'}, {'price': '0.31', 'size': '1130.65'}, {'price': '0.32', 'size': '200'}, {'price': '0.33', 'size': '620'}, {'price': '0.34', 'size': '4000'}, {'price': '0.35', 'size': '232'}, {'price': '0.39', 'size': '10.5'}, {'price': '0.4', 'size': '3135'}, {'price': '0.41', 'size': '20'}, {'price': '0.42', 'size': '3050'}, {'price': '0.43', 'size': '50'}, {'price': '0.44', 'size': '3660'}, {'price': '0.45', 'size': '478'}, {'price': '0.47', 'size': '3297.23'}, {'price': '0.48', 'size': '242.18'}, {'price': '0.49', 'size': '40'}, {'price': '0.5', 'size': '2115'}, {'price': '0.51', 'size': '4026.18'}, {'price': '0.52', 'size': '1885.92'}, {'price': '0.53', 'size': '1218.99'}, {'price': '0.54', 'size': '51.19'}, {'price': '0.55', 'size': '3932.77'}, {'price': '0.56', 'size': '3750.94'}], 'event_type': 'book', 'hash': 'b0298713962d62c72c367dfb8768e6ab223c44dc', 'market': '0x7aa4a910b31b2c4ddb09d1e3408e52aa8e09a14402f376070a44b1b85cb36d13', 'timestamp': '1733334133268'}
{'asset_id': '114416409796971863099144323163249651172534872992222856507897414949637892047507', 'changes': [{'price': '0.47', 'side': 'BUY', 'size': '2797.23'}, {'price': '0.52', 'side': 'BUY', 'size': '885.92'}, {'price': '0.57', 'side': 'SELL', 'size': '1340.1'}], 'event_type': 'price_change', 'hash': '65952a976b38e38396b7d66b288ee11abc41de4a', 'market': '0x7aa4a910b31b2c4ddb09d1e3408e52aa8e09a14402f376070a44b1b85cb36d13', 'timestamp': '1733334133699'}
{'asset_id': '114416409796971863099144323163249651172534872992222856507897414949637892047507', 'changes': [{'price': '0.47', 'side': 'BUY', 'size': '2797.23'}, {'price': '0.52', 'side': 'BUY', 'size': '885.92'}, {'price': '0.57', 'side': 'SELL', 'size': '1340.1'}], 'event_type': 'price_change', 'hash': '65952a976b38e38396b7d66b288ee11abc41de4a', 'market': '0x7aa4a910b31b2c4ddb09d1e3408e52aa8e09a14402f376070a44b1b85cb36d13', 'timestamp': '1733334133699'}
{'asset_id': '114416409796971863099144323163249651172534872992222856507897414949637892047507', 'changes': [{'price': '0.53', 'side': 'BUY', 'size': '1118.99'}], 'event_type': 'price_change', 'hash': '8403421c18cfd8faa428f6bd0b1b55565d3ec90a', 'market': '0x7aa4a910b31b2c4ddb09d1e3408e52aa8e09a14402f376070a44b1b85cb36d13', 'timestamp': '1733334133870'}
{'asset_id': '114416409796971863099144323163249651172534872992222856507897414949637892047507', 'changes': [{'price': '0.53', 'side': 'BUY', 'size': '1118.99'}], 'event_type': 'price_change', 'hash': '8403421c18cfd8faa428f6bd0b1b55565d3ec90a', 'market': '0x7aa4a910b31b2c4ddb09d1e3408e52aa8e09a14402f376070a44b1b85cb36d13', 'timestamp': '1733334133870'}
{'asset_id': '114416409796971863099144323163249651172534872992222856507897414949637892047507', 'changes': [{'price': '0.48', 'side': 'BUY', 'size': '742.18'}], 'event_type': 'price_change', 'hash': '88e792705ba01b082fa759f4d83719ed412ca1fa', 'market': '0x7aa4a910b31b2c4ddb09d1e3408e52aa8e09a14402f376070a44b1b85cb36d13', 'timestamp': '1733334134757'}
{'asset_id': '114416409796971863099144323163249651172534872992222856507897414949637892047507', 'changes': [{'price': '0.48', 'side': 'BUY', 'size': '742.18'}], 'event_type': 'price_change', 'hash': '88e792705ba01b082fa759f4d83719ed412ca1fa', 'market': '0x7aa4a910b31b2c4ddb09d1e3408e52aa8e09a14402f376070a44b1b85cb36d13', 'timestamp': '1733334134757'}
{'asset_id': '114416409796971863099144323163249651172534872992222856507897414949637892047507', 'changes': [{'price': '0.57', 'side': 'SELL', 'size': '1840.1'}], 'event_type': 'price_change', 'hash': 'd3536d98095a0e7e660deb90e616ef728adec39a', 'market': '0x7aa4a910b31b2c4ddb09d1e3408e52aa8e09a14402f376070a44b1b85cb36d13', 'timestamp': '1733334135362'}
{'asset_id': '114416409796971863099144323163249651172534872992222856507897414949637892047507', 'changes': [{'price': '0.57', 'side': 'SELL', 'size': '1840.1'}], 'event_type': 'price_change', 'hash': 'd3536d98095a0e7e660deb90e616ef728adec39a', 'market': '0x7aa4a910b31b2c4ddb09d1e3408e52aa8e09a14402f376070a44b1b85cb36d13', 'timestamp': '1733334135362'}
{'asset_id': '114416409796971863099144323163249651172534872992222856507897414949637892047507', 'changes': [{'price': '0.52', 'side': 'BUY', 'size': '1885.92'}], 'event_type': 'price_change', 'hash': 'e35f79d0a1b193fdd04686d1b4a1831156b45305', 'market': '0x7aa4a910b31b2c4ddb09d1e3408e52aa8e09a14402f376070a44b1b85cb36d13', 'timestamp': '1733334135753'}
{'asset_id': '114416409796971863099144323163249651172534872992222856507897414949637892047507', 'changes': [{'price': '0.52', 'side': 'BUY', 'size': '1885.92'}], 'event_type': 'price_change', 'hash': 'e35f79d0a1b193fdd04686d1b4a1831156b45305', 'market': '0x7aa4a910b31b2c4ddb09d1e3408e52aa8e09a14402f376070a44b1b85cb36d13', 'timestamp': '1733334135753'}
{'asset_id': '114416409796971863099144323163249651172534872992222856507897414949637892047507', 'changes': [{'price': '0.55', 'side': 'BUY', 'size': '3832.77'}], 'event_type': 'price_change', 'hash': 'e098b97810aa9d63e2a25809ca0ef6e03a813535', 'market': '0x7aa4a910b31b2c4ddb09d1e3408e52aa8e09a14402f376070a44b1b85cb36d13', 'timestamp': '1733334136519'}
{'asset_id': '114416409796971863099144323163249651172534872992222856507897414949637892047507', 'changes': [{'price': '0.55', 'side': 'BUY', 'size': '3832.77'}], 'event_type': 'price_change', 'hash': 'e098b97810aa9d63e2a25809ca0ef6e03a813535', 'market': '0x7aa4a910b31b2c4ddb09d1e3408e52aa8e09a14402f376070a44b1b85cb36d13', 'timestamp': '1733334136519'}
{'asset_id': '114416409796971863099144323163249651172534872992222856507897414949637892047507', 'changes': [{'price': '0.56', 'side': 'BUY', 'size': '3850.94'}], 'event_type': 'price_change', 'hash': '2bdb4eab13df94f1d32c9cf2a717d8b79ba3de6e', 'market': '0x7aa4a910b31b2c4ddb09d1e3408e52aa8e09a14402f376070a44b1b85cb36d13', 'timestamp': '1733334136930'}
{'asset_id': '114416409796971863099144323163249651172534872992222856507897414949637892047507', 'changes': [{'price': '0.56', 'side': 'BUY', 'size': '3850.94'}], 'event_type': 'price_change', 'hash': '2bdb4eab13df94f1d32c9cf2a717d8b79ba3de6e', 'market': '0x7aa4a910b31b2c4ddb09d1e3408e52aa8e09a14402f376070a44b1b85cb36d13', 'timestamp': '1733334136930'}
{'asset_id': '114416409796971863099144323163249651172534872992222856507897414949637892047507', 'changes': [{'price': '0.6', 'side': 'SELL', 'size': '3067.85'}, {'price': '0.57', 'side': 'SELL', 'size': '1810.1'}, {'price': '0.51', 'side': 'BUY', 'size': '3786.18'}], 'event_type': 'price_change', 'hash': 'dced9540e3d0865f8d93cecbe43474b3d56969a5', 'market': '0x7aa4a910b31b2c4ddb09d1e3408e52aa8e09a14402f376070a44b1b85cb36d13', 'timestamp': '1733334138232'}
{'asset_id': '114416409796971863099144323163249651172534872992222856507897414949637892047507', 'changes': [{'price': '0.6', 'side': 'SELL', 'size': '3067.85'}, {'price': '0.57', 'side': 'SELL', 'size': '1810.1'}, {'price': '0.51', 'side': 'BUY', 'size': '3786.18'}], 'event_type': 'price_change', 'hash': 'dced9540e3d0865f8d93cecbe43474b3d56969a5', 'market': '0x7aa4a910b31b2c4ddb09d1e3408e52aa8e09a14402f376070a44b1b85cb36d13', 'timestamp': '1733334138232'}
{'asset_id': '114416409796971863099144323163249651172534872992222856507897414949637892047507', 'changes': [{'price': '0.58', 'side': 'SELL', 'size': '218.1'}], 'event_type': 'price_change', 'hash': '98ffd65449b191cdc8fb6d7d4d2ad5978cd2b34d', 'market': '0x7aa4a910b31b2c4ddb09d1e3408e52aa8e09a14402f376070a44b1b85cb36d13', 'timestamp': '1733334138364'}
{'asset_id': '114416409796971863099144323163249651172534872992222856507897414949637892047507', 'changes': [{'price': '0.58', 'side': 'SELL', 'size': '218.1'}], 'event_type': 'price_change', 'hash': '98ffd65449b191cdc8fb6d7d4d2ad5978cd2b34d', 'market': '0x7aa4a910b31b2c4ddb09d1e3408e52aa8e09a14402f376070a44b1b85cb36d13', 'timestamp': '1733334138364'}
{'asset_id': '114416409796971863099144323163249651172534872992222856507897414949637892047507', 'changes': [{'price': '0.61', 'side': 'SELL', 'size': '791.06'}], 'event_type': 'price_change', 'hash': '09b4944c4170521fc55d03aba1835252f2a31fc8', 'market': '0x7aa4a910b31b2c4ddb09d1e3408e52aa8e09a14402f376070a44b1b85cb36d13', 'timestamp': '1733334138489'}
{'asset_id': '114416409796971863099144323163249651172534872992222856507897414949637892047507', 'changes': [{'price': '0.61', 'side': 'SELL', 'size': '791.06'}], 'event_type': 'price_change', 'hash': '09b4944c4170521fc55d03aba1835252f2a31fc8', 'market': '0x7aa4a910b31b2c4ddb09d1e3408e52aa8e09a14402f376070a44b1b85cb36d13', 'timestamp': '1733334138489'}
{'asset_id': '114416409796971863099144323163249651172534872992222856507897414949637892047507', 'changes': [{'price': '0.54', 'side': 'BUY', 'size': '21.19'}, {'price': '0.52', 'side': 'BUY', 'size': '2115.92'}], 'event_type': 'price_change', 'hash': 'd362e02a4c99fdeb37c27064980d51fa1e3b0967', 'market': '0x7aa4a910b31b2c4ddb09d1e3408e52aa8e09a14402f376070a44b1b85cb36d13', 'timestamp': '1733334138748'}
{'asset_id': '114416409796971863099144323163249651172534872992222856507897414949637892047507', 'changes': [{'price': '0.54', 'side': 'BUY', 'size': '21.19'}, {'price': '0.52', 'side': 'BUY', 'size': '2115.92'}], 'event_type': 'price_change', 'hash': 'd362e02a4c99fdeb37c27064980d51fa1e3b0967', 'market': '0x7aa4a910b31b2c4ddb09d1e3408e52aa8e09a14402f376070a44b1b85cb36d13', 'timestamp': '1733334138748'}
{'asset_id': '114416409796971863099144323163249651172534872992222856507897414949637892047507', 'changes': [{'price': '0.55', 'side': 'BUY', 'size': '3862.77'}], 'event_type': 'price_change', 'hash': '1fb5b6656974bbbb00d61b6a7aa026a1b4c3acf2', 'market': '0x7aa4a910b31b2c4ddb09d1e3408e52aa8e09a14402f376070a44b1b85cb36d13', 'timestamp': '1733334138852'}
{'asset_id': '114416409796971863099144323163249651172534872992222856507897414949637892047507', 'changes': [{'price': '0.55', 'side': 'BUY', 'size': '3862.77'}], 'event_type': 'price_change', 'hash': '1fb5b6656974bbbb00d61b6a7aa026a1b4c3acf2', 'market': '0x7aa4a910b31b2c4ddb09d1e3408e52aa8e09a14402f376070a44b1b85cb36d13', 'timestamp': '1733334138852'}
{'asset_id': '114416409796971863099144323163249651172534872992222856507897414949637892047507', 'changes': [{'price': '0.58', 'side': 'SELL', 'size': '168.1'}], 'event_type': 'price_change', 'hash': '09b377ee22fa381576d96d28fb19b83c123a0799', 'market': '0x7aa4a910b31b2c4ddb09d1e3408e52aa8e09a14402f376070a44b1b85cb36d13', 'timestamp': '1733334139390'}
{'asset_id': '114416409796971863099144323163249651172534872992222856507897414949637892047507', 'changes': [{'price': '0.58', 'side': 'SELL', 'size': '168.1'}], 'event_type': 'price_change', 'hash': '09b377ee22fa381576d96d28fb19b83c123a0799', 'market': '0x7aa4a910b31b2c4ddb09d1e3408e52aa8e09a14402f376070a44b1b85cb36d13', 'timestamp': '1733334139390'}
{'asset_id': '114416409796971863099144323163249651172534872992222856507897414949637892047507', 'changes': [{'price': '0.57', 'side': 'SELL', 'size': '1760.1'}], 'event_type': 'price_change', 'hash': '17ee8164c556b576220a9f2e03c3a3ed9e0987b4', 'market': '0x7aa4a910b31b2c4ddb09d1e3408e52aa8e09a14402f376070a44b1b85cb36d13', 'timestamp': '1733334139855'}
{'asset_id': '114416409796971863099144323163249651172534872992222856507897414949637892047507', 'changes': [{'price': '0.57', 'side': 'SELL', 'size': '1760.1'}], 'event_type': 'price_change', 'hash': '17ee8164c556b576220a9f2e03c3a3ed9e0987b4', 'market': '0x7aa4a910b31b2c4ddb09d1e3408e52aa8e09a14402f376070a44b1b85cb36d13', 'timestamp': '1733334139855'}
{'asset_id': '114416409796971863099144323163249651172534872992222856507897414949637892047507', 'changes': [{'price': '0.51', 'side': 'BUY', 'size': '3736.18'}], 'event_type': 'price_change', 'hash': '092e1763ea4c1e924ed5294a7caaeba993cf3c74', 'market': '0x7aa4a910b31b2c4ddb09d1e3408e52aa8e09a14402f376070a44b1b85cb36d13', 'timestamp': '1733334140385'}
{'asset_id': '114416409796971863099144323163249651172534872992222856507897414949637892047507', 'changes': [{'price': '0.51', 'side': 'BUY', 'size': '3736.18'}], 'event_type': 'price_change', 'hash': '092e1763ea4c1e924ed5294a7caaeba993cf3c74', 'market': '0x7aa4a910b31b2c4ddb09d1e3408e52aa8e09a14402f376070a44b1b85cb36d13', 'timestamp': '1733334140385'}
{'asset_id': '114416409796971863099144323163249651172534872992222856507897414949637892047507', 'changes': [{'price': '0.58', 'side': 'SELL', 'size': '118.1'}], 'event_type': 'price_change', 'hash': '5dc21cca72cc3c181fb000a425ceb1cd648ead85', 'market': '0x7aa4a910b31b2c4ddb09d1e3408e52aa8e09a14402f376070a44b1b85cb36d13', 'timestamp': '1733334140436'}
{'asset_id': '114416409796971863099144323163249651172534872992222856507897414949637892047507', 'changes': [{'price': '0.58', 'side': 'SELL', 'size': '118.1'}], 'event_type': 'price_change', 'hash': '5dc21cca72cc3c181fb000a425ceb1cd648ead85', 'market': '0x7aa4a910b31b2c4ddb09d1e3408e52aa8e09a14402f376070a44b1b85cb36d13', 'timestamp': '1733334140436'}
{'asset_id': '114416409796971863099144323163249651172534872992222856507897414949637892047507', 'changes': [{'price': '0.51', 'side': 'BUY', 'size': '2536.18'}, {'price': '0.5', 'side': 'BUY', 'size': '2065'}], 'event_type': 'price_change', 'hash': '53dab5a525e277a41bd574499aa032c69b3fefa0', 'market': '0x7aa4a910b31b2c4ddb09d1e3408e52aa8e09a14402f376070a44b1b85cb36d13', 'timestamp': '1733334140873'}
{'asset_id': '114416409796971863099144323163249651172534872992222856507897414949637892047507', 'changes': [{'price': '0.51', 'side': 'BUY', 'size': '2536.18'}, {'price': '0.5', 'side': 'BUY', 'size': '2065'}], 'event_type': 'price_change', 'hash': '53dab5a525e277a41bd574499aa032c69b3fefa0', 'market': '0x7aa4a910b31b2c4ddb09d1e3408e52aa8e09a14402f376070a44b1b85cb36d13', 'timestamp': '1733334140873'}
{'asset_id': '114416409796971863099144323163249651172534872992222856507897414949637892047507', 'changes': [{'price': '0.57', 'side': 'SELL', 'size': '1710.1'}], 'event_type': 'price_change', 'hash': 'b1bf89e2a0f2657892f7b38a2364d230e7b3897a', 'market': '0x7aa4a910b31b2c4ddb09d1e3408e52aa8e09a14402f376070a44b1b85cb36d13', 'timestamp': '1733334140935'}
{'asset_id': '114416409796971863099144323163249651172534872992222856507897414949637892047507', 'changes': [{'price': '0.57', 'side': 'SELL', 'size': '1710.1'}], 'event_type': 'price_change', 'hash': 'b1bf89e2a0f2657892f7b38a2364d230e7b3897a', 'market': '0x7aa4a910b31b2c4ddb09d1e3408e52aa8e09a14402f376070a44b1b85cb36d13', 'timestamp': '1733334140935'}
{'asset_id': '114416409796971863099144323163249651172534872992222856507897414949637892047507', 'changes': [{'price': '0.61', 'side': 'SELL', 'size': '841.06'}], 'event_type': 'price_change', 'hash': '1ccffc27e7b3447d6e6a5172a0673c0d5396d414', 'market': '0x7aa4a910b31b2c4ddb09d1e3408e52aa8e09a14402f376070a44b1b85cb36d13', 'timestamp': '1733334141141'}
{'asset_id': '114416409796971863099144323163249651172534872992222856507897414949637892047507', 'changes': [{'price': '0.61', 'side': 'SELL', 'size': '841.06'}], 'event_type': 'price_change', 'hash': '1ccffc27e7b3447d6e6a5172a0673c0d5396d414', 'market': '0x7aa4a910b31b2c4ddb09d1e3408e52aa8e09a14402f376070a44b1b85cb36d13', 'timestamp': '1733334141141'}
{'asset_id': '114416409796971863099144323163249651172534872992222856507897414949637892047507', 'changes': [{'price': '0.52', 'side': 'BUY', 'size': '3315.92'}], 'event_type': 'price_change', 'hash': '66c1e903aefa68703df7702d4f0d11509ff4f6b0', 'market': '0x7aa4a910b31b2c4ddb09d1e3408e52aa8e09a14402f376070a44b1b85cb36d13', 'timestamp': '1733334141243'}
{'asset_id': '114416409796971863099144323163249651172534872992222856507897414949637892047507', 'changes': [{'price': '0.52', 'side': 'BUY', 'size': '3315.92'}], 'event_type': 'price_change', 'hash': '66c1e903aefa68703df7702d4f0d11509ff4f6b0', 'market': '0x7aa4a910b31b2c4ddb09d1e3408e52aa8e09a14402f376070a44b1b85cb36d13', 'timestamp': '1733334141243'}
{'asset_id': '114416409796971863099144323163249651172534872992222856507897414949637892047507', 'changes': [{'price': '0.51', 'side': 'BUY', 'size': '2486.18'}, {'price': '0.62', 'side': 'SELL', 'size': '350.1'}], 'event_type': 'price_change', 'hash': '6088a8f0481fd6e5737acb45f77cc6087ef01083', 'market': '0x7aa4a910b31b2c4ddb09d1e3408e52aa8e09a14402f376070a44b1b85cb36d13', 'timestamp': '1733334141435'}
{'asset_id': '114416409796971863099144323163249651172534872992222856507897414949637892047507', 'changes': [{'price': '0.51', 'side': 'BUY', 'size': '2486.18'}, {'price': '0.62', 'side': 'SELL', 'size': '350.1'}], 'event_type': 'price_change', 'hash': '6088a8f0481fd6e5737acb45f77cc6087ef01083', 'market': '0x7aa4a910b31b2c4ddb09d1e3408e52aa8e09a14402f376070a44b1b85cb36d13', 'timestamp': '1733334141435'}
{'asset_id': '114416409796971863099144323163249651172534872992222856507897414949637892047507', 'changes': [{'price': '0.55', 'side': 'BUY', 'size': '3912.77'}], 'event_type': 'price_change', 'hash': 'b7516a3ee03ad08c4509a3c1a4313a2bd2fdb304', 'market': '0x7aa4a910b31b2c4ddb09d1e3408e52aa8e09a14402f376070a44b1b85cb36d13', 'timestamp': '1733334141703'}
{'asset_id': '114416409796971863099144323163249651172534872992222856507897414949637892047507', 'changes': [{'price': '0.55', 'side': 'BUY', 'size': '3912.77'}], 'event_type': 'price_change', 'hash': 'b7516a3ee03ad08c4509a3c1a4313a2bd2fdb304', 'market': '0x7aa4a910b31b2c4ddb09d1e3408e52aa8e09a14402f376070a44b1b85cb36d13', 'timestamp': '1733334141703'}
{'asset_id': '114416409796971863099144323163249651172534872992222856507897414949637892047507', 'changes': [{'price': '0.5', 'side': 'BUY', 'size': '2015'}], 'event_type': 'price_change', 'hash': 'f4ff07defa4748a28703c467ca8964cdfb9bb574', 'market': '0x7aa4a910b31b2c4ddb09d1e3408e52aa8e09a14402f376070a44b1b85cb36d13', 'timestamp': '1733334141929'}
{'asset_id': '114416409796971863099144323163249651172534872992222856507897414949637892047507', 'changes': [{'price': '0.5', 'side': 'BUY', 'size': '2015'}], 'event_type': 'price_change', 'hash': 'f4ff07defa4748a28703c467ca8964cdfb9bb574', 'market': '0x7aa4a910b31b2c4ddb09d1e3408e52aa8e09a14402f376070a44b1b85cb36d13', 'timestamp': '1733334141929'}
{'asset_id': '114416409796971863099144323163249651172534872992222856507897414949637892047507', 'changes': [{'price': '0.54', 'side': 'BUY', 'size': '71.19'}], 'event_type': 'price_change', 'hash': 'f7d1263a92f684b1c25e6129f3e0ae13c07e4c47', 'market': '0x7aa4a910b31b2c4ddb09d1e3408e52aa8e09a14402f376070a44b1b85cb36d13', 'timestamp': '1733334142036'}
{'asset_id': '114416409796971863099144323163249651172534872992222856507897414949637892047507', 'changes': [{'price': '0.54', 'side': 'BUY', 'size': '71.19'}], 'event_type': 'price_change', 'hash': 'f7d1263a92f684b1c25e6129f3e0ae13c07e4c47', 'market': '0x7aa4a910b31b2c4ddb09d1e3408e52aa8e09a14402f376070a44b1b85cb36d13', 'timestamp': '1733334142036'}
{'asset_id': '114416409796971863099144323163249651172534872992222856507897414949637892047507', 'changes': [{'price': '0.61', 'side': 'SELL', 'size': '891.06'}], 'event_type': 'price_change', 'hash': '9e0adbd4e7b8f74aee5aaa7d2e1a1e762fd52363', 'market': '0x7aa4a910b31b2c4ddb09d1e3408e52aa8e09a14402f376070a44b1b85cb36d13', 'timestamp': '1733334142178'}
{'asset_id': '114416409796971863099144323163249651172534872992222856507897414949637892047507', 'changes': [{'price': '0.61', 'side': 'SELL', 'size': '891.06'}], 'event_type': 'price_change', 'hash': '9e0adbd4e7b8f74aee5aaa7d2e1a1e762fd52363', 'market': '0x7aa4a910b31b2c4ddb09d1e3408e52aa8e09a14402f376070a44b1b85cb36d13', 'timestamp': '1733334142178'}
{'asset_id': '114416409796971863099144323163249651172534872992222856507897414949637892047507', 'changes': [{'price': '0.62', 'side': 'SELL', 'size': '400.1'}], 'event_type': 'price_change', 'hash': '9311fd2606b45f0e6fda676a87ea1b1ba9160fe4', 'market': '0x7aa4a910b31b2c4ddb09d1e3408e52aa8e09a14402f376070a44b1b85cb36d13', 'timestamp': '1733334142436'}
{'asset_id': '114416409796971863099144323163249651172534872992222856507897414949637892047507', 'changes': [{'price': '0.62', 'side': 'SELL', 'size': '400.1'}], 'event_type': 'price_change', 'hash': '9311fd2606b45f0e6fda676a87ea1b1ba9160fe4', 'market': '0x7aa4a910b31b2c4ddb09d1e3408e52aa8e09a14402f376070a44b1b85cb36d13', 'timestamp': '1733334142436'}
{'asset_id': '114416409796971863099144323163249651172534872992222856507897414949637892047507', 'changes': [{'price': '0.55', 'side': 'BUY', 'size': '3962.77'}], 'event_type': 'price_change', 'hash': 'ceaa96265cea7644fd66bd2d3e23717d3356e17a', 'market': '0x7aa4a910b31b2c4ddb09d1e3408e52aa8e09a14402f376070a44b1b85cb36d13', 'timestamp': '1733334142684'}
{'asset_id': '114416409796971863099144323163249651172534872992222856507897414949637892047507', 'changes': [{'price': '0.55', 'side': 'BUY', 'size': '3962.77'}], 'event_type': 'price_change', 'hash': 'ceaa96265cea7644fd66bd2d3e23717d3356e17a', 'market': '0x7aa4a910b31b2c4ddb09d1e3408e52aa8e09a14402f376070a44b1b85cb36d13', 'timestamp': '1733334142684'}
{'asset_id': '114416409796971863099144323163249651172534872992222856507897414949637892047507', 'changes': [{'price': '0.54', 'side': 'BUY', 'size': '121.19'}], 'event_type': 'price_change', 'hash': 'e570cf0ab86e4c815780a08065bdd71aa84a48d9', 'market': '0x7aa4a910b31b2c4ddb09d1e3408e52aa8e09a14402f376070a44b1b85cb36d13', 'timestamp': '1733334142962'}
{'asset_id': '114416409796971863099144323163249651172534872992222856507897414949637892047507', 'changes': [{'price': '0.54', 'side': 'BUY', 'size': '121.19'}], 'event_type': 'price_change', 'hash': 'e570cf0ab86e4c815780a08065bdd71aa84a48d9', 'market': '0x7aa4a910b31b2c4ddb09d1e3408e52aa8e09a14402f376070a44b1b85cb36d13', 'timestamp': '1733334142962'}
{'asks': [{'price': '0.99', 'size': '4217.01'}, {'price': '0.98', 'size': '505'}, {'price': '0.97', 'size': '511.03'}, {'price': '0.96', 'size': '300'}, {'price': '0.95', 'size': '657.12'}, {'price': '0.94', 'size': '300'}, {'price': '0.92', 'size': '20000.45'}, {'price': '0.91', 'size': '10406.3'}, {'price': '0.9', 'size': '4587.5'}, {'price': '0.89', 'size': '13017.18'}, {'price': '0.88', 'size': '200'}, {'price': '0.87', 'size': '3229'}, {'price': '0.86', 'size': '17.1'}, {'price': '0.85', 'size': '109.68'}, {'price': '0.84', 'size': '250'}, {'price': '0.83', 'size': '100'}, {'price': '0.82', 'size': '16029'}, {'price': '0.81', 'size': '45721.39'}, {'price': '0.8', 'size': '26531'}, {'price': '0.79', 'size': '7110'}, {'price': '0.78', 'size': '15350'}, {'price': '0.77', 'size': '67'}, {'price': '0.76', 'size': '200'}, {'price': '0.75', 'size': '13329.25'}, {'price': '0.74', 'size': '11370.7'}, {'price': '0.73', 'size': '5020.1'}, {'price': '0.72', 'size': '380.52'}, {'price': '0.71', 'size': '15073.2'}, {'price': '0.7', 'size': '5570.1'}, {'price': '0.69', 'size': '6088.6'}, {'price': '0.68', 'size': '6131.34'}, {'price': '0.67', 'size': '3010.1'}, {'price': '0.66', 'size': '510.1'}, {'price': '0.65', 'size': '1010.1'}, {'price': '0.64', 'size': '4230.1'}, {'price': '0.63', 'size': '210.1'}, {'price': '0.62', 'size': '400.1'}, {'price': '0.61', 'size': '891.06'}, {'price': '0.6', 'size': '3067.85'}, {'price': '0.59', 'size': '3610'}, {'price': '0.58', 'size': '118.1'}, {'price': '0.57', 'size': '1710.1'}], 'asset_id': '114416409796971863099144323163249651172534872992222856507897414949637892047507', 'bids': [{'price': '0.01', 'size': '2850.27'}, {'price': '0.02', 'size': '500'}, {'price': '0.03', 'size': '500'}, {'price': '0.04', 'size': '300'}, {'price': '0.05', 'size': '320'}, {'price': '0.06', 'size': '300'}, {'price': '0.08', 'size': '250'}, {'price': '0.09', 'size': '300'}, {'price': '0.1', 'size': '6205'}, {'price': '0.12', 'size': '200'}, {'price': '0.13', 'size': '426.92'}, {'price': '0.14', 'size': '15'}, {'price': '0.15', 'size': '110'}, {'price': '0.16', 'size': '4709.51'}, {'price': '0.18', 'size': '19.13'}, {'price': '0.19', 'size': '120'}, {'price': '0.2', 'size': '691.17'}, {'price': '0.24', 'size': '5027'}, {'price': '0.25', 'size': '86.66'}, {'price': '0.27', 'size': '215.25'}, {'price': '0.29', 'size': '1102.28'}, {'price': '0.31', 'size': '1130.65'}, {'price': '0.32', 'size': '200'}, {'price': '0.33', 'size': '620'}, {'price': '0.34', 'size': '4000'}, {'price': '0.35', 'size': '232'}, {'price': '0.39', 'size': '10.5'}, {'price': '0.4', 'size': '3135'}, {'price': '0.41', 'size': '20'}, {'price': '0.42', 'size': '3050'}, {'price': '0.43', 'size': '50'}, {'price': '0.44', 'size': '3660'}, {'price': '0.45', 'size': '478'}, {'price': '0.47', 'size': '2797.23'}, {'price': '0.48', 'size': '742.18'}, {'price': '0.49', 'size': '40'}, {'price': '0.5', 'size': '2015'}, {'price': '0.51', 'size': '2486.18'}, {'price': '0.52', 'size': '3315.92'}, {'price': '0.53', 'size': '1118.99'}, {'price': '0.54', 'size': '121.19'}, {'price': '0.55', 'size': '3962.77'}, {'price': '0.56', 'size': '3658.41'}], 'event_type': 'book', 'hash': 'b52e9a2037c8cc6511a63dc13721a0094cbfc54e', 'market': '0x7aa4a910b31b2c4ddb09d1e3408e52aa8e09a14402f376070a44b1b85cb36d13', 'timestamp': '1733334149100'}
{'asks': [{'price': '0.99', 'size': '4217.01'}, {'price': '0.98', 'size': '505'}, {'price': '0.97', 'size': '511.03'}, {'price': '0.96', 'size': '300'}, {'price': '0.95', 'size': '657.12'}, {'price': '0.94', 'size': '300'}, {'price': '0.92', 'size': '20000.45'}, {'price': '0.91', 'size': '10406.3'}, {'price': '0.9', 'size': '4587.5'}, {'price': '0.89', 'size': '13017.18'}, {'price': '0.88', 'size': '200'}, {'price': '0.87', 'size': '3229'}, {'price': '0.86', 'size': '17.1'}, {'price': '0.85', 'size': '109.68'}, {'price': '0.84', 'size': '250'}, {'price': '0.83', 'size': '100'}, {'price': '0.82', 'size': '16029'}, {'price': '0.81', 'size': '45721.39'}, {'price': '0.8', 'size': '26531'}, {'price': '0.79', 'size': '7110'}, {'price': '0.78', 'size': '15350'}, {'price': '0.77', 'size': '67'}, {'price': '0.76', 'size': '200'}, {'price': '0.75', 'size': '13329.25'}, {'price': '0.74', 'size': '11370.7'}, {'price': '0.73', 'size': '5020.1'}, {'price': '0.72', 'size': '380.52'}, {'price': '0.71', 'size': '15073.2'}, {'price': '0.7', 'size': '5570.1'}, {'price': '0.69', 'size': '6088.6'}, {'price': '0.68', 'size': '6131.34'}, {'price': '0.67', 'size': '3010.1'}, {'price': '0.66', 'size': '510.1'}, {'price': '0.65', 'size': '1010.1'}, {'price': '0.64', 'size': '4230.1'}, {'price': '0.63', 'size': '210.1'}, {'price': '0.62', 'size': '400.1'}, {'price': '0.61', 'size': '891.06'}, {'price': '0.6', 'size': '3067.85'}, {'price': '0.59', 'size': '3610'}, {'price': '0.58', 'size': '118.1'}, {'price': '0.57', 'size': '1710.1'}], 'asset_id': '114416409796971863099144323163249651172534872992222856507897414949637892047507', 'bids': [{'price': '0.01', 'size': '2850.27'}, {'price': '0.02', 'size': '500'}, {'price': '0.03', 'size': '500'}, {'price': '0.04', 'size': '300'}, {'price': '0.05', 'size': '320'}, {'price': '0.06', 'size': '300'}, {'price': '0.08', 'size': '250'}, {'price': '0.09', 'size': '300'}, {'price': '0.1', 'size': '6205'}, {'price': '0.12', 'size': '200'}, {'price': '0.13', 'size': '426.92'}, {'price': '0.14', 'size': '15'}, {'price': '0.15', 'size': '110'}, {'price': '0.16', 'size': '4709.51'}, {'price': '0.18', 'size': '19.13'}, {'price': '0.19', 'size': '120'}, {'price': '0.2', 'size': '691.17'}, {'price': '0.24', 'size': '5027'}, {'price': '0.25', 'size': '86.66'}, {'price': '0.27', 'size': '215.25'}, {'price': '0.29', 'size': '1102.28'}, {'price': '0.31', 'size': '1130.65'}, {'price': '0.32', 'size': '200'}, {'price': '0.33', 'size': '620'}, {'price': '0.34', 'size': '4000'}, {'price': '0.35', 'size': '232'}, {'price': '0.39', 'size': '10.5'}, {'price': '0.4', 'size': '3135'}, {'price': '0.41', 'size': '20'}, {'price': '0.42', 'size': '3050'}, {'price': '0.43', 'size': '50'}, {'price': '0.44', 'size': '3660'}, {'price': '0.45', 'size': '478'}, {'price': '0.47', 'size': '2797.23'}, {'price': '0.48', 'size': '742.18'}, {'price': '0.49', 'size': '40'}, {'price': '0.5', 'size': '2015'}, {'price': '0.51', 'size': '2486.18'}, {'price': '0.52', 'size': '3315.92'}, {'price': '0.53', 'size': '1118.99'}, {'price': '0.54', 'size': '121.19'}, {'price': '0.55', 'size': '3962.77'}, {'price': '0.56', 'size': '3658.41'}], 'event_type': 'book', 'hash': 'b52e9a2037c8cc6511a63dc13721a0094cbfc54e', 'market': '0x7aa4a910b31b2c4ddb09d1e3408e52aa8e09a14402f376070a44b1b85cb36d13', 'timestamp': '1733334149100'}
{'asset_id': '114416409796971863099144323163249651172534872992222856507897414949637892047507', 'changes': [{'price': '0.61', 'side': 'SELL', 'size': '611.06'}, {'price': '0.52', 'side': 'BUY', 'size': '3085.92'}], 'event_type': 'price_change', 'hash': '8ba4bbf944a2ac51474b3af5ca60b64331db6798', 'market': '0x7aa4a910b31b2c4ddb09d1e3408e52aa8e09a14402f376070a44b1b85cb36d13', 'timestamp': '1733334155254'}
{'asset_id': '114416409796971863099144323163249651172534872992222856507897414949637892047507', 'changes': [{'price': '0.61', 'side': 'SELL', 'size': '611.06'}, {'price': '0.52', 'side': 'BUY', 'size': '3085.92'}], 'event_type': 'price_change', 'hash': '8ba4bbf944a2ac51474b3af5ca60b64331db6798', 'market': '0x7aa4a910b31b2c4ddb09d1e3408e52aa8e09a14402f376070a44b1b85cb36d13', 'timestamp': '1733334155254'}
{'asset_id': '114416409796971863099144323163249651172534872992222856507897414949637892047507', 'changes': [{'price': '0.53', 'side': 'BUY', 'size': '1328.99'}], 'event_type': 'price_change', 'hash': '47d1f932c7c8f9c2119d99e71b440292234371cb', 'market': '0x7aa4a910b31b2c4ddb09d1e3408e52aa8e09a14402f376070a44b1b85cb36d13', 'timestamp': '1733334155535'}
{'asset_id': '114416409796971863099144323163249651172534872992222856507897414949637892047507', 'changes': [{'price': '0.53', 'side': 'BUY', 'size': '1328.99'}], 'event_type': 'price_change', 'hash': '47d1f932c7c8f9c2119d99e71b440292234371cb', 'market': '0x7aa4a910b31b2c4ddb09d1e3408e52aa8e09a14402f376070a44b1b85cb36d13', 'timestamp': '1733334155535'}
{'asset_id': '114416409796971863099144323163249651172534872992222856507897414949637892047507', 'changes': [{'price': '0.61', 'side': 'SELL', 'size': '871.06'}], 'event_type': 'price_change', 'hash': '2c7c8bc542b6bcd798dca3827dffce58f002e8d1', 'market': '0x7aa4a910b31b2c4ddb09d1e3408e52aa8e09a14402f376070a44b1b85cb36d13', 'timestamp': '1733334155793'}
{'asset_id': '114416409796971863099144323163249651172534872992222856507897414949637892047507', 'changes': [{'price': '0.61', 'side': 'SELL', 'size': '871.06'}], 'event_type': 'price_change', 'hash': '2c7c8bc542b6bcd798dca3827dffce58f002e8d1', 'market': '0x7aa4a910b31b2c4ddb09d1e3408e52aa8e09a14402f376070a44b1b85cb36d13', 'timestamp': '1733334155793'}
{'asks': [{'price': '0.99', 'size': '4217.01'}, {'price': '0.98', 'size': '505'}, {'price': '0.97', 'size': '511.03'}, {'price': '0.96', 'size': '300'}, {'price': '0.95', 'size': '657.12'}, {'price': '0.94', 'size': '300'}, {'price': '0.92', 'size': '20000.45'}, {'price': '0.91', 'size': '10406.3'}, {'price': '0.9', 'size': '4587.5'}, {'price': '0.89', 'size': '13017.18'}, {'price': '0.88', 'size': '200'}, {'price': '0.87', 'size': '3229'}, {'price': '0.86', 'size': '17.1'}, {'price': '0.85', 'size': '109.68'}, {'price': '0.84', 'size': '250'}, {'price': '0.83', 'size': '100'}, {'price': '0.82', 'size': '16029'}, {'price': '0.81', 'size': '45721.39'}, {'price': '0.8', 'size': '26531'}, {'price': '0.79', 'size': '7110'}, {'price': '0.78', 'size': '15350'}, {'price': '0.77', 'size': '67'}, {'price': '0.76', 'size': '200'}, {'price': '0.75', 'size': '13329.25'}, {'price': '0.74', 'size': '11370.7'}, {'price': '0.73', 'size': '5020.1'}, {'price': '0.72', 'size': '380.52'}, {'price': '0.71', 'size': '15073.2'}, {'price': '0.7', 'size': '5570.1'}, {'price': '0.69', 'size': '6088.6'}, {'price': '0.68', 'size': '6131.34'}, {'price': '0.67', 'size': '3010.1'}, {'price': '0.66', 'size': '510.1'}, {'price': '0.65', 'size': '1010.1'}, {'price': '0.64', 'size': '4230.1'}, {'price': '0.63', 'size': '210.1'}, {'price': '0.62', 'size': '400.1'}, {'price': '0.61', 'size': '871.06'}, {'price': '0.6', 'size': '3067.85'}, {'price': '0.59', 'size': '3610'}, {'price': '0.58', 'size': '118.1'}, {'price': '0.57', 'size': '1710.02'}], 'asset_id': '114416409796971863099144323163249651172534872992222856507897414949637892047507', 'bids': [{'price': '0.01', 'size': '2850.27'}, {'price': '0.02', 'size': '500'}, {'price': '0.03', 'size': '500'}, {'price': '0.04', 'size': '300'}, {'price': '0.05', 'size': '320'}, {'price': '0.06', 'size': '300'}, {'price': '0.08', 'size': '250'}, {'price': '0.09', 'size': '300'}, {'price': '0.1', 'size': '6205'}, {'price': '0.12', 'size': '200'}, {'price': '0.13', 'size': '426.92'}, {'price': '0.14', 'size': '15'}, {'price': '0.15', 'size': '110'}, {'price': '0.16', 'size': '4709.51'}, {'price': '0.18', 'size': '19.13'}, {'price': '0.19', 'size': '120'}, {'price': '0.2', 'size': '691.17'}, {'price': '0.24', 'size': '5027'}, {'price': '0.25', 'size': '86.66'}, {'price': '0.27', 'size': '215.25'}, {'price': '0.29', 'size': '1102.28'}, {'price': '0.31', 'size': '1130.65'}, {'price': '0.32', 'size': '200'}, {'price': '0.33', 'size': '620'}, {'price': '0.34', 'size': '4000'}, {'price': '0.35', 'size': '232'}, {'price': '0.39', 'size': '10.5'}, {'price': '0.4', 'size': '3135'}, {'price': '0.41', 'size': '20'}, {'price': '0.42', 'size': '3050'}, {'price': '0.43', 'size': '50'}, {'price': '0.44', 'size': '3660'}, {'price': '0.45', 'size': '478'}, {'price': '0.47', 'size': '2797.23'}, {'price': '0.48', 'size': '742.18'}, {'price': '0.49', 'size': '40'}, {'price': '0.5', 'size': '2015'}, {'price': '0.51', 'size': '2486.18'}, {'price': '0.52', 'size': '3085.92'}, {'price': '0.53', 'size': '1328.99'}, {'price': '0.54', 'size': '121.19'}, {'price': '0.55', 'size': '3962.77'}, {'price': '0.56', 'size': '3658.41'}], 'event_type': 'book', 'hash': '5fb9e49110072495110a560aaafa6e92f9f9530f', 'market': '0x7aa4a910b31b2c4ddb09d1e3408e52aa8e09a14402f376070a44b1b85cb36d13', 'timestamp': '1733334165689'}
{'asset_id': '114416409796971863099144323163249651172534872992222856507897414949637892047507', 'event_type': 'last_trade_price', 'fee_rate_bps': '0', 'market': '0x7aa4a910b31b2c4ddb09d1e3408e52aa8e09a14402f376070a44b1b85cb36d13', 'price': '0.57', 'side': 'BUY', 'size': '0.070174', 'timestamp': '1733334165709'}
{'asks': [{'price': '0.99', 'size': '4217.01'}, {'price': '0.98', 'size': '505'}, {'price': '0.97', 'size': '511.03'}, {'price': '0.96', 'size': '300'}, {'price': '0.95', 'size': '657.12'}, {'price': '0.94', 'size': '300'}, {'price': '0.92', 'size': '20000.45'}, {'price': '0.91', 'size': '10406.3'}, {'price': '0.9', 'size': '4587.5'}, {'price': '0.89', 'size': '13017.18'}, {'price': '0.88', 'size': '200'}, {'price': '0.87', 'size': '3229'}, {'price': '0.86', 'size': '17.1'}, {'price': '0.85', 'size': '109.68'}, {'price': '0.84', 'size': '250'}, {'price': '0.83', 'size': '100'}, {'price': '0.82', 'size': '16029'}, {'price': '0.81', 'size': '45721.39'}, {'price': '0.8', 'size': '26531'}, {'price': '0.79', 'size': '7110'}, {'price': '0.78', 'size': '15350'}, {'price': '0.77', 'size': '67'}, {'price': '0.76', 'size': '200'}, {'price': '0.75', 'size': '13329.25'}, {'price': '0.74', 'size': '11370.7'}, {'price': '0.73', 'size': '5020.1'}, {'price': '0.72', 'size': '380.52'}, {'price': '0.71', 'size': '15073.2'}, {'price': '0.7', 'size': '5570.1'}, {'price': '0.69', 'size': '6088.6'}, {'price': '0.68', 'size': '6131.34'}, {'price': '0.67', 'size': '3010.1'}, {'price': '0.66', 'size': '510.1'}, {'price': '0.65', 'size': '1010.1'}, {'price': '0.64', 'size': '4230.1'}, {'price': '0.63', 'size': '210.1'}, {'price': '0.62', 'size': '400.1'}, {'price': '0.61', 'size': '871.06'}, {'price': '0.6', 'size': '3067.85'}, {'price': '0.59', 'size': '3610'}, {'price': '0.58', 'size': '118.1'}, {'price': '0.57', 'size': '1710.02'}], 'asset_id': '114416409796971863099144323163249651172534872992222856507897414949637892047507', 'bids': [{'price': '0.01', 'size': '2850.27'}, {'price': '0.02', 'size': '500'}, {'price': '0.03', 'size': '500'}, {'price': '0.04', 'size': '300'}, {'price': '0.05', 'size': '320'}, {'price': '0.06', 'size': '300'}, {'price': '0.08', 'size': '250'}, {'price': '0.09', 'size': '300'}, {'price': '0.1', 'size': '6205'}, {'price': '0.12', 'size': '200'}, {'price': '0.13', 'size': '426.92'}, {'price': '0.14', 'size': '15'}, {'price': '0.15', 'size': '110'}, {'price': '0.16', 'size': '4709.51'}, {'price': '0.18', 'size': '19.13'}, {'price': '0.19', 'size': '120'}, {'price': '0.2', 'size': '691.17'}, {'price': '0.24', 'size': '5027'}, {'price': '0.25', 'size': '86.66'}, {'price': '0.27', 'size': '215.25'}, {'price': '0.29', 'size': '1102.28'}, {'price': '0.31', 'size': '1130.65'}, {'price': '0.32', 'size': '200'}, {'price': '0.33', 'size': '620'}, {'price': '0.34', 'size': '4000'}, {'price': '0.35', 'size': '232'}, {'price': '0.39', 'size': '10.5'}, {'price': '0.4', 'size': '3135'}, {'price': '0.41', 'size': '20'}, {'price': '0.42', 'size': '3050'}, {'price': '0.43', 'size': '50'}, {'price': '0.44', 'size': '3660'}, {'price': '0.45', 'size': '478'}, {'price': '0.47', 'size': '2797.23'}, {'price': '0.48', 'size': '742.18'}, {'price': '0.49', 'size': '40'}, {'price': '0.5', 'size': '2015'}, {'price': '0.51', 'size': '2486.18'}, {'price': '0.52', 'size': '3085.92'}, {'price': '0.53', 'size': '1328.99'}, {'price': '0.54', 'size': '121.19'}, {'price': '0.55', 'size': '3962.77'}, {'price': '0.56', 'size': '3658.41'}], 'event_type': 'book', 'hash': '5fb9e49110072495110a560aaafa6e92f9f9530f', 'market': '0x7aa4a910b31b2c4ddb09d1e3408e52aa8e09a14402f376070a44b1b85cb36d13', 'timestamp': '1733334165689'}
{'asset_id': '114416409796971863099144323163249651172534872992222856507897414949637892047507', 'event_type': 'last_trade_price', 'fee_rate_bps': '0', 'market': '0x7aa4a910b31b2c4ddb09d1e3408e52aa8e09a14402f376070a44b1b85cb36d13', 'price': '0.57', 'side': 'BUY', 'size': '0.070174', 'timestamp': '1733334165709'}
{'asks': [{'price': '0.99', 'size': '4217.01'}, {'price': '0.98', 'size': '505'}, {'price': '0.97', 'size': '511.03'}, {'price': '0.96', 'size': '300'}, {'price': '0.95', 'size': '657.12'}, {'price': '0.94', 'size': '300'}, {'price': '0.92', 'size': '20000.45'}, {'price': '0.91', 'size': '10406.3'}, {'price': '0.9', 'size': '4587.5'}, {'price': '0.89', 'size': '13017.18'}, {'price': '0.88', 'size': '200'}, {'price': '0.87', 'size': '3229'}, {'price': '0.86', 'size': '17.1'}, {'price': '0.85', 'size': '109.68'}, {'price': '0.84', 'size': '250'}, {'price': '0.83', 'size': '100'}, {'price': '0.82', 'size': '16029'}, {'price': '0.81', 'size': '45721.39'}, {'price': '0.8', 'size': '26531'}, {'price': '0.79', 'size': '7110'}, {'price': '0.78', 'size': '15350'}, {'price': '0.77', 'size': '67'}, {'price': '0.76', 'size': '200'}, {'price': '0.75', 'size': '13329.25'}, {'price': '0.74', 'size': '11370.7'}, {'price': '0.73', 'size': '5020.1'}, {'price': '0.72', 'size': '380.52'}, {'price': '0.71', 'size': '15073.2'}, {'price': '0.7', 'size': '5570.1'}, {'price': '0.69', 'size': '6088.6'}, {'price': '0.68', 'size': '6131.34'}, {'price': '0.67', 'size': '3010.1'}, {'price': '0.66', 'size': '510.1'}, {'price': '0.65', 'size': '1010.1'}, {'price': '0.64', 'size': '4230.1'}, {'price': '0.63', 'size': '210.1'}, {'price': '0.62', 'size': '400.1'}, {'price': '0.61', 'size': '871.06'}, {'price': '0.6', 'size': '3067.85'}, {'price': '0.59', 'size': '3610'}, {'price': '0.58', 'size': '118.1'}, {'price': '0.57', 'size': '1710.02'}], 'asset_id': '114416409796971863099144323163249651172534872992222856507897414949637892047507', 'bids': [{'price': '0.01', 'size': '2850.27'}, {'price': '0.02', 'size': '500'}, {'price': '0.03', 'size': '500'}, {'price': '0.04', 'size': '300'}, {'price': '0.05', 'size': '320'}, {'price': '0.06', 'size': '300'}, {'price': '0.08', 'size': '250'}, {'price': '0.09', 'size': '300'}, {'price': '0.1', 'size': '6205'}, {'price': '0.12', 'size': '200'}, {'price': '0.13', 'size': '426.92'}, {'price': '0.14', 'size': '15'}, {'price': '0.15', 'size': '110'}, {'price': '0.16', 'size': '4709.51'}, {'price': '0.18', 'size': '19.13'}, {'price': '0.19', 'size': '120'}, {'price': '0.2', 'size': '691.17'}, {'price': '0.24', 'size': '5027'}, {'price': '0.25', 'size': '86.66'}, {'price': '0.27', 'size': '215.25'}, {'price': '0.29', 'size': '1102.28'}, {'price': '0.31', 'size': '1130.65'}, {'price': '0.32', 'size': '200'}, {'price': '0.33', 'size': '620'}, {'price': '0.34', 'size': '4000'}, {'price': '0.35', 'size': '232'}, {'price': '0.39', 'size': '10.5'}, {'price': '0.4', 'size': '3135'}, {'price': '0.41', 'size': '20'}, {'price': '0.42', 'size': '3050'}, {'price': '0.43', 'size': '50'}, {'price': '0.44', 'size': '3660'}, {'price': '0.45', 'size': '478'}, {'price': '0.47', 'size': '2797.23'}, {'price': '0.48', 'size': '742.18'}, {'price': '0.49', 'size': '40'}, {'price': '0.5', 'size': '2015'}, {'price': '0.51', 'size': '2486.18'}, {'price': '0.52', 'size': '3085.92'}, {'price': '0.53', 'size': '1328.99'}, {'price': '0.54', 'size': '121.19'}, {'price': '0.55', 'size': '3962.77'}, {'price': '0.56', 'size': '3658.31'}], 'event_type': 'book', 'hash': 'ac05148eef383eb79fe84bd895b27e53ae42e6e0', 'market': '0x7aa4a910b31b2c4ddb09d1e3408e52aa8e09a14402f376070a44b1b85cb36d13', 'timestamp': '1733334165858'}
{'asks': [{'price': '0.99', 'size': '4217.01'}, {'price': '0.98', 'size': '505'}, {'price': '0.97', 'size': '511.03'}, {'price': '0.96', 'size': '300'}, {'price': '0.95', 'size': '657.12'}, {'price': '0.94', 'size': '300'}, {'price': '0.92', 'size': '20000.45'}, {'price': '0.91', 'size': '10406.3'}, {'price': '0.9', 'size': '4587.5'}, {'price': '0.89', 'size': '13017.18'}, {'price': '0.88', 'size': '200'}, {'price': '0.87', 'size': '3229'}, {'price': '0.86', 'size': '17.1'}, {'price': '0.85', 'size': '109.68'}, {'price': '0.84', 'size': '250'}, {'price': '0.83', 'size': '100'}, {'price': '0.82', 'size': '16029'}, {'price': '0.81', 'size': '45721.39'}, {'price': '0.8', 'size': '26531'}, {'price': '0.79', 'size': '7110'}, {'price': '0.78', 'size': '15350'}, {'price': '0.77', 'size': '67'}, {'price': '0.76', 'size': '200'}, {'price': '0.75', 'size': '13329.25'}, {'price': '0.74', 'size': '11370.7'}, {'price': '0.73', 'size': '5020.1'}, {'price': '0.72', 'size': '380.52'}, {'price': '0.71', 'size': '15073.2'}, {'price': '0.7', 'size': '5570.1'}, {'price': '0.69', 'size': '6088.6'}, {'price': '0.68', 'size': '6131.34'}, {'price': '0.67', 'size': '3010.1'}, {'price': '0.66', 'size': '510.1'}, {'price': '0.65', 'size': '1010.1'}, {'price': '0.64', 'size': '4230.1'}, {'price': '0.63', 'size': '210.1'}, {'price': '0.62', 'size': '400.1'}, {'price': '0.61', 'size': '871.06'}, {'price': '0.6', 'size': '3067.85'}, {'price': '0.59', 'size': '3610'}, {'price': '0.58', 'size': '118.1'}, {'price': '0.57', 'size': '1710.02'}], 'asset_id': '114416409796971863099144323163249651172534872992222856507897414949637892047507', 'bids': [{'price': '0.01', 'size': '2850.27'}, {'price': '0.02', 'size': '500'}, {'price': '0.03', 'size': '500'}, {'price': '0.04', 'size': '300'}, {'price': '0.05', 'size': '320'}, {'price': '0.06', 'size': '300'}, {'price': '0.08', 'size': '250'}, {'price': '0.09', 'size': '300'}, {'price': '0.1', 'size': '6205'}, {'price': '0.12', 'size': '200'}, {'price': '0.13', 'size': '426.92'}, {'price': '0.14', 'size': '15'}, {'price': '0.15', 'size': '110'}, {'price': '0.16', 'size': '4709.51'}, {'price': '0.18', 'size': '19.13'}, {'price': '0.19', 'size': '120'}, {'price': '0.2', 'size': '691.17'}, {'price': '0.24', 'size': '5027'}, {'price': '0.25', 'size': '86.66'}, {'price': '0.27', 'size': '215.25'}, {'price': '0.29', 'size': '1102.28'}, {'price': '0.31', 'size': '1130.65'}, {'price': '0.32', 'size': '200'}, {'price': '0.33', 'size': '620'}, {'price': '0.34', 'size': '4000'}, {'price': '0.35', 'size': '232'}, {'price': '0.39', 'size': '10.5'}, {'price': '0.4', 'size': '3135'}, {'price': '0.41', 'size': '20'}, {'price': '0.42', 'size': '3050'}, {'price': '0.43', 'size': '50'}, {'price': '0.44', 'size': '3660'}, {'price': '0.45', 'size': '478'}, {'price': '0.47', 'size': '2797.23'}, {'price': '0.48', 'size': '742.18'}, {'price': '0.49', 'size': '40'}, {'price': '0.5', 'size': '2015'}, {'price': '0.51', 'size': '2486.18'}, {'price': '0.52', 'size': '3085.92'}, {'price': '0.53', 'size': '1328.99'}, {'price': '0.54', 'size': '121.19'}, {'price': '0.55', 'size': '3962.77'}, {'price': '0.56', 'size': '3658.31'}], 'event_type': 'book', 'hash': 'ac05148eef383eb79fe84bd895b27e53ae42e6e0', 'market': '0x7aa4a910b31b2c4ddb09d1e3408e52aa8e09a14402f376070a44b1b85cb36d13', 'timestamp': '1733334165858'}
{'asset_id': '114416409796971863099144323163249651172534872992222856507897414949637892047507', 'changes': [{'price': '0.48', 'side': 'BUY', 'size': '242.18'}, {'price': '0.52', 'side': 'BUY', 'size': '2085.92'}, {'price': '0.57', 'side': 'SELL', 'size': '1210.02'}], 'event_type': 'price_change', 'hash': 'a0de7d6f9374af3d55882e8a2a8ac90d4992f632', 'market': '0x7aa4a910b31b2c4ddb09d1e3408e52aa8e09a14402f376070a44b1b85cb36d13', 'timestamp': '1733334195799'}
{'asset_id': '114416409796971863099144323163249651172534872992222856507897414949637892047507', 'changes': [{'price': '0.48', 'side': 'BUY', 'size': '242.18'}, {'price': '0.52', 'side': 'BUY', 'size': '2085.92'}, {'price': '0.57', 'side': 'SELL', 'size': '1210.02'}], 'event_type': 'price_change', 'hash': 'a0de7d6f9374af3d55882e8a2a8ac90d4992f632', 'market': '0x7aa4a910b31b2c4ddb09d1e3408e52aa8e09a14402f376070a44b1b85cb36d13', 'timestamp': '1733334195799'}
{'asset_id': '114416409796971863099144323163249651172534872992222856507897414949637892047507', 'changes': [{'price': '0.47', 'side': 'BUY', 'size': '3297.23'}], 'event_type': 'price_change', 'hash': 'a97d14f7ab0e98b2f93ffb493437b7b126b591a3', 'market': '0x7aa4a910b31b2c4ddb09d1e3408e52aa8e09a14402f376070a44b1b85cb36d13', 'timestamp': '1733334196887'}
{'asset_id': '114416409796971863099144323163249651172534872992222856507897414949637892047507', 'changes': [{'price': '0.47', 'side': 'BUY', 'size': '3297.23'}], 'event_type': 'price_change', 'hash': 'a97d14f7ab0e98b2f93ffb493437b7b126b591a3', 'market': '0x7aa4a910b31b2c4ddb09d1e3408e52aa8e09a14402f376070a44b1b85cb36d13', 'timestamp': '1733334196887'}
{'asset_id': '114416409796971863099144323163249651172534872992222856507897414949637892047507', 'changes': [{'price': '0.57', 'side': 'SELL', 'size': '1710.02'}], 'event_type': 'price_change', 'hash': '6356b622db02495a7dc0dc77394aa3338865574f', 'market': '0x7aa4a910b31b2c4ddb09d1e3408e52aa8e09a14402f376070a44b1b85cb36d13', 'timestamp': '1733334197276'}
{'asset_id': '114416409796971863099144323163249651172534872992222856507897414949637892047507', 'changes': [{'price': '0.57', 'side': 'SELL', 'size': '1710.02'}], 'event_type': 'price_change', 'hash': '6356b622db02495a7dc0dc77394aa3338865574f', 'market': '0x7aa4a910b31b2c4ddb09d1e3408e52aa8e09a14402f376070a44b1b85cb36d13', 'timestamp': '1733334197276'}
{'asset_id': '114416409796971863099144323163249651172534872992222856507897414949637892047507', 'changes': [{'price': '0.52', 'side': 'BUY', 'size': '3085.92'}], 'event_type': 'price_change', 'hash': '2a9f7f1a1fa3845e9815d11bff626615e38ff3e3', 'market': '0x7aa4a910b31b2c4ddb09d1e3408e52aa8e09a14402f376070a44b1b85cb36d13', 'timestamp': '1733334197645'}
{'asset_id': '114416409796971863099144323163249651172534872992222856507897414949637892047507', 'changes': [{'price': '0.52', 'side': 'BUY', 'size': '3085.92'}], 'event_type': 'price_change', 'hash': '2a9f7f1a1fa3845e9815d11bff626615e38ff3e3', 'market': '0x7aa4a910b31b2c4ddb09d1e3408e52aa8e09a14402f376070a44b1b85cb36d13', 'timestamp': '1733334197645'}
{'asset_id': '114416409796971863099144323163249651172534872992222856507897414949637892047507', 'changes': [{'price': '0.47', 'side': 'BUY', 'size': '797.23'}], 'event_type': 'price_change', 'hash': '79058ce495153c8f795370baf4f324ef6e897bf3', 'market': '0x7aa4a910b31b2c4ddb09d1e3408e52aa8e09a14402f376070a44b1b85cb36d13', 'timestamp': '1733334202010'}
{'asset_id': '114416409796971863099144323163249651172534872992222856507897414949637892047507', 'changes': [{'price': '0.51', 'side': 'BUY', 'size': '986.18'}], 'event_type': 'price_change', 'hash': '59369219eb6823d751669725333d906b4c01a04d', 'market': '0x7aa4a910b31b2c4ddb09d1e3408e52aa8e09a14402f376070a44b1b85cb36d13', 'timestamp': '1733334209011'}
{'asset_id': '114416409796971863099144323163249651172534872992222856507897414949637892047507', 'changes': [{'price': '0.51', 'side': 'BUY', 'size': '986.18'}], 'event_type': 'price_change', 'hash': '59369219eb6823d751669725333d906b4c01a04d', 'market': '0x7aa4a910b31b2c4ddb09d1e3408e52aa8e09a14402f376070a44b1b85cb36d13', 'timestamp': '1733334209011'}
{'asset_id': '114416409796971863099144323163249651172534872992222856507897414949637892047507', 'changes': [{'price': '0.48', 'side': 'BUY', 'size': '2742.18'}], 'event_type': 'price_change', 'hash': 'f50be16ca102787b8318d665f95dfcab69b109a9', 'market': '0x7aa4a910b31b2c4ddb09d1e3408e52aa8e09a14402f376070a44b1b85cb36d13', 'timestamp': '1733334211863'}
{'asset_id': '114416409796971863099144323163249651172534872992222856507897414949637892047507', 'changes': [{'price': '0.48', 'side': 'BUY', 'size': '2742.18'}], 'event_type': 'price_change', 'hash': 'f50be16ca102787b8318d665f95dfcab69b109a9', 'market': '0x7aa4a910b31b2c4ddb09d1e3408e52aa8e09a14402f376070a44b1b85cb36d13', 'timestamp': '1733334211863'}
{'asset_id': '114416409796971863099144323163249651172534872992222856507897414949637892047507', 'changes': [{'price': '0.57', 'side': 'SELL', 'size': '1210.02'}, {'price': '0.52', 'side': 'BUY', 'size': '2085.92'}, {'price': '0.47', 'side': 'BUY', 'size': '297.23'}], 'event_type': 'price_change', 'hash': '93f33609966c8412ed5cac924f9952a61ad06e6c', 'market': '0x7aa4a910b31b2c4ddb09d1e3408e52aa8e09a14402f376070a44b1b85cb36d13', 'timestamp': '1733334212346'}
{'asset_id': '114416409796971863099144323163249651172534872992222856507897414949637892047507', 'changes': [{'price': '0.57', 'side': 'SELL', 'size': '1210.02'}, {'price': '0.52', 'side': 'BUY', 'size': '2085.92'}, {'price': '0.47', 'side': 'BUY', 'size': '297.23'}], 'event_type': 'price_change', 'hash': '93f33609966c8412ed5cac924f9952a61ad06e6c', 'market': '0x7aa4a910b31b2c4ddb09d1e3408e52aa8e09a14402f376070a44b1b85cb36d13', 'timestamp': '1733334212346'}
{'asset_id': '114416409796971863099144323163249651172534872992222856507897414949637892047507', 'changes': [{'price': '0.48', 'side': 'BUY', 'size': '3242.18'}], 'event_type': 'price_change', 'hash': 'e85fb3f7d5271cb2a606fc639fc7e92e0a23c49b', 'market': '0x7aa4a910b31b2c4ddb09d1e3408e52aa8e09a14402f376070a44b1b85cb36d13', 'timestamp': '1733334213490'}
{'asset_id': '114416409796971863099144323163249651172534872992222856507897414949637892047507', 'changes': [{'price': '0.48', 'side': 'BUY', 'size': '3242.18'}], 'event_type': 'price_change', 'hash': 'e85fb3f7d5271cb2a606fc639fc7e92e0a23c49b', 'market': '0x7aa4a910b31b2c4ddb09d1e3408e52aa8e09a14402f376070a44b1b85cb36d13', 'timestamp': '1733334213490'}
{'asset_id': '114416409796971863099144323163249651172534872992222856507897414949637892047507', 'changes': [{'price': '0.57', 'side': 'SELL', 'size': '1710.02'}], 'event_type': 'price_change', 'hash': '5517c98e0f898abaab11ed567ba2511090a2f146', 'market': '0x7aa4a910b31b2c4ddb09d1e3408e52aa8e09a14402f376070a44b1b85cb36d13', 'timestamp': '1733334213855'}
{'asset_id': '114416409796971863099144323163249651172534872992222856507897414949637892047507', 'changes': [{'price': '0.57', 'side': 'SELL', 'size': '1710.02'}], 'event_type': 'price_change', 'hash': '5517c98e0f898abaab11ed567ba2511090a2f146', 'market': '0x7aa4a910b31b2c4ddb09d1e3408e52aa8e09a14402f376070a44b1b85cb36d13', 'timestamp': '1733334213855'}
{'asset_id': '114416409796971863099144323163249651172534872992222856507897414949637892047507', 'changes': [{'price': '0.52', 'side': 'BUY', 'size': '3085.92'}], 'event_type': 'price_change', 'hash': '9e65ce2c52b5b8cfce5423ac9bc8b9e9cf965e22', 'market': '0x7aa4a910b31b2c4ddb09d1e3408e52aa8e09a14402f376070a44b1b85cb36d13', 'timestamp': '1733334214224'}
{'asset_id': '114416409796971863099144323163249651172534872992222856507897414949637892047507', 'changes': [{'price': '0.52', 'side': 'BUY', 'size': '3085.92'}], 'event_type': 'price_change', 'hash': '9e65ce2c52b5b8cfce5423ac9bc8b9e9cf965e22', 'market': '0x7aa4a910b31b2c4ddb09d1e3408e52aa8e09a14402f376070a44b1b85cb36d13', 'timestamp': '1733334214224'}
{'asset_id': '114416409796971863099144323163249651172534872992222856507897414949637892047507', 'changes': [{'price': '0.51', 'side': 'BUY', 'size': '2486.18'}], 'event_type': 'price_change', 'hash': 'd0e3518275eb4883e5b8c1c2a7eb8cc6931f66ca', 'market': '0x7aa4a910b31b2c4ddb09d1e3408e52aa8e09a14402f376070a44b1b85cb36d13', 'timestamp': '1733334218821'}
{'asset_id': '114416409796971863099144323163249651172534872992222856507897414949637892047507', 'changes': [{'price': '0.51', 'side': 'BUY', 'size': '2486.18'}], 'event_type': 'price_change', 'hash': 'd0e3518275eb4883e5b8c1c2a7eb8cc6931f66ca', 'market': '0x7aa4a910b31b2c4ddb09d1e3408e52aa8e09a14402f376070a44b1b85cb36d13', 'timestamp': '1733334218821'}
{'asks': [{'price': '0.99', 'size': '4217.01'}, {'price': '0.98', 'size': '505'}, {'price': '0.97', 'size': '511.03'}, {'price': '0.96', 'size': '300'}, {'price': '0.95', 'size': '657.12'}, {'price': '0.94', 'size': '300'}, {'price': '0.92', 'size': '20000.45'}, {'price': '0.91', 'size': '10406.3'}, {'price': '0.9', 'size': '4587.5'}, {'price': '0.89', 'size': '13017.18'}, {'price': '0.88', 'size': '200'}, {'price': '0.87', 'size': '3229'}, {'price': '0.86', 'size': '17.1'}, {'price': '0.85', 'size': '109.68'}, {'price': '0.84', 'size': '250'}, {'price': '0.83', 'size': '100'}, {'price': '0.82', 'size': '16029'}, {'price': '0.81', 'size': '45721.39'}, {'price': '0.8', 'size': '26531'}, {'price': '0.79', 'size': '7110'}, {'price': '0.78', 'size': '15350'}, {'price': '0.77', 'size': '67'}, {'price': '0.76', 'size': '200'}, {'price': '0.75', 'size': '13329.25'}, {'price': '0.74', 'size': '11370.7'}, {'price': '0.73', 'size': '5020.1'}, {'price': '0.72', 'size': '380.52'}, {'price': '0.71', 'size': '15073.2'}, {'price': '0.7', 'size': '5570.1'}, {'price': '0.69', 'size': '6088.6'}, {'price': '0.68', 'size': '6131.34'}, {'price': '0.67', 'size': '3010.1'}, {'price': '0.66', 'size': '510.1'}, {'price': '0.65', 'size': '1010.1'}, {'price': '0.64', 'size': '4230.1'}, {'price': '0.63', 'size': '210.1'}, {'price': '0.62', 'size': '400.1'}, {'price': '0.61', 'size': '871.06'}, {'price': '0.6', 'size': '3067.85'}, {'price': '0.59', 'size': '3610'}, {'price': '0.58', 'size': '118.1'}], 'asset_id': '114416409796971863099144323163249651172534872992222856507897414949637892047507', 'bids': [{'price': '0.01', 'size': '2850.27'}, {'price': '0.02', 'size': '500'}, {'price': '0.03', 'size': '500'}, {'price': '0.04', 'size': '300'}, {'price': '0.05', 'size': '320'}, {'price': '0.06', 'size': '300'}, {'price': '0.08', 'size': '250'}, {'price': '0.09', 'size': '300'}, {'price': '0.1', 'size': '6205'}, {'price': '0.12', 'size': '200'}, {'price': '0.13', 'size': '426.92'}, {'price': '0.14', 'size': '15'}, {'price': '0.15', 'size': '110'}, {'price': '0.16', 'size': '4709.51'}, {'price': '0.18', 'size': '19.13'}, {'price': '0.19', 'size': '120'}, {'price': '0.2', 'size': '691.17'}, {'price': '0.24', 'size': '5027'}, {'price': '0.25', 'size': '86.66'}, {'price': '0.27', 'size': '215.25'}, {'price': '0.29', 'size': '1102.28'}, {'price': '0.31', 'size': '1130.65'}, {'price': '0.32', 'size': '200'}, {'price': '0.33', 'size': '620'}, {'price': '0.34', 'size': '4000'}, {'price': '0.35', 'size': '232'}, {'price': '0.39', 'size': '10.5'}, {'price': '0.4', 'size': '3135'}, {'price': '0.41', 'size': '20'}, {'price': '0.42', 'size': '3050'}, {'price': '0.43', 'size': '50'}, {'price': '0.44', 'size': '3660'}, {'price': '0.45', 'size': '478'}, {'price': '0.47', 'size': '297.23'}, {'price': '0.48', 'size': '3242.18'}, {'price': '0.49', 'size': '40'}, {'price': '0.5', 'size': '2015'}, {'price': '0.51', 'size': '2486.18'}, {'price': '0.52', 'size': '3085.92'}, {'price': '0.53', 'size': '1328.99'}, {'price': '0.54', 'size': '121.19'}, {'price': '0.55', 'size': '3962.77'}, {'price': '0.56', 'size': '3658.31'}], 'event_type': 'book', 'hash': '38b65c9f722a1b9dfcfc29381a993cfef6c4bc0b', 'market': '0x7aa4a910b31b2c4ddb09d1e3408e52aa8e09a14402f376070a44b1b85cb36d13', 'timestamp': '1733334219836'}
{'asset_id': '114416409796971863099144323163249651172534872992222856507897414949637892047507', 'event_type': 'last_trade_price', 'fee_rate_bps': '0', 'market': '0x7aa4a910b31b2c4ddb09d1e3408e52aa8e09a14402f376070a44b1b85cb36d13', 'price': '0.57', 'side': 'BUY', 'size': '1710.02', 'timestamp': '1733334219862'}
{'asks': [{'price': '0.99', 'size': '4217.01'}, {'price': '0.98', 'size': '505'}, {'price': '0.97', 'size': '511.03'}, {'price': '0.96', 'size': '300'}, {'price': '0.95', 'size': '657.12'}, {'price': '0.94', 'size': '300'}, {'price': '0.92', 'size': '20000.45'}, {'price': '0.91', 'size': '10406.3'}, {'price': '0.9', 'size': '4587.5'}, {'price': '0.89', 'size': '13017.18'}, {'price': '0.88', 'size': '200'}, {'price': '0.87', 'size': '3229'}, {'price': '0.86', 'size': '17.1'}, {'price': '0.85', 'size': '109.68'}, {'price': '0.84', 'size': '250'}, {'price': '0.83', 'size': '100'}, {'price': '0.82', 'size': '16029'}, {'price': '0.81', 'size': '45721.39'}, {'price': '0.8', 'size': '26531'}, {'price': '0.79', 'size': '7110'}, {'price': '0.78', 'size': '15350'}, {'price': '0.77', 'size': '67'}, {'price': '0.76', 'size': '200'}, {'price': '0.75', 'size': '13329.25'}, {'price': '0.74', 'size': '11370.7'}, {'price': '0.73', 'size': '5020.1'}, {'price': '0.72', 'size': '380.52'}, {'price': '0.71', 'size': '15073.2'}, {'price': '0.7', 'size': '5570.1'}, {'price': '0.69', 'size': '6088.6'}, {'price': '0.68', 'size': '6131.34'}, {'price': '0.67', 'size': '3010.1'}, {'price': '0.66', 'size': '510.1'}, {'price': '0.65', 'size': '1010.1'}, {'price': '0.64', 'size': '4230.1'}, {'price': '0.63', 'size': '210.1'}, {'price': '0.62', 'size': '400.1'}, {'price': '0.61', 'size': '871.06'}, {'price': '0.6', 'size': '3067.85'}, {'price': '0.59', 'size': '3610'}, {'price': '0.58', 'size': '118.1'}], 'asset_id': '114416409796971863099144323163249651172534872992222856507897414949637892047507', 'bids': [{'price': '0.01', 'size': '2850.27'}, {'price': '0.02', 'size': '500'}, {'price': '0.03', 'size': '500'}, {'price': '0.04', 'size': '300'}, {'price': '0.05', 'size': '320'}, {'price': '0.06', 'size': '300'}, {'price': '0.08', 'size': '250'}, {'price': '0.09', 'size': '300'}, {'price': '0.1', 'size': '6205'}, {'price': '0.12', 'size': '200'}, {'price': '0.13', 'size': '426.92'}, {'price': '0.14', 'size': '15'}, {'price': '0.15', 'size': '110'}, {'price': '0.16', 'size': '4709.51'}, {'price': '0.18', 'size': '19.13'}, {'price': '0.19', 'size': '120'}, {'price': '0.2', 'size': '691.17'}, {'price': '0.24', 'size': '5027'}, {'price': '0.25', 'size': '86.66'}, {'price': '0.27', 'size': '215.25'}, {'price': '0.29', 'size': '1102.28'}, {'price': '0.31', 'size': '1130.65'}, {'price': '0.32', 'size': '200'}, {'price': '0.33', 'size': '620'}, {'price': '0.34', 'size': '4000'}, {'price': '0.35', 'size': '232'}, {'price': '0.39', 'size': '10.5'}, {'price': '0.4', 'size': '3135'}, {'price': '0.41', 'size': '20'}, {'price': '0.42', 'size': '3050'}, {'price': '0.43', 'size': '50'}, {'price': '0.44', 'size': '3660'}, {'price': '0.45', 'size': '478'}, {'price': '0.47', 'size': '297.23'}, {'price': '0.48', 'size': '3242.18'}, {'price': '0.49', 'size': '40'}, {'price': '0.5', 'size': '2015'}, {'price': '0.51', 'size': '2486.18'}, {'price': '0.52', 'size': '3085.92'}, {'price': '0.53', 'size': '1328.99'}, {'price': '0.54', 'size': '121.19'}, {'price': '0.55', 'size': '3962.77'}, {'price': '0.56', 'size': '3658.31'}], 'event_type': 'book', 'hash': '38b65c9f722a1b9dfcfc29381a993cfef6c4bc0b', 'market': '0x7aa4a910b31b2c4ddb09d1e3408e52aa8e09a14402f376070a44b1b85cb36d13', 'timestamp': '1733334219836'}
{'asset_id': '114416409796971863099144323163249651172534872992222856507897414949637892047507', 'event_type': 'last_trade_price', 'fee_rate_bps': '0', 'market': '0x7aa4a910b31b2c4ddb09d1e3408e52aa8e09a14402f376070a44b1b85cb36d13', 'price': '0.57', 'side': 'BUY', 'size': '1710.02', 'timestamp': '1733334219862'}
{'asset_id': '114416409796971863099144323163249651172534872992222856507897414949637892047507', 'changes': [{'price': '0.58', 'side': 'SELL', 'size': '1318.1'}], 'event_type': 'price_change', 'hash': '22c0d0a21f40b228f8e30a59d84da2090a7f9528', 'market': '0x7aa4a910b31b2c4ddb09d1e3408e52aa8e09a14402f376070a44b1b85cb36d13', 'timestamp': '1733334226770'}
{'asset_id': '114416409796971863099144323163249651172534872992222856507897414949637892047507', 'changes': [{'price': '0.58', 'side': 'SELL', 'size': '1318.1'}], 'event_type': 'price_change', 'hash': '22c0d0a21f40b228f8e30a59d84da2090a7f9528', 'market': '0x7aa4a910b31b2c4ddb09d1e3408e52aa8e09a14402f376070a44b1b85cb36d13', 'timestamp': '1733334226770'}
{'asset_id': '114416409796971863099144323163249651172534872992222856507897414949637892047507', 'changes': [{'price': '0.61', 'side': 'SELL', 'size': '611.06'}], 'event_type': 'price_change', 'hash': '9e3e005b126e90f49842636202719a9aa675527e', 'market': '0x7aa4a910b31b2c4ddb09d1e3408e52aa8e09a14402f376070a44b1b85cb36d13', 'timestamp': '1733334231804'}
{'asset_id': '114416409796971863099144323163249651172534872992222856507897414949637892047507', 'changes': [{'price': '0.61', 'side': 'SELL', 'size': '611.06'}], 'event_type': 'price_change', 'hash': '9e3e005b126e90f49842636202719a9aa675527e', 'market': '0x7aa4a910b31b2c4ddb09d1e3408e52aa8e09a14402f376070a44b1b85cb36d13', 'timestamp': '1733334231804'}
{'asset_id': '114416409796971863099144323163249651172534872992222856507897414949637892047507', 'changes': [{'price': '0.53', 'side': 'BUY', 'size': '1118.99'}], 'event_type': 'price_change', 'hash': 'c31df8138f3413debe1f56a1a80ecab8f5b06392', 'market': '0x7aa4a910b31b2c4ddb09d1e3408e52aa8e09a14402f376070a44b1b85cb36d13', 'timestamp': '1733334231816'}
{'asset_id': '114416409796971863099144323163249651172534872992222856507897414949637892047507', 'changes': [{'price': '0.53', 'side': 'BUY', 'size': '1118.99'}], 'event_type': 'price_change', 'hash': 'c31df8138f3413debe1f56a1a80ecab8f5b06392', 'market': '0x7aa4a910b31b2c4ddb09d1e3408e52aa8e09a14402f376070a44b1b85cb36d13', 'timestamp': '1733334231816'}
{'asset_id': '114416409796971863099144323163249651172534872992222856507897414949637892047507', 'changes': [{'price': '0.61', 'side': 'SELL', 'size': '861.06'}], 'event_type': 'price_change', 'hash': 'b677682433dbce29b55a69af1d7b805901adc703', 'market': '0x7aa4a910b31b2c4ddb09d1e3408e52aa8e09a14402f376070a44b1b85cb36d13', 'timestamp': '1733334232079'}
{'asset_id': '114416409796971863099144323163249651172534872992222856507897414949637892047507', 'changes': [{'price': '0.61', 'side': 'SELL', 'size': '861.06'}], 'event_type': 'price_change', 'hash': 'b677682433dbce29b55a69af1d7b805901adc703', 'market': '0x7aa4a910b31b2c4ddb09d1e3408e52aa8e09a14402f376070a44b1b85cb36d13', 'timestamp': '1733334232079'}
{'asset_id': '114416409796971863099144323163249651172534872992222856507897414949637892047507', 'changes': [{'price': '0.53', 'side': 'BUY', 'size': '1318.99'}], 'event_type': 'price_change', 'hash': 'fbf41b3e9028a90bc619e8422b58c2a48b017b43', 'market': '0x7aa4a910b31b2c4ddb09d1e3408e52aa8e09a14402f376070a44b1b85cb36d13', 'timestamp': '1733334232339'}
{'asset_id': '114416409796971863099144323163249651172534872992222856507897414949637892047507', 'changes': [{'price': '0.53', 'side': 'BUY', 'size': '1318.99'}], 'event_type': 'price_change', 'hash': 'fbf41b3e9028a90bc619e8422b58c2a48b017b43', 'market': '0x7aa4a910b31b2c4ddb09d1e3408e52aa8e09a14402f376070a44b1b85cb36d13', 'timestamp': '1733334232339'}
{'asset_id': '114416409796971863099144323163249651172534872992222856507897414949637892047507', 'changes': [{'price': '0.34', 'side': 'BUY', 'size': '0'}], 'event_type': 'price_change', 'hash': 'c120f417a9ff4f21f092c1456c034acaf4bb024c', 'market': '0x7aa4a910b31b2c4ddb09d1e3408e52aa8e09a14402f376070a44b1b85cb36d13', 'timestamp': '1733334233016'}
{'asset_id': '114416409796971863099144323163249651172534872992222856507897414949637892047507', 'changes': [{'price': '0.34', 'side': 'BUY', 'size': '0'}], 'event_type': 'price_change', 'hash': 'c120f417a9ff4f21f092c1456c034acaf4bb024c', 'market': '0x7aa4a910b31b2c4ddb09d1e3408e52aa8e09a14402f376070a44b1b85cb36d13', 'timestamp': '1733334233016'}
{'asset_id': '114416409796971863099144323163249651172534872992222856507897414949637892047507', 'changes': [{'price': '0.37', 'side': 'BUY', 'size': '4000'}], 'event_type': 'price_change', 'hash': 'bebba03927ae6fea02ddaf8e2a19bf0defa55c19', 'market': '0x7aa4a910b31b2c4ddb09d1e3408e52aa8e09a14402f376070a44b1b85cb36d13', 'timestamp': '1733334241980'}
{'asset_id': '114416409796971863099144323163249651172534872992222856507897414949637892047507', 'changes': [{'price': '0.37', 'side': 'BUY', 'size': '4000'}], 'event_type': 'price_change', 'hash': 'bebba03927ae6fea02ddaf8e2a19bf0defa55c19', 'market': '0x7aa4a910b31b2c4ddb09d1e3408e52aa8e09a14402f376070a44b1b85cb36d13', 'timestamp': '1733334241980'}
{'asks': [{'price': '0.99', 'size': '4217.01'}, {'price': '0.98', 'size': '505'}, {'price': '0.97', 'size': '511.03'}, {'price': '0.96', 'size': '300'}, {'price': '0.95', 'size': '657.12'}, {'price': '0.94', 'size': '300'}, {'price': '0.92', 'size': '20000.45'}, {'price': '0.91', 'size': '10406.3'}, {'price': '0.9', 'size': '4587.5'}, {'price': '0.89', 'size': '13017.18'}, {'price': '0.88', 'size': '200'}, {'price': '0.87', 'size': '3229'}, {'price': '0.86', 'size': '17.1'}, {'price': '0.85', 'size': '109.68'}, {'price': '0.84', 'size': '250'}, {'price': '0.83', 'size': '100'}, {'price': '0.82', 'size': '16029'}, {'price': '0.81', 'size': '45721.39'}, {'price': '0.8', 'size': '26531'}, {'price': '0.79', 'size': '7110'}, {'price': '0.78', 'size': '15350'}, {'price': '0.77', 'size': '67'}, {'price': '0.76', 'size': '200'}, {'price': '0.75', 'size': '13329.25'}, {'price': '0.74', 'size': '11370.7'}, {'price': '0.73', 'size': '5020.1'}, {'price': '0.72', 'size': '380.52'}, {'price': '0.71', 'size': '15073.2'}, {'price': '0.7', 'size': '5570.1'}, {'price': '0.69', 'size': '6088.6'}, {'price': '0.68', 'size': '6131.34'}, {'price': '0.67', 'size': '3010.1'}, {'price': '0.66', 'size': '510.1'}, {'price': '0.65', 'size': '1010.1'}, {'price': '0.64', 'size': '4230.1'}, {'price': '0.63', 'size': '210.1'}, {'price': '0.62', 'size': '400.1'}, {'price': '0.61', 'size': '861.06'}, {'price': '0.6', 'size': '3067.85'}, {'price': '0.59', 'size': '3610'}, {'price': '0.58', 'size': '1250.49'}], 'asset_id': '114416409796971863099144323163249651172534872992222856507897414949637892047507', 'bids': [{'price': '0.01', 'size': '2850.27'}, {'price': '0.02', 'size': '500'}, {'price': '0.03', 'size': '500'}, {'price': '0.04', 'size': '300'}, {'price': '0.05', 'size': '320'}, {'price': '0.06', 'size': '300'}, {'price': '0.08', 'size': '250'}, {'price': '0.09', 'size': '300'}, {'price': '0.1', 'size': '6205'}, {'price': '0.12', 'size': '200'}, {'price': '0.13', 'size': '426.92'}, {'price': '0.14', 'size': '15'}, {'price': '0.15', 'size': '110'}, {'price': '0.16', 'size': '4709.51'}, {'price': '0.18', 'size': '19.13'}, {'price': '0.19', 'size': '120'}, {'price': '0.2', 'size': '691.17'}, {'price': '0.24', 'size': '5027'}, {'price': '0.25', 'size': '86.66'}, {'price': '0.27', 'size': '215.25'}, {'price': '0.29', 'size': '1102.28'}, {'price': '0.31', 'size': '1130.65'}, {'price': '0.32', 'size': '200'}, {'price': '0.33', 'size': '620'}, {'price': '0.35', 'size': '232'}, {'price': '0.37', 'size': '4000'}, {'price': '0.39', 'size': '10.5'}, {'price': '0.4', 'size': '3135'}, {'price': '0.41', 'size': '20'}, {'price': '0.42', 'size': '3050'}, {'price': '0.43', 'size': '50'}, {'price': '0.44', 'size': '3660'}, {'price': '0.45', 'size': '478'}, {'price': '0.47', 'size': '297.23'}, {'price': '0.48', 'size': '3242.18'}, {'price': '0.49', 'size': '40'}, {'price': '0.5', 'size': '2015'}, {'price': '0.51', 'size': '2486.18'}, {'price': '0.52', 'size': '3085.92'}, {'price': '0.53', 'size': '1318.99'}, {'price': '0.54', 'size': '121.19'}, {'price': '0.55', 'size': '3962.77'}, {'price': '0.56', 'size': '3658.31'}], 'event_type': 'book', 'hash': '4d3efb0b236812f16a955ad9db92680eac503ffa', 'market': '0x7aa4a910b31b2c4ddb09d1e3408e52aa8e09a14402f376070a44b1b85cb36d13', 'timestamp': '1733334260740'}
{'asks': [{'price': '0.99', 'size': '4217.01'}, {'price': '0.98', 'size': '505'}, {'price': '0.97', 'size': '511.03'}, {'price': '0.96', 'size': '300'}, {'price': '0.95', 'size': '657.12'}, {'price': '0.94', 'size': '300'}, {'price': '0.92', 'size': '20000.45'}, {'price': '0.91', 'size': '10406.3'}, {'price': '0.9', 'size': '4587.5'}, {'price': '0.89', 'size': '13017.18'}, {'price': '0.88', 'size': '200'}, {'price': '0.87', 'size': '3229'}, {'price': '0.86', 'size': '17.1'}, {'price': '0.85', 'size': '109.68'}, {'price': '0.84', 'size': '250'}, {'price': '0.83', 'size': '100'}, {'price': '0.82', 'size': '16029'}, {'price': '0.81', 'size': '45721.39'}, {'price': '0.8', 'size': '26531'}, {'price': '0.79', 'size': '7110'}, {'price': '0.78', 'size': '15350'}, {'price': '0.77', 'size': '67'}, {'price': '0.76', 'size': '200'}, {'price': '0.75', 'size': '13329.25'}, {'price': '0.74', 'size': '11370.7'}, {'price': '0.73', 'size': '5020.1'}, {'price': '0.72', 'size': '380.52'}, {'price': '0.71', 'size': '15073.2'}, {'price': '0.7', 'size': '5570.1'}, {'price': '0.69', 'size': '6088.6'}, {'price': '0.68', 'size': '6131.34'}, {'price': '0.67', 'size': '3010.1'}, {'price': '0.66', 'size': '510.1'}, {'price': '0.65', 'size': '1010.1'}, {'price': '0.64', 'size': '4230.1'}, {'price': '0.63', 'size': '210.1'}, {'price': '0.62', 'size': '400.1'}, {'price': '0.61', 'size': '861.06'}, {'price': '0.6', 'size': '3067.85'}, {'price': '0.59', 'size': '3610'}, {'price': '0.58', 'size': '1250.49'}], 'asset_id': '114416409796971863099144323163249651172534872992222856507897414949637892047507', 'bids': [{'price': '0.01', 'size': '2850.27'}, {'price': '0.02', 'size': '500'}, {'price': '0.03', 'size': '500'}, {'price': '0.04', 'size': '300'}, {'price': '0.05', 'size': '320'}, {'price': '0.06', 'size': '300'}, {'price': '0.08', 'size': '250'}, {'price': '0.09', 'size': '300'}, {'price': '0.1', 'size': '6205'}, {'price': '0.12', 'size': '200'}, {'price': '0.13', 'size': '426.92'}, {'price': '0.14', 'size': '15'}, {'price': '0.15', 'size': '110'}, {'price': '0.16', 'size': '4709.51'}, {'price': '0.18', 'size': '19.13'}, {'price': '0.19', 'size': '120'}, {'price': '0.2', 'size': '691.17'}, {'price': '0.24', 'size': '5027'}, {'price': '0.25', 'size': '86.66'}, {'price': '0.27', 'size': '215.25'}, {'price': '0.29', 'size': '1102.28'}, {'price': '0.31', 'size': '1130.65'}, {'price': '0.32', 'size': '200'}, {'price': '0.33', 'size': '620'}, {'price': '0.35', 'size': '232'}, {'price': '0.37', 'size': '4000'}, {'price': '0.39', 'size': '10.5'}, {'price': '0.4', 'size': '3135'}, {'price': '0.41', 'size': '20'}, {'price': '0.42', 'size': '3050'}, {'price': '0.43', 'size': '50'}, {'price': '0.44', 'size': '3660'}, {'price': '0.45', 'size': '478'}, {'price': '0.47', 'size': '297.23'}, {'price': '0.48', 'size': '3242.18'}, {'price': '0.49', 'size': '40'}, {'price': '0.5', 'size': '2015'}, {'price': '0.51', 'size': '2486.18'}, {'price': '0.52', 'size': '3085.92'}, {'price': '0.53', 'size': '1318.99'}, {'price': '0.54', 'size': '121.19'}, {'price': '0.55', 'size': '3962.77'}, {'price': '0.56', 'size': '3658.31'}], 'event_type': 'book', 'hash': '4d3efb0b236812f16a955ad9db92680eac503ffa', 'market': '0x7aa4a910b31b2c4ddb09d1e3408e52aa8e09a14402f376070a44b1b85cb36d13', 'timestamp': '1733334260740'}
{'asset_id': '114416409796971863099144323163249651172534872992222856507897414949637892047507', 'changes': [{'price': '0.48', 'side': 'BUY', 'size': '2742.18'}, {'price': '0.52', 'side': 'BUY', 'size': '2085.92'}], 'event_type': 'price_change', 'hash': 'dbee172398b57d3a073be2d63d1445d1a3573830', 'market': '0x7aa4a910b31b2c4ddb09d1e3408e52aa8e09a14402f376070a44b1b85cb36d13', 'timestamp': '1733334261892'}
{'asset_id': '114416409796971863099144323163249651172534872992222856507897414949637892047507', 'changes': [{'price': '0.48', 'side': 'BUY', 'size': '2742.18'}, {'price': '0.52', 'side': 'BUY', 'size': '2085.92'}], 'event_type': 'price_change', 'hash': 'dbee172398b57d3a073be2d63d1445d1a3573830', 'market': '0x7aa4a910b31b2c4ddb09d1e3408e52aa8e09a14402f376070a44b1b85cb36d13', 'timestamp': '1733334261892'}
{'asset_id': '114416409796971863099144323163249651172534872992222856507897414949637892047507', 'changes': [{'price': '0.48', 'side': 'BUY', 'size': '3242.18'}], 'event_type': 'price_change', 'hash': '9c98b514f18ee642eecca031bfddb45ea2f4b495', 'market': '0x7aa4a910b31b2c4ddb09d1e3408e52aa8e09a14402f376070a44b1b85cb36d13', 'timestamp': '1733334262925'}
{'asset_id': '114416409796971863099144323163249651172534872992222856507897414949637892047507', 'changes': [{'price': '0.48', 'side': 'BUY', 'size': '3242.18'}], 'event_type': 'price_change', 'hash': '9c98b514f18ee642eecca031bfddb45ea2f4b495', 'market': '0x7aa4a910b31b2c4ddb09d1e3408e52aa8e09a14402f376070a44b1b85cb36d13', 'timestamp': '1733334262925'}
{'asset_id': '114416409796971863099144323163249651172534872992222856507897414949637892047507', 'changes': [{'price': '0.58', 'side': 'SELL', 'size': '1750.49'}], 'event_type': 'price_change', 'hash': 'b5214d94922d4624a7a88d9564d38473cef1e140', 'market': '0x7aa4a910b31b2c4ddb09d1e3408e52aa8e09a14402f376070a44b1b85cb36d13', 'timestamp': '1733334263308'}
{'asset_id': '114416409796971863099144323163249651172534872992222856507897414949637892047507', 'changes': [{'price': '0.58', 'side': 'SELL', 'size': '1750.49'}], 'event_type': 'price_change', 'hash': 'b5214d94922d4624a7a88d9564d38473cef1e140', 'market': '0x7aa4a910b31b2c4ddb09d1e3408e52aa8e09a14402f376070a44b1b85cb36d13', 'timestamp': '1733334263308'}
{'asset_id': '114416409796971863099144323163249651172534872992222856507897414949637892047507', 'changes': [{'price': '0.54', 'side': 'BUY', 'size': '1121.19'}], 'event_type': 'price_change', 'hash': 'f5a95fa3c54f4b5c107955256b89ef3dd8176002', 'market': '0x7aa4a910b31b2c4ddb09d1e3408e52aa8e09a14402f376070a44b1b85cb36d13', 'timestamp': '1733334263706'}
{'asset_id': '114416409796971863099144323163249651172534872992222856507897414949637892047507', 'changes': [{'price': '0.54', 'side': 'BUY', 'size': '1121.19'}], 'event_type': 'price_change', 'hash': 'f5a95fa3c54f4b5c107955256b89ef3dd8176002', 'market': '0x7aa4a910b31b2c4ddb09d1e3408e52aa8e09a14402f376070a44b1b85cb36d13', 'timestamp': '1733334263706'}
{'asset_id': '114416409796971863099144323163249651172534872992222856507897414949637892047507', 'changes': [{'price': '0.52', 'side': 'BUY', 'size': '885.92'}], 'event_type': 'price_change', 'hash': 'ba404d525dd12410a849e08af69c49559adba2bd', 'market': '0x7aa4a910b31b2c4ddb09d1e3408e52aa8e09a14402f376070a44b1b85cb36d13', 'timestamp': '1733334291012'}
{'asset_id': '114416409796971863099144323163249651172534872992222856507897414949637892047507', 'changes': [{'price': '0.52', 'side': 'BUY', 'size': '885.92'}], 'event_type': 'price_change', 'hash': 'ba404d525dd12410a849e08af69c49559adba2bd', 'market': '0x7aa4a910b31b2c4ddb09d1e3408e52aa8e09a14402f376070a44b1b85cb36d13', 'timestamp': '1733334291012'}
{'asset_id': '114416409796971863099144323163249651172534872992222856507897414949637892047507', 'changes': [{'price': '0.52', 'side': 'BUY', 'size': '2085.92'}], 'event_type': 'price_change', 'hash': '5ba2c017d226e185a601f15d41bf1ad5bba1e6c2', 'market': '0x7aa4a910b31b2c4ddb09d1e3408e52aa8e09a14402f376070a44b1b85cb36d13', 'timestamp': '1733334304062'}
{'asset_id': '114416409796971863099144323163249651172534872992222856507897414949637892047507', 'changes': [{'price': '0.52', 'side': 'BUY', 'size': '2085.92'}], 'event_type': 'price_change', 'hash': '5ba2c017d226e185a601f15d41bf1ad5bba1e6c2', 'market': '0x7aa4a910b31b2c4ddb09d1e3408e52aa8e09a14402f376070a44b1b85cb36d13', 'timestamp': '1733334304062'}
{'asks': [{'price': '0.99', 'size': '4217.01'}, {'price': '0.98', 'size': '505'}, {'price': '0.97', 'size': '511.03'}, {'price': '0.96', 'size': '300'}, {'price': '0.95', 'size': '657.12'}, {'price': '0.94', 'size': '300'}, {'price': '0.92', 'size': '20000.45'}, {'price': '0.91', 'size': '10406.3'}, {'price': '0.9', 'size': '4587.5'}, {'price': '0.89', 'size': '13017.18'}, {'price': '0.88', 'size': '200'}, {'price': '0.87', 'size': '3229'}, {'price': '0.86', 'size': '17.1'}, {'price': '0.85', 'size': '109.68'}, {'price': '0.84', 'size': '250'}, {'price': '0.83', 'size': '100'}, {'price': '0.82', 'size': '16029'}, {'price': '0.81', 'size': '45721.39'}, {'price': '0.8', 'size': '26531'}, {'price': '0.79', 'size': '7110'}, {'price': '0.78', 'size': '15350'}, {'price': '0.77', 'size': '67'}, {'price': '0.76', 'size': '200'}, {'price': '0.75', 'size': '13329.25'}, {'price': '0.74', 'size': '11370.7'}, {'price': '0.73', 'size': '5020.1'}, {'price': '0.72', 'size': '380.52'}, {'price': '0.71', 'size': '15073.2'}, {'price': '0.7', 'size': '5570.1'}, {'price': '0.69', 'size': '6088.6'}, {'price': '0.68', 'size': '6131.34'}, {'price': '0.67', 'size': '3010.1'}, {'price': '0.66', 'size': '510.1'}, {'price': '0.65', 'size': '1010.1'}, {'price': '0.64', 'size': '4230.1'}, {'price': '0.63', 'size': '210.1'}, {'price': '0.62', 'size': '400.1'}, {'price': '0.61', 'size': '861.06'}, {'price': '0.6', 'size': '3067.85'}, {'price': '0.59', 'size': '3610'}, {'price': '0.58', 'size': '1750.49'}], 'asset_id': '114416409796971863099144323163249651172534872992222856507897414949637892047507', 'bids': [{'price': '0.01', 'size': '2850.27'}, {'price': '0.02', 'size': '500'}, {'price': '0.03', 'size': '500'}, {'price': '0.04', 'size': '300'}, {'price': '0.05', 'size': '320'}, {'price': '0.06', 'size': '300'}, {'price': '0.08', 'size': '250'}, {'price': '0.09', 'size': '300'}, {'price': '0.1', 'size': '6205'}, {'price': '0.12', 'size': '200'}, {'price': '0.13', 'size': '426.92'}, {'price': '0.14', 'size': '15'}, {'price': '0.15', 'size': '110'}, {'price': '0.16', 'size': '4709.51'}, {'price': '0.18', 'size': '19.13'}, {'price': '0.19', 'size': '120'}, {'price': '0.2', 'size': '691.17'}, {'price': '0.24', 'size': '5027'}, {'price': '0.25', 'size': '86.66'}, {'price': '0.27', 'size': '215.25'}, {'price': '0.29', 'size': '1102.28'}, {'price': '0.31', 'size': '1130.65'}, {'price': '0.32', 'size': '200'}, {'price': '0.33', 'size': '620'}, {'price': '0.35', 'size': '232'}, {'price': '0.37', 'size': '4000'}, {'price': '0.39', 'size': '10.5'}, {'price': '0.4', 'size': '3135'}, {'price': '0.41', 'size': '20'}, {'price': '0.42', 'size': '3050'}, {'price': '0.43', 'size': '50'}, {'price': '0.44', 'size': '3660'}, {'price': '0.45', 'size': '478'}, {'price': '0.47', 'size': '297.23'}, {'price': '0.48', 'size': '3242.18'}, {'price': '0.49', 'size': '40'}, {'price': '0.5', 'size': '2015'}, {'price': '0.51', 'size': '2486.18'}, {'price': '0.52', 'size': '2085.92'}, {'price': '0.53', 'size': '1318.99'}, {'price': '0.54', 'size': '1121.19'}, {'price': '0.55', 'size': '3962.77'}, {'price': '0.56', 'size': '3658.28'}], 'event_type': 'book', 'hash': '844439c10a60b9507c10e2af0e4c0f059ba09cc6', 'market': '0x7aa4a910b31b2c4ddb09d1e3408e52aa8e09a14402f376070a44b1b85cb36d13', 'timestamp': '1733334307387'}
{'asks': [{'price': '0.99', 'size': '4217.01'}, {'price': '0.98', 'size': '505'}, {'price': '0.97', 'size': '511.03'}, {'price': '0.96', 'size': '300'}, {'price': '0.95', 'size': '657.12'}, {'price': '0.94', 'size': '300'}, {'price': '0.92', 'size': '20000.45'}, {'price': '0.91', 'size': '10406.3'}, {'price': '0.9', 'size': '4587.5'}, {'price': '0.89', 'size': '13017.18'}, {'price': '0.88', 'size': '200'}, {'price': '0.87', 'size': '3229'}, {'price': '0.86', 'size': '17.1'}, {'price': '0.85', 'size': '109.68'}, {'price': '0.84', 'size': '250'}, {'price': '0.83', 'size': '100'}, {'price': '0.82', 'size': '16029'}, {'price': '0.81', 'size': '45721.39'}, {'price': '0.8', 'size': '26531'}, {'price': '0.79', 'size': '7110'}, {'price': '0.78', 'size': '15350'}, {'price': '0.77', 'size': '67'}, {'price': '0.76', 'size': '200'}, {'price': '0.75', 'size': '13329.25'}, {'price': '0.74', 'size': '11370.7'}, {'price': '0.73', 'size': '5020.1'}, {'price': '0.72', 'size': '380.52'}, {'price': '0.71', 'size': '15073.2'}, {'price': '0.7', 'size': '5570.1'}, {'price': '0.69', 'size': '6088.6'}, {'price': '0.68', 'size': '6131.34'}, {'price': '0.67', 'size': '3010.1'}, {'price': '0.66', 'size': '510.1'}, {'price': '0.65', 'size': '1010.1'}, {'price': '0.64', 'size': '4230.1'}, {'price': '0.63', 'size': '210.1'}, {'price': '0.62', 'size': '400.1'}, {'price': '0.61', 'size': '861.06'}, {'price': '0.6', 'size': '3067.85'}, {'price': '0.59', 'size': '3610'}, {'price': '0.58', 'size': '1750.49'}], 'asset_id': '114416409796971863099144323163249651172534872992222856507897414949637892047507', 'bids': [{'price': '0.01', 'size': '2850.27'}, {'price': '0.02', 'size': '500'}, {'price': '0.03', 'size': '500'}, {'price': '0.04', 'size': '300'}, {'price': '0.05', 'size': '320'}, {'price': '0.06', 'size': '300'}, {'price': '0.08', 'size': '250'}, {'price': '0.09', 'size': '300'}, {'price': '0.1', 'size': '6205'}, {'price': '0.12', 'size': '200'}, {'price': '0.13', 'size': '426.92'}, {'price': '0.14', 'size': '15'}, {'price': '0.15', 'size': '110'}, {'price': '0.16', 'size': '4709.51'}, {'price': '0.18', 'size': '19.13'}, {'price': '0.19', 'size': '120'}, {'price': '0.2', 'size': '691.17'}, {'price': '0.24', 'size': '5027'}, {'price': '0.25', 'size': '86.66'}, {'price': '0.27', 'size': '215.25'}, {'price': '0.29', 'size': '1102.28'}, {'price': '0.31', 'size': '1130.65'}, {'price': '0.32', 'size': '200'}, {'price': '0.33', 'size': '620'}, {'price': '0.35', 'size': '232'}, {'price': '0.37', 'size': '4000'}, {'price': '0.39', 'size': '10.5'}, {'price': '0.4', 'size': '3135'}, {'price': '0.41', 'size': '20'}, {'price': '0.42', 'size': '3050'}, {'price': '0.43', 'size': '50'}, {'price': '0.44', 'size': '3660'}, {'price': '0.45', 'size': '478'}, {'price': '0.47', 'size': '297.23'}, {'price': '0.48', 'size': '3242.18'}, {'price': '0.49', 'size': '40'}, {'price': '0.5', 'size': '2015'}, {'price': '0.51', 'size': '2486.18'}, {'price': '0.52', 'size': '2085.92'}, {'price': '0.53', 'size': '1318.99'}, {'price': '0.54', 'size': '1121.19'}, {'price': '0.55', 'size': '3962.77'}, {'price': '0.56', 'size': '3658.28'}], 'event_type': 'book', 'hash': '844439c10a60b9507c10e2af0e4c0f059ba09cc6', 'market': '0x7aa4a910b31b2c4ddb09d1e3408e52aa8e09a14402f376070a44b1b85cb36d13', 'timestamp': '1733334307387'}
{'asks': [{'price': '0.99', 'size': '4217.01'}, {'price': '0.98', 'size': '505'}, {'price': '0.97', 'size': '511.03'}, {'price': '0.96', 'size': '300'}, {'price': '0.95', 'size': '657.12'}, {'price': '0.94', 'size': '300'}, {'price': '0.92', 'size': '20000.45'}, {'price': '0.91', 'size': '10406.3'}, {'price': '0.9', 'size': '4587.5'}, {'price': '0.89', 'size': '13017.18'}, {'price': '0.88', 'size': '200'}, {'price': '0.87', 'size': '3229'}, {'price': '0.86', 'size': '17.1'}, {'price': '0.85', 'size': '109.68'}, {'price': '0.84', 'size': '250'}, {'price': '0.83', 'size': '100'}, {'price': '0.82', 'size': '16029'}, {'price': '0.81', 'size': '45721.39'}, {'price': '0.8', 'size': '26531'}, {'price': '0.79', 'size': '7110'}, {'price': '0.78', 'size': '15350'}, {'price': '0.77', 'size': '67'}, {'price': '0.76', 'size': '200'}, {'price': '0.75', 'size': '13329.25'}, {'price': '0.74', 'size': '11370.7'}, {'price': '0.73', 'size': '5020.1'}, {'price': '0.72', 'size': '380.52'}, {'price': '0.71', 'size': '15073.2'}, {'price': '0.7', 'size': '5570.1'}, {'price': '0.69', 'size': '6088.6'}, {'price': '0.68', 'size': '6131.34'}, {'price': '0.67', 'size': '3010.1'}, {'price': '0.66', 'size': '510.1'}, {'price': '0.65', 'size': '1010.1'}, {'price': '0.64', 'size': '4230.1'}, {'price': '0.63', 'size': '210.1'}, {'price': '0.62', 'size': '400.1'}, {'price': '0.61', 'size': '861.06'}, {'price': '0.6', 'size': '3067.85'}, {'price': '0.59', 'size': '3610'}, {'price': '0.58', 'size': '1750.47'}], 'asset_id': '114416409796971863099144323163249651172534872992222856507897414949637892047507', 'bids': [{'price': '0.01', 'size': '2850.27'}, {'price': '0.02', 'size': '500'}, {'price': '0.03', 'size': '500'}, {'price': '0.04', 'size': '300'}, {'price': '0.05', 'size': '320'}, {'price': '0.06', 'size': '300'}, {'price': '0.08', 'size': '250'}, {'price': '0.09', 'size': '300'}, {'price': '0.1', 'size': '6205'}, {'price': '0.12', 'size': '200'}, {'price': '0.13', 'size': '426.92'}, {'price': '0.14', 'size': '15'}, {'price': '0.15', 'size': '110'}, {'price': '0.16', 'size': '4709.51'}, {'price': '0.18', 'size': '19.13'}, {'price': '0.19', 'size': '120'}, {'price': '0.2', 'size': '691.17'}, {'price': '0.24', 'size': '5027'}, {'price': '0.25', 'size': '86.66'}, {'price': '0.27', 'size': '215.25'}, {'price': '0.29', 'size': '1102.28'}, {'price': '0.31', 'size': '1130.65'}, {'price': '0.32', 'size': '200'}, {'price': '0.33', 'size': '620'}, {'price': '0.35', 'size': '232'}, {'price': '0.37', 'size': '4000'}, {'price': '0.39', 'size': '10.5'}, {'price': '0.4', 'size': '3135'}, {'price': '0.41', 'size': '20'}, {'price': '0.42', 'size': '3050'}, {'price': '0.43', 'size': '50'}, {'price': '0.44', 'size': '3660'}, {'price': '0.45', 'size': '478'}, {'price': '0.47', 'size': '297.23'}, {'price': '0.48', 'size': '3242.18'}, {'price': '0.49', 'size': '40'}, {'price': '0.5', 'size': '2015'}, {'price': '0.51', 'size': '2486.18'}, {'price': '0.52', 'size': '2085.92'}, {'price': '0.53', 'size': '1318.99'}, {'price': '0.54', 'size': '1121.19'}, {'price': '0.55', 'size': '3962.77'}, {'price': '0.56', 'size': '3658.28'}], 'event_type': 'book', 'hash': 'c78ef26dd865cd8795e95c1873ab50adfcd4e3b1', 'market': '0x7aa4a910b31b2c4ddb09d1e3408e52aa8e09a14402f376070a44b1b85cb36d13', 'timestamp': '1733334307778'}
{'asset_id': '114416409796971863099144323163249651172534872992222856507897414949637892047507', 'event_type': 'last_trade_price', 'fee_rate_bps': '0', 'market': '0x7aa4a910b31b2c4ddb09d1e3408e52aa8e09a14402f376070a44b1b85cb36d13', 'price': '0.58', 'side': 'BUY', 'size': '0.01724', 'timestamp': '1733334307797'}
{'asset_id': '114416409796971863099144323163249651172534872992222856507897414949637892047507', 'event_type': 'last_trade_price', 'fee_rate_bps': '0', 'market': '0x7aa4a910b31b2c4ddb09d1e3408e52aa8e09a14402f376070a44b1b85cb36d13', 'price': '0.58', 'side': 'BUY', 'size': '0.01724', 'timestamp': '1733334307797'}
{'asset_id': '114416409796971863099144323163249651172534872992222856507897414949637892047507', 'changes': [{'price': '0.54', 'side': 'BUY', 'size': '1131.19'}], 'event_type': 'price_change', 'hash': '94982c653f69d4dd51619df16c110f0cfc2ac75b', 'market': '0x7aa4a910b31b2c4ddb09d1e3408e52aa8e09a14402f376070a44b1b85cb36d13', 'timestamp': '1733334329235'}
{'asset_id': '114416409796971863099144323163249651172534872992222856507897414949637892047507', 'changes': [{'price': '0.54', 'side': 'BUY', 'size': '1131.19'}], 'event_type': 'price_change', 'hash': '94982c653f69d4dd51619df16c110f0cfc2ac75b', 'market': '0x7aa4a910b31b2c4ddb09d1e3408e52aa8e09a14402f376070a44b1b85cb36d13', 'timestamp': '1733334329235'}
{'asset_id': '114416409796971863099144323163249651172534872992222856507897414949637892047507', 'changes': [{'price': '0.48', 'side': 'BUY', 'size': '2742.18'}], 'event_type': 'price_change', 'hash': 'd3a3ade4fbda33d8448cfaf954f2ef4c7fc992bd', 'market': '0x7aa4a910b31b2c4ddb09d1e3408e52aa8e09a14402f376070a44b1b85cb36d13', 'timestamp': '1733334340947'}
{'asset_id': '114416409796971863099144323163249651172534872992222856507897414949637892047507', 'changes': [{'price': '0.48', 'side': 'BUY', 'size': '2742.18'}], 'event_type': 'price_change', 'hash': 'd3a3ade4fbda33d8448cfaf954f2ef4c7fc992bd', 'market': '0x7aa4a910b31b2c4ddb09d1e3408e52aa8e09a14402f376070a44b1b85cb36d13', 'timestamp': '1733334340947'}
{'asset_id': '114416409796971863099144323163249651172534872992222856507897414949637892047507', 'changes': [{'price': '0.58', 'side': 'SELL', 'size': '1250.47'}, {'price': '0.54', 'side': 'BUY', 'size': '131.19'}], 'event_type': 'price_change', 'hash': '2bbd33f4dd4d6355eb1217cbcd72f3d174b5cd76', 'market': '0x7aa4a910b31b2c4ddb09d1e3408e52aa8e09a14402f376070a44b1b85cb36d13', 'timestamp': '1733334340957'}
{'asset_id': '114416409796971863099144323163249651172534872992222856507897414949637892047507', 'changes': [{'price': '0.58', 'side': 'SELL', 'size': '1250.47'}, {'price': '0.54', 'side': 'BUY', 'size': '131.19'}], 'event_type': 'price_change', 'hash': '2bbd33f4dd4d6355eb1217cbcd72f3d174b5cd76', 'market': '0x7aa4a910b31b2c4ddb09d1e3408e52aa8e09a14402f376070a44b1b85cb36d13', 'timestamp': '1733334340957'}
{'asset_id': '114416409796971863099144323163249651172534872992222856507897414949637892047507', 'changes': [{'price': '0.48', 'side': 'BUY', 'size': '3242.18'}], 'event_type': 'price_change', 'hash': '3bfb044248b92f59c86fd0cec79a2e2c48dca0bc', 'market': '0x7aa4a910b31b2c4ddb09d1e3408e52aa8e09a14402f376070a44b1b85cb36d13', 'timestamp': '1733334342059'}
{'asset_id': '114416409796971863099144323163249651172534872992222856507897414949637892047507', 'changes': [{'price': '0.48', 'side': 'BUY', 'size': '3242.18'}], 'event_type': 'price_change', 'hash': '3bfb044248b92f59c86fd0cec79a2e2c48dca0bc', 'market': '0x7aa4a910b31b2c4ddb09d1e3408e52aa8e09a14402f376070a44b1b85cb36d13', 'timestamp': '1733334342059'}
{'asset_id': '114416409796971863099144323163249651172534872992222856507897414949637892047507', 'changes': [{'price': '0.58', 'side': 'SELL', 'size': '1750.47'}], 'event_type': 'price_change', 'hash': '64dd1f68b99483abdb207c9c0a955b80cc71b6a8', 'market': '0x7aa4a910b31b2c4ddb09d1e3408e52aa8e09a14402f376070a44b1b85cb36d13', 'timestamp': '1733334342430'}
{'asset_id': '114416409796971863099144323163249651172534872992222856507897414949637892047507', 'changes': [{'price': '0.58', 'side': 'SELL', 'size': '1750.47'}], 'event_type': 'price_change', 'hash': '64dd1f68b99483abdb207c9c0a955b80cc71b6a8', 'market': '0x7aa4a910b31b2c4ddb09d1e3408e52aa8e09a14402f376070a44b1b85cb36d13', 'timestamp': '1733334342430'}
{'asset_id': '114416409796971863099144323163249651172534872992222856507897414949637892047507', 'changes': [{'price': '0.53', 'side': 'BUY', 'size': '2318.99'}], 'event_type': 'price_change', 'hash': '729e9d9ad67816d265ef8e263f8fbb123b9e6df8', 'market': '0x7aa4a910b31b2c4ddb09d1e3408e52aa8e09a14402f376070a44b1b85cb36d13', 'timestamp': '1733334342805'}
{'asset_id': '114416409796971863099144323163249651172534872992222856507897414949637892047507', 'changes': [{'price': '0.53', 'side': 'BUY', 'size': '2318.99'}], 'event_type': 'price_change', 'hash': '729e9d9ad67816d265ef8e263f8fbb123b9e6df8', 'market': '0x7aa4a910b31b2c4ddb09d1e3408e52aa8e09a14402f376070a44b1b85cb36d13', 'timestamp': '1733334342805'}
{'asset_id': '114416409796971863099144323163249651172534872992222856507897414949637892047507', 'changes': [{'price': '0.55', 'side': 'BUY', 'size': '3972.77'}], 'event_type': 'price_change', 'hash': '8d851db437538403993bf2cc0a6036ed035d99a9', 'market': '0x7aa4a910b31b2c4ddb09d1e3408e52aa8e09a14402f376070a44b1b85cb36d13', 'timestamp': '1733334362980'}
{'asset_id': '114416409796971863099144323163249651172534872992222856507897414949637892047507', 'changes': [{'price': '0.55', 'side': 'BUY', 'size': '3972.77'}], 'event_type': 'price_change', 'hash': '8d851db437538403993bf2cc0a6036ed035d99a9', 'market': '0x7aa4a910b31b2c4ddb09d1e3408e52aa8e09a14402f376070a44b1b85cb36d13', 'timestamp': '1733334362980'}
{'asset_id': '114416409796971863099144323163249651172534872992222856507897414949637892047507', 'changes': [{'price': '0.59', 'side': 'SELL', 'size': '2110'}], 'event_type': 'price_change', 'hash': '28289ba1d04528f9dba4d0ad0f5a1f2ad027c325', 'market': '0x7aa4a910b31b2c4ddb09d1e3408e52aa8e09a14402f376070a44b1b85cb36d13', 'timestamp': '1733334382012'}
{'asset_id': '114416409796971863099144323163249651172534872992222856507897414949637892047507', 'changes': [{'price': '0.59', 'side': 'SELL', 'size': '2110'}], 'event_type': 'price_change', 'hash': '28289ba1d04528f9dba4d0ad0f5a1f2ad027c325', 'market': '0x7aa4a910b31b2c4ddb09d1e3408e52aa8e09a14402f376070a44b1b85cb36d13', 'timestamp': '1733334382012'}
{'asset_id': '114416409796971863099144323163249651172534872992222856507897414949637892047507', 'changes': [{'price': '0.48', 'side': 'BUY', 'size': '2742.18'}, {'price': '0.58', 'side': 'SELL', 'size': '1250.47'}, {'price': '0.53', 'side': 'BUY', 'size': '1318.99'}], 'event_type': 'price_change', 'hash': '7d819b3ea77eb36535110704fdbb46d7a17fa0f8', 'market': '0x7aa4a910b31b2c4ddb09d1e3408e52aa8e09a14402f376070a44b1b85cb36d13', 'timestamp': '1733334383018'}
{'asset_id': '114416409796971863099144323163249651172534872992222856507897414949637892047507', 'changes': [{'price': '0.48', 'side': 'BUY', 'size': '2742.18'}, {'price': '0.58', 'side': 'SELL', 'size': '1250.47'}, {'price': '0.53', 'side': 'BUY', 'size': '1318.99'}], 'event_type': 'price_change', 'hash': '7d819b3ea77eb36535110704fdbb46d7a17fa0f8', 'market': '0x7aa4a910b31b2c4ddb09d1e3408e52aa8e09a14402f376070a44b1b85cb36d13', 'timestamp': '1733334383018'}
{'asset_id': '114416409796971863099144323163249651172534872992222856507897414949637892047507', 'changes': [{'price': '0.47', 'side': 'BUY', 'size': '797.23'}], 'event_type': 'price_change', 'hash': '876ed477ecb5c6489a1e215d0782208de63f3594', 'market': '0x7aa4a910b31b2c4ddb09d1e3408e52aa8e09a14402f376070a44b1b85cb36d13', 'timestamp': '1733334384074'}
{'asset_id': '114416409796971863099144323163249651172534872992222856507897414949637892047507', 'changes': [{'price': '0.47', 'side': 'BUY', 'size': '797.23'}], 'event_type': 'price_change', 'hash': '876ed477ecb5c6489a1e215d0782208de63f3594', 'market': '0x7aa4a910b31b2c4ddb09d1e3408e52aa8e09a14402f376070a44b1b85cb36d13', 'timestamp': '1733334384074'}
{'asset_id': '114416409796971863099144323163249651172534872992222856507897414949637892047507', 'changes': [{'price': '0.57', 'side': 'SELL', 'size': '500'}], 'event_type': 'price_change', 'hash': 'b9ed6049db30cd0b8189b7a56b63abb2923d6494', 'market': '0x7aa4a910b31b2c4ddb09d1e3408e52aa8e09a14402f376070a44b1b85cb36d13', 'timestamp': '1733334384442'}
{'asset_id': '114416409796971863099144323163249651172534872992222856507897414949637892047507', 'changes': [{'price': '0.57', 'side': 'SELL', 'size': '500'}], 'event_type': 'price_change', 'hash': 'b9ed6049db30cd0b8189b7a56b63abb2923d6494', 'market': '0x7aa4a910b31b2c4ddb09d1e3408e52aa8e09a14402f376070a44b1b85cb36d13', 'timestamp': '1733334384442'}
{'asset_id': '114416409796971863099144323163249651172534872992222856507897414949637892047507', 'changes': [{'price': '0.53', 'side': 'BUY', 'size': '2318.99'}], 'event_type': 'price_change', 'hash': 'e1002d8ccaaa9a7d4a7b9cc7e125054d621d3f85', 'market': '0x7aa4a910b31b2c4ddb09d1e3408e52aa8e09a14402f376070a44b1b85cb36d13', 'timestamp': '1733334384847'}
{'asset_id': '114416409796971863099144323163249651172534872992222856507897414949637892047507', 'changes': [{'price': '0.53', 'side': 'BUY', 'size': '2318.99'}], 'event_type': 'price_change', 'hash': 'e1002d8ccaaa9a7d4a7b9cc7e125054d621d3f85', 'market': '0x7aa4a910b31b2c4ddb09d1e3408e52aa8e09a14402f376070a44b1b85cb36d13', 'timestamp': '1733334384847'}
{'asset_id': '114416409796971863099144323163249651172534872992222856507897414949637892047507', 'changes': [{'price': '0.56', 'side': 'BUY', 'size': '3668.28'}], 'event_type': 'price_change', 'hash': '4b8ae679a8e7208b634ba84498bbb246810aad85', 'market': '0x7aa4a910b31b2c4ddb09d1e3408e52aa8e09a14402f376070a44b1b85cb36d13', 'timestamp': '1733334386959'}
{'asset_id': '114416409796971863099144323163249651172534872992222856507897414949637892047507', 'changes': [{'price': '0.56', 'side': 'BUY', 'size': '3668.28'}], 'event_type': 'price_change', 'hash': '4b8ae679a8e7208b634ba84498bbb246810aad85', 'market': '0x7aa4a910b31b2c4ddb09d1e3408e52aa8e09a14402f376070a44b1b85cb36d13', 'timestamp': '1733334386959'}
{'asset_id': '114416409796971863099144323163249651172534872992222856507897414949637892047507', 'changes': [{'price': '0.59', 'side': 'SELL', 'size': '3610'}], 'event_type': 'price_change', 'hash': 'f48ab66e6f2554cc99234024b78589cc76a625e5', 'market': '0x7aa4a910b31b2c4ddb09d1e3408e52aa8e09a14402f376070a44b1b85cb36d13', 'timestamp': '1733334390856'}
{'asset_id': '114416409796971863099144323163249651172534872992222856507897414949637892047507', 'changes': [{'price': '0.59', 'side': 'SELL', 'size': '3610'}], 'event_type': 'price_change', 'hash': 'f48ab66e6f2554cc99234024b78589cc76a625e5', 'market': '0x7aa4a910b31b2c4ddb09d1e3408e52aa8e09a14402f376070a44b1b85cb36d13', 'timestamp': '1733334390856'}
{'asset_id': '114416409796971863099144323163249651172534872992222856507897414949637892047507', 'changes': [{'price': '0.58', 'side': 'SELL', 'size': '50.47'}, {'price': '0.52', 'side': 'BUY', 'size': '885.92'}], 'event_type': 'price_change', 'hash': '5df2f1a9e9c3dc697ce767992fe91ff8d82e137a', 'market': '0x7aa4a910b31b2c4ddb09d1e3408e52aa8e09a14402f376070a44b1b85cb36d13', 'timestamp': '1733334398461'}
{'asset_id': '114416409796971863099144323163249651172534872992222856507897414949637892047507', 'changes': [{'price': '0.58', 'side': 'SELL', 'size': '50.47'}, {'price': '0.52', 'side': 'BUY', 'size': '885.92'}], 'event_type': 'price_change', 'hash': '5df2f1a9e9c3dc697ce767992fe91ff8d82e137a', 'market': '0x7aa4a910b31b2c4ddb09d1e3408e52aa8e09a14402f376070a44b1b85cb36d13', 'timestamp': '1733334398461'}
{'asset_id': '114416409796971863099144323163249651172534872992222856507897414949637892047507', 'changes': [{'price': '0.57', 'side': 'SELL', 'size': '1700'}, {'price': '0.51', 'side': 'BUY', 'size': '3686.18'}], 'event_type': 'price_change', 'hash': '28f3acfc49e654c3feb4a3cbac6dafc8a52fe8a7', 'market': '0x7aa4a910b31b2c4ddb09d1e3408e52aa8e09a14402f376070a44b1b85cb36d13', 'timestamp': '1733334400769'}
{'asset_id': '114416409796971863099144323163249651172534872992222856507897414949637892047507', 'changes': [{'price': '0.57', 'side': 'SELL', 'size': '1700'}, {'price': '0.51', 'side': 'BUY', 'size': '3686.18'}], 'event_type': 'price_change', 'hash': '28f3acfc49e654c3feb4a3cbac6dafc8a52fe8a7', 'market': '0x7aa4a910b31b2c4ddb09d1e3408e52aa8e09a14402f376070a44b1b85cb36d13', 'timestamp': '1733334400769'}
